Log file created at: 2012/03/30 23:07:24
Running on machine: azad
Log line format: [IWEF]mmdd hh:mm:ss.uuuuuu threadid file:line] msg
I0330 23:07:24.449641 13318 logging.cpp:70] Logging to /mesos-distro/logdir
I0330 23:07:24.450228 13318 main.cpp:95] Build: 2012-03-28 23:30:52 by hduser
I0330 23:07:24.450252 13318 main.cpp:96] Starting Mesos master
I0330 23:07:24.450995 13319 master.cpp:264] Master started at mesos://master@192.168.1.64:5050
I0330 23:07:24.451060 13319 master.cpp:279] Master ID: 201203302307-0
I0330 23:07:24.451066 13318 webui.cpp:81] Starting master web server on port 9836
I0330 23:07:24.451239 13322 webui.cpp:47] Master web server thread started
I0330 23:07:24.451357 13319 master.cpp:462] Elected as master!
I0330 23:07:24.460672 13322 webui.cpp:59] Loading webui/master/webui.py
I0330 23:07:24.609072 13319 master.cpp:814] Attempting to register slave 201203302307-0-0 at slave@192.168.1.66:38618
I0330 23:07:24.609411 13319 master.cpp:1057] Master now considering a slave at ubuntu.gateway.2wire.net:38618 as active
I0330 23:07:24.609521 13319 master.cpp:1588] Adding slave 201203302307-0-0 at ubuntu.gateway.2wire.net with cpus=8; mem=6144
I0330 23:07:24.609680 13319 simple_allocator.cpp:71] Added slave 201203302307-0-0 with cpus=8; mem=6144
I0330 23:07:25.420804 13319 master.cpp:814] Attempting to register slave 201203302307-0-1 at slave@192.168.1.64:48930
I0330 23:07:25.421082 13319 master.cpp:1057] Master now considering a slave at azad.gateway.2wire.net:48930 as active
I0330 23:07:25.421190 13319 master.cpp:1588] Adding slave 201203302307-0-1 at azad.gateway.2wire.net with cpus=8; mem=8192
I0330 23:07:25.421373 13319 simple_allocator.cpp:71] Added slave 201203302307-0-1 with cpus=8; mem=8192
I0330 23:07:33.565109 13319 master.cpp:492] Registering framework 201203302307-0-0000 at 2@192.168.1.64:47084
I0330 23:07:33.565271 13319 simple_allocator.cpp:48] Added framework 201203302307-0-0000
I0330 23:07:33.565386 13319 master.cpp:1184] Sending 2 offers to framework 201203302307-0-0000
I0330 23:07:33.579244 13319 master.cpp:679] Received reply for offer 201203302307-0-0
I0330 23:07:33.579349 13319 master.cpp:1403] Filtered slave 201203302307-0-0 for framework 201203302307-0-0000 for 1 seconds
I0330 23:07:33.579402 13319 master.cpp:679] Received reply for offer 201203302307-0-1
I0330 23:07:33.579473 13319 master.cpp:1403] Filtered slave 201203302307-0-1 for framework 201203302307-0-0000 for 1 seconds
I0330 23:07:33.954622 13319 master.cpp:718] Reviving offers for framework 201203302307-0-0000
I0330 23:07:33.954665 13319 simple_allocator.cpp:145] Filters removed for framework 201203302307-0-0000
I0330 23:07:33.954782 13319 master.cpp:1184] Sending 2 offers to framework 201203302307-0-0000
I0330 23:07:34.042363 13319 master.cpp:679] Received reply for offer 201203302307-0-2
I0330 23:07:34.042459 13319 master.cpp:1403] Filtered slave 201203302307-0-0 for framework 201203302307-0-0000 for 1 seconds
I0330 23:07:34.044251 13319 master.cpp:679] Received reply for offer 201203302307-0-3
I0330 23:07:34.044353 13319 master.cpp:1453] Launching task 0 on slave 201203302307-0-1
I0330 23:07:34.044579 13319 master.cpp:1453] Launching task 1 on slave 201203302307-0-1
I0330 23:07:34.044688 13319 master.cpp:1453] Launching task 2 on slave 201203302307-0-1
I0330 23:07:34.044780 13319 master.cpp:1453] Launching task 3 on slave 201203302307-0-1
I0330 23:07:34.044908 13319 master.cpp:1453] Launching task 4 on slave 201203302307-0-1
I0330 23:07:34.044996 13319 master.cpp:1453] Launching task 5 on slave 201203302307-0-1
I0330 23:07:34.045083 13319 master.cpp:1453] Launching task 6 on slave 201203302307-0-1
I0330 23:07:34.045168 13319 master.cpp:1453] Launching task 7 on slave 201203302307-0-1
I0330 23:07:34.947716 13319 master.cpp:902] Status update from slave@192.168.1.64:48930: task 3 of framework 201203302307-0-0000 is now in state TASK_RUNNING
I0330 23:07:34.947870 13319 master.cpp:902] Status update from slave@192.168.1.64:48930: task 2 of framework 201203302307-0-0000 is now in state TASK_RUNNING
I0330 23:07:34.948513 13319 master.cpp:902] Status update from slave@192.168.1.64:48930: task 6 of framework 201203302307-0-0000 is now in state TASK_RUNNING
I0330 23:07:34.951401 13319 master.cpp:902] Status update from slave@192.168.1.64:48930: task 4 of framework 201203302307-0-0000 is now in state TASK_RUNNING
I0330 23:07:34.955028 13319 master.cpp:902] Status update from slave@192.168.1.64:48930: task 5 of framework 201203302307-0-0000 is now in state TASK_RUNNING
I0330 23:07:34.956327 13319 master.cpp:902] Status update from slave@192.168.1.64:48930: task 0 of framework 201203302307-0-0000 is now in state TASK_RUNNING
I0330 23:07:34.958510 13319 master.cpp:902] Status update from slave@192.168.1.64:48930: task 1 of framework 201203302307-0-0000 is now in state TASK_RUNNING
I0330 23:07:34.960808 13319 master.cpp:902] Status update from slave@192.168.1.64:48930: task 7 of framework 201203302307-0-0000 is now in state TASK_RUNNING
I0330 23:07:35.462645 13319 master.cpp:1184] Sending 1 offers to framework 201203302307-0-0000
I0330 23:07:35.464134 13319 master.cpp:679] Received reply for offer 201203302307-0-4
I0330 23:07:35.464280 13319 master.cpp:1403] Filtered slave 201203302307-0-0 for framework 201203302307-0-0000 for 1 seconds
I0330 23:07:36.782819 13319 master.cpp:902] Status update from slave@192.168.1.64:48930: task 7 of framework 201203302307-0-0000 is now in state TASK_FINISHED
I0330 23:07:36.783067 13319 master.cpp:1184] Sending 1 offers to framework 201203302307-0-0000
I0330 23:07:36.790186 13319 master.cpp:902] Status update from slave@192.168.1.64:48930: task 4 of framework 201203302307-0-0000 is now in state TASK_FINISHED
I0330 23:07:36.792392 13319 master.cpp:902] Status update from slave@192.168.1.64:48930: task 3 of framework 201203302307-0-0000 is now in state TASK_FINISHED
I0330 23:07:36.807204 13319 master.cpp:902] Status update from slave@192.168.1.64:48930: task 1 of framework 201203302307-0-0000 is now in state TASK_FINISHED
I0330 23:07:36.810982 13319 master.cpp:679] Received reply for offer 201203302307-0-5
I0330 23:07:36.811175 13319 master.cpp:1403] Filtered slave 201203302307-0-1 for framework 201203302307-0-0000 for 1 seconds
I0330 23:07:36.812466 13319 master.cpp:902] Status update from slave@192.168.1.64:48930: task 0 of framework 201203302307-0-0000 is now in state TASK_FINISHED
I0330 23:07:36.826645 13319 master.cpp:902] Status update from slave@192.168.1.64:48930: task 2 of framework 201203302307-0-0000 is now in state TASK_FINISHED
I0330 23:07:36.831704 13319 master.cpp:902] Status update from slave@192.168.1.64:48930: task 5 of framework 201203302307-0-0000 is now in state TASK_FINISHED
I0330 23:07:36.835309 13319 master.cpp:902] Status update from slave@192.168.1.64:48930: task 6 of framework 201203302307-0-0000 is now in state TASK_FINISHED
I0330 23:07:37.465373 13319 master.cpp:1184] Sending 1 offers to framework 201203302307-0-0000
I0330 23:07:37.466779 13319 master.cpp:679] Received reply for offer 201203302307-0-6
I0330 23:07:37.466924 13319 master.cpp:1403] Filtered slave 201203302307-0-0 for framework 201203302307-0-0000 for 1 seconds
I0330 23:07:38.466943 13319 master.cpp:1184] Sending 1 offers to framework 201203302307-0-0000
I0330 23:07:38.468265 13319 master.cpp:679] Received reply for offer 201203302307-0-7
I0330 23:07:38.468384 13319 master.cpp:1403] Filtered slave 201203302307-0-1 for framework 201203302307-0-0000 for 1 seconds
I0330 23:07:39.468451 13319 master.cpp:1184] Sending 1 offers to framework 201203302307-0-0000
I0330 23:07:39.469779 13319 master.cpp:679] Received reply for offer 201203302307-0-8
I0330 23:07:39.469926 13319 master.cpp:1403] Filtered slave 201203302307-0-0 for framework 201203302307-0-0000 for 1 seconds
I0330 23:07:40.469780 13319 master.cpp:1184] Sending 1 offers to framework 201203302307-0-0000
I0330 23:07:40.470904 13319 master.cpp:679] Received reply for offer 201203302307-0-9
I0330 23:07:40.471024 13319 master.cpp:1403] Filtered slave 201203302307-0-1 for framework 201203302307-0-0000 for 1 seconds
I0330 23:07:41.472090 13319 master.cpp:1184] Sending 2 offers to framework 201203302307-0-0000
I0330 23:07:41.473556 13319 master.cpp:679] Received reply for offer 201203302307-0-10
I0330 23:07:41.473702 13319 master.cpp:1403] Filtered slave 201203302307-0-0 for framework 201203302307-0-0000 for 1 seconds
I0330 23:07:41.473969 13319 master.cpp:679] Received reply for offer 201203302307-0-11
I0330 23:07:41.474125 13319 master.cpp:1403] Filtered slave 201203302307-0-1 for framework 201203302307-0-0000 for 1 seconds
I0330 23:07:43.475026 13319 master.cpp:1184] Sending 2 offers to framework 201203302307-0-0000
I0330 23:07:43.476315 13319 master.cpp:679] Received reply for offer 201203302307-0-12
I0330 23:07:43.476438 13319 master.cpp:1403] Filtered slave 201203302307-0-0 for framework 201203302307-0-0000 for 1 seconds
I0330 23:07:43.476692 13319 master.cpp:679] Received reply for offer 201203302307-0-13
I0330 23:07:43.476819 13319 master.cpp:1403] Filtered slave 201203302307-0-1 for framework 201203302307-0-0000 for 1 seconds
I0330 23:07:45.477789 13319 master.cpp:1184] Sending 2 offers to framework 201203302307-0-0000
I0330 23:07:45.479087 13319 master.cpp:679] Received reply for offer 201203302307-0-14
I0330 23:07:45.479208 13319 master.cpp:1403] Filtered slave 201203302307-0-0 for framework 201203302307-0-0000 for 1 seconds
I0330 23:07:45.479465 13319 master.cpp:679] Received reply for offer 201203302307-0-15
I0330 23:07:45.479590 13319 master.cpp:1403] Filtered slave 201203302307-0-1 for framework 201203302307-0-0000 for 1 seconds
I0330 23:07:47.480561 13319 master.cpp:1184] Sending 2 offers to framework 201203302307-0-0000
I0330 23:07:47.481817 13319 master.cpp:679] Received reply for offer 201203302307-0-16
I0330 23:07:47.481936 13319 master.cpp:1403] Filtered slave 201203302307-0-0 for framework 201203302307-0-0000 for 1 seconds
I0330 23:07:47.482192 13319 master.cpp:679] Received reply for offer 201203302307-0-17
I0330 23:07:47.482316 13319 master.cpp:1403] Filtered slave 201203302307-0-1 for framework 201203302307-0-0000 for 1 seconds
I0330 23:07:49.483211 13319 master.cpp:1184] Sending 2 offers to framework 201203302307-0-0000
I0330 23:07:49.484547 13319 master.cpp:679] Received reply for offer 201203302307-0-18
I0330 23:07:49.484670 13319 master.cpp:1403] Filtered slave 201203302307-0-0 for framework 201203302307-0-0000 for 1 seconds
I0330 23:07:49.484940 13319 master.cpp:679] Received reply for offer 201203302307-0-19
I0330 23:07:49.485069 13319 master.cpp:1403] Filtered slave 201203302307-0-1 for framework 201203302307-0-0000 for 1 seconds
I0330 23:07:51.486004 13319 master.cpp:1184] Sending 2 offers to framework 201203302307-0-0000
I0330 23:07:51.487309 13319 master.cpp:679] Received reply for offer 201203302307-0-20
I0330 23:07:51.487431 13319 master.cpp:1403] Filtered slave 201203302307-0-0 for framework 201203302307-0-0000 for 1 seconds
I0330 23:07:51.487687 13319 master.cpp:679] Received reply for offer 201203302307-0-21
I0330 23:07:51.487812 13319 master.cpp:1403] Filtered slave 201203302307-0-1 for framework 201203302307-0-0000 for 1 seconds
I0330 23:07:53.488788 13319 master.cpp:1184] Sending 2 offers to framework 201203302307-0-0000
I0330 23:07:53.490072 13319 master.cpp:679] Received reply for offer 201203302307-0-22
I0330 23:07:53.490192 13319 master.cpp:1403] Filtered slave 201203302307-0-0 for framework 201203302307-0-0000 for 1 seconds
I0330 23:07:53.490447 13319 master.cpp:679] Received reply for offer 201203302307-0-23
I0330 23:07:53.490573 13319 master.cpp:1403] Filtered slave 201203302307-0-1 for framework 201203302307-0-0000 for 1 seconds
I0330 23:07:55.491196 13319 master.cpp:1184] Sending 2 offers to framework 201203302307-0-0000
I0330 23:07:55.492437 13319 master.cpp:679] Received reply for offer 201203302307-0-24
I0330 23:07:55.492559 13319 master.cpp:1403] Filtered slave 201203302307-0-0 for framework 201203302307-0-0000 for 1 seconds
I0330 23:07:55.492815 13319 master.cpp:679] Received reply for offer 201203302307-0-25
I0330 23:07:55.492941 13319 master.cpp:1403] Filtered slave 201203302307-0-1 for framework 201203302307-0-0000 for 1 seconds
I0330 23:07:57.493875 13319 master.cpp:1184] Sending 2 offers to framework 201203302307-0-0000
I0330 23:07:57.495437 13319 master.cpp:679] Received reply for offer 201203302307-0-26
I0330 23:07:57.495564 13319 master.cpp:1403] Filtered slave 201203302307-0-0 for framework 201203302307-0-0000 for 1 seconds
I0330 23:07:57.495805 13319 master.cpp:679] Received reply for offer 201203302307-0-27
I0330 23:07:57.495956 13319 master.cpp:1403] Filtered slave 201203302307-0-1 for framework 201203302307-0-0000 for 1 seconds
I0330 23:07:59.496446 13319 master.cpp:1184] Sending 2 offers to framework 201203302307-0-0000
I0330 23:07:59.497797 13319 master.cpp:679] Received reply for offer 201203302307-0-28
I0330 23:07:59.497927 13319 master.cpp:1403] Filtered slave 201203302307-0-0 for framework 201203302307-0-0000 for 1 seconds
I0330 23:07:59.498178 13319 master.cpp:679] Received reply for offer 201203302307-0-29
I0330 23:07:59.498358 13319 master.cpp:1403] Filtered slave 201203302307-0-1 for framework 201203302307-0-0000 for 1 seconds
I0330 23:08:01.498913 13319 master.cpp:1184] Sending 2 offers to framework 201203302307-0-0000
I0330 23:08:01.500350 13319 master.cpp:679] Received reply for offer 201203302307-0-30
I0330 23:08:01.500561 13319 master.cpp:1403] Filtered slave 201203302307-0-0 for framework 201203302307-0-0000 for 1 seconds
I0330 23:08:01.500812 13319 master.cpp:679] Received reply for offer 201203302307-0-31
I0330 23:08:01.500977 13319 master.cpp:1403] Filtered slave 201203302307-0-1 for framework 201203302307-0-0000 for 1 seconds
I0330 23:08:03.501813 13319 master.cpp:1184] Sending 2 offers to framework 201203302307-0-0000
I0330 23:08:03.503039 13319 master.cpp:679] Received reply for offer 201203302307-0-32
I0330 23:08:03.503162 13319 master.cpp:1403] Filtered slave 201203302307-0-0 for framework 201203302307-0-0000 for 1 seconds
I0330 23:08:03.503443 13319 master.cpp:679] Received reply for offer 201203302307-0-33
I0330 23:08:03.503641 13319 master.cpp:1403] Filtered slave 201203302307-0-1 for framework 201203302307-0-0000 for 1 seconds
I0330 23:08:05.504451 13319 master.cpp:1184] Sending 2 offers to framework 201203302307-0-0000
I0330 23:08:05.505811 13319 master.cpp:679] Received reply for offer 201203302307-0-34
I0330 23:08:05.505931 13319 master.cpp:1403] Filtered slave 201203302307-0-0 for framework 201203302307-0-0000 for 1 seconds
I0330 23:08:05.506214 13319 master.cpp:679] Received reply for offer 201203302307-0-35
I0330 23:08:05.506371 13319 master.cpp:1403] Filtered slave 201203302307-0-1 for framework 201203302307-0-0000 for 1 seconds
I0330 23:08:07.507179 13319 master.cpp:1184] Sending 2 offers to framework 201203302307-0-0000
I0330 23:08:07.508584 13319 master.cpp:679] Received reply for offer 201203302307-0-36
I0330 23:08:07.508703 13319 master.cpp:1403] Filtered slave 201203302307-0-0 for framework 201203302307-0-0000 for 1 seconds
I0330 23:08:07.509018 13319 master.cpp:679] Received reply for offer 201203302307-0-37
I0330 23:08:07.509198 13319 master.cpp:1403] Filtered slave 201203302307-0-1 for framework 201203302307-0-0000 for 1 seconds
I0330 23:08:09.509994 13319 master.cpp:1184] Sending 2 offers to framework 201203302307-0-0000
I0330 23:08:09.511451 13319 master.cpp:679] Received reply for offer 201203302307-0-38
I0330 23:08:09.511570 13319 master.cpp:1403] Filtered slave 201203302307-0-0 for framework 201203302307-0-0000 for 1 seconds
I0330 23:08:09.511858 13319 master.cpp:679] Received reply for offer 201203302307-0-39
I0330 23:08:09.512037 13319 master.cpp:1403] Filtered slave 201203302307-0-1 for framework 201203302307-0-0000 for 1 seconds
I0330 23:08:11.511862 13319 master.cpp:1184] Sending 2 offers to framework 201203302307-0-0000
I0330 23:08:11.513393 13319 master.cpp:679] Received reply for offer 201203302307-0-40
I0330 23:08:11.513514 13319 master.cpp:1403] Filtered slave 201203302307-0-0 for framework 201203302307-0-0000 for 1 seconds
I0330 23:08:11.513792 13319 master.cpp:679] Received reply for offer 201203302307-0-41
I0330 23:08:11.513914 13319 master.cpp:1403] Filtered slave 201203302307-0-1 for framework 201203302307-0-0000 for 1 seconds
I0330 23:08:13.514811 13319 master.cpp:1184] Sending 2 offers to framework 201203302307-0-0000
I0330 23:08:13.516324 13319 master.cpp:679] Received reply for offer 201203302307-0-42
I0330 23:08:13.516445 13319 master.cpp:1403] Filtered slave 201203302307-0-0 for framework 201203302307-0-0000 for 1 seconds
I0330 23:08:13.516706 13319 master.cpp:679] Received reply for offer 201203302307-0-43
I0330 23:08:13.516855 13319 master.cpp:1403] Filtered slave 201203302307-0-1 for framework 201203302307-0-0000 for 1 seconds
I0330 23:08:15.517700 13319 master.cpp:1184] Sending 2 offers to framework 201203302307-0-0000
I0330 23:08:15.519220 13319 master.cpp:679] Received reply for offer 201203302307-0-44
I0330 23:08:15.519342 13319 master.cpp:1403] Filtered slave 201203302307-0-0 for framework 201203302307-0-0000 for 1 seconds
I0330 23:08:15.519677 13319 master.cpp:679] Received reply for offer 201203302307-0-45
I0330 23:08:15.519804 13319 master.cpp:1403] Filtered slave 201203302307-0-1 for framework 201203302307-0-0000 for 1 seconds
I0330 23:08:17.520694 13319 master.cpp:1184] Sending 2 offers to framework 201203302307-0-0000
I0330 23:08:17.522186 13319 master.cpp:679] Received reply for offer 201203302307-0-46
I0330 23:08:17.522331 13319 master.cpp:1403] Filtered slave 201203302307-0-0 for framework 201203302307-0-0000 for 1 seconds
I0330 23:08:17.522577 13319 master.cpp:679] Received reply for offer 201203302307-0-47
I0330 23:08:17.522778 13319 master.cpp:1403] Filtered slave 201203302307-0-1 for framework 201203302307-0-0000 for 1 seconds
I0330 23:08:19.523327 13319 master.cpp:1184] Sending 2 offers to framework 201203302307-0-0000
I0330 23:08:19.524881 13319 master.cpp:679] Received reply for offer 201203302307-0-48
I0330 23:08:19.525017 13319 master.cpp:1403] Filtered slave 201203302307-0-0 for framework 201203302307-0-0000 for 1 seconds
I0330 23:08:19.525279 13319 master.cpp:679] Received reply for offer 201203302307-0-49
I0330 23:08:19.525408 13319 master.cpp:1403] Filtered slave 201203302307-0-1 for framework 201203302307-0-0000 for 1 seconds
I0330 23:08:21.064524 13319 master.cpp:718] Reviving offers for framework 201203302307-0-0000
I0330 23:08:21.064587 13319 simple_allocator.cpp:145] Filters removed for framework 201203302307-0-0000
I0330 23:08:21.065122 13319 master.cpp:1184] Sending 2 offers to framework 201203302307-0-0000
I0330 23:08:21.155823 13319 master.cpp:679] Received reply for offer 201203302307-0-50
I0330 23:08:21.155976 13319 master.cpp:1403] Filtered slave 201203302307-0-0 for framework 201203302307-0-0000 for 1 seconds
I0330 23:08:21.157474 13319 master.cpp:679] Received reply for offer 201203302307-0-51
I0330 23:08:21.157600 13319 master.cpp:1453] Launching task 8 on slave 201203302307-0-1
I0330 23:08:21.157804 13319 master.cpp:1453] Launching task 9 on slave 201203302307-0-1
I0330 23:08:21.157976 13319 master.cpp:1453] Launching task 10 on slave 201203302307-0-1
I0330 23:08:21.158197 13319 master.cpp:1453] Launching task 11 on slave 201203302307-0-1
I0330 23:08:21.158318 13319 master.cpp:1453] Launching task 12 on slave 201203302307-0-1
I0330 23:08:21.159287 13319 master.cpp:1453] Launching task 13 on slave 201203302307-0-1
I0330 23:08:21.160370 13319 master.cpp:1453] Launching task 14 on slave 201203302307-0-1
I0330 23:08:21.160661 13319 master.cpp:1453] Launching task 15 on slave 201203302307-0-1
I0330 23:08:21.162309 13319 master.cpp:902] Status update from slave@192.168.1.64:48930: task 8 of framework 201203302307-0-0000 is now in state TASK_RUNNING
I0330 23:08:21.164039 13319 master.cpp:902] Status update from slave@192.168.1.64:48930: task 9 of framework 201203302307-0-0000 is now in state TASK_RUNNING
I0330 23:08:21.171573 13319 master.cpp:902] Status update from slave@192.168.1.64:48930: task 10 of framework 201203302307-0-0000 is now in state TASK_RUNNING
I0330 23:08:21.172773 13319 master.cpp:902] Status update from slave@192.168.1.64:48930: task 11 of framework 201203302307-0-0000 is now in state TASK_RUNNING
I0330 23:08:21.175235 13319 master.cpp:902] Status update from slave@192.168.1.64:48930: task 12 of framework 201203302307-0-0000 is now in state TASK_RUNNING
I0330 23:08:21.177180 13319 master.cpp:902] Status update from slave@192.168.1.64:48930: task 13 of framework 201203302307-0-0000 is now in state TASK_RUNNING
I0330 23:08:21.179695 13319 master.cpp:902] Status update from slave@192.168.1.64:48930: task 15 of framework 201203302307-0-0000 is now in state TASK_RUNNING
I0330 23:08:21.181818 13319 master.cpp:902] Status update from slave@192.168.1.64:48930: task 14 of framework 201203302307-0-0000 is now in state TASK_RUNNING
I0330 23:08:22.527235 13319 master.cpp:1184] Sending 1 offers to framework 201203302307-0-0000
I0330 23:08:22.539335 13319 master.cpp:679] Received reply for offer 201203302307-0-52
I0330 23:08:22.539549 13319 master.cpp:1403] Filtered slave 201203302307-0-0 for framework 201203302307-0-0000 for 1 seconds
I0330 23:08:24.530619 13319 master.cpp:1184] Sending 1 offers to framework 201203302307-0-0000
I0330 23:08:24.535187 13319 master.cpp:679] Received reply for offer 201203302307-0-53
I0330 23:08:24.535326 13319 master.cpp:1403] Filtered slave 201203302307-0-0 for framework 201203302307-0-0000 for 1 seconds
I0330 23:08:26.532980 13319 master.cpp:1184] Sending 1 offers to framework 201203302307-0-0000
I0330 23:08:26.535187 13319 master.cpp:679] Received reply for offer 201203302307-0-54
I0330 23:08:26.535323 13319 master.cpp:1403] Filtered slave 201203302307-0-0 for framework 201203302307-0-0000 for 1 seconds
I0330 23:08:28.536403 13319 master.cpp:1184] Sending 1 offers to framework 201203302307-0-0000
I0330 23:08:28.539111 13319 master.cpp:679] Received reply for offer 201203302307-0-55
I0330 23:08:28.539249 13319 master.cpp:1403] Filtered slave 201203302307-0-0 for framework 201203302307-0-0000 for 1 seconds
I0330 23:08:30.539232 13319 master.cpp:1184] Sending 1 offers to framework 201203302307-0-0000
I0330 23:08:30.543185 13319 master.cpp:679] Received reply for offer 201203302307-0-56
I0330 23:08:30.543323 13319 master.cpp:1403] Filtered slave 201203302307-0-0 for framework 201203302307-0-0000 for 1 seconds
I0330 23:08:32.542484 13319 master.cpp:1184] Sending 1 offers to framework 201203302307-0-0000
I0330 23:08:32.544922 13319 master.cpp:679] Received reply for offer 201203302307-0-57
I0330 23:08:32.545063 13319 master.cpp:1403] Filtered slave 201203302307-0-0 for framework 201203302307-0-0000 for 1 seconds
I0330 23:08:34.544445 13319 master.cpp:1184] Sending 1 offers to framework 201203302307-0-0000
I0330 23:08:34.551183 13319 master.cpp:679] Received reply for offer 201203302307-0-58
I0330 23:08:34.551321 13319 master.cpp:1403] Filtered slave 201203302307-0-0 for framework 201203302307-0-0000 for 1 seconds
I0330 23:08:36.546635 13319 master.cpp:1184] Sending 1 offers to framework 201203302307-0-0000
I0330 23:08:36.555266 13319 master.cpp:679] Received reply for offer 201203302307-0-59
I0330 23:08:36.555461 13319 master.cpp:1403] Filtered slave 201203302307-0-0 for framework 201203302307-0-0000 for 1 seconds
I0330 23:08:38.549355 13319 master.cpp:1184] Sending 1 offers to framework 201203302307-0-0000
I0330 23:08:38.555181 13319 master.cpp:679] Received reply for offer 201203302307-0-60
I0330 23:08:38.555320 13319 master.cpp:1403] Filtered slave 201203302307-0-0 for framework 201203302307-0-0000 for 1 seconds
I0330 23:08:40.551944 13319 master.cpp:1184] Sending 1 offers to framework 201203302307-0-0000
I0330 23:08:40.559241 13319 master.cpp:679] Received reply for offer 201203302307-0-61
I0330 23:08:40.559433 13319 master.cpp:1403] Filtered slave 201203302307-0-0 for framework 201203302307-0-0000 for 1 seconds
I0330 23:08:42.554524 13319 master.cpp:1184] Sending 1 offers to framework 201203302307-0-0000
I0330 23:08:42.557962 13319 master.cpp:679] Received reply for offer 201203302307-0-62
I0330 23:08:42.558101 13319 master.cpp:1403] Filtered slave 201203302307-0-0 for framework 201203302307-0-0000 for 1 seconds
I0330 23:08:44.556404 13319 master.cpp:1184] Sending 1 offers to framework 201203302307-0-0000
I0330 23:08:44.557709 13319 master.cpp:679] Received reply for offer 201203302307-0-63
I0330 23:08:44.557880 13319 master.cpp:1403] Filtered slave 201203302307-0-0 for framework 201203302307-0-0000 for 1 seconds
I0330 23:08:46.559007 13319 master.cpp:1184] Sending 1 offers to framework 201203302307-0-0000
I0330 23:08:46.560312 13319 master.cpp:679] Received reply for offer 201203302307-0-64
I0330 23:08:46.560449 13319 master.cpp:1403] Filtered slave 201203302307-0-0 for framework 201203302307-0-0000 for 1 seconds
I0330 23:08:48.561606 13319 master.cpp:1184] Sending 1 offers to framework 201203302307-0-0000
I0330 23:08:48.562878 13319 master.cpp:679] Received reply for offer 201203302307-0-65
I0330 23:08:48.563015 13319 master.cpp:1403] Filtered slave 201203302307-0-0 for framework 201203302307-0-0000 for 1 seconds
I0330 23:08:50.563282 13319 master.cpp:1184] Sending 1 offers to framework 201203302307-0-0000
I0330 23:08:50.565048 13319 master.cpp:679] Received reply for offer 201203302307-0-66
I0330 23:08:50.565276 13319 master.cpp:1403] Filtered slave 201203302307-0-0 for framework 201203302307-0-0000 for 1 seconds
I0330 23:08:52.566347 13319 master.cpp:1184] Sending 1 offers to framework 201203302307-0-0000
I0330 23:08:52.567610 13319 master.cpp:679] Received reply for offer 201203302307-0-67
I0330 23:08:52.567747 13319 master.cpp:1403] Filtered slave 201203302307-0-0 for framework 201203302307-0-0000 for 1 seconds
I0330 23:08:54.568392 13319 master.cpp:1184] Sending 1 offers to framework 201203302307-0-0000
I0330 23:08:54.569686 13319 master.cpp:679] Received reply for offer 201203302307-0-68
I0330 23:08:54.569823 13319 master.cpp:1403] Filtered slave 201203302307-0-0 for framework 201203302307-0-0000 for 1 seconds
I0330 23:08:56.570873 13319 master.cpp:1184] Sending 1 offers to framework 201203302307-0-0000
I0330 23:08:56.572202 13319 master.cpp:679] Received reply for offer 201203302307-0-69
I0330 23:08:56.572340 13319 master.cpp:1403] Filtered slave 201203302307-0-0 for framework 201203302307-0-0000 for 1 seconds
I0330 23:08:58.573505 13319 master.cpp:1184] Sending 1 offers to framework 201203302307-0-0000
I0330 23:08:58.574815 13319 master.cpp:679] Received reply for offer 201203302307-0-70
I0330 23:08:58.574954 13319 master.cpp:1403] Filtered slave 201203302307-0-0 for framework 201203302307-0-0000 for 1 seconds
I0330 23:09:00.575237 13319 master.cpp:1184] Sending 1 offers to framework 201203302307-0-0000
I0330 23:09:00.599939 13319 master.cpp:679] Received reply for offer 201203302307-0-71
I0330 23:09:00.600112 13319 master.cpp:1403] Filtered slave 201203302307-0-0 for framework 201203302307-0-0000 for 1 seconds
I0330 23:09:02.578207 13319 master.cpp:1184] Sending 1 offers to framework 201203302307-0-0000
I0330 23:09:02.579505 13319 master.cpp:679] Received reply for offer 201203302307-0-72
I0330 23:09:02.579643 13319 master.cpp:1403] Filtered slave 201203302307-0-0 for framework 201203302307-0-0000 for 1 seconds
I0330 23:09:04.580399 13319 master.cpp:1184] Sending 1 offers to framework 201203302307-0-0000
I0330 23:09:04.581706 13319 master.cpp:679] Received reply for offer 201203302307-0-73
I0330 23:09:04.581840 13319 master.cpp:1403] Filtered slave 201203302307-0-0 for framework 201203302307-0-0000 for 1 seconds
I0330 23:09:06.583006 13319 master.cpp:1184] Sending 1 offers to framework 201203302307-0-0000
I0330 23:09:06.584321 13319 master.cpp:679] Received reply for offer 201203302307-0-74
I0330 23:09:06.584457 13319 master.cpp:1403] Filtered slave 201203302307-0-0 for framework 201203302307-0-0000 for 1 seconds
I0330 23:09:08.585626 13319 master.cpp:1184] Sending 1 offers to framework 201203302307-0-0000
I0330 23:09:08.587095 13319 master.cpp:679] Received reply for offer 201203302307-0-75
I0330 23:09:08.587291 13319 master.cpp:1403] Filtered slave 201203302307-0-0 for framework 201203302307-0-0000 for 1 seconds
I0330 23:09:10.588011 13319 master.cpp:1184] Sending 1 offers to framework 201203302307-0-0000
I0330 23:09:10.589524 13319 master.cpp:679] Received reply for offer 201203302307-0-76
I0330 23:09:10.589721 13319 master.cpp:1403] Filtered slave 201203302307-0-0 for framework 201203302307-0-0000 for 1 seconds
I0330 23:09:12.590818 13319 master.cpp:1184] Sending 1 offers to framework 201203302307-0-0000
I0330 23:09:12.592181 13319 master.cpp:679] Received reply for offer 201203302307-0-77
I0330 23:09:12.592319 13319 master.cpp:1403] Filtered slave 201203302307-0-0 for framework 201203302307-0-0000 for 1 seconds
I0330 23:09:14.593482 13319 master.cpp:1184] Sending 1 offers to framework 201203302307-0-0000
I0330 23:09:14.594835 13319 master.cpp:679] Received reply for offer 201203302307-0-78
I0330 23:09:14.594969 13319 master.cpp:1403] Filtered slave 201203302307-0-0 for framework 201203302307-0-0000 for 1 seconds
I0330 23:09:16.596102 13319 master.cpp:1184] Sending 1 offers to framework 201203302307-0-0000
I0330 23:09:16.597587 13319 master.cpp:679] Received reply for offer 201203302307-0-79
I0330 23:09:16.597762 13319 master.cpp:1403] Filtered slave 201203302307-0-0 for framework 201203302307-0-0000 for 1 seconds
I0330 23:09:18.598886 13319 master.cpp:1184] Sending 1 offers to framework 201203302307-0-0000
I0330 23:09:18.600196 13319 master.cpp:679] Received reply for offer 201203302307-0-80
I0330 23:09:18.600330 13319 master.cpp:1403] Filtered slave 201203302307-0-0 for framework 201203302307-0-0000 for 1 seconds
I0330 23:09:20.601528 13319 master.cpp:1184] Sending 1 offers to framework 201203302307-0-0000
I0330 23:09:20.602874 13319 master.cpp:679] Received reply for offer 201203302307-0-81
I0330 23:09:20.603010 13319 master.cpp:1403] Filtered slave 201203302307-0-0 for framework 201203302307-0-0000 for 1 seconds
I0330 23:09:22.603241 13319 master.cpp:1184] Sending 1 offers to framework 201203302307-0-0000
I0330 23:09:22.604603 13319 master.cpp:679] Received reply for offer 201203302307-0-82
I0330 23:09:22.604738 13319 master.cpp:1403] Filtered slave 201203302307-0-0 for framework 201203302307-0-0000 for 1 seconds
I0330 23:09:24.605578 13319 master.cpp:1184] Sending 1 offers to framework 201203302307-0-0000
I0330 23:09:24.606951 13319 master.cpp:679] Received reply for offer 201203302307-0-83
I0330 23:09:24.607095 13319 master.cpp:1403] Filtered slave 201203302307-0-0 for framework 201203302307-0-0000 for 1 seconds
I0330 23:09:26.607233 13319 master.cpp:1184] Sending 1 offers to framework 201203302307-0-0000
I0330 23:09:26.608564 13319 master.cpp:679] Received reply for offer 201203302307-0-84
I0330 23:09:26.608698 13319 master.cpp:1403] Filtered slave 201203302307-0-0 for framework 201203302307-0-0000 for 1 seconds
I0330 23:09:28.609866 13319 master.cpp:1184] Sending 1 offers to framework 201203302307-0-0000
I0330 23:09:28.611213 13319 master.cpp:679] Received reply for offer 201203302307-0-85
I0330 23:09:28.611351 13319 master.cpp:1403] Filtered slave 201203302307-0-0 for framework 201203302307-0-0000 for 1 seconds
I0330 23:09:30.315584 13319 master.cpp:1118] Framework 201203302307-0-0000 disconnected
I0330 23:09:41.759310 13319 master.cpp:492] Registering framework 201203302307-0-0001 at 2@192.168.1.64:52411
I0330 23:09:41.759631 13319 simple_allocator.cpp:48] Added framework 201203302307-0-0001
I0330 23:09:41.759791 13319 master.cpp:1184] Sending 1 offers to framework 201203302307-0-0001
I0330 23:09:41.807251 13319 master.cpp:492] Registering framework 201203302307-0-0002 at 4@192.168.1.64:52411
I0330 23:09:41.807487 13319 simple_allocator.cpp:48] Added framework 201203302307-0-0002
I0330 23:09:41.843361 13319 master.cpp:679] Received reply for offer 201203302307-0-86
I0330 23:09:41.843566 13319 master.cpp:1403] Filtered slave 201203302307-0-0 for framework 201203302307-0-0001 for 1 seconds
I0330 23:09:42.534605 13319 master.cpp:718] Reviving offers for framework 201203302307-0-0002
I0330 23:09:42.534740 13319 simple_allocator.cpp:145] Filters removed for framework 201203302307-0-0002
I0330 23:09:42.535033 13319 master.cpp:1184] Sending 1 offers to framework 201203302307-0-0002
I0330 23:09:42.539172 13319 master.cpp:679] Received reply for offer 201203302307-0-87
I0330 23:09:42.539392 13319 master.cpp:1403] Filtered slave 201203302307-0-0 for framework 201203302307-0-0002 for 1 seconds
I0330 23:09:43.624563 13319 master.cpp:1184] Sending 1 offers to framework 201203302307-0-0001
I0330 23:09:43.625881 13319 master.cpp:679] Received reply for offer 201203302307-0-88
I0330 23:09:43.626023 13319 master.cpp:1403] Filtered slave 201203302307-0-0 for framework 201203302307-0-0001 for 1 seconds
I0330 23:09:44.626018 13319 master.cpp:1184] Sending 1 offers to framework 201203302307-0-0002
I0330 23:09:44.627341 13319 master.cpp:679] Received reply for offer 201203302307-0-89
I0330 23:09:44.627480 13319 master.cpp:1403] Filtered slave 201203302307-0-0 for framework 201203302307-0-0002 for 1 seconds
I0330 23:09:45.627246 13319 master.cpp:1184] Sending 1 offers to framework 201203302307-0-0001
I0330 23:09:45.628552 13319 master.cpp:679] Received reply for offer 201203302307-0-90
I0330 23:09:45.628692 13319 master.cpp:1403] Filtered slave 201203302307-0-0 for framework 201203302307-0-0001 for 1 seconds
I0330 23:09:46.628690 13319 master.cpp:1184] Sending 1 offers to framework 201203302307-0-0002
I0330 23:09:46.630012 13319 master.cpp:679] Received reply for offer 201203302307-0-91
I0330 23:09:46.630149 13319 master.cpp:1403] Filtered slave 201203302307-0-0 for framework 201203302307-0-0002 for 1 seconds
I0330 23:09:47.630151 13319 master.cpp:1184] Sending 1 offers to framework 201203302307-0-0001
I0330 23:09:47.631458 13319 master.cpp:679] Received reply for offer 201203302307-0-92
I0330 23:09:47.631600 13319 master.cpp:1403] Filtered slave 201203302307-0-0 for framework 201203302307-0-0001 for 1 seconds
I0330 23:09:48.631239 13319 master.cpp:1184] Sending 1 offers to framework 201203302307-0-0002
I0330 23:09:48.810055 13319 master.cpp:679] Received reply for offer 201203302307-0-93
I0330 23:09:48.810261 13319 master.cpp:1453] Launching task 0 on slave 201203302307-0-0
I0330 23:09:48.810590 13319 master.cpp:1453] Launching task 1 on slave 201203302307-0-0
I0330 23:09:48.810768 13319 master.cpp:1453] Launching task 2 on slave 201203302307-0-0
I0330 23:09:48.810928 13319 master.cpp:1453] Launching task 3 on slave 201203302307-0-0
I0330 23:09:48.811102 13319 master.cpp:1453] Launching task 4 on slave 201203302307-0-0
I0330 23:09:48.811259 13319 master.cpp:1453] Launching task 5 on slave 201203302307-0-0
I0330 23:09:48.811432 13319 master.cpp:1453] Launching task 6 on slave 201203302307-0-0
I0330 23:09:48.811591 13319 master.cpp:1453] Launching task 7 on slave 201203302307-0-0
I0330 23:09:50.665390 13319 master.cpp:902] Status update from slave@192.168.1.64:48930: task 15 of framework 201203302307-0-0000 is now in state TASK_FINISHED
I0330 23:09:50.665699 13319 master.cpp:1184] Sending 1 offers to framework 201203302307-0-0001
I0330 23:09:50.666800 13319 master.cpp:679] Received reply for offer 201203302307-0-94
I0330 23:09:50.666937 13319 master.cpp:1403] Filtered slave 201203302307-0-1 for framework 201203302307-0-0001 for 1 seconds
I0330 23:09:51.815469 13319 master.cpp:902] Status update from slave@192.168.1.66:38618: task 7 of framework 201203302307-0-0002 is now in state TASK_RUNNING
I0330 23:09:51.817109 13319 master.cpp:902] Status update from slave@192.168.1.66:38618: task 5 of framework 201203302307-0-0002 is now in state TASK_RUNNING
I0330 23:09:51.831604 13319 master.cpp:902] Status update from slave@192.168.1.66:38618: task 1 of framework 201203302307-0-0002 is now in state TASK_RUNNING
I0330 23:09:51.831759 13319 master.cpp:902] Status update from slave@192.168.1.66:38618: task 2 of framework 201203302307-0-0002 is now in state TASK_RUNNING
I0330 23:09:51.832053 13319 master.cpp:902] Status update from slave@192.168.1.66:38618: task 6 of framework 201203302307-0-0002 is now in state TASK_RUNNING
I0330 23:09:51.890681 13319 master.cpp:902] Status update from slave@192.168.1.66:38618: task 4 of framework 201203302307-0-0002 is now in state TASK_RUNNING
I0330 23:09:51.898808 13319 master.cpp:902] Status update from slave@192.168.1.66:38618: task 0 of framework 201203302307-0-0002 is now in state TASK_RUNNING
I0330 23:09:51.899019 13319 master.cpp:902] Status update from slave@192.168.1.66:38618: task 3 of framework 201203302307-0-0002 is now in state TASK_RUNNING
I0330 23:09:56.461873 13319 master.cpp:902] Status update from slave@192.168.1.66:38618: task 7 of framework 201203302307-0-0002 is now in state TASK_FAILED
I0330 23:09:56.462172 13319 master.cpp:1184] Sending 1 offers to framework 201203302307-0-0001
I0330 23:09:56.462313 13319 master.cpp:1184] Sending 1 offers to framework 201203302307-0-0002
I0330 23:09:56.462579 13319 master.cpp:902] Status update from slave@192.168.1.66:38618: task 4 of framework 201203302307-0-0002 is now in state TASK_FAILED
I0330 23:09:56.462833 13319 master.cpp:902] Status update from slave@192.168.1.66:38618: task 6 of framework 201203302307-0-0002 is now in state TASK_FAILED
I0330 23:09:56.463107 13319 master.cpp:902] Status update from slave@192.168.1.66:38618: task 2 of framework 201203302307-0-0002 is now in state TASK_FAILED
I0330 23:09:56.463358 13319 master.cpp:902] Status update from slave@192.168.1.66:38618: task 1 of framework 201203302307-0-0002 is now in state TASK_FAILED
I0330 23:09:56.463608 13319 master.cpp:902] Status update from slave@192.168.1.66:38618: task 3 of framework 201203302307-0-0002 is now in state TASK_FAILED
I0330 23:09:56.466028 13319 master.cpp:902] Status update from slave@192.168.1.66:38618: task 0 of framework 201203302307-0-0002 is now in state TASK_FAILED
I0330 23:09:56.466332 13319 master.cpp:902] Status update from slave@192.168.1.66:38618: task 5 of framework 201203302307-0-0002 is now in state TASK_FAILED
I0330 23:09:56.486562 13319 master.cpp:679] Received reply for offer 201203302307-0-95
I0330 23:09:56.486763 13319 master.cpp:1403] Filtered slave 201203302307-0-0 for framework 201203302307-0-0001 for 1 seconds
I0330 23:09:56.497935 13319 master.cpp:679] Received reply for offer 201203302307-0-96
I0330 23:09:56.498141 13319 master.cpp:1453] Launching task 8 on slave 201203302307-0-1
I0330 23:09:56.498445 13319 master.cpp:1184] Sending 1 offers to framework 201203302307-0-0002
I0330 23:09:56.516777 13319 master.cpp:679] Received reply for offer 201203302307-0-97
I0330 23:09:56.516962 13319 master.cpp:1403] Filtered slave 201203302307-0-0 for framework 201203302307-0-0002 for 1 seconds
I0330 23:09:57.639252 13319 master.cpp:1184] Sending 1 offers to framework 201203302307-0-0001
I0330 23:09:57.640522 13319 master.cpp:679] Received reply for offer 201203302307-0-98
I0330 23:09:57.640666 13319 master.cpp:1403] Filtered slave 201203302307-0-0 for framework 201203302307-0-0001 for 1 seconds
I0330 23:09:57.776058 13319 master.cpp:1001] Executor default of framework 201203302307-0-0002 on slave 201203302307-0-0 (ubuntu.gateway.2wire.net) exited with status 256
I0330 23:09:58.212584 13319 master.cpp:902] Status update from slave@192.168.1.64:48930: task 8 of framework 201203302307-0-0002 is now in state TASK_RUNNING
I0330 23:09:58.640365 13319 master.cpp:1184] Sending 1 offers to framework 201203302307-0-0002
I0330 23:09:58.641680 13319 master.cpp:679] Received reply for offer 201203302307-0-99
I0330 23:09:58.641820 13319 master.cpp:1403] Filtered slave 201203302307-0-0 for framework 201203302307-0-0002 for 1 seconds
I0330 23:09:59.358394 13319 master.cpp:902] Status update from slave@192.168.1.64:48930: task 14 of framework 201203302307-0-0000 is now in state TASK_FINISHED
I0330 23:09:59.358695 13319 master.cpp:1184] Sending 1 offers to framework 201203302307-0-0001
I0330 23:09:59.359802 13319 master.cpp:679] Received reply for offer 201203302307-0-100
I0330 23:09:59.359954 13319 master.cpp:1403] Filtered slave 201203302307-0-1 for framework 201203302307-0-0001 for 1 seconds
I0330 23:09:59.641211 13319 master.cpp:1184] Sending 1 offers to framework 201203302307-0-0001
I0330 23:09:59.641410 13319 master.cpp:1184] Sending 1 offers to framework 201203302307-0-0002
I0330 23:09:59.642526 13319 master.cpp:679] Received reply for offer 201203302307-0-101
I0330 23:09:59.642668 13319 master.cpp:1403] Filtered slave 201203302307-0-0 for framework 201203302307-0-0001 for 1 seconds
I0330 23:09:59.654425 13319 master.cpp:679] Received reply for offer 201203302307-0-102
I0330 23:09:59.654650 13319 master.cpp:1453] Launching task 9 on slave 201203302307-0-1
I0330 23:09:59.679646 13319 master.cpp:902] Status update from slave@192.168.1.64:48930: task 9 of framework 201203302307-0-0002 is now in state TASK_RUNNING
I0330 23:10:00.419740 13319 master.cpp:902] Status update from slave@192.168.1.64:48930: task 8 of framework 201203302307-0-0002 is now in state TASK_FAILED
I0330 23:10:00.420086 13319 master.cpp:1184] Sending 1 offers to framework 201203302307-0-0002
I0330 23:10:00.422711 13319 master.cpp:902] Status update from slave@192.168.1.64:48930: task 9 of framework 201203302307-0-0002 is now in state TASK_FAILED
I0330 23:10:00.447291 13319 master.cpp:679] Received reply for offer 201203302307-0-103
I0330 23:10:00.447470 13319 master.cpp:1453] Launching task 10 on slave 201203302307-0-1
I0330 23:10:00.458708 13319 master.cpp:902] Status update from slave@192.168.1.64:48930: task 10 of framework 201203302307-0-0002 is now in state TASK_RUNNING
I0330 23:10:00.642246 13319 master.cpp:1184] Sending 1 offers to framework 201203302307-0-0002
I0330 23:10:00.643694 13319 master.cpp:679] Received reply for offer 201203302307-0-104
I0330 23:10:00.643844 13319 master.cpp:1403] Filtered slave 201203302307-0-0 for framework 201203302307-0-0002 for 1 seconds
I0330 23:10:00.666000 13319 master.cpp:902] Status update from slave@192.168.1.64:48930: task 15 of framework 201203302307-0-0000 is now in state TASK_FINISHED
W0330 23:10:00.666230 13319 master.cpp:934] Status update from slave@192.168.1.64:48930: error, couldn't lookup task 15
I0330 23:10:01.577716 13319 master.cpp:1001] Executor default of framework 201203302307-0-0002 on slave 201203302307-0-1 (azad.gateway.2wire.net) exited with status 256
I0330 23:10:01.579301 13319 master.cpp:1033] Removing task 10 of framework 201203302307-0-0002 because of lost executor
I0330 23:10:01.630298 13319 master.cpp:1184] Sending 1 offers to framework 201203302307-0-0001
I0330 23:10:01.631620 13319 master.cpp:679] Received reply for offer 201203302307-0-105
I0330 23:10:01.631796 13319 master.cpp:1403] Filtered slave 201203302307-0-1 for framework 201203302307-0-0001 for 1 seconds
I0330 23:10:01.642772 13319 master.cpp:1184] Sending 1 offers to framework 201203302307-0-0001
I0330 23:10:01.642941 13319 master.cpp:1184] Sending 1 offers to framework 201203302307-0-0002
I0330 23:10:01.643702 13319 master.cpp:679] Received reply for offer 201203302307-0-106
I0330 23:10:01.643865 13319 master.cpp:1403] Filtered slave 201203302307-0-0 for framework 201203302307-0-0001 for 1 seconds
I0330 23:10:01.660523 13319 master.cpp:679] Received reply for offer 201203302307-0-107
I0330 23:10:01.660735 13319 master.cpp:1453] Launching task 11 on slave 201203302307-0-1
I0330 23:10:01.660928 13319 master.cpp:1453] Launching task 12 on slave 201203302307-0-1
I0330 23:10:02.248740 13319 master.cpp:902] Status update from slave@192.168.1.64:48930: task 12 of framework 201203302307-0-0000 is now in state TASK_FINISHED
I0330 23:10:02.249070 13319 master.cpp:1184] Sending 1 offers to framework 201203302307-0-0002
I0330 23:10:02.256777 13319 master.cpp:679] Received reply for offer 201203302307-0-108
I0330 23:10:02.256922 13319 master.cpp:1453] Launching task 13 on slave 201203302307-0-1
I0330 23:10:02.643669 13319 master.cpp:1184] Sending 1 offers to framework 201203302307-0-0002
I0330 23:10:02.645131 13319 master.cpp:679] Received reply for offer 201203302307-0-109
I0330 23:10:02.645273 13319 master.cpp:1403] Filtered slave 201203302307-0-0 for framework 201203302307-0-0002 for 1 seconds
I0330 23:10:02.993455 13319 master.cpp:902] Status update from slave@192.168.1.64:48930: task 8 of framework 201203302307-0-0000 is now in state TASK_FINISHED
I0330 23:10:02.993760 13319 master.cpp:1184] Sending 1 offers to framework 201203302307-0-0001
I0330 23:10:02.995022 13319 master.cpp:679] Received reply for offer 201203302307-0-110
I0330 23:10:02.995175 13319 master.cpp:1403] Filtered slave 201203302307-0-1 for framework 201203302307-0-0001 for 1 seconds
I0330 23:10:03.198606 13319 master.cpp:902] Status update from slave@192.168.1.64:48930: task 13 of framework 201203302307-0-0002 is now in state TASK_RUNNING
I0330 23:10:03.200544 13319 master.cpp:902] Status update from slave@192.168.1.64:48930: task 12 of framework 201203302307-0-0002 is now in state TASK_RUNNING
I0330 23:10:03.203057 13319 master.cpp:902] Status update from slave@192.168.1.64:48930: task 11 of framework 201203302307-0-0002 is now in state TASK_RUNNING
I0330 23:10:03.246908 13319 master.cpp:902] Status update from slave@192.168.1.64:48930: task 13 of framework 201203302307-0-0000 is now in state TASK_FINISHED
I0330 23:10:03.247257 13319 master.cpp:1184] Sending 1 offers to framework 201203302307-0-0002
I0330 23:10:03.266834 13319 master.cpp:679] Received reply for offer 201203302307-0-111
I0330 23:10:03.267009 13319 master.cpp:1453] Launching task 14 on slave 201203302307-0-1
I0330 23:10:03.267348 13319 master.cpp:1453] Launching task 15 on slave 201203302307-0-1
I0330 23:10:03.273669 13319 master.cpp:902] Status update from slave@192.168.1.64:48930: task 14 of framework 201203302307-0-0002 is now in state TASK_RUNNING
I0330 23:10:03.276922 13319 master.cpp:902] Status update from slave@192.168.1.64:48930: task 15 of framework 201203302307-0-0002 is now in state TASK_RUNNING
I0330 23:10:03.644634 13319 master.cpp:1184] Sending 1 offers to framework 201203302307-0-0001
I0330 23:10:03.645792 13319 master.cpp:679] Received reply for offer 201203302307-0-112
I0330 23:10:03.645913 13319 master.cpp:1403] Filtered slave 201203302307-0-0 for framework 201203302307-0-0001 for 1 seconds
I0330 23:10:04.646952 13319 master.cpp:1184] Sending 1 offers to framework 201203302307-0-0002
I0330 23:10:04.648298 13319 master.cpp:679] Received reply for offer 201203302307-0-113
I0330 23:10:04.648439 13319 master.cpp:1403] Filtered slave 201203302307-0-0 for framework 201203302307-0-0002 for 1 seconds
I0330 23:10:05.648429 13319 master.cpp:1184] Sending 1 offers to framework 201203302307-0-0001
I0330 23:10:05.649616 13319 master.cpp:679] Received reply for offer 201203302307-0-114
I0330 23:10:05.649754 13319 master.cpp:1403] Filtered slave 201203302307-0-0 for framework 201203302307-0-0001 for 1 seconds
I0330 23:10:06.015048 13319 master.cpp:902] Status update from slave@192.168.1.64:48930: task 13 of framework 201203302307-0-0002 is now in state TASK_FAILED
I0330 23:10:06.015352 13319 master.cpp:1184] Sending 1 offers to framework 201203302307-0-0001
I0330 23:10:06.016382 13319 master.cpp:902] Status update from slave@192.168.1.64:48930: task 12 of framework 201203302307-0-0002 is now in state TASK_FAILED
I0330 23:10:06.020194 13319 master.cpp:679] Received reply for offer 201203302307-0-115
I0330 23:10:06.020370 13319 master.cpp:1403] Filtered slave 201203302307-0-1 for framework 201203302307-0-0001 for 1 seconds
I0330 23:10:06.023800 13319 master.cpp:902] Status update from slave@192.168.1.64:48930: task 14 of framework 201203302307-0-0002 is now in state TASK_FAILED
I0330 23:10:06.024036 13319 master.cpp:1184] Sending 1 offers to framework 201203302307-0-0002
I0330 23:10:06.026634 13319 master.cpp:902] Status update from slave@192.168.1.64:48930: task 11 of framework 201203302307-0-0002 is now in state TASK_FAILED
I0330 23:10:06.051270 13319 master.cpp:679] Received reply for offer 201203302307-0-116
I0330 23:10:06.051450 13319 master.cpp:1453] Launching task 16 on slave 201203302307-0-1
I0330 23:10:06.051729 13319 master.cpp:1453] Launching task 17 on slave 201203302307-0-1
I0330 23:10:06.052113 13319 master.cpp:1453] Launching task 18 on slave 201203302307-0-1
I0330 23:10:06.450270 13319 master.cpp:902] Status update from slave@192.168.1.64:48930: task 10 of framework 201203302307-0-0000 is now in state TASK_FINISHED
I0330 23:10:06.450556 13319 master.cpp:1184] Sending 1 offers to framework 201203302307-0-0002
I0330 23:10:06.457948 13319 master.cpp:679] Received reply for offer 201203302307-0-117
I0330 23:10:06.458070 13319 master.cpp:1453] Launching task 19 on slave 201203302307-0-1
I0330 23:10:06.458256 13319 master.cpp:1453] Launching task 20 on slave 201203302307-0-1
I0330 23:10:06.582141 13319 master.cpp:1001] Executor default of framework 201203302307-0-0002 on slave 201203302307-0-1 (azad.gateway.2wire.net) exited with status 256
I0330 23:10:06.583103 13319 master.cpp:1033] Removing task 19 of framework 201203302307-0-0002 because of lost executor
I0330 23:10:06.617210 13319 master.cpp:1184] Sending 1 offers to framework 201203302307-0-0002
I0330 23:10:06.638597 13319 master.cpp:1033] Removing task 20 of framework 201203302307-0-0002 because of lost executor
I0330 23:10:06.639932 13319 master.cpp:1033] Removing task 17 of framework 201203302307-0-0002 because of lost executor
I0330 23:10:06.641062 13319 master.cpp:1033] Removing task 18 of framework 201203302307-0-0002 because of lost executor
I0330 23:10:06.642187 13319 master.cpp:1033] Removing task 15 of framework 201203302307-0-0002 because of lost executor
I0330 23:10:06.643337 13319 master.cpp:1033] Removing task 16 of framework 201203302307-0-0002 because of lost executor
I0330 23:10:06.643514 13319 master.cpp:679] Received reply for offer 201203302307-0-118
I0330 23:10:06.643722 13319 master.cpp:1403] Filtered slave 201203302307-0-1 for framework 201203302307-0-0002 for 1 seconds
I0330 23:10:06.649570 13319 master.cpp:1184] Sending 1 offers to framework 201203302307-0-0002
I0330 23:10:06.650353 13319 master.cpp:679] Received reply for offer 201203302307-0-119
I0330 23:10:06.650477 13319 master.cpp:1403] Filtered slave 201203302307-0-0 for framework 201203302307-0-0002 for 1 seconds
I0330 23:10:07.651530 13319 master.cpp:1184] Sending 2 offers to framework 201203302307-0-0001
I0330 23:10:07.652760 13319 master.cpp:679] Received reply for offer 201203302307-0-120
I0330 23:10:07.652904 13319 master.cpp:1403] Filtered slave 201203302307-0-0 for framework 201203302307-0-0001 for 1 seconds
I0330 23:10:07.653152 13319 master.cpp:679] Received reply for offer 201203302307-0-121
I0330 23:10:07.653328 13319 master.cpp:1184] Sending 1 offers to framework 201203302307-0-0002
I0330 23:10:07.653501 13319 master.cpp:1403] Filtered slave 201203302307-0-1 for framework 201203302307-0-0001 for 1 seconds
I0330 23:10:07.654306 13319 master.cpp:679] Received reply for offer 201203302307-0-122
I0330 23:10:07.654495 13319 master.cpp:1184] Sending 1 offers to framework 201203302307-0-0002
I0330 23:10:07.654685 13319 master.cpp:1403] Filtered slave 201203302307-0-0 for framework 201203302307-0-0002 for 1 seconds
I0330 23:10:07.655511 13319 master.cpp:679] Received reply for offer 201203302307-0-123
I0330 23:10:07.655679 13319 master.cpp:1403] Filtered slave 201203302307-0-1 for framework 201203302307-0-0002 for 1 seconds
I0330 23:10:08.653642 13319 master.cpp:1184] Sending 1 offers to framework 201203302307-0-0001
I0330 23:10:08.655097 13319 master.cpp:679] Received reply for offer 201203302307-0-124
I0330 23:10:08.655252 13319 master.cpp:1403] Filtered slave 201203302307-0-0 for framework 201203302307-0-0001 for 1 seconds
I0330 23:10:09.359750 13319 master.cpp:902] Status update from slave@192.168.1.64:48930: task 14 of framework 201203302307-0-0000 is now in state TASK_FINISHED
W0330 23:10:09.360121 13319 master.cpp:934] Status update from slave@192.168.1.64:48930: error, couldn't lookup task 14
I0330 23:10:09.431195 13319 master.cpp:902] Status update from slave@192.168.1.64:48930: task 9 of framework 201203302307-0-0000 is now in state TASK_FINISHED
I0330 23:10:09.654801 13319 master.cpp:1184] Sending 1 offers to framework 201203302307-0-0001
I0330 23:10:09.654979 13319 master.cpp:1184] Sending 1 offers to framework 201203302307-0-0002
I0330 23:10:09.656111 13319 master.cpp:679] Received reply for offer 201203302307-0-125
I0330 23:10:09.656276 13319 master.cpp:1403] Filtered slave 201203302307-0-1 for framework 201203302307-0-0001 for 1 seconds
I0330 23:10:09.656864 13319 master.cpp:679] Received reply for offer 201203302307-0-126
I0330 23:10:09.657001 13319 master.cpp:1403] Filtered slave 201203302307-0-0 for framework 201203302307-0-0002 for 1 seconds
I0330 23:10:09.962770 13319 master.cpp:902] Status update from slave@192.168.1.64:48930: task 11 of framework 201203302307-0-0000 is now in state TASK_FINISHED
I0330 23:10:09.963184 13319 master.cpp:1184] Sending 1 offers to framework 201203302307-0-0002
I0330 23:10:09.964476 13319 master.cpp:679] Received reply for offer 201203302307-0-127
I0330 23:10:09.964602 13319 master.cpp:1403] Filtered slave 201203302307-0-1 for framework 201203302307-0-0002 for 1 seconds
I0330 23:10:10.656718 13319 master.cpp:1184] Sending 2 offers to framework 201203302307-0-0001
I0330 23:10:10.658382 13319 master.cpp:679] Received reply for offer 201203302307-0-128
I0330 23:10:10.658522 13319 master.cpp:1403] Filtered slave 201203302307-0-0 for framework 201203302307-0-0001 for 1 seconds
I0330 23:10:10.658884 13319 master.cpp:679] Received reply for offer 201203302307-0-129
I0330 23:10:10.659009 13319 master.cpp:1403] Filtered slave 201203302307-0-1 for framework 201203302307-0-0001 for 1 seconds
I0330 23:10:11.659066 13319 master.cpp:1184] Sending 2 offers to framework 201203302307-0-0002
I0330 23:10:11.660712 13319 master.cpp:679] Received reply for offer 201203302307-0-130
I0330 23:10:11.660799 13319 master.cpp:1403] Filtered slave 201203302307-0-0 for framework 201203302307-0-0002 for 1 seconds
I0330 23:10:11.678741 13319 master.cpp:679] Received reply for offer 201203302307-0-131
I0330 23:10:11.698963 13319 master.cpp:1184] Sending 1 offers to framework 201203302307-0-0001
I0330 23:10:11.699246 13319 master.cpp:1403] Filtered slave 201203302307-0-1 for framework 201203302307-0-0002 for 1 seconds
I0330 23:10:11.700017 13319 master.cpp:679] Received reply for offer 201203302307-0-132
I0330 23:10:11.700178 13319 master.cpp:1403] Filtered slave 201203302307-0-0 for framework 201203302307-0-0001 for 1 seconds
I0330 23:10:12.250754 13319 master.cpp:902] Status update from slave@192.168.1.64:48930: task 12 of framework 201203302307-0-0000 is now in state TASK_FINISHED
W0330 23:10:12.250993 13319 master.cpp:934] Status update from slave@192.168.1.64:48930: error, couldn't lookup task 12
I0330 23:10:12.994768 13319 master.cpp:902] Status update from slave@192.168.1.64:48930: task 8 of framework 201203302307-0-0000 is now in state TASK_FINISHED
W0330 23:10:12.994941 13319 master.cpp:934] Status update from slave@192.168.1.64:48930: error, couldn't lookup task 8
I0330 23:10:13.247673 13319 master.cpp:902] Status update from slave@192.168.1.64:48930: task 13 of framework 201203302307-0-0000 is now in state TASK_FINISHED
W0330 23:10:13.247879 13319 master.cpp:934] Status update from slave@192.168.1.64:48930: error, couldn't lookup task 13
I0330 23:10:13.661416 13319 master.cpp:1184] Sending 1 offers to framework 201203302307-0-0002
I0330 23:10:13.662586 13319 master.cpp:679] Received reply for offer 201203302307-0-133
I0330 23:10:13.662729 13319 master.cpp:1403] Filtered slave 201203302307-0-0 for framework 201203302307-0-0002 for 1 seconds
I0330 23:10:14.663749 13319 master.cpp:1184] Sending 2 offers to framework 201203302307-0-0001
I0330 23:10:14.665099 13319 master.cpp:679] Received reply for offer 201203302307-0-134
I0330 23:10:14.665241 13319 master.cpp:1403] Filtered slave 201203302307-0-0 for framework 201203302307-0-0001 for 1 seconds
I0330 23:10:14.665627 13319 master.cpp:679] Received reply for offer 201203302307-0-135
I0330 23:10:14.665778 13319 master.cpp:1184] Sending 1 offers to framework 201203302307-0-0002
I0330 23:10:14.665940 13319 master.cpp:1403] Filtered slave 201203302307-0-1 for framework 201203302307-0-0001 for 1 seconds
I0330 23:10:14.666834 13319 master.cpp:679] Received reply for offer 201203302307-0-136
I0330 23:10:14.666996 13319 master.cpp:1184] Sending 1 offers to framework 201203302307-0-0002
I0330 23:10:14.667163 13319 master.cpp:1403] Filtered slave 201203302307-0-0 for framework 201203302307-0-0002 for 1 seconds
I0330 23:10:14.667888 13319 master.cpp:679] Received reply for offer 201203302307-0-137
I0330 23:10:14.668027 13319 master.cpp:1403] Filtered slave 201203302307-0-1 for framework 201203302307-0-0002 for 1 seconds
I0330 23:10:15.666023 13319 master.cpp:1184] Sending 1 offers to framework 201203302307-0-0001
I0330 23:10:15.667356 13319 master.cpp:679] Received reply for offer 201203302307-0-138
I0330 23:10:15.667502 13319 master.cpp:1403] Filtered slave 201203302307-0-0 for framework 201203302307-0-0001 for 1 seconds
I0330 23:10:16.451757 13319 master.cpp:902] Status update from slave@192.168.1.64:48930: task 10 of framework 201203302307-0-0000 is now in state TASK_FINISHED
W0330 23:10:16.451967 13319 master.cpp:934] Status update from slave@192.168.1.64:48930: error, couldn't lookup task 10
I0330 23:10:16.667309 13319 master.cpp:1184] Sending 1 offers to framework 201203302307-0-0002
I0330 23:10:16.668560 13319 master.cpp:679] Received reply for offer 201203302307-0-139
I0330 23:10:16.668637 13319 master.cpp:1403] Filtered slave 201203302307-0-0 for framework 201203302307-0-0002 for 1 seconds
I0330 23:10:17.668757 13319 master.cpp:1184] Sending 2 offers to framework 201203302307-0-0001
I0330 23:10:17.670325 13319 master.cpp:679] Received reply for offer 201203302307-0-140
I0330 23:10:17.670444 13319 master.cpp:1403] Filtered slave 201203302307-0-0 for framework 201203302307-0-0001 for 1 seconds
I0330 23:10:17.670804 13319 master.cpp:679] Received reply for offer 201203302307-0-141
I0330 23:10:17.670914 13319 master.cpp:1403] Filtered slave 201203302307-0-1 for framework 201203302307-0-0001 for 1 seconds
I0330 23:10:18.670608 13319 master.cpp:1184] Sending 2 offers to framework 201203302307-0-0002
I0330 23:10:18.672165 13319 master.cpp:679] Received reply for offer 201203302307-0-142
I0330 23:10:18.672288 13319 master.cpp:1403] Filtered slave 201203302307-0-0 for framework 201203302307-0-0002 for 1 seconds
I0330 23:10:18.672616 13319 master.cpp:679] Received reply for offer 201203302307-0-143
I0330 23:10:18.672814 13319 master.cpp:1403] Filtered slave 201203302307-0-1 for framework 201203302307-0-0002 for 1 seconds
I0330 23:10:19.432271 13319 master.cpp:902] Status update from slave@192.168.1.64:48930: task 9 of framework 201203302307-0-0000 is now in state TASK_FINISHED
W0330 23:10:19.432461 13319 master.cpp:934] Status update from slave@192.168.1.64:48930: error, couldn't lookup task 9
I0330 23:10:19.671962 13319 master.cpp:1184] Sending 2 offers to framework 201203302307-0-0001
I0330 23:10:19.673456 13319 master.cpp:679] Received reply for offer 201203302307-0-144
I0330 23:10:19.673585 13319 master.cpp:1403] Filtered slave 201203302307-0-0 for framework 201203302307-0-0001 for 1 seconds
I0330 23:10:19.673830 13319 master.cpp:679] Received reply for offer 201203302307-0-145
I0330 23:10:19.673962 13319 master.cpp:1403] Filtered slave 201203302307-0-1 for framework 201203302307-0-0001 for 1 seconds
I0330 23:10:19.964429 13319 master.cpp:902] Status update from slave@192.168.1.64:48930: task 11 of framework 201203302307-0-0000 is now in state TASK_FINISHED
W0330 23:10:19.964586 13319 master.cpp:934] Status update from slave@192.168.1.64:48930: error, couldn't lookup task 11
I0330 23:10:20.673493 13319 master.cpp:1184] Sending 2 offers to framework 201203302307-0-0002
I0330 23:10:20.674789 13319 master.cpp:679] Received reply for offer 201203302307-0-146
I0330 23:10:20.674932 13319 master.cpp:1403] Filtered slave 201203302307-0-0 for framework 201203302307-0-0002 for 1 seconds
I0330 23:10:20.675207 13319 master.cpp:679] Received reply for offer 201203302307-0-147
I0330 23:10:20.675364 13319 master.cpp:1403] Filtered slave 201203302307-0-1 for framework 201203302307-0-0002 for 1 seconds
I0330 23:10:21.675184 13319 master.cpp:1184] Sending 2 offers to framework 201203302307-0-0001
I0330 23:10:21.676524 13319 master.cpp:679] Received reply for offer 201203302307-0-148
I0330 23:10:21.676616 13319 master.cpp:1403] Filtered slave 201203302307-0-0 for framework 201203302307-0-0001 for 1 seconds
I0330 23:10:21.693979 13319 master.cpp:679] Received reply for offer 201203302307-0-149
I0330 23:10:21.715854 13319 master.cpp:1403] Filtered slave 201203302307-0-1 for framework 201203302307-0-0001 for 1 seconds
I0330 23:10:22.677463 13319 master.cpp:1184] Sending 2 offers to framework 201203302307-0-0002
I0330 23:10:22.678810 13319 master.cpp:679] Received reply for offer 201203302307-0-150
I0330 23:10:22.678952 13319 master.cpp:1403] Filtered slave 201203302307-0-0 for framework 201203302307-0-0002 for 1 seconds
I0330 23:10:22.679229 13319 master.cpp:679] Received reply for offer 201203302307-0-151
I0330 23:10:22.679386 13319 master.cpp:1403] Filtered slave 201203302307-0-1 for framework 201203302307-0-0002 for 1 seconds
I0330 23:10:23.680106 13319 master.cpp:1184] Sending 2 offers to framework 201203302307-0-0001
I0330 23:10:23.681404 13319 master.cpp:679] Received reply for offer 201203302307-0-152
I0330 23:10:23.681686 13319 master.cpp:1403] Filtered slave 201203302307-0-0 for framework 201203302307-0-0001 for 1 seconds
I0330 23:10:23.681826 13319 master.cpp:679] Received reply for offer 201203302307-0-153
I0330 23:10:23.681998 13319 master.cpp:1184] Sending 1 offers to framework 201203302307-0-0002
I0330 23:10:23.682106 13319 master.cpp:1403] Filtered slave 201203302307-0-1 for framework 201203302307-0-0001 for 1 seconds
I0330 23:10:23.682840 13319 master.cpp:679] Received reply for offer 201203302307-0-154
I0330 23:10:23.683035 13319 master.cpp:1184] Sending 1 offers to framework 201203302307-0-0002
I0330 23:10:23.683186 13319 master.cpp:1403] Filtered slave 201203302307-0-0 for framework 201203302307-0-0002 for 1 seconds
I0330 23:10:23.683833 13319 master.cpp:679] Received reply for offer 201203302307-0-155
I0330 23:10:23.684006 13319 master.cpp:1403] Filtered slave 201203302307-0-1 for framework 201203302307-0-0002 for 1 seconds
I0330 23:10:25.682526 13319 master.cpp:1184] Sending 2 offers to framework 201203302307-0-0001
I0330 23:10:25.683768 13319 master.cpp:679] Received reply for offer 201203302307-0-156
I0330 23:10:25.683894 13319 master.cpp:1403] Filtered slave 201203302307-0-0 for framework 201203302307-0-0001 for 1 seconds
I0330 23:10:25.684131 13319 master.cpp:679] Received reply for offer 201203302307-0-157
I0330 23:10:25.684329 13319 master.cpp:1184] Sending 1 offers to framework 201203302307-0-0002
I0330 23:10:25.684435 13319 master.cpp:1403] Filtered slave 201203302307-0-1 for framework 201203302307-0-0001 for 1 seconds
I0330 23:10:25.685009 13319 master.cpp:679] Received reply for offer 201203302307-0-158
I0330 23:10:25.685147 13319 master.cpp:1184] Sending 1 offers to framework 201203302307-0-0002
I0330 23:10:25.685245 13319 master.cpp:1403] Filtered slave 201203302307-0-0 for framework 201203302307-0-0002 for 1 seconds
I0330 23:10:25.685943 13319 master.cpp:679] Received reply for offer 201203302307-0-159
I0330 23:10:25.686069 13319 master.cpp:1403] Filtered slave 201203302307-0-1 for framework 201203302307-0-0002 for 1 seconds
I0330 23:10:27.685508 13319 master.cpp:1184] Sending 2 offers to framework 201203302307-0-0001
I0330 23:10:27.686722 13319 master.cpp:679] Received reply for offer 201203302307-0-160
I0330 23:10:27.686846 13319 master.cpp:1403] Filtered slave 201203302307-0-0 for framework 201203302307-0-0001 for 1 seconds
I0330 23:10:27.687093 13319 master.cpp:679] Received reply for offer 201203302307-0-161
I0330 23:10:27.687242 13319 master.cpp:1184] Sending 1 offers to framework 201203302307-0-0002
I0330 23:10:27.687340 13319 master.cpp:1403] Filtered slave 201203302307-0-1 for framework 201203302307-0-0001 for 1 seconds
I0330 23:10:27.687957 13319 master.cpp:679] Received reply for offer 201203302307-0-162
I0330 23:10:27.688133 13319 master.cpp:1184] Sending 1 offers to framework 201203302307-0-0002
I0330 23:10:27.688247 13319 master.cpp:1403] Filtered slave 201203302307-0-0 for framework 201203302307-0-0002 for 1 seconds
I0330 23:10:27.688895 13319 master.cpp:679] Received reply for offer 201203302307-0-163
I0330 23:10:27.689034 13319 master.cpp:1403] Filtered slave 201203302307-0-1 for framework 201203302307-0-0002 for 1 seconds
I0330 23:10:29.688578 13319 master.cpp:1184] Sending 2 offers to framework 201203302307-0-0001
I0330 23:10:29.689826 13319 master.cpp:679] Received reply for offer 201203302307-0-164
I0330 23:10:29.689967 13319 master.cpp:1403] Filtered slave 201203302307-0-0 for framework 201203302307-0-0001 for 1 seconds
I0330 23:10:29.690320 13319 master.cpp:679] Received reply for offer 201203302307-0-165
I0330 23:10:29.690933 13319 master.cpp:1184] Sending 1 offers to framework 201203302307-0-0002
I0330 23:10:29.691071 13319 master.cpp:1403] Filtered slave 201203302307-0-1 for framework 201203302307-0-0001 for 1 seconds
I0330 23:10:29.691719 13319 master.cpp:679] Received reply for offer 201203302307-0-166
I0330 23:10:29.691922 13319 master.cpp:1184] Sending 1 offers to framework 201203302307-0-0002
I0330 23:10:29.692031 13319 master.cpp:1403] Filtered slave 201203302307-0-0 for framework 201203302307-0-0002 for 1 seconds
I0330 23:10:29.692682 13319 master.cpp:679] Received reply for offer 201203302307-0-167
I0330 23:10:29.692808 13319 master.cpp:1403] Filtered slave 201203302307-0-1 for framework 201203302307-0-0002 for 1 seconds
I0330 23:10:30.690840 13319 master.cpp:1184] Sending 1 offers to framework 201203302307-0-0001
I0330 23:10:30.691925 13319 master.cpp:679] Received reply for offer 201203302307-0-168
I0330 23:10:30.692052 13319 master.cpp:1403] Filtered slave 201203302307-0-0 for framework 201203302307-0-0001 for 1 seconds
I0330 23:10:31.693065 13319 master.cpp:1184] Sending 1 offers to framework 201203302307-0-0002
I0330 23:10:31.694110 13319 master.cpp:679] Received reply for offer 201203302307-0-169
I0330 23:10:31.694236 13319 master.cpp:1403] Filtered slave 201203302307-0-0 for framework 201203302307-0-0002 for 1 seconds
I0330 23:10:32.695301 13319 master.cpp:1184] Sending 2 offers to framework 201203302307-0-0001
I0330 23:10:32.696532 13319 master.cpp:679] Received reply for offer 201203302307-0-170
I0330 23:10:32.696655 13319 master.cpp:1403] Filtered slave 201203302307-0-0 for framework 201203302307-0-0001 for 1 seconds
I0330 23:10:32.696892 13319 master.cpp:679] Received reply for offer 201203302307-0-171
I0330 23:10:32.697017 13319 master.cpp:1184] Sending 1 offers to framework 201203302307-0-0002
I0330 23:10:32.697113 13319 master.cpp:1403] Filtered slave 201203302307-0-1 for framework 201203302307-0-0001 for 1 seconds
I0330 23:10:32.697787 13319 master.cpp:679] Received reply for offer 201203302307-0-172
I0330 23:10:32.697933 13319 master.cpp:1184] Sending 1 offers to framework 201203302307-0-0002
I0330 23:10:32.698037 13319 master.cpp:1403] Filtered slave 201203302307-0-0 for framework 201203302307-0-0002 for 1 seconds
I0330 23:10:32.698708 13319 master.cpp:679] Received reply for offer 201203302307-0-173
I0330 23:10:32.698839 13319 master.cpp:1403] Filtered slave 201203302307-0-1 for framework 201203302307-0-0002 for 1 seconds
I0330 23:10:34.697783 13319 master.cpp:1184] Sending 2 offers to framework 201203302307-0-0001
I0330 23:10:34.699044 13319 master.cpp:679] Received reply for offer 201203302307-0-174
I0330 23:10:34.699213 13319 master.cpp:1403] Filtered slave 201203302307-0-0 for framework 201203302307-0-0001 for 1 seconds
I0330 23:10:34.699445 13319 master.cpp:679] Received reply for offer 201203302307-0-175
I0330 23:10:34.699625 13319 master.cpp:1184] Sending 1 offers to framework 201203302307-0-0002
I0330 23:10:34.699771 13319 master.cpp:1403] Filtered slave 201203302307-0-1 for framework 201203302307-0-0001 for 1 seconds
I0330 23:10:34.700467 13319 master.cpp:679] Received reply for offer 201203302307-0-176
I0330 23:10:34.700666 13319 master.cpp:1184] Sending 1 offers to framework 201203302307-0-0002
I0330 23:10:34.700774 13319 master.cpp:1403] Filtered slave 201203302307-0-0 for framework 201203302307-0-0002 for 1 seconds
I0330 23:10:34.701427 13319 master.cpp:679] Received reply for offer 201203302307-0-177
I0330 23:10:34.701588 13319 master.cpp:1403] Filtered slave 201203302307-0-1 for framework 201203302307-0-0002 for 1 seconds
I0330 23:10:36.700784 13319 master.cpp:1184] Sending 2 offers to framework 201203302307-0-0001
I0330 23:10:36.702142 13319 master.cpp:679] Received reply for offer 201203302307-0-178
I0330 23:10:36.702285 13319 master.cpp:1403] Filtered slave 201203302307-0-0 for framework 201203302307-0-0001 for 1 seconds
I0330 23:10:36.702561 13319 master.cpp:679] Received reply for offer 201203302307-0-179
I0330 23:10:36.703022 13319 master.cpp:1184] Sending 1 offers to framework 201203302307-0-0002
I0330 23:10:36.703352 13319 master.cpp:1403] Filtered slave 201203302307-0-1 for framework 201203302307-0-0001 for 1 seconds
I0330 23:10:36.704087 13319 master.cpp:679] Received reply for offer 201203302307-0-180
I0330 23:10:36.704277 13319 master.cpp:1184] Sending 1 offers to framework 201203302307-0-0002
I0330 23:10:36.704421 13319 master.cpp:1403] Filtered slave 201203302307-0-0 for framework 201203302307-0-0002 for 1 seconds
I0330 23:10:36.705147 13319 master.cpp:679] Received reply for offer 201203302307-0-181
I0330 23:10:36.705296 13319 master.cpp:1403] Filtered slave 201203302307-0-1 for framework 201203302307-0-0002 for 1 seconds
I0330 23:10:38.703322 13319 master.cpp:1184] Sending 2 offers to framework 201203302307-0-0001
I0330 23:10:38.704850 13319 master.cpp:679] Received reply for offer 201203302307-0-182
I0330 23:10:38.705008 13319 master.cpp:1403] Filtered slave 201203302307-0-0 for framework 201203302307-0-0001 for 1 seconds
I0330 23:10:38.705255 13319 master.cpp:679] Received reply for offer 201203302307-0-183
I0330 23:10:38.705445 13319 master.cpp:1184] Sending 1 offers to framework 201203302307-0-0002
I0330 23:10:38.705698 13319 master.cpp:1403] Filtered slave 201203302307-0-1 for framework 201203302307-0-0001 for 1 seconds
I0330 23:10:38.706291 13319 master.cpp:679] Received reply for offer 201203302307-0-184
I0330 23:10:38.706485 13319 master.cpp:1184] Sending 1 offers to framework 201203302307-0-0002
I0330 23:10:38.706626 13319 master.cpp:1403] Filtered slave 201203302307-0-0 for framework 201203302307-0-0002 for 1 seconds
I0330 23:10:38.707294 13319 master.cpp:679] Received reply for offer 201203302307-0-185
I0330 23:10:38.707466 13319 master.cpp:1403] Filtered slave 201203302307-0-1 for framework 201203302307-0-0002 for 1 seconds
I0330 23:10:39.705550 13319 master.cpp:1184] Sending 1 offers to framework 201203302307-0-0001
I0330 23:10:39.706888 13319 master.cpp:679] Received reply for offer 201203302307-0-186
I0330 23:10:39.707042 13319 master.cpp:1403] Filtered slave 201203302307-0-0 for framework 201203302307-0-0001 for 1 seconds
I0330 23:10:40.707075 13319 master.cpp:1184] Sending 1 offers to framework 201203302307-0-0002
I0330 23:10:40.708225 13319 master.cpp:679] Received reply for offer 201203302307-0-187
I0330 23:10:40.708379 13319 master.cpp:1403] Filtered slave 201203302307-0-0 for framework 201203302307-0-0002 for 1 seconds
I0330 23:10:41.709429 13319 master.cpp:1184] Sending 2 offers to framework 201203302307-0-0001
I0330 23:10:41.710616 13319 master.cpp:679] Received reply for offer 201203302307-0-188
I0330 23:10:41.710775 13319 master.cpp:1403] Filtered slave 201203302307-0-0 for framework 201203302307-0-0001 for 1 seconds
I0330 23:10:41.710974 13319 master.cpp:679] Received reply for offer 201203302307-0-189
I0330 23:10:41.711117 13319 master.cpp:1184] Sending 1 offers to framework 201203302307-0-0002
I0330 23:10:41.711222 13319 master.cpp:1403] Filtered slave 201203302307-0-1 for framework 201203302307-0-0001 for 1 seconds
I0330 23:10:41.711864 13319 master.cpp:679] Received reply for offer 201203302307-0-190
I0330 23:10:41.712039 13319 master.cpp:1184] Sending 1 offers to framework 201203302307-0-0002
I0330 23:10:41.712147 13319 master.cpp:1403] Filtered slave 201203302307-0-0 for framework 201203302307-0-0002 for 1 seconds
I0330 23:10:41.712836 13319 master.cpp:679] Received reply for offer 201203302307-0-191
I0330 23:10:41.712973 13319 master.cpp:1403] Filtered slave 201203302307-0-1 for framework 201203302307-0-0002 for 1 seconds
I0330 23:10:43.712416 13319 master.cpp:1184] Sending 2 offers to framework 201203302307-0-0001
I0330 23:10:43.713759 13319 master.cpp:679] Received reply for offer 201203302307-0-192
I0330 23:10:43.713846 13319 master.cpp:1403] Filtered slave 201203302307-0-0 for framework 201203302307-0-0001 for 1 seconds
I0330 23:10:43.732790 13319 master.cpp:679] Received reply for offer 201203302307-0-193
I0330 23:10:43.756994 13319 master.cpp:1184] Sending 1 offers to framework 201203302307-0-0002
I0330 23:10:43.757248 13319 master.cpp:1403] Filtered slave 201203302307-0-1 for framework 201203302307-0-0001 for 1 seconds
I0330 23:10:43.757891 13319 master.cpp:679] Received reply for offer 201203302307-0-194
I0330 23:10:43.758055 13319 master.cpp:1184] Sending 1 offers to framework 201203302307-0-0002
I0330 23:10:43.758211 13319 master.cpp:1403] Filtered slave 201203302307-0-0 for framework 201203302307-0-0002 for 1 seconds
I0330 23:10:43.758901 13319 master.cpp:679] Received reply for offer 201203302307-0-195
I0330 23:10:43.759042 13319 master.cpp:1403] Filtered slave 201203302307-0-1 for framework 201203302307-0-0002 for 1 seconds
I0330 23:10:45.715476 13319 master.cpp:1184] Sending 2 offers to framework 201203302307-0-0001
I0330 23:10:45.716721 13319 master.cpp:679] Received reply for offer 201203302307-0-196
I0330 23:10:45.716862 13319 master.cpp:1403] Filtered slave 201203302307-0-0 for framework 201203302307-0-0001 for 1 seconds
I0330 23:10:45.717089 13319 master.cpp:679] Received reply for offer 201203302307-0-197
I0330 23:10:45.717244 13319 master.cpp:1184] Sending 1 offers to framework 201203302307-0-0002
I0330 23:10:45.717352 13319 master.cpp:1403] Filtered slave 201203302307-0-1 for framework 201203302307-0-0001 for 1 seconds
I0330 23:10:45.718013 13319 master.cpp:679] Received reply for offer 201203302307-0-198
I0330 23:10:45.718176 13319 master.cpp:1184] Sending 1 offers to framework 201203302307-0-0002
I0330 23:10:45.718287 13319 master.cpp:1403] Filtered slave 201203302307-0-0 for framework 201203302307-0-0002 for 1 seconds
I0330 23:10:45.718951 13319 master.cpp:679] Received reply for offer 201203302307-0-199
I0330 23:10:45.719104 13319 master.cpp:1403] Filtered slave 201203302307-0-1 for framework 201203302307-0-0002 for 1 seconds
I0330 23:10:46.717180 13319 master.cpp:1184] Sending 1 offers to framework 201203302307-0-0001
I0330 23:10:46.718240 13319 master.cpp:679] Received reply for offer 201203302307-0-200
I0330 23:10:46.718382 13319 master.cpp:1403] Filtered slave 201203302307-0-0 for framework 201203302307-0-0001 for 1 seconds
I0330 23:10:47.719379 13319 master.cpp:1184] Sending 1 offers to framework 201203302307-0-0002
I0330 23:10:47.720448 13319 master.cpp:679] Received reply for offer 201203302307-0-201
I0330 23:10:47.720592 13319 master.cpp:1403] Filtered slave 201203302307-0-0 for framework 201203302307-0-0002 for 1 seconds
I0330 23:10:48.721714 13319 master.cpp:1184] Sending 2 offers to framework 201203302307-0-0001
I0330 23:10:48.723124 13319 master.cpp:679] Received reply for offer 201203302307-0-202
I0330 23:10:48.723211 13319 master.cpp:1403] Filtered slave 201203302307-0-0 for framework 201203302307-0-0001 for 1 seconds
I0330 23:10:48.744690 13319 master.cpp:679] Received reply for offer 201203302307-0-203
I0330 23:10:48.768615 13319 master.cpp:1184] Sending 1 offers to framework 201203302307-0-0002
I0330 23:10:48.768867 13319 master.cpp:1403] Filtered slave 201203302307-0-1 for framework 201203302307-0-0001 for 1 seconds
I0330 23:10:48.769538 13319 master.cpp:679] Received reply for offer 201203302307-0-204
I0330 23:10:48.769703 13319 master.cpp:1184] Sending 1 offers to framework 201203302307-0-0002
I0330 23:10:48.769811 13319 master.cpp:1403] Filtered slave 201203302307-0-0 for framework 201203302307-0-0002 for 1 seconds
I0330 23:10:48.770481 13319 master.cpp:679] Received reply for offer 201203302307-0-205
I0330 23:10:48.770624 13319 master.cpp:1403] Filtered slave 201203302307-0-1 for framework 201203302307-0-0002 for 1 seconds
I0330 23:10:50.725111 13319 master.cpp:1184] Sending 2 offers to framework 201203302307-0-0001
I0330 23:10:50.726433 13319 master.cpp:679] Received reply for offer 201203302307-0-206
I0330 23:10:50.726575 13319 master.cpp:1403] Filtered slave 201203302307-0-0 for framework 201203302307-0-0001 for 1 seconds
I0330 23:10:50.726814 13319 master.cpp:679] Received reply for offer 201203302307-0-207
I0330 23:10:50.726973 13319 master.cpp:1184] Sending 1 offers to framework 201203302307-0-0002
I0330 23:10:50.727119 13319 master.cpp:1403] Filtered slave 201203302307-0-1 for framework 201203302307-0-0001 for 1 seconds
I0330 23:10:50.728014 13319 master.cpp:679] Received reply for offer 201203302307-0-208
I0330 23:10:50.728175 13319 master.cpp:1184] Sending 1 offers to framework 201203302307-0-0002
I0330 23:10:50.728335 13319 master.cpp:1403] Filtered slave 201203302307-0-0 for framework 201203302307-0-0002 for 1 seconds
I0330 23:10:50.729101 13319 master.cpp:679] Received reply for offer 201203302307-0-209
I0330 23:10:50.729243 13319 master.cpp:1403] Filtered slave 201203302307-0-1 for framework 201203302307-0-0002 for 1 seconds
I0330 23:10:51.727355 13319 master.cpp:1184] Sending 1 offers to framework 201203302307-0-0001
I0330 23:10:51.728647 13319 master.cpp:679] Received reply for offer 201203302307-0-210
I0330 23:10:51.728792 13319 master.cpp:1403] Filtered slave 201203302307-0-0 for framework 201203302307-0-0001 for 1 seconds
I0330 23:10:52.728914 13319 master.cpp:1184] Sending 1 offers to framework 201203302307-0-0002
I0330 23:10:52.730156 13319 master.cpp:679] Received reply for offer 201203302307-0-211
I0330 23:10:52.730299 13319 master.cpp:1403] Filtered slave 201203302307-0-0 for framework 201203302307-0-0002 for 1 seconds
I0330 23:10:53.731390 13319 master.cpp:1184] Sending 2 offers to framework 201203302307-0-0001
I0330 23:10:53.732723 13319 master.cpp:679] Received reply for offer 201203302307-0-212
I0330 23:10:53.732813 13319 master.cpp:1403] Filtered slave 201203302307-0-0 for framework 201203302307-0-0001 for 1 seconds
I0330 23:10:53.748167 13319 master.cpp:679] Received reply for offer 201203302307-0-213
I0330 23:10:53.771908 13319 master.cpp:1184] Sending 1 offers to framework 201203302307-0-0002
I0330 23:10:53.772338 13319 master.cpp:1403] Filtered slave 201203302307-0-1 for framework 201203302307-0-0001 for 1 seconds
I0330 23:10:53.773182 13319 master.cpp:679] Received reply for offer 201203302307-0-214
I0330 23:10:53.773365 13319 master.cpp:1184] Sending 1 offers to framework 201203302307-0-0002
I0330 23:10:53.773473 13319 master.cpp:1403] Filtered slave 201203302307-0-0 for framework 201203302307-0-0002 for 1 seconds
I0330 23:10:53.774449 13319 master.cpp:679] Received reply for offer 201203302307-0-215
I0330 23:10:53.774631 13319 master.cpp:1403] Filtered slave 201203302307-0-1 for framework 201203302307-0-0002 for 1 seconds
I0330 23:10:55.734336 13319 master.cpp:1184] Sending 2 offers to framework 201203302307-0-0001
I0330 23:10:55.735932 13319 master.cpp:679] Received reply for offer 201203302307-0-216
I0330 23:10:55.736099 13319 master.cpp:1403] Filtered slave 201203302307-0-0 for framework 201203302307-0-0001 for 1 seconds
I0330 23:10:55.736351 13319 master.cpp:679] Received reply for offer 201203302307-0-217
I0330 23:10:55.736542 13319 master.cpp:1184] Sending 1 offers to framework 201203302307-0-0002
I0330 23:10:55.736687 13319 master.cpp:1403] Filtered slave 201203302307-0-1 for framework 201203302307-0-0001 for 1 seconds
I0330 23:10:55.737686 13319 master.cpp:679] Received reply for offer 201203302307-0-218
I0330 23:10:55.737882 13319 master.cpp:1184] Sending 1 offers to framework 201203302307-0-0002
I0330 23:10:55.738062 13319 master.cpp:1403] Filtered slave 201203302307-0-0 for framework 201203302307-0-0002 for 1 seconds
I0330 23:10:55.738929 13319 master.cpp:679] Received reply for offer 201203302307-0-219
I0330 23:10:55.739105 13319 master.cpp:1403] Filtered slave 201203302307-0-1 for framework 201203302307-0-0002 for 1 seconds
I0330 23:10:57.737421 13319 master.cpp:1184] Sending 2 offers to framework 201203302307-0-0001
I0330 23:10:57.739071 13319 master.cpp:679] Received reply for offer 201203302307-0-220
I0330 23:10:57.739212 13319 master.cpp:1403] Filtered slave 201203302307-0-0 for framework 201203302307-0-0001 for 1 seconds
I0330 23:10:57.739516 13319 master.cpp:679] Received reply for offer 201203302307-0-221
I0330 23:10:57.739707 13319 master.cpp:1184] Sending 1 offers to framework 201203302307-0-0002
I0330 23:10:57.739982 13319 master.cpp:1403] Filtered slave 201203302307-0-1 for framework 201203302307-0-0001 for 1 seconds
I0330 23:10:57.740682 13319 master.cpp:679] Received reply for offer 201203302307-0-222
I0330 23:10:57.740864 13319 master.cpp:1184] Sending 1 offers to framework 201203302307-0-0002
I0330 23:10:57.741325 13319 master.cpp:1403] Filtered slave 201203302307-0-0 for framework 201203302307-0-0002 for 1 seconds
I0330 23:10:57.741984 13319 master.cpp:679] Received reply for offer 201203302307-0-223
I0330 23:10:57.742136 13319 master.cpp:1403] Filtered slave 201203302307-0-1 for framework 201203302307-0-0002 for 1 seconds
I0330 23:10:59.740159 13319 master.cpp:1184] Sending 2 offers to framework 201203302307-0-0001
I0330 23:10:59.741750 13319 master.cpp:679] Received reply for offer 201203302307-0-224
I0330 23:10:59.741919 13319 master.cpp:1403] Filtered slave 201203302307-0-0 for framework 201203302307-0-0001 for 1 seconds
I0330 23:10:59.742156 13319 master.cpp:679] Received reply for offer 201203302307-0-225
I0330 23:10:59.742395 13319 master.cpp:1184] Sending 1 offers to framework 201203302307-0-0002
I0330 23:10:59.742540 13319 master.cpp:1403] Filtered slave 201203302307-0-1 for framework 201203302307-0-0001 for 1 seconds
I0330 23:10:59.743459 13319 master.cpp:679] Received reply for offer 201203302307-0-226
I0330 23:10:59.743675 13319 master.cpp:1184] Sending 1 offers to framework 201203302307-0-0002
I0330 23:10:59.743818 13319 master.cpp:1403] Filtered slave 201203302307-0-0 for framework 201203302307-0-0002 for 1 seconds
I0330 23:10:59.744822 13319 master.cpp:679] Received reply for offer 201203302307-0-227
I0330 23:10:59.744994 13319 master.cpp:1403] Filtered slave 201203302307-0-1 for framework 201203302307-0-0002 for 1 seconds
I0330 23:11:01.743491 13319 master.cpp:1184] Sending 2 offers to framework 201203302307-0-0001
I0330 23:11:01.745157 13319 master.cpp:679] Received reply for offer 201203302307-0-228
I0330 23:11:01.745368 13319 master.cpp:1403] Filtered slave 201203302307-0-0 for framework 201203302307-0-0001 for 1 seconds
I0330 23:11:01.745568 13319 master.cpp:679] Received reply for offer 201203302307-0-229
I0330 23:11:01.745759 13319 master.cpp:1184] Sending 1 offers to framework 201203302307-0-0002
I0330 23:11:01.745915 13319 master.cpp:1403] Filtered slave 201203302307-0-1 for framework 201203302307-0-0001 for 1 seconds
I0330 23:11:01.746814 13319 master.cpp:679] Received reply for offer 201203302307-0-230
I0330 23:11:01.747007 13319 master.cpp:1184] Sending 1 offers to framework 201203302307-0-0002
I0330 23:11:01.747161 13319 master.cpp:1403] Filtered slave 201203302307-0-0 for framework 201203302307-0-0002 for 1 seconds
I0330 23:11:01.747978 13319 master.cpp:679] Received reply for offer 201203302307-0-231
I0330 23:11:01.748147 13319 master.cpp:1403] Filtered slave 201203302307-0-1 for framework 201203302307-0-0002 for 1 seconds
I0330 23:11:03.746677 13319 master.cpp:1184] Sending 2 offers to framework 201203302307-0-0001
I0330 23:11:03.748240 13319 master.cpp:679] Received reply for offer 201203302307-0-232
I0330 23:11:03.748364 13319 master.cpp:1403] Filtered slave 201203302307-0-0 for framework 201203302307-0-0001 for 1 seconds
I0330 23:11:03.748641 13319 master.cpp:679] Received reply for offer 201203302307-0-233
I0330 23:11:03.748819 13319 master.cpp:1184] Sending 1 offers to framework 201203302307-0-0002
I0330 23:11:03.748929 13319 master.cpp:1403] Filtered slave 201203302307-0-1 for framework 201203302307-0-0001 for 1 seconds
I0330 23:11:03.749780 13319 master.cpp:679] Received reply for offer 201203302307-0-234
I0330 23:11:03.750061 13319 master.cpp:1184] Sending 1 offers to framework 201203302307-0-0002
I0330 23:11:03.750172 13319 master.cpp:1403] Filtered slave 201203302307-0-0 for framework 201203302307-0-0002 for 1 seconds
I0330 23:11:03.751042 13319 master.cpp:679] Received reply for offer 201203302307-0-235
I0330 23:11:03.751286 13319 master.cpp:1403] Filtered slave 201203302307-0-1 for framework 201203302307-0-0002 for 1 seconds
I0330 23:11:05.749706 13319 master.cpp:1184] Sending 2 offers to framework 201203302307-0-0001
I0330 23:11:05.751255 13319 master.cpp:679] Received reply for offer 201203302307-0-236
I0330 23:11:05.751401 13319 master.cpp:1403] Filtered slave 201203302307-0-0 for framework 201203302307-0-0001 for 1 seconds
I0330 23:11:05.751680 13319 master.cpp:679] Received reply for offer 201203302307-0-237
I0330 23:11:05.751939 13319 master.cpp:1184] Sending 1 offers to framework 201203302307-0-0002
I0330 23:11:05.752120 13319 master.cpp:1403] Filtered slave 201203302307-0-1 for framework 201203302307-0-0001 for 1 seconds
I0330 23:11:05.753026 13319 master.cpp:679] Received reply for offer 201203302307-0-238
I0330 23:11:05.753231 13319 master.cpp:1184] Sending 1 offers to framework 201203302307-0-0002
I0330 23:11:05.753396 13319 master.cpp:1403] Filtered slave 201203302307-0-0 for framework 201203302307-0-0002 for 1 seconds
I0330 23:11:05.754220 13319 master.cpp:679] Received reply for offer 201203302307-0-239
I0330 23:11:05.754364 13319 master.cpp:1403] Filtered slave 201203302307-0-1 for framework 201203302307-0-0002 for 1 seconds
I0330 23:11:07.752907 13319 master.cpp:1184] Sending 2 offers to framework 201203302307-0-0001
I0330 23:11:07.754462 13319 master.cpp:679] Received reply for offer 201203302307-0-240
I0330 23:11:07.754608 13319 master.cpp:1403] Filtered slave 201203302307-0-0 for framework 201203302307-0-0001 for 1 seconds
I0330 23:11:07.754906 13319 master.cpp:679] Received reply for offer 201203302307-0-241
I0330 23:11:07.755125 13319 master.cpp:1184] Sending 1 offers to framework 201203302307-0-0002
I0330 23:11:07.755261 13319 master.cpp:1403] Filtered slave 201203302307-0-1 for framework 201203302307-0-0001 for 1 seconds
I0330 23:11:07.756211 13319 master.cpp:679] Received reply for offer 201203302307-0-242
I0330 23:11:07.756397 13319 master.cpp:1184] Sending 1 offers to framework 201203302307-0-0002
I0330 23:11:07.756505 13319 master.cpp:1403] Filtered slave 201203302307-0-0 for framework 201203302307-0-0002 for 1 seconds
I0330 23:11:07.757343 13319 master.cpp:679] Received reply for offer 201203302307-0-243
I0330 23:11:07.757500 13319 master.cpp:1403] Filtered slave 201203302307-0-1 for framework 201203302307-0-0002 for 1 seconds
I0330 23:11:09.755023 13319 master.cpp:1184] Sending 2 offers to framework 201203302307-0-0001
I0330 23:11:09.756685 13319 master.cpp:679] Received reply for offer 201203302307-0-244
I0330 23:11:09.756813 13319 master.cpp:1403] Filtered slave 201203302307-0-0 for framework 201203302307-0-0001 for 1 seconds
I0330 23:11:09.757129 13319 master.cpp:679] Received reply for offer 201203302307-0-245
I0330 23:11:09.757372 13319 master.cpp:1184] Sending 1 offers to framework 201203302307-0-0002
I0330 23:11:09.757810 13319 master.cpp:1403] Filtered slave 201203302307-0-1 for framework 201203302307-0-0001 for 1 seconds
I0330 23:11:09.758638 13319 master.cpp:679] Received reply for offer 201203302307-0-246
I0330 23:11:09.758937 13319 master.cpp:1184] Sending 1 offers to framework 201203302307-0-0002
I0330 23:11:09.759196 13319 master.cpp:1403] Filtered slave 201203302307-0-0 for framework 201203302307-0-0002 for 1 seconds
I0330 23:11:09.759897 13319 master.cpp:679] Received reply for offer 201203302307-0-247
I0330 23:11:09.760077 13319 master.cpp:1403] Filtered slave 201203302307-0-1 for framework 201203302307-0-0002 for 1 seconds
I0330 23:11:11.757619 13319 master.cpp:1184] Sending 2 offers to framework 201203302307-0-0001
I0330 23:11:11.759131 13319 master.cpp:679] Received reply for offer 201203302307-0-248
I0330 23:11:11.759275 13319 master.cpp:1403] Filtered slave 201203302307-0-0 for framework 201203302307-0-0001 for 1 seconds
I0330 23:11:11.759544 13319 master.cpp:679] Received reply for offer 201203302307-0-249
I0330 23:11:11.759729 13319 master.cpp:1184] Sending 1 offers to framework 201203302307-0-0002
I0330 23:11:11.759861 13319 master.cpp:1403] Filtered slave 201203302307-0-1 for framework 201203302307-0-0001 for 1 seconds
I0330 23:11:11.760993 13319 master.cpp:679] Received reply for offer 201203302307-0-250
I0330 23:11:11.761178 13319 master.cpp:1184] Sending 1 offers to framework 201203302307-0-0002
I0330 23:11:11.761312 13319 master.cpp:1403] Filtered slave 201203302307-0-0 for framework 201203302307-0-0002 for 1 seconds
I0330 23:11:11.762251 13319 master.cpp:679] Received reply for offer 201203302307-0-251
I0330 23:11:11.762398 13319 master.cpp:1403] Filtered slave 201203302307-0-1 for framework 201203302307-0-0002 for 1 seconds
I0330 23:11:13.760872 13319 master.cpp:1184] Sending 2 offers to framework 201203302307-0-0001
I0330 23:11:13.762440 13319 master.cpp:679] Received reply for offer 201203302307-0-252
I0330 23:11:13.762565 13319 master.cpp:1403] Filtered slave 201203302307-0-0 for framework 201203302307-0-0001 for 1 seconds
I0330 23:11:13.762892 13319 master.cpp:679] Received reply for offer 201203302307-0-253
I0330 23:11:13.763113 13319 master.cpp:1184] Sending 1 offers to framework 201203302307-0-0002
I0330 23:11:13.763213 13319 master.cpp:1403] Filtered slave 201203302307-0-1 for framework 201203302307-0-0001 for 1 seconds
I0330 23:11:13.763964 13319 master.cpp:679] Received reply for offer 201203302307-0-254
I0330 23:11:13.764133 13319 master.cpp:1184] Sending 1 offers to framework 201203302307-0-0002
I0330 23:11:13.764242 13319 master.cpp:1403] Filtered slave 201203302307-0-0 for framework 201203302307-0-0002 for 1 seconds
I0330 23:11:13.765099 13319 master.cpp:679] Received reply for offer 201203302307-0-255
I0330 23:11:13.765219 13319 master.cpp:1403] Filtered slave 201203302307-0-1 for framework 201203302307-0-0002 for 1 seconds
I0330 23:11:15.763568 13319 master.cpp:1184] Sending 2 offers to framework 201203302307-0-0001
I0330 23:11:15.764855 13319 master.cpp:679] Received reply for offer 201203302307-0-256
I0330 23:11:15.764983 13319 master.cpp:1403] Filtered slave 201203302307-0-0 for framework 201203302307-0-0001 for 1 seconds
I0330 23:11:15.765221 13319 master.cpp:679] Received reply for offer 201203302307-0-257
I0330 23:11:15.765468 13319 master.cpp:1184] Sending 1 offers to framework 201203302307-0-0002
I0330 23:11:15.765566 13319 master.cpp:1403] Filtered slave 201203302307-0-1 for framework 201203302307-0-0001 for 1 seconds
I0330 23:11:15.766245 13319 master.cpp:679] Received reply for offer 201203302307-0-258
I0330 23:11:15.766383 13319 master.cpp:1184] Sending 1 offers to framework 201203302307-0-0002
I0330 23:11:15.766479 13319 master.cpp:1403] Filtered slave 201203302307-0-0 for framework 201203302307-0-0002 for 1 seconds
I0330 23:11:15.767194 13319 master.cpp:679] Received reply for offer 201203302307-0-259
I0330 23:11:15.767320 13319 master.cpp:1403] Filtered slave 201203302307-0-1 for framework 201203302307-0-0002 for 1 seconds
I0330 23:11:16.765384 13319 master.cpp:1184] Sending 1 offers to framework 201203302307-0-0001
I0330 23:11:16.766510 13319 master.cpp:679] Received reply for offer 201203302307-0-260
I0330 23:11:16.766584 13319 master.cpp:1403] Filtered slave 201203302307-0-0 for framework 201203302307-0-0001 for 1 seconds
I0330 23:11:17.767678 13319 master.cpp:1184] Sending 1 offers to framework 201203302307-0-0002
I0330 23:11:17.768826 13319 master.cpp:679] Received reply for offer 201203302307-0-261
I0330 23:11:17.768952 13319 master.cpp:1403] Filtered slave 201203302307-0-0 for framework 201203302307-0-0002 for 1 seconds
I0330 23:11:18.769867 13319 master.cpp:1184] Sending 2 offers to framework 201203302307-0-0001
I0330 23:11:18.771221 13319 master.cpp:679] Received reply for offer 201203302307-0-262
I0330 23:11:18.771344 13319 master.cpp:1403] Filtered slave 201203302307-0-0 for framework 201203302307-0-0001 for 1 seconds
I0330 23:11:18.771620 13319 master.cpp:679] Received reply for offer 201203302307-0-263
I0330 23:11:18.771780 13319 master.cpp:1184] Sending 1 offers to framework 201203302307-0-0002
I0330 23:11:18.771941 13319 master.cpp:1403] Filtered slave 201203302307-0-1 for framework 201203302307-0-0001 for 1 seconds
I0330 23:11:18.772639 13319 master.cpp:679] Received reply for offer 201203302307-0-264
I0330 23:11:18.772800 13319 master.cpp:1184] Sending 1 offers to framework 201203302307-0-0002
I0330 23:11:18.773061 13319 master.cpp:1403] Filtered slave 201203302307-0-0 for framework 201203302307-0-0002 for 1 seconds
I0330 23:11:18.773733 13319 master.cpp:679] Received reply for offer 201203302307-0-265
I0330 23:11:18.773876 13319 master.cpp:1403] Filtered slave 201203302307-0-1 for framework 201203302307-0-0002 for 1 seconds
I0330 23:11:19.771863 13319 master.cpp:1184] Sending 1 offers to framework 201203302307-0-0001
I0330 23:11:19.773016 13319 master.cpp:679] Received reply for offer 201203302307-0-266
I0330 23:11:19.773164 13319 master.cpp:1403] Filtered slave 201203302307-0-0 for framework 201203302307-0-0001 for 1 seconds
I0330 23:11:20.774126 13319 master.cpp:1184] Sending 1 offers to framework 201203302307-0-0002
I0330 23:11:20.775298 13319 master.cpp:679] Received reply for offer 201203302307-0-267
I0330 23:11:20.775421 13319 master.cpp:1403] Filtered slave 201203302307-0-0 for framework 201203302307-0-0002 for 1 seconds
I0330 23:11:21.776459 13319 master.cpp:1184] Sending 2 offers to framework 201203302307-0-0001
I0330 23:11:21.778136 13319 master.cpp:679] Received reply for offer 201203302307-0-268
I0330 23:11:21.778226 13319 master.cpp:1403] Filtered slave 201203302307-0-0 for framework 201203302307-0-0001 for 1 seconds
I0330 23:11:21.795888 13319 master.cpp:679] Received reply for offer 201203302307-0-269
I0330 23:11:21.818889 13319 master.cpp:1184] Sending 1 offers to framework 201203302307-0-0002
I0330 23:11:21.819259 13319 master.cpp:1403] Filtered slave 201203302307-0-1 for framework 201203302307-0-0001 for 1 seconds
I0330 23:11:21.819866 13319 master.cpp:679] Received reply for offer 201203302307-0-270
I0330 23:11:21.820055 13319 master.cpp:1184] Sending 1 offers to framework 201203302307-0-0002
I0330 23:11:21.820230 13319 master.cpp:1403] Filtered slave 201203302307-0-0 for framework 201203302307-0-0002 for 1 seconds
I0330 23:11:21.821107 13319 master.cpp:679] Received reply for offer 201203302307-0-271
I0330 23:11:21.821276 13319 master.cpp:1403] Filtered slave 201203302307-0-1 for framework 201203302307-0-0002 for 1 seconds
I0330 23:11:23.780412 13319 master.cpp:1184] Sending 2 offers to framework 201203302307-0-0001
I0330 23:11:23.781729 13319 master.cpp:679] Received reply for offer 201203302307-0-272
I0330 23:11:23.781852 13319 master.cpp:1403] Filtered slave 201203302307-0-0 for framework 201203302307-0-0001 for 1 seconds
I0330 23:11:23.782134 13319 master.cpp:679] Received reply for offer 201203302307-0-273
I0330 23:11:23.782312 13319 master.cpp:1184] Sending 1 offers to framework 201203302307-0-0002
I0330 23:11:23.782584 13319 master.cpp:1403] Filtered slave 201203302307-0-1 for framework 201203302307-0-0001 for 1 seconds
I0330 23:11:23.783265 13319 master.cpp:679] Received reply for offer 201203302307-0-274
I0330 23:11:23.783470 13319 master.cpp:1184] Sending 1 offers to framework 201203302307-0-0002
I0330 23:11:23.783754 13319 master.cpp:1403] Filtered slave 201203302307-0-0 for framework 201203302307-0-0002 for 1 seconds
I0330 23:11:23.784384 13319 master.cpp:679] Received reply for offer 201203302307-0-275
I0330 23:11:23.784544 13319 master.cpp:1403] Filtered slave 201203302307-0-1 for framework 201203302307-0-0002 for 1 seconds
I0330 23:11:25.783262 13319 master.cpp:1184] Sending 2 offers to framework 201203302307-0-0001
I0330 23:11:25.784593 13319 master.cpp:679] Received reply for offer 201203302307-0-276
I0330 23:11:25.784715 13319 master.cpp:1403] Filtered slave 201203302307-0-0 for framework 201203302307-0-0001 for 1 seconds
I0330 23:11:25.785029 13319 master.cpp:679] Received reply for offer 201203302307-0-277
I0330 23:11:25.785236 13319 master.cpp:1184] Sending 1 offers to framework 201203302307-0-0002
I0330 23:11:25.785585 13319 master.cpp:1403] Filtered slave 201203302307-0-1 for framework 201203302307-0-0001 for 1 seconds
I0330 23:11:25.786257 13319 master.cpp:679] Received reply for offer 201203302307-0-278
I0330 23:11:25.786550 13319 master.cpp:1184] Sending 1 offers to framework 201203302307-0-0002
I0330 23:11:25.786816 13319 master.cpp:1403] Filtered slave 201203302307-0-0 for framework 201203302307-0-0002 for 1 seconds
I0330 23:11:25.787590 13319 master.cpp:679] Received reply for offer 201203302307-0-279
I0330 23:11:25.787758 13319 master.cpp:1403] Filtered slave 201203302307-0-1 for framework 201203302307-0-0002 for 1 seconds
I0330 23:11:26.785845 13319 master.cpp:1184] Sending 2 offers to framework 201203302307-0-0001
I0330 23:11:26.787179 13319 master.cpp:679] Received reply for offer 201203302307-0-280
I0330 23:11:26.787278 13319 master.cpp:1403] Filtered slave 201203302307-0-0 for framework 201203302307-0-0001 for 1 seconds
I0330 23:11:26.799579 13319 master.cpp:679] Received reply for offer 201203302307-0-281
I0330 23:11:26.822221 13319 master.cpp:1403] Filtered slave 201203302307-0-1 for framework 201203302307-0-0001 for 1 seconds
I0330 23:11:27.787521 13319 master.cpp:1184] Sending 2 offers to framework 201203302307-0-0002
I0330 23:11:27.788944 13319 master.cpp:679] Received reply for offer 201203302307-0-282
I0330 23:11:27.789085 13319 master.cpp:1403] Filtered slave 201203302307-0-0 for framework 201203302307-0-0002 for 1 seconds
I0330 23:11:27.789433 13319 master.cpp:679] Received reply for offer 201203302307-0-283
I0330 23:11:27.789588 13319 master.cpp:1403] Filtered slave 201203302307-0-1 for framework 201203302307-0-0002 for 1 seconds
I0330 23:11:28.789141 13319 master.cpp:1184] Sending 2 offers to framework 201203302307-0-0001
I0330 23:11:28.790460 13319 master.cpp:679] Received reply for offer 201203302307-0-284
I0330 23:11:28.790611 13319 master.cpp:1403] Filtered slave 201203302307-0-0 for framework 201203302307-0-0001 for 1 seconds
I0330 23:11:28.790873 13319 master.cpp:679] Received reply for offer 201203302307-0-285
I0330 23:11:28.791028 13319 master.cpp:1403] Filtered slave 201203302307-0-1 for framework 201203302307-0-0001 for 1 seconds
I0330 23:11:29.790698 13319 master.cpp:1184] Sending 2 offers to framework 201203302307-0-0002
I0330 23:11:29.791940 13319 master.cpp:679] Received reply for offer 201203302307-0-286
I0330 23:11:29.792083 13319 master.cpp:1403] Filtered slave 201203302307-0-0 for framework 201203302307-0-0002 for 1 seconds
I0330 23:11:29.792417 13319 master.cpp:679] Received reply for offer 201203302307-0-287
I0330 23:11:29.792587 13319 master.cpp:1403] Filtered slave 201203302307-0-1 for framework 201203302307-0-0002 for 1 seconds
I0330 23:11:30.792353 13319 master.cpp:1184] Sending 2 offers to framework 201203302307-0-0001
I0330 23:11:30.793747 13319 master.cpp:679] Received reply for offer 201203302307-0-288
I0330 23:11:30.793897 13319 master.cpp:1403] Filtered slave 201203302307-0-0 for framework 201203302307-0-0001 for 1 seconds
I0330 23:11:30.794219 13319 master.cpp:679] Received reply for offer 201203302307-0-289
I0330 23:11:30.794373 13319 master.cpp:1403] Filtered slave 201203302307-0-1 for framework 201203302307-0-0001 for 1 seconds
I0330 23:11:31.793920 13319 master.cpp:1184] Sending 2 offers to framework 201203302307-0-0002
I0330 23:11:31.795332 13319 master.cpp:679] Received reply for offer 201203302307-0-290
I0330 23:11:31.795419 13319 master.cpp:1403] Filtered slave 201203302307-0-0 for framework 201203302307-0-0002 for 1 seconds
I0330 23:11:31.811132 13319 master.cpp:679] Received reply for offer 201203302307-0-291
I0330 23:11:31.833834 13319 master.cpp:1403] Filtered slave 201203302307-0-1 for framework 201203302307-0-0002 for 1 seconds
I0330 23:11:32.795634 13319 master.cpp:1184] Sending 2 offers to framework 201203302307-0-0001
I0330 23:11:32.796989 13319 master.cpp:679] Received reply for offer 201203302307-0-292
I0330 23:11:32.797116 13319 master.cpp:1403] Filtered slave 201203302307-0-0 for framework 201203302307-0-0001 for 1 seconds
I0330 23:11:32.797410 13319 master.cpp:679] Received reply for offer 201203302307-0-293
I0330 23:11:32.797544 13319 master.cpp:1403] Filtered slave 201203302307-0-1 for framework 201203302307-0-0001 for 1 seconds
I0330 23:11:33.797235 13319 master.cpp:1184] Sending 2 offers to framework 201203302307-0-0002
I0330 23:11:33.798480 13319 master.cpp:679] Received reply for offer 201203302307-0-294
I0330 23:11:33.798601 13319 master.cpp:1403] Filtered slave 201203302307-0-0 for framework 201203302307-0-0002 for 1 seconds
I0330 23:11:33.798890 13319 master.cpp:679] Received reply for offer 201203302307-0-295
I0330 23:11:33.799331 13319 master.cpp:1403] Filtered slave 201203302307-0-1 for framework 201203302307-0-0002 for 1 seconds
I0330 23:11:34.798781 13319 master.cpp:1184] Sending 2 offers to framework 201203302307-0-0001
I0330 23:11:34.800218 13319 master.cpp:679] Received reply for offer 201203302307-0-296
I0330 23:11:34.800364 13319 master.cpp:1403] Filtered slave 201203302307-0-0 for framework 201203302307-0-0001 for 1 seconds
I0330 23:11:34.800647 13319 master.cpp:679] Received reply for offer 201203302307-0-297
I0330 23:11:34.800809 13319 master.cpp:1403] Filtered slave 201203302307-0-1 for framework 201203302307-0-0001 for 1 seconds
I0330 23:11:35.800569 13319 master.cpp:1184] Sending 2 offers to framework 201203302307-0-0002
I0330 23:11:35.801965 13319 master.cpp:679] Received reply for offer 201203302307-0-298
I0330 23:11:35.802104 13319 master.cpp:1403] Filtered slave 201203302307-0-0 for framework 201203302307-0-0002 for 1 seconds
I0330 23:11:35.802422 13319 master.cpp:679] Received reply for offer 201203302307-0-299
I0330 23:11:35.802577 13319 master.cpp:1403] Filtered slave 201203302307-0-1 for framework 201203302307-0-0002 for 1 seconds
I0330 23:11:36.802376 13319 master.cpp:1184] Sending 2 offers to framework 201203302307-0-0001
I0330 23:11:36.803874 13319 master.cpp:679] Received reply for offer 201203302307-0-300
I0330 23:11:36.803966 13319 master.cpp:1403] Filtered slave 201203302307-0-0 for framework 201203302307-0-0001 for 1 seconds
I0330 23:11:36.822967 13319 master.cpp:679] Received reply for offer 201203302307-0-301
I0330 23:11:36.845502 13319 master.cpp:1403] Filtered slave 201203302307-0-1 for framework 201203302307-0-0001 for 1 seconds
I0330 23:11:37.804986 13319 master.cpp:1184] Sending 2 offers to framework 201203302307-0-0002
I0330 23:11:37.806632 13319 master.cpp:679] Received reply for offer 201203302307-0-302
I0330 23:11:37.806771 13319 master.cpp:1403] Filtered slave 201203302307-0-0 for framework 201203302307-0-0002 for 1 seconds
I0330 23:11:37.807065 13319 master.cpp:679] Received reply for offer 201203302307-0-303
I0330 23:11:37.807270 13319 master.cpp:1403] Filtered slave 201203302307-0-1 for framework 201203302307-0-0002 for 1 seconds
I0330 23:11:38.806921 13319 master.cpp:1184] Sending 2 offers to framework 201203302307-0-0001
I0330 23:11:38.808619 13319 master.cpp:679] Received reply for offer 201203302307-0-304
I0330 23:11:38.808770 13319 master.cpp:1403] Filtered slave 201203302307-0-0 for framework 201203302307-0-0001 for 1 seconds
I0330 23:11:38.809010 13319 master.cpp:679] Received reply for offer 201203302307-0-305
I0330 23:11:38.809156 13319 master.cpp:1403] Filtered slave 201203302307-0-1 for framework 201203302307-0-0001 for 1 seconds
I0330 23:11:39.808434 13319 master.cpp:1184] Sending 2 offers to framework 201203302307-0-0002
I0330 23:11:39.810098 13319 master.cpp:679] Received reply for offer 201203302307-0-306
I0330 23:11:39.810246 13319 master.cpp:1403] Filtered slave 201203302307-0-0 for framework 201203302307-0-0002 for 1 seconds
I0330 23:11:39.810521 13319 master.cpp:679] Received reply for offer 201203302307-0-307
I0330 23:11:39.810641 13319 master.cpp:1403] Filtered slave 201203302307-0-1 for framework 201203302307-0-0002 for 1 seconds
I0330 23:11:40.810004 13319 master.cpp:1184] Sending 2 offers to framework 201203302307-0-0001
I0330 23:11:40.811691 13319 master.cpp:679] Received reply for offer 201203302307-0-308
I0330 23:11:40.811841 13319 master.cpp:1403] Filtered slave 201203302307-0-0 for framework 201203302307-0-0001 for 1 seconds
I0330 23:11:40.812115 13319 master.cpp:679] Received reply for offer 201203302307-0-309
I0330 23:11:40.812258 13319 master.cpp:1403] Filtered slave 201203302307-0-1 for framework 201203302307-0-0001 for 1 seconds
I0330 23:11:41.811380 13319 master.cpp:1184] Sending 2 offers to framework 201203302307-0-0002
I0330 23:11:41.813043 13319 master.cpp:679] Received reply for offer 201203302307-0-310
I0330 23:11:41.813163 13319 master.cpp:1403] Filtered slave 201203302307-0-0 for framework 201203302307-0-0002 for 1 seconds
I0330 23:11:41.826518 13319 master.cpp:679] Received reply for offer 201203302307-0-311
I0330 23:11:41.848920 13319 master.cpp:1403] Filtered slave 201203302307-0-1 for framework 201203302307-0-0002 for 1 seconds
I0330 23:11:42.813309 13319 master.cpp:1184] Sending 2 offers to framework 201203302307-0-0001
I0330 23:11:42.814586 13319 master.cpp:679] Received reply for offer 201203302307-0-312
I0330 23:11:42.814725 13319 master.cpp:1403] Filtered slave 201203302307-0-0 for framework 201203302307-0-0001 for 1 seconds
I0330 23:11:42.815038 13319 master.cpp:679] Received reply for offer 201203302307-0-313
I0330 23:11:42.815171 13319 master.cpp:1403] Filtered slave 201203302307-0-1 for framework 201203302307-0-0001 for 1 seconds
I0330 23:11:43.814753 13319 master.cpp:1184] Sending 2 offers to framework 201203302307-0-0002
I0330 23:11:43.816043 13319 master.cpp:679] Received reply for offer 201203302307-0-314
I0330 23:11:43.816172 13319 master.cpp:1403] Filtered slave 201203302307-0-0 for framework 201203302307-0-0002 for 1 seconds
I0330 23:11:43.816475 13319 master.cpp:679] Received reply for offer 201203302307-0-315
I0330 23:11:43.816601 13319 master.cpp:1403] Filtered slave 201203302307-0-1 for framework 201203302307-0-0002 for 1 seconds
I0330 23:11:44.816285 13319 master.cpp:1184] Sending 2 offers to framework 201203302307-0-0001
I0330 23:11:44.817401 13319 master.cpp:679] Received reply for offer 201203302307-0-316
I0330 23:11:44.817518 13319 master.cpp:1403] Filtered slave 201203302307-0-0 for framework 201203302307-0-0001 for 1 seconds
I0330 23:11:44.817822 13319 master.cpp:679] Received reply for offer 201203302307-0-317
I0330 23:11:44.817950 13319 master.cpp:1403] Filtered slave 201203302307-0-1 for framework 201203302307-0-0001 for 1 seconds
I0330 23:11:45.818652 13319 master.cpp:1184] Sending 1 offers to framework 201203302307-0-0001
I0330 23:11:45.818872 13319 master.cpp:1184] Sending 1 offers to framework 201203302307-0-0002
I0330 23:11:45.819854 13319 master.cpp:679] Received reply for offer 201203302307-0-318
I0330 23:11:45.820034 13319 master.cpp:1403] Filtered slave 201203302307-0-1 for framework 201203302307-0-0001 for 1 seconds
I0330 23:11:45.820381 13319 master.cpp:679] Received reply for offer 201203302307-0-319
I0330 23:11:45.820535 13319 master.cpp:1403] Filtered slave 201203302307-0-0 for framework 201203302307-0-0002 for 1 seconds
I0330 23:11:46.820528 13319 master.cpp:1184] Sending 1 offers to framework 201203302307-0-0001
I0330 23:11:46.820714 13319 master.cpp:1184] Sending 1 offers to framework 201203302307-0-0002
I0330 23:11:46.821732 13319 master.cpp:679] Received reply for offer 201203302307-0-320
I0330 23:11:46.838376 13319 master.cpp:1403] Filtered slave 201203302307-0-0 for framework 201203302307-0-0001 for 1 seconds
I0330 23:11:46.860602 13319 master.cpp:679] Received reply for offer 201203302307-0-321
I0330 23:11:46.860818 13319 master.cpp:1403] Filtered slave 201203302307-0-1 for framework 201203302307-0-0002 for 1 seconds
I0330 23:11:47.823330 13319 master.cpp:1184] Sending 1 offers to framework 201203302307-0-0001
I0330 23:11:47.823490 13319 master.cpp:1184] Sending 1 offers to framework 201203302307-0-0002
I0330 23:11:47.824429 13319 master.cpp:679] Received reply for offer 201203302307-0-322
I0330 23:11:47.824614 13319 master.cpp:1403] Filtered slave 201203302307-0-1 for framework 201203302307-0-0001 for 1 seconds
I0330 23:11:47.824841 13319 master.cpp:679] Received reply for offer 201203302307-0-323
I0330 23:11:47.824988 13319 master.cpp:1403] Filtered slave 201203302307-0-0 for framework 201203302307-0-0002 for 1 seconds
I0330 23:11:48.825036 13319 master.cpp:1184] Sending 1 offers to framework 201203302307-0-0001
I0330 23:11:48.825255 13319 master.cpp:1184] Sending 1 offers to framework 201203302307-0-0002
I0330 23:11:48.826252 13319 master.cpp:679] Received reply for offer 201203302307-0-324
I0330 23:11:48.826431 13319 master.cpp:1403] Filtered slave 201203302307-0-0 for framework 201203302307-0-0001 for 1 seconds
I0330 23:11:48.826589 13319 master.cpp:679] Received reply for offer 201203302307-0-325
I0330 23:11:48.827067 13319 master.cpp:1403] Filtered slave 201203302307-0-1 for framework 201203302307-0-0002 for 1 seconds
I0330 23:11:49.826766 13319 master.cpp:1184] Sending 1 offers to framework 201203302307-0-0001
I0330 23:11:49.826977 13319 master.cpp:1184] Sending 1 offers to framework 201203302307-0-0002
I0330 23:11:49.827894 13319 master.cpp:679] Received reply for offer 201203302307-0-326
I0330 23:11:49.828078 13319 master.cpp:1403] Filtered slave 201203302307-0-1 for framework 201203302307-0-0001 for 1 seconds
I0330 23:11:49.828237 13319 master.cpp:679] Received reply for offer 201203302307-0-327
I0330 23:11:49.828376 13319 master.cpp:1403] Filtered slave 201203302307-0-0 for framework 201203302307-0-0002 for 1 seconds
I0330 23:11:50.828508 13319 master.cpp:1184] Sending 1 offers to framework 201203302307-0-0001
I0330 23:11:50.828735 13319 master.cpp:1184] Sending 1 offers to framework 201203302307-0-0002
I0330 23:11:50.829743 13319 master.cpp:679] Received reply for offer 201203302307-0-328
I0330 23:11:50.829921 13319 master.cpp:1403] Filtered slave 201203302307-0-0 for framework 201203302307-0-0001 for 1 seconds
I0330 23:11:50.830121 13319 master.cpp:679] Received reply for offer 201203302307-0-329
I0330 23:11:50.830267 13319 master.cpp:1403] Filtered slave 201203302307-0-1 for framework 201203302307-0-0002 for 1 seconds
I0330 23:11:51.830319 13319 master.cpp:1184] Sending 1 offers to framework 201203302307-0-0001
I0330 23:11:51.830510 13319 master.cpp:1184] Sending 1 offers to framework 201203302307-0-0002
I0330 23:11:51.831468 13319 master.cpp:679] Received reply for offer 201203302307-0-330
I0330 23:11:51.850230 13319 master.cpp:1403] Filtered slave 201203302307-0-1 for framework 201203302307-0-0001 for 1 seconds
I0330 23:11:51.872280 13319 master.cpp:679] Received reply for offer 201203302307-0-331
I0330 23:11:51.872499 13319 master.cpp:1403] Filtered slave 201203302307-0-0 for framework 201203302307-0-0002 for 1 seconds
I0330 23:11:52.833039 13319 master.cpp:1184] Sending 1 offers to framework 201203302307-0-0001
I0330 23:11:52.833201 13319 master.cpp:1184] Sending 1 offers to framework 201203302307-0-0002
I0330 23:11:52.834229 13319 master.cpp:679] Received reply for offer 201203302307-0-332
I0330 23:11:52.834411 13319 master.cpp:1403] Filtered slave 201203302307-0-0 for framework 201203302307-0-0001 for 1 seconds
I0330 23:11:52.834640 13319 master.cpp:679] Received reply for offer 201203302307-0-333
I0330 23:11:52.834789 13319 master.cpp:1403] Filtered slave 201203302307-0-1 for framework 201203302307-0-0002 for 1 seconds
I0330 23:11:53.834849 13319 master.cpp:1184] Sending 1 offers to framework 201203302307-0-0001
I0330 23:11:53.835072 13319 master.cpp:1184] Sending 1 offers to framework 201203302307-0-0002
I0330 23:11:53.836086 13319 master.cpp:679] Received reply for offer 201203302307-0-334
I0330 23:11:53.836227 13319 master.cpp:1403] Filtered slave 201203302307-0-1 for framework 201203302307-0-0001 for 1 seconds
I0330 23:11:53.836345 13319 master.cpp:679] Received reply for offer 201203302307-0-335
I0330 23:11:53.836571 13319 master.cpp:1403] Filtered slave 201203302307-0-0 for framework 201203302307-0-0002 for 1 seconds
I0330 23:11:54.835783 13319 master.cpp:1184] Sending 1 offers to framework 201203302307-0-0001
I0330 23:11:54.835949 13319 master.cpp:1184] Sending 1 offers to framework 201203302307-0-0002
I0330 23:11:54.836896 13319 master.cpp:679] Received reply for offer 201203302307-0-336
I0330 23:11:54.837023 13319 master.cpp:1403] Filtered slave 201203302307-0-0 for framework 201203302307-0-0001 for 1 seconds
I0330 23:11:54.837232 13319 master.cpp:679] Received reply for offer 201203302307-0-337
I0330 23:11:54.837355 13319 master.cpp:1403] Filtered slave 201203302307-0-1 for framework 201203302307-0-0002 for 1 seconds
I0330 23:11:55.836848 13319 master.cpp:1184] Sending 1 offers to framework 201203302307-0-0001
I0330 23:11:55.837091 13319 master.cpp:1184] Sending 1 offers to framework 201203302307-0-0002
I0330 23:11:55.838045 13319 master.cpp:679] Received reply for offer 201203302307-0-338
I0330 23:11:55.838168 13319 master.cpp:1403] Filtered slave 201203302307-0-1 for framework 201203302307-0-0001 for 1 seconds
I0330 23:11:55.838464 13319 master.cpp:679] Received reply for offer 201203302307-0-339
I0330 23:11:55.838764 13319 master.cpp:1403] Filtered slave 201203302307-0-0 for framework 201203302307-0-0002 for 1 seconds
I0330 23:11:56.839611 13319 master.cpp:1184] Sending 1 offers to framework 201203302307-0-0001
I0330 23:11:56.839870 13319 master.cpp:1184] Sending 1 offers to framework 201203302307-0-0002
I0330 23:11:56.840798 13319 master.cpp:679] Received reply for offer 201203302307-0-340
I0330 23:11:56.862058 13319 master.cpp:1403] Filtered slave 201203302307-0-0 for framework 201203302307-0-0001 for 1 seconds
I0330 23:11:56.883998 13319 master.cpp:679] Received reply for offer 201203302307-0-341
I0330 23:11:56.884321 13319 master.cpp:1184] Sending 1 offers to framework 201203302307-0-0002
I0330 23:11:56.884440 13319 master.cpp:1403] Filtered slave 201203302307-0-1 for framework 201203302307-0-0002 for 1 seconds
I0330 23:11:56.885182 13319 master.cpp:679] Received reply for offer 201203302307-0-342
I0330 23:11:56.885349 13319 master.cpp:1184] Sending 1 offers to framework 201203302307-0-0001
I0330 23:11:56.885480 13319 master.cpp:1403] Filtered slave 201203302307-0-0 for framework 201203302307-0-0002 for 1 seconds
I0330 23:11:56.886210 13319 master.cpp:679] Received reply for offer 201203302307-0-343
I0330 23:11:56.886361 13319 master.cpp:1403] Filtered slave 201203302307-0-1 for framework 201203302307-0-0001 for 1 seconds
I0330 23:11:58.843617 13319 master.cpp:1184] Sending 1 offers to framework 201203302307-0-0001
I0330 23:11:58.843790 13319 master.cpp:1184] Sending 1 offers to framework 201203302307-0-0002
I0330 23:11:58.844861 13319 master.cpp:679] Received reply for offer 201203302307-0-344
I0330 23:11:58.845001 13319 master.cpp:1403] Filtered slave 201203302307-0-0 for framework 201203302307-0-0001 for 1 seconds
I0330 23:11:58.845163 13319 master.cpp:679] Received reply for offer 201203302307-0-345
I0330 23:11:58.845314 13319 master.cpp:1184] Sending 1 offers to framework 201203302307-0-0002
I0330 23:11:58.845410 13319 master.cpp:1403] Filtered slave 201203302307-0-1 for framework 201203302307-0-0002 for 1 seconds
I0330 23:11:58.846135 13319 master.cpp:679] Received reply for offer 201203302307-0-346
I0330 23:11:58.846287 13319 master.cpp:1184] Sending 1 offers to framework 201203302307-0-0001
I0330 23:11:58.846407 13319 master.cpp:1403] Filtered slave 201203302307-0-0 for framework 201203302307-0-0002 for 1 seconds
I0330 23:11:58.847153 13319 master.cpp:679] Received reply for offer 201203302307-0-347
I0330 23:11:58.847292 13319 master.cpp:1403] Filtered slave 201203302307-0-1 for framework 201203302307-0-0001 for 1 seconds
I0330 23:11:59.845335 13319 master.cpp:1184] Sending 1 offers to framework 201203302307-0-0001
I0330 23:11:59.846442 13319 master.cpp:679] Received reply for offer 201203302307-0-348
I0330 23:11:59.846566 13319 master.cpp:1403] Filtered slave 201203302307-0-0 for framework 201203302307-0-0001 for 1 seconds
I0330 23:12:00.686975 13319 master.cpp:1118] Framework 201203302307-0-0001 disconnected
I0330 23:12:00.687147 13319 master.cpp:1118] Framework 201203302307-0-0002 disconnected
