Log file created at: 2012/03/29 00:30:54
Running on machine: azad
Log line format: [IWEF]mmdd hh:mm:ss.uuuuuu threadid file:line] msg
I0329 00:30:54.904265 21854 logging.cpp:70] Logging to /mesos-distro/logdir
I0329 00:30:54.905164 21854 main.cpp:95] Build: 2012-03-28 23:30:52 by hduser
I0329 00:30:54.905261 21854 main.cpp:96] Starting Mesos master
I0329 00:30:54.906358 21854 webui.cpp:81] Starting master web server on port 9836
I0329 00:30:54.906440 21855 master.cpp:264] Master started at mesos://master@192.168.1.64:5050
I0329 00:30:54.906502 21855 master.cpp:279] Master ID: 201203290030-0
I0329 00:30:54.906538 21858 webui.cpp:47] Master web server thread started
I0329 00:30:54.906874 21855 master.cpp:462] Elected as master!
I0329 00:30:54.919709 21858 webui.cpp:59] Loading webui/master/webui.py
I0329 00:30:58.083781 21855 master.cpp:814] Attempting to register slave 201203290030-0-0 at slave@192.168.1.64:33399
I0329 00:30:58.084059 21855 master.cpp:1057] Master now considering a slave at azad.gateway.2wire.net:33399 as active
I0329 00:30:58.084103 21855 master.cpp:1588] Adding slave 201203290030-0-0 at azad.gateway.2wire.net with cpus=4; mem=16384
I0329 00:30:58.084370 21855 simple_allocator.cpp:71] Added slave 201203290030-0-0 with cpus=4; mem=16384
I0329 00:31:01.613051 21855 master.cpp:814] Attempting to register slave 201203290030-0-1 at slave@192.168.1.66:60325
I0329 00:31:01.613281 21855 master.cpp:1057] Master now considering a slave at ubuntu.gateway.2wire.net:60325 as active
I0329 00:31:01.613325 21855 master.cpp:1588] Adding slave 201203290030-0-1 at ubuntu.gateway.2wire.net with cpus=4; mem=4096
I0329 00:31:01.613428 21855 simple_allocator.cpp:71] Added slave 201203290030-0-1 with cpus=4; mem=4096
I0329 00:31:10.032834 21855 master.cpp:492] Registering framework 201203290030-0-0000 at 3@192.168.1.64:33624
I0329 00:31:10.032999 21855 simple_allocator.cpp:48] Added framework 201203290030-0-0000
I0329 00:31:10.033109 21855 master.cpp:1184] Sending 2 offers to framework 201203290030-0-0000
I0329 00:31:10.033187 21855 master.cpp:492] Registering framework 201203290030-0-0001 at 2@192.168.1.64:33624
I0329 00:31:10.033234 21855 simple_allocator.cpp:48] Added framework 201203290030-0-0001
I0329 00:31:10.050009 21855 master.cpp:679] Received reply for offer 201203290030-0-0
I0329 00:31:10.050093 21855 master.cpp:1403] Filtered slave 201203290030-0-0 for framework 201203290030-0-0000 for 1 seconds
I0329 00:31:10.050135 21855 master.cpp:679] Received reply for offer 201203290030-0-1
I0329 00:31:10.050194 21855 master.cpp:1184] Sending 1 offers to framework 201203290030-0-0001
I0329 00:31:10.050233 21855 master.cpp:1403] Filtered slave 201203290030-0-1 for framework 201203290030-0-0000 for 1 seconds
I0329 00:31:10.051144 21855 master.cpp:679] Received reply for offer 201203290030-0-2
I0329 00:31:10.051218 21855 master.cpp:1184] Sending 1 offers to framework 201203290030-0-0001
I0329 00:31:10.051249 21855 master.cpp:1403] Filtered slave 201203290030-0-0 for framework 201203290030-0-0001 for 1 seconds
I0329 00:31:10.052230 21855 master.cpp:679] Received reply for offer 201203290030-0-3
I0329 00:31:10.052289 21855 master.cpp:1403] Filtered slave 201203290030-0-1 for framework 201203290030-0-0001 for 1 seconds
I0329 00:31:10.389317 21855 master.cpp:718] Reviving offers for framework 201203290030-0-0000
I0329 00:31:10.389365 21855 simple_allocator.cpp:145] Filters removed for framework 201203290030-0-0000
I0329 00:31:10.389482 21855 master.cpp:1184] Sending 2 offers to framework 201203290030-0-0000
I0329 00:31:10.453995 21855 master.cpp:679] Received reply for offer 201203290030-0-4
I0329 00:31:10.454118 21855 master.cpp:1453] Launching task 0 on slave 201203290030-0-0
I0329 00:31:10.454346 21855 master.cpp:1453] Launching task 1 on slave 201203290030-0-0
I0329 00:31:10.454512 21855 master.cpp:1453] Launching task 2 on slave 201203290030-0-0
I0329 00:31:10.454618 21855 master.cpp:1453] Launching task 3 on slave 201203290030-0-0
I0329 00:31:10.454784 21855 master.cpp:679] Received reply for offer 201203290030-0-5
I0329 00:31:10.454833 21855 master.cpp:1403] Filtered slave 201203290030-0-1 for framework 201203290030-0-0000 for 1 seconds
I0329 00:31:11.349231 21855 master.cpp:902] Status update from slave@192.168.1.64:33399: task 1 of framework 201203290030-0-0000 is now in state TASK_RUNNING
I0329 00:31:11.351907 21855 master.cpp:902] Status update from slave@192.168.1.64:33399: task 2 of framework 201203290030-0-0000 is now in state TASK_RUNNING
I0329 00:31:11.354341 21855 master.cpp:902] Status update from slave@192.168.1.64:33399: task 3 of framework 201203290030-0-0000 is now in state TASK_RUNNING
I0329 00:31:11.356106 21855 master.cpp:902] Status update from slave@192.168.1.64:33399: task 0 of framework 201203290030-0-0000 is now in state TASK_RUNNING
I0329 00:31:11.726668 21855 master.cpp:902] Status update from slave@192.168.1.64:33399: task 1 of framework 201203290030-0-0000 is now in state TASK_FAILED
I0329 00:31:11.727016 21855 master.cpp:1184] Sending 1 offers to framework 201203290030-0-0000
I0329 00:31:11.746654 21855 master.cpp:679] Received reply for offer 201203290030-0-6
I0329 00:31:11.746803 21855 master.cpp:1453] Launching task 4 on slave 201203290030-0-0
I0329 00:31:11.926872 21855 master.cpp:1184] Sending 1 offers to framework 201203290030-0-0001
I0329 00:31:11.928208 21855 master.cpp:679] Received reply for offer 201203290030-0-7
I0329 00:31:11.928346 21855 master.cpp:1403] Filtered slave 201203290030-0-1 for framework 201203290030-0-0001 for 1 seconds
I0329 00:31:12.099463 21855 master.cpp:1001] Executor default of framework 201203290030-0-0000 on slave 201203290030-0-0 (azad.gateway.2wire.net) exited with status 256
I0329 00:31:12.100884 21855 master.cpp:1033] Removing task 0 of framework 201203290030-0-0000 because of lost executor
I0329 00:31:12.101119 21855 master.cpp:1184] Sending 1 offers to framework 201203290030-0-0001
I0329 00:31:12.101346 21855 master.cpp:1184] Sending 1 offers to framework 201203290030-0-0000
I0329 00:31:12.102939 21855 master.cpp:1033] Removing task 2 of framework 201203290030-0-0000 because of lost executor
I0329 00:31:12.104437 21855 master.cpp:1033] Removing task 3 of framework 201203290030-0-0000 because of lost executor
I0329 00:31:12.105880 21855 master.cpp:1033] Removing task 4 of framework 201203290030-0-0000 because of lost executor
I0329 00:31:12.106065 21855 master.cpp:679] Received reply for offer 201203290030-0-9
I0329 00:31:12.106241 21855 master.cpp:1184] Sending 1 offers to framework 201203290030-0-0000
I0329 00:31:12.106355 21855 master.cpp:1403] Filtered slave 201203290030-0-1 for framework 201203290030-0-0000 for 1 seconds
I0329 00:31:12.106574 21855 master.cpp:679] Received reply for offer 201203290030-0-8
I0329 00:31:12.106752 21855 master.cpp:1403] Filtered slave 201203290030-0-0 for framework 201203290030-0-0001 for 1 seconds
I0329 00:31:12.128694 21855 master.cpp:679] Received reply for offer 201203290030-0-10
I0329 00:31:12.128882 21855 master.cpp:1453] Launching task 5 on slave 201203290030-0-0
I0329 00:31:12.129174 21855 master.cpp:1453] Launching task 6 on slave 201203290030-0-0
I0329 00:31:12.129523 21855 master.cpp:1453] Launching task 7 on slave 201203290030-0-0
I0329 00:31:12.928830 21855 master.cpp:1184] Sending 1 offers to framework 201203290030-0-0001
I0329 00:31:12.930246 21855 master.cpp:679] Received reply for offer 201203290030-0-11
I0329 00:31:12.930374 21855 master.cpp:1403] Filtered slave 201203290030-0-1 for framework 201203290030-0-0001 for 1 seconds
I0329 00:31:12.961607 21855 master.cpp:902] Status update from slave@192.168.1.64:33399: task 6 of framework 201203290030-0-0000 is now in state TASK_RUNNING
I0329 00:31:12.963551 21855 master.cpp:902] Status update from slave@192.168.1.64:33399: task 7 of framework 201203290030-0-0000 is now in state TASK_RUNNING
I0329 00:31:12.965924 21855 master.cpp:902] Status update from slave@192.168.1.64:33399: task 5 of framework 201203290030-0-0000 is now in state TASK_RUNNING
I0329 00:31:13.297107 21855 master.cpp:902] Status update from slave@192.168.1.64:33399: task 6 of framework 201203290030-0-0000 is now in state TASK_FAILED
I0329 00:31:13.297485 21855 master.cpp:1184] Sending 1 offers to framework 201203290030-0-0000
I0329 00:31:13.313994 21855 master.cpp:679] Received reply for offer 201203290030-0-12
I0329 00:31:13.314178 21855 master.cpp:1453] Launching task 8 on slave 201203290030-0-0
I0329 00:31:13.314508 21855 master.cpp:1453] Launching task 9 on slave 201203290030-0-0
I0329 00:31:13.930824 21855 master.cpp:1184] Sending 1 offers to framework 201203290030-0-0001
I0329 00:31:13.932427 21855 master.cpp:679] Received reply for offer 201203290030-0-13
I0329 00:31:13.932582 21855 master.cpp:1403] Filtered slave 201203290030-0-1 for framework 201203290030-0-0001 for 1 seconds
I0329 00:31:14.101696 21855 master.cpp:1001] Executor default of framework 201203290030-0-0000 on slave 201203290030-0-0 (azad.gateway.2wire.net) exited with status 256
I0329 00:31:14.103420 21855 master.cpp:1033] Removing task 5 of framework 201203290030-0-0000 because of lost executor
I0329 00:31:14.103637 21855 master.cpp:1184] Sending 1 offers to framework 201203290030-0-0001
I0329 00:31:14.104984 21855 master.cpp:1184] Sending 1 offers to framework 201203290030-0-0000
I0329 00:31:14.106633 21855 master.cpp:1033] Removing task 7 of framework 201203290030-0-0000 because of lost executor
I0329 00:31:14.108310 21855 master.cpp:1033] Removing task 8 of framework 201203290030-0-0000 because of lost executor
I0329 00:31:14.109879 21855 master.cpp:1033] Removing task 9 of framework 201203290030-0-0000 because of lost executor
I0329 00:31:14.110056 21855 master.cpp:679] Received reply for offer 201203290030-0-14
I0329 00:31:14.110954 21855 master.cpp:1184] Sending 1 offers to framework 201203290030-0-0000
I0329 00:31:14.111281 21855 master.cpp:1403] Filtered slave 201203290030-0-0 for framework 201203290030-0-0001 for 1 seconds
I0329 00:31:14.111419 21855 master.cpp:679] Received reply for offer 201203290030-0-15
I0329 00:31:14.111866 21855 master.cpp:1403] Filtered slave 201203290030-0-1 for framework 201203290030-0-0000 for 1 seconds
I0329 00:31:14.135197 21855 master.cpp:679] Received reply for offer 201203290030-0-16
I0329 00:31:14.135381 21855 master.cpp:1453] Launching task 10 on slave 201203290030-0-0
I0329 00:31:14.135792 21855 master.cpp:1453] Launching task 11 on slave 201203290030-0-0
I0329 00:31:14.136103 21855 master.cpp:1453] Launching task 12 on slave 201203290030-0-0
I0329 00:31:14.932348 21855 master.cpp:1184] Sending 1 offers to framework 201203290030-0-0000
I0329 00:31:14.938874 21855 master.cpp:679] Received reply for offer 201203290030-0-17
I0329 00:31:14.939003 21855 master.cpp:1453] Launching task 13 on slave 201203290030-0-0
I0329 00:31:14.982729 21855 master.cpp:902] Status update from slave@192.168.1.64:33399: task 13 of framework 201203290030-0-0000 is now in state TASK_RUNNING
I0329 00:31:14.984196 21855 master.cpp:902] Status update from slave@192.168.1.64:33399: task 10 of framework 201203290030-0-0000 is now in state TASK_RUNNING
I0329 00:31:14.986268 21855 master.cpp:902] Status update from slave@192.168.1.64:33399: task 12 of framework 201203290030-0-0000 is now in state TASK_RUNNING
I0329 00:31:14.988651 21855 master.cpp:902] Status update from slave@192.168.1.64:33399: task 11 of framework 201203290030-0-0000 is now in state TASK_RUNNING
I0329 00:31:15.336982 21855 master.cpp:902] Status update from slave@192.168.1.64:33399: task 13 of framework 201203290030-0-0000 is now in state TASK_FAILED
I0329 00:31:15.337260 21855 master.cpp:1184] Sending 1 offers to framework 201203290030-0-0000
I0329 00:31:15.345852 21855 master.cpp:679] Received reply for offer 201203290030-0-18
I0329 00:31:15.345996 21855 master.cpp:1453] Launching task 14 on slave 201203290030-0-0
I0329 00:31:15.934329 21855 master.cpp:1184] Sending 1 offers to framework 201203290030-0-0001
I0329 00:31:15.936184 21855 master.cpp:679] Received reply for offer 201203290030-0-19
I0329 00:31:15.936337 21855 master.cpp:1403] Filtered slave 201203290030-0-1 for framework 201203290030-0-0001 for 1 seconds
I0329 00:31:16.102905 21855 master.cpp:1001] Executor default of framework 201203290030-0-0000 on slave 201203290030-0-0 (azad.gateway.2wire.net) exited with status 256
I0329 00:31:16.104620 21855 master.cpp:1033] Removing task 10 of framework 201203290030-0-0000 because of lost executor
I0329 00:31:16.104814 21855 master.cpp:1184] Sending 1 offers to framework 201203290030-0-0001
I0329 00:31:16.105123 21855 master.cpp:1184] Sending 1 offers to framework 201203290030-0-0000
I0329 00:31:16.106645 21855 master.cpp:1033] Removing task 14 of framework 201203290030-0-0000 because of lost executor
I0329 00:31:16.108125 21855 master.cpp:1033] Removing task 11 of framework 201203290030-0-0000 because of lost executor
I0329 00:31:16.109698 21855 master.cpp:1033] Removing task 12 of framework 201203290030-0-0000 because of lost executor
I0329 00:31:16.109904 21855 master.cpp:679] Received reply for offer 201203290030-0-20
I0329 00:31:16.110120 21855 master.cpp:1184] Sending 1 offers to framework 201203290030-0-0000
I0329 00:31:16.110278 21855 master.cpp:1403] Filtered slave 201203290030-0-0 for framework 201203290030-0-0001 for 1 seconds
I0329 00:31:16.110435 21855 master.cpp:679] Received reply for offer 201203290030-0-21
I0329 00:31:16.110662 21855 master.cpp:1403] Filtered slave 201203290030-0-1 for framework 201203290030-0-0000 for 1 seconds
I0329 00:31:16.111348 21855 master.cpp:679] Received reply for offer 201203290030-0-22
I0329 00:31:16.111532 21855 master.cpp:1184] Sending 1 offers to framework 201203290030-0-0000
I0329 00:31:16.112140 21855 master.cpp:1403] Filtered slave 201203290030-0-0 for framework 201203290030-0-0000 for 1 seconds
I0329 00:31:16.113385 21855 master.cpp:679] Received reply for offer 201203290030-0-23
I0329 00:31:16.113631 21855 master.cpp:1403] Filtered slave 201203290030-0-0 for framework 201203290030-0-0000 for 1 seconds
I0329 00:31:17.936755 21855 master.cpp:1184] Sending 1 offers to framework 201203290030-0-0000
I0329 00:31:17.936965 21855 master.cpp:1184] Sending 1 offers to framework 201203290030-0-0001
I0329 00:31:17.938576 21855 master.cpp:679] Received reply for offer 201203290030-0-24
I0329 00:31:17.938731 21855 master.cpp:1403] Filtered slave 201203290030-0-1 for framework 201203290030-0-0000 for 1 seconds
I0329 00:31:17.939072 21855 master.cpp:679] Received reply for offer 201203290030-0-25
I0329 00:31:17.939369 21855 master.cpp:1184] Sending 1 offers to framework 201203290030-0-0001
I0329 00:31:17.939527 21855 master.cpp:1403] Filtered slave 201203290030-0-0 for framework 201203290030-0-0001 for 1 seconds
I0329 00:31:17.940845 21855 master.cpp:679] Received reply for offer 201203290030-0-26
I0329 00:31:17.941045 21855 master.cpp:1184] Sending 1 offers to framework 201203290030-0-0000
I0329 00:31:17.941282 21855 master.cpp:1403] Filtered slave 201203290030-0-1 for framework 201203290030-0-0001 for 1 seconds
I0329 00:31:17.942522 21855 master.cpp:679] Received reply for offer 201203290030-0-27
I0329 00:31:17.942702 21855 master.cpp:1403] Filtered slave 201203290030-0-0 for framework 201203290030-0-0000 for 1 seconds
I0329 00:31:19.939934 21855 master.cpp:1184] Sending 1 offers to framework 201203290030-0-0000
I0329 00:31:19.940146 21855 master.cpp:1184] Sending 1 offers to framework 201203290030-0-0001
I0329 00:31:19.941580 21855 master.cpp:679] Received reply for offer 201203290030-0-28
I0329 00:31:19.941741 21855 master.cpp:1403] Filtered slave 201203290030-0-1 for framework 201203290030-0-0000 for 1 seconds
I0329 00:31:19.942008 21855 master.cpp:679] Received reply for offer 201203290030-0-29
I0329 00:31:19.942200 21855 master.cpp:1184] Sending 1 offers to framework 201203290030-0-0001
I0329 00:31:19.942344 21855 master.cpp:1403] Filtered slave 201203290030-0-0 for framework 201203290030-0-0001 for 1 seconds
I0329 00:31:19.943500 21855 master.cpp:679] Received reply for offer 201203290030-0-30
I0329 00:31:19.943694 21855 master.cpp:1184] Sending 1 offers to framework 201203290030-0-0000
I0329 00:31:19.943819 21855 master.cpp:1403] Filtered slave 201203290030-0-1 for framework 201203290030-0-0001 for 1 seconds
I0329 00:31:19.944911 21855 master.cpp:679] Received reply for offer 201203290030-0-31
I0329 00:31:19.945153 21855 master.cpp:1403] Filtered slave 201203290030-0-0 for framework 201203290030-0-0000 for 1 seconds
I0329 00:31:20.942127 21855 master.cpp:1184] Sending 1 offers to framework 201203290030-0-0000
I0329 00:31:20.943761 21855 master.cpp:679] Received reply for offer 201203290030-0-32
I0329 00:31:20.943863 21855 master.cpp:1403] Filtered slave 201203290030-0-1 for framework 201203290030-0-0000 for 1 seconds
I0329 00:31:21.943992 21855 master.cpp:1184] Sending 2 offers to framework 201203290030-0-0001
I0329 00:31:21.945787 21855 master.cpp:679] Received reply for offer 201203290030-0-33
I0329 00:31:21.945941 21855 master.cpp:1403] Filtered slave 201203290030-0-0 for framework 201203290030-0-0001 for 1 seconds
I0329 00:31:21.946223 21855 master.cpp:679] Received reply for offer 201203290030-0-34
I0329 00:31:21.946406 21855 master.cpp:1184] Sending 1 offers to framework 201203290030-0-0000
I0329 00:31:21.946547 21855 master.cpp:1403] Filtered slave 201203290030-0-1 for framework 201203290030-0-0001 for 1 seconds
I0329 00:31:21.947721 21855 master.cpp:679] Received reply for offer 201203290030-0-35
I0329 00:31:21.947888 21855 master.cpp:1403] Filtered slave 201203290030-0-0 for framework 201203290030-0-0000 for 1 seconds
I0329 00:31:22.945914 21855 master.cpp:1184] Sending 1 offers to framework 201203290030-0-0000
I0329 00:31:22.947571 21855 master.cpp:679] Received reply for offer 201203290030-0-36
I0329 00:31:22.947718 21855 master.cpp:1403] Filtered slave 201203290030-0-1 for framework 201203290030-0-0000 for 1 seconds
I0329 00:31:23.947811 21855 master.cpp:1184] Sending 2 offers to framework 201203290030-0-0001
I0329 00:31:23.949727 21855 master.cpp:679] Received reply for offer 201203290030-0-37
I0329 00:31:23.949879 21855 master.cpp:1403] Filtered slave 201203290030-0-0 for framework 201203290030-0-0001 for 1 seconds
I0329 00:31:23.950153 21855 master.cpp:679] Received reply for offer 201203290030-0-38
I0329 00:31:23.950336 21855 master.cpp:1184] Sending 1 offers to framework 201203290030-0-0000
I0329 00:31:23.950479 21855 master.cpp:1403] Filtered slave 201203290030-0-1 for framework 201203290030-0-0001 for 1 seconds
I0329 00:31:23.951648 21855 master.cpp:679] Received reply for offer 201203290030-0-39
I0329 00:31:23.951812 21855 master.cpp:1403] Filtered slave 201203290030-0-0 for framework 201203290030-0-0000 for 1 seconds
I0329 00:31:24.949863 21855 master.cpp:1184] Sending 1 offers to framework 201203290030-0-0000
I0329 00:31:24.951454 21855 master.cpp:679] Received reply for offer 201203290030-0-40
I0329 00:31:24.951604 21855 master.cpp:1403] Filtered slave 201203290030-0-1 for framework 201203290030-0-0000 for 1 seconds
I0329 00:31:25.951624 21855 master.cpp:1184] Sending 2 offers to framework 201203290030-0-0001
I0329 00:31:25.953325 21855 master.cpp:679] Received reply for offer 201203290030-0-41
I0329 00:31:25.953420 21855 master.cpp:1403] Filtered slave 201203290030-0-0 for framework 201203290030-0-0001 for 1 seconds
I0329 00:31:25.996528 21855 master.cpp:679] Received reply for offer 201203290030-0-42
I0329 00:31:26.037154 21855 master.cpp:1184] Sending 1 offers to framework 201203290030-0-0000
I0329 00:31:26.037402 21855 master.cpp:1403] Filtered slave 201203290030-0-1 for framework 201203290030-0-0001 for 1 seconds
I0329 00:31:26.038522 21855 master.cpp:679] Received reply for offer 201203290030-0-43
I0329 00:31:26.038684 21855 master.cpp:1403] Filtered slave 201203290030-0-0 for framework 201203290030-0-0000 for 1 seconds
I0329 00:31:26.953625 21855 master.cpp:1184] Sending 1 offers to framework 201203290030-0-0000
I0329 00:31:26.955157 21855 master.cpp:679] Received reply for offer 201203290030-0-44
I0329 00:31:26.955310 21855 master.cpp:1403] Filtered slave 201203290030-0-1 for framework 201203290030-0-0000 for 1 seconds
I0329 00:31:27.955361 21855 master.cpp:1184] Sending 2 offers to framework 201203290030-0-0001
I0329 00:31:27.957088 21855 master.cpp:679] Received reply for offer 201203290030-0-45
I0329 00:31:27.957300 21855 master.cpp:1403] Filtered slave 201203290030-0-0 for framework 201203290030-0-0001 for 1 seconds
I0329 00:31:27.957770 21855 master.cpp:679] Received reply for offer 201203290030-0-46
I0329 00:31:27.958294 21855 master.cpp:1184] Sending 1 offers to framework 201203290030-0-0000
I0329 00:31:27.958619 21855 master.cpp:1403] Filtered slave 201203290030-0-1 for framework 201203290030-0-0001 for 1 seconds
I0329 00:31:27.959810 21855 master.cpp:679] Received reply for offer 201203290030-0-47
I0329 00:31:27.959987 21855 master.cpp:1403] Filtered slave 201203290030-0-0 for framework 201203290030-0-0000 for 1 seconds
I0329 00:31:28.956681 21855 master.cpp:1184] Sending 1 offers to framework 201203290030-0-0000
I0329 00:31:28.958282 21855 master.cpp:679] Received reply for offer 201203290030-0-48
I0329 00:31:28.958433 21855 master.cpp:1403] Filtered slave 201203290030-0-1 for framework 201203290030-0-0000 for 1 seconds
I0329 00:31:29.958499 21855 master.cpp:1184] Sending 2 offers to framework 201203290030-0-0001
I0329 00:31:29.960360 21855 master.cpp:679] Received reply for offer 201203290030-0-49
I0329 00:31:29.960587 21855 master.cpp:1403] Filtered slave 201203290030-0-0 for framework 201203290030-0-0001 for 1 seconds
I0329 00:31:29.960886 21855 master.cpp:679] Received reply for offer 201203290030-0-50
I0329 00:31:29.961135 21855 master.cpp:1184] Sending 1 offers to framework 201203290030-0-0000
I0329 00:31:29.961304 21855 master.cpp:1403] Filtered slave 201203290030-0-1 for framework 201203290030-0-0001 for 1 seconds
I0329 00:31:29.962436 21855 master.cpp:679] Received reply for offer 201203290030-0-51
I0329 00:31:29.962615 21855 master.cpp:1403] Filtered slave 201203290030-0-0 for framework 201203290030-0-0000 for 1 seconds
I0329 00:31:30.960628 21855 master.cpp:1184] Sending 1 offers to framework 201203290030-0-0000
I0329 00:31:30.962293 21855 master.cpp:679] Received reply for offer 201203290030-0-52
I0329 00:31:30.962389 21855 master.cpp:1403] Filtered slave 201203290030-0-1 for framework 201203290030-0-0000 for 1 seconds
I0329 00:31:31.961364 21855 master.cpp:1184] Sending 2 offers to framework 201203290030-0-0001
I0329 00:31:31.963165 21855 master.cpp:679] Received reply for offer 201203290030-0-53
I0329 00:31:31.963320 21855 master.cpp:1403] Filtered slave 201203290030-0-0 for framework 201203290030-0-0001 for 1 seconds
I0329 00:31:31.963621 21855 master.cpp:679] Received reply for offer 201203290030-0-54
I0329 00:31:31.963896 21855 master.cpp:1184] Sending 1 offers to framework 201203290030-0-0000
I0329 00:31:31.964054 21855 master.cpp:1403] Filtered slave 201203290030-0-1 for framework 201203290030-0-0001 for 1 seconds
I0329 00:31:31.965112 21855 master.cpp:679] Received reply for offer 201203290030-0-55
I0329 00:31:31.965276 21855 master.cpp:1403] Filtered slave 201203290030-0-0 for framework 201203290030-0-0000 for 1 seconds
I0329 00:31:32.963301 21855 master.cpp:1184] Sending 1 offers to framework 201203290030-0-0000
I0329 00:31:32.964813 21855 master.cpp:679] Received reply for offer 201203290030-0-56
I0329 00:31:32.964962 21855 master.cpp:1403] Filtered slave 201203290030-0-1 for framework 201203290030-0-0000 for 1 seconds
I0329 00:31:33.965042 21855 master.cpp:1184] Sending 2 offers to framework 201203290030-0-0001
I0329 00:31:33.966784 21855 master.cpp:679] Received reply for offer 201203290030-0-57
I0329 00:31:33.966936 21855 master.cpp:1403] Filtered slave 201203290030-0-0 for framework 201203290030-0-0001 for 1 seconds
I0329 00:31:33.967226 21855 master.cpp:679] Received reply for offer 201203290030-0-58
I0329 00:31:33.967499 21855 master.cpp:1184] Sending 1 offers to framework 201203290030-0-0000
I0329 00:31:33.967957 21855 master.cpp:1403] Filtered slave 201203290030-0-1 for framework 201203290030-0-0001 for 1 seconds
I0329 00:31:33.969022 21855 master.cpp:679] Received reply for offer 201203290030-0-59
I0329 00:31:33.969192 21855 master.cpp:1403] Filtered slave 201203290030-0-0 for framework 201203290030-0-0000 for 1 seconds
I0329 00:31:34.967241 21855 master.cpp:1184] Sending 1 offers to framework 201203290030-0-0000
I0329 00:31:34.968833 21855 master.cpp:679] Received reply for offer 201203290030-0-60
I0329 00:31:34.969074 21855 master.cpp:1403] Filtered slave 201203290030-0-1 for framework 201203290030-0-0000 for 1 seconds
I0329 00:31:35.969073 21855 master.cpp:1184] Sending 2 offers to framework 201203290030-0-0001
I0329 00:31:35.970851 21855 master.cpp:679] Received reply for offer 201203290030-0-61
I0329 00:31:35.970948 21855 master.cpp:1403] Filtered slave 201203290030-0-0 for framework 201203290030-0-0001 for 1 seconds
I0329 00:31:36.019664 21855 master.cpp:679] Received reply for offer 201203290030-0-62
I0329 00:31:36.060791 21855 master.cpp:1184] Sending 1 offers to framework 201203290030-0-0000
I0329 00:31:36.061017 21855 master.cpp:1403] Filtered slave 201203290030-0-1 for framework 201203290030-0-0001 for 1 seconds
I0329 00:31:36.061974 21855 master.cpp:679] Received reply for offer 201203290030-0-63
I0329 00:31:36.062501 21855 master.cpp:1403] Filtered slave 201203290030-0-0 for framework 201203290030-0-0000 for 1 seconds
I0329 00:31:36.971072 21855 master.cpp:1184] Sending 1 offers to framework 201203290030-0-0000
I0329 00:31:36.972570 21855 master.cpp:679] Received reply for offer 201203290030-0-64
I0329 00:31:36.972719 21855 master.cpp:1403] Filtered slave 201203290030-0-1 for framework 201203290030-0-0000 for 1 seconds
I0329 00:31:37.972815 21855 master.cpp:1184] Sending 2 offers to framework 201203290030-0-0001
I0329 00:31:37.974659 21855 master.cpp:679] Received reply for offer 201203290030-0-65
I0329 00:31:37.974813 21855 master.cpp:1403] Filtered slave 201203290030-0-0 for framework 201203290030-0-0001 for 1 seconds
I0329 00:31:37.975136 21855 master.cpp:679] Received reply for offer 201203290030-0-66
I0329 00:31:37.975406 21855 master.cpp:1184] Sending 1 offers to framework 201203290030-0-0000
I0329 00:31:37.975874 21855 master.cpp:1403] Filtered slave 201203290030-0-1 for framework 201203290030-0-0001 for 1 seconds
I0329 00:31:37.976996 21855 master.cpp:679] Received reply for offer 201203290030-0-67
I0329 00:31:37.977165 21855 master.cpp:1403] Filtered slave 201203290030-0-0 for framework 201203290030-0-0000 for 1 seconds
I0329 00:31:38.975222 21855 master.cpp:1184] Sending 1 offers to framework 201203290030-0-0000
I0329 00:31:38.975657 21855 master.cpp:1184] Sending 1 offers to framework 201203290030-0-0001
I0329 00:31:38.977042 21855 master.cpp:679] Received reply for offer 201203290030-0-68
I0329 00:31:38.977202 21855 master.cpp:1403] Filtered slave 201203290030-0-1 for framework 201203290030-0-0000 for 1 seconds
I0329 00:31:38.977469 21855 master.cpp:679] Received reply for offer 201203290030-0-69
I0329 00:31:38.977637 21855 master.cpp:1403] Filtered slave 201203290030-0-0 for framework 201203290030-0-0001 for 1 seconds
I0329 00:31:39.977684 21855 master.cpp:1184] Sending 1 offers to framework 201203290030-0-0000
I0329 00:31:39.977885 21855 master.cpp:1184] Sending 1 offers to framework 201203290030-0-0001
I0329 00:31:39.979251 21855 master.cpp:679] Received reply for offer 201203290030-0-70
I0329 00:31:39.979420 21855 master.cpp:1403] Filtered slave 201203290030-0-0 for framework 201203290030-0-0000 for 1 seconds
I0329 00:31:39.979867 21855 master.cpp:679] Received reply for offer 201203290030-0-71
I0329 00:31:39.980039 21855 master.cpp:1403] Filtered slave 201203290030-0-1 for framework 201203290030-0-0001 for 1 seconds
I0329 00:31:40.980095 21855 master.cpp:1184] Sending 1 offers to framework 201203290030-0-0000
I0329 00:31:40.980259 21855 master.cpp:1184] Sending 1 offers to framework 201203290030-0-0001
I0329 00:31:40.981644 21855 master.cpp:679] Received reply for offer 201203290030-0-72
I0329 00:31:41.031344 21855 master.cpp:1403] Filtered slave 201203290030-0-1 for framework 201203290030-0-0000 for 1 seconds
I0329 00:31:41.064199 21855 master.cpp:679] Received reply for offer 201203290030-0-73
I0329 00:31:41.064525 21855 master.cpp:1403] Filtered slave 201203290030-0-0 for framework 201203290030-0-0001 for 1 seconds
I0329 00:31:41.982352 21855 master.cpp:1184] Sending 1 offers to framework 201203290030-0-0000
I0329 00:31:41.982563 21855 master.cpp:1184] Sending 1 offers to framework 201203290030-0-0001
I0329 00:31:41.984014 21855 master.cpp:679] Received reply for offer 201203290030-0-74
I0329 00:31:41.984158 21855 master.cpp:1403] Filtered slave 201203290030-0-0 for framework 201203290030-0-0000 for 1 seconds
I0329 00:31:41.984514 21855 master.cpp:679] Received reply for offer 201203290030-0-75
I0329 00:31:41.984695 21855 master.cpp:1403] Filtered slave 201203290030-0-1 for framework 201203290030-0-0001 for 1 seconds
I0329 00:31:42.984683 21855 master.cpp:1184] Sending 1 offers to framework 201203290030-0-0000
I0329 00:31:42.984874 21855 master.cpp:1184] Sending 1 offers to framework 201203290030-0-0001
I0329 00:31:42.986278 21855 master.cpp:679] Received reply for offer 201203290030-0-76
I0329 00:31:42.986445 21855 master.cpp:1403] Filtered slave 201203290030-0-1 for framework 201203290030-0-0000 for 1 seconds
I0329 00:31:42.986661 21855 master.cpp:679] Received reply for offer 201203290030-0-77
I0329 00:31:42.986826 21855 master.cpp:1403] Filtered slave 201203290030-0-0 for framework 201203290030-0-0001 for 1 seconds
I0329 00:31:43.987287 21855 master.cpp:1184] Sending 1 offers to framework 201203290030-0-0000
I0329 00:31:43.987490 21855 master.cpp:1184] Sending 1 offers to framework 201203290030-0-0001
I0329 00:31:43.988936 21855 master.cpp:679] Received reply for offer 201203290030-0-78
I0329 00:31:43.989104 21855 master.cpp:1403] Filtered slave 201203290030-0-0 for framework 201203290030-0-0000 for 1 seconds
I0329 00:31:43.989320 21855 master.cpp:679] Received reply for offer 201203290030-0-79
I0329 00:31:43.989483 21855 master.cpp:1403] Filtered slave 201203290030-0-1 for framework 201203290030-0-0001 for 1 seconds
I0329 00:31:44.989539 21855 master.cpp:1184] Sending 1 offers to framework 201203290030-0-0000
I0329 00:31:44.989740 21855 master.cpp:1184] Sending 1 offers to framework 201203290030-0-0001
I0329 00:31:44.991135 21855 master.cpp:679] Received reply for offer 201203290030-0-80
I0329 00:31:44.991282 21855 master.cpp:1403] Filtered slave 201203290030-0-1 for framework 201203290030-0-0000 for 1 seconds
I0329 00:31:44.991555 21855 master.cpp:679] Received reply for offer 201203290030-0-81
I0329 00:31:44.991719 21855 master.cpp:1403] Filtered slave 201203290030-0-0 for framework 201203290030-0-0001 for 1 seconds
I0329 00:31:45.991761 21855 master.cpp:1184] Sending 1 offers to framework 201203290030-0-0000
I0329 00:31:45.992152 21855 master.cpp:1184] Sending 1 offers to framework 201203290030-0-0001
I0329 00:31:45.993451 21855 master.cpp:679] Received reply for offer 201203290030-0-82
I0329 00:31:46.059789 21855 master.cpp:1403] Filtered slave 201203290030-0-0 for framework 201203290030-0-0000 for 1 seconds
I0329 00:31:46.101205 21855 master.cpp:679] Received reply for offer 201203290030-0-83
I0329 00:31:46.101577 21855 master.cpp:1403] Filtered slave 201203290030-0-1 for framework 201203290030-0-0001 for 1 seconds
I0329 00:31:46.994161 21855 master.cpp:1184] Sending 1 offers to framework 201203290030-0-0000
I0329 00:31:46.994375 21855 master.cpp:1184] Sending 1 offers to framework 201203290030-0-0001
I0329 00:31:46.995803 21855 master.cpp:679] Received reply for offer 201203290030-0-84
I0329 00:31:46.995949 21855 master.cpp:1403] Filtered slave 201203290030-0-1 for framework 201203290030-0-0000 for 1 seconds
I0329 00:31:46.996229 21855 master.cpp:679] Received reply for offer 201203290030-0-85
I0329 00:31:46.996402 21855 master.cpp:1403] Filtered slave 201203290030-0-0 for framework 201203290030-0-0001 for 1 seconds
I0329 00:31:47.996580 21855 master.cpp:1184] Sending 1 offers to framework 201203290030-0-0000
I0329 00:31:47.996767 21855 master.cpp:1184] Sending 1 offers to framework 201203290030-0-0001
I0329 00:31:47.998330 21855 master.cpp:679] Received reply for offer 201203290030-0-86
I0329 00:31:47.998500 21855 master.cpp:1403] Filtered slave 201203290030-0-0 for framework 201203290030-0-0000 for 1 seconds
I0329 00:31:47.998986 21855 master.cpp:679] Received reply for offer 201203290030-0-87
I0329 00:31:47.999176 21855 master.cpp:1403] Filtered slave 201203290030-0-1 for framework 201203290030-0-0001 for 1 seconds
I0329 00:31:48.999286 21855 master.cpp:1184] Sending 1 offers to framework 201203290030-0-0000
I0329 00:31:48.999467 21855 master.cpp:1184] Sending 1 offers to framework 201203290030-0-0001
I0329 00:31:49.000978 21855 master.cpp:679] Received reply for offer 201203290030-0-88
I0329 00:31:49.001147 21855 master.cpp:1403] Filtered slave 201203290030-0-1 for framework 201203290030-0-0000 for 1 seconds
I0329 00:31:49.001664 21855 master.cpp:679] Received reply for offer 201203290030-0-89
I0329 00:31:49.001947 21855 master.cpp:1403] Filtered slave 201203290030-0-0 for framework 201203290030-0-0001 for 1 seconds
I0329 00:31:50.001920 21855 master.cpp:1184] Sending 1 offers to framework 201203290030-0-0000
I0329 00:31:50.002110 21855 master.cpp:1184] Sending 1 offers to framework 201203290030-0-0001
I0329 00:31:50.003757 21855 master.cpp:679] Received reply for offer 201203290030-0-90
I0329 00:31:50.003942 21855 master.cpp:1403] Filtered slave 201203290030-0-0 for framework 201203290030-0-0000 for 1 seconds
I0329 00:31:50.004339 21855 master.cpp:679] Received reply for offer 201203290030-0-91
I0329 00:31:50.004526 21855 master.cpp:1403] Filtered slave 201203290030-0-1 for framework 201203290030-0-0001 for 1 seconds
I0329 00:31:51.004570 21855 master.cpp:1184] Sending 1 offers to framework 201203290030-0-0000
I0329 00:31:51.004856 21855 master.cpp:1184] Sending 1 offers to framework 201203290030-0-0001
I0329 00:31:51.006166 21855 master.cpp:679] Received reply for offer 201203290030-0-92
I0329 00:31:51.055004 21855 master.cpp:1403] Filtered slave 201203290030-0-1 for framework 201203290030-0-0000 for 1 seconds
I0329 00:31:51.087858 21855 master.cpp:679] Received reply for offer 201203290030-0-93
I0329 00:31:51.088166 21855 master.cpp:1403] Filtered slave 201203290030-0-0 for framework 201203290030-0-0001 for 1 seconds
I0329 00:31:52.007019 21855 master.cpp:1184] Sending 1 offers to framework 201203290030-0-0000
I0329 00:31:52.007366 21855 master.cpp:1184] Sending 1 offers to framework 201203290030-0-0001
I0329 00:31:52.008605 21855 master.cpp:679] Received reply for offer 201203290030-0-94
I0329 00:31:52.008788 21855 master.cpp:1403] Filtered slave 201203290030-0-0 for framework 201203290030-0-0000 for 1 seconds
I0329 00:31:52.009105 21855 master.cpp:679] Received reply for offer 201203290030-0-95
I0329 00:31:52.009294 21855 master.cpp:1403] Filtered slave 201203290030-0-1 for framework 201203290030-0-0001 for 1 seconds
I0329 00:31:53.009377 21855 master.cpp:1184] Sending 1 offers to framework 201203290030-0-0000
I0329 00:31:53.009678 21855 master.cpp:1184] Sending 1 offers to framework 201203290030-0-0001
I0329 00:31:53.011252 21855 master.cpp:679] Received reply for offer 201203290030-0-96
I0329 00:31:53.011440 21855 master.cpp:1403] Filtered slave 201203290030-0-1 for framework 201203290030-0-0000 for 1 seconds
I0329 00:31:53.011724 21855 master.cpp:679] Received reply for offer 201203290030-0-97
I0329 00:31:53.011911 21855 master.cpp:1403] Filtered slave 201203290030-0-0 for framework 201203290030-0-0001 for 1 seconds
I0329 00:31:54.011988 21855 master.cpp:1184] Sending 1 offers to framework 201203290030-0-0000
I0329 00:31:54.012506 21855 master.cpp:1184] Sending 1 offers to framework 201203290030-0-0001
I0329 00:31:54.013910 21855 master.cpp:679] Received reply for offer 201203290030-0-98
I0329 00:31:54.014091 21855 master.cpp:1403] Filtered slave 201203290030-0-0 for framework 201203290030-0-0000 for 1 seconds
I0329 00:31:54.014493 21855 master.cpp:679] Received reply for offer 201203290030-0-99
I0329 00:31:54.014678 21855 master.cpp:1403] Filtered slave 201203290030-0-1 for framework 201203290030-0-0001 for 1 seconds
I0329 00:31:55.014715 21855 master.cpp:1184] Sending 1 offers to framework 201203290030-0-0000
I0329 00:31:55.014968 21855 master.cpp:1184] Sending 1 offers to framework 201203290030-0-0001
I0329 00:31:55.016388 21855 master.cpp:679] Received reply for offer 201203290030-0-100
I0329 00:31:55.016571 21855 master.cpp:1403] Filtered slave 201203290030-0-1 for framework 201203290030-0-0000 for 1 seconds
I0329 00:31:55.016988 21855 master.cpp:679] Received reply for offer 201203290030-0-101
I0329 00:31:55.017266 21855 master.cpp:1403] Filtered slave 201203290030-0-0 for framework 201203290030-0-0001 for 1 seconds
I0329 00:31:56.017252 21855 master.cpp:1184] Sending 1 offers to framework 201203290030-0-0000
I0329 00:31:56.017490 21855 master.cpp:1184] Sending 1 offers to framework 201203290030-0-0001
I0329 00:31:56.018900 21855 master.cpp:679] Received reply for offer 201203290030-0-102
I0329 00:31:56.066936 21855 master.cpp:1403] Filtered slave 201203290030-0-0 for framework 201203290030-0-0000 for 1 seconds
I0329 00:31:56.099673 21855 master.cpp:679] Received reply for offer 201203290030-0-103
I0329 00:31:56.099874 21855 master.cpp:1403] Filtered slave 201203290030-0-1 for framework 201203290030-0-0001 for 1 seconds
I0329 00:31:57.019686 21855 master.cpp:1184] Sending 1 offers to framework 201203290030-0-0000
I0329 00:31:57.019870 21855 master.cpp:1184] Sending 1 offers to framework 201203290030-0-0001
I0329 00:31:57.021311 21855 master.cpp:679] Received reply for offer 201203290030-0-104
I0329 00:31:57.021481 21855 master.cpp:1403] Filtered slave 201203290030-0-1 for framework 201203290030-0-0000 for 1 seconds
I0329 00:31:57.021955 21855 master.cpp:679] Received reply for offer 201203290030-0-105
I0329 00:31:57.022130 21855 master.cpp:1403] Filtered slave 201203290030-0-0 for framework 201203290030-0-0001 for 1 seconds
I0329 00:31:58.022253 21855 master.cpp:1184] Sending 1 offers to framework 201203290030-0-0000
I0329 00:31:58.022430 21855 master.cpp:1184] Sending 1 offers to framework 201203290030-0-0001
I0329 00:31:58.023938 21855 master.cpp:679] Received reply for offer 201203290030-0-106
I0329 00:31:58.024149 21855 master.cpp:1403] Filtered slave 201203290030-0-0 for framework 201203290030-0-0000 for 1 seconds
I0329 00:31:58.024278 21855 master.cpp:679] Received reply for offer 201203290030-0-107
I0329 00:31:58.024535 21855 master.cpp:1403] Filtered slave 201203290030-0-1 for framework 201203290030-0-0001 for 1 seconds
I0329 00:31:59.024350 21855 master.cpp:1184] Sending 1 offers to framework 201203290030-0-0000
I0329 00:31:59.024540 21855 master.cpp:1184] Sending 1 offers to framework 201203290030-0-0001
I0329 00:31:59.026051 21855 master.cpp:679] Received reply for offer 201203290030-0-108
I0329 00:31:59.026202 21855 master.cpp:1403] Filtered slave 201203290030-0-1 for framework 201203290030-0-0000 for 1 seconds
I0329 00:31:59.026600 21855 master.cpp:679] Received reply for offer 201203290030-0-109
I0329 00:31:59.026747 21855 master.cpp:1403] Filtered slave 201203290030-0-0 for framework 201203290030-0-0001 for 1 seconds
I0329 00:32:00.026903 21855 master.cpp:1184] Sending 1 offers to framework 201203290030-0-0000
I0329 00:32:00.027140 21855 master.cpp:1184] Sending 1 offers to framework 201203290030-0-0001
I0329 00:32:00.028560 21855 master.cpp:679] Received reply for offer 201203290030-0-110
I0329 00:32:00.028728 21855 master.cpp:1403] Filtered slave 201203290030-0-0 for framework 201203290030-0-0000 for 1 seconds
I0329 00:32:00.029080 21855 master.cpp:679] Received reply for offer 201203290030-0-111
I0329 00:32:00.029250 21855 master.cpp:1403] Filtered slave 201203290030-0-1 for framework 201203290030-0-0001 for 1 seconds
I0329 00:32:01.029412 21855 master.cpp:1184] Sending 1 offers to framework 201203290030-0-0000
I0329 00:32:01.029579 21855 master.cpp:1184] Sending 1 offers to framework 201203290030-0-0001
I0329 00:32:01.030930 21855 master.cpp:679] Received reply for offer 201203290030-0-112
I0329 00:32:01.070263 21855 master.cpp:1403] Filtered slave 201203290030-0-1 for framework 201203290030-0-0000 for 1 seconds
I0329 00:32:01.111064 21855 master.cpp:679] Received reply for offer 201203290030-0-113
I0329 00:32:01.111379 21855 master.cpp:1403] Filtered slave 201203290030-0-0 for framework 201203290030-0-0001 for 1 seconds
I0329 00:32:02.030792 21855 master.cpp:1184] Sending 1 offers to framework 201203290030-0-0000
I0329 00:32:02.031031 21855 master.cpp:1184] Sending 1 offers to framework 201203290030-0-0001
I0329 00:32:02.032466 21855 master.cpp:679] Received reply for offer 201203290030-0-114
I0329 00:32:02.032634 21855 master.cpp:1403] Filtered slave 201203290030-0-0 for framework 201203290030-0-0000 for 1 seconds
I0329 00:32:02.032831 21855 master.cpp:679] Received reply for offer 201203290030-0-115
I0329 00:32:02.032997 21855 master.cpp:1403] Filtered slave 201203290030-0-1 for framework 201203290030-0-0001 for 1 seconds
I0329 00:32:03.033030 21855 master.cpp:1184] Sending 1 offers to framework 201203290030-0-0000
I0329 00:32:03.033226 21855 master.cpp:1184] Sending 1 offers to framework 201203290030-0-0001
I0329 00:32:03.034577 21855 master.cpp:679] Received reply for offer 201203290030-0-116
I0329 00:32:03.034742 21855 master.cpp:1403] Filtered slave 201203290030-0-1 for framework 201203290030-0-0000 for 1 seconds
I0329 00:32:03.035037 21855 master.cpp:679] Received reply for offer 201203290030-0-117
I0329 00:32:03.035311 21855 master.cpp:1403] Filtered slave 201203290030-0-0 for framework 201203290030-0-0001 for 1 seconds
I0329 00:32:04.035307 21855 master.cpp:1184] Sending 1 offers to framework 201203290030-0-0000
I0329 00:32:04.035502 21855 master.cpp:1184] Sending 1 offers to framework 201203290030-0-0001
I0329 00:32:04.036809 21855 master.cpp:679] Received reply for offer 201203290030-0-118
I0329 00:32:04.036975 21855 master.cpp:1403] Filtered slave 201203290030-0-0 for framework 201203290030-0-0000 for 1 seconds
I0329 00:32:04.037268 21855 master.cpp:679] Received reply for offer 201203290030-0-119
I0329 00:32:04.037446 21855 master.cpp:1403] Filtered slave 201203290030-0-1 for framework 201203290030-0-0001 for 1 seconds
I0329 00:32:05.037500 21855 master.cpp:1184] Sending 1 offers to framework 201203290030-0-0000
I0329 00:32:05.037742 21855 master.cpp:1184] Sending 1 offers to framework 201203290030-0-0001
I0329 00:32:05.039247 21855 master.cpp:679] Received reply for offer 201203290030-0-120
I0329 00:32:05.039409 21855 master.cpp:1403] Filtered slave 201203290030-0-1 for framework 201203290030-0-0000 for 1 seconds
I0329 00:32:05.039765 21855 master.cpp:679] Received reply for offer 201203290030-0-121
I0329 00:32:05.039924 21855 master.cpp:1403] Filtered slave 201203290030-0-0 for framework 201203290030-0-0001 for 1 seconds
I0329 00:32:06.039325 21855 master.cpp:1184] Sending 1 offers to framework 201203290030-0-0000
I0329 00:32:06.039551 21855 master.cpp:1184] Sending 1 offers to framework 201203290030-0-0001
I0329 00:32:06.040952 21855 master.cpp:679] Received reply for offer 201203290030-0-122
I0329 00:32:06.098713 21855 master.cpp:1403] Filtered slave 201203290030-0-0 for framework 201203290030-0-0000 for 1 seconds
I0329 00:32:06.139425 21855 master.cpp:679] Received reply for offer 201203290030-0-123
I0329 00:32:06.139781 21855 master.cpp:1403] Filtered slave 201203290030-0-1 for framework 201203290030-0-0001 for 1 seconds
I0329 00:32:07.041705 21855 master.cpp:1184] Sending 1 offers to framework 201203290030-0-0000
I0329 00:32:07.041904 21855 master.cpp:1184] Sending 1 offers to framework 201203290030-0-0001
I0329 00:32:07.043288 21855 master.cpp:679] Received reply for offer 201203290030-0-124
I0329 00:32:07.043448 21855 master.cpp:1403] Filtered slave 201203290030-0-1 for framework 201203290030-0-0000 for 1 seconds
I0329 00:32:07.043772 21855 master.cpp:679] Received reply for offer 201203290030-0-125
I0329 00:32:07.043936 21855 master.cpp:1403] Filtered slave 201203290030-0-0 for framework 201203290030-0-0001 for 1 seconds
I0329 00:32:08.043342 21855 master.cpp:1184] Sending 1 offers to framework 201203290030-0-0000
I0329 00:32:08.043550 21855 master.cpp:1184] Sending 1 offers to framework 201203290030-0-0001
I0329 00:32:08.044858 21855 master.cpp:679] Received reply for offer 201203290030-0-126
I0329 00:32:08.045014 21855 master.cpp:1403] Filtered slave 201203290030-0-0 for framework 201203290030-0-0000 for 1 seconds
I0329 00:32:08.045367 21855 master.cpp:679] Received reply for offer 201203290030-0-127
I0329 00:32:08.045539 21855 master.cpp:1403] Filtered slave 201203290030-0-1 for framework 201203290030-0-0001 for 1 seconds
I0329 00:32:09.045558 21855 master.cpp:1184] Sending 1 offers to framework 201203290030-0-0000
I0329 00:32:09.045768 21855 master.cpp:1184] Sending 1 offers to framework 201203290030-0-0001
I0329 00:32:09.047075 21855 master.cpp:679] Received reply for offer 201203290030-0-128
I0329 00:32:09.047251 21855 master.cpp:1403] Filtered slave 201203290030-0-1 for framework 201203290030-0-0000 for 1 seconds
I0329 00:32:09.047626 21855 master.cpp:679] Received reply for offer 201203290030-0-129
I0329 00:32:09.047786 21855 master.cpp:1403] Filtered slave 201203290030-0-0 for framework 201203290030-0-0001 for 1 seconds
I0329 00:32:10.047371 21855 master.cpp:1184] Sending 1 offers to framework 201203290030-0-0000
I0329 00:32:10.047574 21855 master.cpp:1184] Sending 1 offers to framework 201203290030-0-0001
I0329 00:32:10.048943 21855 master.cpp:679] Received reply for offer 201203290030-0-130
I0329 00:32:10.049095 21855 master.cpp:1403] Filtered slave 201203290030-0-0 for framework 201203290030-0-0000 for 1 seconds
I0329 00:32:10.049399 21855 master.cpp:679] Received reply for offer 201203290030-0-131
I0329 00:32:10.049558 21855 master.cpp:1403] Filtered slave 201203290030-0-1 for framework 201203290030-0-0001 for 1 seconds
I0329 00:32:11.049622 21855 master.cpp:1184] Sending 1 offers to framework 201203290030-0-0000
I0329 00:32:11.049782 21855 master.cpp:1184] Sending 1 offers to framework 201203290030-0-0001
I0329 00:32:11.051105 21855 master.cpp:679] Received reply for offer 201203290030-0-132
I0329 00:32:11.102246 21855 master.cpp:1403] Filtered slave 201203290030-0-1 for framework 201203290030-0-0000 for 1 seconds
I0329 00:32:11.142775 21855 master.cpp:679] Received reply for offer 201203290030-0-133
I0329 00:32:11.143152 21855 master.cpp:1403] Filtered slave 201203290030-0-0 for framework 201203290030-0-0001 for 1 seconds
I0329 00:32:12.051432 21855 master.cpp:1184] Sending 1 offers to framework 201203290030-0-0000
I0329 00:32:12.051627 21855 master.cpp:1184] Sending 1 offers to framework 201203290030-0-0001
I0329 00:32:12.052943 21855 master.cpp:679] Received reply for offer 201203290030-0-134
I0329 00:32:12.053096 21855 master.cpp:1403] Filtered slave 201203290030-0-0 for framework 201203290030-0-0000 for 1 seconds
I0329 00:32:12.053465 21855 master.cpp:679] Received reply for offer 201203290030-0-135
I0329 00:32:12.053632 21855 master.cpp:1403] Filtered slave 201203290030-0-1 for framework 201203290030-0-0001 for 1 seconds
I0329 00:32:13.053805 21855 master.cpp:1184] Sending 1 offers to framework 201203290030-0-0000
I0329 00:32:13.053997 21855 master.cpp:1184] Sending 1 offers to framework 201203290030-0-0001
I0329 00:32:13.055512 21855 master.cpp:679] Received reply for offer 201203290030-0-136
I0329 00:32:13.055685 21855 master.cpp:1403] Filtered slave 201203290030-0-1 for framework 201203290030-0-0000 for 1 seconds
I0329 00:32:13.056145 21855 master.cpp:679] Received reply for offer 201203290030-0-137
I0329 00:32:13.056320 21855 master.cpp:1403] Filtered slave 201203290030-0-0 for framework 201203290030-0-0001 for 1 seconds
I0329 00:32:14.055418 21855 master.cpp:1184] Sending 1 offers to framework 201203290030-0-0000
I0329 00:32:14.055608 21855 master.cpp:1184] Sending 1 offers to framework 201203290030-0-0001
I0329 00:32:14.057090 21855 master.cpp:679] Received reply for offer 201203290030-0-138
I0329 00:32:14.057260 21855 master.cpp:1403] Filtered slave 201203290030-0-0 for framework 201203290030-0-0000 for 1 seconds
I0329 00:32:14.057591 21855 master.cpp:679] Received reply for offer 201203290030-0-139
I0329 00:32:14.057759 21855 master.cpp:1403] Filtered slave 201203290030-0-1 for framework 201203290030-0-0001 for 1 seconds
I0329 00:32:15.057891 21855 master.cpp:1184] Sending 1 offers to framework 201203290030-0-0000
I0329 00:32:15.058071 21855 master.cpp:1184] Sending 1 offers to framework 201203290030-0-0001
I0329 00:32:15.060413 21855 master.cpp:679] Received reply for offer 201203290030-0-140
I0329 00:32:15.060673 21855 master.cpp:1403] Filtered slave 201203290030-0-1 for framework 201203290030-0-0000 for 1 seconds
I0329 00:32:15.061164 21855 master.cpp:679] Received reply for offer 201203290030-0-141
I0329 00:32:15.061458 21855 master.cpp:1403] Filtered slave 201203290030-0-0 for framework 201203290030-0-0001 for 1 seconds
I0329 00:32:16.060678 21855 master.cpp:1184] Sending 1 offers to framework 201203290030-0-0000
I0329 00:32:16.060972 21855 master.cpp:1184] Sending 1 offers to framework 201203290030-0-0001
I0329 00:32:16.062248 21855 master.cpp:679] Received reply for offer 201203290030-0-142
I0329 00:32:16.114068 21855 master.cpp:1403] Filtered slave 201203290030-0-0 for framework 201203290030-0-0000 for 1 seconds
I0329 00:32:16.146093 21855 master.cpp:679] Received reply for offer 201203290030-0-143
I0329 00:32:16.146420 21855 master.cpp:1403] Filtered slave 201203290030-0-1 for framework 201203290030-0-0001 for 1 seconds
I0329 00:32:17.062067 21855 master.cpp:1184] Sending 1 offers to framework 201203290030-0-0000
I0329 00:32:17.062260 21855 master.cpp:1184] Sending 1 offers to framework 201203290030-0-0001
I0329 00:32:17.063601 21855 master.cpp:679] Received reply for offer 201203290030-0-144
I0329 00:32:17.063756 21855 master.cpp:1403] Filtered slave 201203290030-0-1 for framework 201203290030-0-0000 for 1 seconds
I0329 00:32:17.064060 21855 master.cpp:679] Received reply for offer 201203290030-0-145
I0329 00:32:17.064216 21855 master.cpp:1403] Filtered slave 201203290030-0-0 for framework 201203290030-0-0001 for 1 seconds
I0329 00:32:18.064265 21855 master.cpp:1184] Sending 1 offers to framework 201203290030-0-0000
I0329 00:32:18.064453 21855 master.cpp:1184] Sending 1 offers to framework 201203290030-0-0001
I0329 00:32:18.065760 21855 master.cpp:679] Received reply for offer 201203290030-0-146
I0329 00:32:18.065912 21855 master.cpp:1403] Filtered slave 201203290030-0-0 for framework 201203290030-0-0000 for 1 seconds
I0329 00:32:18.066225 21855 master.cpp:679] Received reply for offer 201203290030-0-147
I0329 00:32:18.066381 21855 master.cpp:1403] Filtered slave 201203290030-0-1 for framework 201203290030-0-0001 for 1 seconds
I0329 00:32:19.066356 21855 master.cpp:1184] Sending 1 offers to framework 201203290030-0-0000
I0329 00:32:19.066545 21855 master.cpp:1184] Sending 1 offers to framework 201203290030-0-0001
I0329 00:32:19.067932 21855 master.cpp:679] Received reply for offer 201203290030-0-148
I0329 00:32:19.068089 21855 master.cpp:1403] Filtered slave 201203290030-0-1 for framework 201203290030-0-0000 for 1 seconds
I0329 00:32:19.068397 21855 master.cpp:679] Received reply for offer 201203290030-0-149
I0329 00:32:19.068557 21855 master.cpp:1403] Filtered slave 201203290030-0-0 for framework 201203290030-0-0001 for 1 seconds
I0329 00:32:20.068617 21855 master.cpp:1184] Sending 1 offers to framework 201203290030-0-0000
I0329 00:32:20.068828 21855 master.cpp:1184] Sending 1 offers to framework 201203290030-0-0001
I0329 00:32:20.070158 21855 master.cpp:679] Received reply for offer 201203290030-0-150
I0329 00:32:20.070324 21855 master.cpp:1403] Filtered slave 201203290030-0-0 for framework 201203290030-0-0000 for 1 seconds
I0329 00:32:20.070662 21855 master.cpp:679] Received reply for offer 201203290030-0-151
I0329 00:32:20.070832 21855 master.cpp:1403] Filtered slave 201203290030-0-1 for framework 201203290030-0-0001 for 1 seconds
I0329 00:32:21.070880 21855 master.cpp:1184] Sending 1 offers to framework 201203290030-0-0000
I0329 00:32:21.071041 21855 master.cpp:1184] Sending 1 offers to framework 201203290030-0-0001
I0329 00:32:21.072350 21855 master.cpp:679] Received reply for offer 201203290030-0-152
I0329 00:32:21.117472 21855 master.cpp:1403] Filtered slave 201203290030-0-1 for framework 201203290030-0-0000 for 1 seconds
I0329 00:32:21.149382 21855 master.cpp:679] Received reply for offer 201203290030-0-153
I0329 00:32:21.149664 21855 master.cpp:1403] Filtered slave 201203290030-0-0 for framework 201203290030-0-0001 for 1 seconds
I0329 00:32:22.073089 21855 master.cpp:1184] Sending 1 offers to framework 201203290030-0-0000
I0329 00:32:22.073379 21855 master.cpp:1184] Sending 1 offers to framework 201203290030-0-0001
I0329 00:32:22.074719 21855 master.cpp:679] Received reply for offer 201203290030-0-154
I0329 00:32:22.074862 21855 master.cpp:1403] Filtered slave 201203290030-0-0 for framework 201203290030-0-0000 for 1 seconds
I0329 00:32:22.075258 21855 master.cpp:679] Received reply for offer 201203290030-0-155
I0329 00:32:22.075413 21855 master.cpp:1403] Filtered slave 201203290030-0-1 for framework 201203290030-0-0001 for 1 seconds
I0329 00:32:23.075476 21855 master.cpp:1184] Sending 1 offers to framework 201203290030-0-0000
I0329 00:32:23.075690 21855 master.cpp:1184] Sending 1 offers to framework 201203290030-0-0001
I0329 00:32:23.077026 21855 master.cpp:679] Received reply for offer 201203290030-0-156
I0329 00:32:23.077194 21855 master.cpp:1403] Filtered slave 201203290030-0-1 for framework 201203290030-0-0000 for 1 seconds
I0329 00:32:23.077532 21855 master.cpp:679] Received reply for offer 201203290030-0-157
I0329 00:32:23.077702 21855 master.cpp:1403] Filtered slave 201203290030-0-0 for framework 201203290030-0-0001 for 1 seconds
I0329 00:32:24.077751 21855 master.cpp:1184] Sending 1 offers to framework 201203290030-0-0000
I0329 00:32:24.077951 21855 master.cpp:1184] Sending 1 offers to framework 201203290030-0-0001
I0329 00:32:24.079284 21855 master.cpp:679] Received reply for offer 201203290030-0-158
I0329 00:32:24.079450 21855 master.cpp:1403] Filtered slave 201203290030-0-0 for framework 201203290030-0-0000 for 1 seconds
I0329 00:32:24.079912 21855 master.cpp:679] Received reply for offer 201203290030-0-159
I0329 00:32:24.080083 21855 master.cpp:1403] Filtered slave 201203290030-0-1 for framework 201203290030-0-0001 for 1 seconds
I0329 00:32:25.080133 21855 master.cpp:1184] Sending 1 offers to framework 201203290030-0-0000
I0329 00:32:25.080330 21855 master.cpp:1184] Sending 1 offers to framework 201203290030-0-0001
I0329 00:32:25.081574 21855 master.cpp:679] Received reply for offer 201203290030-0-160
I0329 00:32:25.081739 21855 master.cpp:1403] Filtered slave 201203290030-0-1 for framework 201203290030-0-0000 for 1 seconds
I0329 00:32:25.082197 21855 master.cpp:679] Received reply for offer 201203290030-0-161
I0329 00:32:25.082361 21855 master.cpp:1403] Filtered slave 201203290030-0-0 for framework 201203290030-0-0001 for 1 seconds
I0329 00:32:26.082479 21855 master.cpp:1184] Sending 1 offers to framework 201203290030-0-0000
I0329 00:32:26.082641 21855 master.cpp:1184] Sending 1 offers to framework 201203290030-0-0001
I0329 00:32:26.084022 21855 master.cpp:679] Received reply for offer 201203290030-0-162
I0329 00:32:26.129358 21855 master.cpp:1403] Filtered slave 201203290030-0-0 for framework 201203290030-0-0000 for 1 seconds
I0329 00:32:26.161075 21855 master.cpp:679] Received reply for offer 201203290030-0-163
I0329 00:32:26.161383 21855 master.cpp:1403] Filtered slave 201203290030-0-1 for framework 201203290030-0-0001 for 1 seconds
I0329 00:32:27.084769 21855 master.cpp:1184] Sending 1 offers to framework 201203290030-0-0000
I0329 00:32:27.084955 21855 master.cpp:1184] Sending 1 offers to framework 201203290030-0-0001
I0329 00:32:27.086333 21855 master.cpp:679] Received reply for offer 201203290030-0-164
I0329 00:32:27.086488 21855 master.cpp:1403] Filtered slave 201203290030-0-1 for framework 201203290030-0-0000 for 1 seconds
I0329 00:32:27.086843 21855 master.cpp:679] Received reply for offer 201203290030-0-165
I0329 00:32:27.087009 21855 master.cpp:1403] Filtered slave 201203290030-0-0 for framework 201203290030-0-0001 for 1 seconds
I0329 00:32:28.087188 21855 master.cpp:1184] Sending 1 offers to framework 201203290030-0-0000
I0329 00:32:28.087355 21855 master.cpp:1184] Sending 1 offers to framework 201203290030-0-0001
I0329 00:32:28.088732 21855 master.cpp:679] Received reply for offer 201203290030-0-166
I0329 00:32:28.088886 21855 master.cpp:1403] Filtered slave 201203290030-0-0 for framework 201203290030-0-0000 for 1 seconds
I0329 00:32:28.089236 21855 master.cpp:679] Received reply for offer 201203290030-0-167
I0329 00:32:28.089426 21855 master.cpp:1403] Filtered slave 201203290030-0-1 for framework 201203290030-0-0001 for 1 seconds
I0329 00:32:29.088866 21855 master.cpp:1184] Sending 1 offers to framework 201203290030-0-0000
I0329 00:32:29.089076 21855 master.cpp:1184] Sending 1 offers to framework 201203290030-0-0001
I0329 00:32:29.090430 21855 master.cpp:679] Received reply for offer 201203290030-0-168
I0329 00:32:29.090585 21855 master.cpp:1403] Filtered slave 201203290030-0-1 for framework 201203290030-0-0000 for 1 seconds
I0329 00:32:29.091007 21855 master.cpp:679] Received reply for offer 201203290030-0-169
I0329 00:32:29.091191 21855 master.cpp:1403] Filtered slave 201203290030-0-0 for framework 201203290030-0-0001 for 1 seconds
I0329 00:32:30.091343 21855 master.cpp:1184] Sending 1 offers to framework 201203290030-0-0000
I0329 00:32:30.091531 21855 master.cpp:1184] Sending 1 offers to framework 201203290030-0-0001
I0329 00:32:30.092937 21855 master.cpp:679] Received reply for offer 201203290030-0-170
I0329 00:32:30.093092 21855 master.cpp:1403] Filtered slave 201203290030-0-0 for framework 201203290030-0-0000 for 1 seconds
I0329 00:32:30.093480 21855 master.cpp:679] Received reply for offer 201203290030-0-171
I0329 00:32:30.093649 21855 master.cpp:1403] Filtered slave 201203290030-0-1 for framework 201203290030-0-0001 for 1 seconds
I0329 00:32:31.093792 21855 master.cpp:1184] Sending 1 offers to framework 201203290030-0-0000
I0329 00:32:31.093951 21855 master.cpp:1184] Sending 1 offers to framework 201203290030-0-0001
I0329 00:32:31.095341 21855 master.cpp:679] Received reply for offer 201203290030-0-172
I0329 00:32:31.141271 21855 master.cpp:1403] Filtered slave 201203290030-0-1 for framework 201203290030-0-0000 for 1 seconds
I0329 00:32:31.172755 21855 master.cpp:679] Received reply for offer 201203290030-0-173
I0329 00:32:31.173063 21855 master.cpp:1403] Filtered slave 201203290030-0-0 for framework 201203290030-0-0001 for 1 seconds
I0329 00:32:32.095988 21855 master.cpp:1184] Sending 1 offers to framework 201203290030-0-0000
I0329 00:32:32.096187 21855 master.cpp:1184] Sending 1 offers to framework 201203290030-0-0001
I0329 00:32:32.097606 21855 master.cpp:679] Received reply for offer 201203290030-0-174
I0329 00:32:32.097761 21855 master.cpp:1403] Filtered slave 201203290030-0-0 for framework 201203290030-0-0000 for 1 seconds
I0329 00:32:32.098136 21855 master.cpp:679] Received reply for offer 201203290030-0-175
I0329 00:32:32.098304 21855 master.cpp:1403] Filtered slave 201203290030-0-1 for framework 201203290030-0-0001 for 1 seconds
I0329 00:32:33.098528 21855 master.cpp:1184] Sending 1 offers to framework 201203290030-0-0000
I0329 00:32:33.098707 21855 master.cpp:1184] Sending 1 offers to framework 201203290030-0-0001
I0329 00:32:33.100136 21855 master.cpp:679] Received reply for offer 201203290030-0-176
I0329 00:32:33.100297 21855 master.cpp:1403] Filtered slave 201203290030-0-1 for framework 201203290030-0-0000 for 1 seconds
I0329 00:32:33.100636 21855 master.cpp:679] Received reply for offer 201203290030-0-177
I0329 00:32:33.100793 21855 master.cpp:1403] Filtered slave 201203290030-0-0 for framework 201203290030-0-0001 for 1 seconds
I0329 00:32:34.100854 21855 master.cpp:1184] Sending 1 offers to framework 201203290030-0-0000
I0329 00:32:34.101052 21855 master.cpp:1184] Sending 1 offers to framework 201203290030-0-0001
I0329 00:32:34.102480 21855 master.cpp:679] Received reply for offer 201203290030-0-178
I0329 00:32:34.102637 21855 master.cpp:1403] Filtered slave 201203290030-0-0 for framework 201203290030-0-0000 for 1 seconds
I0329 00:32:34.102895 21855 master.cpp:679] Received reply for offer 201203290030-0-179
I0329 00:32:34.103052 21855 master.cpp:1403] Filtered slave 201203290030-0-1 for framework 201203290030-0-0001 for 1 seconds
I0329 00:32:35.103106 21855 master.cpp:1184] Sending 1 offers to framework 201203290030-0-0000
I0329 00:32:35.103317 21855 master.cpp:1184] Sending 1 offers to framework 201203290030-0-0001
I0329 00:32:35.104627 21855 master.cpp:679] Received reply for offer 201203290030-0-180
I0329 00:32:35.104884 21855 master.cpp:1403] Filtered slave 201203290030-0-1 for framework 201203290030-0-0000 for 1 seconds
I0329 00:32:35.105295 21855 master.cpp:679] Received reply for offer 201203290030-0-181
I0329 00:32:35.105656 21855 master.cpp:1403] Filtered slave 201203290030-0-0 for framework 201203290030-0-0001 for 1 seconds
I0329 00:32:36.105229 21855 master.cpp:1184] Sending 1 offers to framework 201203290030-0-0000
I0329 00:32:36.105387 21855 master.cpp:1184] Sending 1 offers to framework 201203290030-0-0001
I0329 00:32:36.106719 21855 master.cpp:679] Received reply for offer 201203290030-0-182
I0329 00:32:36.161309 21855 master.cpp:1403] Filtered slave 201203290030-0-0 for framework 201203290030-0-0000 for 1 seconds
I0329 00:32:36.192718 21855 master.cpp:679] Received reply for offer 201203290030-0-183
I0329 00:32:36.193121 21855 master.cpp:1403] Filtered slave 201203290030-0-1 for framework 201203290030-0-0001 for 1 seconds
I0329 00:32:37.107421 21855 master.cpp:1184] Sending 1 offers to framework 201203290030-0-0000
I0329 00:32:37.107610 21855 master.cpp:1184] Sending 1 offers to framework 201203290030-0-0001
I0329 00:32:37.108988 21855 master.cpp:679] Received reply for offer 201203290030-0-184
I0329 00:32:37.109145 21855 master.cpp:1403] Filtered slave 201203290030-0-1 for framework 201203290030-0-0000 for 1 seconds
I0329 00:32:37.109429 21855 master.cpp:679] Received reply for offer 201203290030-0-185
I0329 00:32:37.109588 21855 master.cpp:1403] Filtered slave 201203290030-0-0 for framework 201203290030-0-0001 for 1 seconds
I0329 00:32:38.109647 21855 master.cpp:1184] Sending 1 offers to framework 201203290030-0-0000
I0329 00:32:38.109839 21855 master.cpp:1184] Sending 1 offers to framework 201203290030-0-0001
I0329 00:32:38.111188 21855 master.cpp:679] Received reply for offer 201203290030-0-186
I0329 00:32:38.111333 21855 master.cpp:1403] Filtered slave 201203290030-0-0 for framework 201203290030-0-0000 for 1 seconds
I0329 00:32:38.111781 21855 master.cpp:679] Received reply for offer 201203290030-0-187
I0329 00:32:38.111925 21855 master.cpp:1403] Filtered slave 201203290030-0-1 for framework 201203290030-0-0001 for 1 seconds
I0329 00:32:39.112071 21855 master.cpp:1184] Sending 1 offers to framework 201203290030-0-0000
I0329 00:32:39.112254 21855 master.cpp:1184] Sending 1 offers to framework 201203290030-0-0001
I0329 00:32:39.113826 21855 master.cpp:679] Received reply for offer 201203290030-0-188
I0329 00:32:39.113992 21855 master.cpp:1403] Filtered slave 201203290030-0-1 for framework 201203290030-0-0000 for 1 seconds
I0329 00:32:39.114403 21855 master.cpp:679] Received reply for offer 201203290030-0-189
I0329 00:32:39.114886 21855 master.cpp:1403] Filtered slave 201203290030-0-0 for framework 201203290030-0-0001 for 1 seconds
I0329 00:32:40.114713 21855 master.cpp:1184] Sending 1 offers to framework 201203290030-0-0000
I0329 00:32:40.114902 21855 master.cpp:1184] Sending 1 offers to framework 201203290030-0-0001
I0329 00:32:40.116300 21855 master.cpp:679] Received reply for offer 201203290030-0-190
I0329 00:32:40.116518 21855 master.cpp:1403] Filtered slave 201203290030-0-0 for framework 201203290030-0-0000 for 1 seconds
I0329 00:32:40.116768 21855 master.cpp:679] Received reply for offer 201203290030-0-191
I0329 00:32:40.116951 21855 master.cpp:1403] Filtered slave 201203290030-0-1 for framework 201203290030-0-0001 for 1 seconds
I0329 00:32:41.117046 21855 master.cpp:1184] Sending 1 offers to framework 201203290030-0-0000
I0329 00:32:41.117213 21855 master.cpp:1184] Sending 1 offers to framework 201203290030-0-0001
I0329 00:32:41.118630 21855 master.cpp:679] Received reply for offer 201203290030-0-192
I0329 00:32:41.164731 21855 master.cpp:1403] Filtered slave 201203290030-0-1 for framework 201203290030-0-0000 for 1 seconds
I0329 00:32:41.196055 21855 master.cpp:679] Received reply for offer 201203290030-0-193
I0329 00:32:41.196372 21855 master.cpp:1403] Filtered slave 201203290030-0-0 for framework 201203290030-0-0001 for 1 seconds
I0329 00:32:42.119375 21855 master.cpp:1184] Sending 1 offers to framework 201203290030-0-0000
I0329 00:32:42.119578 21855 master.cpp:1184] Sending 1 offers to framework 201203290030-0-0001
I0329 00:32:42.121098 21855 master.cpp:679] Received reply for offer 201203290030-0-194
I0329 00:32:42.121266 21855 master.cpp:1403] Filtered slave 201203290030-0-0 for framework 201203290030-0-0000 for 1 seconds
I0329 00:32:42.121654 21855 master.cpp:679] Received reply for offer 201203290030-0-195
I0329 00:32:42.121829 21855 master.cpp:1403] Filtered slave 201203290030-0-1 for framework 201203290030-0-0001 for 1 seconds
I0329 00:32:43.120648 21855 master.cpp:1184] Sending 1 offers to framework 201203290030-0-0000
I0329 00:32:43.120834 21855 master.cpp:1184] Sending 1 offers to framework 201203290030-0-0001
I0329 00:32:43.122283 21855 master.cpp:679] Received reply for offer 201203290030-0-196
I0329 00:32:43.122453 21855 master.cpp:1403] Filtered slave 201203290030-0-1 for framework 201203290030-0-0000 for 1 seconds
I0329 00:32:43.122812 21855 master.cpp:679] Received reply for offer 201203290030-0-197
I0329 00:32:43.122979 21855 master.cpp:1403] Filtered slave 201203290030-0-0 for framework 201203290030-0-0001 for 1 seconds
I0329 00:32:44.123129 21855 master.cpp:1184] Sending 1 offers to framework 201203290030-0-0000
I0329 00:32:44.123321 21855 master.cpp:1184] Sending 1 offers to framework 201203290030-0-0001
I0329 00:32:44.124871 21855 master.cpp:679] Received reply for offer 201203290030-0-198
I0329 00:32:44.125041 21855 master.cpp:1403] Filtered slave 201203290030-0-0 for framework 201203290030-0-0000 for 1 seconds
I0329 00:32:44.125295 21855 master.cpp:679] Received reply for offer 201203290030-0-199
I0329 00:32:44.125464 21855 master.cpp:1403] Filtered slave 201203290030-0-1 for framework 201203290030-0-0001 for 1 seconds
I0329 00:32:45.125633 21855 master.cpp:1184] Sending 1 offers to framework 201203290030-0-0000
I0329 00:32:45.125820 21855 master.cpp:1184] Sending 1 offers to framework 201203290030-0-0001
I0329 00:32:45.127300 21855 master.cpp:679] Received reply for offer 201203290030-0-200
I0329 00:32:45.127470 21855 master.cpp:1403] Filtered slave 201203290030-0-1 for framework 201203290030-0-0000 for 1 seconds
I0329 00:32:45.127886 21855 master.cpp:679] Received reply for offer 201203290030-0-201
I0329 00:32:45.128059 21855 master.cpp:1403] Filtered slave 201203290030-0-0 for framework 201203290030-0-0001 for 1 seconds
I0329 00:32:46.128155 21855 master.cpp:1184] Sending 1 offers to framework 201203290030-0-0000
I0329 00:32:46.128538 21855 master.cpp:1184] Sending 1 offers to framework 201203290030-0-0001
I0329 00:32:46.129832 21855 master.cpp:679] Received reply for offer 201203290030-0-202
I0329 00:32:46.179210 21855 master.cpp:1403] Filtered slave 201203290030-0-0 for framework 201203290030-0-0000 for 1 seconds
I0329 00:32:46.217969 21855 master.cpp:679] Received reply for offer 201203290030-0-203
I0329 00:32:46.218279 21855 master.cpp:1403] Filtered slave 201203290030-0-1 for framework 201203290030-0-0001 for 1 seconds
I0329 00:32:47.130579 21855 master.cpp:1184] Sending 1 offers to framework 201203290030-0-0000
I0329 00:32:47.130789 21855 master.cpp:1184] Sending 1 offers to framework 201203290030-0-0001
I0329 00:32:47.132123 21855 master.cpp:679] Received reply for offer 201203290030-0-204
I0329 00:32:47.132294 21855 master.cpp:1403] Filtered slave 201203290030-0-1 for framework 201203290030-0-0000 for 1 seconds
I0329 00:32:47.132601 21855 master.cpp:679] Received reply for offer 201203290030-0-205
I0329 00:32:47.132756 21855 master.cpp:1403] Filtered slave 201203290030-0-0 for framework 201203290030-0-0001 for 1 seconds
I0329 00:32:48.132791 21855 master.cpp:1184] Sending 1 offers to framework 201203290030-0-0000
I0329 00:32:48.132997 21855 master.cpp:1184] Sending 1 offers to framework 201203290030-0-0001
I0329 00:32:48.134313 21855 master.cpp:679] Received reply for offer 201203290030-0-206
I0329 00:32:48.134466 21855 master.cpp:1403] Filtered slave 201203290030-0-0 for framework 201203290030-0-0000 for 1 seconds
I0329 00:32:48.134768 21855 master.cpp:679] Received reply for offer 201203290030-0-207
I0329 00:32:48.135179 21855 master.cpp:1403] Filtered slave 201203290030-0-1 for framework 201203290030-0-0001 for 1 seconds
I0329 00:32:49.134984 21855 master.cpp:1184] Sending 1 offers to framework 201203290030-0-0000
I0329 00:32:49.135200 21855 master.cpp:1184] Sending 1 offers to framework 201203290030-0-0001
I0329 00:32:49.136514 21855 master.cpp:679] Received reply for offer 201203290030-0-208
I0329 00:32:49.136670 21855 master.cpp:1403] Filtered slave 201203290030-0-1 for framework 201203290030-0-0000 for 1 seconds
I0329 00:32:49.137055 21855 master.cpp:679] Received reply for offer 201203290030-0-209
I0329 00:32:49.137223 21855 master.cpp:1403] Filtered slave 201203290030-0-0 for framework 201203290030-0-0001 for 1 seconds
I0329 00:32:50.137398 21855 master.cpp:1184] Sending 1 offers to framework 201203290030-0-0000
I0329 00:32:50.137574 21855 master.cpp:1184] Sending 1 offers to framework 201203290030-0-0001
I0329 00:32:50.139193 21855 master.cpp:679] Received reply for offer 201203290030-0-210
I0329 00:32:50.139359 21855 master.cpp:1403] Filtered slave 201203290030-0-0 for framework 201203290030-0-0000 for 1 seconds
I0329 00:32:50.139724 21855 master.cpp:679] Received reply for offer 201203290030-0-211
I0329 00:32:50.139955 21855 master.cpp:1403] Filtered slave 201203290030-0-1 for framework 201203290030-0-0001 for 1 seconds
I0329 00:32:51.139989 21855 master.cpp:1184] Sending 1 offers to framework 201203290030-0-0000
I0329 00:32:51.140151 21855 master.cpp:1184] Sending 1 offers to framework 201203290030-0-0001
I0329 00:32:51.141609 21855 master.cpp:679] Received reply for offer 201203290030-0-212
I0329 00:32:51.191021 21855 master.cpp:1403] Filtered slave 201203290030-0-1 for framework 201203290030-0-0000 for 1 seconds
I0329 00:32:51.229842 21855 master.cpp:679] Received reply for offer 201203290030-0-213
I0329 00:32:51.230126 21855 master.cpp:1403] Filtered slave 201203290030-0-0 for framework 201203290030-0-0001 for 1 seconds
I0329 00:32:52.142572 21855 master.cpp:1184] Sending 1 offers to framework 201203290030-0-0000
I0329 00:32:52.142776 21855 master.cpp:1184] Sending 1 offers to framework 201203290030-0-0001
I0329 00:32:52.144171 21855 master.cpp:679] Received reply for offer 201203290030-0-214
I0329 00:32:52.144353 21855 master.cpp:1403] Filtered slave 201203290030-0-0 for framework 201203290030-0-0000 for 1 seconds
I0329 00:32:52.144742 21855 master.cpp:679] Received reply for offer 201203290030-0-215
I0329 00:32:52.144923 21855 master.cpp:1403] Filtered slave 201203290030-0-1 for framework 201203290030-0-0001 for 1 seconds
I0329 00:32:53.145069 21855 master.cpp:1184] Sending 1 offers to framework 201203290030-0-0000
I0329 00:32:53.145261 21855 master.cpp:1184] Sending 1 offers to framework 201203290030-0-0001
I0329 00:32:53.146700 21855 master.cpp:679] Received reply for offer 201203290030-0-216
I0329 00:32:53.146847 21855 master.cpp:1403] Filtered slave 201203290030-0-1 for framework 201203290030-0-0000 for 1 seconds
I0329 00:32:53.147284 21855 master.cpp:679] Received reply for offer 201203290030-0-217
I0329 00:32:53.147472 21855 master.cpp:1403] Filtered slave 201203290030-0-0 for framework 201203290030-0-0001 for 1 seconds
I0329 00:32:54.147562 21855 master.cpp:1184] Sending 1 offers to framework 201203290030-0-0000
I0329 00:32:54.147747 21855 master.cpp:1184] Sending 1 offers to framework 201203290030-0-0001
I0329 00:32:54.149207 21855 master.cpp:679] Received reply for offer 201203290030-0-218
I0329 00:32:54.149374 21855 master.cpp:1403] Filtered slave 201203290030-0-0 for framework 201203290030-0-0000 for 1 seconds
I0329 00:32:54.149677 21855 master.cpp:679] Received reply for offer 201203290030-0-219
I0329 00:32:54.149848 21855 master.cpp:1403] Filtered slave 201203290030-0-1 for framework 201203290030-0-0001 for 1 seconds
I0329 00:32:55.149119 21855 master.cpp:1184] Sending 1 offers to framework 201203290030-0-0000
I0329 00:32:55.149297 21855 master.cpp:1184] Sending 1 offers to framework 201203290030-0-0001
I0329 00:32:55.150807 21855 master.cpp:679] Received reply for offer 201203290030-0-220
I0329 00:32:55.150955 21855 master.cpp:1403] Filtered slave 201203290030-0-1 for framework 201203290030-0-0000 for 1 seconds
I0329 00:32:55.151340 21855 master.cpp:679] Received reply for offer 201203290030-0-221
I0329 00:32:55.151759 21855 master.cpp:1403] Filtered slave 201203290030-0-0 for framework 201203290030-0-0001 for 1 seconds
I0329 00:32:56.151654 21855 master.cpp:1184] Sending 1 offers to framework 201203290030-0-0000
I0329 00:32:56.151815 21855 master.cpp:1184] Sending 1 offers to framework 201203290030-0-0001
I0329 00:32:56.153301 21855 master.cpp:679] Received reply for offer 201203290030-0-222
I0329 00:32:56.219290 21855 master.cpp:1403] Filtered slave 201203290030-0-0 for framework 201203290030-0-0000 for 1 seconds
I0329 00:32:56.249933 21855 master.cpp:679] Received reply for offer 201203290030-0-223
I0329 00:32:56.250360 21855 master.cpp:1403] Filtered slave 201203290030-0-1 for framework 201203290030-0-0001 for 1 seconds
I0329 00:32:57.154044 21855 master.cpp:1184] Sending 1 offers to framework 201203290030-0-0000
I0329 00:32:57.154259 21855 master.cpp:1184] Sending 1 offers to framework 201203290030-0-0001
I0329 00:32:57.155796 21855 master.cpp:679] Received reply for offer 201203290030-0-224
I0329 00:32:57.155944 21855 master.cpp:1403] Filtered slave 201203290030-0-1 for framework 201203290030-0-0000 for 1 seconds
I0329 00:32:57.156378 21855 master.cpp:679] Received reply for offer 201203290030-0-225
I0329 00:32:57.156673 21855 master.cpp:1403] Filtered slave 201203290030-0-0 for framework 201203290030-0-0001 for 1 seconds
I0329 00:32:58.155321 21855 master.cpp:1184] Sending 1 offers to framework 201203290030-0-0000
I0329 00:32:58.155494 21855 master.cpp:1184] Sending 1 offers to framework 201203290030-0-0001
I0329 00:32:58.156916 21855 master.cpp:679] Received reply for offer 201203290030-0-226
I0329 00:32:58.157063 21855 master.cpp:1403] Filtered slave 201203290030-0-0 for framework 201203290030-0-0000 for 1 seconds
I0329 00:32:58.157387 21855 master.cpp:679] Received reply for offer 201203290030-0-227
I0329 00:32:58.157552 21855 master.cpp:1403] Filtered slave 201203290030-0-1 for framework 201203290030-0-0001 for 1 seconds
I0329 00:32:59.157662 21855 master.cpp:1184] Sending 1 offers to framework 201203290030-0-0000
I0329 00:32:59.157856 21855 master.cpp:1184] Sending 1 offers to framework 201203290030-0-0001
I0329 00:32:59.159492 21855 master.cpp:679] Received reply for offer 201203290030-0-228
I0329 00:32:59.159663 21855 master.cpp:1403] Filtered slave 201203290030-0-1 for framework 201203290030-0-0000 for 1 seconds
I0329 00:32:59.160053 21855 master.cpp:679] Received reply for offer 201203290030-0-229
I0329 00:32:59.160315 21855 master.cpp:1403] Filtered slave 201203290030-0-0 for framework 201203290030-0-0001 for 1 seconds
I0329 00:33:00.160330 21855 master.cpp:1184] Sending 1 offers to framework 201203290030-0-0000
I0329 00:33:00.160503 21855 master.cpp:1184] Sending 1 offers to framework 201203290030-0-0001
I0329 00:33:00.162113 21855 master.cpp:679] Received reply for offer 201203290030-0-230
I0329 00:33:00.162281 21855 master.cpp:1403] Filtered slave 201203290030-0-0 for framework 201203290030-0-0000 for 1 seconds
I0329 00:33:00.162698 21855 master.cpp:679] Received reply for offer 201203290030-0-231
I0329 00:33:00.162871 21855 master.cpp:1403] Filtered slave 201203290030-0-1 for framework 201203290030-0-0001 for 1 seconds
I0329 00:33:01.162958 21855 master.cpp:1184] Sending 1 offers to framework 201203290030-0-0000
I0329 00:33:01.163190 21855 master.cpp:1184] Sending 1 offers to framework 201203290030-0-0001
I0329 00:33:01.164652 21855 master.cpp:679] Received reply for offer 201203290030-0-232
I0329 00:33:01.197712 21855 master.cpp:1403] Filtered slave 201203290030-0-1 for framework 201203290030-0-0000 for 1 seconds
I0329 00:33:01.236749 21855 master.cpp:679] Received reply for offer 201203290030-0-233
I0329 00:33:01.237056 21855 master.cpp:1403] Filtered slave 201203290030-0-0 for framework 201203290030-0-0001 for 1 seconds
I0329 00:33:02.165417 21855 master.cpp:1184] Sending 1 offers to framework 201203290030-0-0000
I0329 00:33:02.165627 21855 master.cpp:1184] Sending 1 offers to framework 201203290030-0-0001
I0329 00:33:02.167107 21855 master.cpp:679] Received reply for offer 201203290030-0-234
I0329 00:33:02.167273 21855 master.cpp:1403] Filtered slave 201203290030-0-0 for framework 201203290030-0-0000 for 1 seconds
I0329 00:33:02.167645 21855 master.cpp:679] Received reply for offer 201203290030-0-235
I0329 00:33:02.167896 21855 master.cpp:1403] Filtered slave 201203290030-0-1 for framework 201203290030-0-0001 for 1 seconds
I0329 00:33:03.167835 21855 master.cpp:1184] Sending 1 offers to framework 201203290030-0-0000
I0329 00:33:03.168036 21855 master.cpp:1184] Sending 1 offers to framework 201203290030-0-0001
I0329 00:33:03.169529 21855 master.cpp:679] Received reply for offer 201203290030-0-236
I0329 00:33:03.169697 21855 master.cpp:1403] Filtered slave 201203290030-0-1 for framework 201203290030-0-0000 for 1 seconds
I0329 00:33:03.170101 21855 master.cpp:679] Received reply for offer 201203290030-0-237
I0329 00:33:03.170272 21855 master.cpp:1403] Filtered slave 201203290030-0-0 for framework 201203290030-0-0001 for 1 seconds
I0329 00:33:04.170286 21855 master.cpp:1184] Sending 1 offers to framework 201203290030-0-0000
I0329 00:33:04.170582 21855 master.cpp:1184] Sending 1 offers to framework 201203290030-0-0001
I0329 00:33:04.171835 21855 master.cpp:679] Received reply for offer 201203290030-0-238
I0329 00:33:04.172003 21855 master.cpp:1403] Filtered slave 201203290030-0-0 for framework 201203290030-0-0000 for 1 seconds
I0329 00:33:04.172423 21855 master.cpp:679] Received reply for offer 201203290030-0-239
I0329 00:33:04.172592 21855 master.cpp:1403] Filtered slave 201203290030-0-1 for framework 201203290030-0-0001 for 1 seconds
I0329 00:33:05.171787 21855 master.cpp:1184] Sending 1 offers to framework 201203290030-0-0000
I0329 00:33:05.172010 21855 master.cpp:1184] Sending 1 offers to framework 201203290030-0-0001
I0329 00:33:05.173496 21855 master.cpp:679] Received reply for offer 201203290030-0-240
I0329 00:33:05.173666 21855 master.cpp:1403] Filtered slave 201203290030-0-1 for framework 201203290030-0-0000 for 1 seconds
I0329 00:33:05.174053 21855 master.cpp:679] Received reply for offer 201203290030-0-241
I0329 00:33:05.174226 21855 master.cpp:1403] Filtered slave 201203290030-0-0 for framework 201203290030-0-0001 for 1 seconds
I0329 00:33:06.174247 21855 master.cpp:1184] Sending 1 offers to framework 201203290030-0-0000
I0329 00:33:06.174412 21855 master.cpp:1184] Sending 1 offers to framework 201203290030-0-0001
I0329 00:33:06.175982 21855 master.cpp:679] Received reply for offer 201203290030-0-242
I0329 00:33:06.223798 21855 master.cpp:1403] Filtered slave 201203290030-0-0 for framework 201203290030-0-0000 for 1 seconds
I0329 00:33:06.250629 21855 master.cpp:679] Received reply for offer 201203290030-0-243
I0329 00:33:06.250948 21855 master.cpp:1403] Filtered slave 201203290030-0-1 for framework 201203290030-0-0001 for 1 seconds
I0329 00:33:07.176748 21855 master.cpp:1184] Sending 1 offers to framework 201203290030-0-0000
I0329 00:33:07.176951 21855 master.cpp:1184] Sending 1 offers to framework 201203290030-0-0001
I0329 00:33:07.178423 21855 master.cpp:679] Received reply for offer 201203290030-0-244
I0329 00:33:07.178591 21855 master.cpp:1403] Filtered slave 201203290030-0-1 for framework 201203290030-0-0000 for 1 seconds
I0329 00:33:07.178985 21855 master.cpp:679] Received reply for offer 201203290030-0-245
I0329 00:33:07.179162 21855 master.cpp:1403] Filtered slave 201203290030-0-0 for framework 201203290030-0-0001 for 1 seconds
I0329 00:33:08.179190 21855 master.cpp:1184] Sending 1 offers to framework 201203290030-0-0000
I0329 00:33:08.179622 21855 master.cpp:1184] Sending 1 offers to framework 201203290030-0-0001
I0329 00:33:08.180940 21855 master.cpp:679] Received reply for offer 201203290030-0-246
I0329 00:33:08.181107 21855 master.cpp:1403] Filtered slave 201203290030-0-0 for framework 201203290030-0-0000 for 1 seconds
I0329 00:33:08.181470 21855 master.cpp:679] Received reply for offer 201203290030-0-247
I0329 00:33:08.181761 21855 master.cpp:1403] Filtered slave 201203290030-0-1 for framework 201203290030-0-0001 for 1 seconds
I0329 00:33:09.181643 21855 master.cpp:1184] Sending 1 offers to framework 201203290030-0-0000
I0329 00:33:09.181846 21855 master.cpp:1184] Sending 1 offers to framework 201203290030-0-0001
I0329 00:33:09.183187 21855 master.cpp:679] Received reply for offer 201203290030-0-248
I0329 00:33:09.183357 21855 master.cpp:1403] Filtered slave 201203290030-0-1 for framework 201203290030-0-0000 for 1 seconds
I0329 00:33:09.183748 21855 master.cpp:679] Received reply for offer 201203290030-0-249
I0329 00:33:09.183923 21855 master.cpp:1403] Filtered slave 201203290030-0-0 for framework 201203290030-0-0001 for 1 seconds
I0329 00:33:10.183878 21855 master.cpp:1184] Sending 1 offers to framework 201203290030-0-0000
I0329 00:33:10.184072 21855 master.cpp:1184] Sending 1 offers to framework 201203290030-0-0001
I0329 00:33:10.185530 21855 master.cpp:679] Received reply for offer 201203290030-0-250
I0329 00:33:10.185691 21855 master.cpp:1403] Filtered slave 201203290030-0-0 for framework 201203290030-0-0000 for 1 seconds
I0329 00:33:10.185969 21855 master.cpp:679] Received reply for offer 201203290030-0-251
I0329 00:33:10.186204 21855 master.cpp:1403] Filtered slave 201203290030-0-1 for framework 201203290030-0-0001 for 1 seconds
I0329 00:33:11.186185 21855 master.cpp:1184] Sending 1 offers to framework 201203290030-0-0000
I0329 00:33:11.186424 21855 master.cpp:1184] Sending 1 offers to framework 201203290030-0-0001
I0329 00:33:11.187933 21855 master.cpp:679] Received reply for offer 201203290030-0-252
I0329 00:33:11.237633 21855 master.cpp:1403] Filtered slave 201203290030-0-1 for framework 201203290030-0-0000 for 1 seconds
I0329 00:33:11.278650 21855 master.cpp:679] Received reply for offer 201203290030-0-253
I0329 00:33:11.278986 21855 master.cpp:1403] Filtered slave 201203290030-0-0 for framework 201203290030-0-0001 for 1 seconds
I0329 00:33:12.188565 21855 master.cpp:1184] Sending 1 offers to framework 201203290030-0-0000
I0329 00:33:12.188760 21855 master.cpp:1184] Sending 1 offers to framework 201203290030-0-0001
I0329 00:33:12.190068 21855 master.cpp:679] Received reply for offer 201203290030-0-254
I0329 00:33:12.190232 21855 master.cpp:1403] Filtered slave 201203290030-0-0 for framework 201203290030-0-0000 for 1 seconds
I0329 00:33:12.190635 21855 master.cpp:679] Received reply for offer 201203290030-0-255
I0329 00:33:12.190805 21855 master.cpp:1403] Filtered slave 201203290030-0-1 for framework 201203290030-0-0001 for 1 seconds
I0329 00:33:13.190250 21855 master.cpp:1184] Sending 1 offers to framework 201203290030-0-0000
I0329 00:33:13.190450 21855 master.cpp:1184] Sending 1 offers to framework 201203290030-0-0001
I0329 00:33:13.191879 21855 master.cpp:679] Received reply for offer 201203290030-0-256
I0329 00:33:13.192044 21855 master.cpp:1403] Filtered slave 201203290030-0-1 for framework 201203290030-0-0000 for 1 seconds
I0329 00:33:13.192364 21855 master.cpp:679] Received reply for offer 201203290030-0-257
I0329 00:33:13.192529 21855 master.cpp:1403] Filtered slave 201203290030-0-0 for framework 201203290030-0-0001 for 1 seconds
I0329 00:33:14.192586 21855 master.cpp:1184] Sending 1 offers to framework 201203290030-0-0000
I0329 00:33:14.192790 21855 master.cpp:1184] Sending 1 offers to framework 201203290030-0-0001
I0329 00:33:14.194232 21855 master.cpp:679] Received reply for offer 201203290030-0-258
I0329 00:33:14.194396 21855 master.cpp:1403] Filtered slave 201203290030-0-0 for framework 201203290030-0-0000 for 1 seconds
I0329 00:33:14.194715 21855 master.cpp:679] Received reply for offer 201203290030-0-259
I0329 00:33:14.194880 21855 master.cpp:1403] Filtered slave 201203290030-0-1 for framework 201203290030-0-0001 for 1 seconds
I0329 00:33:15.194906 21855 master.cpp:1184] Sending 1 offers to framework 201203290030-0-0000
I0329 00:33:15.195281 21855 master.cpp:1184] Sending 1 offers to framework 201203290030-0-0001
I0329 00:33:15.196584 21855 master.cpp:679] Received reply for offer 201203290030-0-260
I0329 00:33:15.196730 21855 master.cpp:1403] Filtered slave 201203290030-0-1 for framework 201203290030-0-0000 for 1 seconds
I0329 00:33:15.197106 21855 master.cpp:679] Received reply for offer 201203290030-0-261
I0329 00:33:15.197397 21855 master.cpp:1403] Filtered slave 201203290030-0-0 for framework 201203290030-0-0001 for 1 seconds
I0329 00:33:16.197161 21855 master.cpp:1184] Sending 1 offers to framework 201203290030-0-0000
I0329 00:33:16.197311 21855 master.cpp:1184] Sending 1 offers to framework 201203290030-0-0001
I0329 00:33:16.198714 21855 master.cpp:679] Received reply for offer 201203290030-0-262
I0329 00:33:16.257697 21855 master.cpp:1403] Filtered slave 201203290030-0-0 for framework 201203290030-0-0000 for 1 seconds
I0329 00:33:16.290503 21855 master.cpp:679] Received reply for offer 201203290030-0-263
I0329 00:33:16.290952 21855 master.cpp:1403] Filtered slave 201203290030-0-1 for framework 201203290030-0-0001 for 1 seconds
I0329 00:33:17.199409 21855 master.cpp:1184] Sending 1 offers to framework 201203290030-0-0000
I0329 00:33:17.199776 21855 master.cpp:1184] Sending 1 offers to framework 201203290030-0-0001
I0329 00:33:17.201035 21855 master.cpp:679] Received reply for offer 201203290030-0-264
I0329 00:33:17.201190 21855 master.cpp:1403] Filtered slave 201203290030-0-1 for framework 201203290030-0-0000 for 1 seconds
I0329 00:33:17.201416 21855 master.cpp:679] Received reply for offer 201203290030-0-265
I0329 00:33:17.201581 21855 master.cpp:1403] Filtered slave 201203290030-0-0 for framework 201203290030-0-0001 for 1 seconds
I0329 00:33:18.201603 21855 master.cpp:1184] Sending 1 offers to framework 201203290030-0-0000
I0329 00:33:18.201800 21855 master.cpp:1184] Sending 1 offers to framework 201203290030-0-0001
I0329 00:33:18.203227 21855 master.cpp:679] Received reply for offer 201203290030-0-266
I0329 00:33:18.203369 21855 master.cpp:1403] Filtered slave 201203290030-0-0 for framework 201203290030-0-0000 for 1 seconds
I0329 00:33:18.203634 21855 master.cpp:679] Received reply for offer 201203290030-0-267
I0329 00:33:18.203799 21855 master.cpp:1403] Filtered slave 201203290030-0-1 for framework 201203290030-0-0001 for 1 seconds
I0329 00:33:19.203819 21855 master.cpp:1184] Sending 1 offers to framework 201203290030-0-0000
I0329 00:33:19.204007 21855 master.cpp:1184] Sending 1 offers to framework 201203290030-0-0001
I0329 00:33:19.205427 21855 master.cpp:679] Received reply for offer 201203290030-0-268
I0329 00:33:19.205591 21855 master.cpp:1403] Filtered slave 201203290030-0-1 for framework 201203290030-0-0000 for 1 seconds
I0329 00:33:19.205808 21855 master.cpp:679] Received reply for offer 201203290030-0-269
I0329 00:33:19.205971 21855 master.cpp:1403] Filtered slave 201203290030-0-0 for framework 201203290030-0-0001 for 1 seconds
I0329 00:33:20.205975 21855 master.cpp:1184] Sending 1 offers to framework 201203290030-0-0000
I0329 00:33:20.206179 21855 master.cpp:1184] Sending 1 offers to framework 201203290030-0-0001
I0329 00:33:20.207551 21855 master.cpp:679] Received reply for offer 201203290030-0-270
I0329 00:33:20.207739 21855 master.cpp:1403] Filtered slave 201203290030-0-0 for framework 201203290030-0-0000 for 1 seconds
I0329 00:33:20.207919 21855 master.cpp:679] Received reply for offer 201203290030-0-271
I0329 00:33:20.208096 21855 master.cpp:1403] Filtered slave 201203290030-0-1 for framework 201203290030-0-0001 for 1 seconds
I0329 00:33:21.208139 21855 master.cpp:1184] Sending 1 offers to framework 201203290030-0-0000
I0329 00:33:21.208297 21855 master.cpp:1184] Sending 1 offers to framework 201203290030-0-0001
I0329 00:33:21.209810 21855 master.cpp:679] Received reply for offer 201203290030-0-272
I0329 00:33:21.269264 21855 master.cpp:1403] Filtered slave 201203290030-0-1 for framework 201203290030-0-0000 for 1 seconds
I0329 00:33:21.310518 21855 master.cpp:679] Received reply for offer 201203290030-0-273
I0329 00:33:21.310817 21855 master.cpp:1403] Filtered slave 201203290030-0-0 for framework 201203290030-0-0001 for 1 seconds
I0329 00:33:22.210453 21855 master.cpp:1184] Sending 1 offers to framework 201203290030-0-0000
I0329 00:33:22.210659 21855 master.cpp:1184] Sending 1 offers to framework 201203290030-0-0001
I0329 00:33:22.212046 21855 master.cpp:679] Received reply for offer 201203290030-0-274
I0329 00:33:22.212213 21855 master.cpp:1403] Filtered slave 201203290030-0-0 for framework 201203290030-0-0000 for 1 seconds
I0329 00:33:22.212494 21855 master.cpp:679] Received reply for offer 201203290030-0-275
I0329 00:33:22.212668 21855 master.cpp:1403] Filtered slave 201203290030-0-1 for framework 201203290030-0-0001 for 1 seconds
I0329 00:33:23.212720 21855 master.cpp:1184] Sending 1 offers to framework 201203290030-0-0000
I0329 00:33:23.213158 21855 master.cpp:1184] Sending 1 offers to framework 201203290030-0-0001
I0329 00:33:23.214480 21855 master.cpp:679] Received reply for offer 201203290030-0-276
I0329 00:33:23.214658 21855 master.cpp:1403] Filtered slave 201203290030-0-1 for framework 201203290030-0-0000 for 1 seconds
I0329 00:33:23.214992 21855 master.cpp:679] Received reply for offer 201203290030-0-277
I0329 00:33:23.215327 21855 master.cpp:1403] Filtered slave 201203290030-0-0 for framework 201203290030-0-0001 for 1 seconds
I0329 00:33:24.215312 21855 master.cpp:1184] Sending 1 offers to framework 201203290030-0-0000
I0329 00:33:24.215749 21855 master.cpp:1184] Sending 1 offers to framework 201203290030-0-0001
I0329 00:33:24.216739 21855 master.cpp:679] Received reply for offer 201203290030-0-278
I0329 00:33:24.216866 21855 master.cpp:1403] Filtered slave 201203290030-0-0 for framework 201203290030-0-0000 for 1 seconds
I0329 00:33:24.217139 21855 master.cpp:679] Received reply for offer 201203290030-0-279
I0329 00:33:24.217314 21855 master.cpp:1403] Filtered slave 201203290030-0-1 for framework 201203290030-0-0001 for 1 seconds
I0329 00:33:25.217273 21855 master.cpp:1184] Sending 1 offers to framework 201203290030-0-0000
I0329 00:33:25.217463 21855 master.cpp:1184] Sending 1 offers to framework 201203290030-0-0001
I0329 00:33:25.218663 21855 master.cpp:679] Received reply for offer 201203290030-0-280
I0329 00:33:25.218827 21855 master.cpp:1403] Filtered slave 201203290030-0-1 for framework 201203290030-0-0000 for 1 seconds
I0329 00:33:25.219051 21855 master.cpp:679] Received reply for offer 201203290030-0-281
I0329 00:33:25.219286 21855 master.cpp:1403] Filtered slave 201203290030-0-0 for framework 201203290030-0-0001 for 1 seconds
I0329 00:33:26.219259 21855 master.cpp:1184] Sending 1 offers to framework 201203290030-0-0000
I0329 00:33:26.219414 21855 master.cpp:1184] Sending 1 offers to framework 201203290030-0-0001
I0329 00:33:26.220721 21855 master.cpp:679] Received reply for offer 201203290030-0-282
I0329 00:33:26.272646 21855 master.cpp:1403] Filtered slave 201203290030-0-0 for framework 201203290030-0-0000 for 1 seconds
I0329 00:33:26.314054 21855 master.cpp:679] Received reply for offer 201203290030-0-283
I0329 00:33:26.314371 21855 master.cpp:1403] Filtered slave 201203290030-0-1 for framework 201203290030-0-0001 for 1 seconds
I0329 00:33:27.221362 21855 master.cpp:1184] Sending 1 offers to framework 201203290030-0-0000
I0329 00:33:27.221564 21855 master.cpp:1184] Sending 1 offers to framework 201203290030-0-0001
I0329 00:33:27.222862 21855 master.cpp:679] Received reply for offer 201203290030-0-284
I0329 00:33:27.223031 21855 master.cpp:1403] Filtered slave 201203290030-0-1 for framework 201203290030-0-0000 for 1 seconds
I0329 00:33:27.223260 21855 master.cpp:679] Received reply for offer 201203290030-0-285
I0329 00:33:27.223427 21855 master.cpp:1403] Filtered slave 201203290030-0-0 for framework 201203290030-0-0001 for 1 seconds
I0329 00:33:28.222312 21855 master.cpp:1184] Sending 1 offers to framework 201203290030-0-0000
I0329 00:33:28.222515 21855 master.cpp:1184] Sending 1 offers to framework 201203290030-0-0001
I0329 00:33:28.223850 21855 master.cpp:679] Received reply for offer 201203290030-0-286
I0329 00:33:28.224009 21855 master.cpp:1403] Filtered slave 201203290030-0-0 for framework 201203290030-0-0000 for 1 seconds
I0329 00:33:28.224236 21855 master.cpp:679] Received reply for offer 201203290030-0-287
I0329 00:33:28.224673 21855 master.cpp:1403] Filtered slave 201203290030-0-1 for framework 201203290030-0-0001 for 1 seconds
I0329 00:33:29.224136 21855 master.cpp:1184] Sending 1 offers to framework 201203290030-0-0000
I0329 00:33:29.224344 21855 master.cpp:1184] Sending 1 offers to framework 201203290030-0-0001
I0329 00:33:29.225780 21855 master.cpp:679] Received reply for offer 201203290030-0-288
I0329 00:33:29.225949 21855 master.cpp:1403] Filtered slave 201203290030-0-1 for framework 201203290030-0-0000 for 1 seconds
I0329 00:33:29.226193 21855 master.cpp:679] Received reply for offer 201203290030-0-289
I0329 00:33:29.226361 21855 master.cpp:1403] Filtered slave 201203290030-0-0 for framework 201203290030-0-0001 for 1 seconds
I0329 00:33:30.226409 21855 master.cpp:1184] Sending 1 offers to framework 201203290030-0-0000
I0329 00:33:30.226608 21855 master.cpp:1184] Sending 1 offers to framework 201203290030-0-0001
I0329 00:33:30.227782 21855 master.cpp:679] Received reply for offer 201203290030-0-290
I0329 00:33:30.227947 21855 master.cpp:1403] Filtered slave 201203290030-0-0 for framework 201203290030-0-0000 for 1 seconds
I0329 00:33:30.228203 21855 master.cpp:679] Received reply for offer 201203290030-0-291
I0329 00:33:30.228371 21855 master.cpp:1403] Filtered slave 201203290030-0-1 for framework 201203290030-0-0001 for 1 seconds
I0329 00:33:31.228420 21855 master.cpp:1184] Sending 1 offers to framework 201203290030-0-0000
I0329 00:33:31.228575 21855 master.cpp:1184] Sending 1 offers to framework 201203290030-0-0001
I0329 00:33:31.229784 21855 master.cpp:679] Received reply for offer 201203290030-0-292
I0329 00:33:31.284492 21855 master.cpp:1403] Filtered slave 201203290030-0-1 for framework 201203290030-0-0000 for 1 seconds
I0329 00:33:31.325711 21855 master.cpp:679] Received reply for offer 201203290030-0-293
I0329 00:33:31.326009 21855 master.cpp:1403] Filtered slave 201203290030-0-0 for framework 201203290030-0-0001 for 1 seconds
I0329 00:33:32.230999 21855 master.cpp:1184] Sending 1 offers to framework 201203290030-0-0000
I0329 00:33:32.231364 21855 master.cpp:1184] Sending 1 offers to framework 201203290030-0-0001
I0329 00:33:32.232841 21855 master.cpp:679] Received reply for offer 201203290030-0-294
I0329 00:33:32.233023 21855 master.cpp:1403] Filtered slave 201203290030-0-0 for framework 201203290030-0-0000 for 1 seconds
I0329 00:33:32.233392 21855 master.cpp:679] Received reply for offer 201203290030-0-295
I0329 00:33:32.233578 21855 master.cpp:1403] Filtered slave 201203290030-0-1 for framework 201203290030-0-0001 for 1 seconds
I0329 00:33:33.233477 21855 master.cpp:1184] Sending 1 offers to framework 201203290030-0-0000
I0329 00:33:33.233747 21855 master.cpp:1184] Sending 1 offers to framework 201203290030-0-0001
I0329 00:33:33.235106 21855 master.cpp:679] Received reply for offer 201203290030-0-296
I0329 00:33:33.235276 21855 master.cpp:1403] Filtered slave 201203290030-0-1 for framework 201203290030-0-0000 for 1 seconds
I0329 00:33:33.235568 21855 master.cpp:679] Received reply for offer 201203290030-0-297
I0329 00:33:33.235739 21855 master.cpp:1403] Filtered slave 201203290030-0-0 for framework 201203290030-0-0001 for 1 seconds
I0329 00:33:34.235772 21855 master.cpp:1184] Sending 1 offers to framework 201203290030-0-0000
I0329 00:33:34.236027 21855 master.cpp:1184] Sending 1 offers to framework 201203290030-0-0001
I0329 00:33:34.237519 21855 master.cpp:679] Received reply for offer 201203290030-0-298
I0329 00:33:34.237748 21855 master.cpp:1403] Filtered slave 201203290030-0-0 for framework 201203290030-0-0000 for 1 seconds
I0329 00:33:34.237905 21855 master.cpp:679] Received reply for offer 201203290030-0-299
I0329 00:33:34.238073 21855 master.cpp:1403] Filtered slave 201203290030-0-1 for framework 201203290030-0-0001 for 1 seconds
I0329 00:33:35.238029 21855 master.cpp:1184] Sending 1 offers to framework 201203290030-0-0000
I0329 00:33:35.238315 21855 master.cpp:1184] Sending 1 offers to framework 201203290030-0-0001
I0329 00:33:35.239821 21855 master.cpp:679] Received reply for offer 201203290030-0-300
I0329 00:33:35.239980 21855 master.cpp:1403] Filtered slave 201203290030-0-1 for framework 201203290030-0-0000 for 1 seconds
I0329 00:33:35.240406 21855 master.cpp:679] Received reply for offer 201203290030-0-301
I0329 00:33:35.240676 21855 master.cpp:1403] Filtered slave 201203290030-0-0 for framework 201203290030-0-0001 for 1 seconds
I0329 00:33:36.240620 21855 master.cpp:1184] Sending 1 offers to framework 201203290030-0-0000
I0329 00:33:36.240859 21855 master.cpp:1184] Sending 1 offers to framework 201203290030-0-0001
I0329 00:33:36.242094 21855 master.cpp:679] Received reply for offer 201203290030-0-302
I0329 00:33:36.304669 21855 master.cpp:1403] Filtered slave 201203290030-0-0 for framework 201203290030-0-0000 for 1 seconds
I0329 00:33:36.345774 21855 master.cpp:679] Received reply for offer 201203290030-0-303
I0329 00:33:36.346086 21855 master.cpp:1403] Filtered slave 201203290030-0-1 for framework 201203290030-0-0001 for 1 seconds
I0329 00:33:37.242770 21855 master.cpp:1184] Sending 1 offers to framework 201203290030-0-0000
I0329 00:33:37.243163 21855 master.cpp:1184] Sending 1 offers to framework 201203290030-0-0001
I0329 00:33:37.244468 21855 master.cpp:679] Received reply for offer 201203290030-0-304
I0329 00:33:37.244652 21855 master.cpp:1403] Filtered slave 201203290030-0-1 for framework 201203290030-0-0000 for 1 seconds
I0329 00:33:37.244882 21855 master.cpp:679] Received reply for offer 201203290030-0-305
I0329 00:33:37.245053 21855 master.cpp:1403] Filtered slave 201203290030-0-0 for framework 201203290030-0-0001 for 1 seconds
I0329 00:33:38.245110 21855 master.cpp:1184] Sending 1 offers to framework 201203290030-0-0000
I0329 00:33:38.245463 21855 master.cpp:1184] Sending 1 offers to framework 201203290030-0-0001
I0329 00:33:38.246829 21855 master.cpp:679] Received reply for offer 201203290030-0-306
I0329 00:33:38.246997 21855 master.cpp:1403] Filtered slave 201203290030-0-0 for framework 201203290030-0-0000 for 1 seconds
I0329 00:33:38.247251 21855 master.cpp:679] Received reply for offer 201203290030-0-307
I0329 00:33:38.247423 21855 master.cpp:1403] Filtered slave 201203290030-0-1 for framework 201203290030-0-0001 for 1 seconds
I0329 00:33:39.247452 21855 master.cpp:1184] Sending 1 offers to framework 201203290030-0-0000
I0329 00:33:39.247719 21855 master.cpp:1184] Sending 1 offers to framework 201203290030-0-0001
I0329 00:33:39.249045 21855 master.cpp:679] Received reply for offer 201203290030-0-308
I0329 00:33:39.249200 21855 master.cpp:1403] Filtered slave 201203290030-0-1 for framework 201203290030-0-0000 for 1 seconds
I0329 00:33:39.249488 21855 master.cpp:679] Received reply for offer 201203290030-0-309
I0329 00:33:39.249665 21855 master.cpp:1403] Filtered slave 201203290030-0-0 for framework 201203290030-0-0001 for 1 seconds
I0329 00:33:40.249701 21855 master.cpp:1184] Sending 1 offers to framework 201203290030-0-0000
I0329 00:33:40.250053 21855 master.cpp:1184] Sending 1 offers to framework 201203290030-0-0001
I0329 00:33:40.251332 21855 master.cpp:679] Received reply for offer 201203290030-0-310
I0329 00:33:40.251513 21855 master.cpp:1403] Filtered slave 201203290030-0-0 for framework 201203290030-0-0000 for 1 seconds
I0329 00:33:40.251698 21855 master.cpp:679] Received reply for offer 201203290030-0-311
I0329 00:33:40.251875 21855 master.cpp:1403] Filtered slave 201203290030-0-1 for framework 201203290030-0-0001 for 1 seconds
I0329 00:33:41.251922 21855 master.cpp:1184] Sending 1 offers to framework 201203290030-0-0000
I0329 00:33:41.252168 21855 master.cpp:1184] Sending 1 offers to framework 201203290030-0-0001
I0329 00:33:41.253448 21855 master.cpp:679] Received reply for offer 201203290030-0-312
I0329 00:33:41.308161 21855 master.cpp:1403] Filtered slave 201203290030-0-1 for framework 201203290030-0-0000 for 1 seconds
I0329 00:33:41.340790 21855 master.cpp:679] Received reply for offer 201203290030-0-313
I0329 00:33:41.341100 21855 master.cpp:1403] Filtered slave 201203290030-0-0 for framework 201203290030-0-0001 for 1 seconds
I0329 00:33:42.255100 21855 master.cpp:1184] Sending 1 offers to framework 201203290030-0-0000
I0329 00:33:42.255358 21855 master.cpp:1184] Sending 1 offers to framework 201203290030-0-0001
I0329 00:33:42.256721 21855 master.cpp:679] Received reply for offer 201203290030-0-314
I0329 00:33:42.256903 21855 master.cpp:1403] Filtered slave 201203290030-0-0 for framework 201203290030-0-0000 for 1 seconds
I0329 00:33:42.257127 21855 master.cpp:679] Received reply for offer 201203290030-0-315
I0329 00:33:42.257304 21855 master.cpp:1403] Filtered slave 201203290030-0-1 for framework 201203290030-0-0001 for 1 seconds
I0329 00:33:43.256726 21855 master.cpp:1184] Sending 1 offers to framework 201203290030-0-0000
I0329 00:33:43.257227 21855 master.cpp:1184] Sending 1 offers to framework 201203290030-0-0001
I0329 00:33:43.258551 21855 master.cpp:679] Received reply for offer 201203290030-0-316
I0329 00:33:43.258740 21855 master.cpp:1403] Filtered slave 201203290030-0-1 for framework 201203290030-0-0000 for 1 seconds
I0329 00:33:43.259233 21855 master.cpp:679] Received reply for offer 201203290030-0-317
I0329 00:33:43.259747 21855 master.cpp:1403] Filtered slave 201203290030-0-0 for framework 201203290030-0-0001 for 1 seconds
I0329 00:33:44.259150 21855 master.cpp:1184] Sending 1 offers to framework 201203290030-0-0000
I0329 00:33:44.259646 21855 master.cpp:1184] Sending 1 offers to framework 201203290030-0-0001
I0329 00:33:44.260939 21855 master.cpp:679] Received reply for offer 201203290030-0-318
I0329 00:33:44.261093 21855 master.cpp:1403] Filtered slave 201203290030-0-0 for framework 201203290030-0-0000 for 1 seconds
I0329 00:33:44.261590 21855 master.cpp:679] Received reply for offer 201203290030-0-319
I0329 00:33:44.261776 21855 master.cpp:1403] Filtered slave 201203290030-0-1 for framework 201203290030-0-0001 for 1 seconds
I0329 00:33:45.261564 21855 master.cpp:1184] Sending 1 offers to framework 201203290030-0-0000
I0329 00:33:45.262068 21855 master.cpp:1184] Sending 1 offers to framework 201203290030-0-0001
I0329 00:33:45.263401 21855 master.cpp:679] Received reply for offer 201203290030-0-320
I0329 00:33:45.263582 21855 master.cpp:1403] Filtered slave 201203290030-0-1 for framework 201203290030-0-0000 for 1 seconds
I0329 00:33:45.263811 21855 master.cpp:679] Received reply for offer 201203290030-0-321
I0329 00:33:45.263988 21855 master.cpp:1403] Filtered slave 201203290030-0-0 for framework 201203290030-0-0001 for 1 seconds
I0329 00:33:46.264021 21855 master.cpp:1184] Sending 1 offers to framework 201203290030-0-0000
I0329 00:33:46.264698 21855 master.cpp:1184] Sending 1 offers to framework 201203290030-0-0001
I0329 00:33:46.286638 21855 master.cpp:679] Received reply for offer 201203290030-0-322
I0329 00:33:46.327448 21855 master.cpp:1403] Filtered slave 201203290030-0-0 for framework 201203290030-0-0000 for 1 seconds
I0329 00:33:46.327689 21855 master.cpp:679] Received reply for offer 201203290030-0-323
I0329 00:33:46.327851 21855 master.cpp:1403] Filtered slave 201203290030-0-1 for framework 201203290030-0-0001 for 1 seconds
I0329 00:33:47.329006 21855 master.cpp:1184] Sending 1 offers to framework 201203290030-0-0000
I0329 00:33:47.329210 21855 master.cpp:1184] Sending 1 offers to framework 201203290030-0-0001
I0329 00:33:47.330648 21855 master.cpp:679] Received reply for offer 201203290030-0-324
I0329 00:33:47.330832 21855 master.cpp:1403] Filtered slave 201203290030-0-1 for framework 201203290030-0-0000 for 1 seconds
I0329 00:33:47.331037 21855 master.cpp:679] Received reply for offer 201203290030-0-325
I0329 00:33:47.331251 21855 master.cpp:1184] Sending 1 offers to framework 201203290030-0-0001
I0329 00:33:47.331455 21855 master.cpp:1403] Filtered slave 201203290030-0-0 for framework 201203290030-0-0001 for 1 seconds
I0329 00:33:47.332888 21855 master.cpp:679] Received reply for offer 201203290030-0-326
I0329 00:33:47.333102 21855 master.cpp:1184] Sending 1 offers to framework 201203290030-0-0000
I0329 00:33:47.333248 21855 master.cpp:1403] Filtered slave 201203290030-0-1 for framework 201203290030-0-0001 for 1 seconds
I0329 00:33:47.334566 21855 master.cpp:679] Received reply for offer 201203290030-0-327
I0329 00:33:47.334717 21855 master.cpp:1403] Filtered slave 201203290030-0-0 for framework 201203290030-0-0000 for 1 seconds
I0329 00:33:48.331775 21855 master.cpp:1184] Sending 1 offers to framework 201203290030-0-0000
I0329 00:33:48.331985 21855 master.cpp:1184] Sending 1 offers to framework 201203290030-0-0001
I0329 00:33:48.333374 21855 master.cpp:679] Received reply for offer 201203290030-0-328
I0329 00:33:48.333529 21855 master.cpp:1403] Filtered slave 201203290030-0-1 for framework 201203290030-0-0000 for 1 seconds
I0329 00:33:48.333757 21855 master.cpp:679] Received reply for offer 201203290030-0-329
I0329 00:33:48.333919 21855 master.cpp:1403] Filtered slave 201203290030-0-0 for framework 201203290030-0-0001 for 1 seconds
I0329 00:33:49.333968 21855 master.cpp:1184] Sending 1 offers to framework 201203290030-0-0000
I0329 00:33:49.334168 21855 master.cpp:1184] Sending 1 offers to framework 201203290030-0-0001
I0329 00:33:49.335618 21855 master.cpp:679] Received reply for offer 201203290030-0-330
I0329 00:33:49.335773 21855 master.cpp:1403] Filtered slave 201203290030-0-0 for framework 201203290030-0-0000 for 1 seconds
I0329 00:33:49.336134 21855 master.cpp:679] Received reply for offer 201203290030-0-331
I0329 00:33:49.336294 21855 master.cpp:1403] Filtered slave 201203290030-0-1 for framework 201203290030-0-0001 for 1 seconds
I0329 00:33:50.336355 21855 master.cpp:1184] Sending 1 offers to framework 201203290030-0-0000
I0329 00:33:50.336565 21855 master.cpp:1184] Sending 1 offers to framework 201203290030-0-0001
I0329 00:33:50.338018 21855 master.cpp:679] Received reply for offer 201203290030-0-332
I0329 00:33:50.338176 21855 master.cpp:1403] Filtered slave 201203290030-0-1 for framework 201203290030-0-0000 for 1 seconds
I0329 00:33:50.338413 21855 master.cpp:679] Received reply for offer 201203290030-0-333
I0329 00:33:50.338569 21855 master.cpp:1403] Filtered slave 201203290030-0-0 for framework 201203290030-0-0001 for 1 seconds
I0329 00:33:51.338620 21855 master.cpp:1184] Sending 1 offers to framework 201203290030-0-0000
I0329 00:33:51.338779 21855 master.cpp:1184] Sending 1 offers to framework 201203290030-0-0001
I0329 00:33:51.340186 21855 master.cpp:679] Received reply for offer 201203290030-0-334
I0329 00:33:51.405902 21855 master.cpp:1403] Filtered slave 201203290030-0-0 for framework 201203290030-0-0000 for 1 seconds
I0329 00:33:51.448154 21855 master.cpp:679] Received reply for offer 201203290030-0-335
I0329 00:33:51.448585 21855 master.cpp:1403] Filtered slave 201203290030-0-1 for framework 201203290030-0-0001 for 1 seconds
I0329 00:33:52.339939 21855 master.cpp:1184] Sending 1 offers to framework 201203290030-0-0000
I0329 00:33:52.340127 21855 master.cpp:1184] Sending 1 offers to framework 201203290030-0-0001
I0329 00:33:52.341522 21855 master.cpp:679] Received reply for offer 201203290030-0-336
I0329 00:33:52.341680 21855 master.cpp:1403] Filtered slave 201203290030-0-1 for framework 201203290030-0-0000 for 1 seconds
I0329 00:33:52.341917 21855 master.cpp:679] Received reply for offer 201203290030-0-337
I0329 00:33:52.342074 21855 master.cpp:1403] Filtered slave 201203290030-0-0 for framework 201203290030-0-0001 for 1 seconds
I0329 00:33:53.342114 21855 master.cpp:1184] Sending 1 offers to framework 201203290030-0-0000
I0329 00:33:53.342321 21855 master.cpp:1184] Sending 1 offers to framework 201203290030-0-0001
I0329 00:33:53.343773 21855 master.cpp:679] Received reply for offer 201203290030-0-338
I0329 00:33:53.343924 21855 master.cpp:1403] Filtered slave 201203290030-0-0 for framework 201203290030-0-0000 for 1 seconds
I0329 00:33:53.344158 21855 master.cpp:679] Received reply for offer 201203290030-0-339
I0329 00:33:53.344315 21855 master.cpp:1403] Filtered slave 201203290030-0-1 for framework 201203290030-0-0001 for 1 seconds
I0329 00:33:54.344365 21855 master.cpp:1184] Sending 1 offers to framework 201203290030-0-0000
I0329 00:33:54.344598 21855 master.cpp:1184] Sending 1 offers to framework 201203290030-0-0001
I0329 00:33:54.346020 21855 master.cpp:679] Received reply for offer 201203290030-0-340
I0329 00:33:54.346176 21855 master.cpp:1403] Filtered slave 201203290030-0-1 for framework 201203290030-0-0000 for 1 seconds
I0329 00:33:54.346441 21855 master.cpp:679] Received reply for offer 201203290030-0-341
I0329 00:33:54.346640 21855 master.cpp:1403] Filtered slave 201203290030-0-0 for framework 201203290030-0-0001 for 1 seconds
I0329 00:33:55.346772 21855 master.cpp:1184] Sending 1 offers to framework 201203290030-0-0000
I0329 00:33:55.347000 21855 master.cpp:1184] Sending 1 offers to framework 201203290030-0-0001
I0329 00:33:55.348569 21855 master.cpp:679] Received reply for offer 201203290030-0-342
I0329 00:33:55.348750 21855 master.cpp:1403] Filtered slave 201203290030-0-0 for framework 201203290030-0-0000 for 1 seconds
I0329 00:33:55.348975 21855 master.cpp:679] Received reply for offer 201203290030-0-343
I0329 00:33:55.349163 21855 master.cpp:1403] Filtered slave 201203290030-0-1 for framework 201203290030-0-0001 for 1 seconds
I0329 00:33:56.349320 21855 master.cpp:1184] Sending 1 offers to framework 201203290030-0-0000
I0329 00:33:56.349496 21855 master.cpp:1184] Sending 1 offers to framework 201203290030-0-0001
I0329 00:33:56.351027 21855 master.cpp:679] Received reply for offer 201203290030-0-344
I0329 00:33:56.393698 21855 master.cpp:1403] Filtered slave 201203290030-0-1 for framework 201203290030-0-0000 for 1 seconds
I0329 00:33:56.434000 21855 master.cpp:679] Received reply for offer 201203290030-0-345
I0329 00:33:56.434278 21855 master.cpp:1403] Filtered slave 201203290030-0-0 for framework 201203290030-0-0001 for 1 seconds
I0329 00:33:57.351943 21855 master.cpp:1184] Sending 1 offers to framework 201203290030-0-0000
I0329 00:33:57.352116 21855 master.cpp:1184] Sending 1 offers to framework 201203290030-0-0001
I0329 00:33:57.353705 21855 master.cpp:679] Received reply for offer 201203290030-0-346
I0329 00:33:57.353865 21855 master.cpp:1403] Filtered slave 201203290030-0-0 for framework 201203290030-0-0000 for 1 seconds
I0329 00:33:57.354015 21855 master.cpp:679] Received reply for offer 201203290030-0-347
I0329 00:33:57.354181 21855 master.cpp:1403] Filtered slave 201203290030-0-1 for framework 201203290030-0-0001 for 1 seconds
I0329 00:33:58.353103 21855 master.cpp:1184] Sending 1 offers to framework 201203290030-0-0000
I0329 00:33:58.353274 21855 master.cpp:1184] Sending 1 offers to framework 201203290030-0-0001
I0329 00:33:58.354831 21855 master.cpp:679] Received reply for offer 201203290030-0-348
I0329 00:33:58.354995 21855 master.cpp:1403] Filtered slave 201203290030-0-1 for framework 201203290030-0-0000 for 1 seconds
I0329 00:33:58.355240 21855 master.cpp:679] Received reply for offer 201203290030-0-349
I0329 00:33:58.355423 21855 master.cpp:1403] Filtered slave 201203290030-0-0 for framework 201203290030-0-0001 for 1 seconds
I0329 00:33:59.355586 21855 master.cpp:1184] Sending 1 offers to framework 201203290030-0-0000
I0329 00:33:59.355773 21855 master.cpp:1184] Sending 1 offers to framework 201203290030-0-0001
I0329 00:33:59.357481 21855 master.cpp:679] Received reply for offer 201203290030-0-350
I0329 00:33:59.357627 21855 master.cpp:1403] Filtered slave 201203290030-0-0 for framework 201203290030-0-0000 for 1 seconds
I0329 00:33:59.357907 21855 master.cpp:679] Received reply for offer 201203290030-0-351
I0329 00:33:59.358067 21855 master.cpp:1403] Filtered slave 201203290030-0-1 for framework 201203290030-0-0001 for 1 seconds
I0329 00:34:00.358155 21855 master.cpp:1184] Sending 1 offers to framework 201203290030-0-0000
I0329 00:34:00.358340 21855 master.cpp:1184] Sending 1 offers to framework 201203290030-0-0001
I0329 00:34:00.359850 21855 master.cpp:679] Received reply for offer 201203290030-0-352
I0329 00:34:00.360015 21855 master.cpp:1403] Filtered slave 201203290030-0-1 for framework 201203290030-0-0000 for 1 seconds
I0329 00:34:00.360340 21855 master.cpp:679] Received reply for offer 201203290030-0-353
I0329 00:34:00.360527 21855 master.cpp:1403] Filtered slave 201203290030-0-0 for framework 201203290030-0-0001 for 1 seconds
I0329 00:34:01.360718 21855 master.cpp:1184] Sending 1 offers to framework 201203290030-0-0000
I0329 00:34:01.360887 21855 master.cpp:1184] Sending 1 offers to framework 201203290030-0-0001
I0329 00:34:01.362408 21855 master.cpp:679] Received reply for offer 201203290030-0-354
I0329 00:34:01.405388 21855 master.cpp:1403] Filtered slave 201203290030-0-0 for framework 201203290030-0-0000 for 1 seconds
I0329 00:34:01.437437 21855 master.cpp:679] Received reply for offer 201203290030-0-355
I0329 00:34:01.437717 21855 master.cpp:1403] Filtered slave 201203290030-0-1 for framework 201203290030-0-0001 for 1 seconds
I0329 00:34:02.363001 21855 master.cpp:1184] Sending 1 offers to framework 201203290030-0-0000
I0329 00:34:02.363219 21855 master.cpp:1184] Sending 1 offers to framework 201203290030-0-0001
I0329 00:34:02.364579 21855 master.cpp:679] Received reply for offer 201203290030-0-356
I0329 00:34:02.364737 21855 master.cpp:1403] Filtered slave 201203290030-0-1 for framework 201203290030-0-0000 for 1 seconds
I0329 00:34:02.365190 21855 master.cpp:679] Received reply for offer 201203290030-0-357
I0329 00:34:02.365350 21855 master.cpp:1403] Filtered slave 201203290030-0-0 for framework 201203290030-0-0001 for 1 seconds
I0329 00:34:03.365403 21855 master.cpp:1184] Sending 1 offers to framework 201203290030-0-0000
I0329 00:34:03.365594 21855 master.cpp:1184] Sending 1 offers to framework 201203290030-0-0001
I0329 00:34:03.367025 21855 master.cpp:679] Received reply for offer 201203290030-0-358
I0329 00:34:03.367194 21855 master.cpp:1403] Filtered slave 201203290030-0-0 for framework 201203290030-0-0000 for 1 seconds
I0329 00:34:03.367568 21855 master.cpp:679] Received reply for offer 201203290030-0-359
I0329 00:34:03.367728 21855 master.cpp:1403] Filtered slave 201203290030-0-1 for framework 201203290030-0-0001 for 1 seconds
I0329 00:34:04.367745 21855 master.cpp:1184] Sending 1 offers to framework 201203290030-0-0000
I0329 00:34:04.367945 21855 master.cpp:1184] Sending 1 offers to framework 201203290030-0-0001
I0329 00:34:04.369359 21855 master.cpp:679] Received reply for offer 201203290030-0-360
I0329 00:34:04.369518 21855 master.cpp:1403] Filtered slave 201203290030-0-1 for framework 201203290030-0-0000 for 1 seconds
I0329 00:34:04.370010 21855 master.cpp:679] Received reply for offer 201203290030-0-361
I0329 00:34:04.370182 21855 master.cpp:1403] Filtered slave 201203290030-0-0 for framework 201203290030-0-0001 for 1 seconds
I0329 00:34:05.370277 21855 master.cpp:1184] Sending 1 offers to framework 201203290030-0-0000
I0329 00:34:05.370466 21855 master.cpp:1184] Sending 1 offers to framework 201203290030-0-0001
I0329 00:34:05.372089 21855 master.cpp:679] Received reply for offer 201203290030-0-362
I0329 00:34:05.372238 21855 master.cpp:1403] Filtered slave 201203290030-0-0 for framework 201203290030-0-0000 for 1 seconds
I0329 00:34:05.372675 21855 master.cpp:679] Received reply for offer 201203290030-0-363
I0329 00:34:05.372846 21855 master.cpp:1403] Filtered slave 201203290030-0-1 for framework 201203290030-0-0001 for 1 seconds
I0329 00:34:06.372946 21855 master.cpp:1184] Sending 1 offers to framework 201203290030-0-0000
I0329 00:34:06.373107 21855 master.cpp:1184] Sending 1 offers to framework 201203290030-0-0001
I0329 00:34:06.374614 21855 master.cpp:679] Received reply for offer 201203290030-0-364
I0329 00:34:06.417161 21855 master.cpp:1403] Filtered slave 201203290030-0-1 for framework 201203290030-0-0000 for 1 seconds
I0329 00:34:06.457300 21855 master.cpp:679] Received reply for offer 201203290030-0-365
I0329 00:34:06.457658 21855 master.cpp:1403] Filtered slave 201203290030-0-0 for framework 201203290030-0-0001 for 1 seconds
I0329 00:34:07.375406 21855 master.cpp:1184] Sending 1 offers to framework 201203290030-0-0000
I0329 00:34:07.375581 21855 master.cpp:1184] Sending 1 offers to framework 201203290030-0-0001
I0329 00:34:07.377060 21855 master.cpp:679] Received reply for offer 201203290030-0-366
I0329 00:34:07.377240 21855 master.cpp:1403] Filtered slave 201203290030-0-0 for framework 201203290030-0-0000 for 1 seconds
I0329 00:34:07.377737 21855 master.cpp:679] Received reply for offer 201203290030-0-367
I0329 00:34:07.378237 21855 master.cpp:1403] Filtered slave 201203290030-0-1 for framework 201203290030-0-0001 for 1 seconds
I0329 00:34:08.377959 21855 master.cpp:1184] Sending 1 offers to framework 201203290030-0-0000
I0329 00:34:08.378152 21855 master.cpp:1184] Sending 1 offers to framework 201203290030-0-0001
I0329 00:34:08.379730 21855 master.cpp:679] Received reply for offer 201203290030-0-368
I0329 00:34:08.379901 21855 master.cpp:1403] Filtered slave 201203290030-0-1 for framework 201203290030-0-0000 for 1 seconds
I0329 00:34:08.380365 21855 master.cpp:679] Received reply for offer 201203290030-0-369
I0329 00:34:08.380506 21855 master.cpp:1403] Filtered slave 201203290030-0-0 for framework 201203290030-0-0001 for 1 seconds
I0329 00:34:09.380624 21855 master.cpp:1184] Sending 1 offers to framework 201203290030-0-0000
I0329 00:34:09.380839 21855 master.cpp:1184] Sending 1 offers to framework 201203290030-0-0001
I0329 00:34:09.382346 21855 master.cpp:679] Received reply for offer 201203290030-0-370
I0329 00:34:09.382527 21855 master.cpp:1403] Filtered slave 201203290030-0-0 for framework 201203290030-0-0000 for 1 seconds
I0329 00:34:09.382969 21855 master.cpp:679] Received reply for offer 201203290030-0-371
I0329 00:34:09.383242 21855 master.cpp:1403] Filtered slave 201203290030-0-1 for framework 201203290030-0-0001 for 1 seconds
I0329 00:34:10.383216 21855 master.cpp:1184] Sending 1 offers to framework 201203290030-0-0000
I0329 00:34:10.383447 21855 master.cpp:1184] Sending 1 offers to framework 201203290030-0-0001
I0329 00:34:10.385040 21855 master.cpp:679] Received reply for offer 201203290030-0-372
I0329 00:34:10.385225 21855 master.cpp:1403] Filtered slave 201203290030-0-1 for framework 201203290030-0-0000 for 1 seconds
I0329 00:34:10.385689 21855 master.cpp:679] Received reply for offer 201203290030-0-373
I0329 00:34:10.385922 21855 master.cpp:1403] Filtered slave 201203290030-0-0 for framework 201203290030-0-0001 for 1 seconds
I0329 00:34:11.385907 21855 master.cpp:1184] Sending 1 offers to framework 201203290030-0-0000
I0329 00:34:11.386083 21855 master.cpp:1184] Sending 1 offers to framework 201203290030-0-0001
I0329 00:34:11.387722 21855 master.cpp:679] Received reply for offer 201203290030-0-374
I0329 00:34:11.452792 21855 master.cpp:1403] Filtered slave 201203290030-0-0 for framework 201203290030-0-0000 for 1 seconds
I0329 00:34:11.478869 21855 master.cpp:679] Received reply for offer 201203290030-0-375
I0329 00:34:11.479300 21855 master.cpp:1403] Filtered slave 201203290030-0-1 for framework 201203290030-0-0001 for 1 seconds
I0329 00:34:12.388730 21855 master.cpp:1184] Sending 1 offers to framework 201203290030-0-0000
I0329 00:34:12.388918 21855 master.cpp:1184] Sending 1 offers to framework 201203290030-0-0001
I0329 00:34:12.390338 21855 master.cpp:679] Received reply for offer 201203290030-0-376
I0329 00:34:12.390498 21855 master.cpp:1403] Filtered slave 201203290030-0-1 for framework 201203290030-0-0000 for 1 seconds
I0329 00:34:12.390724 21855 master.cpp:679] Received reply for offer 201203290030-0-377
I0329 00:34:12.390936 21855 master.cpp:1403] Filtered slave 201203290030-0-0 for framework 201203290030-0-0001 for 1 seconds
I0329 00:34:13.390738 21855 master.cpp:1184] Sending 1 offers to framework 201203290030-0-0000
I0329 00:34:13.390921 21855 master.cpp:1184] Sending 1 offers to framework 201203290030-0-0001
I0329 00:34:13.392307 21855 master.cpp:679] Received reply for offer 201203290030-0-378
I0329 00:34:13.392458 21855 master.cpp:1403] Filtered slave 201203290030-0-0 for framework 201203290030-0-0000 for 1 seconds
I0329 00:34:13.392770 21855 master.cpp:679] Received reply for offer 201203290030-0-379
I0329 00:34:13.392926 21855 master.cpp:1403] Filtered slave 201203290030-0-1 for framework 201203290030-0-0001 for 1 seconds
I0329 00:34:14.393044 21855 master.cpp:1184] Sending 1 offers to framework 201203290030-0-0000
I0329 00:34:14.393265 21855 master.cpp:1184] Sending 1 offers to framework 201203290030-0-0001
I0329 00:34:14.394706 21855 master.cpp:679] Received reply for offer 201203290030-0-380
I0329 00:34:14.394855 21855 master.cpp:1403] Filtered slave 201203290030-0-1 for framework 201203290030-0-0000 for 1 seconds
I0329 00:34:14.395144 21855 master.cpp:679] Received reply for offer 201203290030-0-381
I0329 00:34:14.395372 21855 master.cpp:1403] Filtered slave 201203290030-0-0 for framework 201203290030-0-0001 for 1 seconds
I0329 00:34:15.395408 21855 master.cpp:1184] Sending 1 offers to framework 201203290030-0-0000
I0329 00:34:15.395588 21855 master.cpp:1184] Sending 1 offers to framework 201203290030-0-0001
I0329 00:34:15.397014 21855 master.cpp:679] Received reply for offer 201203290030-0-382
I0329 00:34:15.397183 21855 master.cpp:1403] Filtered slave 201203290030-0-0 for framework 201203290030-0-0000 for 1 seconds
I0329 00:34:15.397446 21855 master.cpp:679] Received reply for offer 201203290030-0-383
I0329 00:34:15.397619 21855 master.cpp:1403] Filtered slave 201203290030-0-1 for framework 201203290030-0-0001 for 1 seconds
I0329 00:34:16.397722 21855 master.cpp:1184] Sending 1 offers to framework 201203290030-0-0000
I0329 00:34:16.397881 21855 master.cpp:1184] Sending 1 offers to framework 201203290030-0-0001
I0329 00:34:16.399271 21855 master.cpp:679] Received reply for offer 201203290030-0-384
I0329 00:34:16.464197 21855 master.cpp:1403] Filtered slave 201203290030-0-1 for framework 201203290030-0-0000 for 1 seconds
I0329 00:34:16.482381 21855 master.cpp:679] Received reply for offer 201203290030-0-385
I0329 00:34:16.482789 21855 master.cpp:1403] Filtered slave 201203290030-0-0 for framework 201203290030-0-0001 for 1 seconds
I0329 00:34:17.399895 21855 master.cpp:1184] Sending 1 offers to framework 201203290030-0-0000
I0329 00:34:17.400099 21855 master.cpp:1184] Sending 1 offers to framework 201203290030-0-0001
I0329 00:34:17.401450 21855 master.cpp:679] Received reply for offer 201203290030-0-386
I0329 00:34:17.401618 21855 master.cpp:1403] Filtered slave 201203290030-0-0 for framework 201203290030-0-0000 for 1 seconds
I0329 00:34:17.402004 21855 master.cpp:679] Received reply for offer 201203290030-0-387
I0329 00:34:17.402175 21855 master.cpp:1403] Filtered slave 201203290030-0-1 for framework 201203290030-0-0001 for 1 seconds
I0329 00:34:18.401507 21855 master.cpp:1184] Sending 1 offers to framework 201203290030-0-0000
I0329 00:34:18.401706 21855 master.cpp:1184] Sending 1 offers to framework 201203290030-0-0001
I0329 00:34:18.403091 21855 master.cpp:679] Received reply for offer 201203290030-0-388
I0329 00:34:18.403259 21855 master.cpp:1403] Filtered slave 201203290030-0-1 for framework 201203290030-0-0000 for 1 seconds
I0329 00:34:18.403652 21855 master.cpp:679] Received reply for offer 201203290030-0-389
I0329 00:34:18.403823 21855 master.cpp:1403] Filtered slave 201203290030-0-0 for framework 201203290030-0-0001 for 1 seconds
I0329 00:34:19.403401 21855 master.cpp:1184] Sending 1 offers to framework 201203290030-0-0000
I0329 00:34:19.403600 21855 master.cpp:1184] Sending 1 offers to framework 201203290030-0-0001
I0329 00:34:19.405026 21855 master.cpp:679] Received reply for offer 201203290030-0-390
I0329 00:34:19.405194 21855 master.cpp:1403] Filtered slave 201203290030-0-0 for framework 201203290030-0-0000 for 1 seconds
I0329 00:34:19.405410 21855 master.cpp:679] Received reply for offer 201203290030-0-391
I0329 00:34:19.405575 21855 master.cpp:1403] Filtered slave 201203290030-0-1 for framework 201203290030-0-0001 for 1 seconds
I0329 00:34:20.405627 21855 master.cpp:1184] Sending 1 offers to framework 201203290030-0-0000
I0329 00:34:20.405829 21855 master.cpp:1184] Sending 1 offers to framework 201203290030-0-0001
I0329 00:34:20.407241 21855 master.cpp:679] Received reply for offer 201203290030-0-392
I0329 00:34:20.407388 21855 master.cpp:1403] Filtered slave 201203290030-0-1 for framework 201203290030-0-0000 for 1 seconds
I0329 00:34:20.407686 21855 master.cpp:679] Received reply for offer 201203290030-0-393
I0329 00:34:20.407861 21855 master.cpp:1403] Filtered slave 201203290030-0-0 for framework 201203290030-0-0001 for 1 seconds
I0329 00:34:21.407877 21855 master.cpp:1184] Sending 1 offers to framework 201203290030-0-0000
I0329 00:34:21.408033 21855 master.cpp:1184] Sending 1 offers to framework 201203290030-0-0001
I0329 00:34:21.409478 21855 master.cpp:679] Received reply for offer 201203290030-0-394
I0329 00:34:21.436100 21855 master.cpp:1403] Filtered slave 201203290030-0-0 for framework 201203290030-0-0000 for 1 seconds
I0329 00:34:21.475656 21855 master.cpp:679] Received reply for offer 201203290030-0-395
I0329 00:34:21.476065 21855 master.cpp:1403] Filtered slave 201203290030-0-1 for framework 201203290030-0-0001 for 1 seconds
I0329 00:34:22.410099 21855 master.cpp:1184] Sending 1 offers to framework 201203290030-0-0000
I0329 00:34:22.410298 21855 master.cpp:1184] Sending 1 offers to framework 201203290030-0-0001
I0329 00:34:22.411633 21855 master.cpp:679] Received reply for offer 201203290030-0-396
I0329 00:34:22.411803 21855 master.cpp:1403] Filtered slave 201203290030-0-1 for framework 201203290030-0-0000 for 1 seconds
I0329 00:34:22.412210 21855 master.cpp:679] Received reply for offer 201203290030-0-397
I0329 00:34:22.412472 21855 master.cpp:1403] Filtered slave 201203290030-0-0 for framework 201203290030-0-0001 for 1 seconds
I0329 00:34:23.412406 21855 master.cpp:1184] Sending 1 offers to framework 201203290030-0-0000
I0329 00:34:23.412611 21855 master.cpp:1184] Sending 1 offers to framework 201203290030-0-0001
I0329 00:34:23.414026 21855 master.cpp:679] Received reply for offer 201203290030-0-398
I0329 00:34:23.414190 21855 master.cpp:1403] Filtered slave 201203290030-0-0 for framework 201203290030-0-0000 for 1 seconds
I0329 00:34:23.414566 21855 master.cpp:679] Received reply for offer 201203290030-0-399
I0329 00:34:23.414736 21855 master.cpp:1403] Filtered slave 201203290030-0-1 for framework 201203290030-0-0001 for 1 seconds
I0329 00:34:24.414736 21855 master.cpp:1184] Sending 1 offers to framework 201203290030-0-0000
I0329 00:34:24.414938 21855 master.cpp:1184] Sending 1 offers to framework 201203290030-0-0001
I0329 00:34:24.416367 21855 master.cpp:679] Received reply for offer 201203290030-0-400
I0329 00:34:24.416606 21855 master.cpp:1403] Filtered slave 201203290030-0-1 for framework 201203290030-0-0000 for 1 seconds
I0329 00:34:24.416774 21855 master.cpp:679] Received reply for offer 201203290030-0-401
I0329 00:34:24.416934 21855 master.cpp:1403] Filtered slave 201203290030-0-0 for framework 201203290030-0-0001 for 1 seconds
I0329 00:34:25.416949 21855 master.cpp:1184] Sending 1 offers to framework 201203290030-0-0000
I0329 00:34:25.417152 21855 master.cpp:1184] Sending 1 offers to framework 201203290030-0-0001
I0329 00:34:25.418540 21855 master.cpp:679] Received reply for offer 201203290030-0-402
I0329 00:34:25.418705 21855 master.cpp:1403] Filtered slave 201203290030-0-0 for framework 201203290030-0-0000 for 1 seconds
I0329 00:34:25.418931 21855 master.cpp:679] Received reply for offer 201203290030-0-403
I0329 00:34:25.419203 21855 master.cpp:1403] Filtered slave 201203290030-0-1 for framework 201203290030-0-0001 for 1 seconds
I0329 00:34:26.419227 21855 master.cpp:1184] Sending 1 offers to framework 201203290030-0-0000
I0329 00:34:26.419402 21855 master.cpp:1184] Sending 1 offers to framework 201203290030-0-0001
I0329 00:34:26.420841 21855 master.cpp:679] Received reply for offer 201203290030-0-404
I0329 00:34:26.456346 21855 master.cpp:1403] Filtered slave 201203290030-0-1 for framework 201203290030-0-0000 for 1 seconds
I0329 00:34:26.504024 21855 master.cpp:679] Received reply for offer 201203290030-0-405
I0329 00:34:26.504315 21855 master.cpp:1403] Filtered slave 201203290030-0-0 for framework 201203290030-0-0001 for 1 seconds
I0329 00:34:27.421529 21855 master.cpp:1184] Sending 1 offers to framework 201203290030-0-0000
I0329 00:34:27.421726 21855 master.cpp:1184] Sending 1 offers to framework 201203290030-0-0001
I0329 00:34:27.423099 21855 master.cpp:679] Received reply for offer 201203290030-0-406
I0329 00:34:27.423285 21855 master.cpp:1403] Filtered slave 201203290030-0-0 for framework 201203290030-0-0000 for 1 seconds
I0329 00:34:27.423742 21855 master.cpp:679] Received reply for offer 201203290030-0-407
I0329 00:34:27.424181 21855 master.cpp:1403] Filtered slave 201203290030-0-1 for framework 201203290030-0-0001 for 1 seconds
I0329 00:34:28.423110 21855 master.cpp:1184] Sending 1 offers to framework 201203290030-0-0000
I0329 00:34:28.423316 21855 master.cpp:1184] Sending 1 offers to framework 201203290030-0-0001
I0329 00:34:28.424741 21855 master.cpp:679] Received reply for offer 201203290030-0-408
I0329 00:34:28.424885 21855 master.cpp:1403] Filtered slave 201203290030-0-1 for framework 201203290030-0-0000 for 1 seconds
I0329 00:34:28.425137 21855 master.cpp:679] Received reply for offer 201203290030-0-409
I0329 00:34:28.425312 21855 master.cpp:1403] Filtered slave 201203290030-0-0 for framework 201203290030-0-0001 for 1 seconds
I0329 00:34:29.425487 21855 master.cpp:1184] Sending 1 offers to framework 201203290030-0-0000
I0329 00:34:29.425775 21855 master.cpp:1184] Sending 1 offers to framework 201203290030-0-0001
I0329 00:34:29.427289 21855 master.cpp:679] Received reply for offer 201203290030-0-410
I0329 00:34:29.427522 21855 master.cpp:1403] Filtered slave 201203290030-0-0 for framework 201203290030-0-0000 for 1 seconds
I0329 00:34:29.427685 21855 master.cpp:679] Received reply for offer 201203290030-0-411
I0329 00:34:29.427852 21855 master.cpp:1403] Filtered slave 201203290030-0-1 for framework 201203290030-0-0001 for 1 seconds
I0329 00:34:30.427981 21855 master.cpp:1184] Sending 1 offers to framework 201203290030-0-0000
I0329 00:34:30.428205 21855 master.cpp:1184] Sending 1 offers to framework 201203290030-0-0001
I0329 00:34:30.429610 21855 master.cpp:679] Received reply for offer 201203290030-0-412
I0329 00:34:30.429838 21855 master.cpp:1403] Filtered slave 201203290030-0-1 for framework 201203290030-0-0000 for 1 seconds
I0329 00:34:30.430006 21855 master.cpp:679] Received reply for offer 201203290030-0-413
I0329 00:34:30.430178 21855 master.cpp:1403] Filtered slave 201203290030-0-0 for framework 201203290030-0-0001 for 1 seconds
I0329 00:34:31.430290 21855 master.cpp:1184] Sending 1 offers to framework 201203290030-0-0000
I0329 00:34:31.430465 21855 master.cpp:1184] Sending 1 offers to framework 201203290030-0-0001
I0329 00:34:31.431937 21855 master.cpp:679] Received reply for offer 201203290030-0-414
I0329 00:34:31.476562 21855 master.cpp:1403] Filtered slave 201203290030-0-0 for framework 201203290030-0-0000 for 1 seconds
I0329 00:34:31.515631 21855 master.cpp:679] Received reply for offer 201203290030-0-415
I0329 00:34:31.515904 21855 master.cpp:1403] Filtered slave 201203290030-0-1 for framework 201203290030-0-0001 for 1 seconds
I0329 00:34:32.432504 21855 master.cpp:1184] Sending 1 offers to framework 201203290030-0-0000
I0329 00:34:32.432783 21855 master.cpp:1184] Sending 1 offers to framework 201203290030-0-0001
I0329 00:34:32.434080 21855 master.cpp:679] Received reply for offer 201203290030-0-416
I0329 00:34:32.434239 21855 master.cpp:1403] Filtered slave 201203290030-0-1 for framework 201203290030-0-0000 for 1 seconds
I0329 00:34:32.434430 21855 master.cpp:679] Received reply for offer 201203290030-0-417
I0329 00:34:32.434592 21855 master.cpp:1403] Filtered slave 201203290030-0-0 for framework 201203290030-0-0001 for 1 seconds
I0329 00:34:33.434640 21855 master.cpp:1184] Sending 1 offers to framework 201203290030-0-0000
I0329 00:34:33.434831 21855 master.cpp:1184] Sending 1 offers to framework 201203290030-0-0001
I0329 00:34:33.436094 21855 master.cpp:679] Received reply for offer 201203290030-0-418
I0329 00:34:33.436247 21855 master.cpp:1403] Filtered slave 201203290030-0-0 for framework 201203290030-0-0000 for 1 seconds
I0329 00:34:33.436465 21855 master.cpp:679] Received reply for offer 201203290030-0-419
I0329 00:34:33.436640 21855 master.cpp:1403] Filtered slave 201203290030-0-1 for framework 201203290030-0-0001 for 1 seconds
I0329 00:34:34.436645 21855 master.cpp:1184] Sending 1 offers to framework 201203290030-0-0000
I0329 00:34:34.436887 21855 master.cpp:1184] Sending 1 offers to framework 201203290030-0-0001
I0329 00:34:34.438192 21855 master.cpp:679] Received reply for offer 201203290030-0-420
I0329 00:34:34.438344 21855 master.cpp:1403] Filtered slave 201203290030-0-1 for framework 201203290030-0-0000 for 1 seconds
I0329 00:34:34.438572 21855 master.cpp:679] Received reply for offer 201203290030-0-421
I0329 00:34:34.438833 21855 master.cpp:1403] Filtered slave 201203290030-0-0 for framework 201203290030-0-0001 for 1 seconds
I0329 00:34:35.438698 21855 master.cpp:1184] Sending 1 offers to framework 201203290030-0-0000
I0329 00:34:35.438928 21855 master.cpp:1184] Sending 1 offers to framework 201203290030-0-0001
I0329 00:34:35.440557 21855 master.cpp:679] Received reply for offer 201203290030-0-422
I0329 00:34:35.440737 21855 master.cpp:1403] Filtered slave 201203290030-0-0 for framework 201203290030-0-0000 for 1 seconds
I0329 00:34:35.440944 21855 master.cpp:679] Received reply for offer 201203290030-0-423
I0329 00:34:35.441170 21855 master.cpp:1403] Filtered slave 201203290030-0-1 for framework 201203290030-0-0001 for 1 seconds
I0329 00:34:36.441154 21855 master.cpp:1184] Sending 1 offers to framework 201203290030-0-0000
I0329 00:34:36.441333 21855 master.cpp:1184] Sending 1 offers to framework 201203290030-0-0001
I0329 00:34:36.442762 21855 master.cpp:679] Received reply for offer 201203290030-0-424
I0329 00:34:36.496628 21855 master.cpp:1403] Filtered slave 201203290030-0-1 for framework 201203290030-0-0000 for 1 seconds
I0329 00:34:36.535648 21855 master.cpp:679] Received reply for offer 201203290030-0-425
I0329 00:34:36.535945 21855 master.cpp:1403] Filtered slave 201203290030-0-0 for framework 201203290030-0-0001 for 1 seconds
I0329 00:34:37.443436 21855 master.cpp:1184] Sending 1 offers to framework 201203290030-0-0000
I0329 00:34:37.443686 21855 master.cpp:1184] Sending 1 offers to framework 201203290030-0-0001
I0329 00:34:37.445106 21855 master.cpp:679] Received reply for offer 201203290030-0-426
I0329 00:34:37.445257 21855 master.cpp:1403] Filtered slave 201203290030-0-0 for framework 201203290030-0-0000 for 1 seconds
I0329 00:34:37.445603 21855 master.cpp:679] Received reply for offer 201203290030-0-427
I0329 00:34:37.445765 21855 master.cpp:1403] Filtered slave 201203290030-0-1 for framework 201203290030-0-0001 for 1 seconds
I0329 00:34:38.445822 21855 master.cpp:1184] Sending 1 offers to framework 201203290030-0-0000
I0329 00:34:38.446027 21855 master.cpp:1184] Sending 1 offers to framework 201203290030-0-0001
I0329 00:34:38.447417 21855 master.cpp:679] Received reply for offer 201203290030-0-428
I0329 00:34:38.447576 21855 master.cpp:1403] Filtered slave 201203290030-0-1 for framework 201203290030-0-0000 for 1 seconds
I0329 00:34:38.447939 21855 master.cpp:679] Received reply for offer 201203290030-0-429
I0329 00:34:38.448107 21855 master.cpp:1403] Filtered slave 201203290030-0-0 for framework 201203290030-0-0001 for 1 seconds
I0329 00:34:39.448168 21855 master.cpp:1184] Sending 1 offers to framework 201203290030-0-0000
I0329 00:34:39.448402 21855 master.cpp:1184] Sending 1 offers to framework 201203290030-0-0001
I0329 00:34:39.449471 21855 master.cpp:679] Received reply for offer 201203290030-0-430
I0329 00:34:39.449625 21855 master.cpp:1403] Filtered slave 201203290030-0-0 for framework 201203290030-0-0000 for 1 seconds
I0329 00:34:39.449759 21855 master.cpp:679] Received reply for offer 201203290030-0-431
I0329 00:34:39.449888 21855 master.cpp:1403] Filtered slave 201203290030-0-1 for framework 201203290030-0-0001 for 1 seconds
I0329 00:34:40.450954 21855 master.cpp:1184] Sending 1 offers to framework 201203290030-0-0000
I0329 00:34:40.451195 21855 master.cpp:1184] Sending 1 offers to framework 201203290030-0-0001
I0329 00:34:40.452721 21855 master.cpp:679] Received reply for offer 201203290030-0-432
I0329 00:34:40.452903 21855 master.cpp:1403] Filtered slave 201203290030-0-1 for framework 201203290030-0-0000 for 1 seconds
I0329 00:34:40.453068 21855 master.cpp:679] Received reply for offer 201203290030-0-433
I0329 00:34:40.453263 21855 master.cpp:1184] Sending 1 offers to framework 201203290030-0-0001
I0329 00:34:40.453730 21855 master.cpp:1403] Filtered slave 201203290030-0-0 for framework 201203290030-0-0001 for 1 seconds
I0329 00:34:40.455009 21855 master.cpp:679] Received reply for offer 201203290030-0-434
I0329 00:34:40.455320 21855 master.cpp:1184] Sending 1 offers to framework 201203290030-0-0000
I0329 00:34:40.455482 21855 master.cpp:1403] Filtered slave 201203290030-0-1 for framework 201203290030-0-0001 for 1 seconds
I0329 00:34:40.456796 21855 master.cpp:679] Received reply for offer 201203290030-0-435
I0329 00:34:40.456994 21855 master.cpp:1403] Filtered slave 201203290030-0-0 for framework 201203290030-0-0000 for 1 seconds
I0329 00:34:41.453119 21855 master.cpp:1184] Sending 1 offers to framework 201203290030-0-0000
I0329 00:34:41.454851 21855 master.cpp:679] Received reply for offer 201203290030-0-436
I0329 00:34:41.454951 21855 master.cpp:1403] Filtered slave 201203290030-0-1 for framework 201203290030-0-0000 for 1 seconds
I0329 00:34:42.455168 21855 master.cpp:1184] Sending 2 offers to framework 201203290030-0-0001
I0329 00:34:42.456961 21855 master.cpp:679] Received reply for offer 201203290030-0-437
I0329 00:34:42.457111 21855 master.cpp:1403] Filtered slave 201203290030-0-0 for framework 201203290030-0-0001 for 1 seconds
I0329 00:34:42.457383 21855 master.cpp:679] Received reply for offer 201203290030-0-438
I0329 00:34:42.457597 21855 master.cpp:1184] Sending 1 offers to framework 201203290030-0-0000
I0329 00:34:42.457746 21855 master.cpp:1403] Filtered slave 201203290030-0-1 for framework 201203290030-0-0001 for 1 seconds
I0329 00:34:42.459100 21855 master.cpp:679] Received reply for offer 201203290030-0-439
I0329 00:34:42.459281 21855 master.cpp:1403] Filtered slave 201203290030-0-0 for framework 201203290030-0-0000 for 1 seconds
I0329 00:34:43.456007 21855 master.cpp:1184] Sending 1 offers to framework 201203290030-0-0000
I0329 00:34:43.457706 21855 master.cpp:679] Received reply for offer 201203290030-0-440
I0329 00:34:43.457867 21855 master.cpp:1403] Filtered slave 201203290030-0-1 for framework 201203290030-0-0000 for 1 seconds
I0329 00:34:44.457983 21855 master.cpp:1184] Sending 2 offers to framework 201203290030-0-0001
I0329 00:34:44.459923 21855 master.cpp:679] Received reply for offer 201203290030-0-441
I0329 00:34:44.460070 21855 master.cpp:1403] Filtered slave 201203290030-0-0 for framework 201203290030-0-0001 for 1 seconds
I0329 00:34:44.460340 21855 master.cpp:679] Received reply for offer 201203290030-0-442
I0329 00:34:44.460551 21855 master.cpp:1184] Sending 1 offers to framework 201203290030-0-0000
I0329 00:34:44.460737 21855 master.cpp:1403] Filtered slave 201203290030-0-1 for framework 201203290030-0-0001 for 1 seconds
I0329 00:34:44.462085 21855 master.cpp:679] Received reply for offer 201203290030-0-443
I0329 00:34:44.462271 21855 master.cpp:1403] Filtered slave 201203290030-0-0 for framework 201203290030-0-0000 for 1 seconds
I0329 00:34:45.460368 21855 master.cpp:1184] Sending 1 offers to framework 201203290030-0-0000
I0329 00:34:45.462015 21855 master.cpp:679] Received reply for offer 201203290030-0-444
I0329 00:34:45.462168 21855 master.cpp:1403] Filtered slave 201203290030-0-1 for framework 201203290030-0-0000 for 1 seconds
I0329 00:34:46.462338 21855 master.cpp:1184] Sending 2 offers to framework 201203290030-0-0001
I0329 00:34:46.464159 21855 master.cpp:679] Received reply for offer 201203290030-0-445
I0329 00:34:46.464252 21855 master.cpp:1403] Filtered slave 201203290030-0-0 for framework 201203290030-0-0001 for 1 seconds
I0329 00:34:46.520129 21855 master.cpp:679] Received reply for offer 201203290030-0-446
I0329 00:34:46.558992 21855 master.cpp:1184] Sending 1 offers to framework 201203290030-0-0000
I0329 00:34:46.559308 21855 master.cpp:1403] Filtered slave 201203290030-0-1 for framework 201203290030-0-0001 for 1 seconds
I0329 00:34:46.560569 21855 master.cpp:679] Received reply for offer 201203290030-0-447
I0329 00:34:46.560749 21855 master.cpp:1403] Filtered slave 201203290030-0-0 for framework 201203290030-0-0000 for 1 seconds
I0329 00:34:47.463655 21855 master.cpp:1184] Sending 1 offers to framework 201203290030-0-0000
I0329 00:34:47.465307 21855 master.cpp:679] Received reply for offer 201203290030-0-448
I0329 00:34:47.465456 21855 master.cpp:1403] Filtered slave 201203290030-0-1 for framework 201203290030-0-0000 for 1 seconds
I0329 00:34:48.465495 21855 master.cpp:1184] Sending 2 offers to framework 201203290030-0-0001
I0329 00:34:48.467268 21855 master.cpp:679] Received reply for offer 201203290030-0-449
I0329 00:34:48.467425 21855 master.cpp:1403] Filtered slave 201203290030-0-0 for framework 201203290030-0-0001 for 1 seconds
I0329 00:34:48.467700 21855 master.cpp:679] Received reply for offer 201203290030-0-450
I0329 00:34:48.467919 21855 master.cpp:1184] Sending 1 offers to framework 201203290030-0-0000
I0329 00:34:48.468081 21855 master.cpp:1403] Filtered slave 201203290030-0-1 for framework 201203290030-0-0001 for 1 seconds
I0329 00:34:48.469267 21855 master.cpp:679] Received reply for offer 201203290030-0-451
I0329 00:34:48.469444 21855 master.cpp:1403] Filtered slave 201203290030-0-0 for framework 201203290030-0-0000 for 1 seconds
I0329 00:34:49.467489 21855 master.cpp:1184] Sending 1 offers to framework 201203290030-0-0000
I0329 00:34:49.469127 21855 master.cpp:679] Received reply for offer 201203290030-0-452
I0329 00:34:49.469280 21855 master.cpp:1403] Filtered slave 201203290030-0-1 for framework 201203290030-0-0000 for 1 seconds
I0329 00:34:50.469344 21855 master.cpp:1184] Sending 2 offers to framework 201203290030-0-0001
I0329 00:34:50.471191 21855 master.cpp:679] Received reply for offer 201203290030-0-453
I0329 00:34:50.471340 21855 master.cpp:1403] Filtered slave 201203290030-0-0 for framework 201203290030-0-0001 for 1 seconds
I0329 00:34:50.471782 21855 master.cpp:679] Received reply for offer 201203290030-0-454
I0329 00:34:50.471992 21855 master.cpp:1184] Sending 1 offers to framework 201203290030-0-0000
I0329 00:34:50.472141 21855 master.cpp:1403] Filtered slave 201203290030-0-1 for framework 201203290030-0-0001 for 1 seconds
I0329 00:34:50.473536 21855 master.cpp:679] Received reply for offer 201203290030-0-455
I0329 00:34:50.473706 21855 master.cpp:1403] Filtered slave 201203290030-0-0 for framework 201203290030-0-0000 for 1 seconds
I0329 00:34:51.471585 21855 master.cpp:1184] Sending 1 offers to framework 201203290030-0-0000
I0329 00:34:51.473263 21855 master.cpp:679] Received reply for offer 201203290030-0-456
I0329 00:34:51.473358 21855 master.cpp:1403] Filtered slave 201203290030-0-1 for framework 201203290030-0-0000 for 1 seconds
I0329 00:34:52.472941 21855 master.cpp:1184] Sending 2 offers to framework 201203290030-0-0001
I0329 00:34:52.474750 21855 master.cpp:679] Received reply for offer 201203290030-0-457
I0329 00:34:52.475049 21855 master.cpp:1403] Filtered slave 201203290030-0-0 for framework 201203290030-0-0001 for 1 seconds
I0329 00:34:52.475232 21855 master.cpp:679] Received reply for offer 201203290030-0-458
I0329 00:34:52.475435 21855 master.cpp:1184] Sending 1 offers to framework 201203290030-0-0000
I0329 00:34:52.475682 21855 master.cpp:1403] Filtered slave 201203290030-0-1 for framework 201203290030-0-0001 for 1 seconds
I0329 00:34:52.476937 21855 master.cpp:679] Received reply for offer 201203290030-0-459
I0329 00:34:52.477089 21855 master.cpp:1403] Filtered slave 201203290030-0-0 for framework 201203290030-0-0000 for 1 seconds
I0329 00:34:53.474231 21855 master.cpp:1184] Sending 1 offers to framework 201203290030-0-0000
I0329 00:34:53.475657 21855 master.cpp:679] Received reply for offer 201203290030-0-460
I0329 00:34:53.475810 21855 master.cpp:1403] Filtered slave 201203290030-0-1 for framework 201203290030-0-0000 for 1 seconds
I0329 00:34:54.475890 21855 master.cpp:1184] Sending 2 offers to framework 201203290030-0-0001
I0329 00:34:54.477730 21855 master.cpp:679] Received reply for offer 201203290030-0-461
I0329 00:34:54.477890 21855 master.cpp:1403] Filtered slave 201203290030-0-0 for framework 201203290030-0-0001 for 1 seconds
I0329 00:34:54.478204 21855 master.cpp:679] Received reply for offer 201203290030-0-462
I0329 00:34:54.478657 21855 master.cpp:1184] Sending 1 offers to framework 201203290030-0-0000
I0329 00:34:54.479027 21855 master.cpp:1403] Filtered slave 201203290030-0-1 for framework 201203290030-0-0001 for 1 seconds
I0329 00:34:54.480197 21855 master.cpp:679] Received reply for offer 201203290030-0-463
I0329 00:34:54.480360 21855 master.cpp:1403] Filtered slave 201203290030-0-0 for framework 201203290030-0-0000 for 1 seconds
I0329 00:34:55.477412 21855 master.cpp:1184] Sending 1 offers to framework 201203290030-0-0000
I0329 00:34:55.479048 21855 master.cpp:679] Received reply for offer 201203290030-0-464
I0329 00:34:55.479285 21855 master.cpp:1403] Filtered slave 201203290030-0-1 for framework 201203290030-0-0000 for 1 seconds
I0329 00:34:56.479277 21855 master.cpp:1184] Sending 2 offers to framework 201203290030-0-0001
I0329 00:34:56.481190 21855 master.cpp:679] Received reply for offer 201203290030-0-465
I0329 00:34:56.481283 21855 master.cpp:1403] Filtered slave 201203290030-0-0 for framework 201203290030-0-0001 for 1 seconds
I0329 00:34:56.535483 21855 master.cpp:679] Received reply for offer 201203290030-0-466
I0329 00:34:56.573971 21855 master.cpp:1184] Sending 1 offers to framework 201203290030-0-0000
I0329 00:34:56.574259 21855 master.cpp:1403] Filtered slave 201203290030-0-1 for framework 201203290030-0-0001 for 1 seconds
I0329 00:34:56.575481 21855 master.cpp:679] Received reply for offer 201203290030-0-467
I0329 00:34:56.575645 21855 master.cpp:1403] Filtered slave 201203290030-0-0 for framework 201203290030-0-0000 for 1 seconds
I0329 00:34:57.480566 21855 master.cpp:1184] Sending 1 offers to framework 201203290030-0-0000
I0329 00:34:57.482132 21855 master.cpp:679] Received reply for offer 201203290030-0-468
I0329 00:34:57.482285 21855 master.cpp:1403] Filtered slave 201203290030-0-1 for framework 201203290030-0-0000 for 1 seconds
I0329 00:34:58.481783 21855 master.cpp:1184] Sending 2 offers to framework 201203290030-0-0001
I0329 00:34:58.483618 21855 master.cpp:679] Received reply for offer 201203290030-0-469
I0329 00:34:58.483767 21855 master.cpp:1403] Filtered slave 201203290030-0-0 for framework 201203290030-0-0001 for 1 seconds
I0329 00:34:58.484184 21855 master.cpp:679] Received reply for offer 201203290030-0-470
I0329 00:34:58.484369 21855 master.cpp:1184] Sending 1 offers to framework 201203290030-0-0000
I0329 00:34:58.484519 21855 master.cpp:1403] Filtered slave 201203290030-0-1 for framework 201203290030-0-0001 for 1 seconds
I0329 00:34:58.485745 21855 master.cpp:679] Received reply for offer 201203290030-0-471
I0329 00:34:58.485991 21855 master.cpp:1403] Filtered slave 201203290030-0-0 for framework 201203290030-0-0000 for 1 seconds
I0329 00:34:59.483309 21855 master.cpp:1184] Sending 1 offers to framework 201203290030-0-0000
I0329 00:34:59.484954 21855 master.cpp:679] Received reply for offer 201203290030-0-472
I0329 00:34:59.485097 21855 master.cpp:1403] Filtered slave 201203290030-0-1 for framework 201203290030-0-0000 for 1 seconds
I0329 00:35:00.485185 21855 master.cpp:1184] Sending 2 offers to framework 201203290030-0-0001
I0329 00:35:00.486963 21855 master.cpp:679] Received reply for offer 201203290030-0-473
I0329 00:35:00.487120 21855 master.cpp:1403] Filtered slave 201203290030-0-0 for framework 201203290030-0-0001 for 1 seconds
I0329 00:35:00.487393 21855 master.cpp:679] Received reply for offer 201203290030-0-474
I0329 00:35:00.487661 21855 master.cpp:1184] Sending 1 offers to framework 201203290030-0-0000
I0329 00:35:00.487805 21855 master.cpp:1403] Filtered slave 201203290030-0-1 for framework 201203290030-0-0001 for 1 seconds
I0329 00:35:00.489084 21855 master.cpp:679] Received reply for offer 201203290030-0-475
I0329 00:35:00.489346 21855 master.cpp:1403] Filtered slave 201203290030-0-0 for framework 201203290030-0-0000 for 1 seconds
I0329 00:35:01.487229 21855 master.cpp:1184] Sending 1 offers to framework 201203290030-0-0000
I0329 00:35:01.488590 21855 master.cpp:679] Received reply for offer 201203290030-0-476
I0329 00:35:01.488703 21855 master.cpp:1403] Filtered slave 201203290030-0-1 for framework 201203290030-0-0000 for 1 seconds
I0329 00:35:02.488739 21855 master.cpp:1184] Sending 2 offers to framework 201203290030-0-0001
I0329 00:35:02.490459 21855 master.cpp:679] Received reply for offer 201203290030-0-477
I0329 00:35:02.490609 21855 master.cpp:1403] Filtered slave 201203290030-0-0 for framework 201203290030-0-0001 for 1 seconds
I0329 00:35:02.490893 21855 master.cpp:679] Received reply for offer 201203290030-0-478
I0329 00:35:02.491070 21855 master.cpp:1184] Sending 1 offers to framework 201203290030-0-0000
I0329 00:35:02.491412 21855 master.cpp:1403] Filtered slave 201203290030-0-1 for framework 201203290030-0-0001 for 1 seconds
I0329 00:35:02.492450 21855 master.cpp:679] Received reply for offer 201203290030-0-479
I0329 00:35:02.492616 21855 master.cpp:1403] Filtered slave 201203290030-0-0 for framework 201203290030-0-0000 for 1 seconds
I0329 00:35:03.490643 21855 master.cpp:1184] Sending 1 offers to framework 201203290030-0-0000
I0329 00:35:03.492173 21855 master.cpp:679] Received reply for offer 201203290030-0-480
I0329 00:35:03.492351 21855 master.cpp:1403] Filtered slave 201203290030-0-1 for framework 201203290030-0-0000 for 1 seconds
I0329 00:35:04.491469 21855 master.cpp:1184] Sending 2 offers to framework 201203290030-0-0001
I0329 00:35:04.493542 21855 master.cpp:679] Received reply for offer 201203290030-0-481
I0329 00:35:04.493691 21855 master.cpp:1403] Filtered slave 201203290030-0-0 for framework 201203290030-0-0001 for 1 seconds
I0329 00:35:04.494024 21855 master.cpp:679] Received reply for offer 201203290030-0-482
I0329 00:35:04.494226 21855 master.cpp:1184] Sending 1 offers to framework 201203290030-0-0000
I0329 00:35:04.494400 21855 master.cpp:1403] Filtered slave 201203290030-0-1 for framework 201203290030-0-0001 for 1 seconds
I0329 00:35:04.495488 21855 master.cpp:679] Received reply for offer 201203290030-0-483
I0329 00:35:04.495702 21855 master.cpp:1403] Filtered slave 201203290030-0-0 for framework 201203290030-0-0000 for 1 seconds
I0329 00:35:05.493788 21855 master.cpp:1184] Sending 1 offers to framework 201203290030-0-0000
I0329 00:35:05.495398 21855 master.cpp:679] Received reply for offer 201203290030-0-484
I0329 00:35:05.495551 21855 master.cpp:1403] Filtered slave 201203290030-0-1 for framework 201203290030-0-0000 for 1 seconds
I0329 00:35:06.495734 21855 master.cpp:1184] Sending 2 offers to framework 201203290030-0-0001
I0329 00:35:06.497606 21855 master.cpp:679] Received reply for offer 201203290030-0-485
I0329 00:35:06.497699 21855 master.cpp:1403] Filtered slave 201203290030-0-0 for framework 201203290030-0-0001 for 1 seconds
I0329 00:35:06.542388 21855 master.cpp:679] Received reply for offer 201203290030-0-486
I0329 00:35:06.580678 21855 master.cpp:1184] Sending 1 offers to framework 201203290030-0-0000
I0329 00:35:06.580924 21855 master.cpp:1403] Filtered slave 201203290030-0-1 for framework 201203290030-0-0001 for 1 seconds
I0329 00:35:06.581984 21855 master.cpp:679] Received reply for offer 201203290030-0-487
I0329 00:35:06.582159 21855 master.cpp:1403] Filtered slave 201203290030-0-0 for framework 201203290030-0-0000 for 1 seconds
I0329 00:35:07.497992 21855 master.cpp:1184] Sending 1 offers to framework 201203290030-0-0000
I0329 00:35:07.499241 21855 master.cpp:679] Received reply for offer 201203290030-0-488
I0329 00:35:07.499398 21855 master.cpp:1403] Filtered slave 201203290030-0-1 for framework 201203290030-0-0000 for 1 seconds
I0329 00:35:08.499467 21855 master.cpp:1184] Sending 2 offers to framework 201203290030-0-0001
I0329 00:35:08.500874 21855 master.cpp:679] Received reply for offer 201203290030-0-489
I0329 00:35:08.500993 21855 master.cpp:1403] Filtered slave 201203290030-0-0 for framework 201203290030-0-0001 for 1 seconds
I0329 00:35:08.501297 21855 master.cpp:679] Received reply for offer 201203290030-0-490
I0329 00:35:08.501464 21855 master.cpp:1184] Sending 1 offers to framework 201203290030-0-0000
I0329 00:35:08.501579 21855 master.cpp:1403] Filtered slave 201203290030-0-1 for framework 201203290030-0-0001 for 1 seconds
I0329 00:35:08.502451 21855 master.cpp:679] Received reply for offer 201203290030-0-491
I0329 00:35:08.502575 21855 master.cpp:1403] Filtered slave 201203290030-0-0 for framework 201203290030-0-0000 for 1 seconds
I0329 00:35:09.501657 21855 master.cpp:1184] Sending 1 offers to framework 201203290030-0-0000
I0329 00:35:09.501868 21855 master.cpp:1184] Sending 1 offers to framework 201203290030-0-0001
I0329 00:35:09.503284 21855 master.cpp:679] Received reply for offer 201203290030-0-492
I0329 00:35:09.503454 21855 master.cpp:1403] Filtered slave 201203290030-0-1 for framework 201203290030-0-0000 for 1 seconds
I0329 00:35:09.503734 21855 master.cpp:679] Received reply for offer 201203290030-0-493
I0329 00:35:09.503900 21855 master.cpp:1403] Filtered slave 201203290030-0-0 for framework 201203290030-0-0001 for 1 seconds
I0329 00:35:10.503952 21855 master.cpp:1184] Sending 1 offers to framework 201203290030-0-0000
I0329 00:35:10.504154 21855 master.cpp:1184] Sending 1 offers to framework 201203290030-0-0001
I0329 00:35:10.505564 21855 master.cpp:679] Received reply for offer 201203290030-0-494
I0329 00:35:10.505730 21855 master.cpp:1403] Filtered slave 201203290030-0-0 for framework 201203290030-0-0000 for 1 seconds
I0329 00:35:10.505936 21855 master.cpp:679] Received reply for offer 201203290030-0-495
I0329 00:35:10.506106 21855 master.cpp:1403] Filtered slave 201203290030-0-1 for framework 201203290030-0-0001 for 1 seconds
I0329 00:35:11.506126 21855 master.cpp:1184] Sending 1 offers to framework 201203290030-0-0000
I0329 00:35:11.506325 21855 master.cpp:1184] Sending 1 offers to framework 201203290030-0-0001
I0329 00:35:11.507709 21855 master.cpp:679] Received reply for offer 201203290030-0-496
I0329 00:35:11.570914 21855 master.cpp:1403] Filtered slave 201203290030-0-1 for framework 201203290030-0-0000 for 1 seconds
I0329 00:35:11.600600 21855 master.cpp:679] Received reply for offer 201203290030-0-497
I0329 00:35:11.600991 21855 master.cpp:1403] Filtered slave 201203290030-0-0 for framework 201203290030-0-0001 for 1 seconds
I0329 00:35:12.508440 21855 master.cpp:1184] Sending 1 offers to framework 201203290030-0-0000
I0329 00:35:12.508646 21855 master.cpp:1184] Sending 1 offers to framework 201203290030-0-0001
I0329 00:35:12.510041 21855 master.cpp:679] Received reply for offer 201203290030-0-498
I0329 00:35:12.510207 21855 master.cpp:1403] Filtered slave 201203290030-0-0 for framework 201203290030-0-0000 for 1 seconds
I0329 00:35:12.510418 21855 master.cpp:679] Received reply for offer 201203290030-0-499
I0329 00:35:12.510583 21855 master.cpp:1403] Filtered slave 201203290030-0-1 for framework 201203290030-0-0001 for 1 seconds
I0329 00:35:13.510259 21855 master.cpp:1184] Sending 1 offers to framework 201203290030-0-0000
I0329 00:35:13.510457 21855 master.cpp:1184] Sending 1 offers to framework 201203290030-0-0001
I0329 00:35:13.511857 21855 master.cpp:679] Received reply for offer 201203290030-0-500
I0329 00:35:13.512027 21855 master.cpp:1403] Filtered slave 201203290030-0-1 for framework 201203290030-0-0000 for 1 seconds
I0329 00:35:13.512248 21855 master.cpp:679] Received reply for offer 201203290030-0-501
I0329 00:35:13.512413 21855 master.cpp:1403] Filtered slave 201203290030-0-0 for framework 201203290030-0-0001 for 1 seconds
I0329 00:35:14.512354 21855 master.cpp:1184] Sending 1 offers to framework 201203290030-0-0000
I0329 00:35:14.512516 21855 master.cpp:1184] Sending 1 offers to framework 201203290030-0-0001
I0329 00:35:14.513725 21855 master.cpp:679] Received reply for offer 201203290030-0-502
I0329 00:35:14.513864 21855 master.cpp:1403] Filtered slave 201203290030-0-0 for framework 201203290030-0-0000 for 1 seconds
I0329 00:35:14.514236 21855 master.cpp:679] Received reply for offer 201203290030-0-503
I0329 00:35:14.514411 21855 master.cpp:1403] Filtered slave 201203290030-0-1 for framework 201203290030-0-0001 for 1 seconds
I0329 00:35:15.514449 21855 master.cpp:1184] Sending 1 offers to framework 201203290030-0-0000
I0329 00:35:15.514683 21855 master.cpp:1184] Sending 1 offers to framework 201203290030-0-0001
I0329 00:35:15.515924 21855 master.cpp:679] Received reply for offer 201203290030-0-504
I0329 00:35:15.516072 21855 master.cpp:1403] Filtered slave 201203290030-0-1 for framework 201203290030-0-0000 for 1 seconds
I0329 00:35:15.516448 21855 master.cpp:679] Received reply for offer 201203290030-0-505
I0329 00:35:15.516626 21855 master.cpp:1403] Filtered slave 201203290030-0-0 for framework 201203290030-0-0001 for 1 seconds
I0329 00:35:16.516659 21855 master.cpp:1184] Sending 1 offers to framework 201203290030-0-0000
I0329 00:35:16.516815 21855 master.cpp:1184] Sending 1 offers to framework 201203290030-0-0001
I0329 00:35:16.518247 21855 master.cpp:679] Received reply for offer 201203290030-0-506
I0329 00:35:16.566074 21855 master.cpp:1403] Filtered slave 201203290030-0-0 for framework 201203290030-0-0000 for 1 seconds
I0329 00:35:16.604007 21855 master.cpp:679] Received reply for offer 201203290030-0-507
I0329 00:35:16.604369 21855 master.cpp:1403] Filtered slave 201203290030-0-1 for framework 201203290030-0-0001 for 1 seconds
I0329 00:35:17.518714 21855 master.cpp:1184] Sending 1 offers to framework 201203290030-0-0000
I0329 00:35:17.518944 21855 master.cpp:1184] Sending 1 offers to framework 201203290030-0-0001
I0329 00:35:17.520280 21855 master.cpp:679] Received reply for offer 201203290030-0-508
I0329 00:35:17.520462 21855 master.cpp:1403] Filtered slave 201203290030-0-1 for framework 201203290030-0-0000 for 1 seconds
I0329 00:35:17.520829 21855 master.cpp:679] Received reply for offer 201203290030-0-509
I0329 00:35:17.521010 21855 master.cpp:1403] Filtered slave 201203290030-0-0 for framework 201203290030-0-0001 for 1 seconds
I0329 00:35:18.521165 21855 master.cpp:1184] Sending 1 offers to framework 201203290030-0-0000
I0329 00:35:18.521348 21855 master.cpp:1184] Sending 1 offers to framework 201203290030-0-0001
I0329 00:35:18.522848 21855 master.cpp:679] Received reply for offer 201203290030-0-510
I0329 00:35:18.523016 21855 master.cpp:1403] Filtered slave 201203290030-0-0 for framework 201203290030-0-0000 for 1 seconds
I0329 00:35:18.523406 21855 master.cpp:679] Received reply for offer 201203290030-0-511
I0329 00:35:18.523573 21855 master.cpp:1403] Filtered slave 201203290030-0-1 for framework 201203290030-0-0001 for 1 seconds
I0329 00:35:19.523673 21855 master.cpp:1184] Sending 1 offers to framework 201203290030-0-0000
I0329 00:35:19.523859 21855 master.cpp:1184] Sending 1 offers to framework 201203290030-0-0001
I0329 00:35:19.525159 21855 master.cpp:679] Received reply for offer 201203290030-0-512
I0329 00:35:19.525331 21855 master.cpp:1403] Filtered slave 201203290030-0-1 for framework 201203290030-0-0000 for 1 seconds
I0329 00:35:19.525787 21855 master.cpp:679] Received reply for offer 201203290030-0-513
I0329 00:35:19.525964 21855 master.cpp:1403] Filtered slave 201203290030-0-0 for framework 201203290030-0-0001 for 1 seconds
I0329 00:35:20.526057 21855 master.cpp:1184] Sending 1 offers to framework 201203290030-0-0000
I0329 00:35:20.526279 21855 master.cpp:1184] Sending 1 offers to framework 201203290030-0-0001
I0329 00:35:20.527689 21855 master.cpp:679] Received reply for offer 201203290030-0-514
I0329 00:35:20.527897 21855 master.cpp:1403] Filtered slave 201203290030-0-0 for framework 201203290030-0-0000 for 1 seconds
I0329 00:35:20.528398 21855 master.cpp:679] Received reply for offer 201203290030-0-515
I0329 00:35:20.528555 21855 master.cpp:1403] Filtered slave 201203290030-0-1 for framework 201203290030-0-0001 for 1 seconds
I0329 00:35:21.528672 21855 master.cpp:1184] Sending 1 offers to framework 201203290030-0-0000
I0329 00:35:21.528910 21855 master.cpp:1184] Sending 1 offers to framework 201203290030-0-0001
I0329 00:35:21.530280 21855 master.cpp:679] Received reply for offer 201203290030-0-516
I0329 00:35:21.586139 21855 master.cpp:1403] Filtered slave 201203290030-0-1 for framework 201203290030-0-0000 for 1 seconds
I0329 00:35:21.623883 21855 master.cpp:679] Received reply for offer 201203290030-0-517
I0329 00:35:21.624301 21855 master.cpp:1403] Filtered slave 201203290030-0-0 for framework 201203290030-0-0001 for 1 seconds
I0329 00:35:22.531098 21855 master.cpp:1184] Sending 1 offers to framework 201203290030-0-0000
I0329 00:35:22.531311 21855 master.cpp:1184] Sending 1 offers to framework 201203290030-0-0001
I0329 00:35:22.532659 21855 master.cpp:679] Received reply for offer 201203290030-0-518
I0329 00:35:22.532829 21855 master.cpp:1403] Filtered slave 201203290030-0-0 for framework 201203290030-0-0000 for 1 seconds
I0329 00:35:22.533146 21855 master.cpp:679] Received reply for offer 201203290030-0-519
I0329 00:35:22.533308 21855 master.cpp:1403] Filtered slave 201203290030-0-1 for framework 201203290030-0-0001 for 1 seconds
I0329 00:35:23.533494 21855 master.cpp:1184] Sending 1 offers to framework 201203290030-0-0000
I0329 00:35:23.533680 21855 master.cpp:1184] Sending 1 offers to framework 201203290030-0-0001
I0329 00:35:23.534984 21855 master.cpp:679] Received reply for offer 201203290030-0-520
I0329 00:35:23.535163 21855 master.cpp:1403] Filtered slave 201203290030-0-1 for framework 201203290030-0-0000 for 1 seconds
I0329 00:35:23.535553 21855 master.cpp:679] Received reply for offer 201203290030-0-521
I0329 00:35:23.535722 21855 master.cpp:1403] Filtered slave 201203290030-0-0 for framework 201203290030-0-0001 for 1 seconds
I0329 00:35:24.535852 21855 master.cpp:1184] Sending 1 offers to framework 201203290030-0-0000
I0329 00:35:24.536072 21855 master.cpp:1184] Sending 1 offers to framework 201203290030-0-0001
I0329 00:35:24.537480 21855 master.cpp:679] Received reply for offer 201203290030-0-522
I0329 00:35:24.537648 21855 master.cpp:1403] Filtered slave 201203290030-0-0 for framework 201203290030-0-0000 for 1 seconds
I0329 00:35:24.538010 21855 master.cpp:679] Received reply for offer 201203290030-0-523
I0329 00:35:24.538184 21855 master.cpp:1403] Filtered slave 201203290030-0-1 for framework 201203290030-0-0001 for 1 seconds
I0329 00:35:25.538226 21855 master.cpp:1184] Sending 1 offers to framework 201203290030-0-0000
I0329 00:35:25.538414 21855 master.cpp:1184] Sending 1 offers to framework 201203290030-0-0001
I0329 00:35:25.539887 21855 master.cpp:679] Received reply for offer 201203290030-0-524
I0329 00:35:25.540038 21855 master.cpp:1403] Filtered slave 201203290030-0-1 for framework 201203290030-0-0000 for 1 seconds
I0329 00:35:25.540408 21855 master.cpp:679] Received reply for offer 201203290030-0-525
I0329 00:35:25.540561 21855 master.cpp:1403] Filtered slave 201203290030-0-0 for framework 201203290030-0-0001 for 1 seconds
I0329 00:35:26.540725 21855 master.cpp:1184] Sending 1 offers to framework 201203290030-0-0000
I0329 00:35:26.540971 21855 master.cpp:1184] Sending 1 offers to framework 201203290030-0-0001
I0329 00:35:26.542251 21855 master.cpp:679] Received reply for offer 201203290030-0-526
I0329 00:35:26.597987 21855 master.cpp:1403] Filtered slave 201203290030-0-0 for framework 201203290030-0-0000 for 1 seconds
I0329 00:35:26.627321 21855 master.cpp:679] Received reply for offer 201203290030-0-527
I0329 00:35:26.627658 21855 master.cpp:1403] Filtered slave 201203290030-0-1 for framework 201203290030-0-0001 for 1 seconds
I0329 00:35:27.543108 21855 master.cpp:1184] Sending 1 offers to framework 201203290030-0-0000
I0329 00:35:27.543287 21855 master.cpp:1184] Sending 1 offers to framework 201203290030-0-0001
I0329 00:35:27.544700 21855 master.cpp:679] Received reply for offer 201203290030-0-528
I0329 00:35:27.544872 21855 master.cpp:1403] Filtered slave 201203290030-0-1 for framework 201203290030-0-0000 for 1 seconds
I0329 00:35:27.545225 21855 master.cpp:679] Received reply for offer 201203290030-0-529
I0329 00:35:27.545393 21855 master.cpp:1403] Filtered slave 201203290030-0-0 for framework 201203290030-0-0001 for 1 seconds
I0329 00:35:28.544406 21855 master.cpp:1184] Sending 1 offers to framework 201203290030-0-0000
I0329 00:35:28.544618 21855 master.cpp:1184] Sending 1 offers to framework 201203290030-0-0001
I0329 00:35:28.545972 21855 master.cpp:679] Received reply for offer 201203290030-0-530
I0329 00:35:28.546172 21855 master.cpp:1403] Filtered slave 201203290030-0-0 for framework 201203290030-0-0000 for 1 seconds
I0329 00:35:28.546607 21855 master.cpp:679] Received reply for offer 201203290030-0-531
I0329 00:35:28.547087 21855 master.cpp:1403] Filtered slave 201203290030-0-1 for framework 201203290030-0-0001 for 1 seconds
I0329 00:35:29.546818 21855 master.cpp:1184] Sending 1 offers to framework 201203290030-0-0000
I0329 00:35:29.547003 21855 master.cpp:1184] Sending 1 offers to framework 201203290030-0-0001
I0329 00:35:29.548373 21855 master.cpp:679] Received reply for offer 201203290030-0-532
I0329 00:35:29.548543 21855 master.cpp:1403] Filtered slave 201203290030-0-1 for framework 201203290030-0-0000 for 1 seconds
I0329 00:35:29.548898 21855 master.cpp:679] Received reply for offer 201203290030-0-533
I0329 00:35:29.549082 21855 master.cpp:1403] Filtered slave 201203290030-0-0 for framework 201203290030-0-0001 for 1 seconds
I0329 00:35:30.549201 21855 master.cpp:1184] Sending 1 offers to framework 201203290030-0-0000
I0329 00:35:30.549422 21855 master.cpp:1184] Sending 1 offers to framework 201203290030-0-0001
I0329 00:35:30.550839 21855 master.cpp:679] Received reply for offer 201203290030-0-534
I0329 00:35:30.551009 21855 master.cpp:1403] Filtered slave 201203290030-0-0 for framework 201203290030-0-0000 for 1 seconds
I0329 00:35:30.551334 21855 master.cpp:679] Received reply for offer 201203290030-0-535
I0329 00:35:30.551504 21855 master.cpp:1403] Filtered slave 201203290030-0-1 for framework 201203290030-0-0001 for 1 seconds
I0329 00:35:31.551643 21855 master.cpp:1184] Sending 1 offers to framework 201203290030-0-0000
I0329 00:35:31.551803 21855 master.cpp:1184] Sending 1 offers to framework 201203290030-0-0001
I0329 00:35:31.553236 21855 master.cpp:679] Received reply for offer 201203290030-0-536
I0329 00:35:31.601547 21855 master.cpp:1403] Filtered slave 201203290030-0-1 for framework 201203290030-0-0000 for 1 seconds
I0329 00:35:31.638959 21855 master.cpp:679] Received reply for offer 201203290030-0-537
I0329 00:35:31.639449 21855 master.cpp:1403] Filtered slave 201203290030-0-0 for framework 201203290030-0-0001 for 1 seconds
I0329 00:35:32.553201 21855 master.cpp:1184] Sending 1 offers to framework 201203290030-0-0000
I0329 00:35:32.553416 21855 master.cpp:1184] Sending 1 offers to framework 201203290030-0-0001
I0329 00:35:32.554684 21855 master.cpp:679] Received reply for offer 201203290030-0-538
I0329 00:35:32.554829 21855 master.cpp:1403] Filtered slave 201203290030-0-0 for framework 201203290030-0-0000 for 1 seconds
I0329 00:35:32.555131 21855 master.cpp:679] Received reply for offer 201203290030-0-539
I0329 00:35:32.555287 21855 master.cpp:1403] Filtered slave 201203290030-0-1 for framework 201203290030-0-0001 for 1 seconds
I0329 00:35:33.555349 21855 master.cpp:1184] Sending 1 offers to framework 201203290030-0-0000
I0329 00:35:33.555536 21855 master.cpp:1184] Sending 1 offers to framework 201203290030-0-0001
I0329 00:35:33.556869 21855 master.cpp:679] Received reply for offer 201203290030-0-540
I0329 00:35:33.557018 21855 master.cpp:1403] Filtered slave 201203290030-0-1 for framework 201203290030-0-0000 for 1 seconds
I0329 00:35:33.557373 21855 master.cpp:679] Received reply for offer 201203290030-0-541
I0329 00:35:33.557548 21855 master.cpp:1403] Filtered slave 201203290030-0-0 for framework 201203290030-0-0001 for 1 seconds
I0329 00:35:34.557646 21855 master.cpp:1184] Sending 1 offers to framework 201203290030-0-0000
I0329 00:35:34.557858 21855 master.cpp:1184] Sending 1 offers to framework 201203290030-0-0001
I0329 00:35:34.559201 21855 master.cpp:679] Received reply for offer 201203290030-0-542
I0329 00:35:34.559371 21855 master.cpp:1403] Filtered slave 201203290030-0-0 for framework 201203290030-0-0000 for 1 seconds
I0329 00:35:34.559797 21855 master.cpp:679] Received reply for offer 201203290030-0-543
I0329 00:35:34.559972 21855 master.cpp:1403] Filtered slave 201203290030-0-1 for framework 201203290030-0-0001 for 1 seconds
I0329 00:35:35.560034 21855 master.cpp:1184] Sending 1 offers to framework 201203290030-0-0000
I0329 00:35:35.560250 21855 master.cpp:1184] Sending 1 offers to framework 201203290030-0-0001
I0329 00:35:35.561682 21855 master.cpp:679] Received reply for offer 201203290030-0-544
I0329 00:35:35.561830 21855 master.cpp:1403] Filtered slave 201203290030-0-1 for framework 201203290030-0-0000 for 1 seconds
I0329 00:35:35.562134 21855 master.cpp:679] Received reply for offer 201203290030-0-545
I0329 00:35:35.562420 21855 master.cpp:1403] Filtered slave 201203290030-0-0 for framework 201203290030-0-0001 for 1 seconds
I0329 00:35:36.562425 21855 master.cpp:1184] Sending 1 offers to framework 201203290030-0-0000
I0329 00:35:36.562600 21855 master.cpp:1184] Sending 1 offers to framework 201203290030-0-0001
I0329 00:35:36.563906 21855 master.cpp:679] Received reply for offer 201203290030-0-546
I0329 00:35:36.634153 21855 master.cpp:1403] Filtered slave 201203290030-0-0 for framework 201203290030-0-0000 for 1 seconds
I0329 00:35:36.671388 21855 master.cpp:679] Received reply for offer 201203290030-0-547
I0329 00:35:36.671751 21855 master.cpp:1403] Filtered slave 201203290030-0-1 for framework 201203290030-0-0001 for 1 seconds
I0329 00:35:37.564821 21855 master.cpp:1184] Sending 1 offers to framework 201203290030-0-0000
I0329 00:35:37.565009 21855 master.cpp:1184] Sending 1 offers to framework 201203290030-0-0001
I0329 00:35:37.566468 21855 master.cpp:679] Received reply for offer 201203290030-0-548
I0329 00:35:37.566642 21855 master.cpp:1403] Filtered slave 201203290030-0-1 for framework 201203290030-0-0000 for 1 seconds
I0329 00:35:37.567033 21855 master.cpp:679] Received reply for offer 201203290030-0-549
I0329 00:35:37.567216 21855 master.cpp:1403] Filtered slave 201203290030-0-0 for framework 201203290030-0-0001 for 1 seconds
I0329 00:35:38.567286 21855 master.cpp:1184] Sending 1 offers to framework 201203290030-0-0000
I0329 00:35:38.567505 21855 master.cpp:1184] Sending 1 offers to framework 201203290030-0-0001
I0329 00:35:38.568938 21855 master.cpp:679] Received reply for offer 201203290030-0-550
I0329 00:35:38.569109 21855 master.cpp:1403] Filtered slave 201203290030-0-0 for framework 201203290030-0-0000 for 1 seconds
I0329 00:35:38.569519 21855 master.cpp:679] Received reply for offer 201203290030-0-551
I0329 00:35:38.569687 21855 master.cpp:1403] Filtered slave 201203290030-0-1 for framework 201203290030-0-0001 for 1 seconds
I0329 00:35:39.569785 21855 master.cpp:1184] Sending 1 offers to framework 201203290030-0-0000
I0329 00:35:39.569958 21855 master.cpp:1184] Sending 1 offers to framework 201203290030-0-0001
I0329 00:35:39.571472 21855 master.cpp:679] Received reply for offer 201203290030-0-552
I0329 00:35:39.571645 21855 master.cpp:1403] Filtered slave 201203290030-0-1 for framework 201203290030-0-0000 for 1 seconds
I0329 00:35:39.572111 21855 master.cpp:679] Received reply for offer 201203290030-0-553
I0329 00:35:39.572285 21855 master.cpp:1403] Filtered slave 201203290030-0-0 for framework 201203290030-0-0001 for 1 seconds
I0329 00:35:40.571393 21855 master.cpp:1184] Sending 1 offers to framework 201203290030-0-0000
I0329 00:35:40.571576 21855 master.cpp:1184] Sending 1 offers to framework 201203290030-0-0001
I0329 00:35:40.573019 21855 master.cpp:679] Received reply for offer 201203290030-0-554
I0329 00:35:40.573266 21855 master.cpp:1403] Filtered slave 201203290030-0-0 for framework 201203290030-0-0000 for 1 seconds
I0329 00:35:40.573544 21855 master.cpp:679] Received reply for offer 201203290030-0-555
I0329 00:35:40.573712 21855 master.cpp:1403] Filtered slave 201203290030-0-1 for framework 201203290030-0-0001 for 1 seconds
I0329 00:35:41.573883 21855 master.cpp:1184] Sending 1 offers to framework 201203290030-0-0000
I0329 00:35:41.574038 21855 master.cpp:1184] Sending 1 offers to framework 201203290030-0-0001
I0329 00:35:41.575594 21855 master.cpp:679] Received reply for offer 201203290030-0-556
I0329 00:35:41.620867 21855 master.cpp:1403] Filtered slave 201203290030-0-1 for framework 201203290030-0-0000 for 1 seconds
I0329 00:35:41.658174 21855 master.cpp:679] Received reply for offer 201203290030-0-557
I0329 00:35:41.658587 21855 master.cpp:1403] Filtered slave 201203290030-0-0 for framework 201203290030-0-0001 for 1 seconds
I0329 00:35:42.576504 21855 master.cpp:1184] Sending 1 offers to framework 201203290030-0-0000
I0329 00:35:42.576684 21855 master.cpp:1184] Sending 1 offers to framework 201203290030-0-0001
I0329 00:35:42.578115 21855 master.cpp:679] Received reply for offer 201203290030-0-558
I0329 00:35:42.578281 21855 master.cpp:1403] Filtered slave 201203290030-0-0 for framework 201203290030-0-0000 for 1 seconds
I0329 00:35:42.578675 21855 master.cpp:679] Received reply for offer 201203290030-0-559
I0329 00:35:42.578842 21855 master.cpp:1403] Filtered slave 201203290030-0-1 for framework 201203290030-0-0001 for 1 seconds
I0329 00:35:43.578644 21855 master.cpp:1184] Sending 1 offers to framework 201203290030-0-0000
I0329 00:35:43.578827 21855 master.cpp:1184] Sending 1 offers to framework 201203290030-0-0001
I0329 00:35:43.580157 21855 master.cpp:679] Received reply for offer 201203290030-0-560
I0329 00:35:43.580327 21855 master.cpp:1403] Filtered slave 201203290030-0-1 for framework 201203290030-0-0000 for 1 seconds
I0329 00:35:43.580773 21855 master.cpp:679] Received reply for offer 201203290030-0-561
I0329 00:35:43.580941 21855 master.cpp:1403] Filtered slave 201203290030-0-0 for framework 201203290030-0-0001 for 1 seconds
I0329 00:35:44.581073 21855 master.cpp:1184] Sending 1 offers to framework 201203290030-0-0000
I0329 00:35:44.581259 21855 master.cpp:1184] Sending 1 offers to framework 201203290030-0-0001
I0329 00:35:44.582610 21855 master.cpp:679] Received reply for offer 201203290030-0-562
I0329 00:35:44.582780 21855 master.cpp:1403] Filtered slave 201203290030-0-0 for framework 201203290030-0-0000 for 1 seconds
I0329 00:35:44.583164 21855 master.cpp:679] Received reply for offer 201203290030-0-563
I0329 00:35:44.583330 21855 master.cpp:1403] Filtered slave 201203290030-0-1 for framework 201203290030-0-0001 for 1 seconds
I0329 00:35:45.583403 21855 master.cpp:1184] Sending 1 offers to framework 201203290030-0-0000
I0329 00:35:45.583608 21855 master.cpp:1184] Sending 1 offers to framework 201203290030-0-0001
I0329 00:35:45.585039 21855 master.cpp:679] Received reply for offer 201203290030-0-564
I0329 00:35:45.585211 21855 master.cpp:1403] Filtered slave 201203290030-0-1 for framework 201203290030-0-0000 for 1 seconds
I0329 00:35:45.585526 21855 master.cpp:679] Received reply for offer 201203290030-0-565
I0329 00:35:45.585693 21855 master.cpp:1403] Filtered slave 201203290030-0-0 for framework 201203290030-0-0001 for 1 seconds
I0329 00:35:46.585798 21855 master.cpp:1184] Sending 1 offers to framework 201203290030-0-0000
I0329 00:35:46.585952 21855 master.cpp:1184] Sending 1 offers to framework 201203290030-0-0001
I0329 00:35:46.587476 21855 master.cpp:679] Received reply for offer 201203290030-0-566
I0329 00:35:46.632531 21855 master.cpp:1403] Filtered slave 201203290030-0-0 for framework 201203290030-0-0000 for 1 seconds
I0329 00:35:46.661672 21855 master.cpp:679] Received reply for offer 201203290030-0-567
I0329 00:35:46.662031 21855 master.cpp:1403] Filtered slave 201203290030-0-1 for framework 201203290030-0-0001 for 1 seconds
I0329 00:35:47.587347 21855 master.cpp:1184] Sending 1 offers to framework 201203290030-0-0000
I0329 00:35:47.587627 21855 master.cpp:1184] Sending 1 offers to framework 201203290030-0-0001
I0329 00:35:47.589078 21855 master.cpp:679] Received reply for offer 201203290030-0-568
I0329 00:35:47.589231 21855 master.cpp:1403] Filtered slave 201203290030-0-1 for framework 201203290030-0-0000 for 1 seconds
I0329 00:35:47.589457 21855 master.cpp:679] Received reply for offer 201203290030-0-569
I0329 00:35:47.589617 21855 master.cpp:1403] Filtered slave 201203290030-0-0 for framework 201203290030-0-0001 for 1 seconds
I0329 00:35:48.589637 21855 master.cpp:1184] Sending 1 offers to framework 201203290030-0-0000
I0329 00:35:48.589834 21855 master.cpp:1184] Sending 1 offers to framework 201203290030-0-0001
I0329 00:35:48.591425 21855 master.cpp:679] Received reply for offer 201203290030-0-570
I0329 00:35:48.591644 21855 master.cpp:1403] Filtered slave 201203290030-0-0 for framework 201203290030-0-0000 for 1 seconds
I0329 00:35:48.592109 21855 master.cpp:679] Received reply for offer 201203290030-0-571
I0329 00:35:48.592627 21855 master.cpp:1403] Filtered slave 201203290030-0-1 for framework 201203290030-0-0001 for 1 seconds
I0329 00:35:49.592224 21855 master.cpp:1184] Sending 1 offers to framework 201203290030-0-0000
I0329 00:35:49.592419 21855 master.cpp:1184] Sending 1 offers to framework 201203290030-0-0001
I0329 00:35:49.593868 21855 master.cpp:679] Received reply for offer 201203290030-0-572
I0329 00:35:49.594020 21855 master.cpp:1403] Filtered slave 201203290030-0-1 for framework 201203290030-0-0000 for 1 seconds
I0329 00:35:49.594322 21855 master.cpp:679] Received reply for offer 201203290030-0-573
I0329 00:35:49.594497 21855 master.cpp:1403] Filtered slave 201203290030-0-0 for framework 201203290030-0-0001 for 1 seconds
I0329 00:35:50.594627 21855 master.cpp:1184] Sending 1 offers to framework 201203290030-0-0000
I0329 00:35:50.594811 21855 master.cpp:1184] Sending 1 offers to framework 201203290030-0-0001
I0329 00:35:50.596441 21855 master.cpp:679] Received reply for offer 201203290030-0-574
I0329 00:35:50.596592 21855 master.cpp:1403] Filtered slave 201203290030-0-0 for framework 201203290030-0-0000 for 1 seconds
I0329 00:35:50.596797 21855 master.cpp:679] Received reply for offer 201203290030-0-575
I0329 00:35:50.596956 21855 master.cpp:1403] Filtered slave 201203290030-0-1 for framework 201203290030-0-0001 for 1 seconds
I0329 00:35:51.596451 21855 master.cpp:1184] Sending 1 offers to framework 201203290030-0-0000
I0329 00:35:51.596631 21855 master.cpp:1184] Sending 1 offers to framework 201203290030-0-0001
I0329 00:35:51.598206 21855 master.cpp:679] Received reply for offer 201203290030-0-576
I0329 00:35:51.644234 21855 master.cpp:1403] Filtered slave 201203290030-0-1 for framework 201203290030-0-0000 for 1 seconds
I0329 00:35:51.681844 21855 master.cpp:679] Received reply for offer 201203290030-0-577
I0329 00:35:51.682239 21855 master.cpp:1403] Filtered slave 201203290030-0-0 for framework 201203290030-0-0001 for 1 seconds
I0329 00:35:52.599002 21855 master.cpp:1184] Sending 1 offers to framework 201203290030-0-0000
I0329 00:35:52.599179 21855 master.cpp:1184] Sending 1 offers to framework 201203290030-0-0001
I0329 00:35:52.600556 21855 master.cpp:679] Received reply for offer 201203290030-0-578
I0329 00:35:52.600711 21855 master.cpp:1403] Filtered slave 201203290030-0-0 for framework 201203290030-0-0000 for 1 seconds
I0329 00:35:52.600973 21855 master.cpp:679] Received reply for offer 201203290030-0-579
I0329 00:35:52.601131 21855 master.cpp:1403] Filtered slave 201203290030-0-1 for framework 201203290030-0-0001 for 1 seconds
I0329 00:35:53.601116 21855 master.cpp:1184] Sending 1 offers to framework 201203290030-0-0000
I0329 00:35:53.601398 21855 master.cpp:1184] Sending 1 offers to framework 201203290030-0-0001
I0329 00:35:53.602603 21855 master.cpp:679] Received reply for offer 201203290030-0-580
I0329 00:35:53.602748 21855 master.cpp:1403] Filtered slave 201203290030-0-1 for framework 201203290030-0-0000 for 1 seconds
I0329 00:35:53.603106 21855 master.cpp:679] Received reply for offer 201203290030-0-581
I0329 00:35:53.603282 21855 master.cpp:1403] Filtered slave 201203290030-0-0 for framework 201203290030-0-0001 for 1 seconds
I0329 00:35:54.603386 21855 master.cpp:1184] Sending 1 offers to framework 201203290030-0-0000
I0329 00:35:54.603544 21855 master.cpp:1184] Sending 1 offers to framework 201203290030-0-0001
I0329 00:35:54.604969 21855 master.cpp:679] Received reply for offer 201203290030-0-582
I0329 00:35:54.605144 21855 master.cpp:1403] Filtered slave 201203290030-0-0 for framework 201203290030-0-0000 for 1 seconds
I0329 00:35:54.605401 21855 master.cpp:679] Received reply for offer 201203290030-0-583
I0329 00:35:54.605566 21855 master.cpp:1403] Filtered slave 201203290030-0-1 for framework 201203290030-0-0001 for 1 seconds
I0329 00:35:55.605664 21855 master.cpp:1184] Sending 1 offers to framework 201203290030-0-0000
I0329 00:35:55.605949 21855 master.cpp:1184] Sending 1 offers to framework 201203290030-0-0001
I0329 00:35:55.607414 21855 master.cpp:679] Received reply for offer 201203290030-0-584
I0329 00:35:55.607586 21855 master.cpp:1403] Filtered slave 201203290030-0-1 for framework 201203290030-0-0000 for 1 seconds
I0329 00:35:55.607910 21855 master.cpp:679] Received reply for offer 201203290030-0-585
I0329 00:35:55.608083 21855 master.cpp:1403] Filtered slave 201203290030-0-0 for framework 201203290030-0-0001 for 1 seconds
I0329 00:35:56.608125 21855 master.cpp:1184] Sending 1 offers to framework 201203290030-0-0000
I0329 00:35:56.608360 21855 master.cpp:1184] Sending 1 offers to framework 201203290030-0-0001
I0329 00:35:56.609778 21855 master.cpp:679] Received reply for offer 201203290030-0-586
I0329 00:35:56.655742 21855 master.cpp:1403] Filtered slave 201203290030-0-0 for framework 201203290030-0-0000 for 1 seconds
I0329 00:35:56.685286 21855 master.cpp:679] Received reply for offer 201203290030-0-587
I0329 00:35:56.685649 21855 master.cpp:1403] Filtered slave 201203290030-0-1 for framework 201203290030-0-0001 for 1 seconds
I0329 00:35:57.610481 21855 master.cpp:1184] Sending 1 offers to framework 201203290030-0-0000
I0329 00:35:57.610682 21855 master.cpp:1184] Sending 1 offers to framework 201203290030-0-0001
I0329 00:35:57.612120 21855 master.cpp:679] Received reply for offer 201203290030-0-588
I0329 00:35:57.612293 21855 master.cpp:1403] Filtered slave 201203290030-0-1 for framework 201203290030-0-0000 for 1 seconds
I0329 00:35:57.612484 21855 master.cpp:679] Received reply for offer 201203290030-0-589
I0329 00:35:57.612653 21855 master.cpp:1403] Filtered slave 201203290030-0-0 for framework 201203290030-0-0001 for 1 seconds
I0329 00:35:58.611801 21855 master.cpp:1184] Sending 1 offers to framework 201203290030-0-0000
I0329 00:35:58.611980 21855 master.cpp:1184] Sending 1 offers to framework 201203290030-0-0001
I0329 00:35:58.613421 21855 master.cpp:679] Received reply for offer 201203290030-0-590
I0329 00:35:58.613591 21855 master.cpp:1403] Filtered slave 201203290030-0-0 for framework 201203290030-0-0000 for 1 seconds
I0329 00:35:58.613816 21855 master.cpp:679] Received reply for offer 201203290030-0-591
I0329 00:35:58.614008 21855 master.cpp:1403] Filtered slave 201203290030-0-1 for framework 201203290030-0-0001 for 1 seconds
I0329 00:35:59.614166 21855 master.cpp:1184] Sending 1 offers to framework 201203290030-0-0000
I0329 00:35:59.614387 21855 master.cpp:1184] Sending 1 offers to framework 201203290030-0-0001
I0329 00:35:59.615790 21855 master.cpp:679] Received reply for offer 201203290030-0-592
I0329 00:35:59.615952 21855 master.cpp:1403] Filtered slave 201203290030-0-1 for framework 201203290030-0-0000 for 1 seconds
I0329 00:35:59.616265 21855 master.cpp:679] Received reply for offer 201203290030-0-593
I0329 00:35:59.616461 21855 master.cpp:1403] Filtered slave 201203290030-0-0 for framework 201203290030-0-0001 for 1 seconds
I0329 00:36:00.616590 21855 master.cpp:1184] Sending 1 offers to framework 201203290030-0-0000
I0329 00:36:00.616773 21855 master.cpp:1184] Sending 1 offers to framework 201203290030-0-0001
I0329 00:36:00.618229 21855 master.cpp:679] Received reply for offer 201203290030-0-594
I0329 00:36:00.618396 21855 master.cpp:1403] Filtered slave 201203290030-0-0 for framework 201203290030-0-0000 for 1 seconds
I0329 00:36:00.618758 21855 master.cpp:679] Received reply for offer 201203290030-0-595
I0329 00:36:00.618942 21855 master.cpp:1403] Filtered slave 201203290030-0-1 for framework 201203290030-0-0001 for 1 seconds
I0329 00:36:01.619053 21855 master.cpp:1184] Sending 1 offers to framework 201203290030-0-0000
I0329 00:36:01.619257 21855 master.cpp:1184] Sending 1 offers to framework 201203290030-0-0001
I0329 00:36:01.620535 21855 master.cpp:679] Received reply for offer 201203290030-0-596
I0329 00:36:01.667613 21855 master.cpp:1403] Filtered slave 201203290030-0-1 for framework 201203290030-0-0000 for 1 seconds
I0329 00:36:01.697033 21855 master.cpp:679] Received reply for offer 201203290030-0-597
I0329 00:36:01.697345 21855 master.cpp:1403] Filtered slave 201203290030-0-0 for framework 201203290030-0-0001 for 1 seconds
I0329 00:36:02.621754 21855 master.cpp:1184] Sending 1 offers to framework 201203290030-0-0000
I0329 00:36:02.621953 21855 master.cpp:1184] Sending 1 offers to framework 201203290030-0-0001
I0329 00:36:02.623241 21855 master.cpp:679] Received reply for offer 201203290030-0-598
I0329 00:36:02.623399 21855 master.cpp:1403] Filtered slave 201203290030-0-0 for framework 201203290030-0-0000 for 1 seconds
I0329 00:36:02.623703 21855 master.cpp:679] Received reply for offer 201203290030-0-599
I0329 00:36:02.623873 21855 master.cpp:1403] Filtered slave 201203290030-0-1 for framework 201203290030-0-0001 for 1 seconds
I0329 00:36:03.623918 21855 master.cpp:1184] Sending 1 offers to framework 201203290030-0-0000
I0329 00:36:03.624182 21855 master.cpp:1184] Sending 1 offers to framework 201203290030-0-0001
I0329 00:36:03.625362 21855 master.cpp:679] Received reply for offer 201203290030-0-600
I0329 00:36:03.625520 21855 master.cpp:1403] Filtered slave 201203290030-0-1 for framework 201203290030-0-0000 for 1 seconds
I0329 00:36:03.625982 21855 master.cpp:679] Received reply for offer 201203290030-0-601
I0329 00:36:03.626157 21855 master.cpp:1403] Filtered slave 201203290030-0-0 for framework 201203290030-0-0001 for 1 seconds
I0329 00:36:04.626276 21855 master.cpp:1184] Sending 1 offers to framework 201203290030-0-0000
I0329 00:36:04.626458 21855 master.cpp:1184] Sending 1 offers to framework 201203290030-0-0001
I0329 00:36:04.627922 21855 master.cpp:679] Received reply for offer 201203290030-0-602
I0329 00:36:04.628080 21855 master.cpp:1403] Filtered slave 201203290030-0-0 for framework 201203290030-0-0000 for 1 seconds
I0329 00:36:04.628423 21855 master.cpp:679] Received reply for offer 201203290030-0-603
I0329 00:36:04.628592 21855 master.cpp:1403] Filtered slave 201203290030-0-1 for framework 201203290030-0-0001 for 1 seconds
I0329 00:36:05.628767 21855 master.cpp:1184] Sending 1 offers to framework 201203290030-0-0000
I0329 00:36:05.628953 21855 master.cpp:1184] Sending 1 offers to framework 201203290030-0-0001
I0329 00:36:05.630422 21855 master.cpp:679] Received reply for offer 201203290030-0-604
I0329 00:36:05.630594 21855 master.cpp:1403] Filtered slave 201203290030-0-1 for framework 201203290030-0-0000 for 1 seconds
I0329 00:36:05.630964 21855 master.cpp:679] Received reply for offer 201203290030-0-605
I0329 00:36:05.631151 21855 master.cpp:1403] Filtered slave 201203290030-0-0 for framework 201203290030-0-0001 for 1 seconds
I0329 00:36:06.631237 21855 master.cpp:1184] Sending 1 offers to framework 201203290030-0-0000
I0329 00:36:06.631441 21855 master.cpp:1184] Sending 1 offers to framework 201203290030-0-0001
I0329 00:36:06.632887 21855 master.cpp:679] Received reply for offer 201203290030-0-606
I0329 00:36:06.679206 21855 master.cpp:1403] Filtered slave 201203290030-0-0 for framework 201203290030-0-0000 for 1 seconds
I0329 00:36:06.717224 21855 master.cpp:679] Received reply for offer 201203290030-0-607
I0329 00:36:06.717634 21855 master.cpp:1403] Filtered slave 201203290030-0-1 for framework 201203290030-0-0001 for 1 seconds
I0329 00:36:07.632583 21855 master.cpp:1184] Sending 1 offers to framework 201203290030-0-0000
I0329 00:36:07.632797 21855 master.cpp:1184] Sending 1 offers to framework 201203290030-0-0001
I0329 00:36:07.634155 21855 master.cpp:679] Received reply for offer 201203290030-0-608
I0329 00:36:07.634327 21855 master.cpp:1403] Filtered slave 201203290030-0-1 for framework 201203290030-0-0000 for 1 seconds
I0329 00:36:07.634702 21855 master.cpp:679] Received reply for offer 201203290030-0-609
I0329 00:36:07.634870 21855 master.cpp:1403] Filtered slave 201203290030-0-0 for framework 201203290030-0-0001 for 1 seconds
I0329 00:36:08.635001 21855 master.cpp:1184] Sending 1 offers to framework 201203290030-0-0000
I0329 00:36:08.635198 21855 master.cpp:1184] Sending 1 offers to framework 201203290030-0-0001
I0329 00:36:08.636750 21855 master.cpp:679] Received reply for offer 201203290030-0-610
I0329 00:36:08.636901 21855 master.cpp:1403] Filtered slave 201203290030-0-0 for framework 201203290030-0-0000 for 1 seconds
I0329 00:36:08.637302 21855 master.cpp:679] Received reply for offer 201203290030-0-611
I0329 00:36:08.637598 21855 master.cpp:1403] Filtered slave 201203290030-0-1 for framework 201203290030-0-0001 for 1 seconds
I0329 00:36:09.637446 21855 master.cpp:1184] Sending 1 offers to framework 201203290030-0-0000
I0329 00:36:09.637656 21855 master.cpp:1184] Sending 1 offers to framework 201203290030-0-0001
I0329 00:36:09.639154 21855 master.cpp:679] Received reply for offer 201203290030-0-612
I0329 00:36:09.639328 21855 master.cpp:1403] Filtered slave 201203290030-0-1 for framework 201203290030-0-0000 for 1 seconds
I0329 00:36:09.639593 21855 master.cpp:679] Received reply for offer 201203290030-0-613
I0329 00:36:09.639791 21855 master.cpp:1403] Filtered slave 201203290030-0-0 for framework 201203290030-0-0001 for 1 seconds
I0329 00:36:10.639925 21855 master.cpp:1184] Sending 1 offers to framework 201203290030-0-0000
I0329 00:36:10.640106 21855 master.cpp:1184] Sending 1 offers to framework 201203290030-0-0001
I0329 00:36:10.641667 21855 master.cpp:679] Received reply for offer 201203290030-0-614
I0329 00:36:10.641815 21855 master.cpp:1403] Filtered slave 201203290030-0-0 for framework 201203290030-0-0000 for 1 seconds
I0329 00:36:10.642107 21855 master.cpp:679] Received reply for offer 201203290030-0-615
I0329 00:36:10.642282 21855 master.cpp:1403] Filtered slave 201203290030-0-1 for framework 201203290030-0-0001 for 1 seconds
I0329 00:36:11.642391 21855 master.cpp:1184] Sending 1 offers to framework 201203290030-0-0000
I0329 00:36:11.642629 21855 master.cpp:1184] Sending 1 offers to framework 201203290030-0-0001
I0329 00:36:11.644049 21855 master.cpp:679] Received reply for offer 201203290030-0-616
I0329 00:36:11.690888 21855 master.cpp:1403] Filtered slave 201203290030-0-1 for framework 201203290030-0-0000 for 1 seconds
I0329 00:36:11.729092 21855 master.cpp:679] Received reply for offer 201203290030-0-617
I0329 00:36:11.729416 21855 master.cpp:1403] Filtered slave 201203290030-0-0 for framework 201203290030-0-0001 for 1 seconds
I0329 00:36:12.644850 21855 master.cpp:1184] Sending 1 offers to framework 201203290030-0-0000
I0329 00:36:12.645030 21855 master.cpp:1184] Sending 1 offers to framework 201203290030-0-0001
I0329 00:36:12.646487 21855 master.cpp:679] Received reply for offer 201203290030-0-618
I0329 00:36:12.646657 21855 master.cpp:1403] Filtered slave 201203290030-0-0 for framework 201203290030-0-0000 for 1 seconds
I0329 00:36:12.646978 21855 master.cpp:679] Received reply for offer 201203290030-0-619
I0329 00:36:12.647142 21855 master.cpp:1403] Filtered slave 201203290030-0-1 for framework 201203290030-0-0001 for 1 seconds
I0329 00:36:13.647063 21855 master.cpp:1184] Sending 1 offers to framework 201203290030-0-0000
I0329 00:36:13.647254 21855 master.cpp:1184] Sending 1 offers to framework 201203290030-0-0001
I0329 00:36:13.648767 21855 master.cpp:679] Received reply for offer 201203290030-0-620
I0329 00:36:13.648937 21855 master.cpp:1403] Filtered slave 201203290030-0-1 for framework 201203290030-0-0000 for 1 seconds
I0329 00:36:13.649267 21855 master.cpp:679] Received reply for offer 201203290030-0-621
I0329 00:36:13.649421 21855 master.cpp:1403] Filtered slave 201203290030-0-0 for framework 201203290030-0-0001 for 1 seconds
I0329 00:36:14.649539 21855 master.cpp:1184] Sending 1 offers to framework 201203290030-0-0000
I0329 00:36:14.649761 21855 master.cpp:1184] Sending 1 offers to framework 201203290030-0-0001
I0329 00:36:14.651247 21855 master.cpp:679] Received reply for offer 201203290030-0-622
I0329 00:36:14.651417 21855 master.cpp:1403] Filtered slave 201203290030-0-0 for framework 201203290030-0-0000 for 1 seconds
I0329 00:36:14.651659 21855 master.cpp:679] Received reply for offer 201203290030-0-623
I0329 00:36:14.651829 21855 master.cpp:1403] Filtered slave 201203290030-0-1 for framework 201203290030-0-0001 for 1 seconds
I0329 00:36:15.651665 21855 master.cpp:1184] Sending 1 offers to framework 201203290030-0-0000
I0329 00:36:15.651841 21855 master.cpp:1184] Sending 1 offers to framework 201203290030-0-0001
I0329 00:36:15.653370 21855 master.cpp:679] Received reply for offer 201203290030-0-624
I0329 00:36:15.653543 21855 master.cpp:1403] Filtered slave 201203290030-0-1 for framework 201203290030-0-0000 for 1 seconds
I0329 00:36:15.654494 21855 master.cpp:679] Received reply for offer 201203290030-0-625
I0329 00:36:15.654650 21855 master.cpp:1403] Filtered slave 201203290030-0-0 for framework 201203290030-0-0001 for 1 seconds
I0329 00:36:16.653754 21855 master.cpp:1184] Sending 1 offers to framework 201203290030-0-0000
I0329 00:36:16.654134 21855 master.cpp:1184] Sending 1 offers to framework 201203290030-0-0001
I0329 00:36:16.655437 21855 master.cpp:679] Received reply for offer 201203290030-0-626
I0329 00:36:16.710841 21855 master.cpp:1403] Filtered slave 201203290030-0-0 for framework 201203290030-0-0000 for 1 seconds
I0329 00:36:16.740830 21855 master.cpp:679] Received reply for offer 201203290030-0-627
I0329 00:36:16.741111 21855 master.cpp:1403] Filtered slave 201203290030-0-1 for framework 201203290030-0-0001 for 1 seconds
I0329 00:36:17.656333 21855 master.cpp:1184] Sending 1 offers to framework 201203290030-0-0000
I0329 00:36:17.656539 21855 master.cpp:1184] Sending 1 offers to framework 201203290030-0-0001
I0329 00:36:17.657876 21855 master.cpp:679] Received reply for offer 201203290030-0-628
I0329 00:36:17.658035 21855 master.cpp:1403] Filtered slave 201203290030-0-1 for framework 201203290030-0-0000 for 1 seconds
I0329 00:36:17.658330 21855 master.cpp:679] Received reply for offer 201203290030-0-629
I0329 00:36:17.658490 21855 master.cpp:1403] Filtered slave 201203290030-0-0 for framework 201203290030-0-0001 for 1 seconds
I0329 00:36:18.658521 21855 master.cpp:1184] Sending 1 offers to framework 201203290030-0-0000
I0329 00:36:18.658716 21855 master.cpp:1184] Sending 1 offers to framework 201203290030-0-0001
I0329 00:36:18.660004 21855 master.cpp:679] Received reply for offer 201203290030-0-630
I0329 00:36:18.660151 21855 master.cpp:1403] Filtered slave 201203290030-0-0 for framework 201203290030-0-0000 for 1 seconds
I0329 00:36:18.660581 21855 master.cpp:679] Received reply for offer 201203290030-0-631
I0329 00:36:18.660750 21855 master.cpp:1403] Filtered slave 201203290030-0-1 for framework 201203290030-0-0001 for 1 seconds
I0329 00:36:19.660917 21855 master.cpp:1184] Sending 1 offers to framework 201203290030-0-0000
I0329 00:36:19.661102 21855 master.cpp:1184] Sending 1 offers to framework 201203290030-0-0001
I0329 00:36:19.662554 21855 master.cpp:679] Received reply for offer 201203290030-0-632
I0329 00:36:19.662725 21855 master.cpp:1403] Filtered slave 201203290030-0-1 for framework 201203290030-0-0000 for 1 seconds
I0329 00:36:19.663045 21855 master.cpp:679] Received reply for offer 201203290030-0-633
I0329 00:36:19.663223 21855 master.cpp:1403] Filtered slave 201203290030-0-0 for framework 201203290030-0-0001 for 1 seconds
I0329 00:36:20.663348 21855 master.cpp:1184] Sending 1 offers to framework 201203290030-0-0000
I0329 00:36:20.663571 21855 master.cpp:1184] Sending 1 offers to framework 201203290030-0-0001
I0329 00:36:20.665036 21855 master.cpp:679] Received reply for offer 201203290030-0-634
I0329 00:36:20.665194 21855 master.cpp:1403] Filtered slave 201203290030-0-0 for framework 201203290030-0-0000 for 1 seconds
I0329 00:36:20.665516 21855 master.cpp:679] Received reply for offer 201203290030-0-635
I0329 00:36:20.665684 21855 master.cpp:1403] Filtered slave 201203290030-0-1 for framework 201203290030-0-0001 for 1 seconds
I0329 00:36:21.665856 21855 master.cpp:1184] Sending 1 offers to framework 201203290030-0-0000
I0329 00:36:21.666020 21855 master.cpp:1184] Sending 1 offers to framework 201203290030-0-0001
I0329 00:36:21.667489 21855 master.cpp:679] Received reply for offer 201203290030-0-636
I0329 00:36:21.714191 21855 master.cpp:1403] Filtered slave 201203290030-0-1 for framework 201203290030-0-0000 for 1 seconds
I0329 00:36:21.752712 21855 master.cpp:679] Received reply for offer 201203290030-0-637
I0329 00:36:21.753113 21855 master.cpp:1403] Filtered slave 201203290030-0-0 for framework 201203290030-0-0001 for 1 seconds
I0329 00:36:22.668401 21855 master.cpp:1184] Sending 1 offers to framework 201203290030-0-0000
I0329 00:36:22.668581 21855 master.cpp:1184] Sending 1 offers to framework 201203290030-0-0001
I0329 00:36:22.670035 21855 master.cpp:679] Received reply for offer 201203290030-0-638
I0329 00:36:22.670204 21855 master.cpp:1403] Filtered slave 201203290030-0-0 for framework 201203290030-0-0000 for 1 seconds
I0329 00:36:22.670500 21855 master.cpp:679] Received reply for offer 201203290030-0-639
I0329 00:36:22.670667 21855 master.cpp:1403] Filtered slave 201203290030-0-1 for framework 201203290030-0-0001 for 1 seconds
I0329 00:36:23.670793 21855 master.cpp:1184] Sending 1 offers to framework 201203290030-0-0000
I0329 00:36:23.670977 21855 master.cpp:1184] Sending 1 offers to framework 201203290030-0-0001
I0329 00:36:23.672399 21855 master.cpp:679] Received reply for offer 201203290030-0-640
I0329 00:36:23.672570 21855 master.cpp:1403] Filtered slave 201203290030-0-1 for framework 201203290030-0-0000 for 1 seconds
I0329 00:36:23.672899 21855 master.cpp:679] Received reply for offer 201203290030-0-641
I0329 00:36:23.673065 21855 master.cpp:1403] Filtered slave 201203290030-0-0 for framework 201203290030-0-0001 for 1 seconds
I0329 00:36:24.673207 21855 master.cpp:1184] Sending 1 offers to framework 201203290030-0-0000
I0329 00:36:24.673393 21855 master.cpp:1184] Sending 1 offers to framework 201203290030-0-0001
I0329 00:36:24.674881 21855 master.cpp:679] Received reply for offer 201203290030-0-642
I0329 00:36:24.675048 21855 master.cpp:1403] Filtered slave 201203290030-0-0 for framework 201203290030-0-0000 for 1 seconds
I0329 00:36:24.675338 21855 master.cpp:679] Received reply for offer 201203290030-0-643
I0329 00:36:24.675508 21855 master.cpp:1403] Filtered slave 201203290030-0-1 for framework 201203290030-0-0001 for 1 seconds
I0329 00:36:25.675673 21855 master.cpp:1184] Sending 1 offers to framework 201203290030-0-0000
I0329 00:36:25.675859 21855 master.cpp:1184] Sending 1 offers to framework 201203290030-0-0001
I0329 00:36:25.677322 21855 master.cpp:679] Received reply for offer 201203290030-0-644
I0329 00:36:25.677495 21855 master.cpp:1403] Filtered slave 201203290030-0-1 for framework 201203290030-0-0000 for 1 seconds
I0329 00:36:25.677814 21855 master.cpp:679] Received reply for offer 201203290030-0-645
I0329 00:36:25.677981 21855 master.cpp:1403] Filtered slave 201203290030-0-0 for framework 201203290030-0-0001 for 1 seconds
I0329 00:36:26.678112 21855 master.cpp:1184] Sending 1 offers to framework 201203290030-0-0000
I0329 00:36:26.678266 21855 master.cpp:1184] Sending 1 offers to framework 201203290030-0-0001
I0329 00:36:26.679729 21855 master.cpp:679] Received reply for offer 201203290030-0-646
I0329 00:36:26.725852 21855 master.cpp:1403] Filtered slave 201203290030-0-0 for framework 201203290030-0-0000 for 1 seconds
I0329 00:36:26.764385 21855 master.cpp:679] Received reply for offer 201203290030-0-647
I0329 00:36:26.764654 21855 master.cpp:1403] Filtered slave 201203290030-0-1 for framework 201203290030-0-0001 for 1 seconds
I0329 00:36:27.680637 21855 master.cpp:1184] Sending 1 offers to framework 201203290030-0-0000
I0329 00:36:27.680819 21855 master.cpp:1184] Sending 1 offers to framework 201203290030-0-0001
I0329 00:36:27.682979 21855 master.cpp:679] Received reply for offer 201203290030-0-648
I0329 00:36:27.683193 21855 master.cpp:1403] Filtered slave 201203290030-0-1 for framework 201203290030-0-0000 for 1 seconds
I0329 00:36:27.683325 21855 master.cpp:679] Received reply for offer 201203290030-0-649
I0329 00:36:27.683485 21855 master.cpp:1403] Filtered slave 201203290030-0-0 for framework 201203290030-0-0001 for 1 seconds
I0329 00:36:28.682142 21855 master.cpp:1184] Sending 1 offers to framework 201203290030-0-0000
I0329 00:36:28.682323 21855 master.cpp:1184] Sending 1 offers to framework 201203290030-0-0001
I0329 00:36:28.683768 21855 master.cpp:679] Received reply for offer 201203290030-0-650
I0329 00:36:28.683922 21855 master.cpp:1403] Filtered slave 201203290030-0-0 for framework 201203290030-0-0000 for 1 seconds
I0329 00:36:28.684306 21855 master.cpp:679] Received reply for offer 201203290030-0-651
I0329 00:36:28.684593 21855 master.cpp:1403] Filtered slave 201203290030-0-1 for framework 201203290030-0-0001 for 1 seconds
I0329 00:36:29.684226 21855 master.cpp:1184] Sending 1 offers to framework 201203290030-0-0000
I0329 00:36:29.684412 21855 master.cpp:1184] Sending 1 offers to framework 201203290030-0-0001
I0329 00:36:29.685986 21855 master.cpp:679] Received reply for offer 201203290030-0-652
I0329 00:36:29.686133 21855 master.cpp:1403] Filtered slave 201203290030-0-1 for framework 201203290030-0-0000 for 1 seconds
I0329 00:36:29.686296 21855 master.cpp:679] Received reply for offer 201203290030-0-653
I0329 00:36:29.686447 21855 master.cpp:1403] Filtered slave 201203290030-0-0 for framework 201203290030-0-0001 for 1 seconds
I0329 00:36:30.686616 21855 master.cpp:1184] Sending 1 offers to framework 201203290030-0-0000
I0329 00:36:30.686800 21855 master.cpp:1184] Sending 1 offers to framework 201203290030-0-0001
I0329 00:36:30.688140 21855 master.cpp:679] Received reply for offer 201203290030-0-654
I0329 00:36:30.688313 21855 master.cpp:1403] Filtered slave 201203290030-0-0 for framework 201203290030-0-0000 for 1 seconds
I0329 00:36:30.688627 21855 master.cpp:679] Received reply for offer 201203290030-0-655
I0329 00:36:30.688796 21855 master.cpp:1403] Filtered slave 201203290030-0-1 for framework 201203290030-0-0001 for 1 seconds
I0329 00:36:31.688931 21855 master.cpp:1184] Sending 1 offers to framework 201203290030-0-0000
I0329 00:36:31.689090 21855 master.cpp:1184] Sending 1 offers to framework 201203290030-0-0001
I0329 00:36:31.690397 21855 master.cpp:679] Received reply for offer 201203290030-0-656
I0329 00:36:31.754220 21855 master.cpp:1403] Filtered slave 201203290030-0-1 for framework 201203290030-0-0000 for 1 seconds
I0329 00:36:31.792948 21855 master.cpp:679] Received reply for offer 201203290030-0-657
I0329 00:36:31.793254 21855 master.cpp:1403] Filtered slave 201203290030-0-0 for framework 201203290030-0-0001 for 1 seconds
I0329 00:36:32.691356 21855 master.cpp:1184] Sending 1 offers to framework 201203290030-0-0000
I0329 00:36:32.691545 21855 master.cpp:1184] Sending 1 offers to framework 201203290030-0-0001
I0329 00:36:32.692872 21855 master.cpp:679] Received reply for offer 201203290030-0-658
I0329 00:36:32.693027 21855 master.cpp:1403] Filtered slave 201203290030-0-0 for framework 201203290030-0-0000 for 1 seconds
I0329 00:36:32.693300 21855 master.cpp:679] Received reply for offer 201203290030-0-659
I0329 00:36:32.693460 21855 master.cpp:1403] Filtered slave 201203290030-0-1 for framework 201203290030-0-0001 for 1 seconds
I0329 00:36:33.693511 21855 master.cpp:1184] Sending 1 offers to framework 201203290030-0-0000
I0329 00:36:33.693723 21855 master.cpp:1184] Sending 1 offers to framework 201203290030-0-0001
I0329 00:36:33.695036 21855 master.cpp:679] Received reply for offer 201203290030-0-660
I0329 00:36:33.695286 21855 master.cpp:1403] Filtered slave 201203290030-0-1 for framework 201203290030-0-0000 for 1 seconds
I0329 00:36:33.695773 21855 master.cpp:679] Received reply for offer 201203290030-0-661
I0329 00:36:33.696107 21855 master.cpp:1403] Filtered slave 201203290030-0-0 for framework 201203290030-0-0001 for 1 seconds
I0329 00:36:34.695322 21855 master.cpp:1184] Sending 1 offers to framework 201203290030-0-0000
I0329 00:36:34.695518 21855 master.cpp:1184] Sending 1 offers to framework 201203290030-0-0001
I0329 00:36:34.696908 21855 master.cpp:679] Received reply for offer 201203290030-0-662
I0329 00:36:34.697075 21855 master.cpp:1403] Filtered slave 201203290030-0-0 for framework 201203290030-0-0000 for 1 seconds
I0329 00:36:34.697309 21855 master.cpp:679] Received reply for offer 201203290030-0-663
I0329 00:36:34.697479 21855 master.cpp:1403] Filtered slave 201203290030-0-1 for framework 201203290030-0-0001 for 1 seconds
I0329 00:36:35.697526 21855 master.cpp:1184] Sending 1 offers to framework 201203290030-0-0000
I0329 00:36:35.697728 21855 master.cpp:1184] Sending 1 offers to framework 201203290030-0-0001
I0329 00:36:35.699183 21855 master.cpp:679] Received reply for offer 201203290030-0-664
I0329 00:36:35.699352 21855 master.cpp:1403] Filtered slave 201203290030-0-1 for framework 201203290030-0-0000 for 1 seconds
I0329 00:36:35.699748 21855 master.cpp:679] Received reply for offer 201203290030-0-665
I0329 00:36:35.699965 21855 master.cpp:1403] Filtered slave 201203290030-0-0 for framework 201203290030-0-0001 for 1 seconds
I0329 00:36:36.699965 21855 master.cpp:1184] Sending 1 offers to framework 201203290030-0-0000
I0329 00:36:36.700124 21855 master.cpp:1184] Sending 1 offers to framework 201203290030-0-0001
I0329 00:36:36.701508 21855 master.cpp:679] Received reply for offer 201203290030-0-666
I0329 00:36:36.757529 21855 master.cpp:1403] Filtered slave 201203290030-0-0 for framework 201203290030-0-0000 for 1 seconds
I0329 00:36:36.788187 21855 master.cpp:679] Received reply for offer 201203290030-0-667
I0329 00:36:36.788645 21855 master.cpp:1403] Filtered slave 201203290030-0-1 for framework 201203290030-0-0001 for 1 seconds
I0329 00:36:37.702119 21855 master.cpp:1184] Sending 1 offers to framework 201203290030-0-0000
I0329 00:36:37.702318 21855 master.cpp:1184] Sending 1 offers to framework 201203290030-0-0001
I0329 00:36:37.703724 21855 master.cpp:679] Received reply for offer 201203290030-0-668
I0329 00:36:37.703883 21855 master.cpp:1403] Filtered slave 201203290030-0-1 for framework 201203290030-0-0000 for 1 seconds
I0329 00:36:37.704164 21855 master.cpp:679] Received reply for offer 201203290030-0-669
I0329 00:36:37.704427 21855 master.cpp:1403] Filtered slave 201203290030-0-0 for framework 201203290030-0-0001 for 1 seconds
I0329 00:36:38.704385 21855 master.cpp:1184] Sending 1 offers to framework 201203290030-0-0000
I0329 00:36:38.704574 21855 master.cpp:1184] Sending 1 offers to framework 201203290030-0-0001
I0329 00:36:38.705929 21855 master.cpp:679] Received reply for offer 201203290030-0-670
I0329 00:36:38.706097 21855 master.cpp:1403] Filtered slave 201203290030-0-0 for framework 201203290030-0-0000 for 1 seconds
I0329 00:36:38.706473 21855 master.cpp:679] Received reply for offer 201203290030-0-671
I0329 00:36:38.706645 21855 master.cpp:1403] Filtered slave 201203290030-0-1 for framework 201203290030-0-0001 for 1 seconds
I0329 00:36:39.706692 21855 master.cpp:1184] Sending 1 offers to framework 201203290030-0-0000
I0329 00:36:39.706895 21855 master.cpp:1184] Sending 1 offers to framework 201203290030-0-0001
I0329 00:36:39.708181 21855 master.cpp:679] Received reply for offer 201203290030-0-672
I0329 00:36:39.708410 21855 master.cpp:1403] Filtered slave 201203290030-0-1 for framework 201203290030-0-0000 for 1 seconds
I0329 00:36:39.708633 21855 master.cpp:679] Received reply for offer 201203290030-0-673
I0329 00:36:39.708804 21855 master.cpp:1403] Filtered slave 201203290030-0-0 for framework 201203290030-0-0001 for 1 seconds
I0329 00:36:40.708842 21855 master.cpp:1184] Sending 1 offers to framework 201203290030-0-0000
I0329 00:36:40.709041 21855 master.cpp:1184] Sending 1 offers to framework 201203290030-0-0001
I0329 00:36:40.710440 21855 master.cpp:679] Received reply for offer 201203290030-0-674
I0329 00:36:40.710615 21855 master.cpp:1403] Filtered slave 201203290030-0-0 for framework 201203290030-0-0000 for 1 seconds
I0329 00:36:40.710849 21855 master.cpp:679] Received reply for offer 201203290030-0-675
I0329 00:36:40.711035 21855 master.cpp:1403] Filtered slave 201203290030-0-1 for framework 201203290030-0-0001 for 1 seconds
I0329 00:36:41.711068 21855 master.cpp:1184] Sending 1 offers to framework 201203290030-0-0000
I0329 00:36:41.711253 21855 master.cpp:1184] Sending 1 offers to framework 201203290030-0-0001
I0329 00:36:41.712520 21855 master.cpp:679] Received reply for offer 201203290030-0-676
I0329 00:36:41.744216 21855 master.cpp:1403] Filtered slave 201203290030-0-1 for framework 201203290030-0-0000 for 1 seconds
I0329 00:36:41.783315 21855 master.cpp:679] Received reply for offer 201203290030-0-677
I0329 00:36:41.783771 21855 master.cpp:1403] Filtered slave 201203290030-0-0 for framework 201203290030-0-0001 for 1 seconds
I0329 00:36:42.713181 21855 master.cpp:1184] Sending 1 offers to framework 201203290030-0-0000
I0329 00:36:42.713382 21855 master.cpp:1184] Sending 1 offers to framework 201203290030-0-0001
I0329 00:36:42.714596 21855 master.cpp:679] Received reply for offer 201203290030-0-678
I0329 00:36:42.714761 21855 master.cpp:1403] Filtered slave 201203290030-0-0 for framework 201203290030-0-0000 for 1 seconds
I0329 00:36:42.715095 21855 master.cpp:679] Received reply for offer 201203290030-0-679
I0329 00:36:42.715260 21855 master.cpp:1403] Filtered slave 201203290030-0-1 for framework 201203290030-0-0001 for 1 seconds
I0329 00:36:43.714859 21855 master.cpp:1184] Sending 1 offers to framework 201203290030-0-0000
I0329 00:36:43.715183 21855 master.cpp:1184] Sending 1 offers to framework 201203290030-0-0001
I0329 00:36:43.716383 21855 master.cpp:679] Received reply for offer 201203290030-0-680
I0329 00:36:43.716549 21855 master.cpp:1403] Filtered slave 201203290030-0-1 for framework 201203290030-0-0000 for 1 seconds
I0329 00:36:43.716925 21855 master.cpp:679] Received reply for offer 201203290030-0-681
I0329 00:36:43.717097 21855 master.cpp:1403] Filtered slave 201203290030-0-0 for framework 201203290030-0-0001 for 1 seconds
I0329 00:36:44.717115 21855 master.cpp:1184] Sending 1 offers to framework 201203290030-0-0000
I0329 00:36:44.717419 21855 master.cpp:1184] Sending 1 offers to framework 201203290030-0-0001
I0329 00:36:44.718569 21855 master.cpp:679] Received reply for offer 201203290030-0-682
I0329 00:36:44.718734 21855 master.cpp:1403] Filtered slave 201203290030-0-0 for framework 201203290030-0-0000 for 1 seconds
I0329 00:36:44.719038 21855 master.cpp:679] Received reply for offer 201203290030-0-683
I0329 00:36:44.719261 21855 master.cpp:1403] Filtered slave 201203290030-0-1 for framework 201203290030-0-0001 for 1 seconds
I0329 00:36:45.719241 21855 master.cpp:1184] Sending 1 offers to framework 201203290030-0-0000
I0329 00:36:45.719442 21855 master.cpp:1184] Sending 1 offers to framework 201203290030-0-0001
I0329 00:36:45.720729 21855 master.cpp:679] Received reply for offer 201203290030-0-684
I0329 00:36:45.720896 21855 master.cpp:1403] Filtered slave 201203290030-0-1 for framework 201203290030-0-0000 for 1 seconds
I0329 00:36:45.721199 21855 master.cpp:679] Received reply for offer 201203290030-0-685
I0329 00:36:45.721364 21855 master.cpp:1403] Filtered slave 201203290030-0-0 for framework 201203290030-0-0001 for 1 seconds
I0329 00:36:46.721387 21855 master.cpp:1184] Sending 1 offers to framework 201203290030-0-0000
I0329 00:36:46.721552 21855 master.cpp:1184] Sending 1 offers to framework 201203290030-0-0001
I0329 00:36:46.722830 21855 master.cpp:679] Received reply for offer 201203290030-0-686
I0329 00:36:46.755811 21855 master.cpp:1403] Filtered slave 201203290030-0-0 for framework 201203290030-0-0000 for 1 seconds
I0329 00:36:46.795049 21855 master.cpp:679] Received reply for offer 201203290030-0-687
I0329 00:36:46.795354 21855 master.cpp:1403] Filtered slave 201203290030-0-1 for framework 201203290030-0-0001 for 1 seconds
I0329 00:36:47.723315 21855 master.cpp:1184] Sending 1 offers to framework 201203290030-0-0000
I0329 00:36:47.723515 21855 master.cpp:1184] Sending 1 offers to framework 201203290030-0-0001
I0329 00:36:47.724839 21855 master.cpp:679] Received reply for offer 201203290030-0-688
I0329 00:36:47.725009 21855 master.cpp:1403] Filtered slave 201203290030-0-1 for framework 201203290030-0-0000 for 1 seconds
I0329 00:36:47.725400 21855 master.cpp:679] Received reply for offer 201203290030-0-689
I0329 00:36:47.725564 21855 master.cpp:1403] Filtered slave 201203290030-0-0 for framework 201203290030-0-0001 for 1 seconds
I0329 00:36:48.725599 21855 master.cpp:1184] Sending 1 offers to framework 201203290030-0-0000
I0329 00:36:48.725821 21855 master.cpp:1184] Sending 1 offers to framework 201203290030-0-0001
I0329 00:36:48.727097 21855 master.cpp:679] Received reply for offer 201203290030-0-690
I0329 00:36:48.727264 21855 master.cpp:1403] Filtered slave 201203290030-0-0 for framework 201203290030-0-0000 for 1 seconds
I0329 00:36:48.727670 21855 master.cpp:679] Received reply for offer 201203290030-0-691
I0329 00:36:48.727922 21855 master.cpp:1403] Filtered slave 201203290030-0-1 for framework 201203290030-0-0001 for 1 seconds
I0329 00:36:49.727309 21855 master.cpp:1184] Sending 1 offers to framework 201203290030-0-0000
I0329 00:36:49.727519 21855 master.cpp:1184] Sending 1 offers to framework 201203290030-0-0001
I0329 00:36:49.728816 21855 master.cpp:679] Received reply for offer 201203290030-0-692
I0329 00:36:49.728982 21855 master.cpp:1403] Filtered slave 201203290030-0-1 for framework 201203290030-0-0000 for 1 seconds
I0329 00:36:49.729267 21855 master.cpp:679] Received reply for offer 201203290030-0-693
I0329 00:36:49.729434 21855 master.cpp:1403] Filtered slave 201203290030-0-0 for framework 201203290030-0-0001 for 1 seconds
I0329 00:36:50.729496 21855 master.cpp:1184] Sending 1 offers to framework 201203290030-0-0000
I0329 00:36:50.729805 21855 master.cpp:1184] Sending 1 offers to framework 201203290030-0-0001
I0329 00:36:50.730990 21855 master.cpp:679] Received reply for offer 201203290030-0-694
I0329 00:36:50.731236 21855 master.cpp:1403] Filtered slave 201203290030-0-0 for framework 201203290030-0-0000 for 1 seconds
I0329 00:36:50.731698 21855 master.cpp:679] Received reply for offer 201203290030-0-695
I0329 00:36:50.731988 21855 master.cpp:1403] Filtered slave 201203290030-0-1 for framework 201203290030-0-0001 for 1 seconds
I0329 00:36:51.731294 21855 master.cpp:1184] Sending 1 offers to framework 201203290030-0-0000
I0329 00:36:51.731521 21855 master.cpp:1184] Sending 1 offers to framework 201203290030-0-0001
I0329 00:36:51.732897 21855 master.cpp:679] Received reply for offer 201203290030-0-696
I0329 00:36:51.733012 21855 master.cpp:1403] Filtered slave 201203290030-0-1 for framework 201203290030-0-0000 for 1 seconds
I0329 00:36:51.759059 21855 master.cpp:679] Received reply for offer 201203290030-0-697
I0329 00:36:51.798586 21855 master.cpp:1403] Filtered slave 201203290030-0-0 for framework 201203290030-0-0001 for 1 seconds
I0329 00:36:52.733587 21855 master.cpp:1184] Sending 1 offers to framework 201203290030-0-0000
I0329 00:36:52.733872 21855 master.cpp:1184] Sending 1 offers to framework 201203290030-0-0001
I0329 00:36:52.735340 21855 master.cpp:679] Received reply for offer 201203290030-0-698
I0329 00:36:52.735501 21855 master.cpp:1403] Filtered slave 201203290030-0-0 for framework 201203290030-0-0000 for 1 seconds
I0329 00:36:52.735896 21855 master.cpp:679] Received reply for offer 201203290030-0-699
I0329 00:36:52.736063 21855 master.cpp:1403] Filtered slave 201203290030-0-1 for framework 201203290030-0-0001 for 1 seconds
I0329 00:36:53.735420 21855 master.cpp:1184] Sending 1 offers to framework 201203290030-0-0000
I0329 00:36:53.735630 21855 master.cpp:1184] Sending 1 offers to framework 201203290030-0-0001
I0329 00:36:53.737135 21855 master.cpp:679] Received reply for offer 201203290030-0-700
I0329 00:36:53.737299 21855 master.cpp:1403] Filtered slave 201203290030-0-1 for framework 201203290030-0-0000 for 1 seconds
I0329 00:36:53.737452 21855 master.cpp:679] Received reply for offer 201203290030-0-701
I0329 00:36:53.737608 21855 master.cpp:1403] Filtered slave 201203290030-0-0 for framework 201203290030-0-0001 for 1 seconds
I0329 00:36:54.737725 21855 master.cpp:1184] Sending 1 offers to framework 201203290030-0-0000
I0329 00:36:54.737951 21855 master.cpp:1184] Sending 1 offers to framework 201203290030-0-0001
I0329 00:36:54.739435 21855 master.cpp:679] Received reply for offer 201203290030-0-702
I0329 00:36:54.739606 21855 master.cpp:1403] Filtered slave 201203290030-0-0 for framework 201203290030-0-0000 for 1 seconds
I0329 00:36:54.739869 21855 master.cpp:679] Received reply for offer 201203290030-0-703
I0329 00:36:54.740052 21855 master.cpp:1403] Filtered slave 201203290030-0-1 for framework 201203290030-0-0001 for 1 seconds
I0329 00:36:55.740211 21855 master.cpp:1184] Sending 1 offers to framework 201203290030-0-0000
I0329 00:36:55.740370 21855 master.cpp:1184] Sending 1 offers to framework 201203290030-0-0001
I0329 00:36:55.741914 21855 master.cpp:679] Received reply for offer 201203290030-0-704
I0329 00:36:55.742072 21855 master.cpp:1403] Filtered slave 201203290030-0-1 for framework 201203290030-0-0000 for 1 seconds
I0329 00:36:55.742483 21855 master.cpp:679] Received reply for offer 201203290030-0-705
I0329 00:36:55.742657 21855 master.cpp:1403] Filtered slave 201203290030-0-0 for framework 201203290030-0-0001 for 1 seconds
I0329 00:36:56.742714 21855 master.cpp:1184] Sending 1 offers to framework 201203290030-0-0000
I0329 00:36:56.742871 21855 master.cpp:1184] Sending 1 offers to framework 201203290030-0-0001
I0329 00:36:56.744189 21855 master.cpp:679] Received reply for offer 201203290030-0-706
I0329 00:36:56.787667 21855 master.cpp:1403] Filtered slave 201203290030-0-0 for framework 201203290030-0-0000 for 1 seconds
I0329 00:36:56.827138 21855 master.cpp:679] Received reply for offer 201203290030-0-707
I0329 00:36:56.827435 21855 master.cpp:1403] Filtered slave 201203290030-0-1 for framework 201203290030-0-0001 for 1 seconds
I0329 00:36:57.744910 21855 master.cpp:1184] Sending 1 offers to framework 201203290030-0-0000
I0329 00:36:57.745091 21855 master.cpp:1184] Sending 1 offers to framework 201203290030-0-0001
I0329 00:36:57.746620 21855 master.cpp:679] Received reply for offer 201203290030-0-708
I0329 00:36:57.746793 21855 master.cpp:1403] Filtered slave 201203290030-0-1 for framework 201203290030-0-0000 for 1 seconds
I0329 00:36:57.747053 21855 master.cpp:679] Received reply for offer 201203290030-0-709
I0329 00:36:57.747230 21855 master.cpp:1403] Filtered slave 201203290030-0-0 for framework 201203290030-0-0001 for 1 seconds
I0329 00:36:58.747023 21855 master.cpp:1184] Sending 1 offers to framework 201203290030-0-0000
I0329 00:36:58.747222 21855 master.cpp:1184] Sending 1 offers to framework 201203290030-0-0001
I0329 00:36:58.748661 21855 master.cpp:679] Received reply for offer 201203290030-0-710
I0329 00:36:58.748831 21855 master.cpp:1403] Filtered slave 201203290030-0-0 for framework 201203290030-0-0000 for 1 seconds
I0329 00:36:58.749258 21855 master.cpp:679] Received reply for offer 201203290030-0-711
I0329 00:36:58.749433 21855 master.cpp:1403] Filtered slave 201203290030-0-1 for framework 201203290030-0-0001 for 1 seconds
I0329 00:36:59.749534 21855 master.cpp:1184] Sending 1 offers to framework 201203290030-0-0000
I0329 00:36:59.749728 21855 master.cpp:1184] Sending 1 offers to framework 201203290030-0-0001
I0329 00:36:59.751287 21855 master.cpp:679] Received reply for offer 201203290030-0-712
I0329 00:36:59.751461 21855 master.cpp:1403] Filtered slave 201203290030-0-1 for framework 201203290030-0-0000 for 1 seconds
I0329 00:36:59.751914 21855 master.cpp:679] Received reply for offer 201203290030-0-713
I0329 00:36:59.752089 21855 master.cpp:1403] Filtered slave 201203290030-0-0 for framework 201203290030-0-0001 for 1 seconds
I0329 00:37:00.752163 21855 master.cpp:1184] Sending 1 offers to framework 201203290030-0-0000
I0329 00:37:00.752362 21855 master.cpp:1184] Sending 1 offers to framework 201203290030-0-0001
I0329 00:37:00.753859 21855 master.cpp:679] Received reply for offer 201203290030-0-714
I0329 00:37:00.754006 21855 master.cpp:1403] Filtered slave 201203290030-0-0 for framework 201203290030-0-0000 for 1 seconds
I0329 00:37:00.754405 21855 master.cpp:679] Received reply for offer 201203290030-0-715
I0329 00:37:00.754575 21855 master.cpp:1403] Filtered slave 201203290030-0-1 for framework 201203290030-0-0001 for 1 seconds
I0329 00:37:01.754711 21855 master.cpp:1184] Sending 1 offers to framework 201203290030-0-0000
I0329 00:37:01.754874 21855 master.cpp:1184] Sending 1 offers to framework 201203290030-0-0001
I0329 00:37:01.756376 21855 master.cpp:679] Received reply for offer 201203290030-0-716
I0329 00:37:01.799119 21855 master.cpp:1403] Filtered slave 201203290030-0-1 for framework 201203290030-0-0000 for 1 seconds
I0329 00:37:01.838817 21855 master.cpp:679] Received reply for offer 201203290030-0-717
I0329 00:37:01.839432 21855 master.cpp:1403] Filtered slave 201203290030-0-0 for framework 201203290030-0-0001 for 1 seconds
I0329 00:37:02.756736 21855 master.cpp:1184] Sending 1 offers to framework 201203290030-0-0000
I0329 00:37:02.756922 21855 master.cpp:1184] Sending 1 offers to framework 201203290030-0-0001
I0329 00:37:02.758256 21855 master.cpp:679] Received reply for offer 201203290030-0-718
I0329 00:37:02.758414 21855 master.cpp:1403] Filtered slave 201203290030-0-0 for framework 201203290030-0-0000 for 1 seconds
I0329 00:37:02.758748 21855 master.cpp:679] Received reply for offer 201203290030-0-719
I0329 00:37:02.758911 21855 master.cpp:1403] Filtered slave 201203290030-0-1 for framework 201203290030-0-0001 for 1 seconds
I0329 00:37:03.758960 21855 master.cpp:1184] Sending 1 offers to framework 201203290030-0-0000
I0329 00:37:03.759174 21855 master.cpp:1184] Sending 1 offers to framework 201203290030-0-0001
I0329 00:37:03.760539 21855 master.cpp:679] Received reply for offer 201203290030-0-720
I0329 00:37:03.760696 21855 master.cpp:1403] Filtered slave 201203290030-0-1 for framework 201203290030-0-0000 for 1 seconds
I0329 00:37:03.761072 21855 master.cpp:679] Received reply for offer 201203290030-0-721
I0329 00:37:03.761232 21855 master.cpp:1403] Filtered slave 201203290030-0-0 for framework 201203290030-0-0001 for 1 seconds
I0329 00:37:04.761176 21855 master.cpp:1184] Sending 1 offers to framework 201203290030-0-0000
I0329 00:37:04.761353 21855 master.cpp:1184] Sending 1 offers to framework 201203290030-0-0001
I0329 00:37:04.762608 21855 master.cpp:679] Received reply for offer 201203290030-0-722
I0329 00:37:04.762761 21855 master.cpp:1403] Filtered slave 201203290030-0-0 for framework 201203290030-0-0000 for 1 seconds
I0329 00:37:04.763037 21855 master.cpp:679] Received reply for offer 201203290030-0-723
I0329 00:37:04.763231 21855 master.cpp:1403] Filtered slave 201203290030-0-1 for framework 201203290030-0-0001 for 1 seconds
I0329 00:37:05.763249 21855 master.cpp:1184] Sending 1 offers to framework 201203290030-0-0000
I0329 00:37:05.763538 21855 master.cpp:1184] Sending 1 offers to framework 201203290030-0-0001
I0329 00:37:05.764806 21855 master.cpp:679] Received reply for offer 201203290030-0-724
I0329 00:37:05.764968 21855 master.cpp:1403] Filtered slave 201203290030-0-1 for framework 201203290030-0-0000 for 1 seconds
I0329 00:37:05.765352 21855 master.cpp:679] Received reply for offer 201203290030-0-725
I0329 00:37:05.765521 21855 master.cpp:1403] Filtered slave 201203290030-0-0 for framework 201203290030-0-0001 for 1 seconds
I0329 00:37:06.765688 21855 master.cpp:1184] Sending 1 offers to framework 201203290030-0-0000
I0329 00:37:06.765920 21855 master.cpp:1184] Sending 1 offers to framework 201203290030-0-0001
I0329 00:37:06.767474 21855 master.cpp:679] Received reply for offer 201203290030-0-726
I0329 00:37:06.819157 21855 master.cpp:1403] Filtered slave 201203290030-0-0 for framework 201203290030-0-0000 for 1 seconds
I0329 00:37:06.858922 21855 master.cpp:679] Received reply for offer 201203290030-0-727
I0329 00:37:06.859388 21855 master.cpp:1403] Filtered slave 201203290030-0-1 for framework 201203290030-0-0001 for 1 seconds
I0329 00:37:07.768311 21855 master.cpp:1184] Sending 1 offers to framework 201203290030-0-0000
I0329 00:37:07.768501 21855 master.cpp:1184] Sending 1 offers to framework 201203290030-0-0001
I0329 00:37:07.769958 21855 master.cpp:679] Received reply for offer 201203290030-0-728
I0329 00:37:07.770165 21855 master.cpp:1403] Filtered slave 201203290030-0-1 for framework 201203290030-0-0000 for 1 seconds
I0329 00:37:07.770644 21855 master.cpp:679] Received reply for offer 201203290030-0-729
I0329 00:37:07.770879 21855 master.cpp:1403] Filtered slave 201203290030-0-0 for framework 201203290030-0-0001 for 1 seconds
I0329 00:37:08.770742 21855 master.cpp:1184] Sending 1 offers to framework 201203290030-0-0000
I0329 00:37:08.770946 21855 master.cpp:1184] Sending 1 offers to framework 201203290030-0-0001
I0329 00:37:08.772425 21855 master.cpp:679] Received reply for offer 201203290030-0-730
I0329 00:37:08.772573 21855 master.cpp:1403] Filtered slave 201203290030-0-0 for framework 201203290030-0-0000 for 1 seconds
I0329 00:37:08.772948 21855 master.cpp:679] Received reply for offer 201203290030-0-731
I0329 00:37:08.773090 21855 master.cpp:1403] Filtered slave 201203290030-0-1 for framework 201203290030-0-0001 for 1 seconds
I0329 00:37:09.772637 21855 master.cpp:1184] Sending 1 offers to framework 201203290030-0-0000
I0329 00:37:09.772855 21855 master.cpp:1184] Sending 1 offers to framework 201203290030-0-0001
I0329 00:37:09.774340 21855 master.cpp:679] Received reply for offer 201203290030-0-732
I0329 00:37:09.774498 21855 master.cpp:1403] Filtered slave 201203290030-0-1 for framework 201203290030-0-0000 for 1 seconds
I0329 00:37:09.774809 21855 master.cpp:679] Received reply for offer 201203290030-0-733
I0329 00:37:09.775058 21855 master.cpp:1403] Filtered slave 201203290030-0-0 for framework 201203290030-0-0001 for 1 seconds
I0329 00:37:10.775101 21855 master.cpp:1184] Sending 1 offers to framework 201203290030-0-0000
I0329 00:37:10.775316 21855 master.cpp:1184] Sending 1 offers to framework 201203290030-0-0001
I0329 00:37:10.776833 21855 master.cpp:679] Received reply for offer 201203290030-0-734
I0329 00:37:10.776990 21855 master.cpp:1403] Filtered slave 201203290030-0-0 for framework 201203290030-0-0000 for 1 seconds
I0329 00:37:10.777391 21855 master.cpp:679] Received reply for offer 201203290030-0-735
I0329 00:37:10.777571 21855 master.cpp:1403] Filtered slave 201203290030-0-1 for framework 201203290030-0-0001 for 1 seconds
I0329 00:37:11.777698 21855 master.cpp:1184] Sending 1 offers to framework 201203290030-0-0000
I0329 00:37:11.778090 21855 master.cpp:1184] Sending 1 offers to framework 201203290030-0-0001
I0329 00:37:11.779608 21855 master.cpp:679] Received reply for offer 201203290030-0-736
I0329 00:37:11.831223 21855 master.cpp:1403] Filtered slave 201203290030-0-1 for framework 201203290030-0-0000 for 1 seconds
I0329 00:37:11.864042 21855 master.cpp:679] Received reply for offer 201203290030-0-737
I0329 00:37:11.864464 21855 master.cpp:1403] Filtered slave 201203290030-0-0 for framework 201203290030-0-0001 for 1 seconds
I0329 00:37:12.779922 21855 master.cpp:1184] Sending 1 offers to framework 201203290030-0-0000
I0329 00:37:12.780144 21855 master.cpp:1184] Sending 1 offers to framework 201203290030-0-0001
I0329 00:37:12.781680 21855 master.cpp:679] Received reply for offer 201203290030-0-738
I0329 00:37:12.781883 21855 master.cpp:1403] Filtered slave 201203290030-0-0 for framework 201203290030-0-0000 for 1 seconds
I0329 00:37:12.782047 21855 master.cpp:679] Received reply for offer 201203290030-0-739
I0329 00:37:12.782217 21855 master.cpp:1403] Filtered slave 201203290030-0-1 for framework 201203290030-0-0001 for 1 seconds
I0329 00:37:13.782138 21855 master.cpp:1184] Sending 1 offers to framework 201203290030-0-0000
I0329 00:37:13.782829 21855 master.cpp:1184] Sending 1 offers to framework 201203290030-0-0001
I0329 00:37:13.784075 21855 master.cpp:679] Received reply for offer 201203290030-0-740
I0329 00:37:13.784260 21855 master.cpp:1403] Filtered slave 201203290030-0-1 for framework 201203290030-0-0000 for 1 seconds
I0329 00:37:13.784749 21855 master.cpp:679] Received reply for offer 201203290030-0-741
I0329 00:37:13.784983 21855 master.cpp:1403] Filtered slave 201203290030-0-0 for framework 201203290030-0-0001 for 1 seconds
I0329 00:37:14.784929 21855 master.cpp:1184] Sending 1 offers to framework 201203290030-0-0000
I0329 00:37:14.785143 21855 master.cpp:1184] Sending 1 offers to framework 201203290030-0-0001
I0329 00:37:14.786666 21855 master.cpp:679] Received reply for offer 201203290030-0-742
I0329 00:37:14.786846 21855 master.cpp:1403] Filtered slave 201203290030-0-0 for framework 201203290030-0-0000 for 1 seconds
I0329 00:37:14.787343 21855 master.cpp:679] Received reply for offer 201203290030-0-743
I0329 00:37:14.787534 21855 master.cpp:1403] Filtered slave 201203290030-0-1 for framework 201203290030-0-0001 for 1 seconds
I0329 00:37:15.787451 21855 master.cpp:1184] Sending 1 offers to framework 201203290030-0-0000
I0329 00:37:15.787730 21855 master.cpp:1184] Sending 1 offers to framework 201203290030-0-0001
I0329 00:37:15.789127 21855 master.cpp:679] Received reply for offer 201203290030-0-744
I0329 00:37:15.789309 21855 master.cpp:1403] Filtered slave 201203290030-0-1 for framework 201203290030-0-0000 for 1 seconds
I0329 00:37:15.789705 21855 master.cpp:679] Received reply for offer 201203290030-0-745
I0329 00:37:15.789927 21855 master.cpp:1403] Filtered slave 201203290030-0-0 for framework 201203290030-0-0001 for 1 seconds
I0329 00:37:16.790007 21855 master.cpp:1184] Sending 1 offers to framework 201203290030-0-0000
I0329 00:37:16.790261 21855 master.cpp:1184] Sending 1 offers to framework 201203290030-0-0001
I0329 00:37:16.791760 21855 master.cpp:679] Received reply for offer 201203290030-0-746
I0329 00:37:16.851277 21855 master.cpp:1403] Filtered slave 201203290030-0-0 for framework 201203290030-0-0000 for 1 seconds
I0329 00:37:16.892261 21855 master.cpp:679] Received reply for offer 201203290030-0-747
I0329 00:37:16.892583 21855 master.cpp:1403] Filtered slave 201203290030-0-1 for framework 201203290030-0-0001 for 1 seconds
I0329 00:37:17.792549 21855 master.cpp:1184] Sending 1 offers to framework 201203290030-0-0000
I0329 00:37:17.792826 21855 master.cpp:1184] Sending 1 offers to framework 201203290030-0-0001
I0329 00:37:17.794186 21855 master.cpp:679] Received reply for offer 201203290030-0-748
I0329 00:37:17.794345 21855 master.cpp:1403] Filtered slave 201203290030-0-1 for framework 201203290030-0-0000 for 1 seconds
I0329 00:37:17.794700 21855 master.cpp:679] Received reply for offer 201203290030-0-749
I0329 00:37:17.794858 21855 master.cpp:1403] Filtered slave 201203290030-0-0 for framework 201203290030-0-0001 for 1 seconds
I0329 00:37:18.794909 21855 master.cpp:1184] Sending 1 offers to framework 201203290030-0-0000
I0329 00:37:18.795119 21855 master.cpp:1184] Sending 1 offers to framework 201203290030-0-0001
I0329 00:37:18.796480 21855 master.cpp:679] Received reply for offer 201203290030-0-750
I0329 00:37:18.796658 21855 master.cpp:1403] Filtered slave 201203290030-0-0 for framework 201203290030-0-0000 for 1 seconds
I0329 00:37:18.797011 21855 master.cpp:679] Received reply for offer 201203290030-0-751
I0329 00:37:18.797227 21855 master.cpp:1403] Filtered slave 201203290030-0-1 for framework 201203290030-0-0001 for 1 seconds
I0329 00:37:19.797235 21855 master.cpp:1184] Sending 1 offers to framework 201203290030-0-0000
I0329 00:37:19.797736 21855 master.cpp:1184] Sending 1 offers to framework 201203290030-0-0001
I0329 00:37:19.798979 21855 master.cpp:679] Received reply for offer 201203290030-0-752
I0329 00:37:19.799166 21855 master.cpp:1403] Filtered slave 201203290030-0-1 for framework 201203290030-0-0000 for 1 seconds
I0329 00:37:19.799700 21855 master.cpp:679] Received reply for offer 201203290030-0-753
I0329 00:37:19.799885 21855 master.cpp:1403] Filtered slave 201203290030-0-0 for framework 201203290030-0-0001 for 1 seconds
I0329 00:37:20.799803 21855 master.cpp:1184] Sending 1 offers to framework 201203290030-0-0000
I0329 00:37:20.800292 21855 master.cpp:1184] Sending 1 offers to framework 201203290030-0-0001
I0329 00:37:20.801651 21855 master.cpp:679] Received reply for offer 201203290030-0-754
I0329 00:37:20.801832 21855 master.cpp:1403] Filtered slave 201203290030-0-0 for framework 201203290030-0-0000 for 1 seconds
I0329 00:37:20.802280 21855 master.cpp:679] Received reply for offer 201203290030-0-755
I0329 00:37:20.802438 21855 master.cpp:1403] Filtered slave 201203290030-0-1 for framework 201203290030-0-0001 for 1 seconds
I0329 00:37:21.802552 21855 master.cpp:1184] Sending 1 offers to framework 201203290030-0-0000
I0329 00:37:21.802953 21855 master.cpp:1184] Sending 1 offers to framework 201203290030-0-0001
I0329 00:37:21.804293 21855 master.cpp:679] Received reply for offer 201203290030-0-756
I0329 00:37:21.854771 21855 master.cpp:1403] Filtered slave 201203290030-0-1 for framework 201203290030-0-0000 for 1 seconds
I0329 00:37:21.895617 21855 master.cpp:679] Received reply for offer 201203290030-0-757
I0329 00:37:21.895995 21855 master.cpp:1403] Filtered slave 201203290030-0-0 for framework 201203290030-0-0001 for 1 seconds
I0329 00:37:22.805240 21855 master.cpp:1184] Sending 1 offers to framework 201203290030-0-0000
I0329 00:37:22.805464 21855 master.cpp:1184] Sending 1 offers to framework 201203290030-0-0001
I0329 00:37:22.806936 21855 master.cpp:679] Received reply for offer 201203290030-0-758
I0329 00:37:22.807127 21855 master.cpp:1403] Filtered slave 201203290030-0-0 for framework 201203290030-0-0000 for 1 seconds
I0329 00:37:22.807368 21855 master.cpp:679] Received reply for offer 201203290030-0-759
I0329 00:37:22.807548 21855 master.cpp:1403] Filtered slave 201203290030-0-1 for framework 201203290030-0-0001 for 1 seconds
I0329 00:37:23.807710 21855 master.cpp:1184] Sending 1 offers to framework 201203290030-0-0000
I0329 00:37:23.808192 21855 master.cpp:1184] Sending 1 offers to framework 201203290030-0-0001
I0329 00:37:23.809489 21855 master.cpp:679] Received reply for offer 201203290030-0-760
I0329 00:37:23.809672 21855 master.cpp:1403] Filtered slave 201203290030-0-1 for framework 201203290030-0-0000 for 1 seconds
I0329 00:37:23.810106 21855 master.cpp:679] Received reply for offer 201203290030-0-761
I0329 00:37:23.810339 21855 master.cpp:1403] Filtered slave 201203290030-0-0 for framework 201203290030-0-0001 for 1 seconds
I0329 00:37:24.810353 21855 master.cpp:1184] Sending 1 offers to framework 201203290030-0-0000
I0329 00:37:24.810583 21855 master.cpp:1184] Sending 1 offers to framework 201203290030-0-0001
I0329 00:37:24.812131 21855 master.cpp:679] Received reply for offer 201203290030-0-762
I0329 00:37:24.812289 21855 master.cpp:1403] Filtered slave 201203290030-0-0 for framework 201203290030-0-0000 for 1 seconds
I0329 00:37:24.812659 21855 master.cpp:679] Received reply for offer 201203290030-0-763
I0329 00:37:24.812908 21855 master.cpp:1403] Filtered slave 201203290030-0-1 for framework 201203290030-0-0001 for 1 seconds
I0329 00:37:25.812968 21855 master.cpp:1184] Sending 1 offers to framework 201203290030-0-0000
I0329 00:37:25.813192 21855 master.cpp:1184] Sending 1 offers to framework 201203290030-0-0001
I0329 00:37:25.814667 21855 master.cpp:679] Received reply for offer 201203290030-0-764
I0329 00:37:25.814826 21855 master.cpp:1403] Filtered slave 201203290030-0-1 for framework 201203290030-0-0000 for 1 seconds
I0329 00:37:25.815215 21855 master.cpp:679] Received reply for offer 201203290030-0-765
I0329 00:37:25.815398 21855 master.cpp:1403] Filtered slave 201203290030-0-0 for framework 201203290030-0-0001 for 1 seconds
I0329 00:37:26.815498 21855 master.cpp:1184] Sending 1 offers to framework 201203290030-0-0000
I0329 00:37:26.815752 21855 master.cpp:1184] Sending 1 offers to framework 201203290030-0-0001
I0329 00:37:26.817405 21855 master.cpp:679] Received reply for offer 201203290030-0-766
I0329 00:37:26.865818 21855 master.cpp:1403] Filtered slave 201203290030-0-0 for framework 201203290030-0-0000 for 1 seconds
I0329 00:37:26.907840 21855 master.cpp:679] Received reply for offer 201203290030-0-767
I0329 00:37:26.908277 21855 master.cpp:1403] Filtered slave 201203290030-0-1 for framework 201203290030-0-0001 for 1 seconds
I0329 00:37:27.818299 21855 master.cpp:1184] Sending 1 offers to framework 201203290030-0-0000
I0329 00:37:27.818522 21855 master.cpp:1184] Sending 1 offers to framework 201203290030-0-0001
I0329 00:37:27.819972 21855 master.cpp:679] Received reply for offer 201203290030-0-768
I0329 00:37:27.820130 21855 master.cpp:1403] Filtered slave 201203290030-0-1 for framework 201203290030-0-0000 for 1 seconds
I0329 00:37:27.820526 21855 master.cpp:679] Received reply for offer 201203290030-0-769
I0329 00:37:27.820708 21855 master.cpp:1403] Filtered slave 201203290030-0-0 for framework 201203290030-0-0001 for 1 seconds
I0329 00:37:28.820381 21855 master.cpp:1184] Sending 1 offers to framework 201203290030-0-0000
I0329 00:37:28.820638 21855 master.cpp:1184] Sending 1 offers to framework 201203290030-0-0001
I0329 00:37:28.822115 21855 master.cpp:679] Received reply for offer 201203290030-0-770
I0329 00:37:28.822271 21855 master.cpp:1403] Filtered slave 201203290030-0-0 for framework 201203290030-0-0000 for 1 seconds
I0329 00:37:28.822664 21855 master.cpp:679] Received reply for offer 201203290030-0-771
I0329 00:37:28.822830 21855 master.cpp:1403] Filtered slave 201203290030-0-1 for framework 201203290030-0-0001 for 1 seconds
I0329 00:37:29.822737 21855 master.cpp:1184] Sending 1 offers to framework 201203290030-0-0000
I0329 00:37:29.822968 21855 master.cpp:1184] Sending 1 offers to framework 201203290030-0-0001
I0329 00:37:29.824473 21855 master.cpp:679] Received reply for offer 201203290030-0-772
I0329 00:37:29.824633 21855 master.cpp:1403] Filtered slave 201203290030-0-1 for framework 201203290030-0-0000 for 1 seconds
I0329 00:37:29.825001 21855 master.cpp:679] Received reply for offer 201203290030-0-773
I0329 00:37:29.825182 21855 master.cpp:1403] Filtered slave 201203290030-0-0 for framework 201203290030-0-0001 for 1 seconds
I0329 00:37:30.825336 21855 master.cpp:1184] Sending 1 offers to framework 201203290030-0-0000
I0329 00:37:30.825525 21855 master.cpp:1184] Sending 1 offers to framework 201203290030-0-0001
I0329 00:37:30.827106 21855 master.cpp:679] Received reply for offer 201203290030-0-774
I0329 00:37:30.827261 21855 master.cpp:1403] Filtered slave 201203290030-0-0 for framework 201203290030-0-0000 for 1 seconds
I0329 00:37:30.827685 21855 master.cpp:679] Received reply for offer 201203290030-0-775
I0329 00:37:30.827858 21855 master.cpp:1403] Filtered slave 201203290030-0-1 for framework 201203290030-0-0001 for 1 seconds
I0329 00:37:31.827991 21855 master.cpp:1184] Sending 1 offers to framework 201203290030-0-0000
I0329 00:37:31.828158 21855 master.cpp:1184] Sending 1 offers to framework 201203290030-0-0001
I0329 00:37:31.829650 21855 master.cpp:679] Received reply for offer 201203290030-0-776
I0329 00:37:31.869235 21855 master.cpp:1403] Filtered slave 201203290030-0-1 for framework 201203290030-0-0000 for 1 seconds
I0329 00:37:31.903025 21855 master.cpp:679] Received reply for offer 201203290030-0-777
I0329 00:37:31.903527 21855 master.cpp:1403] Filtered slave 201203290030-0-0 for framework 201203290030-0-0001 for 1 seconds
I0329 00:37:32.830765 21855 master.cpp:1184] Sending 1 offers to framework 201203290030-0-0000
I0329 00:37:32.830978 21855 master.cpp:1184] Sending 1 offers to framework 201203290030-0-0001
I0329 00:37:32.832401 21855 master.cpp:679] Received reply for offer 201203290030-0-778
I0329 00:37:32.832568 21855 master.cpp:1403] Filtered slave 201203290030-0-0 for framework 201203290030-0-0000 for 1 seconds
I0329 00:37:32.832917 21855 master.cpp:679] Received reply for offer 201203290030-0-779
I0329 00:37:32.833091 21855 master.cpp:1403] Filtered slave 201203290030-0-1 for framework 201203290030-0-0001 for 1 seconds
I0329 00:37:33.833111 21855 master.cpp:1184] Sending 1 offers to framework 201203290030-0-0000
I0329 00:37:33.833319 21855 master.cpp:1184] Sending 1 offers to framework 201203290030-0-0001
I0329 00:37:33.834683 21855 master.cpp:679] Received reply for offer 201203290030-0-780
I0329 00:37:33.834851 21855 master.cpp:1403] Filtered slave 201203290030-0-1 for framework 201203290030-0-0000 for 1 seconds
I0329 00:37:33.835052 21855 master.cpp:679] Received reply for offer 201203290030-0-781
I0329 00:37:33.835228 21855 master.cpp:1403] Filtered slave 201203290030-0-0 for framework 201203290030-0-0001 for 1 seconds
I0329 00:37:34.835283 21855 master.cpp:1184] Sending 1 offers to framework 201203290030-0-0000
I0329 00:37:34.835494 21855 master.cpp:1184] Sending 1 offers to framework 201203290030-0-0001
I0329 00:37:34.836915 21855 master.cpp:679] Received reply for offer 201203290030-0-782
I0329 00:37:34.837059 21855 master.cpp:1403] Filtered slave 201203290030-0-0 for framework 201203290030-0-0000 for 1 seconds
I0329 00:37:34.837308 21855 master.cpp:679] Received reply for offer 201203290030-0-783
I0329 00:37:34.837486 21855 master.cpp:1403] Filtered slave 201203290030-0-1 for framework 201203290030-0-0001 for 1 seconds
I0329 00:37:35.837530 21855 master.cpp:1184] Sending 1 offers to framework 201203290030-0-0000
I0329 00:37:35.837740 21855 master.cpp:1184] Sending 1 offers to framework 201203290030-0-0001
I0329 00:37:35.839201 21855 master.cpp:679] Received reply for offer 201203290030-0-784
I0329 00:37:35.839371 21855 master.cpp:1403] Filtered slave 201203290030-0-1 for framework 201203290030-0-0000 for 1 seconds
I0329 00:37:35.839877 21855 master.cpp:679] Received reply for offer 201203290030-0-785
I0329 00:37:35.840050 21855 master.cpp:1403] Filtered slave 201203290030-0-0 for framework 201203290030-0-0001 for 1 seconds
I0329 00:37:36.840018 21855 master.cpp:1184] Sending 1 offers to framework 201203290030-0-0000
I0329 00:37:36.840178 21855 master.cpp:1184] Sending 1 offers to framework 201203290030-0-0001
I0329 00:37:36.841604 21855 master.cpp:679] Received reply for offer 201203290030-0-786
I0329 00:37:36.889246 21855 master.cpp:1403] Filtered slave 201203290030-0-0 for framework 201203290030-0-0000 for 1 seconds
I0329 00:37:36.931670 21855 master.cpp:679] Received reply for offer 201203290030-0-787
I0329 00:37:36.932104 21855 master.cpp:1403] Filtered slave 201203290030-0-1 for framework 201203290030-0-0001 for 1 seconds
I0329 00:37:37.842377 21855 master.cpp:1184] Sending 1 offers to framework 201203290030-0-0000
I0329 00:37:37.842576 21855 master.cpp:1184] Sending 1 offers to framework 201203290030-0-0001
I0329 00:37:37.843955 21855 master.cpp:679] Received reply for offer 201203290030-0-788
I0329 00:37:37.844116 21855 master.cpp:1403] Filtered slave 201203290030-0-1 for framework 201203290030-0-0000 for 1 seconds
I0329 00:37:37.844341 21855 master.cpp:679] Received reply for offer 201203290030-0-789
I0329 00:37:37.844501 21855 master.cpp:1403] Filtered slave 201203290030-0-0 for framework 201203290030-0-0001 for 1 seconds
I0329 00:37:38.844563 21855 master.cpp:1184] Sending 1 offers to framework 201203290030-0-0000
I0329 00:37:38.844771 21855 master.cpp:1184] Sending 1 offers to framework 201203290030-0-0001
I0329 00:37:38.846222 21855 master.cpp:679] Received reply for offer 201203290030-0-790
I0329 00:37:38.846365 21855 master.cpp:1403] Filtered slave 201203290030-0-0 for framework 201203290030-0-0000 for 1 seconds
I0329 00:37:38.846753 21855 master.cpp:679] Received reply for offer 201203290030-0-791
I0329 00:37:38.846935 21855 master.cpp:1403] Filtered slave 201203290030-0-1 for framework 201203290030-0-0001 for 1 seconds
I0329 00:37:39.847059 21855 master.cpp:1184] Sending 1 offers to framework 201203290030-0-0000
I0329 00:37:39.847504 21855 master.cpp:1184] Sending 1 offers to framework 201203290030-0-0001
I0329 00:37:39.848858 21855 master.cpp:679] Received reply for offer 201203290030-0-792
I0329 00:37:39.849046 21855 master.cpp:1403] Filtered slave 201203290030-0-1 for framework 201203290030-0-0000 for 1 seconds
I0329 00:37:39.849501 21855 master.cpp:679] Received reply for offer 201203290030-0-793
I0329 00:37:39.849728 21855 master.cpp:1403] Filtered slave 201203290030-0-0 for framework 201203290030-0-0001 for 1 seconds
I0329 00:37:40.849683 21855 master.cpp:1184] Sending 1 offers to framework 201203290030-0-0000
I0329 00:37:40.849908 21855 master.cpp:1184] Sending 1 offers to framework 201203290030-0-0001
I0329 00:37:40.851452 21855 master.cpp:679] Received reply for offer 201203290030-0-794
I0329 00:37:40.851636 21855 master.cpp:1403] Filtered slave 201203290030-0-0 for framework 201203290030-0-0000 for 1 seconds
I0329 00:37:40.852167 21855 master.cpp:679] Received reply for offer 201203290030-0-795
I0329 00:37:40.852357 21855 master.cpp:1403] Filtered slave 201203290030-0-1 for framework 201203290030-0-0001 for 1 seconds
I0329 00:37:41.852282 21855 master.cpp:1184] Sending 1 offers to framework 201203290030-0-0000
I0329 00:37:41.852514 21855 master.cpp:1184] Sending 1 offers to framework 201203290030-0-0001
I0329 00:37:41.853988 21855 master.cpp:679] Received reply for offer 201203290030-0-796
I0329 00:37:41.901064 21855 master.cpp:1403] Filtered slave 201203290030-0-1 for framework 201203290030-0-0000 for 1 seconds
I0329 00:37:41.943431 21855 master.cpp:679] Received reply for offer 201203290030-0-797
I0329 00:37:41.943706 21855 master.cpp:1403] Filtered slave 201203290030-0-0 for framework 201203290030-0-0001 for 1 seconds
I0329 00:37:42.854884 21855 master.cpp:1184] Sending 1 offers to framework 201203290030-0-0000
I0329 00:37:42.855381 21855 master.cpp:1184] Sending 1 offers to framework 201203290030-0-0001
I0329 00:37:42.856585 21855 master.cpp:679] Received reply for offer 201203290030-0-798
I0329 00:37:42.856741 21855 master.cpp:1403] Filtered slave 201203290030-0-0 for framework 201203290030-0-0000 for 1 seconds
I0329 00:37:42.857216 21855 master.cpp:679] Received reply for offer 201203290030-0-799
I0329 00:37:42.857445 21855 master.cpp:1403] Filtered slave 201203290030-0-1 for framework 201203290030-0-0001 for 1 seconds
I0329 00:37:43.856986 21855 master.cpp:1184] Sending 1 offers to framework 201203290030-0-0000
I0329 00:37:43.857214 21855 master.cpp:1184] Sending 1 offers to framework 201203290030-0-0001
I0329 00:37:43.858700 21855 master.cpp:679] Received reply for offer 201203290030-0-800
I0329 00:37:43.858880 21855 master.cpp:1403] Filtered slave 201203290030-0-1 for framework 201203290030-0-0000 for 1 seconds
I0329 00:37:43.859252 21855 master.cpp:679] Received reply for offer 201203290030-0-801
I0329 00:37:43.859432 21855 master.cpp:1403] Filtered slave 201203290030-0-0 for framework 201203290030-0-0001 for 1 seconds
I0329 00:37:44.859565 21855 master.cpp:1184] Sending 1 offers to framework 201203290030-0-0000
I0329 00:37:44.859793 21855 master.cpp:1184] Sending 1 offers to framework 201203290030-0-0001
I0329 00:37:44.861314 21855 master.cpp:679] Received reply for offer 201203290030-0-802
I0329 00:37:44.861470 21855 master.cpp:1403] Filtered slave 201203290030-0-0 for framework 201203290030-0-0000 for 1 seconds
I0329 00:37:44.861948 21855 master.cpp:679] Received reply for offer 201203290030-0-803
I0329 00:37:44.862220 21855 master.cpp:1403] Filtered slave 201203290030-0-1 for framework 201203290030-0-0001 for 1 seconds
I0329 00:37:45.861846 21855 master.cpp:1184] Sending 1 offers to framework 201203290030-0-0000
I0329 00:37:45.862082 21855 master.cpp:1184] Sending 1 offers to framework 201203290030-0-0001
I0329 00:37:45.863678 21855 master.cpp:679] Received reply for offer 201203290030-0-804
I0329 00:37:45.863864 21855 master.cpp:1403] Filtered slave 201203290030-0-1 for framework 201203290030-0-0000 for 1 seconds
I0329 00:37:45.864233 21855 master.cpp:679] Received reply for offer 201203290030-0-805
I0329 00:37:45.864492 21855 master.cpp:1403] Filtered slave 201203290030-0-0 for framework 201203290030-0-0001 for 1 seconds
I0329 00:37:46.864509 21855 master.cpp:1184] Sending 1 offers to framework 201203290030-0-0000
I0329 00:37:46.864724 21855 master.cpp:1184] Sending 1 offers to framework 201203290030-0-0001
I0329 00:37:46.866288 21855 master.cpp:679] Received reply for offer 201203290030-0-806
I0329 00:37:46.922067 21855 master.cpp:1403] Filtered slave 201203290030-0-0 for framework 201203290030-0-0000 for 1 seconds
I0329 00:37:46.962239 21855 master.cpp:679] Received reply for offer 201203290030-0-807
I0329 00:37:46.962625 21855 master.cpp:1403] Filtered slave 201203290030-0-1 for framework 201203290030-0-0001 for 1 seconds
I0329 00:37:47.866832 21855 master.cpp:1184] Sending 1 offers to framework 201203290030-0-0000
I0329 00:37:47.867041 21855 master.cpp:1184] Sending 1 offers to framework 201203290030-0-0001
I0329 00:37:47.868408 21855 master.cpp:679] Received reply for offer 201203290030-0-808
I0329 00:37:47.868566 21855 master.cpp:1403] Filtered slave 201203290030-0-1 for framework 201203290030-0-0000 for 1 seconds
I0329 00:37:47.868934 21855 master.cpp:679] Received reply for offer 201203290030-0-809
I0329 00:37:47.869093 21855 master.cpp:1403] Filtered slave 201203290030-0-0 for framework 201203290030-0-0001 for 1 seconds
I0329 00:37:48.869148 21855 master.cpp:1184] Sending 1 offers to framework 201203290030-0-0000
I0329 00:37:48.869465 21855 master.cpp:1184] Sending 1 offers to framework 201203290030-0-0001
I0329 00:37:48.870767 21855 master.cpp:679] Received reply for offer 201203290030-0-810
I0329 00:37:48.870913 21855 master.cpp:1403] Filtered slave 201203290030-0-0 for framework 201203290030-0-0000 for 1 seconds
I0329 00:37:48.871384 21855 master.cpp:679] Received reply for offer 201203290030-0-811
I0329 00:37:48.871536 21855 master.cpp:1403] Filtered slave 201203290030-0-1 for framework 201203290030-0-0001 for 1 seconds
I0329 00:37:49.871647 21855 master.cpp:1184] Sending 1 offers to framework 201203290030-0-0000
I0329 00:37:49.871830 21855 master.cpp:1184] Sending 1 offers to framework 201203290030-0-0001
I0329 00:37:49.873322 21855 master.cpp:679] Received reply for offer 201203290030-0-812
I0329 00:37:49.873471 21855 master.cpp:1403] Filtered slave 201203290030-0-1 for framework 201203290030-0-0000 for 1 seconds
I0329 00:37:49.873855 21855 master.cpp:679] Received reply for offer 201203290030-0-813
I0329 00:37:49.874022 21855 master.cpp:1403] Filtered slave 201203290030-0-0 for framework 201203290030-0-0001 for 1 seconds
I0329 00:37:50.874146 21855 master.cpp:1184] Sending 1 offers to framework 201203290030-0-0000
I0329 00:37:50.874476 21855 master.cpp:1184] Sending 1 offers to framework 201203290030-0-0001
I0329 00:37:50.875928 21855 master.cpp:679] Received reply for offer 201203290030-0-814
I0329 00:37:50.876077 21855 master.cpp:1403] Filtered slave 201203290030-0-0 for framework 201203290030-0-0000 for 1 seconds
I0329 00:37:50.876489 21855 master.cpp:679] Received reply for offer 201203290030-0-815
I0329 00:37:50.876646 21855 master.cpp:1403] Filtered slave 201203290030-0-1 for framework 201203290030-0-0001 for 1 seconds
I0329 00:37:51.876756 21855 master.cpp:1184] Sending 1 offers to framework 201203290030-0-0000
I0329 00:37:51.876981 21855 master.cpp:1184] Sending 1 offers to framework 201203290030-0-0001
I0329 00:37:51.878424 21855 master.cpp:679] Received reply for offer 201203290030-0-816
I0329 00:37:51.942322 21855 master.cpp:1403] Filtered slave 201203290030-0-1 for framework 201203290030-0-0000 for 1 seconds
I0329 00:37:51.982213 21855 master.cpp:679] Received reply for offer 201203290030-0-817
I0329 00:37:51.982523 21855 master.cpp:1403] Filtered slave 201203290030-0-0 for framework 201203290030-0-0001 for 1 seconds
I0329 00:37:52.879252 21855 master.cpp:1184] Sending 1 offers to framework 201203290030-0-0000
I0329 00:37:52.879464 21855 master.cpp:1184] Sending 1 offers to framework 201203290030-0-0001
I0329 00:37:52.880920 21855 master.cpp:679] Received reply for offer 201203290030-0-818
I0329 00:37:52.881068 21855 master.cpp:1403] Filtered slave 201203290030-0-0 for framework 201203290030-0-0000 for 1 seconds
I0329 00:37:52.881461 21855 master.cpp:679] Received reply for offer 201203290030-0-819
I0329 00:37:52.881629 21855 master.cpp:1403] Filtered slave 201203290030-0-1 for framework 201203290030-0-0001 for 1 seconds
I0329 00:37:53.881753 21855 master.cpp:1184] Sending 1 offers to framework 201203290030-0-0000
I0329 00:37:53.881938 21855 master.cpp:1184] Sending 1 offers to framework 201203290030-0-0001
I0329 00:37:53.883545 21855 master.cpp:679] Received reply for offer 201203290030-0-820
I0329 00:37:53.883697 21855 master.cpp:1403] Filtered slave 201203290030-0-1 for framework 201203290030-0-0000 for 1 seconds
I0329 00:37:53.884055 21855 master.cpp:679] Received reply for offer 201203290030-0-821
I0329 00:37:53.884230 21855 master.cpp:1403] Filtered slave 201203290030-0-0 for framework 201203290030-0-0001 for 1 seconds
I0329 00:37:54.884340 21855 master.cpp:1184] Sending 1 offers to framework 201203290030-0-0000
I0329 00:37:54.884527 21855 master.cpp:1184] Sending 1 offers to framework 201203290030-0-0001
I0329 00:37:54.886034 21855 master.cpp:679] Received reply for offer 201203290030-0-822
I0329 00:37:54.886180 21855 master.cpp:1403] Filtered slave 201203290030-0-0 for framework 201203290030-0-0000 for 1 seconds
I0329 00:37:54.886589 21855 master.cpp:679] Received reply for offer 201203290030-0-823
I0329 00:37:54.886766 21855 master.cpp:1403] Filtered slave 201203290030-0-1 for framework 201203290030-0-0001 for 1 seconds
I0329 00:37:55.886850 21855 master.cpp:1184] Sending 1 offers to framework 201203290030-0-0000
I0329 00:37:55.887034 21855 master.cpp:1184] Sending 1 offers to framework 201203290030-0-0001
I0329 00:37:55.888500 21855 master.cpp:679] Received reply for offer 201203290030-0-824
I0329 00:37:55.888671 21855 master.cpp:1403] Filtered slave 201203290030-0-1 for framework 201203290030-0-0000 for 1 seconds
I0329 00:37:55.889020 21855 master.cpp:679] Received reply for offer 201203290030-0-825
I0329 00:37:55.889188 21855 master.cpp:1403] Filtered slave 201203290030-0-0 for framework 201203290030-0-0001 for 1 seconds
I0329 00:37:56.889339 21855 master.cpp:1184] Sending 1 offers to framework 201203290030-0-0000
I0329 00:37:56.889497 21855 master.cpp:1184] Sending 1 offers to framework 201203290030-0-0001
I0329 00:37:56.890959 21855 master.cpp:679] Received reply for offer 201203290030-0-826
I0329 00:37:56.954104 21855 master.cpp:1403] Filtered slave 201203290030-0-0 for framework 201203290030-0-0000 for 1 seconds
I0329 00:37:56.985548 21855 master.cpp:679] Received reply for offer 201203290030-0-827
I0329 00:37:56.985939 21855 master.cpp:1403] Filtered slave 201203290030-0-1 for framework 201203290030-0-0001 for 1 seconds
I0329 00:37:57.891891 21855 master.cpp:1184] Sending 1 offers to framework 201203290030-0-0000
I0329 00:37:57.892112 21855 master.cpp:1184] Sending 1 offers to framework 201203290030-0-0001
I0329 00:37:57.893573 21855 master.cpp:679] Received reply for offer 201203290030-0-828
I0329 00:37:57.893735 21855 master.cpp:1403] Filtered slave 201203290030-0-1 for framework 201203290030-0-0000 for 1 seconds
I0329 00:37:57.894104 21855 master.cpp:679] Received reply for offer 201203290030-0-829
I0329 00:37:57.894270 21855 master.cpp:1403] Filtered slave 201203290030-0-0 for framework 201203290030-0-0001 for 1 seconds
I0329 00:37:58.893165 21855 master.cpp:1184] Sending 1 offers to framework 201203290030-0-0000
I0329 00:37:58.893348 21855 master.cpp:1184] Sending 1 offers to framework 201203290030-0-0001
I0329 00:37:58.894840 21855 master.cpp:679] Received reply for offer 201203290030-0-830
I0329 00:37:58.895009 21855 master.cpp:1403] Filtered slave 201203290030-0-0 for framework 201203290030-0-0000 for 1 seconds
I0329 00:37:58.895270 21855 master.cpp:679] Received reply for offer 201203290030-0-831
I0329 00:37:58.895438 21855 master.cpp:1403] Filtered slave 201203290030-0-1 for framework 201203290030-0-0001 for 1 seconds
I0329 00:37:59.895606 21855 master.cpp:1184] Sending 1 offers to framework 201203290030-0-0000
I0329 00:37:59.895791 21855 master.cpp:1184] Sending 1 offers to framework 201203290030-0-0001
I0329 00:37:59.897272 21855 master.cpp:679] Received reply for offer 201203290030-0-832
I0329 00:37:59.897444 21855 master.cpp:1403] Filtered slave 201203290030-0-1 for framework 201203290030-0-0000 for 1 seconds
I0329 00:37:59.897816 21855 master.cpp:679] Received reply for offer 201203290030-0-833
I0329 00:37:59.897984 21855 master.cpp:1403] Filtered slave 201203290030-0-0 for framework 201203290030-0-0001 for 1 seconds
I0329 00:38:00.897220 21855 master.cpp:1184] Sending 1 offers to framework 201203290030-0-0000
I0329 00:38:00.897414 21855 master.cpp:1184] Sending 1 offers to framework 201203290030-0-0001
I0329 00:38:00.898960 21855 master.cpp:679] Received reply for offer 201203290030-0-834
I0329 00:38:00.899117 21855 master.cpp:1403] Filtered slave 201203290030-0-0 for framework 201203290030-0-0000 for 1 seconds
I0329 00:38:00.899422 21855 master.cpp:679] Received reply for offer 201203290030-0-835
I0329 00:38:00.899588 21855 master.cpp:1403] Filtered slave 201203290030-0-1 for framework 201203290030-0-0001 for 1 seconds
I0329 00:38:01.899765 21855 master.cpp:1184] Sending 1 offers to framework 201203290030-0-0000
I0329 00:38:01.899946 21855 master.cpp:1184] Sending 1 offers to framework 201203290030-0-0001
I0329 00:38:01.901394 21855 master.cpp:679] Received reply for offer 201203290030-0-836
I0329 00:38:01.901599 21855 master.cpp:1403] Filtered slave 201203290030-0-1 for framework 201203290030-0-0000 for 1 seconds
I0329 00:38:01.902027 21855 master.cpp:679] Received reply for offer 201203290030-0-837
I0329 00:38:01.902442 21855 master.cpp:1403] Filtered slave 201203290030-0-0 for framework 201203290030-0-0001 for 1 seconds
I0329 00:38:02.902104 21855 master.cpp:1184] Sending 1 offers to framework 201203290030-0-0000
I0329 00:38:02.902324 21855 master.cpp:1184] Sending 1 offers to framework 201203290030-0-0001
I0329 00:38:02.903723 21855 master.cpp:679] Received reply for offer 201203290030-0-838
I0329 00:38:02.903895 21855 master.cpp:1403] Filtered slave 201203290030-0-0 for framework 201203290030-0-0000 for 1 seconds
I0329 00:38:02.904109 21855 master.cpp:679] Received reply for offer 201203290030-0-839
I0329 00:38:02.904275 21855 master.cpp:1403] Filtered slave 201203290030-0-1 for framework 201203290030-0-0001 for 1 seconds
I0329 00:38:03.903291 21855 master.cpp:1184] Sending 1 offers to framework 201203290030-0-0000
I0329 00:38:03.903516 21855 master.cpp:1184] Sending 1 offers to framework 201203290030-0-0001
I0329 00:38:03.904928 21855 master.cpp:679] Received reply for offer 201203290030-0-840
I0329 00:38:03.905098 21855 master.cpp:1403] Filtered slave 201203290030-0-1 for framework 201203290030-0-0000 for 1 seconds
I0329 00:38:03.905292 21855 master.cpp:679] Received reply for offer 201203290030-0-841
I0329 00:38:03.905454 21855 master.cpp:1403] Filtered slave 201203290030-0-0 for framework 201203290030-0-0001 for 1 seconds
I0329 00:38:04.905469 21855 master.cpp:1184] Sending 1 offers to framework 201203290030-0-0000
I0329 00:38:04.905670 21855 master.cpp:1184] Sending 1 offers to framework 201203290030-0-0001
I0329 00:38:04.907161 21855 master.cpp:679] Received reply for offer 201203290030-0-842
I0329 00:38:04.907332 21855 master.cpp:1403] Filtered slave 201203290030-0-0 for framework 201203290030-0-0000 for 1 seconds
I0329 00:38:04.907500 21855 master.cpp:679] Received reply for offer 201203290030-0-843
I0329 00:38:04.907661 21855 master.cpp:1403] Filtered slave 201203290030-0-1 for framework 201203290030-0-0001 for 1 seconds
I0329 00:38:05.907354 21855 master.cpp:1184] Sending 1 offers to framework 201203290030-0-0000
I0329 00:38:05.907601 21855 master.cpp:1184] Sending 1 offers to framework 201203290030-0-0001
I0329 00:38:05.909211 21855 master.cpp:679] Received reply for offer 201203290030-0-844
I0329 00:38:05.909337 21855 master.cpp:1403] Filtered slave 201203290030-0-1 for framework 201203290030-0-0000 for 1 seconds
I0329 00:38:05.968431 21855 master.cpp:679] Received reply for offer 201203290030-0-845
I0329 00:38:06.003870 21855 master.cpp:1403] Filtered slave 201203290030-0-0 for framework 201203290030-0-0001 for 1 seconds
I0329 00:38:06.909821 21855 master.cpp:1184] Sending 1 offers to framework 201203290030-0-0000
I0329 00:38:06.910017 21855 master.cpp:1184] Sending 1 offers to framework 201203290030-0-0001
I0329 00:38:06.911409 21855 master.cpp:679] Received reply for offer 201203290030-0-846
I0329 00:38:06.911568 21855 master.cpp:1403] Filtered slave 201203290030-0-0 for framework 201203290030-0-0000 for 1 seconds
I0329 00:38:06.911931 21855 master.cpp:679] Received reply for offer 201203290030-0-847
I0329 00:38:06.912094 21855 master.cpp:1403] Filtered slave 201203290030-0-1 for framework 201203290030-0-0001 for 1 seconds
I0329 00:38:07.912142 21855 master.cpp:1184] Sending 1 offers to framework 201203290030-0-0000
I0329 00:38:07.912413 21855 master.cpp:1184] Sending 1 offers to framework 201203290030-0-0001
I0329 00:38:07.913738 21855 master.cpp:679] Received reply for offer 201203290030-0-848
I0329 00:38:07.913897 21855 master.cpp:1403] Filtered slave 201203290030-0-1 for framework 201203290030-0-0000 for 1 seconds
I0329 00:38:07.914268 21855 master.cpp:679] Received reply for offer 201203290030-0-849
I0329 00:38:07.914432 21855 master.cpp:1403] Filtered slave 201203290030-0-0 for framework 201203290030-0-0001 for 1 seconds
I0329 00:38:08.914345 21855 master.cpp:1184] Sending 1 offers to framework 201203290030-0-0000
I0329 00:38:08.914538 21855 master.cpp:1184] Sending 1 offers to framework 201203290030-0-0001
I0329 00:38:08.915973 21855 master.cpp:679] Received reply for offer 201203290030-0-850
I0329 00:38:08.916131 21855 master.cpp:1403] Filtered slave 201203290030-0-0 for framework 201203290030-0-0000 for 1 seconds
I0329 00:38:08.916365 21855 master.cpp:679] Received reply for offer 201203290030-0-851
I0329 00:38:08.916527 21855 master.cpp:1403] Filtered slave 201203290030-0-1 for framework 201203290030-0-0001 for 1 seconds
I0329 00:38:09.916581 21855 master.cpp:1184] Sending 1 offers to framework 201203290030-0-0000
I0329 00:38:09.916786 21855 master.cpp:1184] Sending 1 offers to framework 201203290030-0-0001
I0329 00:38:09.918206 21855 master.cpp:679] Received reply for offer 201203290030-0-852
I0329 00:38:09.918366 21855 master.cpp:1403] Filtered slave 201203290030-0-1 for framework 201203290030-0-0000 for 1 seconds
I0329 00:38:09.918598 21855 master.cpp:679] Received reply for offer 201203290030-0-853
I0329 00:38:09.918761 21855 master.cpp:1403] Filtered slave 201203290030-0-0 for framework 201203290030-0-0001 for 1 seconds
I0329 00:38:10.918812 21855 master.cpp:1184] Sending 1 offers to framework 201203290030-0-0000
I0329 00:38:10.918972 21855 master.cpp:1184] Sending 1 offers to framework 201203290030-0-0001
I0329 00:38:10.920397 21855 master.cpp:679] Received reply for offer 201203290030-0-854
I0329 00:38:10.974287 21855 master.cpp:1403] Filtered slave 201203290030-0-0 for framework 201203290030-0-0000 for 1 seconds
I0329 00:38:11.004967 21855 master.cpp:679] Received reply for offer 201203290030-0-855
I0329 00:38:11.005354 21855 master.cpp:1403] Filtered slave 201203290030-0-1 for framework 201203290030-0-0001 for 1 seconds
I0329 00:38:11.921069 21855 master.cpp:1184] Sending 1 offers to framework 201203290030-0-0000
I0329 00:38:11.921254 21855 master.cpp:1184] Sending 1 offers to framework 201203290030-0-0001
I0329 00:38:11.922651 21855 master.cpp:679] Received reply for offer 201203290030-0-856
I0329 00:38:11.922811 21855 master.cpp:1403] Filtered slave 201203290030-0-1 for framework 201203290030-0-0000 for 1 seconds
I0329 00:38:11.923051 21855 master.cpp:679] Received reply for offer 201203290030-0-857
I0329 00:38:11.923225 21855 master.cpp:1403] Filtered slave 201203290030-0-0 for framework 201203290030-0-0001 for 1 seconds
I0329 00:38:12.923251 21855 master.cpp:1184] Sending 1 offers to framework 201203290030-0-0000
I0329 00:38:12.923531 21855 master.cpp:1184] Sending 1 offers to framework 201203290030-0-0001
I0329 00:38:12.924984 21855 master.cpp:679] Received reply for offer 201203290030-0-858
I0329 00:38:12.925143 21855 master.cpp:1403] Filtered slave 201203290030-0-0 for framework 201203290030-0-0000 for 1 seconds
I0329 00:38:12.925374 21855 master.cpp:679] Received reply for offer 201203290030-0-859
I0329 00:38:12.925582 21855 master.cpp:1403] Filtered slave 201203290030-0-1 for framework 201203290030-0-0001 for 1 seconds
I0329 00:38:13.925114 21855 master.cpp:1184] Sending 1 offers to framework 201203290030-0-0000
I0329 00:38:13.925305 21855 master.cpp:1184] Sending 1 offers to framework 201203290030-0-0001
I0329 00:38:13.926733 21855 master.cpp:679] Received reply for offer 201203290030-0-860
I0329 00:38:13.926894 21855 master.cpp:1403] Filtered slave 201203290030-0-1 for framework 201203290030-0-0000 for 1 seconds
I0329 00:38:13.927130 21855 master.cpp:679] Received reply for offer 201203290030-0-861
I0329 00:38:13.927294 21855 master.cpp:1403] Filtered slave 201203290030-0-0 for framework 201203290030-0-0001 for 1 seconds
I0329 00:38:14.927331 21855 master.cpp:1184] Sending 1 offers to framework 201203290030-0-0000
I0329 00:38:14.927535 21855 master.cpp:1184] Sending 1 offers to framework 201203290030-0-0001
I0329 00:38:14.928972 21855 master.cpp:679] Received reply for offer 201203290030-0-862
I0329 00:38:14.929128 21855 master.cpp:1403] Filtered slave 201203290030-0-0 for framework 201203290030-0-0000 for 1 seconds
I0329 00:38:14.929342 21855 master.cpp:679] Received reply for offer 201203290030-0-863
I0329 00:38:14.929795 21855 master.cpp:1403] Filtered slave 201203290030-0-1 for framework 201203290030-0-0001 for 1 seconds
I0329 00:38:15.929551 21855 master.cpp:1184] Sending 1 offers to framework 201203290030-0-0000
I0329 00:38:15.929713 21855 master.cpp:1184] Sending 1 offers to framework 201203290030-0-0001
I0329 00:38:15.931108 21855 master.cpp:679] Received reply for offer 201203290030-0-864
I0329 00:38:15.986193 21855 master.cpp:1403] Filtered slave 201203290030-0-1 for framework 201203290030-0-0000 for 1 seconds
I0329 00:38:16.024981 21855 master.cpp:679] Received reply for offer 201203290030-0-865
I0329 00:38:16.025416 21855 master.cpp:1403] Filtered slave 201203290030-0-0 for framework 201203290030-0-0001 for 1 seconds
I0329 00:38:16.931849 21855 master.cpp:1184] Sending 1 offers to framework 201203290030-0-0000
I0329 00:38:16.932117 21855 master.cpp:1184] Sending 1 offers to framework 201203290030-0-0001
I0329 00:38:16.933501 21855 master.cpp:679] Received reply for offer 201203290030-0-866
I0329 00:38:16.933658 21855 master.cpp:1403] Filtered slave 201203290030-0-0 for framework 201203290030-0-0000 for 1 seconds
I0329 00:38:16.933874 21855 master.cpp:679] Received reply for offer 201203290030-0-867
I0329 00:38:16.934089 21855 master.cpp:1403] Filtered slave 201203290030-0-1 for framework 201203290030-0-0001 for 1 seconds
I0329 00:38:17.933884 21855 master.cpp:1184] Sending 1 offers to framework 201203290030-0-0000
I0329 00:38:17.934090 21855 master.cpp:1184] Sending 1 offers to framework 201203290030-0-0001
I0329 00:38:17.935539 21855 master.cpp:679] Received reply for offer 201203290030-0-868
I0329 00:38:17.935700 21855 master.cpp:1403] Filtered slave 201203290030-0-1 for framework 201203290030-0-0000 for 1 seconds
I0329 00:38:17.935920 21855 master.cpp:679] Received reply for offer 201203290030-0-869
I0329 00:38:17.936079 21855 master.cpp:1403] Filtered slave 201203290030-0-0 for framework 201203290030-0-0001 for 1 seconds
I0329 00:38:18.936133 21855 master.cpp:1184] Sending 1 offers to framework 201203290030-0-0000
I0329 00:38:18.936341 21855 master.cpp:1184] Sending 1 offers to framework 201203290030-0-0001
I0329 00:38:18.937778 21855 master.cpp:679] Received reply for offer 201203290030-0-870
I0329 00:38:18.937924 21855 master.cpp:1403] Filtered slave 201203290030-0-0 for framework 201203290030-0-0000 for 1 seconds
I0329 00:38:18.938168 21855 master.cpp:679] Received reply for offer 201203290030-0-871
I0329 00:38:18.938340 21855 master.cpp:1403] Filtered slave 201203290030-0-1 for framework 201203290030-0-0001 for 1 seconds
I0329 00:38:19.938519 21855 master.cpp:1184] Sending 1 offers to framework 201203290030-0-0000
I0329 00:38:19.938737 21855 master.cpp:1184] Sending 1 offers to framework 201203290030-0-0001
I0329 00:38:19.940219 21855 master.cpp:679] Received reply for offer 201203290030-0-872
I0329 00:38:19.940405 21855 master.cpp:1403] Filtered slave 201203290030-0-1 for framework 201203290030-0-0000 for 1 seconds
I0329 00:38:19.940565 21855 master.cpp:679] Received reply for offer 201203290030-0-873
I0329 00:38:19.940790 21855 master.cpp:1403] Filtered slave 201203290030-0-0 for framework 201203290030-0-0001 for 1 seconds
I0329 00:38:20.940903 21855 master.cpp:1184] Sending 1 offers to framework 201203290030-0-0000
I0329 00:38:20.941093 21855 master.cpp:1184] Sending 1 offers to framework 201203290030-0-0001
I0329 00:38:20.942461 21855 master.cpp:679] Received reply for offer 201203290030-0-874
I0329 00:38:20.997920 21855 master.cpp:1403] Filtered slave 201203290030-0-0 for framework 201203290030-0-0000 for 1 seconds
I0329 00:38:21.036581 21855 master.cpp:679] Received reply for offer 201203290030-0-875
I0329 00:38:21.036890 21855 master.cpp:1403] Filtered slave 201203290030-0-1 for framework 201203290030-0-0001 for 1 seconds
I0329 00:38:21.943146 21855 master.cpp:1184] Sending 1 offers to framework 201203290030-0-0000
I0329 00:38:21.943315 21855 master.cpp:1184] Sending 1 offers to framework 201203290030-0-0001
I0329 00:38:21.944773 21855 master.cpp:679] Received reply for offer 201203290030-0-876
I0329 00:38:21.944927 21855 master.cpp:1403] Filtered slave 201203290030-0-1 for framework 201203290030-0-0000 for 1 seconds
I0329 00:38:21.945370 21855 master.cpp:679] Received reply for offer 201203290030-0-877
I0329 00:38:21.945797 21855 master.cpp:1403] Filtered slave 201203290030-0-0 for framework 201203290030-0-0001 for 1 seconds
I0329 00:38:22.945464 21855 master.cpp:1184] Sending 1 offers to framework 201203290030-0-0000
I0329 00:38:22.945794 21855 master.cpp:1184] Sending 1 offers to framework 201203290030-0-0001
I0329 00:38:22.947237 21855 master.cpp:679] Received reply for offer 201203290030-0-878
I0329 00:38:22.947396 21855 master.cpp:1403] Filtered slave 201203290030-0-0 for framework 201203290030-0-0000 for 1 seconds
I0329 00:38:22.947800 21855 master.cpp:679] Received reply for offer 201203290030-0-879
I0329 00:38:22.947983 21855 master.cpp:1403] Filtered slave 201203290030-0-1 for framework 201203290030-0-0001 for 1 seconds
I0329 00:38:23.947988 21855 master.cpp:1184] Sending 1 offers to framework 201203290030-0-0000
I0329 00:38:23.948246 21855 master.cpp:1184] Sending 1 offers to framework 201203290030-0-0001
I0329 00:38:23.949843 21855 master.cpp:679] Received reply for offer 201203290030-0-880
I0329 00:38:23.950003 21855 master.cpp:1403] Filtered slave 201203290030-0-1 for framework 201203290030-0-0000 for 1 seconds
I0329 00:38:23.950372 21855 master.cpp:679] Received reply for offer 201203290030-0-881
I0329 00:38:23.950554 21855 master.cpp:1403] Filtered slave 201203290030-0-0 for framework 201203290030-0-0001 for 1 seconds
I0329 00:38:24.950678 21855 master.cpp:1184] Sending 1 offers to framework 201203290030-0-0000
I0329 00:38:24.950940 21855 master.cpp:1184] Sending 1 offers to framework 201203290030-0-0001
I0329 00:38:24.952628 21855 master.cpp:679] Received reply for offer 201203290030-0-882
I0329 00:38:24.952782 21855 master.cpp:1403] Filtered slave 201203290030-0-0 for framework 201203290030-0-0000 for 1 seconds
I0329 00:38:24.953012 21855 master.cpp:679] Received reply for offer 201203290030-0-883
I0329 00:38:24.953197 21855 master.cpp:1403] Filtered slave 201203290030-0-1 for framework 201203290030-0-0001 for 1 seconds
I0329 00:38:25.953351 21855 master.cpp:1184] Sending 1 offers to framework 201203290030-0-0000
I0329 00:38:25.953573 21855 master.cpp:1184] Sending 1 offers to framework 201203290030-0-0001
I0329 00:38:25.954895 21855 master.cpp:679] Received reply for offer 201203290030-0-884
I0329 00:38:26.009793 21855 master.cpp:1403] Filtered slave 201203290030-0-1 for framework 201203290030-0-0000 for 1 seconds
I0329 00:38:26.048241 21855 master.cpp:679] Received reply for offer 201203290030-0-885
I0329 00:38:26.048691 21855 master.cpp:1403] Filtered slave 201203290030-0-0 for framework 201203290030-0-0001 for 1 seconds
I0329 00:38:26.955626 21855 master.cpp:1184] Sending 1 offers to framework 201203290030-0-0000
I0329 00:38:26.955967 21855 master.cpp:1184] Sending 1 offers to framework 201203290030-0-0001
I0329 00:38:26.957322 21855 master.cpp:679] Received reply for offer 201203290030-0-886
I0329 00:38:26.957507 21855 master.cpp:1403] Filtered slave 201203290030-0-0 for framework 201203290030-0-0000 for 1 seconds
I0329 00:38:26.957875 21855 master.cpp:679] Received reply for offer 201203290030-0-887
I0329 00:38:26.958060 21855 master.cpp:1403] Filtered slave 201203290030-0-1 for framework 201203290030-0-0001 for 1 seconds
I0329 00:38:27.958052 21855 master.cpp:1184] Sending 1 offers to framework 201203290030-0-0000
I0329 00:38:27.958364 21855 master.cpp:1184] Sending 1 offers to framework 201203290030-0-0001
I0329 00:38:27.960037 21855 master.cpp:679] Received reply for offer 201203290030-0-888
I0329 00:38:27.960199 21855 master.cpp:1403] Filtered slave 201203290030-0-1 for framework 201203290030-0-0000 for 1 seconds
I0329 00:38:27.960657 21855 master.cpp:679] Received reply for offer 201203290030-0-889
I0329 00:38:27.960846 21855 master.cpp:1403] Filtered slave 201203290030-0-0 for framework 201203290030-0-0001 for 1 seconds
I0329 00:38:28.960489 21855 master.cpp:1184] Sending 1 offers to framework 201203290030-0-0000
I0329 00:38:28.960886 21855 master.cpp:1184] Sending 1 offers to framework 201203290030-0-0001
I0329 00:38:28.962126 21855 master.cpp:679] Received reply for offer 201203290030-0-890
I0329 00:38:28.962309 21855 master.cpp:1403] Filtered slave 201203290030-0-0 for framework 201203290030-0-0000 for 1 seconds
I0329 00:38:28.962637 21855 master.cpp:679] Received reply for offer 201203290030-0-891
I0329 00:38:28.962898 21855 master.cpp:1403] Filtered slave 201203290030-0-1 for framework 201203290030-0-0001 for 1 seconds
I0329 00:38:29.962928 21855 master.cpp:1184] Sending 1 offers to framework 201203290030-0-0000
I0329 00:38:29.963194 21855 master.cpp:1184] Sending 1 offers to framework 201203290030-0-0001
I0329 00:38:29.964608 21855 master.cpp:679] Received reply for offer 201203290030-0-892
I0329 00:38:29.964769 21855 master.cpp:1403] Filtered slave 201203290030-0-1 for framework 201203290030-0-0000 for 1 seconds
I0329 00:38:29.966307 21855 master.cpp:679] Received reply for offer 201203290030-0-893
I0329 00:38:29.966599 21855 master.cpp:1403] Filtered slave 201203290030-0-0 for framework 201203290030-0-0001 for 1 seconds
I0329 00:38:30.965576 21855 master.cpp:1184] Sending 1 offers to framework 201203290030-0-0000
I0329 00:38:30.965891 21855 master.cpp:1184] Sending 1 offers to framework 201203290030-0-0001
I0329 00:38:30.967129 21855 master.cpp:679] Received reply for offer 201203290030-0-894
I0329 00:38:31.021703 21855 master.cpp:1403] Filtered slave 201203290030-0-0 for framework 201203290030-0-0000 for 1 seconds
I0329 00:38:31.051646 21855 master.cpp:679] Received reply for offer 201203290030-0-895
I0329 00:38:31.052044 21855 master.cpp:1403] Filtered slave 201203290030-0-1 for framework 201203290030-0-0001 for 1 seconds
I0329 00:38:31.967959 21855 master.cpp:1184] Sending 1 offers to framework 201203290030-0-0000
I0329 00:38:31.968209 21855 master.cpp:1184] Sending 1 offers to framework 201203290030-0-0001
I0329 00:38:31.970027 21855 master.cpp:679] Received reply for offer 201203290030-0-896
I0329 00:38:31.970240 21855 master.cpp:1403] Filtered slave 201203290030-0-1 for framework 201203290030-0-0000 for 1 seconds
I0329 00:38:31.970366 21855 master.cpp:679] Received reply for offer 201203290030-0-897
I0329 00:38:31.970649 21855 master.cpp:1403] Filtered slave 201203290030-0-0 for framework 201203290030-0-0001 for 1 seconds
I0329 00:38:32.970660 21855 master.cpp:1184] Sending 1 offers to framework 201203290030-0-0000
I0329 00:38:32.970993 21855 master.cpp:1184] Sending 1 offers to framework 201203290030-0-0001
I0329 00:38:32.972678 21855 master.cpp:679] Received reply for offer 201203290030-0-898
I0329 00:38:32.972908 21855 master.cpp:1403] Filtered slave 201203290030-0-0 for framework 201203290030-0-0000 for 1 seconds
I0329 00:38:32.973120 21855 master.cpp:679] Received reply for offer 201203290030-0-899
I0329 00:38:32.973306 21855 master.cpp:1403] Filtered slave 201203290030-0-1 for framework 201203290030-0-0001 for 1 seconds
I0329 00:38:33.973450 21855 master.cpp:1184] Sending 1 offers to framework 201203290030-0-0000
I0329 00:38:33.973711 21855 master.cpp:1184] Sending 1 offers to framework 201203290030-0-0001
I0329 00:38:33.975371 21855 master.cpp:679] Received reply for offer 201203290030-0-900
I0329 00:38:33.975560 21855 master.cpp:1403] Filtered slave 201203290030-0-1 for framework 201203290030-0-0000 for 1 seconds
I0329 00:38:33.975872 21855 master.cpp:679] Received reply for offer 201203290030-0-901
I0329 00:38:33.976052 21855 master.cpp:1403] Filtered slave 201203290030-0-0 for framework 201203290030-0-0001 for 1 seconds
I0329 00:38:34.976024 21855 master.cpp:1184] Sending 1 offers to framework 201203290030-0-0000
I0329 00:38:34.976354 21855 master.cpp:1184] Sending 1 offers to framework 201203290030-0-0001
I0329 00:38:34.977960 21855 master.cpp:679] Received reply for offer 201203290030-0-902
I0329 00:38:34.978143 21855 master.cpp:1403] Filtered slave 201203290030-0-0 for framework 201203290030-0-0000 for 1 seconds
I0329 00:38:34.978363 21855 master.cpp:679] Received reply for offer 201203290030-0-903
I0329 00:38:34.978808 21855 master.cpp:1403] Filtered slave 201203290030-0-1 for framework 201203290030-0-0001 for 1 seconds
I0329 00:38:35.978706 21855 master.cpp:1184] Sending 1 offers to framework 201203290030-0-0000
I0329 00:38:35.978953 21855 master.cpp:1184] Sending 1 offers to framework 201203290030-0-0001
I0329 00:38:35.980537 21855 master.cpp:679] Received reply for offer 201203290030-0-904
I0329 00:38:36.025120 21855 master.cpp:1403] Filtered slave 201203290030-0-1 for framework 201203290030-0-0000 for 1 seconds
I0329 00:38:36.055043 21855 master.cpp:679] Received reply for offer 201203290030-0-905
I0329 00:38:36.055301 21855 master.cpp:1403] Filtered slave 201203290030-0-0 for framework 201203290030-0-0001 for 1 seconds
I0329 00:38:36.981284 21855 master.cpp:1184] Sending 1 offers to framework 201203290030-0-0000
I0329 00:38:36.981561 21855 master.cpp:1184] Sending 1 offers to framework 201203290030-0-0001
I0329 00:38:36.983096 21855 master.cpp:679] Received reply for offer 201203290030-0-906
I0329 00:38:36.983257 21855 master.cpp:1403] Filtered slave 201203290030-0-0 for framework 201203290030-0-0000 for 1 seconds
I0329 00:38:36.983548 21855 master.cpp:679] Received reply for offer 201203290030-0-907
I0329 00:38:36.983712 21855 master.cpp:1403] Filtered slave 201203290030-0-1 for framework 201203290030-0-0001 for 1 seconds
I0329 00:38:37.983690 21855 master.cpp:1184] Sending 1 offers to framework 201203290030-0-0000
I0329 00:38:37.983893 21855 master.cpp:1184] Sending 1 offers to framework 201203290030-0-0001
I0329 00:38:37.985321 21855 master.cpp:679] Received reply for offer 201203290030-0-908
I0329 00:38:37.985489 21855 master.cpp:1403] Filtered slave 201203290030-0-1 for framework 201203290030-0-0000 for 1 seconds
I0329 00:38:37.985787 21855 master.cpp:679] Received reply for offer 201203290030-0-909
I0329 00:38:37.985954 21855 master.cpp:1403] Filtered slave 201203290030-0-0 for framework 201203290030-0-0001 for 1 seconds
I0329 00:38:38.985988 21855 master.cpp:1184] Sending 1 offers to framework 201203290030-0-0000
I0329 00:38:38.986202 21855 master.cpp:1184] Sending 1 offers to framework 201203290030-0-0001
I0329 00:38:38.987653 21855 master.cpp:679] Received reply for offer 201203290030-0-910
I0329 00:38:38.987838 21855 master.cpp:1403] Filtered slave 201203290030-0-0 for framework 201203290030-0-0000 for 1 seconds
I0329 00:38:38.988365 21855 master.cpp:679] Received reply for offer 201203290030-0-911
I0329 00:38:38.988538 21855 master.cpp:1403] Filtered slave 201203290030-0-1 for framework 201203290030-0-0001 for 1 seconds
I0329 00:38:39.988572 21855 master.cpp:1184] Sending 1 offers to framework 201203290030-0-0000
I0329 00:38:39.988785 21855 master.cpp:1184] Sending 1 offers to framework 201203290030-0-0001
I0329 00:38:39.990124 21855 master.cpp:679] Received reply for offer 201203290030-0-912
I0329 00:38:39.990310 21855 master.cpp:1403] Filtered slave 201203290030-0-1 for framework 201203290030-0-0000 for 1 seconds
I0329 00:38:39.990779 21855 master.cpp:679] Received reply for offer 201203290030-0-913
I0329 00:38:39.990959 21855 master.cpp:1403] Filtered slave 201203290030-0-0 for framework 201203290030-0-0001 for 1 seconds
I0329 00:38:40.991000 21855 master.cpp:1184] Sending 1 offers to framework 201203290030-0-0000
I0329 00:38:40.991195 21855 master.cpp:1184] Sending 1 offers to framework 201203290030-0-0001
I0329 00:38:40.992465 21855 master.cpp:679] Received reply for offer 201203290030-0-914
I0329 00:38:41.050129 21855 master.cpp:1403] Filtered slave 201203290030-0-0 for framework 201203290030-0-0000 for 1 seconds
I0329 00:38:41.094861 21855 master.cpp:679] Received reply for offer 201203290030-0-915
I0329 00:38:41.095173 21855 master.cpp:1403] Filtered slave 201203290030-0-1 for framework 201203290030-0-0001 for 1 seconds
I0329 00:38:41.993116 21855 master.cpp:1184] Sending 1 offers to framework 201203290030-0-0000
I0329 00:38:41.993330 21855 master.cpp:1184] Sending 1 offers to framework 201203290030-0-0001
I0329 00:38:41.994665 21855 master.cpp:679] Received reply for offer 201203290030-0-916
I0329 00:38:41.994875 21855 master.cpp:1403] Filtered slave 201203290030-0-1 for framework 201203290030-0-0000 for 1 seconds
I0329 00:38:41.995216 21855 master.cpp:679] Received reply for offer 201203290030-0-917
I0329 00:38:41.995478 21855 master.cpp:1403] Filtered slave 201203290030-0-0 for framework 201203290030-0-0001 for 1 seconds
I0329 00:38:42.995404 21855 master.cpp:1184] Sending 1 offers to framework 201203290030-0-0000
I0329 00:38:42.995620 21855 master.cpp:1184] Sending 1 offers to framework 201203290030-0-0001
I0329 00:38:42.997012 21855 master.cpp:679] Received reply for offer 201203290030-0-918
I0329 00:38:42.997184 21855 master.cpp:1403] Filtered slave 201203290030-0-0 for framework 201203290030-0-0000 for 1 seconds
I0329 00:38:42.997418 21855 master.cpp:679] Received reply for offer 201203290030-0-919
I0329 00:38:42.997586 21855 master.cpp:1403] Filtered slave 201203290030-0-1 for framework 201203290030-0-0001 for 1 seconds
I0329 00:38:43.997143 21855 master.cpp:1184] Sending 1 offers to framework 201203290030-0-0000
I0329 00:38:43.997339 21855 master.cpp:1184] Sending 1 offers to framework 201203290030-0-0001
I0329 00:38:43.998720 21855 master.cpp:679] Received reply for offer 201203290030-0-920
I0329 00:38:43.998901 21855 master.cpp:1403] Filtered slave 201203290030-0-1 for framework 201203290030-0-0000 for 1 seconds
I0329 00:38:43.999059 21855 master.cpp:679] Received reply for offer 201203290030-0-921
I0329 00:38:43.999243 21855 master.cpp:1403] Filtered slave 201203290030-0-0 for framework 201203290030-0-0001 for 1 seconds
I0329 00:38:44.999409 21855 master.cpp:1184] Sending 1 offers to framework 201203290030-0-0000
I0329 00:38:44.999635 21855 master.cpp:1184] Sending 1 offers to framework 201203290030-0-0001
I0329 00:38:45.001138 21855 master.cpp:679] Received reply for offer 201203290030-0-922
I0329 00:38:45.001301 21855 master.cpp:1403] Filtered slave 201203290030-0-0 for framework 201203290030-0-0000 for 1 seconds
I0329 00:38:45.001719 21855 master.cpp:679] Received reply for offer 201203290030-0-923
I0329 00:38:45.001895 21855 master.cpp:1403] Filtered slave 201203290030-0-1 for framework 201203290030-0-0001 for 1 seconds
I0329 00:38:46.002019 21855 master.cpp:1184] Sending 1 offers to framework 201203290030-0-0000
I0329 00:38:46.002187 21855 master.cpp:1184] Sending 1 offers to framework 201203290030-0-0001
I0329 00:38:46.003679 21855 master.cpp:679] Received reply for offer 201203290030-0-924
I0329 00:38:46.048564 21855 master.cpp:1403] Filtered slave 201203290030-0-1 for framework 201203290030-0-0000 for 1 seconds
I0329 00:38:46.086513 21855 master.cpp:679] Received reply for offer 201203290030-0-925
I0329 00:38:46.086906 21855 master.cpp:1403] Filtered slave 201203290030-0-0 for framework 201203290030-0-0001 for 1 seconds
I0329 00:38:47.003556 21855 master.cpp:1184] Sending 1 offers to framework 201203290030-0-0000
I0329 00:38:47.003823 21855 master.cpp:1184] Sending 1 offers to framework 201203290030-0-0001
I0329 00:38:47.004976 21855 master.cpp:679] Received reply for offer 201203290030-0-926
I0329 00:38:47.005133 21855 master.cpp:1403] Filtered slave 201203290030-0-0 for framework 201203290030-0-0000 for 1 seconds
I0329 00:38:47.005513 21855 master.cpp:679] Received reply for offer 201203290030-0-927
I0329 00:38:47.005751 21855 master.cpp:1403] Filtered slave 201203290030-0-1 for framework 201203290030-0-0001 for 1 seconds
I0329 00:38:48.005913 21855 master.cpp:1184] Sending 1 offers to framework 201203290030-0-0000
I0329 00:38:48.006103 21855 master.cpp:1184] Sending 1 offers to framework 201203290030-0-0001
I0329 00:38:48.007666 21855 master.cpp:679] Received reply for offer 201203290030-0-928
I0329 00:38:48.007843 21855 master.cpp:1403] Filtered slave 201203290030-0-1 for framework 201203290030-0-0000 for 1 seconds
I0329 00:38:48.008101 21855 master.cpp:679] Received reply for offer 201203290030-0-929
I0329 00:38:48.008271 21855 master.cpp:1403] Filtered slave 201203290030-0-0 for framework 201203290030-0-0001 for 1 seconds
I0329 00:38:49.008445 21855 master.cpp:1184] Sending 1 offers to framework 201203290030-0-0000
I0329 00:38:49.008671 21855 master.cpp:1184] Sending 1 offers to framework 201203290030-0-0001
I0329 00:38:49.010052 21855 master.cpp:679] Received reply for offer 201203290030-0-930
I0329 00:38:49.010215 21855 master.cpp:1403] Filtered slave 201203290030-0-0 for framework 201203290030-0-0000 for 1 seconds
I0329 00:38:49.010594 21855 master.cpp:679] Received reply for offer 201203290030-0-931
I0329 00:38:49.010804 21855 master.cpp:1403] Filtered slave 201203290030-0-1 for framework 201203290030-0-0001 for 1 seconds
I0329 00:38:50.010922 21855 master.cpp:1184] Sending 1 offers to framework 201203290030-0-0000
I0329 00:38:50.011184 21855 master.cpp:1184] Sending 1 offers to framework 201203290030-0-0001
I0329 00:38:50.012681 21855 master.cpp:679] Received reply for offer 201203290030-0-932
I0329 00:38:50.012845 21855 master.cpp:1403] Filtered slave 201203290030-0-1 for framework 201203290030-0-0000 for 1 seconds
I0329 00:38:50.013162 21855 master.cpp:679] Received reply for offer 201203290030-0-933
I0329 00:38:50.013349 21855 master.cpp:1403] Filtered slave 201203290030-0-0 for framework 201203290030-0-0001 for 1 seconds
I0329 00:38:51.013501 21855 master.cpp:1184] Sending 1 offers to framework 201203290030-0-0000
I0329 00:38:51.013690 21855 master.cpp:1184] Sending 1 offers to framework 201203290030-0-0001
I0329 00:38:51.015125 21855 master.cpp:679] Received reply for offer 201203290030-0-934
I0329 00:38:51.060432 21855 master.cpp:1403] Filtered slave 201203290030-0-0 for framework 201203290030-0-0000 for 1 seconds
I0329 00:38:51.098227 21855 master.cpp:679] Received reply for offer 201203290030-0-935
I0329 00:38:51.098515 21855 master.cpp:1403] Filtered slave 201203290030-0-1 for framework 201203290030-0-0001 for 1 seconds
I0329 00:38:52.016084 21855 master.cpp:1184] Sending 1 offers to framework 201203290030-0-0000
I0329 00:38:52.016259 21855 master.cpp:1184] Sending 1 offers to framework 201203290030-0-0001
I0329 00:38:52.017734 21855 master.cpp:679] Received reply for offer 201203290030-0-936
I0329 00:38:52.017907 21855 master.cpp:1403] Filtered slave 201203290030-0-1 for framework 201203290030-0-0000 for 1 seconds
I0329 00:38:52.018189 21855 master.cpp:679] Received reply for offer 201203290030-0-937
I0329 00:38:52.018359 21855 master.cpp:1403] Filtered slave 201203290030-0-0 for framework 201203290030-0-0001 for 1 seconds
I0329 00:38:53.018532 21855 master.cpp:1184] Sending 1 offers to framework 201203290030-0-0000
I0329 00:38:53.018748 21855 master.cpp:1184] Sending 1 offers to framework 201203290030-0-0001
I0329 00:38:53.020190 21855 master.cpp:679] Received reply for offer 201203290030-0-938
I0329 00:38:53.020364 21855 master.cpp:1403] Filtered slave 201203290030-0-0 for framework 201203290030-0-0000 for 1 seconds
I0329 00:38:53.020688 21855 master.cpp:679] Received reply for offer 201203290030-0-939
I0329 00:38:53.020858 21855 master.cpp:1403] Filtered slave 201203290030-0-1 for framework 201203290030-0-0001 for 1 seconds
I0329 00:38:54.020992 21855 master.cpp:1184] Sending 1 offers to framework 201203290030-0-0000
I0329 00:38:54.021188 21855 master.cpp:1184] Sending 1 offers to framework 201203290030-0-0001
I0329 00:38:54.022704 21855 master.cpp:679] Received reply for offer 201203290030-0-940
I0329 00:38:54.022876 21855 master.cpp:1403] Filtered slave 201203290030-0-1 for framework 201203290030-0-0000 for 1 seconds
I0329 00:38:54.023202 21855 master.cpp:679] Received reply for offer 201203290030-0-941
I0329 00:38:54.023372 21855 master.cpp:1403] Filtered slave 201203290030-0-0 for framework 201203290030-0-0001 for 1 seconds
I0329 00:38:55.023511 21855 master.cpp:1184] Sending 1 offers to framework 201203290030-0-0000
I0329 00:38:55.023736 21855 master.cpp:1184] Sending 1 offers to framework 201203290030-0-0001
I0329 00:38:55.025079 21855 master.cpp:679] Received reply for offer 201203290030-0-942
I0329 00:38:55.025239 21855 master.cpp:1403] Filtered slave 201203290030-0-0 for framework 201203290030-0-0000 for 1 seconds
I0329 00:38:55.025631 21855 master.cpp:679] Received reply for offer 201203290030-0-943
I0329 00:38:55.025858 21855 master.cpp:1403] Filtered slave 201203290030-0-1 for framework 201203290030-0-0001 for 1 seconds
I0329 00:38:56.025970 21855 master.cpp:1184] Sending 1 offers to framework 201203290030-0-0000
I0329 00:38:56.026135 21855 master.cpp:1184] Sending 1 offers to framework 201203290030-0-0001
I0329 00:38:56.027513 21855 master.cpp:679] Received reply for offer 201203290030-0-944
I0329 00:38:56.085111 21855 master.cpp:1403] Filtered slave 201203290030-0-1 for framework 201203290030-0-0000 for 1 seconds
I0329 00:38:56.122053 21855 master.cpp:679] Received reply for offer 201203290030-0-945
I0329 00:38:56.122401 21855 master.cpp:1403] Filtered slave 201203290030-0-0 for framework 201203290030-0-0001 for 1 seconds
I0329 00:38:57.028343 21855 master.cpp:1184] Sending 1 offers to framework 201203290030-0-0000
I0329 00:38:57.028759 21855 master.cpp:1184] Sending 1 offers to framework 201203290030-0-0001
I0329 00:38:57.030001 21855 master.cpp:679] Received reply for offer 201203290030-0-946
I0329 00:38:57.030184 21855 master.cpp:1403] Filtered slave 201203290030-0-0 for framework 201203290030-0-0000 for 1 seconds
I0329 00:38:57.030572 21855 master.cpp:679] Received reply for offer 201203290030-0-947
I0329 00:38:57.030731 21855 master.cpp:1403] Filtered slave 201203290030-0-1 for framework 201203290030-0-0001 for 1 seconds
I0329 00:38:58.030887 21855 master.cpp:1184] Sending 1 offers to framework 201203290030-0-0000
I0329 00:38:58.031132 21855 master.cpp:1184] Sending 1 offers to framework 201203290030-0-0001
I0329 00:38:58.032409 21855 master.cpp:679] Received reply for offer 201203290030-0-948
I0329 00:38:58.032583 21855 master.cpp:1403] Filtered slave 201203290030-0-1 for framework 201203290030-0-0000 for 1 seconds
I0329 00:38:58.032920 21855 master.cpp:679] Received reply for offer 201203290030-0-949
I0329 00:38:58.033089 21855 master.cpp:1403] Filtered slave 201203290030-0-0 for framework 201203290030-0-0001 for 1 seconds
I0329 00:38:59.032767 21855 master.cpp:1184] Sending 1 offers to framework 201203290030-0-0000
I0329 00:38:59.032956 21855 master.cpp:1184] Sending 1 offers to framework 201203290030-0-0001
I0329 00:38:59.034366 21855 master.cpp:679] Received reply for offer 201203290030-0-950
I0329 00:38:59.034538 21855 master.cpp:1403] Filtered slave 201203290030-0-0 for framework 201203290030-0-0000 for 1 seconds
I0329 00:38:59.034893 21855 master.cpp:679] Received reply for offer 201203290030-0-951
I0329 00:38:59.035063 21855 master.cpp:1403] Filtered slave 201203290030-0-1 for framework 201203290030-0-0001 for 1 seconds
I0329 00:39:00.035207 21855 master.cpp:1184] Sending 1 offers to framework 201203290030-0-0000
I0329 00:39:00.035392 21855 master.cpp:1184] Sending 1 offers to framework 201203290030-0-0001
I0329 00:39:00.036782 21855 master.cpp:679] Received reply for offer 201203290030-0-952
I0329 00:39:00.036968 21855 master.cpp:1403] Filtered slave 201203290030-0-1 for framework 201203290030-0-0000 for 1 seconds
I0329 00:39:00.037296 21855 master.cpp:679] Received reply for offer 201203290030-0-953
I0329 00:39:00.037477 21855 master.cpp:1403] Filtered slave 201203290030-0-0 for framework 201203290030-0-0001 for 1 seconds
I0329 00:39:01.037600 21855 master.cpp:1184] Sending 1 offers to framework 201203290030-0-0000
I0329 00:39:01.037766 21855 master.cpp:1184] Sending 1 offers to framework 201203290030-0-0001
I0329 00:39:01.039191 21855 master.cpp:679] Received reply for offer 201203290030-0-954
I0329 00:39:01.096850 21855 master.cpp:1403] Filtered slave 201203290030-0-0 for framework 201203290030-0-0000 for 1 seconds
I0329 00:39:01.133759 21855 master.cpp:679] Received reply for offer 201203290030-0-955
I0329 00:39:01.134125 21855 master.cpp:1403] Filtered slave 201203290030-0-1 for framework 201203290030-0-0001 for 1 seconds
I0329 00:39:02.038902 21855 master.cpp:1184] Sending 1 offers to framework 201203290030-0-0000
I0329 00:39:02.039173 21855 master.cpp:1184] Sending 1 offers to framework 201203290030-0-0001
I0329 00:39:02.040482 21855 master.cpp:679] Received reply for offer 201203290030-0-956
I0329 00:39:02.040637 21855 master.cpp:1403] Filtered slave 201203290030-0-1 for framework 201203290030-0-0000 for 1 seconds
I0329 00:39:02.041007 21855 master.cpp:679] Received reply for offer 201203290030-0-957
I0329 00:39:02.041291 21855 master.cpp:1403] Filtered slave 201203290030-0-0 for framework 201203290030-0-0001 for 1 seconds
I0329 00:39:03.040582 21855 master.cpp:1184] Sending 1 offers to framework 201203290030-0-0000
I0329 00:39:03.040791 21855 master.cpp:1184] Sending 1 offers to framework 201203290030-0-0001
I0329 00:39:03.042055 21855 master.cpp:679] Received reply for offer 201203290030-0-958
I0329 00:39:03.042202 21855 master.cpp:1403] Filtered slave 201203290030-0-0 for framework 201203290030-0-0000 for 1 seconds
I0329 00:39:03.042415 21855 master.cpp:679] Received reply for offer 201203290030-0-959
I0329 00:39:03.042578 21855 master.cpp:1403] Filtered slave 201203290030-0-1 for framework 201203290030-0-0001 for 1 seconds
I0329 00:39:04.042636 21855 master.cpp:1184] Sending 1 offers to framework 201203290030-0-0000
I0329 00:39:04.042986 21855 master.cpp:1184] Sending 1 offers to framework 201203290030-0-0001
I0329 00:39:04.044173 21855 master.cpp:679] Received reply for offer 201203290030-0-960
I0329 00:39:04.044344 21855 master.cpp:1403] Filtered slave 201203290030-0-1 for framework 201203290030-0-0000 for 1 seconds
I0329 00:39:04.044672 21855 master.cpp:679] Received reply for offer 201203290030-0-961
I0329 00:39:04.044846 21855 master.cpp:1403] Filtered slave 201203290030-0-0 for framework 201203290030-0-0001 for 1 seconds
I0329 00:39:05.044770 21855 master.cpp:1184] Sending 1 offers to framework 201203290030-0-0000
I0329 00:39:05.044988 21855 master.cpp:1184] Sending 1 offers to framework 201203290030-0-0001
I0329 00:39:05.046277 21855 master.cpp:679] Received reply for offer 201203290030-0-962
I0329 00:39:05.046432 21855 master.cpp:1403] Filtered slave 201203290030-0-0 for framework 201203290030-0-0000 for 1 seconds
I0329 00:39:05.046574 21855 master.cpp:679] Received reply for offer 201203290030-0-963
I0329 00:39:05.046735 21855 master.cpp:1403] Filtered slave 201203290030-0-1 for framework 201203290030-0-0001 for 1 seconds
I0329 00:39:06.046768 21855 master.cpp:1184] Sending 1 offers to framework 201203290030-0-0000
I0329 00:39:06.046922 21855 master.cpp:1184] Sending 1 offers to framework 201203290030-0-0001
I0329 00:39:06.048214 21855 master.cpp:679] Received reply for offer 201203290030-0-964
I0329 00:39:06.104177 21855 master.cpp:1403] Filtered slave 201203290030-0-1 for framework 201203290030-0-0000 for 1 seconds
I0329 00:39:06.141590 21855 master.cpp:679] Received reply for offer 201203290030-0-965
I0329 00:39:06.142009 21855 master.cpp:1403] Filtered slave 201203290030-0-0 for framework 201203290030-0-0001 for 1 seconds
I0329 00:39:07.048809 21855 master.cpp:1184] Sending 1 offers to framework 201203290030-0-0000
I0329 00:39:07.049088 21855 master.cpp:1184] Sending 1 offers to framework 201203290030-0-0001
I0329 00:39:07.050317 21855 master.cpp:679] Received reply for offer 201203290030-0-966
I0329 00:39:07.050462 21855 master.cpp:1403] Filtered slave 201203290030-0-0 for framework 201203290030-0-0000 for 1 seconds
I0329 00:39:07.050730 21855 master.cpp:679] Received reply for offer 201203290030-0-967
I0329 00:39:07.050907 21855 master.cpp:1403] Filtered slave 201203290030-0-1 for framework 201203290030-0-0001 for 1 seconds
I0329 00:39:08.050057 21855 master.cpp:1184] Sending 1 offers to framework 201203290030-0-0000
I0329 00:39:08.050318 21855 master.cpp:1184] Sending 1 offers to framework 201203290030-0-0001
I0329 00:39:08.051606 21855 master.cpp:679] Received reply for offer 201203290030-0-968
I0329 00:39:08.051769 21855 master.cpp:1403] Filtered slave 201203290030-0-1 for framework 201203290030-0-0000 for 1 seconds
I0329 00:39:08.052206 21855 master.cpp:679] Received reply for offer 201203290030-0-969
I0329 00:39:08.052376 21855 master.cpp:1403] Filtered slave 201203290030-0-0 for framework 201203290030-0-0001 for 1 seconds
I0329 00:39:09.052495 21855 master.cpp:1184] Sending 1 offers to framework 201203290030-0-0000
I0329 00:39:09.052723 21855 master.cpp:1184] Sending 1 offers to framework 201203290030-0-0001
I0329 00:39:09.054075 21855 master.cpp:679] Received reply for offer 201203290030-0-970
I0329 00:39:09.054234 21855 master.cpp:1403] Filtered slave 201203290030-0-0 for framework 201203290030-0-0000 for 1 seconds
I0329 00:39:09.054564 21855 master.cpp:679] Received reply for offer 201203290030-0-971
I0329 00:39:09.054728 21855 master.cpp:1403] Filtered slave 201203290030-0-1 for framework 201203290030-0-0001 for 1 seconds
I0329 00:39:10.054827 21855 master.cpp:1184] Sending 1 offers to framework 201203290030-0-0000
I0329 00:39:10.055022 21855 master.cpp:1184] Sending 1 offers to framework 201203290030-0-0001
I0329 00:39:10.056372 21855 master.cpp:679] Received reply for offer 201203290030-0-972
I0329 00:39:10.056545 21855 master.cpp:1403] Filtered slave 201203290030-0-1 for framework 201203290030-0-0000 for 1 seconds
I0329 00:39:10.056881 21855 master.cpp:679] Received reply for offer 201203290030-0-973
I0329 00:39:10.057070 21855 master.cpp:1403] Filtered slave 201203290030-0-0 for framework 201203290030-0-0001 for 1 seconds
I0329 00:39:11.057190 21855 master.cpp:1184] Sending 1 offers to framework 201203290030-0-0000
I0329 00:39:11.057371 21855 master.cpp:1184] Sending 1 offers to framework 201203290030-0-0001
I0329 00:39:11.058784 21855 master.cpp:679] Received reply for offer 201203290030-0-974
I0329 00:39:11.103600 21855 master.cpp:1403] Filtered slave 201203290030-0-0 for framework 201203290030-0-0000 for 1 seconds
I0329 00:39:11.140956 21855 master.cpp:679] Received reply for offer 201203290030-0-975
I0329 00:39:11.141242 21855 master.cpp:1403] Filtered slave 201203290030-0-1 for framework 201203290030-0-0001 for 1 seconds
I0329 00:39:12.059602 21855 master.cpp:1184] Sending 1 offers to framework 201203290030-0-0000
I0329 00:39:12.059793 21855 master.cpp:1184] Sending 1 offers to framework 201203290030-0-0001
I0329 00:39:12.061264 21855 master.cpp:679] Received reply for offer 201203290030-0-976
I0329 00:39:12.061436 21855 master.cpp:1403] Filtered slave 201203290030-0-1 for framework 201203290030-0-0000 for 1 seconds
I0329 00:39:12.061858 21855 master.cpp:679] Received reply for offer 201203290030-0-977
I0329 00:39:12.062058 21855 master.cpp:1403] Filtered slave 201203290030-0-0 for framework 201203290030-0-0001 for 1 seconds
I0329 00:39:13.062101 21855 master.cpp:1184] Sending 1 offers to framework 201203290030-0-0000
I0329 00:39:13.062401 21855 master.cpp:1184] Sending 1 offers to framework 201203290030-0-0001
I0329 00:39:13.063734 21855 master.cpp:679] Received reply for offer 201203290030-0-978
I0329 00:39:13.063906 21855 master.cpp:1403] Filtered slave 201203290030-0-0 for framework 201203290030-0-0000 for 1 seconds
I0329 00:39:13.064364 21855 master.cpp:679] Received reply for offer 201203290030-0-979
I0329 00:39:13.064522 21855 master.cpp:1403] Filtered slave 201203290030-0-1 for framework 201203290030-0-0001 for 1 seconds
I0329 00:39:14.064173 21855 master.cpp:1184] Sending 1 offers to framework 201203290030-0-0000
I0329 00:39:14.064398 21855 master.cpp:1184] Sending 1 offers to framework 201203290030-0-0001
I0329 00:39:14.065768 21855 master.cpp:679] Received reply for offer 201203290030-0-980
I0329 00:39:14.065940 21855 master.cpp:1403] Filtered slave 201203290030-0-1 for framework 201203290030-0-0000 for 1 seconds
I0329 00:39:14.066171 21855 master.cpp:679] Received reply for offer 201203290030-0-981
I0329 00:39:14.066340 21855 master.cpp:1403] Filtered slave 201203290030-0-0 for framework 201203290030-0-0001 for 1 seconds
I0329 00:39:15.066427 21855 master.cpp:1184] Sending 1 offers to framework 201203290030-0-0000
I0329 00:39:15.066661 21855 master.cpp:1184] Sending 1 offers to framework 201203290030-0-0001
I0329 00:39:15.068225 21855 master.cpp:679] Received reply for offer 201203290030-0-982
I0329 00:39:15.068377 21855 master.cpp:1403] Filtered slave 201203290030-0-0 for framework 201203290030-0-0000 for 1 seconds
I0329 00:39:15.068819 21855 master.cpp:679] Received reply for offer 201203290030-0-983
I0329 00:39:15.069144 21855 master.cpp:1403] Filtered slave 201203290030-0-1 for framework 201203290030-0-0001 for 1 seconds
I0329 00:39:16.069159 21855 master.cpp:1184] Sending 1 offers to framework 201203290030-0-0000
I0329 00:39:16.069322 21855 master.cpp:1184] Sending 1 offers to framework 201203290030-0-0001
I0329 00:39:16.070700 21855 master.cpp:679] Received reply for offer 201203290030-0-984
I0329 00:39:16.115267 21855 master.cpp:1403] Filtered slave 201203290030-0-1 for framework 201203290030-0-0000 for 1 seconds
I0329 00:39:16.152825 21855 master.cpp:679] Received reply for offer 201203290030-0-985
I0329 00:39:16.153132 21855 master.cpp:1403] Filtered slave 201203290030-0-0 for framework 201203290030-0-0001 for 1 seconds
I0329 00:39:17.071634 21855 master.cpp:1184] Sending 1 offers to framework 201203290030-0-0000
I0329 00:39:17.071841 21855 master.cpp:1184] Sending 1 offers to framework 201203290030-0-0001
I0329 00:39:17.073137 21855 master.cpp:679] Received reply for offer 201203290030-0-986
I0329 00:39:17.073297 21855 master.cpp:1403] Filtered slave 201203290030-0-0 for framework 201203290030-0-0000 for 1 seconds
I0329 00:39:17.073624 21855 master.cpp:679] Received reply for offer 201203290030-0-987
I0329 00:39:17.073784 21855 master.cpp:1403] Filtered slave 201203290030-0-1 for framework 201203290030-0-0001 for 1 seconds
I0329 00:39:18.073837 21855 master.cpp:1184] Sending 1 offers to framework 201203290030-0-0000
I0329 00:39:18.074033 21855 master.cpp:1184] Sending 1 offers to framework 201203290030-0-0001
I0329 00:39:18.075389 21855 master.cpp:679] Received reply for offer 201203290030-0-988
I0329 00:39:18.075551 21855 master.cpp:1403] Filtered slave 201203290030-0-1 for framework 201203290030-0-0000 for 1 seconds
I0329 00:39:18.075960 21855 master.cpp:679] Received reply for offer 201203290030-0-989
I0329 00:39:18.076120 21855 master.cpp:1403] Filtered slave 201203290030-0-0 for framework 201203290030-0-0001 for 1 seconds
I0329 00:39:19.076174 21855 master.cpp:1184] Sending 1 offers to framework 201203290030-0-0000
I0329 00:39:19.076383 21855 master.cpp:1184] Sending 1 offers to framework 201203290030-0-0001
I0329 00:39:19.077734 21855 master.cpp:679] Received reply for offer 201203290030-0-990
I0329 00:39:19.077891 21855 master.cpp:1403] Filtered slave 201203290030-0-0 for framework 201203290030-0-0000 for 1 seconds
I0329 00:39:19.078279 21855 master.cpp:679] Received reply for offer 201203290030-0-991
I0329 00:39:19.078434 21855 master.cpp:1403] Filtered slave 201203290030-0-1 for framework 201203290030-0-0001 for 1 seconds
I0329 00:39:20.078532 21855 master.cpp:1184] Sending 1 offers to framework 201203290030-0-0000
I0329 00:39:20.078722 21855 master.cpp:1184] Sending 1 offers to framework 201203290030-0-0001
I0329 00:39:20.080061 21855 master.cpp:679] Received reply for offer 201203290030-0-992
I0329 00:39:20.080235 21855 master.cpp:1403] Filtered slave 201203290030-0-1 for framework 201203290030-0-0000 for 1 seconds
I0329 00:39:20.080628 21855 master.cpp:679] Received reply for offer 201203290030-0-993
I0329 00:39:20.080857 21855 master.cpp:1403] Filtered slave 201203290030-0-0 for framework 201203290030-0-0001 for 1 seconds
I0329 00:39:21.080942 21855 master.cpp:1184] Sending 1 offers to framework 201203290030-0-0000
I0329 00:39:21.081302 21855 master.cpp:1184] Sending 1 offers to framework 201203290030-0-0001
I0329 00:39:21.082624 21855 master.cpp:679] Received reply for offer 201203290030-0-994
I0329 00:39:21.118463 21855 master.cpp:1403] Filtered slave 201203290030-0-0 for framework 201203290030-0-0000 for 1 seconds
I0329 00:39:21.147898 21855 master.cpp:679] Received reply for offer 201203290030-0-995
I0329 00:39:21.148311 21855 master.cpp:1403] Filtered slave 201203290030-0-1 for framework 201203290030-0-0001 for 1 seconds
I0329 00:39:22.083259 21855 master.cpp:1184] Sending 1 offers to framework 201203290030-0-0000
I0329 00:39:22.083485 21855 master.cpp:1184] Sending 1 offers to framework 201203290030-0-0001
I0329 00:39:22.084797 21855 master.cpp:679] Received reply for offer 201203290030-0-996
I0329 00:39:22.084946 21855 master.cpp:1403] Filtered slave 201203290030-0-1 for framework 201203290030-0-0000 for 1 seconds
I0329 00:39:22.085233 21855 master.cpp:679] Received reply for offer 201203290030-0-997
I0329 00:39:22.085499 21855 master.cpp:1403] Filtered slave 201203290030-0-0 for framework 201203290030-0-0001 for 1 seconds
I0329 00:39:23.085538 21855 master.cpp:1184] Sending 1 offers to framework 201203290030-0-0000
I0329 00:39:23.085690 21855 master.cpp:1184] Sending 1 offers to framework 201203290030-0-0001
I0329 00:39:23.086889 21855 master.cpp:679] Received reply for offer 201203290030-0-998
I0329 00:39:23.087048 21855 master.cpp:1403] Filtered slave 201203290030-0-0 for framework 201203290030-0-0000 for 1 seconds
I0329 00:39:23.087298 21855 master.cpp:679] Received reply for offer 201203290030-0-999
I0329 00:39:23.087468 21855 master.cpp:1403] Filtered slave 201203290030-0-1 for framework 201203290030-0-0001 for 1 seconds
I0329 00:39:24.087587 21855 master.cpp:1184] Sending 1 offers to framework 201203290030-0-0000
I0329 00:39:24.087774 21855 master.cpp:1184] Sending 1 offers to framework 201203290030-0-0001
I0329 00:39:24.089252 21855 master.cpp:679] Received reply for offer 201203290030-0-1000
I0329 00:39:24.089426 21855 master.cpp:1403] Filtered slave 201203290030-0-1 for framework 201203290030-0-0000 for 1 seconds
I0329 00:39:24.089685 21855 master.cpp:679] Received reply for offer 201203290030-0-1001
I0329 00:39:24.089862 21855 master.cpp:1403] Filtered slave 201203290030-0-0 for framework 201203290030-0-0001 for 1 seconds
I0329 00:39:25.090018 21855 master.cpp:1184] Sending 1 offers to framework 201203290030-0-0000
I0329 00:39:25.090245 21855 master.cpp:1184] Sending 1 offers to framework 201203290030-0-0001
I0329 00:39:25.091707 21855 master.cpp:679] Received reply for offer 201203290030-0-1002
I0329 00:39:25.091860 21855 master.cpp:1403] Filtered slave 201203290030-0-0 for framework 201203290030-0-0000 for 1 seconds
I0329 00:39:25.092157 21855 master.cpp:679] Received reply for offer 201203290030-0-1003
I0329 00:39:25.092336 21855 master.cpp:1403] Filtered slave 201203290030-0-1 for framework 201203290030-0-0001 for 1 seconds
I0329 00:39:26.092504 21855 master.cpp:1184] Sending 1 offers to framework 201203290030-0-0000
I0329 00:39:26.092669 21855 master.cpp:1184] Sending 1 offers to framework 201203290030-0-0001
I0329 00:39:26.094138 21855 master.cpp:679] Received reply for offer 201203290030-0-1004
I0329 00:39:26.130141 21855 master.cpp:1403] Filtered slave 201203290030-0-1 for framework 201203290030-0-0000 for 1 seconds
I0329 00:39:26.159754 21855 master.cpp:679] Received reply for offer 201203290030-0-1005
I0329 00:39:26.160173 21855 master.cpp:1403] Filtered slave 201203290030-0-0 for framework 201203290030-0-0001 for 1 seconds
I0329 00:39:27.095011 21855 master.cpp:1184] Sending 1 offers to framework 201203290030-0-0000
I0329 00:39:27.095229 21855 master.cpp:1184] Sending 1 offers to framework 201203290030-0-0001
I0329 00:39:27.096653 21855 master.cpp:679] Received reply for offer 201203290030-0-1006
I0329 00:39:27.096827 21855 master.cpp:1403] Filtered slave 201203290030-0-0 for framework 201203290030-0-0000 for 1 seconds
I0329 00:39:27.097203 21855 master.cpp:679] Received reply for offer 201203290030-0-1007
I0329 00:39:27.097372 21855 master.cpp:1403] Filtered slave 201203290030-0-1 for framework 201203290030-0-0001 for 1 seconds
I0329 00:39:28.097473 21855 master.cpp:1184] Sending 1 offers to framework 201203290030-0-0000
I0329 00:39:28.097668 21855 master.cpp:1184] Sending 1 offers to framework 201203290030-0-0001
I0329 00:39:28.099148 21855 master.cpp:679] Received reply for offer 201203290030-0-1008
I0329 00:39:28.099299 21855 master.cpp:1403] Filtered slave 201203290030-0-1 for framework 201203290030-0-0000 for 1 seconds
I0329 00:39:28.099715 21855 master.cpp:679] Received reply for offer 201203290030-0-1009
I0329 00:39:28.099902 21855 master.cpp:1403] Filtered slave 201203290030-0-0 for framework 201203290030-0-0001 for 1 seconds
I0329 00:39:29.099673 21855 master.cpp:1184] Sending 1 offers to framework 201203290030-0-0000
I0329 00:39:29.099853 21855 master.cpp:1184] Sending 1 offers to framework 201203290030-0-0001
I0329 00:39:29.101377 21855 master.cpp:679] Received reply for offer 201203290030-0-1010
I0329 00:39:29.101527 21855 master.cpp:1403] Filtered slave 201203290030-0-0 for framework 201203290030-0-0000 for 1 seconds
I0329 00:39:29.101939 21855 master.cpp:679] Received reply for offer 201203290030-0-1011
I0329 00:39:29.102118 21855 master.cpp:1403] Filtered slave 201203290030-0-1 for framework 201203290030-0-0001 for 1 seconds
I0329 00:39:30.102212 21855 master.cpp:1184] Sending 1 offers to framework 201203290030-0-0000
I0329 00:39:30.102404 21855 master.cpp:1184] Sending 1 offers to framework 201203290030-0-0001
I0329 00:39:30.103921 21855 master.cpp:679] Received reply for offer 201203290030-0-1012
I0329 00:39:30.104074 21855 master.cpp:1403] Filtered slave 201203290030-0-1 for framework 201203290030-0-0000 for 1 seconds
I0329 00:39:30.104485 21855 master.cpp:679] Received reply for offer 201203290030-0-1013
I0329 00:39:30.104663 21855 master.cpp:1403] Filtered slave 201203290030-0-0 for framework 201203290030-0-0001 for 1 seconds
I0329 00:39:31.104769 21855 master.cpp:1184] Sending 1 offers to framework 201203290030-0-0000
I0329 00:39:31.104955 21855 master.cpp:1184] Sending 1 offers to framework 201203290030-0-0001
I0329 00:39:31.106446 21855 master.cpp:679] Received reply for offer 201203290030-0-1014
I0329 00:39:31.158493 21855 master.cpp:1403] Filtered slave 201203290030-0-0 for framework 201203290030-0-0000 for 1 seconds
I0329 00:39:31.196594 21855 master.cpp:679] Received reply for offer 201203290030-0-1015
I0329 00:39:31.196960 21855 master.cpp:1403] Filtered slave 201203290030-0-1 for framework 201203290030-0-0001 for 1 seconds
I0329 00:39:32.106245 21855 master.cpp:1184] Sending 1 offers to framework 201203290030-0-0000
I0329 00:39:32.106436 21855 master.cpp:1184] Sending 1 offers to framework 201203290030-0-0001
I0329 00:39:32.107846 21855 master.cpp:679] Received reply for offer 201203290030-0-1016
I0329 00:39:32.108011 21855 master.cpp:1403] Filtered slave 201203290030-0-1 for framework 201203290030-0-0000 for 1 seconds
I0329 00:39:32.108224 21855 master.cpp:679] Received reply for offer 201203290030-0-1017
I0329 00:39:32.108386 21855 master.cpp:1403] Filtered slave 201203290030-0-0 for framework 201203290030-0-0001 for 1 seconds
I0329 00:39:33.108422 21855 master.cpp:1184] Sending 1 offers to framework 201203290030-0-0000
I0329 00:39:33.108635 21855 master.cpp:1184] Sending 1 offers to framework 201203290030-0-0001
I0329 00:39:33.109956 21855 master.cpp:679] Received reply for offer 201203290030-0-1018
I0329 00:39:33.110116 21855 master.cpp:1403] Filtered slave 201203290030-0-0 for framework 201203290030-0-0000 for 1 seconds
I0329 00:39:33.110515 21855 master.cpp:679] Received reply for offer 201203290030-0-1019
I0329 00:39:33.110682 21855 master.cpp:1403] Filtered slave 201203290030-0-1 for framework 201203290030-0-0001 for 1 seconds
I0329 00:39:34.110848 21855 master.cpp:1184] Sending 1 offers to framework 201203290030-0-0000
I0329 00:39:34.111026 21855 master.cpp:1184] Sending 1 offers to framework 201203290030-0-0001
I0329 00:39:34.112434 21855 master.cpp:679] Received reply for offer 201203290030-0-1020
I0329 00:39:34.112581 21855 master.cpp:1403] Filtered slave 201203290030-0-1 for framework 201203290030-0-0000 for 1 seconds
I0329 00:39:34.112948 21855 master.cpp:679] Received reply for offer 201203290030-0-1021
I0329 00:39:34.113122 21855 master.cpp:1403] Filtered slave 201203290030-0-0 for framework 201203290030-0-0001 for 1 seconds
I0329 00:39:35.113183 21855 master.cpp:1184] Sending 1 offers to framework 201203290030-0-0000
I0329 00:39:35.113422 21855 master.cpp:1184] Sending 1 offers to framework 201203290030-0-0001
I0329 00:39:35.114828 21855 master.cpp:679] Received reply for offer 201203290030-0-1022
I0329 00:39:35.115008 21855 master.cpp:1403] Filtered slave 201203290030-0-0 for framework 201203290030-0-0000 for 1 seconds
I0329 00:39:35.115491 21855 master.cpp:679] Received reply for offer 201203290030-0-1023
I0329 00:39:35.115902 21855 master.cpp:1403] Filtered slave 201203290030-0-1 for framework 201203290030-0-0001 for 1 seconds
I0329 00:39:36.115702 21855 master.cpp:1184] Sending 1 offers to framework 201203290030-0-0000
I0329 00:39:36.115870 21855 master.cpp:1184] Sending 1 offers to framework 201203290030-0-0001
I0329 00:39:36.117398 21855 master.cpp:679] Received reply for offer 201203290030-0-1024
I0329 00:39:36.178473 21855 master.cpp:1403] Filtered slave 201203290030-0-1 for framework 201203290030-0-0000 for 1 seconds
I0329 00:39:36.225186 21855 master.cpp:679] Received reply for offer 201203290030-0-1025
I0329 00:39:36.225584 21855 master.cpp:1403] Filtered slave 201203290030-0-0 for framework 201203290030-0-0001 for 1 seconds
I0329 00:39:37.118314 21855 master.cpp:1184] Sending 1 offers to framework 201203290030-0-0000
I0329 00:39:37.118501 21855 master.cpp:1184] Sending 1 offers to framework 201203290030-0-0001
I0329 00:39:37.120123 21855 master.cpp:679] Received reply for offer 201203290030-0-1026
I0329 00:39:37.120296 21855 master.cpp:1403] Filtered slave 201203290030-0-0 for framework 201203290030-0-0000 for 1 seconds
I0329 00:39:37.120626 21855 master.cpp:679] Received reply for offer 201203290030-0-1027
I0329 00:39:37.120795 21855 master.cpp:1403] Filtered slave 201203290030-0-1 for framework 201203290030-0-0001 for 1 seconds
I0329 00:39:38.120944 21855 master.cpp:1184] Sending 1 offers to framework 201203290030-0-0000
I0329 00:39:38.121345 21855 master.cpp:1184] Sending 1 offers to framework 201203290030-0-0001
I0329 00:39:38.122910 21855 master.cpp:679] Received reply for offer 201203290030-0-1028
I0329 00:39:38.123061 21855 master.cpp:1403] Filtered slave 201203290030-0-1 for framework 201203290030-0-0000 for 1 seconds
I0329 00:39:38.123435 21855 master.cpp:679] Received reply for offer 201203290030-0-1029
I0329 00:39:38.123584 21855 master.cpp:1403] Filtered slave 201203290030-0-0 for framework 201203290030-0-0001 for 1 seconds
I0329 00:39:39.123783 21855 master.cpp:1184] Sending 1 offers to framework 201203290030-0-0000
I0329 00:39:39.124066 21855 master.cpp:1184] Sending 1 offers to framework 201203290030-0-0001
I0329 00:39:39.125452 21855 master.cpp:679] Received reply for offer 201203290030-0-1030
I0329 00:39:39.125623 21855 master.cpp:1403] Filtered slave 201203290030-0-0 for framework 201203290030-0-0000 for 1 seconds
I0329 00:39:39.126044 21855 master.cpp:679] Received reply for offer 201203290030-0-1031
I0329 00:39:39.126201 21855 master.cpp:1403] Filtered slave 201203290030-0-1 for framework 201203290030-0-0001 for 1 seconds
I0329 00:39:40.126286 21855 master.cpp:1184] Sending 1 offers to framework 201203290030-0-0000
I0329 00:39:40.126505 21855 master.cpp:1184] Sending 1 offers to framework 201203290030-0-0001
I0329 00:39:40.127989 21855 master.cpp:679] Received reply for offer 201203290030-0-1032
I0329 00:39:40.128161 21855 master.cpp:1403] Filtered slave 201203290030-0-1 for framework 201203290030-0-0000 for 1 seconds
I0329 00:39:40.128597 21855 master.cpp:679] Received reply for offer 201203290030-0-1033
I0329 00:39:40.128795 21855 master.cpp:1403] Filtered slave 201203290030-0-0 for framework 201203290030-0-0001 for 1 seconds
I0329 00:39:41.128895 21855 master.cpp:1184] Sending 1 offers to framework 201203290030-0-0000
I0329 00:39:41.129081 21855 master.cpp:1184] Sending 1 offers to framework 201203290030-0-0001
I0329 00:39:41.130550 21855 master.cpp:679] Received reply for offer 201203290030-0-1034
I0329 00:39:41.130698 21855 master.cpp:1403] Filtered slave 201203290030-0-0 for framework 201203290030-0-0000 for 1 seconds
I0329 00:39:41.131103 21855 master.cpp:679] Received reply for offer 201203290030-0-1035
I0329 00:39:41.131291 21855 master.cpp:1403] Filtered slave 201203290030-0-1 for framework 201203290030-0-0001 for 1 seconds
I0329 00:39:42.131377 21855 master.cpp:1184] Sending 1 offers to framework 201203290030-0-0000
I0329 00:39:42.131621 21855 master.cpp:1184] Sending 1 offers to framework 201203290030-0-0001
I0329 00:39:42.139597 21855 master.cpp:679] Received reply for offer 201203290030-0-1036
I0329 00:39:42.172386 21855 master.cpp:1403] Filtered slave 201203290030-0-1 for framework 201203290030-0-0000 for 1 seconds
I0329 00:39:42.219774 21855 master.cpp:679] Received reply for offer 201203290030-0-1037
I0329 00:39:42.220110 21855 master.cpp:1403] Filtered slave 201203290030-0-0 for framework 201203290030-0-0001 for 1 seconds
I0329 00:39:43.221015 21855 master.cpp:1184] Sending 1 offers to framework 201203290030-0-0000
I0329 00:39:43.221297 21855 master.cpp:1184] Sending 1 offers to framework 201203290030-0-0001
I0329 00:39:43.222697 21855 master.cpp:679] Received reply for offer 201203290030-0-1038
I0329 00:39:43.222867 21855 master.cpp:1403] Filtered slave 201203290030-0-0 for framework 201203290030-0-0000 for 1 seconds
I0329 00:39:43.223238 21855 master.cpp:679] Received reply for offer 201203290030-0-1039
I0329 00:39:43.223408 21855 master.cpp:1403] Filtered slave 201203290030-0-1 for framework 201203290030-0-0001 for 1 seconds
I0329 00:39:44.223570 21855 master.cpp:1184] Sending 1 offers to framework 201203290030-0-0000
I0329 00:39:44.223798 21855 master.cpp:1184] Sending 1 offers to framework 201203290030-0-0001
I0329 00:39:44.225214 21855 master.cpp:679] Received reply for offer 201203290030-0-1040
I0329 00:39:44.225388 21855 master.cpp:1403] Filtered slave 201203290030-0-1 for framework 201203290030-0-0000 for 1 seconds
I0329 00:39:44.225812 21855 master.cpp:679] Received reply for offer 201203290030-0-1041
I0329 00:39:44.225981 21855 master.cpp:1403] Filtered slave 201203290030-0-0 for framework 201203290030-0-0001 for 1 seconds
I0329 00:39:45.226109 21855 master.cpp:1184] Sending 1 offers to framework 201203290030-0-0000
I0329 00:39:45.226295 21855 master.cpp:1184] Sending 1 offers to framework 201203290030-0-0001
I0329 00:39:45.227795 21855 master.cpp:679] Received reply for offer 201203290030-0-1042
I0329 00:39:45.227969 21855 master.cpp:1403] Filtered slave 201203290030-0-0 for framework 201203290030-0-0000 for 1 seconds
I0329 00:39:45.228404 21855 master.cpp:679] Received reply for offer 201203290030-0-1043
I0329 00:39:45.228580 21855 master.cpp:1403] Filtered slave 201203290030-0-1 for framework 201203290030-0-0001 for 1 seconds
I0329 00:39:46.228698 21855 master.cpp:1184] Sending 1 offers to framework 201203290030-0-0000
I0329 00:39:46.228873 21855 master.cpp:1184] Sending 1 offers to framework 201203290030-0-0001
I0329 00:39:46.230334 21855 master.cpp:679] Received reply for offer 201203290030-0-1044
I0329 00:39:46.230507 21855 master.cpp:1403] Filtered slave 201203290030-0-1 for framework 201203290030-0-0000 for 1 seconds
I0329 00:39:46.230942 21855 master.cpp:679] Received reply for offer 201203290030-0-1045
I0329 00:39:46.231118 21855 master.cpp:1403] Filtered slave 201203290030-0-0 for framework 201203290030-0-0001 for 1 seconds
I0329 00:39:47.230135 21855 master.cpp:1184] Sending 1 offers to framework 201203290030-0-0000
I0329 00:39:47.230329 21855 master.cpp:1184] Sending 1 offers to framework 201203290030-0-0001
I0329 00:39:47.231724 21855 master.cpp:679] Received reply for offer 201203290030-0-1046
I0329 00:39:47.231884 21855 master.cpp:1403] Filtered slave 201203290030-0-0 for framework 201203290030-0-0000 for 1 seconds
I0329 00:39:47.232242 21855 master.cpp:679] Received reply for offer 201203290030-0-1047
I0329 00:39:47.232403 21855 master.cpp:1403] Filtered slave 201203290030-0-1 for framework 201203290030-0-0001 for 1 seconds
I0329 00:39:48.232456 21855 master.cpp:1184] Sending 1 offers to framework 201203290030-0-0000
I0329 00:39:48.232663 21855 master.cpp:1184] Sending 1 offers to framework 201203290030-0-0001
I0329 00:39:48.234069 21855 master.cpp:679] Received reply for offer 201203290030-0-1048
I0329 00:39:48.234228 21855 master.cpp:1403] Filtered slave 201203290030-0-1 for framework 201203290030-0-0000 for 1 seconds
I0329 00:39:48.234591 21855 master.cpp:679] Received reply for offer 201203290030-0-1049
I0329 00:39:48.234869 21855 master.cpp:1403] Filtered slave 201203290030-0-0 for framework 201203290030-0-0001 for 1 seconds
I0329 00:39:49.234809 21855 master.cpp:1184] Sending 1 offers to framework 201203290030-0-0000
I0329 00:39:49.235021 21855 master.cpp:1184] Sending 1 offers to framework 201203290030-0-0001
I0329 00:39:49.236374 21855 master.cpp:679] Received reply for offer 201203290030-0-1050
I0329 00:39:49.236531 21855 master.cpp:1403] Filtered slave 201203290030-0-0 for framework 201203290030-0-0000 for 1 seconds
I0329 00:39:49.236884 21855 master.cpp:679] Received reply for offer 201203290030-0-1051
I0329 00:39:49.237045 21855 master.cpp:1403] Filtered slave 201203290030-0-1 for framework 201203290030-0-0001 for 1 seconds
I0329 00:39:50.237095 21855 master.cpp:1184] Sending 1 offers to framework 201203290030-0-0000
I0329 00:39:50.237300 21855 master.cpp:1184] Sending 1 offers to framework 201203290030-0-0001
I0329 00:39:50.238610 21855 master.cpp:679] Received reply for offer 201203290030-0-1052
I0329 00:39:50.238759 21855 master.cpp:1403] Filtered slave 201203290030-0-1 for framework 201203290030-0-0000 for 1 seconds
I0329 00:39:50.238946 21855 master.cpp:679] Received reply for offer 201203290030-0-1053
I0329 00:39:50.239125 21855 master.cpp:1403] Filtered slave 201203290030-0-0 for framework 201203290030-0-0001 for 1 seconds
I0329 00:39:51.239181 21855 master.cpp:1184] Sending 1 offers to framework 201203290030-0-0000
I0329 00:39:51.239378 21855 master.cpp:1184] Sending 1 offers to framework 201203290030-0-0001
I0329 00:39:51.240739 21855 master.cpp:679] Received reply for offer 201203290030-0-1054
I0329 00:39:51.240908 21855 master.cpp:1403] Filtered slave 201203290030-0-0 for framework 201203290030-0-0000 for 1 seconds
I0329 00:39:51.241222 21855 master.cpp:679] Received reply for offer 201203290030-0-1055
I0329 00:39:51.241389 21855 master.cpp:1403] Filtered slave 201203290030-0-1 for framework 201203290030-0-0001 for 1 seconds
I0329 00:39:52.241446 21855 master.cpp:1184] Sending 1 offers to framework 201203290030-0-0000
I0329 00:39:52.241602 21855 master.cpp:1184] Sending 1 offers to framework 201203290030-0-0001
I0329 00:39:52.243165 21855 master.cpp:679] Received reply for offer 201203290030-0-1056
I0329 00:39:52.295711 21855 master.cpp:1403] Filtered slave 201203290030-0-1 for framework 201203290030-0-0000 for 1 seconds
I0329 00:39:52.335052 21855 master.cpp:679] Received reply for offer 201203290030-0-1057
I0329 00:39:52.335466 21855 master.cpp:1403] Filtered slave 201203290030-0-0 for framework 201203290030-0-0001 for 1 seconds
I0329 00:39:53.244036 21855 master.cpp:1184] Sending 1 offers to framework 201203290030-0-0000
I0329 00:39:53.244258 21855 master.cpp:1184] Sending 1 offers to framework 201203290030-0-0001
I0329 00:39:53.245692 21855 master.cpp:679] Received reply for offer 201203290030-0-1058
I0329 00:39:53.245843 21855 master.cpp:1403] Filtered slave 201203290030-0-0 for framework 201203290030-0-0000 for 1 seconds
I0329 00:39:53.246220 21855 master.cpp:679] Received reply for offer 201203290030-0-1059
I0329 00:39:53.246391 21855 master.cpp:1403] Filtered slave 201203290030-0-1 for framework 201203290030-0-0001 for 1 seconds
I0329 00:39:54.246526 21855 master.cpp:1184] Sending 1 offers to framework 201203290030-0-0000
I0329 00:39:54.246711 21855 master.cpp:1184] Sending 1 offers to framework 201203290030-0-0001
I0329 00:39:54.248146 21855 master.cpp:679] Received reply for offer 201203290030-0-1060
I0329 00:39:54.248319 21855 master.cpp:1403] Filtered slave 201203290030-0-1 for framework 201203290030-0-0000 for 1 seconds
I0329 00:39:54.248703 21855 master.cpp:679] Received reply for offer 201203290030-0-1061
I0329 00:39:54.248873 21855 master.cpp:1403] Filtered slave 201203290030-0-0 for framework 201203290030-0-0001 for 1 seconds
I0329 00:39:55.249013 21855 master.cpp:1184] Sending 1 offers to framework 201203290030-0-0000
I0329 00:39:55.249205 21855 master.cpp:1184] Sending 1 offers to framework 201203290030-0-0001
I0329 00:39:55.250619 21855 master.cpp:679] Received reply for offer 201203290030-0-1062
I0329 00:39:55.250777 21855 master.cpp:1403] Filtered slave 201203290030-0-0 for framework 201203290030-0-0000 for 1 seconds
I0329 00:39:55.251216 21855 master.cpp:679] Received reply for offer 201203290030-0-1063
I0329 00:39:55.251505 21855 master.cpp:1403] Filtered slave 201203290030-0-1 for framework 201203290030-0-0001 for 1 seconds
I0329 00:39:56.251477 21855 master.cpp:1184] Sending 1 offers to framework 201203290030-0-0000
I0329 00:39:56.251703 21855 master.cpp:1184] Sending 1 offers to framework 201203290030-0-0001
I0329 00:39:56.253141 21855 master.cpp:679] Received reply for offer 201203290030-0-1064
I0329 00:39:56.253314 21855 master.cpp:1403] Filtered slave 201203290030-0-1 for framework 201203290030-0-0000 for 1 seconds
I0329 00:39:56.253711 21855 master.cpp:679] Received reply for offer 201203290030-0-1065
I0329 00:39:56.253880 21855 master.cpp:1403] Filtered slave 201203290030-0-0 for framework 201203290030-0-0001 for 1 seconds
I0329 00:39:57.254005 21855 master.cpp:1184] Sending 1 offers to framework 201203290030-0-0000
I0329 00:39:57.254232 21855 master.cpp:1184] Sending 1 offers to framework 201203290030-0-0001
I0329 00:39:57.255825 21855 master.cpp:679] Received reply for offer 201203290030-0-1066
I0329 00:39:57.290716 21855 master.cpp:1403] Filtered slave 201203290030-0-0 for framework 201203290030-0-0000 for 1 seconds
I0329 00:39:57.338579 21855 master.cpp:679] Received reply for offer 201203290030-0-1067
I0329 00:39:57.338995 21855 master.cpp:1403] Filtered slave 201203290030-0-1 for framework 201203290030-0-0001 for 1 seconds
I0329 00:39:58.255350 21855 master.cpp:1184] Sending 1 offers to framework 201203290030-0-0000
I0329 00:39:58.255555 21855 master.cpp:1184] Sending 1 offers to framework 201203290030-0-0001
I0329 00:39:58.256968 21855 master.cpp:679] Received reply for offer 201203290030-0-1068
I0329 00:39:58.257119 21855 master.cpp:1403] Filtered slave 201203290030-0-1 for framework 201203290030-0-0000 for 1 seconds
I0329 00:39:58.257535 21855 master.cpp:679] Received reply for offer 201203290030-0-1069
I0329 00:39:58.257714 21855 master.cpp:1403] Filtered slave 201203290030-0-0 for framework 201203290030-0-0001 for 1 seconds
I0329 00:39:59.257781 21855 master.cpp:1184] Sending 1 offers to framework 201203290030-0-0000
I0329 00:39:59.257972 21855 master.cpp:1184] Sending 1 offers to framework 201203290030-0-0001
I0329 00:39:59.259455 21855 master.cpp:679] Received reply for offer 201203290030-0-1070
I0329 00:39:59.259629 21855 master.cpp:1403] Filtered slave 201203290030-0-0 for framework 201203290030-0-0000 for 1 seconds
I0329 00:39:59.260067 21855 master.cpp:679] Received reply for offer 201203290030-0-1071
I0329 00:39:59.260247 21855 master.cpp:1403] Filtered slave 201203290030-0-1 for framework 201203290030-0-0001 for 1 seconds
I0329 00:40:00.260299 21855 master.cpp:1184] Sending 1 offers to framework 201203290030-0-0000
I0329 00:40:00.260534 21855 master.cpp:1184] Sending 1 offers to framework 201203290030-0-0001
I0329 00:40:00.261855 21855 master.cpp:679] Received reply for offer 201203290030-0-1072
I0329 00:40:00.262007 21855 master.cpp:1403] Filtered slave 201203290030-0-1 for framework 201203290030-0-0000 for 1 seconds
I0329 00:40:00.262426 21855 master.cpp:679] Received reply for offer 201203290030-0-1073
I0329 00:40:00.262586 21855 master.cpp:1403] Filtered slave 201203290030-0-0 for framework 201203290030-0-0001 for 1 seconds
I0329 00:40:01.262663 21855 master.cpp:1184] Sending 1 offers to framework 201203290030-0-0000
I0329 00:40:01.262855 21855 master.cpp:1184] Sending 1 offers to framework 201203290030-0-0001
I0329 00:40:01.264286 21855 master.cpp:679] Received reply for offer 201203290030-0-1074
I0329 00:40:01.264458 21855 master.cpp:1403] Filtered slave 201203290030-0-0 for framework 201203290030-0-0000 for 1 seconds
I0329 00:40:01.264854 21855 master.cpp:679] Received reply for offer 201203290030-0-1075
I0329 00:40:01.265082 21855 master.cpp:1403] Filtered slave 201203290030-0-1 for framework 201203290030-0-0001 for 1 seconds
I0329 00:40:02.264150 21855 master.cpp:1184] Sending 1 offers to framework 201203290030-0-0000
I0329 00:40:02.264415 21855 master.cpp:1184] Sending 1 offers to framework 201203290030-0-0001
I0329 00:40:02.265995 21855 master.cpp:679] Received reply for offer 201203290030-0-1076
I0329 00:40:02.266123 21855 master.cpp:1403] Filtered slave 201203290030-0-1 for framework 201203290030-0-0000 for 1 seconds
I0329 00:40:02.302332 21855 master.cpp:679] Received reply for offer 201203290030-0-1077
I0329 00:40:02.342090 21855 master.cpp:1403] Filtered slave 201203290030-0-0 for framework 201203290030-0-0001 for 1 seconds
I0329 00:40:03.266685 21855 master.cpp:1184] Sending 1 offers to framework 201203290030-0-0000
I0329 00:40:03.266897 21855 master.cpp:1184] Sending 1 offers to framework 201203290030-0-0001
I0329 00:40:03.268232 21855 master.cpp:679] Received reply for offer 201203290030-0-1078
I0329 00:40:03.268400 21855 master.cpp:1403] Filtered slave 201203290030-0-0 for framework 201203290030-0-0000 for 1 seconds
I0329 00:40:03.268686 21855 master.cpp:679] Received reply for offer 201203290030-0-1079
I0329 00:40:03.269245 21855 master.cpp:1403] Filtered slave 201203290030-0-1 for framework 201203290030-0-0001 for 1 seconds
I0329 00:40:04.268884 21855 master.cpp:1184] Sending 1 offers to framework 201203290030-0-0000
I0329 00:40:04.269103 21855 master.cpp:1184] Sending 1 offers to framework 201203290030-0-0001
I0329 00:40:04.270437 21855 master.cpp:679] Received reply for offer 201203290030-0-1080
I0329 00:40:04.270606 21855 master.cpp:1403] Filtered slave 201203290030-0-1 for framework 201203290030-0-0000 for 1 seconds
I0329 00:40:04.270833 21855 master.cpp:679] Received reply for offer 201203290030-0-1081
I0329 00:40:04.271016 21855 master.cpp:1403] Filtered slave 201203290030-0-0 for framework 201203290030-0-0001 for 1 seconds
I0329 00:40:05.271071 21855 master.cpp:1184] Sending 1 offers to framework 201203290030-0-0000
I0329 00:40:05.271733 21855 master.cpp:1184] Sending 1 offers to framework 201203290030-0-0001
I0329 00:40:05.273182 21855 master.cpp:679] Received reply for offer 201203290030-0-1082
I0329 00:40:05.273347 21855 master.cpp:1403] Filtered slave 201203290030-0-0 for framework 201203290030-0-0000 for 1 seconds
I0329 00:40:05.273692 21855 master.cpp:679] Received reply for offer 201203290030-0-1083
I0329 00:40:05.273862 21855 master.cpp:1403] Filtered slave 201203290030-0-1 for framework 201203290030-0-0001 for 1 seconds
I0329 00:40:06.273926 21855 master.cpp:1184] Sending 1 offers to framework 201203290030-0-0000
I0329 00:40:06.274147 21855 master.cpp:1184] Sending 1 offers to framework 201203290030-0-0001
I0329 00:40:06.275559 21855 master.cpp:679] Received reply for offer 201203290030-0-1084
I0329 00:40:06.275732 21855 master.cpp:1403] Filtered slave 201203290030-0-1 for framework 201203290030-0-0000 for 1 seconds
I0329 00:40:06.275899 21855 master.cpp:679] Received reply for offer 201203290030-0-1085
I0329 00:40:06.276061 21855 master.cpp:1403] Filtered slave 201203290030-0-0 for framework 201203290030-0-0001 for 1 seconds
I0329 00:40:07.275421 21855 master.cpp:1184] Sending 1 offers to framework 201203290030-0-0000
I0329 00:40:07.275604 21855 master.cpp:1184] Sending 1 offers to framework 201203290030-0-0001
I0329 00:40:07.277107 21855 master.cpp:679] Received reply for offer 201203290030-0-1086
I0329 00:40:07.314044 21855 master.cpp:1403] Filtered slave 201203290030-0-0 for framework 201203290030-0-0000 for 1 seconds
I0329 00:40:07.353860 21855 master.cpp:679] Received reply for offer 201203290030-0-1087
I0329 00:40:07.354112 21855 master.cpp:1403] Filtered slave 201203290030-0-1 for framework 201203290030-0-0001 for 1 seconds
I0329 00:40:08.277705 21855 master.cpp:1184] Sending 1 offers to framework 201203290030-0-0000
I0329 00:40:08.277884 21855 master.cpp:1184] Sending 1 offers to framework 201203290030-0-0001
I0329 00:40:08.279016 21855 master.cpp:679] Received reply for offer 201203290030-0-1088
I0329 00:40:08.279194 21855 master.cpp:1403] Filtered slave 201203290030-0-1 for framework 201203290030-0-0000 for 1 seconds
I0329 00:40:08.279356 21855 master.cpp:679] Received reply for offer 201203290030-0-1089
I0329 00:40:08.279821 21855 master.cpp:1403] Filtered slave 201203290030-0-0 for framework 201203290030-0-0001 for 1 seconds
I0329 00:40:09.279713 21855 master.cpp:1184] Sending 1 offers to framework 201203290030-0-0000
I0329 00:40:09.279903 21855 master.cpp:1184] Sending 1 offers to framework 201203290030-0-0001
I0329 00:40:09.281375 21855 master.cpp:679] Received reply for offer 201203290030-0-1090
I0329 00:40:09.281548 21855 master.cpp:1403] Filtered slave 201203290030-0-0 for framework 201203290030-0-0000 for 1 seconds
I0329 00:40:09.281883 21855 master.cpp:679] Received reply for offer 201203290030-0-1091
I0329 00:40:09.282085 21855 master.cpp:1403] Filtered slave 201203290030-0-1 for framework 201203290030-0-0001 for 1 seconds
I0329 00:40:10.282150 21855 master.cpp:1184] Sending 1 offers to framework 201203290030-0-0000
I0329 00:40:10.282341 21855 master.cpp:1184] Sending 1 offers to framework 201203290030-0-0001
I0329 00:40:10.283819 21855 master.cpp:679] Received reply for offer 201203290030-0-1092
I0329 00:40:10.283995 21855 master.cpp:1403] Filtered slave 201203290030-0-1 for framework 201203290030-0-0000 for 1 seconds
I0329 00:40:10.284409 21855 master.cpp:679] Received reply for offer 201203290030-0-1093
I0329 00:40:10.284687 21855 master.cpp:1403] Filtered slave 201203290030-0-0 for framework 201203290030-0-0001 for 1 seconds
I0329 00:40:11.284621 21855 master.cpp:1184] Sending 1 offers to framework 201203290030-0-0000
I0329 00:40:11.284847 21855 master.cpp:1184] Sending 1 offers to framework 201203290030-0-0001
I0329 00:40:11.286124 21855 master.cpp:679] Received reply for offer 201203290030-0-1094
I0329 00:40:11.286279 21855 master.cpp:1403] Filtered slave 201203290030-0-0 for framework 201203290030-0-0000 for 1 seconds
I0329 00:40:11.286553 21855 master.cpp:679] Received reply for offer 201203290030-0-1095
I0329 00:40:11.286721 21855 master.cpp:1403] Filtered slave 201203290030-0-1 for framework 201203290030-0-0001 for 1 seconds
I0329 00:40:12.286761 21855 master.cpp:1184] Sending 1 offers to framework 201203290030-0-0000
I0329 00:40:12.286926 21855 master.cpp:1184] Sending 1 offers to framework 201203290030-0-0001
I0329 00:40:12.288959 21855 master.cpp:679] Received reply for offer 201203290030-0-1096
I0329 00:40:12.350841 21855 master.cpp:1403] Filtered slave 201203290030-0-1 for framework 201203290030-0-0000 for 1 seconds
I0329 00:40:12.382350 21855 master.cpp:679] Received reply for offer 201203290030-0-1097
I0329 00:40:12.382606 21855 master.cpp:1403] Filtered slave 201203290030-0-0 for framework 201203290030-0-0001 for 1 seconds
I0329 00:40:13.288180 21855 master.cpp:1184] Sending 1 offers to framework 201203290030-0-0000
I0329 00:40:13.288377 21855 master.cpp:1184] Sending 1 offers to framework 201203290030-0-0001
I0329 00:40:13.289698 21855 master.cpp:679] Received reply for offer 201203290030-0-1098
I0329 00:40:13.289963 21855 master.cpp:1403] Filtered slave 201203290030-0-0 for framework 201203290030-0-0000 for 1 seconds
I0329 00:40:13.290143 21855 master.cpp:679] Received reply for offer 201203290030-0-1099
I0329 00:40:13.290323 21855 master.cpp:1403] Filtered slave 201203290030-0-1 for framework 201203290030-0-0001 for 1 seconds
I0329 00:40:14.290279 21855 master.cpp:1184] Sending 1 offers to framework 201203290030-0-0000
I0329 00:40:14.290631 21855 master.cpp:1184] Sending 1 offers to framework 201203290030-0-0001
I0329 00:40:14.291843 21855 master.cpp:679] Received reply for offer 201203290030-0-1100
I0329 00:40:14.292076 21855 master.cpp:1403] Filtered slave 201203290030-0-1 for framework 201203290030-0-0000 for 1 seconds
I0329 00:40:14.292368 21855 master.cpp:679] Received reply for offer 201203290030-0-1101
I0329 00:40:14.292551 21855 master.cpp:1403] Filtered slave 201203290030-0-0 for framework 201203290030-0-0001 for 1 seconds
I0329 00:40:15.292659 21855 master.cpp:1184] Sending 1 offers to framework 201203290030-0-0000
I0329 00:40:15.293017 21855 master.cpp:1184] Sending 1 offers to framework 201203290030-0-0001
I0329 00:40:15.294288 21855 master.cpp:679] Received reply for offer 201203290030-0-1102
I0329 00:40:15.294458 21855 master.cpp:1403] Filtered slave 201203290030-0-0 for framework 201203290030-0-0000 for 1 seconds
I0329 00:40:15.294714 21855 master.cpp:679] Received reply for offer 201203290030-0-1103
I0329 00:40:15.294903 21855 master.cpp:1403] Filtered slave 201203290030-0-1 for framework 201203290030-0-0001 for 1 seconds
I0329 00:40:16.295048 21855 master.cpp:1184] Sending 1 offers to framework 201203290030-0-0000
I0329 00:40:16.295326 21855 master.cpp:1184] Sending 1 offers to framework 201203290030-0-0001
I0329 00:40:16.296771 21855 master.cpp:679] Received reply for offer 201203290030-0-1104
I0329 00:40:16.297000 21855 master.cpp:1403] Filtered slave 201203290030-0-1 for framework 201203290030-0-0000 for 1 seconds
I0329 00:40:16.297142 21855 master.cpp:679] Received reply for offer 201203290030-0-1105
I0329 00:40:16.297440 21855 master.cpp:1403] Filtered slave 201203290030-0-0 for framework 201203290030-0-0001 for 1 seconds
I0329 00:40:17.296286 21855 master.cpp:1184] Sending 1 offers to framework 201203290030-0-0000
I0329 00:40:17.296465 21855 master.cpp:1184] Sending 1 offers to framework 201203290030-0-0001
I0329 00:40:17.298092 21855 master.cpp:679] Received reply for offer 201203290030-0-1106
I0329 00:40:17.354082 21855 master.cpp:1403] Filtered slave 201203290030-0-0 for framework 201203290030-0-0000 for 1 seconds
I0329 00:40:17.394158 21855 master.cpp:679] Received reply for offer 201203290030-0-1107
I0329 00:40:17.394409 21855 master.cpp:1403] Filtered slave 201203290030-0-1 for framework 201203290030-0-0001 for 1 seconds
I0329 00:40:18.299166 21855 master.cpp:1184] Sending 1 offers to framework 201203290030-0-0000
I0329 00:40:18.299345 21855 master.cpp:1184] Sending 1 offers to framework 201203290030-0-0001
I0329 00:40:18.300686 21855 master.cpp:679] Received reply for offer 201203290030-0-1108
I0329 00:40:18.300843 21855 master.cpp:1403] Filtered slave 201203290030-0-1 for framework 201203290030-0-0000 for 1 seconds
I0329 00:40:18.301138 21855 master.cpp:679] Received reply for offer 201203290030-0-1109
I0329 00:40:18.301292 21855 master.cpp:1403] Filtered slave 201203290030-0-0 for framework 201203290030-0-0001 for 1 seconds
I0329 00:40:19.301399 21855 master.cpp:1184] Sending 1 offers to framework 201203290030-0-0000
I0329 00:40:19.301702 21855 master.cpp:1184] Sending 1 offers to framework 201203290030-0-0001
I0329 00:40:19.303141 21855 master.cpp:679] Received reply for offer 201203290030-0-1110
I0329 00:40:19.303292 21855 master.cpp:1403] Filtered slave 201203290030-0-0 for framework 201203290030-0-0000 for 1 seconds
I0329 00:40:19.303632 21855 master.cpp:679] Received reply for offer 201203290030-0-1111
I0329 00:40:19.303786 21855 master.cpp:1403] Filtered slave 201203290030-0-1 for framework 201203290030-0-0001 for 1 seconds
I0329 00:40:20.303890 21855 master.cpp:1184] Sending 1 offers to framework 201203290030-0-0000
I0329 00:40:20.304134 21855 master.cpp:1184] Sending 1 offers to framework 201203290030-0-0001
I0329 00:40:20.305644 21855 master.cpp:679] Received reply for offer 201203290030-0-1112
I0329 00:40:20.305830 21855 master.cpp:1403] Filtered slave 201203290030-0-1 for framework 201203290030-0-0000 for 1 seconds
I0329 00:40:20.306169 21855 master.cpp:679] Received reply for offer 201203290030-0-1113
I0329 00:40:20.306347 21855 master.cpp:1403] Filtered slave 201203290030-0-0 for framework 201203290030-0-0001 for 1 seconds
I0329 00:40:21.306422 21855 master.cpp:1184] Sending 1 offers to framework 201203290030-0-0000
I0329 00:40:21.306607 21855 master.cpp:1184] Sending 1 offers to framework 201203290030-0-0001
I0329 00:40:21.307970 21855 master.cpp:679] Received reply for offer 201203290030-0-1114
I0329 00:40:21.308132 21855 master.cpp:1403] Filtered slave 201203290030-0-0 for framework 201203290030-0-0000 for 1 seconds
I0329 00:40:21.308364 21855 master.cpp:679] Received reply for offer 201203290030-0-1115
I0329 00:40:21.308552 21855 master.cpp:1403] Filtered slave 201203290030-0-1 for framework 201203290030-0-0001 for 1 seconds
I0329 00:40:22.308688 21855 master.cpp:1184] Sending 1 offers to framework 201203290030-0-0000
I0329 00:40:22.308848 21855 master.cpp:1184] Sending 1 offers to framework 201203290030-0-0001
I0329 00:40:22.310088 21855 master.cpp:679] Received reply for offer 201203290030-0-1116
I0329 00:40:22.374032 21855 master.cpp:1403] Filtered slave 201203290030-0-1 for framework 201203290030-0-0000 for 1 seconds
I0329 00:40:22.414345 21855 master.cpp:679] Received reply for offer 201203290030-0-1117
I0329 00:40:22.414762 21855 master.cpp:1403] Filtered slave 201203290030-0-0 for framework 201203290030-0-0001 for 1 seconds
I0329 00:40:23.310801 21855 master.cpp:1184] Sending 1 offers to framework 201203290030-0-0000
I0329 00:40:23.311025 21855 master.cpp:1184] Sending 1 offers to framework 201203290030-0-0001
I0329 00:40:23.312486 21855 master.cpp:679] Received reply for offer 201203290030-0-1118
I0329 00:40:23.312644 21855 master.cpp:1403] Filtered slave 201203290030-0-0 for framework 201203290030-0-0000 for 1 seconds
I0329 00:40:23.312893 21855 master.cpp:679] Received reply for offer 201203290030-0-1119
I0329 00:40:23.313055 21855 master.cpp:1403] Filtered slave 201203290030-0-1 for framework 201203290030-0-0001 for 1 seconds
I0329 00:40:24.313102 21855 master.cpp:1184] Sending 1 offers to framework 201203290030-0-0000
I0329 00:40:24.313304 21855 master.cpp:1184] Sending 1 offers to framework 201203290030-0-0001
I0329 00:40:24.314585 21855 master.cpp:679] Received reply for offer 201203290030-0-1120
I0329 00:40:24.314800 21855 master.cpp:1403] Filtered slave 201203290030-0-1 for framework 201203290030-0-0000 for 1 seconds
I0329 00:40:24.315022 21855 master.cpp:679] Received reply for offer 201203290030-0-1121
I0329 00:40:24.315243 21855 master.cpp:1403] Filtered slave 201203290030-0-0 for framework 201203290030-0-0001 for 1 seconds
I0329 00:40:25.315248 21855 master.cpp:1184] Sending 1 offers to framework 201203290030-0-0000
I0329 00:40:25.315456 21855 master.cpp:1184] Sending 1 offers to framework 201203290030-0-0001
I0329 00:40:25.316715 21855 master.cpp:679] Received reply for offer 201203290030-0-1122
I0329 00:40:25.316871 21855 master.cpp:1403] Filtered slave 201203290030-0-0 for framework 201203290030-0-0000 for 1 seconds
I0329 00:40:25.317248 21855 master.cpp:679] Received reply for offer 201203290030-0-1123
I0329 00:40:25.317414 21855 master.cpp:1403] Filtered slave 201203290030-0-1 for framework 201203290030-0-0001 for 1 seconds
I0329 00:40:26.317555 21855 master.cpp:1184] Sending 1 offers to framework 201203290030-0-0000
I0329 00:40:26.317745 21855 master.cpp:1184] Sending 1 offers to framework 201203290030-0-0001
I0329 00:40:26.319099 21855 master.cpp:679] Received reply for offer 201203290030-0-1124
I0329 00:40:26.319267 21855 master.cpp:1403] Filtered slave 201203290030-0-1 for framework 201203290030-0-0000 for 1 seconds
I0329 00:40:26.319633 21855 master.cpp:679] Received reply for offer 201203290030-0-1125
I0329 00:40:26.319802 21855 master.cpp:1403] Filtered slave 201203290030-0-0 for framework 201203290030-0-0001 for 1 seconds
I0329 00:40:27.319969 21855 master.cpp:1184] Sending 1 offers to framework 201203290030-0-0000
I0329 00:40:27.320126 21855 master.cpp:1184] Sending 1 offers to framework 201203290030-0-0001
I0329 00:40:27.321399 21855 master.cpp:679] Received reply for offer 201203290030-0-1126
I0329 00:40:27.377367 21855 master.cpp:1403] Filtered slave 201203290030-0-0 for framework 201203290030-0-0000 for 1 seconds
I0329 00:40:27.417649 21855 master.cpp:679] Received reply for offer 201203290030-0-1127
I0329 00:40:27.418035 21855 master.cpp:1403] Filtered slave 201203290030-0-1 for framework 201203290030-0-0001 for 1 seconds
I0329 00:40:28.321624 21855 master.cpp:1184] Sending 1 offers to framework 201203290030-0-0000
I0329 00:40:28.321835 21855 master.cpp:1184] Sending 1 offers to framework 201203290030-0-0001
I0329 00:40:28.323184 21855 master.cpp:679] Received reply for offer 201203290030-0-1128
I0329 00:40:28.323365 21855 master.cpp:1403] Filtered slave 201203290030-0-1 for framework 201203290030-0-0000 for 1 seconds
I0329 00:40:28.323815 21855 master.cpp:679] Received reply for offer 201203290030-0-1129
I0329 00:40:28.324234 21855 master.cpp:1403] Filtered slave 201203290030-0-0 for framework 201203290030-0-0001 for 1 seconds
I0329 00:40:29.323338 21855 master.cpp:1184] Sending 1 offers to framework 201203290030-0-0000
I0329 00:40:29.323554 21855 master.cpp:1184] Sending 1 offers to framework 201203290030-0-0001
I0329 00:40:29.324846 21855 master.cpp:679] Received reply for offer 201203290030-0-1130
I0329 00:40:29.325001 21855 master.cpp:1403] Filtered slave 201203290030-0-0 for framework 201203290030-0-0000 for 1 seconds
I0329 00:40:29.325363 21855 master.cpp:679] Received reply for offer 201203290030-0-1131
I0329 00:40:29.325528 21855 master.cpp:1403] Filtered slave 201203290030-0-1 for framework 201203290030-0-0001 for 1 seconds
I0329 00:40:30.325580 21855 master.cpp:1184] Sending 1 offers to framework 201203290030-0-0000
I0329 00:40:30.325809 21855 master.cpp:1184] Sending 1 offers to framework 201203290030-0-0001
I0329 00:40:30.327066 21855 master.cpp:679] Received reply for offer 201203290030-0-1132
I0329 00:40:30.327339 21855 master.cpp:1403] Filtered slave 201203290030-0-1 for framework 201203290030-0-0000 for 1 seconds
I0329 00:40:30.327522 21855 master.cpp:679] Received reply for offer 201203290030-0-1133
I0329 00:40:30.327725 21855 master.cpp:1403] Filtered slave 201203290030-0-0 for framework 201203290030-0-0001 for 1 seconds
I0329 00:40:31.327842 21855 master.cpp:1184] Sending 1 offers to framework 201203290030-0-0000
I0329 00:40:31.328063 21855 master.cpp:1184] Sending 1 offers to framework 201203290030-0-0001
I0329 00:40:31.329210 21855 master.cpp:679] Received reply for offer 201203290030-0-1134
I0329 00:40:31.329418 21855 master.cpp:1403] Filtered slave 201203290030-0-0 for framework 201203290030-0-0000 for 1 seconds
I0329 00:40:31.329591 21855 master.cpp:679] Received reply for offer 201203290030-0-1135
I0329 00:40:31.329753 21855 master.cpp:1403] Filtered slave 201203290030-0-1 for framework 201203290030-0-0001 for 1 seconds
I0329 00:40:32.328903 21855 master.cpp:1184] Sending 1 offers to framework 201203290030-0-0000
I0329 00:40:32.329054 21855 master.cpp:1184] Sending 1 offers to framework 201203290030-0-0001
I0329 00:40:32.330302 21855 master.cpp:679] Received reply for offer 201203290030-0-1136
I0329 00:40:32.389049 21855 master.cpp:1403] Filtered slave 201203290030-0-1 for framework 201203290030-0-0000 for 1 seconds
I0329 00:40:32.422749 21855 master.cpp:679] Received reply for offer 201203290030-0-1137
I0329 00:40:32.423156 21855 master.cpp:1403] Filtered slave 201203290030-0-0 for framework 201203290030-0-0001 for 1 seconds
I0329 00:40:33.331007 21855 master.cpp:1184] Sending 1 offers to framework 201203290030-0-0000
I0329 00:40:33.331203 21855 master.cpp:1184] Sending 1 offers to framework 201203290030-0-0001
I0329 00:40:33.332404 21855 master.cpp:679] Received reply for offer 201203290030-0-1138
I0329 00:40:33.332561 21855 master.cpp:1403] Filtered slave 201203290030-0-0 for framework 201203290030-0-0000 for 1 seconds
I0329 00:40:33.332849 21855 master.cpp:679] Received reply for offer 201203290030-0-1139
I0329 00:40:33.333010 21855 master.cpp:1403] Filtered slave 201203290030-0-1 for framework 201203290030-0-0001 for 1 seconds
I0329 00:40:34.333062 21855 master.cpp:1184] Sending 1 offers to framework 201203290030-0-0000
I0329 00:40:34.333267 21855 master.cpp:1184] Sending 1 offers to framework 201203290030-0-0001
I0329 00:40:34.334424 21855 master.cpp:679] Received reply for offer 201203290030-0-1140
I0329 00:40:34.334581 21855 master.cpp:1403] Filtered slave 201203290030-0-1 for framework 201203290030-0-0000 for 1 seconds
I0329 00:40:34.335019 21855 master.cpp:679] Received reply for offer 201203290030-0-1141
I0329 00:40:34.335213 21855 master.cpp:1403] Filtered slave 201203290030-0-0 for framework 201203290030-0-0001 for 1 seconds
I0329 00:40:35.335322 21855 master.cpp:1184] Sending 1 offers to framework 201203290030-0-0000
I0329 00:40:35.335572 21855 master.cpp:1184] Sending 1 offers to framework 201203290030-0-0001
I0329 00:40:35.336895 21855 master.cpp:679] Received reply for offer 201203290030-0-1142
I0329 00:40:35.337045 21855 master.cpp:1403] Filtered slave 201203290030-0-0 for framework 201203290030-0-0000 for 1 seconds
I0329 00:40:35.337275 21855 master.cpp:679] Received reply for offer 201203290030-0-1143
I0329 00:40:35.337515 21855 master.cpp:1403] Filtered slave 201203290030-0-1 for framework 201203290030-0-0001 for 1 seconds
I0329 00:40:36.337612 21855 master.cpp:1184] Sending 1 offers to framework 201203290030-0-0000
I0329 00:40:36.337826 21855 master.cpp:1184] Sending 1 offers to framework 201203290030-0-0001
I0329 00:40:36.339231 21855 master.cpp:679] Received reply for offer 201203290030-0-1144
I0329 00:40:36.339406 21855 master.cpp:1403] Filtered slave 201203290030-0-1 for framework 201203290030-0-0000 for 1 seconds
I0329 00:40:36.339660 21855 master.cpp:679] Received reply for offer 201203290030-0-1145
I0329 00:40:36.339839 21855 master.cpp:1403] Filtered slave 201203290030-0-0 for framework 201203290030-0-0001 for 1 seconds
I0329 00:40:37.340011 21855 master.cpp:1184] Sending 1 offers to framework 201203290030-0-0000
I0329 00:40:37.340205 21855 master.cpp:1184] Sending 1 offers to framework 201203290030-0-0001
I0329 00:40:37.341564 21855 master.cpp:679] Received reply for offer 201203290030-0-1146
I0329 00:40:37.401496 21855 master.cpp:1403] Filtered slave 201203290030-0-0 for framework 201203290030-0-0000 for 1 seconds
I0329 00:40:37.442100 21855 master.cpp:679] Received reply for offer 201203290030-0-1147
I0329 00:40:37.442553 21855 master.cpp:1403] Filtered slave 201203290030-0-1 for framework 201203290030-0-0001 for 1 seconds
I0329 00:40:38.342361 21855 master.cpp:1184] Sending 1 offers to framework 201203290030-0-0000
I0329 00:40:38.342547 21855 master.cpp:1184] Sending 1 offers to framework 201203290030-0-0001
I0329 00:40:38.344061 21855 master.cpp:679] Received reply for offer 201203290030-0-1148
I0329 00:40:38.344238 21855 master.cpp:1403] Filtered slave 201203290030-0-1 for framework 201203290030-0-0000 for 1 seconds
I0329 00:40:38.344485 21855 master.cpp:679] Received reply for offer 201203290030-0-1149
I0329 00:40:38.344701 21855 master.cpp:1403] Filtered slave 201203290030-0-0 for framework 201203290030-0-0001 for 1 seconds
I0329 00:40:39.344807 21855 master.cpp:1184] Sending 1 offers to framework 201203290030-0-0000
I0329 00:40:39.344991 21855 master.cpp:1184] Sending 1 offers to framework 201203290030-0-0001
I0329 00:40:39.346541 21855 master.cpp:679] Received reply for offer 201203290030-0-1150
I0329 00:40:39.346714 21855 master.cpp:1403] Filtered slave 201203290030-0-0 for framework 201203290030-0-0000 for 1 seconds
I0329 00:40:39.346906 21855 master.cpp:679] Received reply for offer 201203290030-0-1151
I0329 00:40:39.347084 21855 master.cpp:1403] Filtered slave 201203290030-0-1 for framework 201203290030-0-0001 for 1 seconds
I0329 00:40:40.347058 21855 master.cpp:1184] Sending 1 offers to framework 201203290030-0-0000
I0329 00:40:40.347309 21855 master.cpp:1184] Sending 1 offers to framework 201203290030-0-0001
I0329 00:40:40.348701 21855 master.cpp:679] Received reply for offer 201203290030-0-1152
I0329 00:40:40.348922 21855 master.cpp:1403] Filtered slave 201203290030-0-1 for framework 201203290030-0-0000 for 1 seconds
I0329 00:40:40.349270 21855 master.cpp:679] Received reply for offer 201203290030-0-1153
I0329 00:40:40.349470 21855 master.cpp:1403] Filtered slave 201203290030-0-0 for framework 201203290030-0-0001 for 1 seconds
I0329 00:40:41.349486 21855 master.cpp:1184] Sending 1 offers to framework 201203290030-0-0000
I0329 00:40:41.349710 21855 master.cpp:1184] Sending 1 offers to framework 201203290030-0-0001
I0329 00:40:41.351090 21855 master.cpp:679] Received reply for offer 201203290030-0-1154
I0329 00:40:41.351251 21855 master.cpp:1403] Filtered slave 201203290030-0-0 for framework 201203290030-0-0000 for 1 seconds
I0329 00:40:41.351605 21855 master.cpp:679] Received reply for offer 201203290030-0-1155
I0329 00:40:41.351790 21855 master.cpp:1403] Filtered slave 201203290030-0-1 for framework 201203290030-0-0001 for 1 seconds
I0329 00:40:42.351934 21855 master.cpp:1184] Sending 1 offers to framework 201203290030-0-0000
I0329 00:40:42.352087 21855 master.cpp:1184] Sending 1 offers to framework 201203290030-0-0001
I0329 00:40:42.353442 21855 master.cpp:679] Received reply for offer 201203290030-0-1156
I0329 00:40:42.413327 21855 master.cpp:1403] Filtered slave 201203290030-0-1 for framework 201203290030-0-0000 for 1 seconds
I0329 00:40:42.453778 21855 master.cpp:679] Received reply for offer 201203290030-0-1157
I0329 00:40:42.454207 21855 master.cpp:1403] Filtered slave 201203290030-0-0 for framework 201203290030-0-0001 for 1 seconds
I0329 00:40:43.353982 21855 master.cpp:1184] Sending 1 offers to framework 201203290030-0-0000
I0329 00:40:43.354169 21855 master.cpp:1184] Sending 1 offers to framework 201203290030-0-0001
I0329 00:40:43.355620 21855 master.cpp:679] Received reply for offer 201203290030-0-1158
I0329 00:40:43.355794 21855 master.cpp:1403] Filtered slave 201203290030-0-0 for framework 201203290030-0-0000 for 1 seconds
I0329 00:40:43.356094 21855 master.cpp:679] Received reply for offer 201203290030-0-1159
I0329 00:40:43.356263 21855 master.cpp:1403] Filtered slave 201203290030-0-1 for framework 201203290030-0-0001 for 1 seconds
