Log file created at: 2012/03/29 03:32:36
Running on machine: azad
Log line format: [IWEF]mmdd hh:mm:ss.uuuuuu threadid file:line] msg
I0329 03:32:36.189614 10926 logging.cpp:70] Logging to /mesos-distro/logdir
I0329 03:32:36.190531 10926 main.cpp:95] Build: 2012-03-28 23:30:52 by hduser
I0329 03:32:36.190572 10926 main.cpp:96] Starting Mesos master
I0329 03:32:36.191709 10927 master.cpp:264] Master started at mesos://master@192.168.1.64:5050
I0329 03:32:36.191732 10926 webui.cpp:81] Starting master web server on port 9836
I0329 03:32:36.191817 10927 master.cpp:279] Master ID: 201203290332-0
I0329 03:32:36.191897 10930 webui.cpp:47] Master web server thread started
I0329 03:32:36.192075 10927 master.cpp:462] Elected as master!
I0329 03:32:36.203346 10930 webui.cpp:59] Loading webui/master/webui.py
I0329 03:32:39.000938 10927 master.cpp:814] Attempting to register slave 201203290332-0-0 at slave@192.168.1.64:51054
I0329 03:32:39.001219 10927 master.cpp:1057] Master now considering a slave at azad.gateway.2wire.net:51054 as active
I0329 03:32:39.001266 10927 master.cpp:1588] Adding slave 201203290332-0-0 at azad.gateway.2wire.net with cpus=8; mem=16384
I0329 03:32:39.001457 10927 simple_allocator.cpp:71] Added slave 201203290332-0-0 with cpus=8; mem=16384
I0329 03:32:42.217751 10927 master.cpp:814] Attempting to register slave 201203290332-0-1 at slave@192.168.1.66:40945
I0329 03:32:42.217988 10927 master.cpp:1057] Master now considering a slave at ubuntu.gateway.2wire.net:40945 as active
I0329 03:32:42.218034 10927 master.cpp:1588] Adding slave 201203290332-0-1 at ubuntu.gateway.2wire.net with cpus=8; mem=8192
I0329 03:32:42.218176 10927 simple_allocator.cpp:71] Added slave 201203290332-0-1 with cpus=8; mem=8192
I0329 03:32:51.912822 10927 master.cpp:492] Registering framework 201203290332-0-0000 at 2@192.168.1.64:34055
I0329 03:32:51.912953 10927 simple_allocator.cpp:48] Added framework 201203290332-0-0000
I0329 03:32:51.913055 10927 master.cpp:1184] Sending 2 offers to framework 201203290332-0-0000
I0329 03:32:51.913161 10927 master.cpp:492] Registering framework 201203290332-0-0001 at 3@192.168.1.64:34055
I0329 03:32:51.913204 10927 simple_allocator.cpp:48] Added framework 201203290332-0-0001
I0329 03:32:51.929427 10927 master.cpp:679] Received reply for offer 201203290332-0-0
I0329 03:32:51.929514 10927 master.cpp:1403] Filtered slave 201203290332-0-0 for framework 201203290332-0-0000 for 1 seconds
I0329 03:32:51.929556 10927 master.cpp:679] Received reply for offer 201203290332-0-1
I0329 03:32:51.929616 10927 master.cpp:1184] Sending 1 offers to framework 201203290332-0-0001
I0329 03:32:51.929657 10927 master.cpp:1403] Filtered slave 201203290332-0-1 for framework 201203290332-0-0000 for 1 seconds
I0329 03:32:51.930412 10927 master.cpp:679] Received reply for offer 201203290332-0-2
I0329 03:32:51.930465 10927 master.cpp:1403] Filtered slave 201203290332-0-0 for framework 201203290332-0-0001 for 1 seconds
I0329 03:32:52.209872 10927 master.cpp:1184] Sending 1 offers to framework 201203290332-0-0001
I0329 03:32:52.211050 10927 master.cpp:679] Received reply for offer 201203290332-0-3
I0329 03:32:52.211127 10927 master.cpp:1403] Filtered slave 201203290332-0-1 for framework 201203290332-0-0001 for 1 seconds
I0329 03:32:52.280365 10927 master.cpp:718] Reviving offers for framework 201203290332-0-0001
I0329 03:32:52.280415 10927 simple_allocator.cpp:145] Filters removed for framework 201203290332-0-0001
I0329 03:32:52.280534 10927 master.cpp:1184] Sending 2 offers to framework 201203290332-0-0001
I0329 03:32:52.365103 10927 master.cpp:679] Received reply for offer 201203290332-0-4
I0329 03:32:52.365216 10927 master.cpp:1453] Launching task 0 on slave 201203290332-0-0
I0329 03:32:52.365363 10927 master.cpp:1453] Launching task 1 on slave 201203290332-0-0
I0329 03:32:52.365492 10927 master.cpp:1453] Launching task 2 on slave 201203290332-0-0
I0329 03:32:52.365627 10927 master.cpp:1453] Launching task 3 on slave 201203290332-0-0
I0329 03:32:52.365759 10927 master.cpp:1453] Launching task 4 on slave 201203290332-0-0
I0329 03:32:52.365900 10927 master.cpp:1453] Launching task 5 on slave 201203290332-0-0
I0329 03:32:52.366189 10927 master.cpp:1453] Launching task 6 on slave 201203290332-0-0
I0329 03:32:52.366534 10927 master.cpp:1453] Launching task 7 on slave 201203290332-0-0
I0329 03:32:52.366888 10927 master.cpp:679] Received reply for offer 201203290332-0-5
I0329 03:32:52.367051 10927 master.cpp:1403] Filtered slave 201203290332-0-1 for framework 201203290332-0-0001 for 1 seconds
I0329 03:32:53.211297 10927 master.cpp:1184] Sending 1 offers to framework 201203290332-0-0000
I0329 03:32:53.212738 10927 master.cpp:679] Received reply for offer 201203290332-0-6
I0329 03:32:53.212854 10927 master.cpp:1403] Filtered slave 201203290332-0-1 for framework 201203290332-0-0000 for 1 seconds
I0329 03:32:53.340217 10927 master.cpp:902] Status update from slave@192.168.1.64:51054: task 3 of framework 201203290332-0-0001 is now in state TASK_RUNNING
I0329 03:32:53.343049 10927 master.cpp:902] Status update from slave@192.168.1.64:51054: task 7 of framework 201203290332-0-0001 is now in state TASK_RUNNING
I0329 03:32:53.345392 10927 master.cpp:902] Status update from slave@192.168.1.64:51054: task 5 of framework 201203290332-0-0001 is now in state TASK_RUNNING
I0329 03:32:53.348270 10927 master.cpp:902] Status update from slave@192.168.1.64:51054: task 6 of framework 201203290332-0-0001 is now in state TASK_RUNNING
I0329 03:32:53.350457 10927 master.cpp:902] Status update from slave@192.168.1.64:51054: task 0 of framework 201203290332-0-0001 is now in state TASK_RUNNING
I0329 03:32:53.352795 10927 master.cpp:902] Status update from slave@192.168.1.64:51054: task 1 of framework 201203290332-0-0001 is now in state TASK_RUNNING
I0329 03:32:53.355118 10927 master.cpp:902] Status update from slave@192.168.1.64:51054: task 2 of framework 201203290332-0-0001 is now in state TASK_RUNNING
I0329 03:32:53.357496 10927 master.cpp:902] Status update from slave@192.168.1.64:51054: task 4 of framework 201203290332-0-0001 is now in state TASK_RUNNING
I0329 03:32:54.212795 10927 master.cpp:1184] Sending 1 offers to framework 201203290332-0-0001
I0329 03:32:54.214105 10927 master.cpp:679] Received reply for offer 201203290332-0-7
I0329 03:32:54.214252 10927 master.cpp:1403] Filtered slave 201203290332-0-1 for framework 201203290332-0-0001 for 1 seconds
I0329 03:32:54.557281 10927 master.cpp:902] Status update from slave@192.168.1.64:51054: task 5 of framework 201203290332-0-0001 is now in state TASK_FINISHED
I0329 03:32:54.557513 10927 master.cpp:1184] Sending 1 offers to framework 201203290332-0-0000
I0329 03:32:54.559440 10927 master.cpp:902] Status update from slave@192.168.1.64:51054: task 3 of framework 201203290332-0-0001 is now in state TASK_FINISHED
I0329 03:32:54.561772 10927 master.cpp:902] Status update from slave@192.168.1.64:51054: task 2 of framework 201203290332-0-0001 is now in state TASK_FINISHED
I0329 03:32:54.564066 10927 master.cpp:902] Status update from slave@192.168.1.64:51054: task 0 of framework 201203290332-0-0001 is now in state TASK_FINISHED
I0329 03:32:54.565793 10927 master.cpp:902] Status update from slave@192.168.1.64:51054: task 7 of framework 201203290332-0-0001 is now in state TASK_FINISHED
I0329 03:32:54.567484 10927 master.cpp:902] Status update from slave@192.168.1.64:51054: task 4 of framework 201203290332-0-0001 is now in state TASK_FINISHED
I0329 03:32:54.568934 10927 master.cpp:902] Status update from slave@192.168.1.64:51054: task 1 of framework 201203290332-0-0001 is now in state TASK_FINISHED
I0329 03:32:54.573034 10927 master.cpp:902] Status update from slave@192.168.1.64:51054: task 6 of framework 201203290332-0-0001 is now in state TASK_FINISHED
I0329 03:32:54.576987 10927 master.cpp:679] Received reply for offer 201203290332-0-8
I0329 03:32:54.577144 10927 master.cpp:1403] Filtered slave 201203290332-0-0 for framework 201203290332-0-0000 for 1 seconds
I0329 03:32:55.214928 10927 master.cpp:1184] Sending 1 offers to framework 201203290332-0-0001
I0329 03:32:55.256880 10927 master.cpp:679] Received reply for offer 201203290332-0-9
I0329 03:32:55.257097 10927 master.cpp:1453] Launching task 8 on slave 201203290332-0-0
I0329 03:32:55.257627 10927 master.cpp:1453] Launching task 9 on slave 201203290332-0-0
I0329 03:32:55.257982 10927 master.cpp:1453] Launching task 10 on slave 201203290332-0-0
I0329 03:32:55.258251 10927 master.cpp:1453] Launching task 11 on slave 201203290332-0-0
I0329 03:32:55.258327 10927 master.cpp:1453] Launching task 12 on slave 201203290332-0-0
I0329 03:32:55.258841 10927 master.cpp:1453] Launching task 13 on slave 201203290332-0-0
I0329 03:32:55.259277 10927 master.cpp:1453] Launching task 14 on slave 201203290332-0-0
I0329 03:32:55.259733 10927 master.cpp:1453] Launching task 15 on slave 201203290332-0-0
I0329 03:32:55.262094 10927 master.cpp:902] Status update from slave@192.168.1.64:51054: task 8 of framework 201203290332-0-0001 is now in state TASK_RUNNING
I0329 03:32:55.264019 10927 master.cpp:902] Status update from slave@192.168.1.64:51054: task 9 of framework 201203290332-0-0001 is now in state TASK_RUNNING
I0329 03:32:55.276461 10927 master.cpp:902] Status update from slave@192.168.1.64:51054: task 10 of framework 201203290332-0-0001 is now in state TASK_RUNNING
I0329 03:32:55.276648 10927 master.cpp:902] Status update from slave@192.168.1.64:51054: task 11 of framework 201203290332-0-0001 is now in state TASK_RUNNING
I0329 03:32:55.277155 10927 master.cpp:902] Status update from slave@192.168.1.64:51054: task 12 of framework 201203290332-0-0001 is now in state TASK_RUNNING
I0329 03:32:55.277735 10927 master.cpp:902] Status update from slave@192.168.1.64:51054: task 13 of framework 201203290332-0-0001 is now in state TASK_RUNNING
I0329 03:32:55.283687 10927 master.cpp:902] Status update from slave@192.168.1.64:51054: task 15 of framework 201203290332-0-0001 is now in state TASK_RUNNING
I0329 03:32:55.283874 10927 master.cpp:902] Status update from slave@192.168.1.64:51054: task 14 of framework 201203290332-0-0001 is now in state TASK_RUNNING
I0329 03:32:55.378073 10927 master.cpp:902] Status update from slave@192.168.1.64:51054: task 9 of framework 201203290332-0-0001 is now in state TASK_FINISHED
I0329 03:32:55.378345 10927 master.cpp:1184] Sending 1 offers to framework 201203290332-0-0000
I0329 03:32:55.378494 10927 master.cpp:1184] Sending 1 offers to framework 201203290332-0-0001
I0329 03:32:55.381247 10927 master.cpp:679] Received reply for offer 201203290332-0-10
I0329 03:32:55.381448 10927 master.cpp:1403] Filtered slave 201203290332-0-1 for framework 201203290332-0-0000 for 1 seconds
I0329 03:32:55.389068 10927 master.cpp:679] Received reply for offer 201203290332-0-11
I0329 03:32:55.389257 10927 master.cpp:1453] Launching task 16 on slave 201203290332-0-0
I0329 03:32:55.389622 10927 master.cpp:1184] Sending 1 offers to framework 201203290332-0-0001
I0329 03:32:55.391485 10927 master.cpp:679] Received reply for offer 201203290332-0-12
I0329 03:32:55.391669 10927 master.cpp:1403] Filtered slave 201203290332-0-1 for framework 201203290332-0-0001 for 1 seconds
I0329 03:32:55.394834 10927 master.cpp:902] Status update from slave@192.168.1.64:51054: task 11 of framework 201203290332-0-0001 is now in state TASK_FINISHED
I0329 03:32:55.395112 10927 master.cpp:1184] Sending 1 offers to framework 201203290332-0-0001
I0329 03:32:55.403692 10927 master.cpp:679] Received reply for offer 201203290332-0-13
I0329 03:32:55.403883 10927 master.cpp:1453] Launching task 17 on slave 201203290332-0-0
I0329 03:32:55.409005 10927 master.cpp:902] Status update from slave@192.168.1.64:51054: task 8 of framework 201203290332-0-0001 is now in state TASK_FINISHED
I0329 03:32:55.409219 10927 master.cpp:1184] Sending 1 offers to framework 201203290332-0-0001
I0329 03:32:55.417860 10927 master.cpp:679] Received reply for offer 201203290332-0-14
I0329 03:32:55.418051 10927 master.cpp:1453] Launching task 18 on slave 201203290332-0-0
I0329 03:32:55.419642 10927 master.cpp:902] Status update from slave@192.168.1.64:51054: task 16 of framework 201203290332-0-0001 is now in state TASK_RUNNING
I0329 03:32:55.421972 10927 master.cpp:902] Status update from slave@192.168.1.64:51054: task 17 of framework 201203290332-0-0001 is now in state TASK_RUNNING
I0329 03:32:55.424208 10927 master.cpp:902] Status update from slave@192.168.1.64:51054: task 10 of framework 201203290332-0-0001 is now in state TASK_FINISHED
I0329 03:32:55.424458 10927 master.cpp:1184] Sending 1 offers to framework 201203290332-0-0001
I0329 03:32:55.426645 10927 master.cpp:902] Status update from slave@192.168.1.64:51054: task 15 of framework 201203290332-0-0001 is now in state TASK_FINISHED
I0329 03:32:55.428910 10927 master.cpp:902] Status update from slave@192.168.1.64:51054: task 12 of framework 201203290332-0-0001 is now in state TASK_FINISHED
I0329 03:32:55.438233 10927 master.cpp:902] Status update from slave@192.168.1.64:51054: task 18 of framework 201203290332-0-0001 is now in state TASK_RUNNING
I0329 03:32:55.439738 10927 master.cpp:902] Status update from slave@192.168.1.64:51054: task 14 of framework 201203290332-0-0001 is now in state TASK_FINISHED
I0329 03:32:55.467716 10927 master.cpp:679] Received reply for offer 201203290332-0-15
I0329 03:32:55.467892 10927 master.cpp:1453] Launching task 19 on slave 201203290332-0-0
I0329 03:32:55.479310 10927 master.cpp:902] Status update from slave@192.168.1.64:51054: task 13 of framework 201203290332-0-0001 is now in state TASK_FINISHED
I0329 03:32:55.479612 10927 master.cpp:1184] Sending 1 offers to framework 201203290332-0-0001
I0329 03:32:55.479759 10927 master.cpp:902] Status update from slave@192.168.1.64:51054: task 19 of framework 201203290332-0-0001 is now in state TASK_RUNNING
I0329 03:32:55.519265 10927 master.cpp:902] Status update from slave@192.168.1.64:51054: task 17 of framework 201203290332-0-0001 is now in state TASK_FINISHED
I0329 03:32:55.519565 10927 master.cpp:902] Status update from slave@192.168.1.64:51054: task 16 of framework 201203290332-0-0001 is now in state TASK_FINISHED
I0329 03:32:55.520970 10927 master.cpp:679] Received reply for offer 201203290332-0-16
I0329 03:32:55.521126 10927 master.cpp:1453] Launching task 20 on slave 201203290332-0-0
I0329 03:32:55.521448 10927 master.cpp:1453] Launching task 21 on slave 201203290332-0-0
I0329 03:32:55.521620 10927 master.cpp:1453] Launching task 22 on slave 201203290332-0-0
I0329 03:32:55.521831 10927 master.cpp:1453] Launching task 23 on slave 201203290332-0-0
I0329 03:32:55.559305 10927 master.cpp:902] Status update from slave@192.168.1.64:51054: task 18 of framework 201203290332-0-0001 is now in state TASK_FINISHED
I0329 03:32:55.559573 10927 master.cpp:1184] Sending 1 offers to framework 201203290332-0-0001
I0329 03:32:55.559725 10927 master.cpp:902] Status update from slave@192.168.1.64:51054: task 20 of framework 201203290332-0-0001 is now in state TASK_RUNNING
I0329 03:32:55.560212 10927 master.cpp:902] Status update from slave@192.168.1.64:51054: task 21 of framework 201203290332-0-0001 is now in state TASK_RUNNING
I0329 03:32:55.560303 10927 master.cpp:902] Status update from slave@192.168.1.64:51054: task 22 of framework 201203290332-0-0001 is now in state TASK_RUNNING
I0329 03:32:55.560902 10927 master.cpp:902] Status update from slave@192.168.1.64:51054: task 23 of framework 201203290332-0-0001 is now in state TASK_RUNNING
I0329 03:32:55.561161 10927 master.cpp:902] Status update from slave@192.168.1.64:51054: task 19 of framework 201203290332-0-0001 is now in state TASK_FINISHED
I0329 03:32:55.601609 10927 master.cpp:902] Status update from slave@192.168.1.64:51054: task 20 of framework 201203290332-0-0001 is now in state TASK_FINISHED
I0329 03:32:55.606358 10927 master.cpp:679] Received reply for offer 201203290332-0-17
I0329 03:32:55.606538 10927 master.cpp:1453] Launching task 24 on slave 201203290332-0-0
I0329 03:32:55.606839 10927 master.cpp:1453] Launching task 25 on slave 201203290332-0-0
I0329 03:32:55.607005 10927 master.cpp:1453] Launching task 26 on slave 201203290332-0-0
I0329 03:32:55.613873 10927 master.cpp:902] Status update from slave@192.168.1.64:51054: task 25 of framework 201203290332-0-0001 is now in state TASK_RUNNING
I0329 03:32:55.614056 10927 master.cpp:902] Status update from slave@192.168.1.64:51054: task 24 of framework 201203290332-0-0001 is now in state TASK_RUNNING
I0329 03:32:55.615603 10927 master.cpp:902] Status update from slave@192.168.1.64:51054: task 26 of framework 201203290332-0-0001 is now in state TASK_RUNNING
I0329 03:32:55.618060 10927 master.cpp:902] Status update from slave@192.168.1.64:51054: task 22 of framework 201203290332-0-0001 is now in state TASK_FINISHED
I0329 03:32:55.618322 10927 master.cpp:1184] Sending 1 offers to framework 201203290332-0-0001
I0329 03:32:55.621752 10927 master.cpp:902] Status update from slave@192.168.1.64:51054: task 21 of framework 201203290332-0-0001 is now in state TASK_FINISHED
I0329 03:32:55.656333 10927 master.cpp:679] Received reply for offer 201203290332-0-18
I0329 03:32:55.656525 10927 master.cpp:1453] Launching task 27 on slave 201203290332-0-0
I0329 03:32:55.657686 10927 master.cpp:1453] Launching task 28 on slave 201203290332-0-0
I0329 03:32:55.657850 10927 master.cpp:1453] Launching task 29 on slave 201203290332-0-0
I0329 03:32:55.659255 10927 master.cpp:902] Status update from slave@192.168.1.64:51054: task 23 of framework 201203290332-0-0001 is now in state TASK_FINISHED
I0329 03:32:55.659534 10927 master.cpp:1184] Sending 1 offers to framework 201203290332-0-0001
I0329 03:32:55.690708 10927 master.cpp:679] Received reply for offer 201203290332-0-19
I0329 03:32:55.690894 10927 master.cpp:1453] Launching task 30 on slave 201203290332-0-0
I0329 03:32:55.691175 10927 master.cpp:1453] Launching task 31 on slave 201203290332-0-0
I0329 03:32:55.699316 10927 master.cpp:902] Status update from slave@192.168.1.64:51054: task 27 of framework 201203290332-0-0001 is now in state TASK_RUNNING
I0329 03:32:55.699437 10927 master.cpp:902] Status update from slave@192.168.1.64:51054: task 28 of framework 201203290332-0-0001 is now in state TASK_RUNNING
I0329 03:32:55.700031 10927 master.cpp:902] Status update from slave@192.168.1.64:51054: task 26 of framework 201203290332-0-0001 is now in state TASK_FINISHED
I0329 03:32:55.700685 10927 master.cpp:1184] Sending 1 offers to framework 201203290332-0-0001
I0329 03:32:55.701051 10927 master.cpp:902] Status update from slave@192.168.1.64:51054: task 24 of framework 201203290332-0-0001 is now in state TASK_FINISHED
I0329 03:32:55.701585 10927 master.cpp:902] Status update from slave@192.168.1.64:51054: task 25 of framework 201203290332-0-0001 is now in state TASK_FINISHED
I0329 03:32:55.702041 10927 master.cpp:902] Status update from slave@192.168.1.64:51054: task 29 of framework 201203290332-0-0001 is now in state TASK_RUNNING
I0329 03:32:55.702441 10927 master.cpp:902] Status update from slave@192.168.1.64:51054: task 30 of framework 201203290332-0-0001 is now in state TASK_RUNNING
I0329 03:32:55.706434 10927 master.cpp:679] Received reply for offer 201203290332-0-20
I0329 03:32:55.706606 10927 master.cpp:1453] Launching task 32 on slave 201203290332-0-0
I0329 03:32:55.739297 10927 master.cpp:902] Status update from slave@192.168.1.64:51054: task 31 of framework 201203290332-0-0001 is now in state TASK_RUNNING
I0329 03:32:55.739532 10927 master.cpp:902] Status update from slave@192.168.1.64:51054: task 32 of framework 201203290332-0-0001 is now in state TASK_RUNNING
I0329 03:32:55.748888 10927 master.cpp:902] Status update from slave@192.168.1.64:51054: task 28 of framework 201203290332-0-0001 is now in state TASK_FINISHED
I0329 03:32:55.749155 10927 master.cpp:1184] Sending 1 offers to framework 201203290332-0-0001
I0329 03:32:55.750886 10927 master.cpp:902] Status update from slave@192.168.1.64:51054: task 27 of framework 201203290332-0-0001 is now in state TASK_FINISHED
I0329 03:32:55.788174 10927 master.cpp:902] Status update from slave@192.168.1.64:51054: task 31 of framework 201203290332-0-0001 is now in state TASK_FINISHED
I0329 03:32:55.790658 10927 master.cpp:679] Received reply for offer 201203290332-0-21
I0329 03:32:55.790839 10927 master.cpp:1453] Launching task 33 on slave 201203290332-0-0
I0329 03:32:55.791131 10927 master.cpp:1453] Launching task 34 on slave 201203290332-0-0
I0329 03:32:55.791374 10927 master.cpp:1453] Launching task 35 on slave 201203290332-0-0
I0329 03:32:55.827314 10927 master.cpp:902] Status update from slave@192.168.1.64:51054: task 30 of framework 201203290332-0-0001 is now in state TASK_FINISHED
I0329 03:32:55.827610 10927 master.cpp:1184] Sending 1 offers to framework 201203290332-0-0001
I0329 03:32:55.827767 10927 master.cpp:902] Status update from slave@192.168.1.64:51054: task 33 of framework 201203290332-0-0001 is now in state TASK_RUNNING
I0329 03:32:55.827982 10927 master.cpp:902] Status update from slave@192.168.1.64:51054: task 32 of framework 201203290332-0-0001 is now in state TASK_FINISHED
I0329 03:32:55.828357 10927 master.cpp:902] Status update from slave@192.168.1.64:51054: task 29 of framework 201203290332-0-0001 is now in state TASK_FINISHED
I0329 03:32:55.828526 10927 master.cpp:902] Status update from slave@192.168.1.64:51054: task 34 of framework 201203290332-0-0001 is now in state TASK_RUNNING
I0329 03:32:55.828971 10927 master.cpp:902] Status update from slave@192.168.1.64:51054: task 35 of framework 201203290332-0-0001 is now in state TASK_RUNNING
I0329 03:32:55.867522 10927 master.cpp:902] Status update from slave@192.168.1.64:51054: task 33 of framework 201203290332-0-0001 is now in state TASK_FINISHED
I0329 03:32:55.867827 10927 master.cpp:902] Status update from slave@192.168.1.64:51054: task 35 of framework 201203290332-0-0001 is now in state TASK_FINISHED
I0329 03:32:55.873389 10927 master.cpp:679] Received reply for offer 201203290332-0-22
I0329 03:32:55.873564 10927 master.cpp:1453] Launching task 36 on slave 201203290332-0-0
I0329 03:32:55.874100 10927 master.cpp:1453] Launching task 37 on slave 201203290332-0-0
I0329 03:32:55.874280 10927 master.cpp:1453] Launching task 38 on slave 201203290332-0-0
I0329 03:32:55.882426 10927 master.cpp:902] Status update from slave@192.168.1.64:51054: task 36 of framework 201203290332-0-0001 is now in state TASK_RUNNING
I0329 03:32:55.884800 10927 master.cpp:902] Status update from slave@192.168.1.64:51054: task 34 of framework 201203290332-0-0001 is now in state TASK_FINISHED
I0329 03:32:55.885030 10927 master.cpp:1184] Sending 1 offers to framework 201203290332-0-0001
I0329 03:32:55.887935 10927 master.cpp:902] Status update from slave@192.168.1.64:51054: task 37 of framework 201203290332-0-0001 is now in state TASK_RUNNING
I0329 03:32:55.914074 10927 master.cpp:679] Received reply for offer 201203290332-0-23
I0329 03:32:55.914235 10927 master.cpp:1453] Launching task 39 on slave 201203290332-0-0
I0329 03:32:55.916676 10927 master.cpp:902] Status update from slave@192.168.1.64:51054: task 38 of framework 201203290332-0-0001 is now in state TASK_RUNNING
I0329 03:32:55.923892 10927 master.cpp:902] Status update from slave@192.168.1.64:51054: task 36 of framework 201203290332-0-0001 is now in state TASK_FINISHED
I0329 03:32:55.924168 10927 master.cpp:1184] Sending 1 offers to framework 201203290332-0-0001
I0329 03:32:55.949677 10927 master.cpp:679] Received reply for offer 201203290332-0-24
I0329 03:32:55.949861 10927 master.cpp:1403] Filtered slave 201203290332-0-0 for framework 201203290332-0-0001 for 1 seconds
I0329 03:32:55.953963 10927 master.cpp:902] Status update from slave@192.168.1.64:51054: task 37 of framework 201203290332-0-0001 is now in state TASK_FINISHED
I0329 03:32:55.991380 10927 master.cpp:902] Status update from slave@192.168.1.64:51054: task 39 of framework 201203290332-0-0001 is now in state TASK_RUNNING
I0329 03:32:55.991575 10927 master.cpp:902] Status update from slave@192.168.1.64:51054: task 38 of framework 201203290332-0-0001 is now in state TASK_FINISHED
I0329 03:32:56.031359 10927 master.cpp:902] Status update from slave@192.168.1.64:51054: task 39 of framework 201203290332-0-0001 is now in state TASK_FINISHED
I0329 03:32:56.052341 10927 master.cpp:718] Reviving offers for framework 201203290332-0-0001
I0329 03:32:56.052492 10927 simple_allocator.cpp:145] Filters removed for framework 201203290332-0-0001
I0329 03:32:56.052933 10927 master.cpp:1184] Sending 1 offers to framework 201203290332-0-0001
I0329 03:32:56.090226 10927 master.cpp:679] Received reply for offer 201203290332-0-25
I0329 03:32:56.090387 10927 master.cpp:1453] Launching task 40 on slave 201203290332-0-0
I0329 03:32:56.091022 10927 master.cpp:1453] Launching task 41 on slave 201203290332-0-0
I0329 03:32:56.091378 10927 master.cpp:1453] Launching task 42 on slave 201203290332-0-0
I0329 03:32:56.091778 10927 master.cpp:1453] Launching task 43 on slave 201203290332-0-0
I0329 03:32:56.092013 10927 master.cpp:1453] Launching task 44 on slave 201203290332-0-0
I0329 03:32:56.092198 10927 master.cpp:1453] Launching task 45 on slave 201203290332-0-0
I0329 03:32:56.092730 10927 master.cpp:1453] Launching task 46 on slave 201203290332-0-0
I0329 03:32:56.093075 10927 master.cpp:1453] Launching task 47 on slave 201203290332-0-0
I0329 03:32:56.100353 10927 master.cpp:902] Status update from slave@192.168.1.64:51054: task 40 of framework 201203290332-0-0001 is now in state TASK_RUNNING
I0329 03:32:56.104210 10927 master.cpp:902] Status update from slave@192.168.1.64:51054: task 41 of framework 201203290332-0-0001 is now in state TASK_RUNNING
I0329 03:32:56.107472 10927 master.cpp:902] Status update from slave@192.168.1.64:51054: task 42 of framework 201203290332-0-0001 is now in state TASK_RUNNING
I0329 03:32:56.110739 10927 master.cpp:902] Status update from slave@192.168.1.64:51054: task 43 of framework 201203290332-0-0001 is now in state TASK_RUNNING
I0329 03:32:56.114085 10927 master.cpp:902] Status update from slave@192.168.1.64:51054: task 46 of framework 201203290332-0-0001 is now in state TASK_RUNNING
I0329 03:32:56.117504 10927 master.cpp:902] Status update from slave@192.168.1.64:51054: task 44 of framework 201203290332-0-0001 is now in state TASK_RUNNING
I0329 03:32:56.120905 10927 master.cpp:902] Status update from slave@192.168.1.64:51054: task 47 of framework 201203290332-0-0001 is now in state TASK_RUNNING
I0329 03:32:56.123522 10927 master.cpp:902] Status update from slave@192.168.1.64:51054: task 45 of framework 201203290332-0-0001 is now in state TASK_RUNNING
I0329 03:32:56.145838 10927 master.cpp:902] Status update from slave@192.168.1.64:51054: task 42 of framework 201203290332-0-0001 is now in state TASK_FAILED
I0329 03:32:56.146112 10927 master.cpp:1184] Sending 1 offers to framework 201203290332-0-0001
I0329 03:32:56.184017 10927 master.cpp:902] Status update from slave@192.168.1.64:51054: task 46 of framework 201203290332-0-0001 is now in state TASK_FAILED
I0329 03:32:56.187913 10927 master.cpp:679] Received reply for offer 201203290332-0-26
I0329 03:32:56.188047 10927 master.cpp:1453] Launching task 48 on slave 201203290332-0-0
I0329 03:32:56.215538 10927 master.cpp:1184] Sending 1 offers to framework 201203290332-0-0000
I0329 03:32:56.223440 10927 master.cpp:902] Status update from slave@192.168.1.64:51054: task 44 of framework 201203290332-0-0001 is now in state TASK_FAILED
I0329 03:32:56.223742 10927 master.cpp:902] Status update from slave@192.168.1.64:51054: task 47 of framework 201203290332-0-0001 is now in state TASK_FAILED
I0329 03:32:56.223978 10927 master.cpp:902] Status update from slave@192.168.1.64:51054: task 41 of framework 201203290332-0-0001 is now in state TASK_FAILED
I0329 03:32:56.224191 10927 master.cpp:902] Status update from slave@192.168.1.64:51054: task 45 of framework 201203290332-0-0001 is now in state TASK_FAILED
I0329 03:32:56.224422 10927 master.cpp:902] Status update from slave@192.168.1.64:51054: task 43 of framework 201203290332-0-0001 is now in state TASK_FAILED
I0329 03:32:56.225916 10927 master.cpp:679] Received reply for offer 201203290332-0-27
I0329 03:32:56.226064 10927 master.cpp:1403] Filtered slave 201203290332-0-0 for framework 201203290332-0-0000 for 1 seconds
I0329 03:32:57.018971 10927 master.cpp:1001] Executor default of framework 201203290332-0-0001 on slave 201203290332-0-0 (azad.gateway.2wire.net) exited with status 256
I0329 03:32:57.020345 10927 master.cpp:1033] Removing task 48 of framework 201203290332-0-0001 because of lost executor
I0329 03:32:57.082759 10927 master.cpp:1184] Sending 1 offers to framework 201203290332-0-0001
I0329 03:32:57.084317 10927 master.cpp:1033] Removing task 40 of framework 201203290332-0-0001 because of lost executor
I0329 03:32:57.097326 10927 master.cpp:679] Received reply for offer 201203290332-0-28
I0329 03:32:57.097517 10927 master.cpp:1453] Launching task 49 on slave 201203290332-0-0
I0329 03:32:57.097861 10927 master.cpp:1453] Launching task 50 on slave 201203290332-0-0
I0329 03:32:57.098016 10927 master.cpp:1453] Launching task 51 on slave 201203290332-0-0
I0329 03:32:57.098265 10927 master.cpp:1453] Launching task 52 on slave 201203290332-0-0
I0329 03:32:57.098399 10927 master.cpp:1453] Launching task 53 on slave 201203290332-0-0
I0329 03:32:57.100358 10927 master.cpp:1453] Launching task 54 on slave 201203290332-0-0
I0329 03:32:57.100673 10927 master.cpp:1453] Launching task 55 on slave 201203290332-0-0
I0329 03:32:57.216645 10927 master.cpp:1184] Sending 1 offers to framework 201203290332-0-0000
I0329 03:32:57.217984 10927 master.cpp:679] Received reply for offer 201203290332-0-29
I0329 03:32:57.218111 10927 master.cpp:1403] Filtered slave 201203290332-0-1 for framework 201203290332-0-0000 for 1 seconds
I0329 03:32:58.005434 10927 master.cpp:902] Status update from slave@192.168.1.64:51054: task 52 of framework 201203290332-0-0001 is now in state TASK_RUNNING
I0329 03:32:58.007431 10927 master.cpp:902] Status update from slave@192.168.1.64:51054: task 55 of framework 201203290332-0-0001 is now in state TASK_RUNNING
I0329 03:32:58.009745 10927 master.cpp:902] Status update from slave@192.168.1.64:51054: task 54 of framework 201203290332-0-0001 is now in state TASK_RUNNING
I0329 03:32:58.012328 10927 master.cpp:902] Status update from slave@192.168.1.64:51054: task 50 of framework 201203290332-0-0001 is now in state TASK_RUNNING
I0329 03:32:58.015226 10927 master.cpp:902] Status update from slave@192.168.1.64:51054: task 53 of framework 201203290332-0-0001 is now in state TASK_RUNNING
I0329 03:32:58.016814 10927 master.cpp:902] Status update from slave@192.168.1.64:51054: task 49 of framework 201203290332-0-0001 is now in state TASK_RUNNING
I0329 03:32:58.019268 10927 master.cpp:902] Status update from slave@192.168.1.64:51054: task 51 of framework 201203290332-0-0001 is now in state TASK_RUNNING
I0329 03:32:58.217846 10927 master.cpp:1184] Sending 1 offers to framework 201203290332-0-0000
I0329 03:32:58.218056 10927 master.cpp:1184] Sending 1 offers to framework 201203290332-0-0001
I0329 03:32:58.219130 10927 master.cpp:679] Received reply for offer 201203290332-0-30
I0329 03:32:58.219300 10927 master.cpp:1403] Filtered slave 201203290332-0-0 for framework 201203290332-0-0000 for 1 seconds
I0329 03:32:58.219635 10927 master.cpp:679] Received reply for offer 201203290332-0-31
I0329 03:32:58.219826 10927 master.cpp:1184] Sending 1 offers to framework 201203290332-0-0001
I0329 03:32:58.219965 10927 master.cpp:1403] Filtered slave 201203290332-0-1 for framework 201203290332-0-0001 for 1 seconds
I0329 03:32:58.223523 10927 master.cpp:679] Received reply for offer 201203290332-0-32
I0329 03:32:58.223695 10927 master.cpp:1453] Launching task 56 on slave 201203290332-0-0
I0329 03:32:58.243015 10927 master.cpp:902] Status update from slave@192.168.1.64:51054: task 56 of framework 201203290332-0-0001 is now in state TASK_RUNNING
I0329 03:32:58.327349 10927 master.cpp:902] Status update from slave@192.168.1.64:51054: task 55 of framework 201203290332-0-0001 is now in state TASK_FAILED
I0329 03:32:58.327669 10927 master.cpp:1184] Sending 1 offers to framework 201203290332-0-0001
I0329 03:32:58.330601 10927 master.cpp:902] Status update from slave@192.168.1.64:51054: task 49 of framework 201203290332-0-0001 is now in state TASK_FAILED
I0329 03:32:58.333199 10927 master.cpp:679] Received reply for offer 201203290332-0-33
I0329 03:32:58.333262 10927 master.cpp:1453] Launching task 57 on slave 201203290332-0-0
I0329 03:32:58.367548 10927 master.cpp:902] Status update from slave@192.168.1.64:51054: task 53 of framework 201203290332-0-0001 is now in state TASK_FAILED
I0329 03:32:58.367893 10927 master.cpp:1184] Sending 1 offers to framework 201203290332-0-0001
I0329 03:32:58.368043 10927 master.cpp:902] Status update from slave@192.168.1.64:51054: task 54 of framework 201203290332-0-0001 is now in state TASK_FAILED
I0329 03:32:58.368410 10927 master.cpp:902] Status update from slave@192.168.1.64:51054: task 52 of framework 201203290332-0-0001 is now in state TASK_FAILED
I0329 03:32:58.368721 10927 master.cpp:902] Status update from slave@192.168.1.64:51054: task 51 of framework 201203290332-0-0001 is now in state TASK_FAILED
I0329 03:32:58.369070 10927 master.cpp:902] Status update from slave@192.168.1.64:51054: task 50 of framework 201203290332-0-0001 is now in state TASK_FAILED
I0329 03:32:58.413079 10927 master.cpp:679] Received reply for offer 201203290332-0-34
I0329 03:32:58.413244 10927 master.cpp:1453] Launching task 58 on slave 201203290332-0-0
I0329 03:32:58.413910 10927 master.cpp:1453] Launching task 59 on slave 201203290332-0-0
I0329 03:32:59.020128 10927 master.cpp:1001] Executor default of framework 201203290332-0-0001 on slave 201203290332-0-0 (azad.gateway.2wire.net) exited with status 256
I0329 03:32:59.021651 10927 master.cpp:1033] Removing task 58 of framework 201203290332-0-0001 because of lost executor
I0329 03:32:59.021848 10927 master.cpp:1184] Sending 1 offers to framework 201203290332-0-0001
I0329 03:32:59.023926 10927 master.cpp:1033] Removing task 59 of framework 201203290332-0-0001 because of lost executor
I0329 03:32:59.025378 10927 master.cpp:1033] Removing task 56 of framework 201203290332-0-0001 because of lost executor
I0329 03:32:59.026919 10927 master.cpp:1033] Removing task 57 of framework 201203290332-0-0001 because of lost executor
I0329 03:32:59.038230 10927 master.cpp:679] Received reply for offer 201203290332-0-35
I0329 03:32:59.038509 10927 master.cpp:1453] Launching task 60 on slave 201203290332-0-0
I0329 03:32:59.038790 10927 master.cpp:1453] Launching task 61 on slave 201203290332-0-0
I0329 03:32:59.039031 10927 master.cpp:1453] Launching task 62 on slave 201203290332-0-0
I0329 03:32:59.039278 10927 master.cpp:1453] Launching task 63 on slave 201203290332-0-0
I0329 03:32:59.039430 10927 master.cpp:1453] Launching task 64 on slave 201203290332-0-0
I0329 03:32:59.219439 10927 master.cpp:1184] Sending 1 offers to framework 201203290332-0-0000
I0329 03:32:59.220666 10927 master.cpp:679] Received reply for offer 201203290332-0-36
I0329 03:32:59.220808 10927 master.cpp:1403] Filtered slave 201203290332-0-1 for framework 201203290332-0-0000 for 1 seconds
I0329 03:32:59.990419 10927 master.cpp:902] Status update from slave@192.168.1.64:51054: task 63 of framework 201203290332-0-0001 is now in state TASK_RUNNING
I0329 03:32:59.993391 10927 master.cpp:902] Status update from slave@192.168.1.64:51054: task 62 of framework 201203290332-0-0001 is now in state TASK_RUNNING
I0329 03:32:59.995913 10927 master.cpp:902] Status update from slave@192.168.1.64:51054: task 60 of framework 201203290332-0-0001 is now in state TASK_RUNNING
I0329 03:32:59.998013 10927 master.cpp:902] Status update from slave@192.168.1.64:51054: task 64 of framework 201203290332-0-0001 is now in state TASK_RUNNING
I0329 03:33:00.000454 10927 master.cpp:902] Status update from slave@192.168.1.64:51054: task 61 of framework 201203290332-0-0001 is now in state TASK_RUNNING
I0329 03:33:00.221009 10927 master.cpp:1184] Sending 1 offers to framework 201203290332-0-0000
I0329 03:33:00.221215 10927 master.cpp:1184] Sending 1 offers to framework 201203290332-0-0001
I0329 03:33:00.222282 10927 master.cpp:679] Received reply for offer 201203290332-0-37
I0329 03:33:00.222432 10927 master.cpp:1403] Filtered slave 201203290332-0-0 for framework 201203290332-0-0000 for 1 seconds
I0329 03:33:00.223021 10927 master.cpp:679] Received reply for offer 201203290332-0-38
I0329 03:33:00.223206 10927 master.cpp:1184] Sending 1 offers to framework 201203290332-0-0001
I0329 03:33:00.223336 10927 master.cpp:1403] Filtered slave 201203290332-0-1 for framework 201203290332-0-0001 for 1 seconds
I0329 03:33:00.230605 10927 master.cpp:679] Received reply for offer 201203290332-0-39
I0329 03:33:00.230783 10927 master.cpp:1453] Launching task 65 on slave 201203290332-0-0
I0329 03:33:00.231071 10927 master.cpp:1453] Launching task 66 on slave 201203290332-0-0
I0329 03:33:00.231394 10927 master.cpp:1453] Launching task 67 on slave 201203290332-0-0
I0329 03:33:00.238193 10927 master.cpp:902] Status update from slave@192.168.1.64:51054: task 63 of framework 201203290332-0-0001 is now in state TASK_FAILED
I0329 03:33:00.238452 10927 master.cpp:1184] Sending 1 offers to framework 201203290332-0-0001
I0329 03:33:00.242653 10927 master.cpp:902] Status update from slave@192.168.1.64:51054: task 66 of framework 201203290332-0-0001 is now in state TASK_RUNNING
I0329 03:33:00.242804 10927 master.cpp:679] Received reply for offer 201203290332-0-40
I0329 03:33:00.243028 10927 master.cpp:1453] Launching task 68 on slave 201203290332-0-0
I0329 03:33:00.243322 10927 master.cpp:902] Status update from slave@192.168.1.64:51054: task 65 of framework 201203290332-0-0001 is now in state TASK_RUNNING
I0329 03:33:01.022228 10927 master.cpp:1001] Executor default of framework 201203290332-0-0001 on slave 201203290332-0-0 (azad.gateway.2wire.net) exited with status 256
I0329 03:33:01.023679 10927 master.cpp:1033] Removing task 68 of framework 201203290332-0-0001 because of lost executor
I0329 03:33:01.023905 10927 master.cpp:1184] Sending 1 offers to framework 201203290332-0-0001
I0329 03:33:01.025619 10927 master.cpp:1033] Removing task 67 of framework 201203290332-0-0001 because of lost executor
I0329 03:33:01.027237 10927 master.cpp:1033] Removing task 66 of framework 201203290332-0-0001 because of lost executor
I0329 03:33:01.028820 10927 master.cpp:1033] Removing task 65 of framework 201203290332-0-0001 because of lost executor
I0329 03:33:01.030354 10927 master.cpp:1033] Removing task 64 of framework 201203290332-0-0001 because of lost executor
I0329 03:33:01.031981 10927 master.cpp:1033] Removing task 62 of framework 201203290332-0-0001 because of lost executor
I0329 03:33:01.033589 10927 master.cpp:1033] Removing task 61 of framework 201203290332-0-0001 because of lost executor
I0329 03:33:01.035287 10927 master.cpp:1033] Removing task 60 of framework 201203290332-0-0001 because of lost executor
I0329 03:33:01.035521 10927 master.cpp:679] Received reply for offer 201203290332-0-41
I0329 03:33:01.035701 10927 master.cpp:1453] Launching task 69 on slave 201203290332-0-0
I0329 03:33:01.222389 10927 master.cpp:1184] Sending 1 offers to framework 201203290332-0-0000
I0329 03:33:01.223705 10927 master.cpp:679] Received reply for offer 201203290332-0-42
I0329 03:33:01.223847 10927 master.cpp:1403] Filtered slave 201203290332-0-1 for framework 201203290332-0-0000 for 1 seconds
I0329 03:33:01.987391 10927 master.cpp:1118] Framework 201203290332-0-0000 disconnected
I0329 03:33:01.987546 10927 master.cpp:1118] Framework 201203290332-0-0001 disconnected
I0329 03:42:08.963800 10927 master.cpp:492] Registering framework 201203290332-0-0002 at 3@192.168.1.64:39350
I0329 03:42:08.964042 10927 simple_allocator.cpp:48] Added framework 201203290332-0-0002
I0329 03:42:08.964287 10927 master.cpp:1184] Sending 2 offers to framework 201203290332-0-0002
I0329 03:42:08.964504 10927 master.cpp:492] Registering framework 201203290332-0-0003 at 2@192.168.1.64:39350
I0329 03:42:08.964665 10927 simple_allocator.cpp:48] Added framework 201203290332-0-0003
I0329 03:42:08.980875 10927 master.cpp:679] Received reply for offer 201203290332-0-43
I0329 03:42:08.981070 10927 master.cpp:1403] Filtered slave 201203290332-0-0 for framework 201203290332-0-0002 for 1 seconds
I0329 03:42:08.981173 10927 master.cpp:679] Received reply for offer 201203290332-0-44
I0329 03:42:08.981328 10927 master.cpp:1184] Sending 1 offers to framework 201203290332-0-0003
I0329 03:42:08.981448 10927 master.cpp:1403] Filtered slave 201203290332-0-1 for framework 201203290332-0-0002 for 1 seconds
I0329 03:42:08.982409 10927 master.cpp:679] Received reply for offer 201203290332-0-45
I0329 03:42:08.982650 10927 master.cpp:1403] Filtered slave 201203290332-0-0 for framework 201203290332-0-0003 for 1 seconds
I0329 03:42:09.324831 10927 master.cpp:718] Reviving offers for framework 201203290332-0-0002
I0329 03:42:09.324956 10927 simple_allocator.cpp:145] Filters removed for framework 201203290332-0-0002
I0329 03:42:09.325268 10927 master.cpp:1184] Sending 1 offers to framework 201203290332-0-0002
I0329 03:42:09.325532 10927 master.cpp:1184] Sending 1 offers to framework 201203290332-0-0003
I0329 03:42:09.398515 10927 master.cpp:679] Received reply for offer 201203290332-0-46
I0329 03:42:09.398711 10927 master.cpp:1453] Launching task 0 on slave 201203290332-0-0
I0329 03:42:09.399000 10927 master.cpp:1453] Launching task 1 on slave 201203290332-0-0
I0329 03:42:09.399550 10927 master.cpp:1453] Launching task 2 on slave 201203290332-0-0
I0329 03:42:09.399871 10927 master.cpp:1453] Launching task 3 on slave 201203290332-0-0
I0329 03:42:09.400320 10927 master.cpp:1453] Launching task 4 on slave 201203290332-0-0
I0329 03:42:09.400821 10927 master.cpp:1453] Launching task 5 on slave 201203290332-0-0
I0329 03:42:09.401113 10927 master.cpp:1453] Launching task 6 on slave 201203290332-0-0
I0329 03:42:09.401468 10927 master.cpp:679] Received reply for offer 201203290332-0-47
I0329 03:42:09.401589 10927 master.cpp:1403] Filtered slave 201203290332-0-1 for framework 201203290332-0-0003 for 1 seconds
I0329 03:42:10.368088 10927 master.cpp:902] Status update from slave@192.168.1.64:51054: task 5 of framework 201203290332-0-0002 is now in state TASK_RUNNING
I0329 03:42:10.370334 10927 master.cpp:902] Status update from slave@192.168.1.64:51054: task 3 of framework 201203290332-0-0002 is now in state TASK_RUNNING
I0329 03:42:10.373266 10927 master.cpp:902] Status update from slave@192.168.1.64:51054: task 2 of framework 201203290332-0-0002 is now in state TASK_RUNNING
I0329 03:42:10.376673 10927 master.cpp:902] Status update from slave@192.168.1.64:51054: task 1 of framework 201203290332-0-0002 is now in state TASK_RUNNING
I0329 03:42:10.380033 10927 master.cpp:902] Status update from slave@192.168.1.64:51054: task 0 of framework 201203290332-0-0002 is now in state TASK_RUNNING
I0329 03:42:10.383348 10927 master.cpp:902] Status update from slave@192.168.1.64:51054: task 6 of framework 201203290332-0-0002 is now in state TASK_RUNNING
I0329 03:42:10.385586 10927 master.cpp:902] Status update from slave@192.168.1.64:51054: task 4 of framework 201203290332-0-0002 is now in state TASK_RUNNING
I0329 03:42:11.526597 10927 master.cpp:902] Status update from slave@192.168.1.64:51054: task 2 of framework 201203290332-0-0002 is now in state TASK_FINISHED
I0329 03:42:11.526813 10927 master.cpp:1184] Sending 1 offers to framework 201203290332-0-0003
I0329 03:42:11.528723 10927 master.cpp:902] Status update from slave@192.168.1.64:51054: task 6 of framework 201203290332-0-0002 is now in state TASK_FINISHED
I0329 03:42:11.531059 10927 master.cpp:902] Status update from slave@192.168.1.64:51054: task 5 of framework 201203290332-0-0002 is now in state TASK_FINISHED
I0329 03:42:11.544509 10927 master.cpp:679] Received reply for offer 201203290332-0-48
I0329 03:42:11.544677 10927 master.cpp:1403] Filtered slave 201203290332-0-0 for framework 201203290332-0-0003 for 1 seconds
I0329 03:42:11.567430 10927 master.cpp:902] Status update from slave@192.168.1.64:51054: task 4 of framework 201203290332-0-0002 is now in state TASK_FINISHED
I0329 03:42:11.567657 10927 master.cpp:1184] Sending 1 offers to framework 201203290332-0-0002
I0329 03:42:11.568079 10927 master.cpp:902] Status update from slave@192.168.1.64:51054: task 0 of framework 201203290332-0-0002 is now in state TASK_FINISHED
I0329 03:42:11.568747 10927 master.cpp:902] Status update from slave@192.168.1.64:51054: task 1 of framework 201203290332-0-0002 is now in state TASK_FINISHED
I0329 03:42:11.569313 10927 master.cpp:902] Status update from slave@192.168.1.64:51054: task 3 of framework 201203290332-0-0002 is now in state TASK_FINISHED
I0329 03:42:11.595234 10927 master.cpp:679] Received reply for offer 201203290332-0-49
I0329 03:42:11.595573 10927 master.cpp:1453] Launching task 7 on slave 201203290332-0-0
I0329 03:42:11.595953 10927 master.cpp:1453] Launching task 8 on slave 201203290332-0-0
I0329 03:42:11.596309 10927 master.cpp:1453] Launching task 9 on slave 201203290332-0-0
I0329 03:42:11.596421 10927 master.cpp:1453] Launching task 10 on slave 201203290332-0-0
I0329 03:42:11.607285 10927 master.cpp:902] Status update from slave@192.168.1.64:51054: task 7 of framework 201203290332-0-0002 is now in state TASK_RUNNING
I0329 03:42:11.607460 10927 master.cpp:902] Status update from slave@192.168.1.64:51054: task 8 of framework 201203290332-0-0002 is now in state TASK_RUNNING
I0329 03:42:11.607688 10927 master.cpp:902] Status update from slave@192.168.1.64:51054: task 9 of framework 201203290332-0-0002 is now in state TASK_RUNNING
I0329 03:42:11.611258 10927 master.cpp:902] Status update from slave@192.168.1.64:51054: task 10 of framework 201203290332-0-0002 is now in state TASK_RUNNING
I0329 03:42:11.671699 10927 master.cpp:902] Status update from slave@192.168.1.64:51054: task 10 of framework 201203290332-0-0002 is now in state TASK_FINISHED
I0329 03:42:11.671970 10927 master.cpp:1184] Sending 1 offers to framework 201203290332-0-0002
I0329 03:42:11.681310 10927 master.cpp:902] Status update from slave@192.168.1.64:51054: task 8 of framework 201203290332-0-0002 is now in state TASK_FINISHED
I0329 03:42:11.694226 10927 master.cpp:902] Status update from slave@192.168.1.64:51054: task 7 of framework 201203290332-0-0002 is now in state TASK_FINISHED
I0329 03:42:11.696584 10927 master.cpp:679] Received reply for offer 201203290332-0-50
I0329 03:42:11.696708 10927 master.cpp:1453] Launching task 11 on slave 201203290332-0-0
I0329 03:42:11.697134 10927 master.cpp:1453] Launching task 12 on slave 201203290332-0-0
I0329 03:42:11.697458 10927 master.cpp:1453] Launching task 13 on slave 201203290332-0-0
I0329 03:42:11.697662 10927 master.cpp:1453] Launching task 14 on slave 201203290332-0-0
I0329 03:42:11.731354 10927 master.cpp:902] Status update from slave@192.168.1.64:51054: task 9 of framework 201203290332-0-0002 is now in state TASK_FINISHED
I0329 03:42:11.731665 10927 master.cpp:1184] Sending 1 offers to framework 201203290332-0-0002
I0329 03:42:11.731824 10927 master.cpp:902] Status update from slave@192.168.1.64:51054: task 11 of framework 201203290332-0-0002 is now in state TASK_RUNNING
I0329 03:42:11.732118 10927 master.cpp:902] Status update from slave@192.168.1.64:51054: task 12 of framework 201203290332-0-0002 is now in state TASK_RUNNING
I0329 03:42:11.732300 10927 master.cpp:902] Status update from slave@192.168.1.64:51054: task 13 of framework 201203290332-0-0002 is now in state TASK_RUNNING
I0329 03:42:11.732476 10927 master.cpp:902] Status update from slave@192.168.1.64:51054: task 14 of framework 201203290332-0-0002 is now in state TASK_RUNNING
I0329 03:42:11.748597 10927 master.cpp:679] Received reply for offer 201203290332-0-51
I0329 03:42:11.748781 10927 master.cpp:1453] Launching task 15 on slave 201203290332-0-0
I0329 03:42:11.749095 10927 master.cpp:1453] Launching task 16 on slave 201203290332-0-0
I0329 03:42:11.749366 10927 master.cpp:1453] Launching task 17 on slave 201203290332-0-0
I0329 03:42:11.771256 10927 master.cpp:902] Status update from slave@192.168.1.64:51054: task 15 of framework 201203290332-0-0002 is now in state TASK_RUNNING
I0329 03:42:11.773339 10927 master.cpp:902] Status update from slave@192.168.1.64:51054: task 16 of framework 201203290332-0-0002 is now in state TASK_RUNNING
I0329 03:42:11.788609 10927 master.cpp:902] Status update from slave@192.168.1.64:51054: task 12 of framework 201203290332-0-0002 is now in state TASK_FINISHED
I0329 03:42:11.788871 10927 master.cpp:1184] Sending 1 offers to framework 201203290332-0-0002
I0329 03:42:11.792161 10927 master.cpp:902] Status update from slave@192.168.1.64:51054: task 17 of framework 201203290332-0-0002 is now in state TASK_RUNNING
I0329 03:42:11.801564 10927 master.cpp:902] Status update from slave@192.168.1.64:51054: task 11 of framework 201203290332-0-0002 is now in state TASK_FINISHED
I0329 03:42:11.807875 10927 master.cpp:902] Status update from slave@192.168.1.64:51054: task 13 of framework 201203290332-0-0002 is now in state TASK_FINISHED
I0329 03:42:11.836640 10927 master.cpp:679] Received reply for offer 201203290332-0-52
I0329 03:42:11.836817 10927 master.cpp:1453] Launching task 18 on slave 201203290332-0-0
I0329 03:42:11.847319 10927 master.cpp:902] Status update from slave@192.168.1.64:51054: task 18 of framework 201203290332-0-0002 is now in state TASK_RUNNING
I0329 03:42:11.847995 10927 master.cpp:902] Status update from slave@192.168.1.64:51054: task 16 of framework 201203290332-0-0002 is now in state TASK_FINISHED
I0329 03:42:11.848178 10927 master.cpp:1184] Sending 1 offers to framework 201203290332-0-0002
I0329 03:42:11.878378 10927 master.cpp:679] Received reply for offer 201203290332-0-53
I0329 03:42:11.878527 10927 master.cpp:1453] Launching task 19 on slave 201203290332-0-0
I0329 03:42:11.878778 10927 master.cpp:1453] Launching task 20 on slave 201203290332-0-0
I0329 03:42:11.878975 10927 master.cpp:1453] Launching task 21 on slave 201203290332-0-0
I0329 03:42:11.887261 10927 master.cpp:902] Status update from slave@192.168.1.64:51054: task 15 of framework 201203290332-0-0002 is now in state TASK_FINISHED
I0329 03:42:11.887514 10927 master.cpp:1184] Sending 1 offers to framework 201203290332-0-0002
I0329 03:42:11.887657 10927 master.cpp:902] Status update from slave@192.168.1.64:51054: task 19 of framework 201203290332-0-0002 is now in state TASK_RUNNING
I0329 03:42:11.887924 10927 master.cpp:902] Status update from slave@192.168.1.64:51054: task 17 of framework 201203290332-0-0002 is now in state TASK_FINISHED
I0329 03:42:11.895635 10927 master.cpp:679] Received reply for offer 201203290332-0-54
I0329 03:42:11.895762 10927 master.cpp:1453] Launching task 22 on slave 201203290332-0-0
I0329 03:42:11.931316 10927 master.cpp:902] Status update from slave@192.168.1.64:51054: task 20 of framework 201203290332-0-0002 is now in state TASK_RUNNING
I0329 03:42:11.931535 10927 master.cpp:902] Status update from slave@192.168.1.64:51054: task 21 of framework 201203290332-0-0002 is now in state TASK_RUNNING
I0329 03:42:11.931766 10927 master.cpp:902] Status update from slave@192.168.1.64:51054: task 22 of framework 201203290332-0-0002 is now in state TASK_RUNNING
I0329 03:42:11.932091 10927 master.cpp:902] Status update from slave@192.168.1.64:51054: task 18 of framework 201203290332-0-0002 is now in state TASK_FINISHED
I0329 03:42:11.932849 10927 master.cpp:1184] Sending 1 offers to framework 201203290332-0-0002
I0329 03:42:11.943259 10927 master.cpp:679] Received reply for offer 201203290332-0-55
I0329 03:42:11.943442 10927 master.cpp:1453] Launching task 23 on slave 201203290332-0-0
I0329 03:42:11.943709 10927 master.cpp:1453] Launching task 24 on slave 201203290332-0-0
I0329 03:42:11.971366 10927 master.cpp:902] Status update from slave@192.168.1.64:51054: task 23 of framework 201203290332-0-0002 is now in state TASK_RUNNING
I0329 03:42:11.971592 10927 master.cpp:902] Status update from slave@192.168.1.64:51054: task 19 of framework 201203290332-0-0002 is now in state TASK_FINISHED
I0329 03:42:11.971917 10927 master.cpp:1184] Sending 1 offers to framework 201203290332-0-0002
I0329 03:42:11.979610 10927 master.cpp:902] Status update from slave@192.168.1.64:51054: task 22 of framework 201203290332-0-0002 is now in state TASK_FINISHED
I0329 03:42:11.982028 10927 master.cpp:902] Status update from slave@192.168.1.64:51054: task 21 of framework 201203290332-0-0002 is now in state TASK_FINISHED
I0329 03:42:11.982270 10927 master.cpp:679] Received reply for offer 201203290332-0-56
I0329 03:42:11.982395 10927 master.cpp:1453] Launching task 25 on slave 201203290332-0-0
I0329 03:42:12.019283 10927 master.cpp:902] Status update from slave@192.168.1.64:51054: task 20 of framework 201203290332-0-0002 is now in state TASK_FINISHED
I0329 03:42:12.019577 10927 master.cpp:1184] Sending 1 offers to framework 201203290332-0-0002
I0329 03:42:12.019767 10927 master.cpp:902] Status update from slave@192.168.1.64:51054: task 25 of framework 201203290332-0-0002 is now in state TASK_RUNNING
I0329 03:42:12.020300 10927 master.cpp:902] Status update from slave@192.168.1.64:51054: task 24 of framework 201203290332-0-0002 is now in state TASK_RUNNING
I0329 03:42:12.020787 10927 master.cpp:902] Status update from slave@192.168.1.64:51054: task 14 of framework 201203290332-0-0002 is now in state TASK_FINISHED
I0329 03:42:12.063303 10927 master.cpp:902] Status update from slave@192.168.1.64:51054: task 23 of framework 201203290332-0-0002 is now in state TASK_FINISHED
I0329 03:42:12.063581 10927 master.cpp:902] Status update from slave@192.168.1.64:51054: task 25 of framework 201203290332-0-0002 is now in state TASK_FINISHED
I0329 03:42:12.065661 10927 master.cpp:679] Received reply for offer 201203290332-0-57
I0329 03:42:12.065816 10927 master.cpp:1453] Launching task 26 on slave 201203290332-0-0
I0329 03:42:12.065981 10927 master.cpp:1453] Launching task 27 on slave 201203290332-0-0
I0329 03:42:12.066134 10927 master.cpp:1453] Launching task 28 on slave 201203290332-0-0
I0329 03:42:12.070515 10927 master.cpp:902] Status update from slave@192.168.1.64:51054: task 26 of framework 201203290332-0-0002 is now in state TASK_RUNNING
I0329 03:42:12.072749 10927 master.cpp:902] Status update from slave@192.168.1.64:51054: task 27 of framework 201203290332-0-0002 is now in state TASK_RUNNING
I0329 03:42:12.075156 10927 master.cpp:902] Status update from slave@192.168.1.64:51054: task 24 of framework 201203290332-0-0002 is now in state TASK_FINISHED
I0329 03:42:12.075407 10927 master.cpp:1184] Sending 1 offers to framework 201203290332-0-0002
I0329 03:42:12.114195 10927 master.cpp:902] Status update from slave@192.168.1.64:51054: task 28 of framework 201203290332-0-0002 is now in state TASK_RUNNING
I0329 03:42:12.115231 10927 master.cpp:679] Received reply for offer 201203290332-0-58
I0329 03:42:12.115382 10927 master.cpp:1453] Launching task 29 on slave 201203290332-0-0
I0329 03:42:12.115679 10927 master.cpp:1453] Launching task 30 on slave 201203290332-0-0
I0329 03:42:12.115880 10927 master.cpp:1453] Launching task 31 on slave 201203290332-0-0
I0329 03:42:12.116109 10927 master.cpp:1453] Launching task 32 on slave 201203290332-0-0
I0329 03:42:12.123663 10927 master.cpp:902] Status update from slave@192.168.1.64:51054: task 29 of framework 201203290332-0-0002 is now in state TASK_RUNNING
I0329 03:42:12.124457 10927 master.cpp:902] Status update from slave@192.168.1.64:51054: task 30 of framework 201203290332-0-0002 is now in state TASK_RUNNING
I0329 03:42:12.126924 10927 master.cpp:902] Status update from slave@192.168.1.64:51054: task 31 of framework 201203290332-0-0002 is now in state TASK_RUNNING
I0329 03:42:12.134296 10927 master.cpp:902] Status update from slave@192.168.1.64:51054: task 32 of framework 201203290332-0-0002 is now in state TASK_RUNNING
I0329 03:42:12.134493 10927 master.cpp:902] Status update from slave@192.168.1.64:51054: task 27 of framework 201203290332-0-0002 is now in state TASK_FINISHED
I0329 03:42:12.134867 10927 master.cpp:1184] Sending 1 offers to framework 201203290332-0-0002
I0329 03:42:12.143578 10927 master.cpp:902] Status update from slave@192.168.1.64:51054: task 26 of framework 201203290332-0-0002 is now in state TASK_FINISHED
I0329 03:42:12.145066 10927 master.cpp:679] Received reply for offer 201203290332-0-59
I0329 03:42:12.145200 10927 master.cpp:1453] Launching task 33 on slave 201203290332-0-0
I0329 03:42:12.183291 10927 master.cpp:902] Status update from slave@192.168.1.64:51054: task 33 of framework 201203290332-0-0002 is now in state TASK_RUNNING
I0329 03:42:12.195430 10927 master.cpp:902] Status update from slave@192.168.1.64:51054: task 28 of framework 201203290332-0-0002 is now in state TASK_FINISHED
I0329 03:42:12.195696 10927 master.cpp:1184] Sending 1 offers to framework 201203290332-0-0002
I0329 03:42:12.202266 10927 master.cpp:679] Received reply for offer 201203290332-0-60
I0329 03:42:12.202394 10927 master.cpp:1453] Launching task 34 on slave 201203290332-0-0
I0329 03:42:12.202734 10927 master.cpp:1453] Launching task 35 on slave 201203290332-0-0
I0329 03:42:12.239266 10927 master.cpp:902] Status update from slave@192.168.1.64:51054: task 30 of framework 201203290332-0-0002 is now in state TASK_FINISHED
I0329 03:42:12.239564 10927 master.cpp:1184] Sending 1 offers to framework 201203290332-0-0002
I0329 03:42:12.239668 10927 master.cpp:902] Status update from slave@192.168.1.64:51054: task 29 of framework 201203290332-0-0002 is now in state TASK_FINISHED
I0329 03:42:12.240187 10927 master.cpp:902] Status update from slave@192.168.1.64:51054: task 34 of framework 201203290332-0-0002 is now in state TASK_RUNNING
I0329 03:42:12.240623 10927 master.cpp:902] Status update from slave@192.168.1.64:51054: task 31 of framework 201203290332-0-0002 is now in state TASK_FINISHED
I0329 03:42:12.241183 10927 master.cpp:902] Status update from slave@192.168.1.64:51054: task 32 of framework 201203290332-0-0002 is now in state TASK_FINISHED
I0329 03:42:12.244161 10927 master.cpp:679] Received reply for offer 201203290332-0-61
I0329 03:42:12.244334 10927 master.cpp:1453] Launching task 36 on slave 201203290332-0-0
I0329 03:42:12.279441 10927 master.cpp:902] Status update from slave@192.168.1.64:51054: task 33 of framework 201203290332-0-0002 is now in state TASK_FINISHED
I0329 03:42:12.279608 10927 master.cpp:1184] Sending 1 offers to framework 201203290332-0-0002
I0329 03:42:12.280029 10927 master.cpp:902] Status update from slave@192.168.1.64:51054: task 35 of framework 201203290332-0-0002 is now in state TASK_RUNNING
I0329 03:42:12.280261 10927 master.cpp:902] Status update from slave@192.168.1.64:51054: task 34 of framework 201203290332-0-0002 is now in state TASK_FINISHED
I0329 03:42:12.282799 10927 master.cpp:902] Status update from slave@192.168.1.64:51054: task 36 of framework 201203290332-0-0002 is now in state TASK_RUNNING
I0329 03:42:12.319855 10927 master.cpp:902] Status update from slave@192.168.1.64:51054: task 35 of framework 201203290332-0-0002 is now in state TASK_FINISHED
I0329 03:42:12.325314 10927 master.cpp:679] Received reply for offer 201203290332-0-62
I0329 03:42:12.325471 10927 master.cpp:1453] Launching task 37 on slave 201203290332-0-0
I0329 03:42:12.325744 10927 master.cpp:1453] Launching task 38 on slave 201203290332-0-0
I0329 03:42:12.326000 10927 master.cpp:1453] Launching task 39 on slave 201203290332-0-0
I0329 03:42:12.329193 10927 master.cpp:902] Status update from slave@192.168.1.64:51054: task 37 of framework 201203290332-0-0002 is now in state TASK_RUNNING
I0329 03:42:12.330703 10927 master.cpp:902] Status update from slave@192.168.1.64:51054: task 38 of framework 201203290332-0-0002 is now in state TASK_RUNNING
I0329 03:42:12.332362 10927 master.cpp:902] Status update from slave@192.168.1.64:51054: task 36 of framework 201203290332-0-0002 is now in state TASK_FINISHED
I0329 03:42:12.332515 10927 master.cpp:1184] Sending 1 offers to framework 201203290332-0-0002
I0329 03:42:12.334588 10927 master.cpp:902] Status update from slave@192.168.1.64:51054: task 39 of framework 201203290332-0-0002 is now in state TASK_RUNNING
I0329 03:42:12.362825 10927 master.cpp:679] Received reply for offer 201203290332-0-63
I0329 03:42:12.362988 10927 master.cpp:1403] Filtered slave 201203290332-0-0 for framework 201203290332-0-0002 for 1 seconds
I0329 03:42:12.381008 10927 master.cpp:902] Status update from slave@192.168.1.64:51054: task 39 of framework 201203290332-0-0002 is now in state TASK_FINISHED
I0329 03:42:12.393800 10927 master.cpp:902] Status update from slave@192.168.1.64:51054: task 37 of framework 201203290332-0-0002 is now in state TASK_FINISHED
I0329 03:42:12.431366 10927 master.cpp:902] Status update from slave@192.168.1.64:51054: task 38 of framework 201203290332-0-0002 is now in state TASK_FINISHED
I0329 03:42:12.449151 10927 master.cpp:718] Reviving offers for framework 201203290332-0-0002
I0329 03:42:12.449277 10927 simple_allocator.cpp:145] Filters removed for framework 201203290332-0-0002
I0329 03:42:12.449575 10927 master.cpp:1184] Sending 1 offers to framework 201203290332-0-0002
I0329 03:42:12.469735 10927 master.cpp:679] Received reply for offer 201203290332-0-64
I0329 03:42:12.469893 10927 master.cpp:1453] Launching task 40 on slave 201203290332-0-0
I0329 03:42:12.470182 10927 master.cpp:1453] Launching task 41 on slave 201203290332-0-0
I0329 03:42:12.470396 10927 master.cpp:1453] Launching task 42 on slave 201203290332-0-0
I0329 03:42:12.470569 10927 master.cpp:1453] Launching task 43 on slave 201203290332-0-0
I0329 03:42:12.471168 10927 master.cpp:1453] Launching task 44 on slave 201203290332-0-0
I0329 03:42:12.471699 10927 master.cpp:1453] Launching task 45 on slave 201203290332-0-0
I0329 03:42:12.472129 10927 master.cpp:1453] Launching task 46 on slave 201203290332-0-0
I0329 03:42:12.473935 10927 master.cpp:902] Status update from slave@192.168.1.64:51054: task 40 of framework 201203290332-0-0002 is now in state TASK_RUNNING
I0329 03:42:12.480556 10927 master.cpp:902] Status update from slave@192.168.1.64:51054: task 41 of framework 201203290332-0-0002 is now in state TASK_RUNNING
I0329 03:42:12.480711 10927 master.cpp:902] Status update from slave@192.168.1.64:51054: task 42 of framework 201203290332-0-0002 is now in state TASK_RUNNING
I0329 03:42:12.481020 10927 master.cpp:902] Status update from slave@192.168.1.64:51054: task 43 of framework 201203290332-0-0002 is now in state TASK_RUNNING
I0329 03:42:12.485831 10927 master.cpp:902] Status update from slave@192.168.1.64:51054: task 45 of framework 201203290332-0-0002 is now in state TASK_RUNNING
I0329 03:42:12.486048 10927 master.cpp:902] Status update from slave@192.168.1.64:51054: task 44 of framework 201203290332-0-0002 is now in state TASK_RUNNING
I0329 03:42:12.509579 10927 master.cpp:902] Status update from slave@192.168.1.64:51054: task 42 of framework 201203290332-0-0002 is now in state TASK_FAILED
I0329 03:42:12.509840 10927 master.cpp:1184] Sending 1 offers to framework 201203290332-0-0002
I0329 03:42:12.527180 10927 master.cpp:679] Received reply for offer 201203290332-0-65
I0329 03:42:12.527356 10927 master.cpp:1453] Launching task 47 on slave 201203290332-0-0
I0329 03:42:12.547698 10927 master.cpp:902] Status update from slave@192.168.1.64:51054: task 40 of framework 201203290332-0-0002 is now in state TASK_FAILED
I0329 03:42:12.547911 10927 master.cpp:1184] Sending 1 offers to framework 201203290332-0-0002
I0329 03:42:12.555338 10927 master.cpp:679] Received reply for offer 201203290332-0-66
I0329 03:42:12.555495 10927 master.cpp:1453] Launching task 48 on slave 201203290332-0-0
I0329 03:42:12.587347 10927 master.cpp:902] Status update from slave@192.168.1.64:51054: task 43 of framework 201203290332-0-0002 is now in state TASK_FAILED
I0329 03:42:12.587623 10927 master.cpp:1184] Sending 1 offers to framework 201203290332-0-0002
I0329 03:42:12.588001 10927 master.cpp:902] Status update from slave@192.168.1.64:51054: task 41 of framework 201203290332-0-0002 is now in state TASK_FAILED
I0329 03:42:12.588546 10927 master.cpp:902] Status update from slave@192.168.1.64:51054: task 45 of framework 201203290332-0-0002 is now in state TASK_FAILED
I0329 03:42:12.588976 10927 master.cpp:902] Status update from slave@192.168.1.64:51054: task 44 of framework 201203290332-0-0002 is now in state TASK_FAILED
I0329 03:42:12.589213 10927 master.cpp:902] Status update from slave@192.168.1.64:51054: task 46 of framework 201203290332-0-0002 is now in state TASK_RUNNING
I0329 03:42:12.589800 10927 master.cpp:902] Status update from slave@192.168.1.64:51054: task 46 of framework 201203290332-0-0002 is now in state TASK_FAILED
I0329 03:42:12.597164 10927 master.cpp:679] Received reply for offer 201203290332-0-67
I0329 03:42:12.597318 10927 master.cpp:1453] Launching task 49 on slave 201203290332-0-0
I0329 03:42:12.627573 10927 master.cpp:902] Status update from slave@192.168.1.64:51054: task 47 of framework 201203290332-0-0002 is now in state TASK_RUNNING
I0329 03:42:12.627784 10927 master.cpp:902] Status update from slave@192.168.1.64:51054: task 47 of framework 201203290332-0-0002 is now in state TASK_FAILED
I0329 03:42:12.628077 10927 master.cpp:1184] Sending 1 offers to framework 201203290332-0-0002
I0329 03:42:12.629533 10927 master.cpp:902] Status update from slave@192.168.1.64:51054: task 48 of framework 201203290332-0-0002 is now in state TASK_RUNNING
I0329 03:42:12.630452 10927 master.cpp:902] Status update from slave@192.168.1.64:51054: task 49 of framework 201203290332-0-0002 is now in state TASK_RUNNING
I0329 03:42:12.682863 10927 master.cpp:679] Received reply for offer 201203290332-0-68
I0329 03:42:12.683049 10927 master.cpp:1453] Launching task 50 on slave 201203290332-0-0
I0329 03:42:12.683457 10927 master.cpp:1453] Launching task 51 on slave 201203290332-0-0
I0329 03:42:12.683722 10927 master.cpp:1453] Launching task 52 on slave 201203290332-0-0
I0329 03:42:12.683864 10927 master.cpp:1453] Launching task 53 on slave 201203290332-0-0
I0329 03:42:12.684571 10927 master.cpp:1453] Launching task 54 on slave 201203290332-0-0
I0329 03:42:13.718348 10927 master.cpp:1001] Executor default of framework 201203290332-0-0002 on slave 201203290332-0-0 (azad.gateway.2wire.net) exited with status 256
I0329 03:42:13.719868 10927 master.cpp:1033] Removing task 54 of framework 201203290332-0-0002 because of lost executor
I0329 03:42:13.806668 10927 master.cpp:1184] Sending 1 offers to framework 201203290332-0-0003
I0329 03:42:13.808491 10927 master.cpp:1033] Removing task 52 of framework 201203290332-0-0002 because of lost executor
I0329 03:42:13.810322 10927 master.cpp:1033] Removing task 53 of framework 201203290332-0-0002 because of lost executor
I0329 03:42:13.811997 10927 master.cpp:1033] Removing task 50 of framework 201203290332-0-0002 because of lost executor
I0329 03:42:13.813657 10927 master.cpp:1033] Removing task 51 of framework 201203290332-0-0002 because of lost executor
I0329 03:42:13.815284 10927 master.cpp:1033] Removing task 49 of framework 201203290332-0-0002 because of lost executor
I0329 03:42:13.816584 10927 master.cpp:1033] Removing task 48 of framework 201203290332-0-0002 because of lost executor
I0329 03:42:13.816808 10927 master.cpp:679] Received reply for offer 201203290332-0-69
I0329 03:42:13.817047 10927 master.cpp:1184] Sending 1 offers to framework 201203290332-0-0002
I0329 03:42:13.817200 10927 master.cpp:1403] Filtered slave 201203290332-0-0 for framework 201203290332-0-0003 for 1 seconds
I0329 03:42:13.831852 10927 master.cpp:679] Received reply for offer 201203290332-0-70
I0329 03:42:13.832010 10927 master.cpp:1453] Launching task 55 on slave 201203290332-0-0
I0329 03:42:13.832255 10927 master.cpp:1453] Launching task 56 on slave 201203290332-0-0
I0329 03:42:13.832412 10927 master.cpp:1453] Launching task 57 on slave 201203290332-0-0
I0329 03:42:13.832519 10927 master.cpp:1453] Launching task 58 on slave 201203290332-0-0
I0329 03:42:13.833149 10927 master.cpp:1453] Launching task 59 on slave 201203290332-0-0
I0329 03:42:13.833596 10927 master.cpp:1453] Launching task 60 on slave 201203290332-0-0
I0329 03:42:13.888368 10927 master.cpp:1184] Sending 1 offers to framework 201203290332-0-0002
I0329 03:42:13.893270 10927 master.cpp:679] Received reply for offer 201203290332-0-71
I0329 03:42:13.893422 10927 master.cpp:1453] Launching task 61 on slave 201203290332-0-0
I0329 03:42:14.787441 10927 master.cpp:902] Status update from slave@192.168.1.64:51054: task 58 of framework 201203290332-0-0002 is now in state TASK_RUNNING
I0329 03:42:14.789731 10927 master.cpp:902] Status update from slave@192.168.1.64:51054: task 55 of framework 201203290332-0-0002 is now in state TASK_RUNNING
I0329 03:42:14.793005 10927 master.cpp:902] Status update from slave@192.168.1.64:51054: task 59 of framework 201203290332-0-0002 is now in state TASK_RUNNING
I0329 03:42:14.799268 10927 master.cpp:902] Status update from slave@192.168.1.64:51054: task 61 of framework 201203290332-0-0002 is now in state TASK_RUNNING
I0329 03:42:14.800501 10927 master.cpp:902] Status update from slave@192.168.1.64:51054: task 56 of framework 201203290332-0-0002 is now in state TASK_RUNNING
I0329 03:42:14.803002 10927 master.cpp:902] Status update from slave@192.168.1.64:51054: task 57 of framework 201203290332-0-0002 is now in state TASK_RUNNING
I0329 03:42:14.805608 10927 master.cpp:902] Status update from slave@192.168.1.64:51054: task 60 of framework 201203290332-0-0002 is now in state TASK_RUNNING
I0329 03:42:15.084580 10927 master.cpp:902] Status update from slave@192.168.1.64:51054: task 57 of framework 201203290332-0-0002 is now in state TASK_FAILED
I0329 03:42:15.084858 10927 master.cpp:1184] Sending 1 offers to framework 201203290332-0-0003
I0329 03:42:15.086546 10927 master.cpp:902] Status update from slave@192.168.1.64:51054: task 56 of framework 201203290332-0-0002 is now in state TASK_FAILED
I0329 03:42:15.088331 10927 master.cpp:902] Status update from slave@192.168.1.64:51054: task 61 of framework 201203290332-0-0002 is now in state TASK_FAILED
I0329 03:42:15.088556 10927 master.cpp:679] Received reply for offer 201203290332-0-72
I0329 03:42:15.088695 10927 master.cpp:1403] Filtered slave 201203290332-0-0 for framework 201203290332-0-0003 for 1 seconds
I0329 03:42:15.127542 10927 master.cpp:902] Status update from slave@192.168.1.64:51054: task 59 of framework 201203290332-0-0002 is now in state TASK_FAILED
I0329 03:42:15.127769 10927 master.cpp:1184] Sending 1 offers to framework 201203290332-0-0002
I0329 03:42:15.128062 10927 master.cpp:902] Status update from slave@192.168.1.64:51054: task 60 of framework 201203290332-0-0002 is now in state TASK_FAILED
I0329 03:42:15.128568 10927 master.cpp:902] Status update from slave@192.168.1.64:51054: task 55 of framework 201203290332-0-0002 is now in state TASK_FAILED
I0329 03:42:15.129034 10927 master.cpp:902] Status update from slave@192.168.1.64:51054: task 58 of framework 201203290332-0-0002 is now in state TASK_FAILED
I0329 03:42:15.138020 10927 master.cpp:679] Received reply for offer 201203290332-0-73
I0329 03:42:15.138159 10927 master.cpp:1453] Launching task 62 on slave 201203290332-0-0
I0329 03:42:15.138635 10927 master.cpp:1453] Launching task 63 on slave 201203290332-0-0
I0329 03:42:15.138815 10927 master.cpp:1453] Launching task 64 on slave 201203290332-0-0
I0329 03:42:15.139010 10927 master.cpp:1453] Launching task 65 on slave 201203290332-0-0
I0329 03:42:15.719460 10927 master.cpp:1001] Executor default of framework 201203290332-0-0002 on slave 201203290332-0-0 (azad.gateway.2wire.net) exited with status 256
I0329 03:42:15.720911 10927 master.cpp:1033] Removing task 65 of framework 201203290332-0-0002 because of lost executor
I0329 03:42:15.721107 10927 master.cpp:1184] Sending 1 offers to framework 201203290332-0-0002
I0329 03:42:15.722674 10927 master.cpp:1033] Removing task 64 of framework 201203290332-0-0002 because of lost executor
I0329 03:42:15.724174 10927 master.cpp:1033] Removing task 63 of framework 201203290332-0-0002 because of lost executor
I0329 03:42:15.725663 10927 master.cpp:1033] Removing task 62 of framework 201203290332-0-0002 because of lost executor
I0329 03:42:15.731142 10927 master.cpp:679] Received reply for offer 201203290332-0-74
I0329 03:42:15.731323 10927 master.cpp:1453] Launching task 66 on slave 201203290332-0-0
I0329 03:42:15.731533 10927 master.cpp:1453] Launching task 67 on slave 201203290332-0-0
I0329 03:42:15.731770 10927 master.cpp:1453] Launching task 68 on slave 201203290332-0-0
I0329 03:42:15.731991 10927 master.cpp:1453] Launching task 69 on slave 201203290332-0-0
I0329 03:42:16.672791 10927 master.cpp:902] Status update from slave@192.168.1.64:51054: task 66 of framework 201203290332-0-0002 is now in state TASK_RUNNING
I0329 03:42:16.674803 10927 master.cpp:902] Status update from slave@192.168.1.64:51054: task 69 of framework 201203290332-0-0002 is now in state TASK_RUNNING
I0329 03:42:16.677953 10927 master.cpp:902] Status update from slave@192.168.1.64:51054: task 67 of framework 201203290332-0-0002 is now in state TASK_RUNNING
I0329 03:42:16.681298 10927 master.cpp:902] Status update from slave@192.168.1.64:51054: task 68 of framework 201203290332-0-0002 is now in state TASK_RUNNING
I0329 03:42:16.890853 10927 master.cpp:1184] Sending 1 offers to framework 201203290332-0-0003
I0329 03:42:16.892074 10927 master.cpp:679] Received reply for offer 201203290332-0-75
I0329 03:42:16.892201 10927 master.cpp:1403] Filtered slave 201203290332-0-0 for framework 201203290332-0-0003 for 1 seconds
I0329 03:42:16.916975 10927 master.cpp:902] Status update from slave@192.168.1.64:51054: task 68 of framework 201203290332-0-0002 is now in state TASK_FAILED
I0329 03:42:16.917240 10927 master.cpp:1184] Sending 1 offers to framework 201203290332-0-0002
I0329 03:42:16.919715 10927 master.cpp:902] Status update from slave@192.168.1.64:51054: task 69 of framework 201203290332-0-0002 is now in state TASK_FAILED
I0329 03:42:16.926692 10927 master.cpp:679] Received reply for offer 201203290332-0-76
I0329 03:42:16.926833 10927 master.cpp:1453] Launching task 70 on slave 201203290332-0-0
I0329 03:42:16.927171 10927 master.cpp:1453] Launching task 71 on slave 201203290332-0-0
I0329 03:42:16.927495 10927 master.cpp:1453] Launching task 72 on slave 201203290332-0-0
I0329 03:42:16.927588 10927 master.cpp:1453] Launching task 73 on slave 201203290332-0-0
I0329 03:42:17.720324 10927 master.cpp:1001] Executor default of framework 201203290332-0-0002 on slave 201203290332-0-0 (azad.gateway.2wire.net) exited with status 256
I0329 03:42:17.721791 10927 master.cpp:1033] Removing task 67 of framework 201203290332-0-0002 because of lost executor
I0329 03:42:17.721989 10927 master.cpp:1184] Sending 1 offers to framework 201203290332-0-0002
I0329 03:42:17.723778 10927 master.cpp:1033] Removing task 66 of framework 201203290332-0-0002 because of lost executor
I0329 03:42:17.725430 10927 master.cpp:1033] Removing task 70 of framework 201203290332-0-0002 because of lost executor
I0329 03:42:17.726939 10927 master.cpp:1033] Removing task 71 of framework 201203290332-0-0002 because of lost executor
I0329 03:42:17.728735 10927 master.cpp:1033] Removing task 72 of framework 201203290332-0-0002 because of lost executor
I0329 03:42:17.730257 10927 master.cpp:1033] Removing task 73 of framework 201203290332-0-0002 because of lost executor
I0329 03:42:17.730440 10927 master.cpp:679] Received reply for offer 201203290332-0-77
I0329 03:42:17.730659 10927 master.cpp:1403] Filtered slave 201203290332-0-0 for framework 201203290332-0-0002 for 1 seconds
I0329 03:42:18.893353 10927 master.cpp:1184] Sending 1 offers to framework 201203290332-0-0003
I0329 03:42:18.894752 10927 master.cpp:679] Received reply for offer 201203290332-0-78
I0329 03:42:18.894891 10927 master.cpp:1403] Filtered slave 201203290332-0-0 for framework 201203290332-0-0003 for 1 seconds
I0329 03:42:19.895052 10927 master.cpp:1184] Sending 1 offers to framework 201203290332-0-0002
I0329 03:42:19.896559 10927 master.cpp:679] Received reply for offer 201203290332-0-79
I0329 03:42:19.896865 10927 master.cpp:1403] Filtered slave 201203290332-0-0 for framework 201203290332-0-0002 for 1 seconds
I0329 03:42:20.896800 10927 master.cpp:1184] Sending 1 offers to framework 201203290332-0-0003
I0329 03:42:20.898296 10927 master.cpp:679] Received reply for offer 201203290332-0-80
I0329 03:42:20.898453 10927 master.cpp:1403] Filtered slave 201203290332-0-0 for framework 201203290332-0-0003 for 1 seconds
I0329 03:42:21.898512 10927 master.cpp:1184] Sending 1 offers to framework 201203290332-0-0002
I0329 03:42:21.899958 10927 master.cpp:679] Received reply for offer 201203290332-0-81
I0329 03:42:21.900125 10927 master.cpp:1403] Filtered slave 201203290332-0-0 for framework 201203290332-0-0002 for 1 seconds
I0329 03:42:22.900264 10927 master.cpp:1184] Sending 1 offers to framework 201203290332-0-0003
I0329 03:42:22.901690 10927 master.cpp:679] Received reply for offer 201203290332-0-82
I0329 03:42:22.901846 10927 master.cpp:1403] Filtered slave 201203290332-0-0 for framework 201203290332-0-0003 for 1 seconds
I0329 03:42:23.901943 10927 master.cpp:1184] Sending 1 offers to framework 201203290332-0-0002
I0329 03:42:23.903360 10927 master.cpp:679] Received reply for offer 201203290332-0-83
I0329 03:42:23.903461 10927 master.cpp:1403] Filtered slave 201203290332-0-0 for framework 201203290332-0-0002 for 1 seconds
I0329 03:42:24.903517 10927 master.cpp:1184] Sending 1 offers to framework 201203290332-0-0003
I0329 03:42:24.904975 10927 master.cpp:679] Received reply for offer 201203290332-0-84
I0329 03:42:24.905132 10927 master.cpp:1403] Filtered slave 201203290332-0-0 for framework 201203290332-0-0003 for 1 seconds
I0329 03:42:25.905237 10927 master.cpp:1184] Sending 1 offers to framework 201203290332-0-0002
I0329 03:42:25.906688 10927 master.cpp:679] Received reply for offer 201203290332-0-85
I0329 03:42:25.906843 10927 master.cpp:1403] Filtered slave 201203290332-0-0 for framework 201203290332-0-0002 for 1 seconds
I0329 03:42:26.906962 10927 master.cpp:1184] Sending 1 offers to framework 201203290332-0-0003
I0329 03:42:26.908429 10927 master.cpp:679] Received reply for offer 201203290332-0-86
I0329 03:42:26.908586 10927 master.cpp:1403] Filtered slave 201203290332-0-0 for framework 201203290332-0-0003 for 1 seconds
I0329 03:42:27.908722 10927 master.cpp:1184] Sending 1 offers to framework 201203290332-0-0002
I0329 03:42:27.910197 10927 master.cpp:679] Received reply for offer 201203290332-0-87
I0329 03:42:27.910348 10927 master.cpp:1403] Filtered slave 201203290332-0-0 for framework 201203290332-0-0002 for 1 seconds
I0329 03:42:28.910413 10927 master.cpp:1184] Sending 1 offers to framework 201203290332-0-0003
I0329 03:42:28.911900 10927 master.cpp:679] Received reply for offer 201203290332-0-88
I0329 03:42:28.911998 10927 master.cpp:1403] Filtered slave 201203290332-0-0 for framework 201203290332-0-0003 for 1 seconds
I0329 03:42:29.912045 10927 master.cpp:1184] Sending 1 offers to framework 201203290332-0-0002
I0329 03:42:29.913593 10927 master.cpp:679] Received reply for offer 201203290332-0-89
I0329 03:42:29.913779 10927 master.cpp:1403] Filtered slave 201203290332-0-0 for framework 201203290332-0-0002 for 1 seconds
I0329 03:42:30.913784 10927 master.cpp:1184] Sending 1 offers to framework 201203290332-0-0003
I0329 03:42:30.915314 10927 master.cpp:679] Received reply for offer 201203290332-0-90
I0329 03:42:30.915468 10927 master.cpp:1403] Filtered slave 201203290332-0-0 for framework 201203290332-0-0003 for 1 seconds
I0329 03:42:31.915530 10927 master.cpp:1184] Sending 1 offers to framework 201203290332-0-0002
I0329 03:42:31.917002 10927 master.cpp:679] Received reply for offer 201203290332-0-91
I0329 03:42:31.917153 10927 master.cpp:1403] Filtered slave 201203290332-0-0 for framework 201203290332-0-0002 for 1 seconds
I0329 03:42:32.917222 10927 master.cpp:1184] Sending 1 offers to framework 201203290332-0-0003
I0329 03:42:32.918681 10927 master.cpp:679] Received reply for offer 201203290332-0-92
I0329 03:42:32.918833 10927 master.cpp:1403] Filtered slave 201203290332-0-0 for framework 201203290332-0-0003 for 1 seconds
I0329 03:42:33.918895 10927 master.cpp:1184] Sending 1 offers to framework 201203290332-0-0002
I0329 03:42:33.920394 10927 master.cpp:679] Received reply for offer 201203290332-0-93
I0329 03:42:33.920490 10927 master.cpp:1403] Filtered slave 201203290332-0-0 for framework 201203290332-0-0002 for 1 seconds
I0329 03:42:34.920609 10927 master.cpp:1184] Sending 1 offers to framework 201203290332-0-0003
I0329 03:42:34.922075 10927 master.cpp:679] Received reply for offer 201203290332-0-94
I0329 03:42:34.922226 10927 master.cpp:1403] Filtered slave 201203290332-0-0 for framework 201203290332-0-0003 for 1 seconds
I0329 03:42:35.922260 10927 master.cpp:1184] Sending 1 offers to framework 201203290332-0-0002
I0329 03:42:35.923789 10927 master.cpp:679] Received reply for offer 201203290332-0-95
I0329 03:42:35.923941 10927 master.cpp:1403] Filtered slave 201203290332-0-0 for framework 201203290332-0-0002 for 1 seconds
I0329 03:42:36.923331 10927 master.cpp:1184] Sending 1 offers to framework 201203290332-0-0003
I0329 03:42:36.924782 10927 master.cpp:679] Received reply for offer 201203290332-0-96
I0329 03:42:36.924933 10927 master.cpp:1403] Filtered slave 201203290332-0-0 for framework 201203290332-0-0003 for 1 seconds
I0329 03:42:37.924978 10927 master.cpp:1184] Sending 1 offers to framework 201203290332-0-0002
I0329 03:42:37.926409 10927 master.cpp:679] Received reply for offer 201203290332-0-97
I0329 03:42:37.926560 10927 master.cpp:1403] Filtered slave 201203290332-0-0 for framework 201203290332-0-0002 for 1 seconds
I0329 03:42:38.926628 10927 master.cpp:1184] Sending 1 offers to framework 201203290332-0-0003
I0329 03:42:38.928287 10927 master.cpp:679] Received reply for offer 201203290332-0-98
I0329 03:42:38.928386 10927 master.cpp:1403] Filtered slave 201203290332-0-0 for framework 201203290332-0-0003 for 1 seconds
I0329 03:42:39.928179 10927 master.cpp:1184] Sending 1 offers to framework 201203290332-0-0002
I0329 03:42:39.929682 10927 master.cpp:679] Received reply for offer 201203290332-0-99
I0329 03:42:39.929832 10927 master.cpp:1403] Filtered slave 201203290332-0-0 for framework 201203290332-0-0002 for 1 seconds
I0329 03:42:40.929894 10927 master.cpp:1184] Sending 1 offers to framework 201203290332-0-0003
I0329 03:42:40.931349 10927 master.cpp:679] Received reply for offer 201203290332-0-100
I0329 03:42:40.931501 10927 master.cpp:1403] Filtered slave 201203290332-0-0 for framework 201203290332-0-0003 for 1 seconds
I0329 03:42:41.931690 10927 master.cpp:1184] Sending 1 offers to framework 201203290332-0-0002
I0329 03:42:41.933122 10927 master.cpp:679] Received reply for offer 201203290332-0-101
I0329 03:42:41.933274 10927 master.cpp:1403] Filtered slave 201203290332-0-0 for framework 201203290332-0-0002 for 1 seconds
I0329 03:42:42.933323 10927 master.cpp:1184] Sending 1 offers to framework 201203290332-0-0003
I0329 03:42:42.934769 10927 master.cpp:679] Received reply for offer 201203290332-0-102
I0329 03:42:42.934921 10927 master.cpp:1403] Filtered slave 201203290332-0-0 for framework 201203290332-0-0003 for 1 seconds
I0329 03:42:43.934955 10927 master.cpp:1184] Sending 1 offers to framework 201203290332-0-0002
I0329 03:42:43.936815 10927 master.cpp:679] Received reply for offer 201203290332-0-103
I0329 03:42:43.936911 10927 master.cpp:1403] Filtered slave 201203290332-0-0 for framework 201203290332-0-0002 for 1 seconds
I0329 03:42:44.937012 10927 master.cpp:1184] Sending 1 offers to framework 201203290332-0-0003
I0329 03:42:44.938459 10927 master.cpp:679] Received reply for offer 201203290332-0-104
I0329 03:42:44.938612 10927 master.cpp:1403] Filtered slave 201203290332-0-0 for framework 201203290332-0-0003 for 1 seconds
I0329 03:42:45.938684 10927 master.cpp:1184] Sending 1 offers to framework 201203290332-0-0002
I0329 03:42:45.940172 10927 master.cpp:679] Received reply for offer 201203290332-0-105
I0329 03:42:45.940325 10927 master.cpp:1403] Filtered slave 201203290332-0-0 for framework 201203290332-0-0002 for 1 seconds
I0329 03:42:46.940387 10927 master.cpp:1184] Sending 1 offers to framework 201203290332-0-0003
I0329 03:42:46.941808 10927 master.cpp:679] Received reply for offer 201203290332-0-106
I0329 03:42:46.941959 10927 master.cpp:1403] Filtered slave 201203290332-0-0 for framework 201203290332-0-0003 for 1 seconds
I0329 03:42:47.941148 10927 master.cpp:1184] Sending 1 offers to framework 201203290332-0-0002
I0329 03:42:47.942602 10927 master.cpp:679] Received reply for offer 201203290332-0-107
I0329 03:42:47.942751 10927 master.cpp:1403] Filtered slave 201203290332-0-0 for framework 201203290332-0-0002 for 1 seconds
I0329 03:42:48.942883 10927 master.cpp:1184] Sending 1 offers to framework 201203290332-0-0003
I0329 03:42:48.944488 10927 master.cpp:679] Received reply for offer 201203290332-0-108
I0329 03:42:48.944650 10927 master.cpp:1403] Filtered slave 201203290332-0-0 for framework 201203290332-0-0003 for 1 seconds
I0329 03:42:49.944666 10927 master.cpp:1184] Sending 1 offers to framework 201203290332-0-0002
I0329 03:42:49.946141 10927 master.cpp:679] Received reply for offer 201203290332-0-109
I0329 03:42:49.946290 10927 master.cpp:1403] Filtered slave 201203290332-0-0 for framework 201203290332-0-0002 for 1 seconds
I0329 03:42:50.946326 10927 master.cpp:1184] Sending 1 offers to framework 201203290332-0-0003
I0329 03:42:50.947851 10927 master.cpp:679] Received reply for offer 201203290332-0-110
I0329 03:42:50.948006 10927 master.cpp:1403] Filtered slave 201203290332-0-0 for framework 201203290332-0-0003 for 1 seconds
I0329 03:42:51.947348 10927 master.cpp:1184] Sending 1 offers to framework 201203290332-0-0002
I0329 03:42:51.948807 10927 master.cpp:679] Received reply for offer 201203290332-0-111
I0329 03:42:51.949020 10927 master.cpp:1403] Filtered slave 201203290332-0-0 for framework 201203290332-0-0002 for 1 seconds
I0329 03:42:52.948379 10927 master.cpp:1184] Sending 1 offers to framework 201203290332-0-0003
I0329 03:42:52.949800 10927 master.cpp:679] Received reply for offer 201203290332-0-112
I0329 03:42:52.949950 10927 master.cpp:1403] Filtered slave 201203290332-0-0 for framework 201203290332-0-0003 for 1 seconds
I0329 03:42:53.950013 10927 master.cpp:1184] Sending 1 offers to framework 201203290332-0-0002
I0329 03:42:53.951580 10927 master.cpp:679] Received reply for offer 201203290332-0-113
I0329 03:42:53.951678 10927 master.cpp:1403] Filtered slave 201203290332-0-0 for framework 201203290332-0-0002 for 1 seconds
I0329 03:42:54.951349 10927 master.cpp:1184] Sending 1 offers to framework 201203290332-0-0003
I0329 03:42:54.952970 10927 master.cpp:679] Received reply for offer 201203290332-0-114
I0329 03:42:54.953122 10927 master.cpp:1403] Filtered slave 201203290332-0-0 for framework 201203290332-0-0003 for 1 seconds
I0329 03:42:55.953171 10927 master.cpp:1184] Sending 1 offers to framework 201203290332-0-0002
I0329 03:42:55.954502 10927 master.cpp:679] Received reply for offer 201203290332-0-115
I0329 03:42:55.954651 10927 master.cpp:1403] Filtered slave 201203290332-0-0 for framework 201203290332-0-0002 for 1 seconds
I0329 03:42:56.954723 10927 master.cpp:1184] Sending 1 offers to framework 201203290332-0-0003
I0329 03:42:56.956161 10927 master.cpp:679] Received reply for offer 201203290332-0-116
I0329 03:42:56.956313 10927 master.cpp:1403] Filtered slave 201203290332-0-0 for framework 201203290332-0-0003 for 1 seconds
I0329 03:42:57.956362 10927 master.cpp:1184] Sending 1 offers to framework 201203290332-0-0002
I0329 03:42:57.957917 10927 master.cpp:679] Received reply for offer 201203290332-0-117
I0329 03:42:57.958098 10927 master.cpp:1403] Filtered slave 201203290332-0-0 for framework 201203290332-0-0002 for 1 seconds
I0329 03:42:58.958053 10927 master.cpp:1184] Sending 1 offers to framework 201203290332-0-0003
I0329 03:42:58.959563 10927 master.cpp:679] Received reply for offer 201203290332-0-118
I0329 03:42:58.959661 10927 master.cpp:1403] Filtered slave 201203290332-0-0 for framework 201203290332-0-0003 for 1 seconds
I0329 03:42:59.959760 10927 master.cpp:1184] Sending 1 offers to framework 201203290332-0-0002
I0329 03:42:59.961201 10927 master.cpp:679] Received reply for offer 201203290332-0-119
I0329 03:42:59.961415 10927 master.cpp:1403] Filtered slave 201203290332-0-0 for framework 201203290332-0-0002 for 1 seconds
I0329 03:43:00.961415 10927 master.cpp:1184] Sending 1 offers to framework 201203290332-0-0003
I0329 03:43:00.962858 10927 master.cpp:679] Received reply for offer 201203290332-0-120
I0329 03:43:00.963009 10927 master.cpp:1403] Filtered slave 201203290332-0-0 for framework 201203290332-0-0003 for 1 seconds
I0329 03:43:01.963075 10927 master.cpp:1184] Sending 1 offers to framework 201203290332-0-0002
I0329 03:43:01.964520 10927 master.cpp:679] Received reply for offer 201203290332-0-121
I0329 03:43:01.964669 10927 master.cpp:1403] Filtered slave 201203290332-0-0 for framework 201203290332-0-0002 for 1 seconds
I0329 03:43:02.964243 10927 master.cpp:1184] Sending 1 offers to framework 201203290332-0-0003
I0329 03:43:02.965776 10927 master.cpp:679] Received reply for offer 201203290332-0-122
I0329 03:43:02.965929 10927 master.cpp:1403] Filtered slave 201203290332-0-0 for framework 201203290332-0-0003 for 1 seconds
I0329 03:43:03.965966 10927 master.cpp:1184] Sending 1 offers to framework 201203290332-0-0002
I0329 03:43:03.967517 10927 master.cpp:679] Received reply for offer 201203290332-0-123
I0329 03:43:03.967641 10927 master.cpp:1403] Filtered slave 201203290332-0-0 for framework 201203290332-0-0002 for 1 seconds
I0329 03:43:04.967713 10927 master.cpp:1184] Sending 1 offers to framework 201203290332-0-0003
I0329 03:43:04.969123 10927 master.cpp:679] Received reply for offer 201203290332-0-124
I0329 03:43:04.969276 10927 master.cpp:1403] Filtered slave 201203290332-0-0 for framework 201203290332-0-0003 for 1 seconds
I0329 03:43:05.969354 10927 master.cpp:1184] Sending 1 offers to framework 201203290332-0-0002
I0329 03:43:05.971109 10927 master.cpp:679] Received reply for offer 201203290332-0-125
I0329 03:43:05.971263 10927 master.cpp:1403] Filtered slave 201203290332-0-0 for framework 201203290332-0-0002 for 1 seconds
I0329 03:43:06.971329 10927 master.cpp:1184] Sending 1 offers to framework 201203290332-0-0003
I0329 03:43:06.972790 10927 master.cpp:679] Received reply for offer 201203290332-0-126
I0329 03:43:06.972942 10927 master.cpp:1403] Filtered slave 201203290332-0-0 for framework 201203290332-0-0003 for 1 seconds
I0329 03:43:07.973042 10927 master.cpp:1184] Sending 1 offers to framework 201203290332-0-0002
I0329 03:43:07.974488 10927 master.cpp:679] Received reply for offer 201203290332-0-127
I0329 03:43:07.974639 10927 master.cpp:1403] Filtered slave 201203290332-0-0 for framework 201203290332-0-0002 for 1 seconds
I0329 03:43:08.974681 10927 master.cpp:1184] Sending 1 offers to framework 201203290332-0-0003
I0329 03:43:08.976176 10927 master.cpp:679] Received reply for offer 201203290332-0-128
I0329 03:43:08.976275 10927 master.cpp:1403] Filtered slave 201203290332-0-0 for framework 201203290332-0-0003 for 1 seconds
I0329 03:43:09.976125 10927 master.cpp:1184] Sending 1 offers to framework 201203290332-0-0002
I0329 03:43:09.977576 10927 master.cpp:679] Received reply for offer 201203290332-0-129
I0329 03:43:09.977725 10927 master.cpp:1403] Filtered slave 201203290332-0-0 for framework 201203290332-0-0002 for 1 seconds
I0329 03:43:10.977792 10927 master.cpp:1184] Sending 1 offers to framework 201203290332-0-0003
I0329 03:43:10.979426 10927 master.cpp:679] Received reply for offer 201203290332-0-130
I0329 03:43:10.979579 10927 master.cpp:1403] Filtered slave 201203290332-0-0 for framework 201203290332-0-0003 for 1 seconds
I0329 03:43:11.979612 10927 master.cpp:1184] Sending 1 offers to framework 201203290332-0-0002
I0329 03:43:11.981076 10927 master.cpp:679] Received reply for offer 201203290332-0-131
I0329 03:43:11.981225 10927 master.cpp:1403] Filtered slave 201203290332-0-0 for framework 201203290332-0-0002 for 1 seconds
I0329 03:43:12.981279 10927 master.cpp:1184] Sending 1 offers to framework 201203290332-0-0003
I0329 03:43:12.982717 10927 master.cpp:679] Received reply for offer 201203290332-0-132
I0329 03:43:12.982869 10927 master.cpp:1403] Filtered slave 201203290332-0-0 for framework 201203290332-0-0003 for 1 seconds
I0329 03:43:13.982928 10927 master.cpp:1184] Sending 1 offers to framework 201203290332-0-0002
I0329 03:43:13.984352 10927 master.cpp:679] Received reply for offer 201203290332-0-133
I0329 03:43:13.984449 10927 master.cpp:1403] Filtered slave 201203290332-0-0 for framework 201203290332-0-0002 for 1 seconds
I0329 03:43:14.984549 10927 master.cpp:1184] Sending 1 offers to framework 201203290332-0-0003
I0329 03:43:14.986011 10927 master.cpp:679] Received reply for offer 201203290332-0-134
I0329 03:43:14.986162 10927 master.cpp:1403] Filtered slave 201203290332-0-0 for framework 201203290332-0-0003 for 1 seconds
I0329 03:43:15.986282 10927 master.cpp:1184] Sending 1 offers to framework 201203290332-0-0002
I0329 03:43:15.987773 10927 master.cpp:679] Received reply for offer 201203290332-0-135
I0329 03:43:15.987926 10927 master.cpp:1403] Filtered slave 201203290332-0-0 for framework 201203290332-0-0002 for 1 seconds
I0329 03:43:16.987968 10927 master.cpp:1184] Sending 1 offers to framework 201203290332-0-0003
I0329 03:43:16.989446 10927 master.cpp:679] Received reply for offer 201203290332-0-136
I0329 03:43:16.989600 10927 master.cpp:1403] Filtered slave 201203290332-0-0 for framework 201203290332-0-0003 for 1 seconds
I0329 03:43:17.989645 10927 master.cpp:1184] Sending 1 offers to framework 201203290332-0-0002
I0329 03:43:17.991149 10927 master.cpp:679] Received reply for offer 201203290332-0-137
I0329 03:43:17.991302 10927 master.cpp:1403] Filtered slave 201203290332-0-0 for framework 201203290332-0-0002 for 1 seconds
I0329 03:43:18.991360 10927 master.cpp:1184] Sending 1 offers to framework 201203290332-0-0003
I0329 03:43:18.992856 10927 master.cpp:679] Received reply for offer 201203290332-0-138
I0329 03:43:18.993012 10927 master.cpp:1403] Filtered slave 201203290332-0-0 for framework 201203290332-0-0003 for 1 seconds
I0329 03:43:19.993197 10927 master.cpp:1184] Sending 1 offers to framework 201203290332-0-0002
I0329 03:43:19.994786 10927 master.cpp:679] Received reply for offer 201203290332-0-139
I0329 03:43:19.994942 10927 master.cpp:1403] Filtered slave 201203290332-0-0 for framework 201203290332-0-0002 for 1 seconds
I0329 03:43:20.995103 10927 master.cpp:1184] Sending 1 offers to framework 201203290332-0-0003
I0329 03:43:20.996676 10927 master.cpp:679] Received reply for offer 201203290332-0-140
I0329 03:43:20.996844 10927 master.cpp:1403] Filtered slave 201203290332-0-0 for framework 201203290332-0-0003 for 1 seconds
I0329 03:43:21.996990 10927 master.cpp:1184] Sending 1 offers to framework 201203290332-0-0002
I0329 03:43:21.998581 10927 master.cpp:679] Received reply for offer 201203290332-0-141
I0329 03:43:21.998735 10927 master.cpp:1403] Filtered slave 201203290332-0-0 for framework 201203290332-0-0002 for 1 seconds
I0329 03:43:22.998870 10927 master.cpp:1184] Sending 1 offers to framework 201203290332-0-0003
I0329 03:43:23.000435 10927 master.cpp:679] Received reply for offer 201203290332-0-142
I0329 03:43:23.000591 10927 master.cpp:1403] Filtered slave 201203290332-0-0 for framework 201203290332-0-0003 for 1 seconds
I0329 03:43:24.000690 10927 master.cpp:1184] Sending 1 offers to framework 201203290332-0-0002
I0329 03:43:24.002219 10927 master.cpp:679] Received reply for offer 201203290332-0-143
I0329 03:43:24.002316 10927 master.cpp:1403] Filtered slave 201203290332-0-0 for framework 201203290332-0-0002 for 1 seconds
I0329 03:43:25.002205 10927 master.cpp:1184] Sending 1 offers to framework 201203290332-0-0003
I0329 03:43:25.003809 10927 master.cpp:679] Received reply for offer 201203290332-0-144
I0329 03:43:25.003968 10927 master.cpp:1403] Filtered slave 201203290332-0-0 for framework 201203290332-0-0003 for 1 seconds
I0329 03:43:26.004175 10927 master.cpp:1184] Sending 1 offers to framework 201203290332-0-0002
I0329 03:43:26.005758 10927 master.cpp:679] Received reply for offer 201203290332-0-145
I0329 03:43:26.005913 10927 master.cpp:1403] Filtered slave 201203290332-0-0 for framework 201203290332-0-0002 for 1 seconds
I0329 03:43:27.006062 10927 master.cpp:1184] Sending 1 offers to framework 201203290332-0-0003
I0329 03:43:27.007735 10927 master.cpp:679] Received reply for offer 201203290332-0-146
I0329 03:43:27.007933 10927 master.cpp:1403] Filtered slave 201203290332-0-0 for framework 201203290332-0-0003 for 1 seconds
I0329 03:43:28.007897 10927 master.cpp:1184] Sending 1 offers to framework 201203290332-0-0002
I0329 03:43:28.009361 10927 master.cpp:679] Received reply for offer 201203290332-0-147
I0329 03:43:28.009512 10927 master.cpp:1403] Filtered slave 201203290332-0-0 for framework 201203290332-0-0002 for 1 seconds
I0329 03:43:29.009572 10927 master.cpp:1184] Sending 1 offers to framework 201203290332-0-0003
I0329 03:43:29.011031 10927 master.cpp:679] Received reply for offer 201203290332-0-148
I0329 03:43:29.011142 10927 master.cpp:1403] Filtered slave 201203290332-0-0 for framework 201203290332-0-0003 for 1 seconds
I0329 03:43:30.011255 10927 master.cpp:1184] Sending 1 offers to framework 201203290332-0-0002
I0329 03:43:30.012704 10927 master.cpp:679] Received reply for offer 201203290332-0-149
I0329 03:43:30.012857 10927 master.cpp:1403] Filtered slave 201203290332-0-0 for framework 201203290332-0-0002 for 1 seconds
I0329 03:43:31.012917 10927 master.cpp:1184] Sending 1 offers to framework 201203290332-0-0003
I0329 03:43:31.014363 10927 master.cpp:679] Received reply for offer 201203290332-0-150
I0329 03:43:31.014518 10927 master.cpp:1403] Filtered slave 201203290332-0-0 for framework 201203290332-0-0003 for 1 seconds
I0329 03:43:32.014580 10927 master.cpp:1184] Sending 1 offers to framework 201203290332-0-0002
I0329 03:43:32.016016 10927 master.cpp:679] Received reply for offer 201203290332-0-151
I0329 03:43:32.016167 10927 master.cpp:1403] Filtered slave 201203290332-0-0 for framework 201203290332-0-0002 for 1 seconds
I0329 03:43:33.015254 10927 master.cpp:1184] Sending 1 offers to framework 201203290332-0-0003
I0329 03:43:33.016716 10927 master.cpp:679] Received reply for offer 201203290332-0-152
I0329 03:43:33.016868 10927 master.cpp:1403] Filtered slave 201203290332-0-0 for framework 201203290332-0-0003 for 1 seconds
I0329 03:43:34.016895 10927 master.cpp:1184] Sending 1 offers to framework 201203290332-0-0002
I0329 03:43:34.018344 10927 master.cpp:679] Received reply for offer 201203290332-0-153
I0329 03:43:34.018441 10927 master.cpp:1403] Filtered slave 201203290332-0-0 for framework 201203290332-0-0002 for 1 seconds
I0329 03:43:35.018486 10927 master.cpp:1184] Sending 1 offers to framework 201203290332-0-0003
I0329 03:43:35.019999 10927 master.cpp:679] Received reply for offer 201203290332-0-154
I0329 03:43:35.020154 10927 master.cpp:1403] Filtered slave 201203290332-0-0 for framework 201203290332-0-0003 for 1 seconds
I0329 03:43:36.019302 10927 master.cpp:1184] Sending 1 offers to framework 201203290332-0-0002
I0329 03:43:36.020756 10927 master.cpp:679] Received reply for offer 201203290332-0-155
I0329 03:43:36.020907 10927 master.cpp:1403] Filtered slave 201203290332-0-0 for framework 201203290332-0-0002 for 1 seconds
I0329 03:43:37.020967 10927 master.cpp:1184] Sending 1 offers to framework 201203290332-0-0003
I0329 03:43:37.022496 10927 master.cpp:679] Received reply for offer 201203290332-0-156
I0329 03:43:37.022649 10927 master.cpp:1403] Filtered slave 201203290332-0-0 for framework 201203290332-0-0003 for 1 seconds
I0329 03:43:38.022785 10927 master.cpp:1184] Sending 1 offers to framework 201203290332-0-0002
I0329 03:43:38.024279 10927 master.cpp:679] Received reply for offer 201203290332-0-157
I0329 03:43:38.024431 10927 master.cpp:1403] Filtered slave 201203290332-0-0 for framework 201203290332-0-0002 for 1 seconds
I0329 03:43:39.024504 10927 master.cpp:1184] Sending 1 offers to framework 201203290332-0-0003
I0329 03:43:39.025964 10927 master.cpp:679] Received reply for offer 201203290332-0-158
I0329 03:43:39.026064 10927 master.cpp:1403] Filtered slave 201203290332-0-0 for framework 201203290332-0-0003 for 1 seconds
I0329 03:43:40.026726 10927 master.cpp:1184] Sending 1 offers to framework 201203290332-0-0002
I0329 03:43:40.028178 10927 master.cpp:679] Received reply for offer 201203290332-0-159
I0329 03:43:40.028331 10927 master.cpp:1403] Filtered slave 201203290332-0-0 for framework 201203290332-0-0002 for 1 seconds
I0329 03:43:41.028393 10927 master.cpp:1184] Sending 1 offers to framework 201203290332-0-0003
I0329 03:43:41.029796 10927 master.cpp:679] Received reply for offer 201203290332-0-160
I0329 03:43:41.029950 10927 master.cpp:1403] Filtered slave 201203290332-0-0 for framework 201203290332-0-0003 for 1 seconds
I0329 03:43:42.030076 10927 master.cpp:1184] Sending 1 offers to framework 201203290332-0-0002
I0329 03:43:42.031575 10927 master.cpp:679] Received reply for offer 201203290332-0-161
I0329 03:43:42.031728 10927 master.cpp:1403] Filtered slave 201203290332-0-0 for framework 201203290332-0-0002 for 1 seconds
I0329 03:43:43.031797 10927 master.cpp:1184] Sending 1 offers to framework 201203290332-0-0003
I0329 03:43:43.033293 10927 master.cpp:679] Received reply for offer 201203290332-0-162
I0329 03:43:43.033447 10927 master.cpp:1403] Filtered slave 201203290332-0-0 for framework 201203290332-0-0003 for 1 seconds
I0329 03:43:44.033507 10927 master.cpp:1184] Sending 1 offers to framework 201203290332-0-0002
I0329 03:43:44.034984 10927 master.cpp:679] Received reply for offer 201203290332-0-163
I0329 03:43:44.035122 10927 master.cpp:1403] Filtered slave 201203290332-0-0 for framework 201203290332-0-0002 for 1 seconds
I0329 03:43:45.035193 10927 master.cpp:1184] Sending 1 offers to framework 201203290332-0-0003
I0329 03:43:45.036653 10927 master.cpp:679] Received reply for offer 201203290332-0-164
I0329 03:43:45.036808 10927 master.cpp:1403] Filtered slave 201203290332-0-0 for framework 201203290332-0-0003 for 1 seconds
I0329 03:43:46.036846 10927 master.cpp:1184] Sending 1 offers to framework 201203290332-0-0002
I0329 03:43:46.038287 10927 master.cpp:679] Received reply for offer 201203290332-0-165
I0329 03:43:46.038439 10927 master.cpp:1403] Filtered slave 201203290332-0-0 for framework 201203290332-0-0002 for 1 seconds
I0329 03:43:47.038498 10927 master.cpp:1184] Sending 1 offers to framework 201203290332-0-0003
I0329 03:43:47.039981 10927 master.cpp:679] Received reply for offer 201203290332-0-166
I0329 03:43:47.040135 10927 master.cpp:1403] Filtered slave 201203290332-0-0 for framework 201203290332-0-0003 for 1 seconds
I0329 03:43:48.040180 10927 master.cpp:1184] Sending 1 offers to framework 201203290332-0-0002
I0329 03:43:48.041648 10927 master.cpp:679] Received reply for offer 201203290332-0-167
I0329 03:43:48.041801 10927 master.cpp:1403] Filtered slave 201203290332-0-0 for framework 201203290332-0-0002 for 1 seconds
I0329 03:43:49.041858 10927 master.cpp:1184] Sending 1 offers to framework 201203290332-0-0003
I0329 03:43:49.043334 10927 master.cpp:679] Received reply for offer 201203290332-0-168
I0329 03:43:49.043436 10927 master.cpp:1403] Filtered slave 201203290332-0-0 for framework 201203290332-0-0003 for 1 seconds
I0329 03:43:50.043442 10927 master.cpp:1184] Sending 1 offers to framework 201203290332-0-0002
I0329 03:43:50.044868 10927 master.cpp:679] Received reply for offer 201203290332-0-169
I0329 03:43:50.045021 10927 master.cpp:1403] Filtered slave 201203290332-0-0 for framework 201203290332-0-0002 for 1 seconds
I0329 03:43:51.045090 10927 master.cpp:1184] Sending 1 offers to framework 201203290332-0-0003
I0329 03:43:51.046588 10927 master.cpp:679] Received reply for offer 201203290332-0-170
I0329 03:43:51.046743 10927 master.cpp:1403] Filtered slave 201203290332-0-0 for framework 201203290332-0-0003 for 1 seconds
I0329 03:43:52.046798 10927 master.cpp:1184] Sending 1 offers to framework 201203290332-0-0002
I0329 03:43:52.048276 10927 master.cpp:679] Received reply for offer 201203290332-0-171
I0329 03:43:52.048429 10927 master.cpp:1403] Filtered slave 201203290332-0-0 for framework 201203290332-0-0002 for 1 seconds
I0329 03:43:53.048485 10927 master.cpp:1184] Sending 1 offers to framework 201203290332-0-0003
I0329 03:43:53.049903 10927 master.cpp:679] Received reply for offer 201203290332-0-172
I0329 03:43:53.050058 10927 master.cpp:1403] Filtered slave 201203290332-0-0 for framework 201203290332-0-0003 for 1 seconds
I0329 03:43:54.050120 10927 master.cpp:1184] Sending 1 offers to framework 201203290332-0-0002
I0329 03:43:54.051620 10927 master.cpp:679] Received reply for offer 201203290332-0-173
I0329 03:43:54.051719 10927 master.cpp:1403] Filtered slave 201203290332-0-0 for framework 201203290332-0-0002 for 1 seconds
I0329 03:43:55.051985 10927 master.cpp:1184] Sending 1 offers to framework 201203290332-0-0003
I0329 03:43:55.053380 10927 master.cpp:679] Received reply for offer 201203290332-0-174
I0329 03:43:55.053570 10927 master.cpp:1403] Filtered slave 201203290332-0-0 for framework 201203290332-0-0003 for 1 seconds
I0329 03:43:56.053602 10927 master.cpp:1184] Sending 1 offers to framework 201203290332-0-0002
I0329 03:43:56.055038 10927 master.cpp:679] Received reply for offer 201203290332-0-175
I0329 03:43:56.055232 10927 master.cpp:1403] Filtered slave 201203290332-0-0 for framework 201203290332-0-0002 for 1 seconds
I0329 03:43:57.055400 10927 master.cpp:1184] Sending 1 offers to framework 201203290332-0-0003
I0329 03:43:57.056881 10927 master.cpp:679] Received reply for offer 201203290332-0-176
I0329 03:43:57.057035 10927 master.cpp:1403] Filtered slave 201203290332-0-0 for framework 201203290332-0-0003 for 1 seconds
I0329 03:43:58.057106 10927 master.cpp:1184] Sending 1 offers to framework 201203290332-0-0002
I0329 03:43:58.058552 10927 master.cpp:679] Received reply for offer 201203290332-0-177
I0329 03:43:58.058701 10927 master.cpp:1403] Filtered slave 201203290332-0-0 for framework 201203290332-0-0002 for 1 seconds
I0329 03:43:59.058761 10927 master.cpp:1184] Sending 1 offers to framework 201203290332-0-0003
I0329 03:43:59.060286 10927 master.cpp:679] Received reply for offer 201203290332-0-178
I0329 03:43:59.060385 10927 master.cpp:1403] Filtered slave 201203290332-0-0 for framework 201203290332-0-0003 for 1 seconds
I0329 03:44:00.060474 10927 master.cpp:1184] Sending 1 offers to framework 201203290332-0-0002
I0329 03:44:00.062058 10927 master.cpp:679] Received reply for offer 201203290332-0-179
I0329 03:44:00.062209 10927 master.cpp:1403] Filtered slave 201203290332-0-0 for framework 201203290332-0-0002 for 1 seconds
I0329 03:44:01.062228 10927 master.cpp:1184] Sending 1 offers to framework 201203290332-0-0003
I0329 03:44:01.063640 10927 master.cpp:679] Received reply for offer 201203290332-0-180
I0329 03:44:01.063792 10927 master.cpp:1403] Filtered slave 201203290332-0-0 for framework 201203290332-0-0003 for 1 seconds
I0329 03:44:02.063855 10927 master.cpp:1184] Sending 1 offers to framework 201203290332-0-0002
I0329 03:44:02.065310 10927 master.cpp:679] Received reply for offer 201203290332-0-181
I0329 03:44:02.065462 10927 master.cpp:1403] Filtered slave 201203290332-0-0 for framework 201203290332-0-0002 for 1 seconds
I0329 03:44:03.065526 10927 master.cpp:1184] Sending 1 offers to framework 201203290332-0-0003
I0329 03:44:03.067036 10927 master.cpp:679] Received reply for offer 201203290332-0-182
I0329 03:44:03.067199 10927 master.cpp:1403] Filtered slave 201203290332-0-0 for framework 201203290332-0-0003 for 1 seconds
I0329 03:44:04.067242 10927 master.cpp:1184] Sending 1 offers to framework 201203290332-0-0002
I0329 03:44:04.068663 10927 master.cpp:679] Received reply for offer 201203290332-0-183
I0329 03:44:04.068763 10927 master.cpp:1403] Filtered slave 201203290332-0-0 for framework 201203290332-0-0002 for 1 seconds
I0329 03:44:05.068877 10927 master.cpp:1184] Sending 1 offers to framework 201203290332-0-0003
I0329 03:44:05.070341 10927 master.cpp:679] Received reply for offer 201203290332-0-184
I0329 03:44:05.070497 10927 master.cpp:1403] Filtered slave 201203290332-0-0 for framework 201203290332-0-0003 for 1 seconds
I0329 03:44:06.070499 10927 master.cpp:1184] Sending 1 offers to framework 201203290332-0-0002
I0329 03:44:06.072017 10927 master.cpp:679] Received reply for offer 201203290332-0-185
I0329 03:44:06.072171 10927 master.cpp:1403] Filtered slave 201203290332-0-0 for framework 201203290332-0-0002 for 1 seconds
I0329 03:44:07.071492 10927 master.cpp:1184] Sending 1 offers to framework 201203290332-0-0003
I0329 03:44:07.073022 10927 master.cpp:679] Received reply for offer 201203290332-0-186
I0329 03:44:07.073176 10927 master.cpp:1403] Filtered slave 201203290332-0-0 for framework 201203290332-0-0003 for 1 seconds
I0329 03:44:08.073238 10927 master.cpp:1184] Sending 1 offers to framework 201203290332-0-0002
I0329 03:44:08.074708 10927 master.cpp:679] Received reply for offer 201203290332-0-187
I0329 03:44:08.074862 10927 master.cpp:1403] Filtered slave 201203290332-0-0 for framework 201203290332-0-0002 for 1 seconds
I0329 03:44:09.074892 10927 master.cpp:1184] Sending 1 offers to framework 201203290332-0-0003
I0329 03:44:09.076354 10927 master.cpp:679] Received reply for offer 201203290332-0-188
I0329 03:44:09.076455 10927 master.cpp:1403] Filtered slave 201203290332-0-0 for framework 201203290332-0-0003 for 1 seconds
I0329 03:44:10.076280 10927 master.cpp:1184] Sending 1 offers to framework 201203290332-0-0002
I0329 03:44:10.077723 10927 master.cpp:679] Received reply for offer 201203290332-0-189
I0329 03:44:10.077877 10927 master.cpp:1403] Filtered slave 201203290332-0-0 for framework 201203290332-0-0002 for 1 seconds
I0329 03:44:11.077915 10927 master.cpp:1184] Sending 1 offers to framework 201203290332-0-0003
I0329 03:44:11.079399 10927 master.cpp:679] Received reply for offer 201203290332-0-190
I0329 03:44:11.079556 10927 master.cpp:1403] Filtered slave 201203290332-0-0 for framework 201203290332-0-0003 for 1 seconds
I0329 03:44:12.079599 10927 master.cpp:1184] Sending 1 offers to framework 201203290332-0-0002
I0329 03:44:12.081048 10927 master.cpp:679] Received reply for offer 201203290332-0-191
I0329 03:44:12.081202 10927 master.cpp:1403] Filtered slave 201203290332-0-0 for framework 201203290332-0-0002 for 1 seconds
I0329 03:44:13.081222 10927 master.cpp:1184] Sending 1 offers to framework 201203290332-0-0003
I0329 03:44:13.082713 10927 master.cpp:679] Received reply for offer 201203290332-0-192
I0329 03:44:13.082866 10927 master.cpp:1403] Filtered slave 201203290332-0-0 for framework 201203290332-0-0003 for 1 seconds
I0329 03:44:14.082913 10927 master.cpp:1184] Sending 1 offers to framework 201203290332-0-0002
I0329 03:44:14.084367 10927 master.cpp:679] Received reply for offer 201203290332-0-193
I0329 03:44:14.084466 10927 master.cpp:1403] Filtered slave 201203290332-0-0 for framework 201203290332-0-0002 for 1 seconds
I0329 03:44:15.084566 10927 master.cpp:1184] Sending 1 offers to framework 201203290332-0-0003
I0329 03:44:15.086066 10927 master.cpp:679] Received reply for offer 201203290332-0-194
I0329 03:44:15.086220 10927 master.cpp:1403] Filtered slave 201203290332-0-0 for framework 201203290332-0-0003 for 1 seconds
I0329 03:44:16.086282 10927 master.cpp:1184] Sending 1 offers to framework 201203290332-0-0002
I0329 03:44:16.087786 10927 master.cpp:679] Received reply for offer 201203290332-0-195
I0329 03:44:16.087939 10927 master.cpp:1403] Filtered slave 201203290332-0-0 for framework 201203290332-0-0002 for 1 seconds
I0329 03:44:17.087960 10927 master.cpp:1184] Sending 1 offers to framework 201203290332-0-0003
I0329 03:44:17.089519 10927 master.cpp:679] Received reply for offer 201203290332-0-196
I0329 03:44:17.089671 10927 master.cpp:1403] Filtered slave 201203290332-0-0 for framework 201203290332-0-0003 for 1 seconds
I0329 03:44:18.089735 10927 master.cpp:1184] Sending 1 offers to framework 201203290332-0-0002
I0329 03:44:18.091231 10927 master.cpp:679] Received reply for offer 201203290332-0-197
I0329 03:44:18.091384 10927 master.cpp:1403] Filtered slave 201203290332-0-0 for framework 201203290332-0-0002 for 1 seconds
I0329 03:44:19.091444 10927 master.cpp:1184] Sending 1 offers to framework 201203290332-0-0003
I0329 03:44:19.092864 10927 master.cpp:679] Received reply for offer 201203290332-0-198
I0329 03:44:19.092963 10927 master.cpp:1403] Filtered slave 201203290332-0-0 for framework 201203290332-0-0003 for 1 seconds
I0329 03:44:20.093080 10927 master.cpp:1184] Sending 1 offers to framework 201203290332-0-0002
I0329 03:44:20.094527 10927 master.cpp:679] Received reply for offer 201203290332-0-199
I0329 03:44:20.094681 10927 master.cpp:1403] Filtered slave 201203290332-0-0 for framework 201203290332-0-0002 for 1 seconds
I0329 03:44:21.094743 10927 master.cpp:1184] Sending 1 offers to framework 201203290332-0-0003
I0329 03:44:21.096220 10927 master.cpp:679] Received reply for offer 201203290332-0-200
I0329 03:44:21.096375 10927 master.cpp:1403] Filtered slave 201203290332-0-0 for framework 201203290332-0-0003 for 1 seconds
I0329 03:44:22.096415 10927 master.cpp:1184] Sending 1 offers to framework 201203290332-0-0002
I0329 03:44:22.097921 10927 master.cpp:679] Received reply for offer 201203290332-0-201
I0329 03:44:22.098074 10927 master.cpp:1403] Filtered slave 201203290332-0-0 for framework 201203290332-0-0002 for 1 seconds
I0329 03:44:23.098131 10927 master.cpp:1184] Sending 1 offers to framework 201203290332-0-0003
I0329 03:44:23.099623 10927 master.cpp:679] Received reply for offer 201203290332-0-202
I0329 03:44:23.099778 10927 master.cpp:1403] Filtered slave 201203290332-0-0 for framework 201203290332-0-0003 for 1 seconds
I0329 03:44:24.099843 10927 master.cpp:1184] Sending 1 offers to framework 201203290332-0-0002
I0329 03:44:24.101294 10927 master.cpp:679] Received reply for offer 201203290332-0-203
I0329 03:44:24.101418 10927 master.cpp:1403] Filtered slave 201203290332-0-0 for framework 201203290332-0-0002 for 1 seconds
I0329 03:44:25.101327 10927 master.cpp:1184] Sending 1 offers to framework 201203290332-0-0003
I0329 03:44:25.102777 10927 master.cpp:679] Received reply for offer 201203290332-0-204
I0329 03:44:25.102931 10927 master.cpp:1403] Filtered slave 201203290332-0-0 for framework 201203290332-0-0003 for 1 seconds
I0329 03:44:26.102972 10927 master.cpp:1184] Sending 1 offers to framework 201203290332-0-0002
I0329 03:44:26.104425 10927 master.cpp:679] Received reply for offer 201203290332-0-205
I0329 03:44:26.104576 10927 master.cpp:1403] Filtered slave 201203290332-0-0 for framework 201203290332-0-0002 for 1 seconds
I0329 03:44:27.104647 10927 master.cpp:1184] Sending 1 offers to framework 201203290332-0-0003
I0329 03:44:27.106160 10927 master.cpp:679] Received reply for offer 201203290332-0-206
I0329 03:44:27.106314 10927 master.cpp:1403] Filtered slave 201203290332-0-0 for framework 201203290332-0-0003 for 1 seconds
I0329 03:44:28.106303 10927 master.cpp:1184] Sending 1 offers to framework 201203290332-0-0002
I0329 03:44:28.107815 10927 master.cpp:679] Received reply for offer 201203290332-0-207
I0329 03:44:28.107969 10927 master.cpp:1403] Filtered slave 201203290332-0-0 for framework 201203290332-0-0002 for 1 seconds
I0329 03:44:29.108028 10927 master.cpp:1184] Sending 1 offers to framework 201203290332-0-0003
I0329 03:44:29.109490 10927 master.cpp:679] Received reply for offer 201203290332-0-208
I0329 03:44:29.109590 10927 master.cpp:1403] Filtered slave 201203290332-0-0 for framework 201203290332-0-0003 for 1 seconds
I0329 03:44:30.109709 10927 master.cpp:1184] Sending 1 offers to framework 201203290332-0-0002
I0329 03:44:30.111281 10927 master.cpp:679] Received reply for offer 201203290332-0-209
I0329 03:44:30.111436 10927 master.cpp:1403] Filtered slave 201203290332-0-0 for framework 201203290332-0-0002 for 1 seconds
I0329 03:44:31.111403 10927 master.cpp:1184] Sending 1 offers to framework 201203290332-0-0003
I0329 03:44:31.112861 10927 master.cpp:679] Received reply for offer 201203290332-0-210
I0329 03:44:31.113014 10927 master.cpp:1403] Filtered slave 201203290332-0-0 for framework 201203290332-0-0003 for 1 seconds
I0329 03:44:32.113081 10927 master.cpp:1184] Sending 1 offers to framework 201203290332-0-0002
I0329 03:44:32.114560 10927 master.cpp:679] Received reply for offer 201203290332-0-211
I0329 03:44:32.114712 10927 master.cpp:1403] Filtered slave 201203290332-0-0 for framework 201203290332-0-0002 for 1 seconds
I0329 03:44:33.114778 10927 master.cpp:1184] Sending 1 offers to framework 201203290332-0-0003
I0329 03:44:33.116317 10927 master.cpp:679] Received reply for offer 201203290332-0-212
I0329 03:44:33.116472 10927 master.cpp:1403] Filtered slave 201203290332-0-0 for framework 201203290332-0-0003 for 1 seconds
I0329 03:44:34.115942 10927 master.cpp:1184] Sending 1 offers to framework 201203290332-0-0002
I0329 03:44:34.117413 10927 master.cpp:679] Received reply for offer 201203290332-0-213
I0329 03:44:34.117511 10927 master.cpp:1403] Filtered slave 201203290332-0-0 for framework 201203290332-0-0002 for 1 seconds
I0329 03:44:35.117614 10927 master.cpp:1184] Sending 1 offers to framework 201203290332-0-0003
I0329 03:44:35.119050 10927 master.cpp:679] Received reply for offer 201203290332-0-214
I0329 03:44:35.119215 10927 master.cpp:1403] Filtered slave 201203290332-0-0 for framework 201203290332-0-0003 for 1 seconds
I0329 03:44:36.119380 10927 master.cpp:1184] Sending 1 offers to framework 201203290332-0-0002
I0329 03:44:36.120843 10927 master.cpp:679] Received reply for offer 201203290332-0-215
I0329 03:44:36.120998 10927 master.cpp:1403] Filtered slave 201203290332-0-0 for framework 201203290332-0-0002 for 1 seconds
I0329 03:44:37.121152 10927 master.cpp:1184] Sending 1 offers to framework 201203290332-0-0003
I0329 03:44:37.122654 10927 master.cpp:679] Received reply for offer 201203290332-0-216
I0329 03:44:37.122807 10927 master.cpp:1403] Filtered slave 201203290332-0-0 for framework 201203290332-0-0003 for 1 seconds
I0329 03:44:38.122922 10927 master.cpp:1184] Sending 1 offers to framework 201203290332-0-0002
I0329 03:44:38.124460 10927 master.cpp:679] Received reply for offer 201203290332-0-217
I0329 03:44:38.124615 10927 master.cpp:1403] Filtered slave 201203290332-0-0 for framework 201203290332-0-0002 for 1 seconds
I0329 03:44:39.124770 10927 master.cpp:1184] Sending 1 offers to framework 201203290332-0-0003
I0329 03:44:39.126196 10927 master.cpp:679] Received reply for offer 201203290332-0-218
I0329 03:44:39.126301 10927 master.cpp:1403] Filtered slave 201203290332-0-0 for framework 201203290332-0-0003 for 1 seconds
I0329 03:44:40.126927 10927 master.cpp:1184] Sending 1 offers to framework 201203290332-0-0002
I0329 03:44:40.128377 10927 master.cpp:679] Received reply for offer 201203290332-0-219
I0329 03:44:40.128533 10927 master.cpp:1403] Filtered slave 201203290332-0-0 for framework 201203290332-0-0002 for 1 seconds
I0329 03:44:41.128690 10927 master.cpp:1184] Sending 1 offers to framework 201203290332-0-0003
I0329 03:44:41.130177 10927 master.cpp:679] Received reply for offer 201203290332-0-220
I0329 03:44:41.130332 10927 master.cpp:1403] Filtered slave 201203290332-0-0 for framework 201203290332-0-0003 for 1 seconds
I0329 03:44:42.130435 10927 master.cpp:1184] Sending 1 offers to framework 201203290332-0-0002
I0329 03:44:42.131985 10927 master.cpp:679] Received reply for offer 201203290332-0-221
I0329 03:44:42.132143 10927 master.cpp:1403] Filtered slave 201203290332-0-0 for framework 201203290332-0-0002 for 1 seconds
I0329 03:44:43.132319 10927 master.cpp:1184] Sending 1 offers to framework 201203290332-0-0003
I0329 03:44:43.133808 10927 master.cpp:679] Received reply for offer 201203290332-0-222
I0329 03:44:43.133962 10927 master.cpp:1403] Filtered slave 201203290332-0-0 for framework 201203290332-0-0003 for 1 seconds
I0329 03:44:44.133301 10927 master.cpp:1184] Sending 1 offers to framework 201203290332-0-0002
I0329 03:44:44.134822 10927 master.cpp:679] Received reply for offer 201203290332-0-223
I0329 03:44:44.134922 10927 master.cpp:1403] Filtered slave 201203290332-0-0 for framework 201203290332-0-0002 for 1 seconds
I0329 03:44:45.135046 10927 master.cpp:1184] Sending 1 offers to framework 201203290332-0-0003
I0329 03:44:45.136585 10927 master.cpp:679] Received reply for offer 201203290332-0-224
I0329 03:44:45.136740 10927 master.cpp:1403] Filtered slave 201203290332-0-0 for framework 201203290332-0-0003 for 1 seconds
I0329 03:44:46.136798 10927 master.cpp:1184] Sending 1 offers to framework 201203290332-0-0002
I0329 03:44:46.138294 10927 master.cpp:679] Received reply for offer 201203290332-0-225
I0329 03:44:46.138447 10927 master.cpp:1403] Filtered slave 201203290332-0-0 for framework 201203290332-0-0002 for 1 seconds
I0329 03:44:47.138485 10927 master.cpp:1184] Sending 1 offers to framework 201203290332-0-0003
I0329 03:44:47.139978 10927 master.cpp:679] Received reply for offer 201203290332-0-226
I0329 03:44:47.140131 10927 master.cpp:1403] Filtered slave 201203290332-0-0 for framework 201203290332-0-0003 for 1 seconds
I0329 03:44:48.140200 10927 master.cpp:1184] Sending 1 offers to framework 201203290332-0-0002
I0329 03:44:48.141727 10927 master.cpp:679] Received reply for offer 201203290332-0-227
I0329 03:44:48.141880 10927 master.cpp:1403] Filtered slave 201203290332-0-0 for framework 201203290332-0-0002 for 1 seconds
I0329 03:44:49.141938 10927 master.cpp:1184] Sending 1 offers to framework 201203290332-0-0003
I0329 03:44:49.143410 10927 master.cpp:679] Received reply for offer 201203290332-0-228
I0329 03:44:49.143511 10927 master.cpp:1403] Filtered slave 201203290332-0-0 for framework 201203290332-0-0003 for 1 seconds
I0329 03:44:50.143625 10927 master.cpp:1184] Sending 1 offers to framework 201203290332-0-0002
I0329 03:44:50.145091 10927 master.cpp:679] Received reply for offer 201203290332-0-229
I0329 03:44:50.145241 10927 master.cpp:1403] Filtered slave 201203290332-0-0 for framework 201203290332-0-0002 for 1 seconds
I0329 03:44:51.144954 10927 master.cpp:1184] Sending 1 offers to framework 201203290332-0-0003
I0329 03:44:51.146472 10927 master.cpp:679] Received reply for offer 201203290332-0-230
I0329 03:44:51.146625 10927 master.cpp:1403] Filtered slave 201203290332-0-0 for framework 201203290332-0-0003 for 1 seconds
I0329 03:44:52.146690 10927 master.cpp:1184] Sending 1 offers to framework 201203290332-0-0002
I0329 03:44:52.148198 10927 master.cpp:679] Received reply for offer 201203290332-0-231
I0329 03:44:52.148350 10927 master.cpp:1403] Filtered slave 201203290332-0-0 for framework 201203290332-0-0002 for 1 seconds
I0329 03:44:53.148375 10927 master.cpp:1184] Sending 1 offers to framework 201203290332-0-0003
I0329 03:44:53.149819 10927 master.cpp:679] Received reply for offer 201203290332-0-232
I0329 03:44:53.149972 10927 master.cpp:1403] Filtered slave 201203290332-0-0 for framework 201203290332-0-0003 for 1 seconds
I0329 03:44:54.150141 10927 master.cpp:1184] Sending 1 offers to framework 201203290332-0-0002
I0329 03:44:54.151833 10927 master.cpp:679] Received reply for offer 201203290332-0-233
I0329 03:44:54.151938 10927 master.cpp:1403] Filtered slave 201203290332-0-0 for framework 201203290332-0-0002 for 1 seconds
I0329 03:44:55.152077 10927 master.cpp:1184] Sending 1 offers to framework 201203290332-0-0003
I0329 03:44:55.154628 10927 master.cpp:679] Received reply for offer 201203290332-0-234
I0329 03:44:55.154785 10927 master.cpp:1403] Filtered slave 201203290332-0-0 for framework 201203290332-0-0003 for 1 seconds
I0329 03:44:56.153951 10927 master.cpp:1184] Sending 1 offers to framework 201203290332-0-0002
I0329 03:44:56.155478 10927 master.cpp:679] Received reply for offer 201203290332-0-235
I0329 03:44:56.155637 10927 master.cpp:1403] Filtered slave 201203290332-0-0 for framework 201203290332-0-0002 for 1 seconds
I0329 03:44:57.155177 10927 master.cpp:1184] Sending 1 offers to framework 201203290332-0-0003
I0329 03:44:57.156597 10927 master.cpp:679] Received reply for offer 201203290332-0-236
I0329 03:44:57.156754 10927 master.cpp:1403] Filtered slave 201203290332-0-0 for framework 201203290332-0-0003 for 1 seconds
I0329 03:44:58.156967 10927 master.cpp:1184] Sending 1 offers to framework 201203290332-0-0002
I0329 03:44:58.158267 10927 master.cpp:679] Received reply for offer 201203290332-0-237
I0329 03:44:58.158417 10927 master.cpp:1403] Filtered slave 201203290332-0-0 for framework 201203290332-0-0002 for 1 seconds
I0329 03:44:59.158457 10927 master.cpp:1184] Sending 1 offers to framework 201203290332-0-0003
I0329 03:44:59.159800 10927 master.cpp:679] Received reply for offer 201203290332-0-238
I0329 03:44:59.159898 10927 master.cpp:1403] Filtered slave 201203290332-0-0 for framework 201203290332-0-0003 for 1 seconds
I0329 03:45:00.159375 10927 master.cpp:1184] Sending 1 offers to framework 201203290332-0-0002
I0329 03:45:00.160866 10927 master.cpp:679] Received reply for offer 201203290332-0-239
I0329 03:45:00.161020 10927 master.cpp:1403] Filtered slave 201203290332-0-0 for framework 201203290332-0-0002 for 1 seconds
I0329 03:45:01.160949 10927 master.cpp:1184] Sending 1 offers to framework 201203290332-0-0003
I0329 03:45:01.162125 10927 master.cpp:679] Received reply for offer 201203290332-0-240
I0329 03:45:01.162248 10927 master.cpp:1403] Filtered slave 201203290332-0-0 for framework 201203290332-0-0003 for 1 seconds
I0329 03:45:02.163540 10927 master.cpp:1184] Sending 1 offers to framework 201203290332-0-0002
I0329 03:45:02.164953 10927 master.cpp:679] Received reply for offer 201203290332-0-241
I0329 03:45:02.165143 10927 master.cpp:1403] Filtered slave 201203290332-0-0 for framework 201203290332-0-0002 for 1 seconds
I0329 03:45:03.165148 10927 master.cpp:1184] Sending 1 offers to framework 201203290332-0-0003
I0329 03:45:03.166545 10927 master.cpp:679] Received reply for offer 201203290332-0-242
I0329 03:45:03.166759 10927 master.cpp:1403] Filtered slave 201203290332-0-0 for framework 201203290332-0-0003 for 1 seconds
I0329 03:45:04.166779 10927 master.cpp:1184] Sending 1 offers to framework 201203290332-0-0002
I0329 03:45:04.167994 10927 master.cpp:679] Received reply for offer 201203290332-0-243
I0329 03:45:04.176776 10927 master.cpp:1403] Filtered slave 201203290332-0-0 for framework 201203290332-0-0002 for 1 seconds
I0329 03:45:05.169188 10927 master.cpp:1184] Sending 1 offers to framework 201203290332-0-0003
I0329 03:45:05.170501 10927 master.cpp:679] Received reply for offer 201203290332-0-244
I0329 03:45:05.170675 10927 master.cpp:1403] Filtered slave 201203290332-0-0 for framework 201203290332-0-0003 for 1 seconds
I0329 03:45:06.170725 10927 master.cpp:1184] Sending 1 offers to framework 201203290332-0-0002
I0329 03:45:06.172088 10927 master.cpp:679] Received reply for offer 201203290332-0-245
I0329 03:45:06.172241 10927 master.cpp:1403] Filtered slave 201203290332-0-0 for framework 201203290332-0-0002 for 1 seconds
I0329 03:45:07.171231 10927 master.cpp:1184] Sending 1 offers to framework 201203290332-0-0003
I0329 03:45:07.172373 10927 master.cpp:679] Received reply for offer 201203290332-0-246
I0329 03:45:07.172497 10927 master.cpp:1403] Filtered slave 201203290332-0-0 for framework 201203290332-0-0003 for 1 seconds
I0329 03:45:08.173562 10927 master.cpp:1184] Sending 1 offers to framework 201203290332-0-0002
I0329 03:45:08.174698 10927 master.cpp:679] Received reply for offer 201203290332-0-247
I0329 03:45:08.174816 10927 master.cpp:1403] Filtered slave 201203290332-0-0 for framework 201203290332-0-0002 for 1 seconds
I0329 03:45:09.174675 10927 master.cpp:1184] Sending 1 offers to framework 201203290332-0-0003
I0329 03:45:09.176157 10927 master.cpp:679] Received reply for offer 201203290332-0-248
I0329 03:45:09.176257 10927 master.cpp:1403] Filtered slave 201203290332-0-0 for framework 201203290332-0-0003 for 1 seconds
I0329 03:45:10.176410 10927 master.cpp:1184] Sending 1 offers to framework 201203290332-0-0002
I0329 03:45:10.177855 10927 master.cpp:679] Received reply for offer 201203290332-0-249
I0329 03:45:10.178006 10927 master.cpp:1403] Filtered slave 201203290332-0-0 for framework 201203290332-0-0002 for 1 seconds
I0329 03:45:11.178055 10927 master.cpp:1184] Sending 1 offers to framework 201203290332-0-0003
I0329 03:45:11.179628 10927 master.cpp:679] Received reply for offer 201203290332-0-250
I0329 03:45:11.179785 10927 master.cpp:1403] Filtered slave 201203290332-0-0 for framework 201203290332-0-0003 for 1 seconds
I0329 03:45:12.179337 10927 master.cpp:1184] Sending 1 offers to framework 201203290332-0-0002
I0329 03:45:12.180879 10927 master.cpp:679] Received reply for offer 201203290332-0-251
I0329 03:45:12.181030 10927 master.cpp:1403] Filtered slave 201203290332-0-0 for framework 201203290332-0-0002 for 1 seconds
I0329 03:45:13.181010 10927 master.cpp:1184] Sending 1 offers to framework 201203290332-0-0003
I0329 03:45:13.182456 10927 master.cpp:679] Received reply for offer 201203290332-0-252
I0329 03:45:13.182606 10927 master.cpp:1403] Filtered slave 201203290332-0-0 for framework 201203290332-0-0003 for 1 seconds
I0329 03:45:14.182647 10927 master.cpp:1184] Sending 1 offers to framework 201203290332-0-0002
I0329 03:45:14.184118 10927 master.cpp:679] Received reply for offer 201203290332-0-253
I0329 03:45:14.184216 10927 master.cpp:1403] Filtered slave 201203290332-0-0 for framework 201203290332-0-0002 for 1 seconds
I0329 03:45:15.184378 10927 master.cpp:1184] Sending 1 offers to framework 201203290332-0-0003
I0329 03:45:15.185866 10927 master.cpp:679] Received reply for offer 201203290332-0-254
I0329 03:45:15.186027 10927 master.cpp:1403] Filtered slave 201203290332-0-0 for framework 201203290332-0-0003 for 1 seconds
I0329 03:45:16.186066 10927 master.cpp:1184] Sending 1 offers to framework 201203290332-0-0002
I0329 03:45:16.187499 10927 master.cpp:679] Received reply for offer 201203290332-0-255
I0329 03:45:16.187650 10927 master.cpp:1403] Filtered slave 201203290332-0-0 for framework 201203290332-0-0002 for 1 seconds
I0329 03:45:17.187667 10927 master.cpp:1184] Sending 1 offers to framework 201203290332-0-0003
I0329 03:45:17.189163 10927 master.cpp:679] Received reply for offer 201203290332-0-256
I0329 03:45:17.189354 10927 master.cpp:1403] Filtered slave 201203290332-0-0 for framework 201203290332-0-0003 for 1 seconds
I0329 03:45:18.188779 10927 master.cpp:1184] Sending 1 offers to framework 201203290332-0-0002
I0329 03:45:18.190256 10927 master.cpp:679] Received reply for offer 201203290332-0-257
I0329 03:45:18.190407 10927 master.cpp:1403] Filtered slave 201203290332-0-0 for framework 201203290332-0-0002 for 1 seconds
I0329 03:45:19.189821 10927 master.cpp:1184] Sending 1 offers to framework 201203290332-0-0003
I0329 03:45:19.191300 10927 master.cpp:679] Received reply for offer 201203290332-0-258
I0329 03:45:19.191401 10927 master.cpp:1403] Filtered slave 201203290332-0-0 for framework 201203290332-0-0003 for 1 seconds
I0329 03:45:20.191496 10927 master.cpp:1184] Sending 1 offers to framework 201203290332-0-0002
I0329 03:45:20.192967 10927 master.cpp:679] Received reply for offer 201203290332-0-259
I0329 03:45:20.193119 10927 master.cpp:1403] Filtered slave 201203290332-0-0 for framework 201203290332-0-0002 for 1 seconds
I0329 03:45:21.193183 10927 master.cpp:1184] Sending 1 offers to framework 201203290332-0-0003
I0329 03:45:21.194666 10927 master.cpp:679] Received reply for offer 201203290332-0-260
I0329 03:45:21.194820 10927 master.cpp:1403] Filtered slave 201203290332-0-0 for framework 201203290332-0-0003 for 1 seconds
I0329 03:45:22.194861 10927 master.cpp:1184] Sending 1 offers to framework 201203290332-0-0002
I0329 03:45:22.196351 10927 master.cpp:679] Received reply for offer 201203290332-0-261
I0329 03:45:22.196501 10927 master.cpp:1403] Filtered slave 201203290332-0-0 for framework 201203290332-0-0002 for 1 seconds
I0329 03:45:23.196483 10927 master.cpp:1184] Sending 1 offers to framework 201203290332-0-0003
I0329 03:45:23.198004 10927 master.cpp:679] Received reply for offer 201203290332-0-262
I0329 03:45:23.198158 10927 master.cpp:1403] Filtered slave 201203290332-0-0 for framework 201203290332-0-0003 for 1 seconds
I0329 03:45:24.197926 10927 master.cpp:1184] Sending 1 offers to framework 201203290332-0-0002
I0329 03:45:24.199372 10927 master.cpp:679] Received reply for offer 201203290332-0-263
I0329 03:45:24.199481 10927 master.cpp:1403] Filtered slave 201203290332-0-0 for framework 201203290332-0-0002 for 1 seconds
I0329 03:45:25.199620 10927 master.cpp:1184] Sending 1 offers to framework 201203290332-0-0003
I0329 03:45:25.201071 10927 master.cpp:679] Received reply for offer 201203290332-0-264
I0329 03:45:25.201223 10927 master.cpp:1403] Filtered slave 201203290332-0-0 for framework 201203290332-0-0003 for 1 seconds
I0329 03:45:26.201267 10927 master.cpp:1184] Sending 1 offers to framework 201203290332-0-0002
I0329 03:45:26.202741 10927 master.cpp:679] Received reply for offer 201203290332-0-265
I0329 03:45:26.202891 10927 master.cpp:1403] Filtered slave 201203290332-0-0 for framework 201203290332-0-0002 for 1 seconds
I0329 03:45:27.202939 10927 master.cpp:1184] Sending 1 offers to framework 201203290332-0-0003
I0329 03:45:27.204442 10927 master.cpp:679] Received reply for offer 201203290332-0-266
I0329 03:45:27.204597 10927 master.cpp:1403] Filtered slave 201203290332-0-0 for framework 201203290332-0-0003 for 1 seconds
I0329 03:45:28.204637 10927 master.cpp:1184] Sending 1 offers to framework 201203290332-0-0002
I0329 03:45:28.206104 10927 master.cpp:679] Received reply for offer 201203290332-0-267
I0329 03:45:28.206255 10927 master.cpp:1403] Filtered slave 201203290332-0-0 for framework 201203290332-0-0002 for 1 seconds
I0329 03:45:29.206316 10927 master.cpp:1184] Sending 1 offers to framework 201203290332-0-0003
I0329 03:45:29.208089 10927 master.cpp:679] Received reply for offer 201203290332-0-268
I0329 03:45:29.208194 10927 master.cpp:1403] Filtered slave 201203290332-0-0 for framework 201203290332-0-0003 for 1 seconds
I0329 03:45:30.208251 10927 master.cpp:1184] Sending 1 offers to framework 201203290332-0-0002
I0329 03:45:30.209765 10927 master.cpp:679] Received reply for offer 201203290332-0-269
I0329 03:45:30.209919 10927 master.cpp:1403] Filtered slave 201203290332-0-0 for framework 201203290332-0-0002 for 1 seconds
I0329 03:45:31.209943 10927 master.cpp:1184] Sending 1 offers to framework 201203290332-0-0003
I0329 03:45:31.211400 10927 master.cpp:679] Received reply for offer 201203290332-0-270
I0329 03:45:31.211555 10927 master.cpp:1403] Filtered slave 201203290332-0-0 for framework 201203290332-0-0003 for 1 seconds
I0329 03:45:32.211599 10927 master.cpp:1184] Sending 1 offers to framework 201203290332-0-0002
I0329 03:45:32.213073 10927 master.cpp:679] Received reply for offer 201203290332-0-271
I0329 03:45:32.213222 10927 master.cpp:1403] Filtered slave 201203290332-0-0 for framework 201203290332-0-0002 for 1 seconds
I0329 03:45:33.213245 10927 master.cpp:1184] Sending 1 offers to framework 201203290332-0-0003
I0329 03:45:33.214743 10927 master.cpp:679] Received reply for offer 201203290332-0-272
I0329 03:45:33.214896 10927 master.cpp:1403] Filtered slave 201203290332-0-0 for framework 201203290332-0-0003 for 1 seconds
I0329 03:45:34.214962 10927 master.cpp:1184] Sending 1 offers to framework 201203290332-0-0002
I0329 03:45:34.216400 10927 master.cpp:679] Received reply for offer 201203290332-0-273
I0329 03:45:34.216498 10927 master.cpp:1403] Filtered slave 201203290332-0-0 for framework 201203290332-0-0002 for 1 seconds
I0329 03:45:35.216646 10927 master.cpp:1184] Sending 1 offers to framework 201203290332-0-0003
I0329 03:45:35.218185 10927 master.cpp:679] Received reply for offer 201203290332-0-274
I0329 03:45:35.218339 10927 master.cpp:1403] Filtered slave 201203290332-0-0 for framework 201203290332-0-0003 for 1 seconds
I0329 03:45:36.218358 10927 master.cpp:1184] Sending 1 offers to framework 201203290332-0-0002
I0329 03:45:36.219853 10927 master.cpp:679] Received reply for offer 201203290332-0-275
I0329 03:45:36.220012 10927 master.cpp:1403] Filtered slave 201203290332-0-0 for framework 201203290332-0-0002 for 1 seconds
I0329 03:45:37.220073 10927 master.cpp:1184] Sending 1 offers to framework 201203290332-0-0003
I0329 03:45:37.221484 10927 master.cpp:679] Received reply for offer 201203290332-0-276
I0329 03:45:37.221642 10927 master.cpp:1403] Filtered slave 201203290332-0-0 for framework 201203290332-0-0003 for 1 seconds
I0329 03:45:38.221675 10927 master.cpp:1184] Sending 1 offers to framework 201203290332-0-0002
I0329 03:45:38.223325 10927 master.cpp:679] Received reply for offer 201203290332-0-277
I0329 03:45:38.223479 10927 master.cpp:1403] Filtered slave 201203290332-0-0 for framework 201203290332-0-0002 for 1 seconds
I0329 03:45:39.222197 10927 master.cpp:1184] Sending 1 offers to framework 201203290332-0-0003
I0329 03:45:39.223593 10927 master.cpp:679] Received reply for offer 201203290332-0-278
I0329 03:45:39.223736 10927 master.cpp:1403] Filtered slave 201203290332-0-0 for framework 201203290332-0-0003 for 1 seconds
I0329 03:45:40.223778 10927 master.cpp:1184] Sending 1 offers to framework 201203290332-0-0002
I0329 03:45:40.225520 10927 master.cpp:679] Received reply for offer 201203290332-0-279
I0329 03:45:40.225711 10927 master.cpp:1403] Filtered slave 201203290332-0-0 for framework 201203290332-0-0002 for 1 seconds
I0329 03:45:41.225683 10927 master.cpp:1184] Sending 1 offers to framework 201203290332-0-0003
I0329 03:45:41.227063 10927 master.cpp:679] Received reply for offer 201203290332-0-280
I0329 03:45:41.227313 10927 master.cpp:1403] Filtered slave 201203290332-0-0 for framework 201203290332-0-0003 for 1 seconds
I0329 03:45:42.227294 10927 master.cpp:1184] Sending 1 offers to framework 201203290332-0-0002
I0329 03:45:42.228734 10927 master.cpp:679] Received reply for offer 201203290332-0-281
I0329 03:45:42.228911 10927 master.cpp:1403] Filtered slave 201203290332-0-0 for framework 201203290332-0-0002 for 1 seconds
I0329 03:45:43.228895 10927 master.cpp:1184] Sending 1 offers to framework 201203290332-0-0003
I0329 03:45:43.230437 10927 master.cpp:679] Received reply for offer 201203290332-0-282
I0329 03:45:43.230588 10927 master.cpp:1403] Filtered slave 201203290332-0-0 for framework 201203290332-0-0003 for 1 seconds
I0329 03:45:44.230645 10927 master.cpp:1184] Sending 1 offers to framework 201203290332-0-0002
I0329 03:45:44.232029 10927 master.cpp:679] Received reply for offer 201203290332-0-283
I0329 03:45:44.239461 10927 master.cpp:1403] Filtered slave 201203290332-0-0 for framework 201203290332-0-0002 for 1 seconds
I0329 03:45:45.232177 10927 master.cpp:1184] Sending 1 offers to framework 201203290332-0-0003
I0329 03:45:45.233611 10927 master.cpp:679] Received reply for offer 201203290332-0-284
I0329 03:45:45.233803 10927 master.cpp:1403] Filtered slave 201203290332-0-0 for framework 201203290332-0-0003 for 1 seconds
I0329 03:45:46.233805 10927 master.cpp:1184] Sending 1 offers to framework 201203290332-0-0002
I0329 03:45:46.235240 10927 master.cpp:679] Received reply for offer 201203290332-0-285
I0329 03:45:46.235431 10927 master.cpp:1403] Filtered slave 201203290332-0-0 for framework 201203290332-0-0002 for 1 seconds
I0329 03:45:47.235499 10927 master.cpp:1184] Sending 1 offers to framework 201203290332-0-0003
I0329 03:45:47.236958 10927 master.cpp:679] Received reply for offer 201203290332-0-286
I0329 03:45:47.237149 10927 master.cpp:1403] Filtered slave 201203290332-0-0 for framework 201203290332-0-0003 for 1 seconds
I0329 03:45:48.237156 10927 master.cpp:1184] Sending 1 offers to framework 201203290332-0-0002
I0329 03:45:48.238598 10927 master.cpp:679] Received reply for offer 201203290332-0-287
I0329 03:45:48.238790 10927 master.cpp:1403] Filtered slave 201203290332-0-0 for framework 201203290332-0-0002 for 1 seconds
I0329 03:45:49.238806 10927 master.cpp:1184] Sending 1 offers to framework 201203290332-0-0003
I0329 03:45:49.240421 10927 master.cpp:679] Received reply for offer 201203290332-0-288
I0329 03:45:49.240524 10927 master.cpp:1403] Filtered slave 201203290332-0-0 for framework 201203290332-0-0003 for 1 seconds
I0329 03:45:50.240627 10927 master.cpp:1184] Sending 1 offers to framework 201203290332-0-0002
I0329 03:45:50.242144 10927 master.cpp:679] Received reply for offer 201203290332-0-289
I0329 03:45:50.242295 10927 master.cpp:1403] Filtered slave 201203290332-0-0 for framework 201203290332-0-0002 for 1 seconds
I0329 03:45:51.242365 10927 master.cpp:1184] Sending 1 offers to framework 201203290332-0-0003
I0329 03:45:51.243741 10927 master.cpp:679] Received reply for offer 201203290332-0-290
I0329 03:45:51.243921 10927 master.cpp:1403] Filtered slave 201203290332-0-0 for framework 201203290332-0-0003 for 1 seconds
I0329 03:45:52.243960 10927 master.cpp:1184] Sending 1 offers to framework 201203290332-0-0002
I0329 03:45:52.245491 10927 master.cpp:679] Received reply for offer 201203290332-0-291
I0329 03:45:52.245640 10927 master.cpp:1403] Filtered slave 201203290332-0-0 for framework 201203290332-0-0002 for 1 seconds
I0329 03:45:53.245695 10927 master.cpp:1184] Sending 1 offers to framework 201203290332-0-0003
I0329 03:45:53.247215 10927 master.cpp:679] Received reply for offer 201203290332-0-292
I0329 03:45:53.247369 10927 master.cpp:1403] Filtered slave 201203290332-0-0 for framework 201203290332-0-0003 for 1 seconds
I0329 03:45:54.247004 10927 master.cpp:1184] Sending 1 offers to framework 201203290332-0-0002
I0329 03:45:54.248502 10927 master.cpp:679] Received reply for offer 201203290332-0-293
I0329 03:45:54.248600 10927 master.cpp:1403] Filtered slave 201203290332-0-0 for framework 201203290332-0-0002 for 1 seconds
I0329 03:45:55.248685 10927 master.cpp:1184] Sending 1 offers to framework 201203290332-0-0003
I0329 03:45:55.250085 10927 master.cpp:679] Received reply for offer 201203290332-0-294
I0329 03:45:55.250241 10927 master.cpp:1403] Filtered slave 201203290332-0-0 for framework 201203290332-0-0003 for 1 seconds
I0329 03:45:56.249909 10927 master.cpp:1184] Sending 1 offers to framework 201203290332-0-0002
I0329 03:45:56.251314 10927 master.cpp:679] Received reply for offer 201203290332-0-295
I0329 03:45:56.251466 10927 master.cpp:1403] Filtered slave 201203290332-0-0 for framework 201203290332-0-0002 for 1 seconds
I0329 03:45:57.251538 10927 master.cpp:1184] Sending 1 offers to framework 201203290332-0-0003
I0329 03:45:57.252945 10927 master.cpp:679] Received reply for offer 201203290332-0-296
I0329 03:45:57.253196 10927 master.cpp:1403] Filtered slave 201203290332-0-0 for framework 201203290332-0-0003 for 1 seconds
I0329 03:45:58.253211 10927 master.cpp:1184] Sending 1 offers to framework 201203290332-0-0002
I0329 03:45:58.254674 10927 master.cpp:679] Received reply for offer 201203290332-0-297
I0329 03:45:58.254824 10927 master.cpp:1403] Filtered slave 201203290332-0-0 for framework 201203290332-0-0002 for 1 seconds
I0329 03:45:59.254873 10927 master.cpp:1184] Sending 1 offers to framework 201203290332-0-0003
I0329 03:45:59.256429 10927 master.cpp:679] Received reply for offer 201203290332-0-298
I0329 03:45:59.256528 10927 master.cpp:1403] Filtered slave 201203290332-0-0 for framework 201203290332-0-0003 for 1 seconds
I0329 03:46:00.256662 10927 master.cpp:1184] Sending 1 offers to framework 201203290332-0-0002
I0329 03:46:00.258054 10927 master.cpp:679] Received reply for offer 201203290332-0-299
I0329 03:46:00.258249 10927 master.cpp:1403] Filtered slave 201203290332-0-0 for framework 201203290332-0-0002 for 1 seconds
I0329 03:46:01.258255 10927 master.cpp:1184] Sending 1 offers to framework 201203290332-0-0003
I0329 03:46:01.259817 10927 master.cpp:679] Received reply for offer 201203290332-0-300
I0329 03:46:01.260015 10927 master.cpp:1403] Filtered slave 201203290332-0-0 for framework 201203290332-0-0003 for 1 seconds
I0329 03:46:02.259469 10927 master.cpp:1184] Sending 1 offers to framework 201203290332-0-0002
I0329 03:46:02.260918 10927 master.cpp:679] Received reply for offer 201203290332-0-301
I0329 03:46:02.261068 10927 master.cpp:1403] Filtered slave 201203290332-0-0 for framework 201203290332-0-0002 for 1 seconds
I0329 03:46:03.261140 10927 master.cpp:1184] Sending 1 offers to framework 201203290332-0-0003
I0329 03:46:03.262642 10927 master.cpp:679] Received reply for offer 201203290332-0-302
I0329 03:46:03.262795 10927 master.cpp:1403] Filtered slave 201203290332-0-0 for framework 201203290332-0-0003 for 1 seconds
I0329 03:46:04.262842 10927 master.cpp:1184] Sending 1 offers to framework 201203290332-0-0002
I0329 03:46:04.264173 10927 master.cpp:679] Received reply for offer 201203290332-0-303
I0329 03:46:04.264272 10927 master.cpp:1403] Filtered slave 201203290332-0-0 for framework 201203290332-0-0002 for 1 seconds
I0329 03:46:05.264425 10927 master.cpp:1184] Sending 1 offers to framework 201203290332-0-0003
I0329 03:46:05.266047 10927 master.cpp:679] Received reply for offer 201203290332-0-304
I0329 03:46:05.266203 10927 master.cpp:1403] Filtered slave 201203290332-0-0 for framework 201203290332-0-0003 for 1 seconds
I0329 03:46:06.266278 10927 master.cpp:1184] Sending 1 offers to framework 201203290332-0-0002
I0329 03:46:06.267976 10927 master.cpp:679] Received reply for offer 201203290332-0-305
I0329 03:46:06.268131 10927 master.cpp:1403] Filtered slave 201203290332-0-0 for framework 201203290332-0-0002 for 1 seconds
I0329 03:46:07.267482 10927 master.cpp:1184] Sending 1 offers to framework 201203290332-0-0003
I0329 03:46:07.269099 10927 master.cpp:679] Received reply for offer 201203290332-0-306
I0329 03:46:07.269254 10927 master.cpp:1403] Filtered slave 201203290332-0-0 for framework 201203290332-0-0003 for 1 seconds
I0329 03:46:08.269374 10927 master.cpp:1184] Sending 1 offers to framework 201203290332-0-0002
I0329 03:46:08.271033 10927 master.cpp:679] Received reply for offer 201203290332-0-307
I0329 03:46:08.271373 10927 master.cpp:1403] Filtered slave 201203290332-0-0 for framework 201203290332-0-0002 for 1 seconds
I0329 03:46:09.270149 10927 master.cpp:1184] Sending 1 offers to framework 201203290332-0-0003
I0329 03:46:09.271785 10927 master.cpp:679] Received reply for offer 201203290332-0-308
I0329 03:46:09.271888 10927 master.cpp:1403] Filtered slave 201203290332-0-0 for framework 201203290332-0-0003 for 1 seconds
I0329 03:46:10.271591 10927 master.cpp:1184] Sending 1 offers to framework 201203290332-0-0002
I0329 03:46:10.273134 10927 master.cpp:679] Received reply for offer 201203290332-0-309
I0329 03:46:10.273291 10927 master.cpp:1403] Filtered slave 201203290332-0-0 for framework 201203290332-0-0002 for 1 seconds
I0329 03:46:11.273416 10927 master.cpp:1184] Sending 1 offers to framework 201203290332-0-0003
I0329 03:46:11.274993 10927 master.cpp:679] Received reply for offer 201203290332-0-310
I0329 03:46:11.275214 10927 master.cpp:1403] Filtered slave 201203290332-0-0 for framework 201203290332-0-0003 for 1 seconds
I0329 03:46:12.275298 10927 master.cpp:1184] Sending 1 offers to framework 201203290332-0-0002
I0329 03:46:12.277094 10927 master.cpp:679] Received reply for offer 201203290332-0-311
I0329 03:46:12.277250 10927 master.cpp:1403] Filtered slave 201203290332-0-0 for framework 201203290332-0-0002 for 1 seconds
I0329 03:46:13.277565 10927 master.cpp:1184] Sending 1 offers to framework 201203290332-0-0003
I0329 03:46:13.279487 10927 master.cpp:679] Received reply for offer 201203290332-0-312
I0329 03:46:13.279645 10927 master.cpp:1403] Filtered slave 201203290332-0-0 for framework 201203290332-0-0003 for 1 seconds
I0329 03:46:14.279788 10927 master.cpp:1184] Sending 1 offers to framework 201203290332-0-0002
I0329 03:46:14.281569 10927 master.cpp:679] Received reply for offer 201203290332-0-313
I0329 03:46:14.281669 10927 master.cpp:1403] Filtered slave 201203290332-0-0 for framework 201203290332-0-0002 for 1 seconds
I0329 03:46:15.281877 10927 master.cpp:1184] Sending 1 offers to framework 201203290332-0-0003
I0329 03:46:15.283685 10927 master.cpp:679] Received reply for offer 201203290332-0-314
I0329 03:46:15.283841 10927 master.cpp:1403] Filtered slave 201203290332-0-0 for framework 201203290332-0-0003 for 1 seconds
I0329 03:46:16.283963 10927 master.cpp:1184] Sending 1 offers to framework 201203290332-0-0002
I0329 03:46:16.285853 10927 master.cpp:679] Received reply for offer 201203290332-0-315
I0329 03:46:16.286015 10927 master.cpp:1403] Filtered slave 201203290332-0-0 for framework 201203290332-0-0002 for 1 seconds
I0329 03:46:17.286108 10927 master.cpp:1184] Sending 1 offers to framework 201203290332-0-0003
I0329 03:46:17.287889 10927 master.cpp:679] Received reply for offer 201203290332-0-316
I0329 03:46:17.288046 10927 master.cpp:1403] Filtered slave 201203290332-0-0 for framework 201203290332-0-0003 for 1 seconds
I0329 03:46:18.288167 10927 master.cpp:1184] Sending 1 offers to framework 201203290332-0-0002
I0329 03:46:18.289870 10927 master.cpp:679] Received reply for offer 201203290332-0-317
I0329 03:46:18.290025 10927 master.cpp:1403] Filtered slave 201203290332-0-0 for framework 201203290332-0-0002 for 1 seconds
I0329 03:46:19.290205 10927 master.cpp:1184] Sending 1 offers to framework 201203290332-0-0003
I0329 03:46:19.291985 10927 master.cpp:679] Received reply for offer 201203290332-0-318
I0329 03:46:19.292089 10927 master.cpp:1403] Filtered slave 201203290332-0-0 for framework 201203290332-0-0003 for 1 seconds
I0329 03:46:20.292284 10927 master.cpp:1184] Sending 1 offers to framework 201203290332-0-0002
I0329 03:46:20.293954 10927 master.cpp:679] Received reply for offer 201203290332-0-319
I0329 03:46:20.294106 10927 master.cpp:1403] Filtered slave 201203290332-0-0 for framework 201203290332-0-0002 for 1 seconds
I0329 03:46:21.294308 10927 master.cpp:1184] Sending 1 offers to framework 201203290332-0-0003
I0329 03:46:21.296079 10927 master.cpp:679] Received reply for offer 201203290332-0-320
I0329 03:46:21.296236 10927 master.cpp:1403] Filtered slave 201203290332-0-0 for framework 201203290332-0-0003 for 1 seconds
I0329 03:46:22.296350 10927 master.cpp:1184] Sending 1 offers to framework 201203290332-0-0002
I0329 03:46:22.297976 10927 master.cpp:679] Received reply for offer 201203290332-0-321
I0329 03:46:22.298127 10927 master.cpp:1403] Filtered slave 201203290332-0-0 for framework 201203290332-0-0002 for 1 seconds
I0329 03:46:23.298265 10927 master.cpp:1184] Sending 1 offers to framework 201203290332-0-0003
I0329 03:46:23.300046 10927 master.cpp:679] Received reply for offer 201203290332-0-322
I0329 03:46:23.300262 10927 master.cpp:1403] Filtered slave 201203290332-0-0 for framework 201203290332-0-0003 for 1 seconds
I0329 03:46:24.299294 10927 master.cpp:1184] Sending 1 offers to framework 201203290332-0-0002
I0329 03:46:24.301096 10927 master.cpp:679] Received reply for offer 201203290332-0-323
I0329 03:46:24.307497 10927 master.cpp:1403] Filtered slave 201203290332-0-0 for framework 201203290332-0-0002 for 1 seconds
I0329 03:46:25.301400 10927 master.cpp:1184] Sending 1 offers to framework 201203290332-0-0003
I0329 03:46:25.303056 10927 master.cpp:679] Received reply for offer 201203290332-0-324
I0329 03:46:25.303217 10927 master.cpp:1403] Filtered slave 201203290332-0-0 for framework 201203290332-0-0003 for 1 seconds
I0329 03:46:26.303302 10927 master.cpp:1184] Sending 1 offers to framework 201203290332-0-0002
I0329 03:46:26.305096 10927 master.cpp:679] Received reply for offer 201203290332-0-325
I0329 03:46:26.305250 10927 master.cpp:1403] Filtered slave 201203290332-0-0 for framework 201203290332-0-0002 for 1 seconds
I0329 03:46:27.305397 10927 master.cpp:1184] Sending 1 offers to framework 201203290332-0-0003
I0329 03:46:27.307091 10927 master.cpp:679] Received reply for offer 201203290332-0-326
I0329 03:46:27.307276 10927 master.cpp:1403] Filtered slave 201203290332-0-0 for framework 201203290332-0-0003 for 1 seconds
I0329 03:46:28.307325 10927 master.cpp:1184] Sending 1 offers to framework 201203290332-0-0002
I0329 03:46:28.309062 10927 master.cpp:679] Received reply for offer 201203290332-0-327
I0329 03:46:28.309213 10927 master.cpp:1403] Filtered slave 201203290332-0-0 for framework 201203290332-0-0002 for 1 seconds
I0329 03:46:29.309257 10927 master.cpp:1184] Sending 1 offers to framework 201203290332-0-0003
I0329 03:46:29.310881 10927 master.cpp:679] Received reply for offer 201203290332-0-328
I0329 03:46:29.310979 10927 master.cpp:1403] Filtered slave 201203290332-0-0 for framework 201203290332-0-0003 for 1 seconds
I0329 03:46:30.311089 10927 master.cpp:1184] Sending 1 offers to framework 201203290332-0-0002
I0329 03:46:30.312711 10927 master.cpp:679] Received reply for offer 201203290332-0-329
I0329 03:46:30.312861 10927 master.cpp:1403] Filtered slave 201203290332-0-0 for framework 201203290332-0-0002 for 1 seconds
I0329 03:46:31.312928 10927 master.cpp:1184] Sending 1 offers to framework 201203290332-0-0003
I0329 03:46:31.314528 10927 master.cpp:679] Received reply for offer 201203290332-0-330
I0329 03:46:31.314682 10927 master.cpp:1403] Filtered slave 201203290332-0-0 for framework 201203290332-0-0003 for 1 seconds
I0329 03:46:32.314728 10927 master.cpp:1184] Sending 1 offers to framework 201203290332-0-0002
I0329 03:46:32.316393 10927 master.cpp:679] Received reply for offer 201203290332-0-331
I0329 03:46:32.316546 10927 master.cpp:1403] Filtered slave 201203290332-0-0 for framework 201203290332-0-0002 for 1 seconds
I0329 03:46:33.316526 10927 master.cpp:1184] Sending 1 offers to framework 201203290332-0-0003
I0329 03:46:33.318135 10927 master.cpp:679] Received reply for offer 201203290332-0-332
I0329 03:46:33.318289 10927 master.cpp:1403] Filtered slave 201203290332-0-0 for framework 201203290332-0-0003 for 1 seconds
I0329 03:46:34.318352 10927 master.cpp:1184] Sending 1 offers to framework 201203290332-0-0002
I0329 03:46:34.319979 10927 master.cpp:679] Received reply for offer 201203290332-0-333
I0329 03:46:34.320078 10927 master.cpp:1403] Filtered slave 201203290332-0-0 for framework 201203290332-0-0002 for 1 seconds
I0329 03:46:35.320180 10927 master.cpp:1184] Sending 1 offers to framework 201203290332-0-0003
I0329 03:46:35.321746 10927 master.cpp:679] Received reply for offer 201203290332-0-334
I0329 03:46:35.321898 10927 master.cpp:1403] Filtered slave 201203290332-0-0 for framework 201203290332-0-0003 for 1 seconds
I0329 03:46:36.321943 10927 master.cpp:1184] Sending 1 offers to framework 201203290332-0-0002
I0329 03:46:36.323585 10927 master.cpp:679] Received reply for offer 201203290332-0-335
I0329 03:46:36.323737 10927 master.cpp:1403] Filtered slave 201203290332-0-0 for framework 201203290332-0-0002 for 1 seconds
I0329 03:46:37.323782 10927 master.cpp:1184] Sending 1 offers to framework 201203290332-0-0003
I0329 03:46:37.325417 10927 master.cpp:679] Received reply for offer 201203290332-0-336
I0329 03:46:37.325600 10927 master.cpp:1403] Filtered slave 201203290332-0-0 for framework 201203290332-0-0003 for 1 seconds
I0329 03:46:38.325670 10927 master.cpp:1184] Sending 1 offers to framework 201203290332-0-0002
I0329 03:46:38.327296 10927 master.cpp:679] Received reply for offer 201203290332-0-337
I0329 03:46:38.327450 10927 master.cpp:1403] Filtered slave 201203290332-0-0 for framework 201203290332-0-0002 for 1 seconds
I0329 03:46:39.327240 10927 master.cpp:1184] Sending 1 offers to framework 201203290332-0-0003
I0329 03:46:39.328866 10927 master.cpp:679] Received reply for offer 201203290332-0-338
I0329 03:46:39.328965 10927 master.cpp:1403] Filtered slave 201203290332-0-0 for framework 201203290332-0-0003 for 1 seconds
I0329 03:46:40.329062 10927 master.cpp:1184] Sending 1 offers to framework 201203290332-0-0002
I0329 03:46:40.330647 10927 master.cpp:679] Received reply for offer 201203290332-0-339
I0329 03:46:40.330798 10927 master.cpp:1403] Filtered slave 201203290332-0-0 for framework 201203290332-0-0002 for 1 seconds
I0329 03:46:41.330847 10927 master.cpp:1184] Sending 1 offers to framework 201203290332-0-0003
I0329 03:46:41.332448 10927 master.cpp:679] Received reply for offer 201203290332-0-340
I0329 03:46:41.332648 10927 master.cpp:1403] Filtered slave 201203290332-0-0 for framework 201203290332-0-0003 for 1 seconds
I0329 03:46:42.331542 10927 master.cpp:1184] Sending 1 offers to framework 201203290332-0-0002
I0329 03:46:42.333159 10927 master.cpp:679] Received reply for offer 201203290332-0-341
I0329 03:46:42.333312 10927 master.cpp:1403] Filtered slave 201203290332-0-0 for framework 201203290332-0-0002 for 1 seconds
I0329 03:46:43.333320 10927 master.cpp:1184] Sending 1 offers to framework 201203290332-0-0003
I0329 03:46:43.334923 10927 master.cpp:679] Received reply for offer 201203290332-0-342
I0329 03:46:43.335157 10927 master.cpp:1403] Filtered slave 201203290332-0-0 for framework 201203290332-0-0003 for 1 seconds
I0329 03:46:44.335139 10927 master.cpp:1184] Sending 1 offers to framework 201203290332-0-0002
I0329 03:46:44.336735 10927 master.cpp:679] Received reply for offer 201203290332-0-343
I0329 03:46:44.336833 10927 master.cpp:1403] Filtered slave 201203290332-0-0 for framework 201203290332-0-0002 for 1 seconds
I0329 03:46:45.336938 10927 master.cpp:1184] Sending 1 offers to framework 201203290332-0-0003
I0329 03:46:45.338493 10927 master.cpp:679] Received reply for offer 201203290332-0-344
I0329 03:46:45.338646 10927 master.cpp:1403] Filtered slave 201203290332-0-0 for framework 201203290332-0-0003 for 1 seconds
I0329 03:46:46.338739 10927 master.cpp:1184] Sending 1 offers to framework 201203290332-0-0002
I0329 03:46:46.340415 10927 master.cpp:679] Received reply for offer 201203290332-0-345
I0329 03:46:46.340575 10927 master.cpp:1403] Filtered slave 201203290332-0-0 for framework 201203290332-0-0002 for 1 seconds
I0329 03:46:47.340613 10927 master.cpp:1184] Sending 1 offers to framework 201203290332-0-0003
I0329 03:46:47.342139 10927 master.cpp:679] Received reply for offer 201203290332-0-346
I0329 03:46:47.342293 10927 master.cpp:1403] Filtered slave 201203290332-0-0 for framework 201203290332-0-0003 for 1 seconds
I0329 03:46:48.342344 10927 master.cpp:1184] Sending 1 offers to framework 201203290332-0-0002
I0329 03:46:48.343796 10927 master.cpp:679] Received reply for offer 201203290332-0-347
I0329 03:46:48.343951 10927 master.cpp:1403] Filtered slave 201203290332-0-0 for framework 201203290332-0-0002 for 1 seconds
I0329 03:46:49.343997 10927 master.cpp:1184] Sending 1 offers to framework 201203290332-0-0003
I0329 03:46:49.345423 10927 master.cpp:679] Received reply for offer 201203290332-0-348
I0329 03:46:49.345522 10927 master.cpp:1403] Filtered slave 201203290332-0-0 for framework 201203290332-0-0003 for 1 seconds
I0329 03:46:50.345649 10927 master.cpp:1184] Sending 1 offers to framework 201203290332-0-0002
I0329 03:46:50.347178 10927 master.cpp:679] Received reply for offer 201203290332-0-349
I0329 03:46:50.347332 10927 master.cpp:1403] Filtered slave 201203290332-0-0 for framework 201203290332-0-0002 for 1 seconds
I0329 03:46:51.347368 10927 master.cpp:1184] Sending 1 offers to framework 201203290332-0-0003
I0329 03:46:51.348881 10927 master.cpp:679] Received reply for offer 201203290332-0-350
I0329 03:46:51.349035 10927 master.cpp:1403] Filtered slave 201203290332-0-0 for framework 201203290332-0-0003 for 1 seconds
I0329 03:46:52.349072 10927 master.cpp:1184] Sending 1 offers to framework 201203290332-0-0002
I0329 03:46:52.350672 10927 master.cpp:679] Received reply for offer 201203290332-0-351
I0329 03:46:52.350824 10927 master.cpp:1403] Filtered slave 201203290332-0-0 for framework 201203290332-0-0002 for 1 seconds
I0329 03:46:53.350829 10927 master.cpp:1184] Sending 1 offers to framework 201203290332-0-0003
I0329 03:46:53.352426 10927 master.cpp:679] Received reply for offer 201203290332-0-352
I0329 03:46:53.352581 10927 master.cpp:1403] Filtered slave 201203290332-0-0 for framework 201203290332-0-0003 for 1 seconds
I0329 03:46:54.352200 10927 master.cpp:1184] Sending 1 offers to framework 201203290332-0-0002
I0329 03:46:54.353765 10927 master.cpp:679] Received reply for offer 201203290332-0-353
I0329 03:46:54.353870 10927 master.cpp:1403] Filtered slave 201203290332-0-0 for framework 201203290332-0-0002 for 1 seconds
I0329 03:46:55.353960 10927 master.cpp:1184] Sending 1 offers to framework 201203290332-0-0003
I0329 03:46:55.355527 10927 master.cpp:679] Received reply for offer 201203290332-0-354
I0329 03:46:55.355681 10927 master.cpp:1403] Filtered slave 201203290332-0-0 for framework 201203290332-0-0003 for 1 seconds
I0329 03:46:56.355731 10927 master.cpp:1184] Sending 1 offers to framework 201203290332-0-0002
I0329 03:46:56.357236 10927 master.cpp:679] Received reply for offer 201203290332-0-355
I0329 03:46:56.357388 10927 master.cpp:1403] Filtered slave 201203290332-0-0 for framework 201203290332-0-0002 for 1 seconds
I0329 03:46:57.356500 10927 master.cpp:1184] Sending 1 offers to framework 201203290332-0-0003
I0329 03:46:57.358000 10927 master.cpp:679] Received reply for offer 201203290332-0-356
I0329 03:46:57.358154 10927 master.cpp:1403] Filtered slave 201203290332-0-0 for framework 201203290332-0-0003 for 1 seconds
I0329 03:46:58.358202 10927 master.cpp:1184] Sending 1 offers to framework 201203290332-0-0002
I0329 03:46:58.359702 10927 master.cpp:679] Received reply for offer 201203290332-0-357
I0329 03:46:58.359856 10927 master.cpp:1403] Filtered slave 201203290332-0-0 for framework 201203290332-0-0002 for 1 seconds
I0329 03:46:59.359906 10927 master.cpp:1184] Sending 1 offers to framework 201203290332-0-0003
I0329 03:46:59.361382 10927 master.cpp:679] Received reply for offer 201203290332-0-358
I0329 03:46:59.361482 10927 master.cpp:1403] Filtered slave 201203290332-0-0 for framework 201203290332-0-0003 for 1 seconds
I0329 03:47:00.361582 10927 master.cpp:1184] Sending 1 offers to framework 201203290332-0-0002
I0329 03:47:00.363145 10927 master.cpp:679] Received reply for offer 201203290332-0-359
I0329 03:47:00.363298 10927 master.cpp:1403] Filtered slave 201203290332-0-0 for framework 201203290332-0-0002 for 1 seconds
I0329 03:47:01.363287 10927 master.cpp:1184] Sending 1 offers to framework 201203290332-0-0003
I0329 03:47:01.364637 10927 master.cpp:679] Received reply for offer 201203290332-0-360
I0329 03:47:01.364759 10927 master.cpp:1403] Filtered slave 201203290332-0-0 for framework 201203290332-0-0003 for 1 seconds
I0329 03:47:02.364852 10927 master.cpp:1184] Sending 1 offers to framework 201203290332-0-0002
I0329 03:47:02.366509 10927 master.cpp:679] Received reply for offer 201203290332-0-361
I0329 03:47:02.366662 10927 master.cpp:1403] Filtered slave 201203290332-0-0 for framework 201203290332-0-0002 for 1 seconds
I0329 03:47:03.366711 10927 master.cpp:1184] Sending 1 offers to framework 201203290332-0-0003
I0329 03:47:03.368212 10927 master.cpp:679] Received reply for offer 201203290332-0-362
I0329 03:47:03.368367 10927 master.cpp:1403] Filtered slave 201203290332-0-0 for framework 201203290332-0-0003 for 1 seconds
I0329 03:47:04.368415 10927 master.cpp:1184] Sending 1 offers to framework 201203290332-0-0002
I0329 03:47:04.369941 10927 master.cpp:679] Received reply for offer 201203290332-0-363
I0329 03:47:04.370040 10927 master.cpp:1403] Filtered slave 201203290332-0-0 for framework 201203290332-0-0002 for 1 seconds
I0329 03:47:05.370162 10927 master.cpp:1184] Sending 1 offers to framework 201203290332-0-0003
I0329 03:47:05.371726 10927 master.cpp:679] Received reply for offer 201203290332-0-364
I0329 03:47:05.371881 10927 master.cpp:1403] Filtered slave 201203290332-0-0 for framework 201203290332-0-0003 for 1 seconds
I0329 03:47:06.371384 10927 master.cpp:1184] Sending 1 offers to framework 201203290332-0-0002
I0329 03:47:06.372894 10927 master.cpp:679] Received reply for offer 201203290332-0-365
I0329 03:47:06.373044 10927 master.cpp:1403] Filtered slave 201203290332-0-0 for framework 201203290332-0-0002 for 1 seconds
I0329 03:47:07.373049 10927 master.cpp:1184] Sending 1 offers to framework 201203290332-0-0003
I0329 03:47:07.374534 10927 master.cpp:679] Received reply for offer 201203290332-0-366
I0329 03:47:07.374687 10927 master.cpp:1403] Filtered slave 201203290332-0-0 for framework 201203290332-0-0003 for 1 seconds
I0329 03:47:08.374737 10927 master.cpp:1184] Sending 1 offers to framework 201203290332-0-0002
I0329 03:47:08.376241 10927 master.cpp:679] Received reply for offer 201203290332-0-367
I0329 03:47:08.376394 10927 master.cpp:1403] Filtered slave 201203290332-0-0 for framework 201203290332-0-0002 for 1 seconds
I0329 03:47:09.376092 10927 master.cpp:1184] Sending 1 offers to framework 201203290332-0-0003
I0329 03:47:09.377506 10927 master.cpp:679] Received reply for offer 201203290332-0-368
I0329 03:47:09.377606 10927 master.cpp:1403] Filtered slave 201203290332-0-0 for framework 201203290332-0-0003 for 1 seconds
I0329 03:47:10.377645 10927 master.cpp:1184] Sending 1 offers to framework 201203290332-0-0002
I0329 03:47:10.378770 10927 master.cpp:679] Received reply for offer 201203290332-0-369
I0329 03:47:10.378931 10927 master.cpp:1403] Filtered slave 201203290332-0-0 for framework 201203290332-0-0002 for 1 seconds
I0329 03:47:11.379367 10927 master.cpp:1184] Sending 1 offers to framework 201203290332-0-0003
I0329 03:47:11.380964 10927 master.cpp:679] Received reply for offer 201203290332-0-370
I0329 03:47:11.381132 10927 master.cpp:1403] Filtered slave 201203290332-0-0 for framework 201203290332-0-0003 for 1 seconds
I0329 03:47:12.380424 10927 master.cpp:1184] Sending 1 offers to framework 201203290332-0-0002
I0329 03:47:12.381896 10927 master.cpp:679] Received reply for offer 201203290332-0-371
I0329 03:47:12.382050 10927 master.cpp:1403] Filtered slave 201203290332-0-0 for framework 201203290332-0-0002 for 1 seconds
I0329 03:47:13.382112 10927 master.cpp:1184] Sending 1 offers to framework 201203290332-0-0003
I0329 03:47:13.383597 10927 master.cpp:679] Received reply for offer 201203290332-0-372
I0329 03:47:13.383797 10927 master.cpp:1403] Filtered slave 201203290332-0-0 for framework 201203290332-0-0003 for 1 seconds
I0329 03:47:14.383787 10927 master.cpp:1184] Sending 1 offers to framework 201203290332-0-0002
I0329 03:47:14.385301 10927 master.cpp:679] Received reply for offer 201203290332-0-373
I0329 03:47:14.385473 10927 master.cpp:1403] Filtered slave 201203290332-0-0 for framework 201203290332-0-0002 for 1 seconds
I0329 03:47:15.385490 10927 master.cpp:1184] Sending 1 offers to framework 201203290332-0-0003
I0329 03:47:15.386927 10927 master.cpp:679] Received reply for offer 201203290332-0-374
I0329 03:47:15.387126 10927 master.cpp:1403] Filtered slave 201203290332-0-0 for framework 201203290332-0-0003 for 1 seconds
I0329 03:47:16.387343 10927 master.cpp:1184] Sending 1 offers to framework 201203290332-0-0002
I0329 03:47:16.388803 10927 master.cpp:679] Received reply for offer 201203290332-0-375
I0329 03:47:16.389022 10927 master.cpp:1403] Filtered slave 201203290332-0-0 for framework 201203290332-0-0002 for 1 seconds
I0329 03:47:17.389050 10927 master.cpp:1184] Sending 1 offers to framework 201203290332-0-0003
I0329 03:47:17.390379 10927 master.cpp:679] Received reply for offer 201203290332-0-376
I0329 03:47:17.390538 10927 master.cpp:1403] Filtered slave 201203290332-0-0 for framework 201203290332-0-0003 for 1 seconds
I0329 03:47:18.390594 10927 master.cpp:1184] Sending 1 offers to framework 201203290332-0-0002
I0329 03:47:18.392061 10927 master.cpp:679] Received reply for offer 201203290332-0-377
I0329 03:47:18.392215 10927 master.cpp:1403] Filtered slave 201203290332-0-0 for framework 201203290332-0-0002 for 1 seconds
I0329 03:47:19.392277 10927 master.cpp:1184] Sending 1 offers to framework 201203290332-0-0003
I0329 03:47:19.393779 10927 master.cpp:679] Received reply for offer 201203290332-0-378
I0329 03:47:19.393878 10927 master.cpp:1403] Filtered slave 201203290332-0-0 for framework 201203290332-0-0003 for 1 seconds
I0329 03:47:20.393939 10927 master.cpp:1184] Sending 1 offers to framework 201203290332-0-0002
I0329 03:47:20.395413 10927 master.cpp:679] Received reply for offer 201203290332-0-379
I0329 03:47:20.395567 10927 master.cpp:1403] Filtered slave 201203290332-0-0 for framework 201203290332-0-0002 for 1 seconds
I0329 03:47:21.395632 10927 master.cpp:1184] Sending 1 offers to framework 201203290332-0-0003
I0329 03:47:21.397107 10927 master.cpp:679] Received reply for offer 201203290332-0-380
I0329 03:47:21.397261 10927 master.cpp:1403] Filtered slave 201203290332-0-0 for framework 201203290332-0-0003 for 1 seconds
I0329 03:47:22.397297 10927 master.cpp:1184] Sending 1 offers to framework 201203290332-0-0002
I0329 03:47:22.398741 10927 master.cpp:679] Received reply for offer 201203290332-0-381
I0329 03:47:22.398893 10927 master.cpp:1403] Filtered slave 201203290332-0-0 for framework 201203290332-0-0002 for 1 seconds
I0329 03:47:23.398963 10927 master.cpp:1184] Sending 1 offers to framework 201203290332-0-0003
I0329 03:47:23.400543 10927 master.cpp:679] Received reply for offer 201203290332-0-382
I0329 03:47:23.400701 10927 master.cpp:1403] Filtered slave 201203290332-0-0 for framework 201203290332-0-0003 for 1 seconds
I0329 03:47:24.400466 10927 master.cpp:1184] Sending 1 offers to framework 201203290332-0-0002
I0329 03:47:24.401962 10927 master.cpp:679] Received reply for offer 201203290332-0-383
I0329 03:47:24.402060 10927 master.cpp:1403] Filtered slave 201203290332-0-0 for framework 201203290332-0-0002 for 1 seconds
I0329 03:47:25.402144 10927 master.cpp:1184] Sending 1 offers to framework 201203290332-0-0003
I0329 03:47:25.403630 10927 master.cpp:679] Received reply for offer 201203290332-0-384
I0329 03:47:25.403784 10927 master.cpp:1403] Filtered slave 201203290332-0-0 for framework 201203290332-0-0003 for 1 seconds
I0329 03:47:26.403831 10927 master.cpp:1184] Sending 1 offers to framework 201203290332-0-0002
I0329 03:47:26.405300 10927 master.cpp:679] Received reply for offer 201203290332-0-385
I0329 03:47:26.405460 10927 master.cpp:1403] Filtered slave 201203290332-0-0 for framework 201203290332-0-0002 for 1 seconds
I0329 03:47:27.404474 10927 master.cpp:1184] Sending 1 offers to framework 201203290332-0-0003
I0329 03:47:27.405930 10927 master.cpp:679] Received reply for offer 201203290332-0-386
I0329 03:47:27.406082 10927 master.cpp:1403] Filtered slave 201203290332-0-0 for framework 201203290332-0-0003 for 1 seconds
I0329 03:47:28.406142 10927 master.cpp:1184] Sending 1 offers to framework 201203290332-0-0002
I0329 03:47:28.407605 10927 master.cpp:679] Received reply for offer 201203290332-0-387
I0329 03:47:28.407757 10927 master.cpp:1403] Filtered slave 201203290332-0-0 for framework 201203290332-0-0002 for 1 seconds
I0329 03:47:29.407134 10927 master.cpp:1184] Sending 1 offers to framework 201203290332-0-0003
I0329 03:47:29.408627 10927 master.cpp:679] Received reply for offer 201203290332-0-388
I0329 03:47:29.408725 10927 master.cpp:1403] Filtered slave 201203290332-0-0 for framework 201203290332-0-0003 for 1 seconds
I0329 03:47:30.408885 10927 master.cpp:1184] Sending 1 offers to framework 201203290332-0-0002
I0329 03:47:30.410256 10927 master.cpp:679] Received reply for offer 201203290332-0-389
I0329 03:47:30.410444 10927 master.cpp:1403] Filtered slave 201203290332-0-0 for framework 201203290332-0-0002 for 1 seconds
I0329 03:47:31.410509 10927 master.cpp:1184] Sending 1 offers to framework 201203290332-0-0003
I0329 03:47:31.411836 10927 master.cpp:679] Received reply for offer 201203290332-0-390
I0329 03:47:31.411993 10927 master.cpp:1403] Filtered slave 201203290332-0-0 for framework 201203290332-0-0003 for 1 seconds
I0329 03:47:32.412035 10927 master.cpp:1184] Sending 1 offers to framework 201203290332-0-0002
I0329 03:47:32.413738 10927 master.cpp:679] Received reply for offer 201203290332-0-391
I0329 03:47:32.413894 10927 master.cpp:1403] Filtered slave 201203290332-0-0 for framework 201203290332-0-0002 for 1 seconds
I0329 03:47:33.413974 10927 master.cpp:1184] Sending 1 offers to framework 201203290332-0-0003
I0329 03:47:33.415367 10927 master.cpp:679] Received reply for offer 201203290332-0-392
I0329 03:47:33.415525 10927 master.cpp:1403] Filtered slave 201203290332-0-0 for framework 201203290332-0-0003 for 1 seconds
I0329 03:47:34.415562 10927 master.cpp:1184] Sending 1 offers to framework 201203290332-0-0002
I0329 03:47:34.417033 10927 master.cpp:679] Received reply for offer 201203290332-0-393
I0329 03:47:34.417131 10927 master.cpp:1403] Filtered slave 201203290332-0-0 for framework 201203290332-0-0002 for 1 seconds
I0329 03:47:35.417233 10927 master.cpp:1184] Sending 1 offers to framework 201203290332-0-0003
I0329 03:47:35.418673 10927 master.cpp:679] Received reply for offer 201203290332-0-394
I0329 03:47:35.418829 10927 master.cpp:1403] Filtered slave 201203290332-0-0 for framework 201203290332-0-0003 for 1 seconds
I0329 03:47:36.418436 10927 master.cpp:1184] Sending 1 offers to framework 201203290332-0-0002
I0329 03:47:36.419837 10927 master.cpp:679] Received reply for offer 201203290332-0-395
I0329 03:47:36.419993 10927 master.cpp:1403] Filtered slave 201203290332-0-0 for framework 201203290332-0-0002 for 1 seconds
I0329 03:47:37.419996 10927 master.cpp:1184] Sending 1 offers to framework 201203290332-0-0003
I0329 03:47:37.421422 10927 master.cpp:679] Received reply for offer 201203290332-0-396
I0329 03:47:37.421577 10927 master.cpp:1403] Filtered slave 201203290332-0-0 for framework 201203290332-0-0003 for 1 seconds
I0329 03:47:38.421576 10927 master.cpp:1184] Sending 1 offers to framework 201203290332-0-0002
I0329 03:47:38.422942 10927 master.cpp:679] Received reply for offer 201203290332-0-397
I0329 03:47:38.423106 10927 master.cpp:1403] Filtered slave 201203290332-0-0 for framework 201203290332-0-0002 for 1 seconds
I0329 03:47:39.422754 10927 master.cpp:1184] Sending 1 offers to framework 201203290332-0-0003
I0329 03:47:39.424185 10927 master.cpp:679] Received reply for offer 201203290332-0-398
I0329 03:47:39.424286 10927 master.cpp:1403] Filtered slave 201203290332-0-0 for framework 201203290332-0-0003 for 1 seconds
I0329 03:47:40.424402 10927 master.cpp:1184] Sending 1 offers to framework 201203290332-0-0002
I0329 03:47:40.425806 10927 master.cpp:679] Received reply for offer 201203290332-0-399
I0329 03:47:40.425961 10927 master.cpp:1403] Filtered slave 201203290332-0-0 for framework 201203290332-0-0002 for 1 seconds
I0329 03:47:41.425994 10927 master.cpp:1184] Sending 1 offers to framework 201203290332-0-0003
I0329 03:47:41.427345 10927 master.cpp:679] Received reply for offer 201203290332-0-400
I0329 03:47:41.427505 10927 master.cpp:1403] Filtered slave 201203290332-0-0 for framework 201203290332-0-0003 for 1 seconds
I0329 03:47:42.426574 10927 master.cpp:1184] Sending 1 offers to framework 201203290332-0-0002
I0329 03:47:42.428122 10927 master.cpp:679] Received reply for offer 201203290332-0-401
I0329 03:47:42.428275 10927 master.cpp:1403] Filtered slave 201203290332-0-0 for framework 201203290332-0-0002 for 1 seconds
I0329 03:47:43.428339 10927 master.cpp:1184] Sending 1 offers to framework 201203290332-0-0003
I0329 03:47:43.429677 10927 master.cpp:679] Received reply for offer 201203290332-0-402
I0329 03:47:43.429860 10927 master.cpp:1403] Filtered slave 201203290332-0-0 for framework 201203290332-0-0003 for 1 seconds
I0329 03:47:44.429867 10927 master.cpp:1184] Sending 1 offers to framework 201203290332-0-0002
I0329 03:47:44.431300 10927 master.cpp:679] Received reply for offer 201203290332-0-403
I0329 03:47:44.431399 10927 master.cpp:1403] Filtered slave 201203290332-0-0 for framework 201203290332-0-0002 for 1 seconds
I0329 03:47:45.431520 10927 master.cpp:1184] Sending 1 offers to framework 201203290332-0-0003
I0329 03:47:45.432929 10927 master.cpp:679] Received reply for offer 201203290332-0-404
I0329 03:47:45.433086 10927 master.cpp:1403] Filtered slave 201203290332-0-0 for framework 201203290332-0-0003 for 1 seconds
I0329 03:47:46.433097 10927 master.cpp:1184] Sending 1 offers to framework 201203290332-0-0002
I0329 03:47:46.434623 10927 master.cpp:679] Received reply for offer 201203290332-0-405
I0329 03:47:46.434777 10927 master.cpp:1403] Filtered slave 201203290332-0-0 for framework 201203290332-0-0002 for 1 seconds
I0329 03:47:47.434816 10927 master.cpp:1184] Sending 1 offers to framework 201203290332-0-0003
I0329 03:47:47.436416 10927 master.cpp:679] Received reply for offer 201203290332-0-406
I0329 03:47:47.436573 10927 master.cpp:1403] Filtered slave 201203290332-0-0 for framework 201203290332-0-0003 for 1 seconds
I0329 03:47:48.436616 10927 master.cpp:1184] Sending 1 offers to framework 201203290332-0-0002
I0329 03:47:48.438019 10927 master.cpp:679] Received reply for offer 201203290332-0-407
I0329 03:47:48.438174 10927 master.cpp:1403] Filtered slave 201203290332-0-0 for framework 201203290332-0-0002 for 1 seconds
I0329 03:47:49.438315 10927 master.cpp:1184] Sending 1 offers to framework 201203290332-0-0003
I0329 03:47:49.439828 10927 master.cpp:679] Received reply for offer 201203290332-0-408
I0329 03:47:49.439934 10927 master.cpp:1403] Filtered slave 201203290332-0-0 for framework 201203290332-0-0003 for 1 seconds
I0329 03:47:50.440078 10927 master.cpp:1184] Sending 1 offers to framework 201203290332-0-0002
I0329 03:47:50.441567 10927 master.cpp:679] Received reply for offer 201203290332-0-409
I0329 03:47:50.441755 10927 master.cpp:1403] Filtered slave 201203290332-0-0 for framework 201203290332-0-0002 for 1 seconds
I0329 03:47:51.441455 10927 master.cpp:1184] Sending 1 offers to framework 201203290332-0-0003
I0329 03:47:51.442947 10927 master.cpp:679] Received reply for offer 201203290332-0-410
I0329 03:47:51.443132 10927 master.cpp:1403] Filtered slave 201203290332-0-0 for framework 201203290332-0-0003 for 1 seconds
I0329 03:47:52.443161 10927 master.cpp:1184] Sending 1 offers to framework 201203290332-0-0002
I0329 03:47:52.444633 10927 master.cpp:679] Received reply for offer 201203290332-0-411
I0329 03:47:52.444784 10927 master.cpp:1403] Filtered slave 201203290332-0-0 for framework 201203290332-0-0002 for 1 seconds
I0329 03:47:53.444861 10927 master.cpp:1184] Sending 1 offers to framework 201203290332-0-0003
I0329 03:47:53.446320 10927 master.cpp:679] Received reply for offer 201203290332-0-412
I0329 03:47:53.446473 10927 master.cpp:1403] Filtered slave 201203290332-0-0 for framework 201203290332-0-0003 for 1 seconds
I0329 03:47:54.446152 10927 master.cpp:1184] Sending 1 offers to framework 201203290332-0-0002
I0329 03:47:54.447659 10927 master.cpp:679] Received reply for offer 201203290332-0-413
I0329 03:47:54.447758 10927 master.cpp:1403] Filtered slave 201203290332-0-0 for framework 201203290332-0-0002 for 1 seconds
I0329 03:47:55.447865 10927 master.cpp:1184] Sending 1 offers to framework 201203290332-0-0003
I0329 03:47:55.449342 10927 master.cpp:679] Received reply for offer 201203290332-0-414
I0329 03:47:55.449496 10927 master.cpp:1403] Filtered slave 201203290332-0-0 for framework 201203290332-0-0003 for 1 seconds
I0329 03:47:56.449548 10927 master.cpp:1184] Sending 1 offers to framework 201203290332-0-0002
I0329 03:47:56.451143 10927 master.cpp:679] Received reply for offer 201203290332-0-415
I0329 03:47:56.451297 10927 master.cpp:1403] Filtered slave 201203290332-0-0 for framework 201203290332-0-0002 for 1 seconds
I0329 03:47:57.450332 10927 master.cpp:1184] Sending 1 offers to framework 201203290332-0-0003
I0329 03:47:57.451895 10927 master.cpp:679] Received reply for offer 201203290332-0-416
I0329 03:47:57.452052 10927 master.cpp:1403] Filtered slave 201203290332-0-0 for framework 201203290332-0-0003 for 1 seconds
I0329 03:47:58.452152 10927 master.cpp:1184] Sending 1 offers to framework 201203290332-0-0002
I0329 03:47:58.453642 10927 master.cpp:679] Received reply for offer 201203290332-0-417
I0329 03:47:58.453796 10927 master.cpp:1403] Filtered slave 201203290332-0-0 for framework 201203290332-0-0002 for 1 seconds
I0329 03:47:59.453845 10927 master.cpp:1184] Sending 1 offers to framework 201203290332-0-0003
I0329 03:47:59.455543 10927 master.cpp:679] Received reply for offer 201203290332-0-418
I0329 03:47:59.455643 10927 master.cpp:1403] Filtered slave 201203290332-0-0 for framework 201203290332-0-0003 for 1 seconds
I0329 03:48:00.455704 10927 master.cpp:1184] Sending 1 offers to framework 201203290332-0-0002
I0329 03:48:00.457284 10927 master.cpp:679] Received reply for offer 201203290332-0-419
I0329 03:48:00.457437 10927 master.cpp:1403] Filtered slave 201203290332-0-0 for framework 201203290332-0-0002 for 1 seconds
I0329 03:48:01.457484 10927 master.cpp:1184] Sending 1 offers to framework 201203290332-0-0003
I0329 03:48:01.458958 10927 master.cpp:679] Received reply for offer 201203290332-0-420
I0329 03:48:01.459123 10927 master.cpp:1403] Filtered slave 201203290332-0-0 for framework 201203290332-0-0003 for 1 seconds
I0329 03:48:02.459178 10927 master.cpp:1184] Sending 1 offers to framework 201203290332-0-0002
I0329 03:48:02.460616 10927 master.cpp:679] Received reply for offer 201203290332-0-421
I0329 03:48:02.460769 10927 master.cpp:1403] Filtered slave 201203290332-0-0 for framework 201203290332-0-0002 for 1 seconds
I0329 03:48:03.460816 10927 master.cpp:1184] Sending 1 offers to framework 201203290332-0-0003
I0329 03:48:03.462309 10927 master.cpp:679] Received reply for offer 201203290332-0-422
I0329 03:48:03.462463 10927 master.cpp:1403] Filtered slave 201203290332-0-0 for framework 201203290332-0-0003 for 1 seconds
I0329 03:48:04.462512 10927 master.cpp:1184] Sending 1 offers to framework 201203290332-0-0002
I0329 03:48:04.463986 10927 master.cpp:679] Received reply for offer 201203290332-0-423
I0329 03:48:04.464086 10927 master.cpp:1403] Filtered slave 201203290332-0-0 for framework 201203290332-0-0002 for 1 seconds
I0329 03:48:05.464249 10927 master.cpp:1184] Sending 1 offers to framework 201203290332-0-0003
I0329 03:48:05.465896 10927 master.cpp:679] Received reply for offer 201203290332-0-424
I0329 03:48:05.466055 10927 master.cpp:1403] Filtered slave 201203290332-0-0 for framework 201203290332-0-0003 for 1 seconds
I0329 03:48:06.466032 10927 master.cpp:1184] Sending 1 offers to framework 201203290332-0-0002
I0329 03:48:06.467567 10927 master.cpp:679] Received reply for offer 201203290332-0-425
I0329 03:48:06.467727 10927 master.cpp:1403] Filtered slave 201203290332-0-0 for framework 201203290332-0-0002 for 1 seconds
I0329 03:48:07.467751 10927 master.cpp:1184] Sending 1 offers to framework 201203290332-0-0003
I0329 03:48:07.469215 10927 master.cpp:679] Received reply for offer 201203290332-0-426
I0329 03:48:07.469368 10927 master.cpp:1403] Filtered slave 201203290332-0-0 for framework 201203290332-0-0003 for 1 seconds
I0329 03:48:08.469470 10927 master.cpp:1184] Sending 1 offers to framework 201203290332-0-0002
I0329 03:48:08.470906 10927 master.cpp:679] Received reply for offer 201203290332-0-427
I0329 03:48:08.471057 10927 master.cpp:1403] Filtered slave 201203290332-0-0 for framework 201203290332-0-0002 for 1 seconds
I0329 03:48:09.470842 10927 master.cpp:1184] Sending 1 offers to framework 201203290332-0-0003
I0329 03:48:09.472304 10927 master.cpp:679] Received reply for offer 201203290332-0-428
I0329 03:48:09.472404 10927 master.cpp:1403] Filtered slave 201203290332-0-0 for framework 201203290332-0-0003 for 1 seconds
I0329 03:48:10.472483 10927 master.cpp:1184] Sending 1 offers to framework 201203290332-0-0002
I0329 03:48:10.473932 10927 master.cpp:679] Received reply for offer 201203290332-0-429
I0329 03:48:10.474115 10927 master.cpp:1403] Filtered slave 201203290332-0-0 for framework 201203290332-0-0002 for 1 seconds
I0329 03:48:11.474148 10927 master.cpp:1184] Sending 1 offers to framework 201203290332-0-0003
I0329 03:48:11.475702 10927 master.cpp:679] Received reply for offer 201203290332-0-430
I0329 03:48:11.475857 10927 master.cpp:1403] Filtered slave 201203290332-0-0 for framework 201203290332-0-0003 for 1 seconds
I0329 03:48:12.474879 10927 master.cpp:1184] Sending 1 offers to framework 201203290332-0-0002
I0329 03:48:12.476363 10927 master.cpp:679] Received reply for offer 201203290332-0-431
I0329 03:48:12.476516 10927 master.cpp:1403] Filtered slave 201203290332-0-0 for framework 201203290332-0-0002 for 1 seconds
I0329 03:48:13.476568 10927 master.cpp:1184] Sending 1 offers to framework 201203290332-0-0003
I0329 03:48:13.477998 10927 master.cpp:679] Received reply for offer 201203290332-0-432
I0329 03:48:13.478152 10927 master.cpp:1403] Filtered slave 201203290332-0-0 for framework 201203290332-0-0003 for 1 seconds
I0329 03:48:14.477502 10927 master.cpp:1184] Sending 1 offers to framework 201203290332-0-0002
I0329 03:48:14.478952 10927 master.cpp:679] Received reply for offer 201203290332-0-433
I0329 03:48:14.479048 10927 master.cpp:1403] Filtered slave 201203290332-0-0 for framework 201203290332-0-0002 for 1 seconds
I0329 03:48:15.479182 10927 master.cpp:1184] Sending 1 offers to framework 201203290332-0-0003
I0329 03:48:15.480654 10927 master.cpp:679] Received reply for offer 201203290332-0-434
I0329 03:48:15.480808 10927 master.cpp:1403] Filtered slave 201203290332-0-0 for framework 201203290332-0-0003 for 1 seconds
I0329 03:48:16.480850 10927 master.cpp:1184] Sending 1 offers to framework 201203290332-0-0002
I0329 03:48:16.482326 10927 master.cpp:679] Received reply for offer 201203290332-0-435
I0329 03:48:16.482476 10927 master.cpp:1403] Filtered slave 201203290332-0-0 for framework 201203290332-0-0002 for 1 seconds
I0329 03:48:17.482523 10927 master.cpp:1184] Sending 1 offers to framework 201203290332-0-0003
I0329 03:48:17.483973 10927 master.cpp:679] Received reply for offer 201203290332-0-436
I0329 03:48:17.484127 10927 master.cpp:1403] Filtered slave 201203290332-0-0 for framework 201203290332-0-0003 for 1 seconds
I0329 03:48:18.483319 10927 master.cpp:1184] Sending 1 offers to framework 201203290332-0-0002
I0329 03:48:18.484794 10927 master.cpp:679] Received reply for offer 201203290332-0-437
I0329 03:48:18.484946 10927 master.cpp:1403] Filtered slave 201203290332-0-0 for framework 201203290332-0-0002 for 1 seconds
I0329 03:48:19.484982 10927 master.cpp:1184] Sending 1 offers to framework 201203290332-0-0003
I0329 03:48:19.486354 10927 master.cpp:679] Received reply for offer 201203290332-0-438
I0329 03:48:19.486460 10927 master.cpp:1403] Filtered slave 201203290332-0-0 for framework 201203290332-0-0003 for 1 seconds
I0329 03:48:20.485669 10927 master.cpp:1184] Sending 1 offers to framework 201203290332-0-0002
I0329 03:48:20.487009 10927 master.cpp:679] Received reply for offer 201203290332-0-439
I0329 03:48:20.487227 10927 master.cpp:1403] Filtered slave 201203290332-0-0 for framework 201203290332-0-0002 for 1 seconds
I0329 03:48:21.487242 10927 master.cpp:1184] Sending 1 offers to framework 201203290332-0-0003
I0329 03:48:21.488610 10927 master.cpp:679] Received reply for offer 201203290332-0-440
I0329 03:48:21.488762 10927 master.cpp:1403] Filtered slave 201203290332-0-0 for framework 201203290332-0-0003 for 1 seconds
I0329 03:48:22.488750 10927 master.cpp:1184] Sending 1 offers to framework 201203290332-0-0002
I0329 03:48:22.490355 10927 master.cpp:679] Received reply for offer 201203290332-0-441
I0329 03:48:22.490510 10927 master.cpp:1403] Filtered slave 201203290332-0-0 for framework 201203290332-0-0002 for 1 seconds
I0329 03:48:23.490550 10927 master.cpp:1184] Sending 1 offers to framework 201203290332-0-0003
I0329 03:48:23.491966 10927 master.cpp:679] Received reply for offer 201203290332-0-442
I0329 03:48:23.492123 10927 master.cpp:1403] Filtered slave 201203290332-0-0 for framework 201203290332-0-0003 for 1 seconds
I0329 03:48:24.491760 10927 master.cpp:1184] Sending 1 offers to framework 201203290332-0-0002
I0329 03:48:24.493252 10927 master.cpp:679] Received reply for offer 201203290332-0-443
I0329 03:48:24.493350 10927 master.cpp:1403] Filtered slave 201203290332-0-0 for framework 201203290332-0-0002 for 1 seconds
I0329 03:48:25.493471 10927 master.cpp:1184] Sending 1 offers to framework 201203290332-0-0003
I0329 03:48:25.494843 10927 master.cpp:679] Received reply for offer 201203290332-0-444
I0329 03:48:25.495002 10927 master.cpp:1403] Filtered slave 201203290332-0-0 for framework 201203290332-0-0003 for 1 seconds
I0329 03:48:26.495020 10927 master.cpp:1184] Sending 1 offers to framework 201203290332-0-0002
I0329 03:48:26.496619 10927 master.cpp:679] Received reply for offer 201203290332-0-445
I0329 03:48:26.496773 10927 master.cpp:1403] Filtered slave 201203290332-0-0 for framework 201203290332-0-0002 for 1 seconds
I0329 03:48:27.495832 10927 master.cpp:1184] Sending 1 offers to framework 201203290332-0-0003
I0329 03:48:27.497499 10927 master.cpp:679] Received reply for offer 201203290332-0-446
I0329 03:48:27.497653 10927 master.cpp:1403] Filtered slave 201203290332-0-0 for framework 201203290332-0-0003 for 1 seconds
I0329 03:48:28.497700 10927 master.cpp:1184] Sending 1 offers to framework 201203290332-0-0002
I0329 03:48:28.499199 10927 master.cpp:679] Received reply for offer 201203290332-0-447
I0329 03:48:28.499356 10927 master.cpp:1403] Filtered slave 201203290332-0-0 for framework 201203290332-0-0002 for 1 seconds
I0329 03:48:29.499385 10927 master.cpp:1184] Sending 1 offers to framework 201203290332-0-0003
I0329 03:48:29.501036 10927 master.cpp:679] Received reply for offer 201203290332-0-448
I0329 03:48:29.501175 10927 master.cpp:1403] Filtered slave 201203290332-0-0 for framework 201203290332-0-0003 for 1 seconds
I0329 03:48:30.501262 10927 master.cpp:1184] Sending 1 offers to framework 201203290332-0-0002
I0329 03:48:30.502782 10927 master.cpp:679] Received reply for offer 201203290332-0-449
I0329 03:48:30.502939 10927 master.cpp:1403] Filtered slave 201203290332-0-0 for framework 201203290332-0-0002 for 1 seconds
I0329 03:48:31.502974 10927 master.cpp:1184] Sending 1 offers to framework 201203290332-0-0003
I0329 03:48:31.504587 10927 master.cpp:679] Received reply for offer 201203290332-0-450
I0329 03:48:31.504745 10927 master.cpp:1403] Filtered slave 201203290332-0-0 for framework 201203290332-0-0003 for 1 seconds
I0329 03:48:32.504791 10927 master.cpp:1184] Sending 1 offers to framework 201203290332-0-0002
I0329 03:48:32.506340 10927 master.cpp:679] Received reply for offer 201203290332-0-451
I0329 03:48:32.506495 10927 master.cpp:1403] Filtered slave 201203290332-0-0 for framework 201203290332-0-0002 for 1 seconds
I0329 03:48:33.506486 10927 master.cpp:1184] Sending 1 offers to framework 201203290332-0-0003
I0329 03:48:33.508056 10927 master.cpp:679] Received reply for offer 201203290332-0-452
I0329 03:48:33.508213 10927 master.cpp:1403] Filtered slave 201203290332-0-0 for framework 201203290332-0-0003 for 1 seconds
I0329 03:48:34.508280 10927 master.cpp:1184] Sending 1 offers to framework 201203290332-0-0002
I0329 03:48:34.510056 10927 master.cpp:679] Received reply for offer 201203290332-0-453
I0329 03:48:34.510155 10927 master.cpp:1403] Filtered slave 201203290332-0-0 for framework 201203290332-0-0002 for 1 seconds
I0329 03:48:35.510262 10927 master.cpp:1184] Sending 1 offers to framework 201203290332-0-0003
I0329 03:48:35.511793 10927 master.cpp:679] Received reply for offer 201203290332-0-454
I0329 03:48:35.511950 10927 master.cpp:1403] Filtered slave 201203290332-0-0 for framework 201203290332-0-0003 for 1 seconds
I0329 03:48:36.511984 10927 master.cpp:1184] Sending 1 offers to framework 201203290332-0-0002
I0329 03:48:36.513703 10927 master.cpp:679] Received reply for offer 201203290332-0-455
I0329 03:48:36.513860 10927 master.cpp:1403] Filtered slave 201203290332-0-0 for framework 201203290332-0-0002 for 1 seconds
I0329 03:48:37.513902 10927 master.cpp:1184] Sending 1 offers to framework 201203290332-0-0003
I0329 03:48:37.515486 10927 master.cpp:679] Received reply for offer 201203290332-0-456
I0329 03:48:37.515645 10927 master.cpp:1403] Filtered slave 201203290332-0-0 for framework 201203290332-0-0003 for 1 seconds
I0329 03:48:38.515703 10927 master.cpp:1184] Sending 1 offers to framework 201203290332-0-0002
I0329 03:48:38.517190 10927 master.cpp:679] Received reply for offer 201203290332-0-457
I0329 03:48:38.517345 10927 master.cpp:1403] Filtered slave 201203290332-0-0 for framework 201203290332-0-0002 for 1 seconds
I0329 03:48:39.517010 10927 master.cpp:1184] Sending 1 offers to framework 201203290332-0-0003
I0329 03:48:39.518792 10927 master.cpp:679] Received reply for offer 201203290332-0-458
I0329 03:48:39.518954 10927 master.cpp:1403] Filtered slave 201203290332-0-0 for framework 201203290332-0-0003 for 1 seconds
I0329 03:48:40.518988 10927 master.cpp:1184] Sending 1 offers to framework 201203290332-0-0002
I0329 03:48:40.520676 10927 master.cpp:679] Received reply for offer 201203290332-0-459
I0329 03:48:40.520830 10927 master.cpp:1403] Filtered slave 201203290332-0-0 for framework 201203290332-0-0002 for 1 seconds
I0329 03:48:41.520874 10927 master.cpp:1184] Sending 1 offers to framework 201203290332-0-0003
I0329 03:48:41.522359 10927 master.cpp:679] Received reply for offer 201203290332-0-460
I0329 03:48:41.522516 10927 master.cpp:1403] Filtered slave 201203290332-0-0 for framework 201203290332-0-0003 for 1 seconds
I0329 03:48:42.521560 10927 master.cpp:1184] Sending 1 offers to framework 201203290332-0-0002
I0329 03:48:42.523269 10927 master.cpp:679] Received reply for offer 201203290332-0-461
I0329 03:48:42.523426 10927 master.cpp:1403] Filtered slave 201203290332-0-0 for framework 201203290332-0-0002 for 1 seconds
I0329 03:48:43.523488 10927 master.cpp:1184] Sending 1 offers to framework 201203290332-0-0003
I0329 03:48:43.524941 10927 master.cpp:679] Received reply for offer 201203290332-0-462
I0329 03:48:43.525097 10927 master.cpp:1403] Filtered slave 201203290332-0-0 for framework 201203290332-0-0003 for 1 seconds
I0329 03:48:44.525163 10927 master.cpp:1184] Sending 1 offers to framework 201203290332-0-0002
I0329 03:48:44.526785 10927 master.cpp:679] Received reply for offer 201203290332-0-463
I0329 03:48:44.526917 10927 master.cpp:1403] Filtered slave 201203290332-0-0 for framework 201203290332-0-0002 for 1 seconds
I0329 03:48:45.526988 10927 master.cpp:1184] Sending 1 offers to framework 201203290332-0-0003
I0329 03:48:45.528750 10927 master.cpp:679] Received reply for offer 201203290332-0-464
I0329 03:48:45.528908 10927 master.cpp:1403] Filtered slave 201203290332-0-0 for framework 201203290332-0-0003 for 1 seconds
I0329 03:48:46.528944 10927 master.cpp:1184] Sending 1 offers to framework 201203290332-0-0002
I0329 03:48:46.530617 10927 master.cpp:679] Received reply for offer 201203290332-0-465
I0329 03:48:46.530772 10927 master.cpp:1403] Filtered slave 201203290332-0-0 for framework 201203290332-0-0002 for 1 seconds
I0329 03:48:47.530500 10927 master.cpp:1184] Sending 1 offers to framework 201203290332-0-0003
I0329 03:48:47.531980 10927 master.cpp:679] Received reply for offer 201203290332-0-466
I0329 03:48:47.532138 10927 master.cpp:1403] Filtered slave 201203290332-0-0 for framework 201203290332-0-0003 for 1 seconds
I0329 03:48:48.532183 10927 master.cpp:1184] Sending 1 offers to framework 201203290332-0-0002
I0329 03:48:48.533951 10927 master.cpp:679] Received reply for offer 201203290332-0-467
I0329 03:48:48.534106 10927 master.cpp:1403] Filtered slave 201203290332-0-0 for framework 201203290332-0-0002 for 1 seconds
I0329 03:48:49.534209 10927 master.cpp:1184] Sending 1 offers to framework 201203290332-0-0003
I0329 03:48:49.535730 10927 master.cpp:679] Received reply for offer 201203290332-0-468
I0329 03:48:49.535833 10927 master.cpp:1403] Filtered slave 201203290332-0-0 for framework 201203290332-0-0003 for 1 seconds
I0329 03:48:50.535366 10927 master.cpp:1184] Sending 1 offers to framework 201203290332-0-0002
I0329 03:48:50.536864 10927 master.cpp:679] Received reply for offer 201203290332-0-469
I0329 03:48:50.537050 10927 master.cpp:1403] Filtered slave 201203290332-0-0 for framework 201203290332-0-0002 for 1 seconds
I0329 03:48:51.537085 10927 master.cpp:1184] Sending 1 offers to framework 201203290332-0-0003
I0329 03:48:51.538790 10927 master.cpp:679] Received reply for offer 201203290332-0-470
I0329 03:48:51.538945 10927 master.cpp:1403] Filtered slave 201203290332-0-0 for framework 201203290332-0-0003 for 1 seconds
I0329 03:48:52.538962 10927 master.cpp:1184] Sending 1 offers to framework 201203290332-0-0002
I0329 03:48:52.540532 10927 master.cpp:679] Received reply for offer 201203290332-0-471
I0329 03:48:52.540689 10927 master.cpp:1403] Filtered slave 201203290332-0-0 for framework 201203290332-0-0002 for 1 seconds
I0329 03:48:53.540699 10927 master.cpp:1184] Sending 1 offers to framework 201203290332-0-0003
I0329 03:48:53.542207 10927 master.cpp:679] Received reply for offer 201203290332-0-472
I0329 03:48:53.542363 10927 master.cpp:1403] Filtered slave 201203290332-0-0 for framework 201203290332-0-0003 for 1 seconds
I0329 03:48:54.542053 10927 master.cpp:1184] Sending 1 offers to framework 201203290332-0-0002
I0329 03:48:54.543545 10927 master.cpp:679] Received reply for offer 201203290332-0-473
I0329 03:48:54.543642 10927 master.cpp:1403] Filtered slave 201203290332-0-0 for framework 201203290332-0-0002 for 1 seconds
I0329 03:48:55.543738 10927 master.cpp:1184] Sending 1 offers to framework 201203290332-0-0003
I0329 03:48:55.545269 10927 master.cpp:679] Received reply for offer 201203290332-0-474
I0329 03:48:55.545430 10927 master.cpp:1403] Filtered slave 201203290332-0-0 for framework 201203290332-0-0003 for 1 seconds
I0329 03:48:56.545475 10927 master.cpp:1184] Sending 1 offers to framework 201203290332-0-0002
I0329 03:48:56.547070 10927 master.cpp:679] Received reply for offer 201203290332-0-475
I0329 03:48:56.547317 10927 master.cpp:1403] Filtered slave 201203290332-0-0 for framework 201203290332-0-0002 for 1 seconds
I0329 03:48:57.546179 10927 master.cpp:1184] Sending 1 offers to framework 201203290332-0-0003
I0329 03:48:57.547811 10927 master.cpp:679] Received reply for offer 201203290332-0-476
I0329 03:48:57.547966 10927 master.cpp:1403] Filtered slave 201203290332-0-0 for framework 201203290332-0-0003 for 1 seconds
I0329 03:48:58.548022 10927 master.cpp:1184] Sending 1 offers to framework 201203290332-0-0002
I0329 03:48:58.549581 10927 master.cpp:679] Received reply for offer 201203290332-0-477
I0329 03:48:58.549775 10927 master.cpp:1403] Filtered slave 201203290332-0-0 for framework 201203290332-0-0002 for 1 seconds
I0329 03:48:59.549778 10927 master.cpp:1184] Sending 1 offers to framework 201203290332-0-0003
I0329 03:48:59.551369 10927 master.cpp:679] Received reply for offer 201203290332-0-478
I0329 03:48:59.551470 10927 master.cpp:1403] Filtered slave 201203290332-0-0 for framework 201203290332-0-0003 for 1 seconds
I0329 03:49:00.551563 10927 master.cpp:1184] Sending 1 offers to framework 201203290332-0-0002
I0329 03:49:00.553109 10927 master.cpp:679] Received reply for offer 201203290332-0-479
I0329 03:49:00.553304 10927 master.cpp:1403] Filtered slave 201203290332-0-0 for framework 201203290332-0-0002 for 1 seconds
I0329 03:49:01.553297 10927 master.cpp:1184] Sending 1 offers to framework 201203290332-0-0003
I0329 03:49:01.555138 10927 master.cpp:679] Received reply for offer 201203290332-0-480
I0329 03:49:01.555295 10927 master.cpp:1403] Filtered slave 201203290332-0-0 for framework 201203290332-0-0003 for 1 seconds
I0329 03:49:02.555341 10927 master.cpp:1184] Sending 1 offers to framework 201203290332-0-0002
I0329 03:49:02.557163 10927 master.cpp:679] Received reply for offer 201203290332-0-481
I0329 03:49:02.557322 10927 master.cpp:1403] Filtered slave 201203290332-0-0 for framework 201203290332-0-0002 for 1 seconds
I0329 03:49:03.557477 10927 master.cpp:1184] Sending 1 offers to framework 201203290332-0-0003
I0329 03:49:03.559054 10927 master.cpp:679] Received reply for offer 201203290332-0-482
I0329 03:49:03.559264 10927 master.cpp:1403] Filtered slave 201203290332-0-0 for framework 201203290332-0-0003 for 1 seconds
I0329 03:49:04.559336 10927 master.cpp:1184] Sending 1 offers to framework 201203290332-0-0002
I0329 03:49:04.560930 10927 master.cpp:679] Received reply for offer 201203290332-0-483
I0329 03:49:04.561028 10927 master.cpp:1403] Filtered slave 201203290332-0-0 for framework 201203290332-0-0002 for 1 seconds
I0329 03:49:05.561133 10927 master.cpp:1184] Sending 1 offers to framework 201203290332-0-0003
I0329 03:49:05.562656 10927 master.cpp:679] Received reply for offer 201203290332-0-484
I0329 03:49:05.562809 10927 master.cpp:1403] Filtered slave 201203290332-0-0 for framework 201203290332-0-0003 for 1 seconds
I0329 03:49:06.562872 10927 master.cpp:1184] Sending 1 offers to framework 201203290332-0-0002
I0329 03:49:06.564400 10927 master.cpp:679] Received reply for offer 201203290332-0-485
I0329 03:49:06.564553 10927 master.cpp:1403] Filtered slave 201203290332-0-0 for framework 201203290332-0-0002 for 1 seconds
I0329 03:49:07.564558 10927 master.cpp:1184] Sending 1 offers to framework 201203290332-0-0003
I0329 03:49:07.566104 10927 master.cpp:679] Received reply for offer 201203290332-0-486
I0329 03:49:07.566231 10927 master.cpp:1403] Filtered slave 201203290332-0-0 for framework 201203290332-0-0003 for 1 seconds
I0329 03:49:08.566310 10927 master.cpp:1184] Sending 1 offers to framework 201203290332-0-0002
I0329 03:49:08.567900 10927 master.cpp:679] Received reply for offer 201203290332-0-487
I0329 03:49:08.568027 10927 master.cpp:1403] Filtered slave 201203290332-0-0 for framework 201203290332-0-0002 for 1 seconds
I0329 03:49:09.567811 10927 master.cpp:1184] Sending 1 offers to framework 201203290332-0-0003
I0329 03:49:09.569516 10927 master.cpp:679] Received reply for offer 201203290332-0-488
I0329 03:49:09.569617 10927 master.cpp:1403] Filtered slave 201203290332-0-0 for framework 201203290332-0-0003 for 1 seconds
I0329 03:49:10.569752 10927 master.cpp:1184] Sending 1 offers to framework 201203290332-0-0002
I0329 03:49:10.571346 10927 master.cpp:679] Received reply for offer 201203290332-0-489
I0329 03:49:10.571540 10927 master.cpp:1403] Filtered slave 201203290332-0-0 for framework 201203290332-0-0002 for 1 seconds
I0329 03:49:11.571550 10927 master.cpp:1184] Sending 1 offers to framework 201203290332-0-0003
I0329 03:49:11.573297 10927 master.cpp:679] Received reply for offer 201203290332-0-490
I0329 03:49:11.573453 10927 master.cpp:1403] Filtered slave 201203290332-0-0 for framework 201203290332-0-0003 for 1 seconds
I0329 03:49:12.572489 10927 master.cpp:1184] Sending 1 offers to framework 201203290332-0-0002
I0329 03:49:12.574239 10927 master.cpp:679] Received reply for offer 201203290332-0-491
I0329 03:49:12.574462 10927 master.cpp:1403] Filtered slave 201203290332-0-0 for framework 201203290332-0-0002 for 1 seconds
I0329 03:49:13.574405 10927 master.cpp:1184] Sending 1 offers to framework 201203290332-0-0003
I0329 03:49:13.576321 10927 master.cpp:679] Received reply for offer 201203290332-0-492
I0329 03:49:13.576482 10927 master.cpp:1403] Filtered slave 201203290332-0-0 for framework 201203290332-0-0003 for 1 seconds
I0329 03:49:14.576536 10927 master.cpp:1184] Sending 1 offers to framework 201203290332-0-0002
I0329 03:49:14.578296 10927 master.cpp:679] Received reply for offer 201203290332-0-493
I0329 03:49:14.578397 10927 master.cpp:1403] Filtered slave 201203290332-0-0 for framework 201203290332-0-0002 for 1 seconds
I0329 03:49:15.578519 10927 master.cpp:1184] Sending 1 offers to framework 201203290332-0-0003
I0329 03:49:15.580073 10927 master.cpp:679] Received reply for offer 201203290332-0-494
I0329 03:49:15.580231 10927 master.cpp:1403] Filtered slave 201203290332-0-0 for framework 201203290332-0-0003 for 1 seconds
I0329 03:49:16.579334 10927 master.cpp:1184] Sending 1 offers to framework 201203290332-0-0002
I0329 03:49:16.580816 10927 master.cpp:679] Received reply for offer 201203290332-0-495
I0329 03:49:16.581011 10927 master.cpp:1403] Filtered slave 201203290332-0-0 for framework 201203290332-0-0002 for 1 seconds
I0329 03:49:17.581030 10927 master.cpp:1184] Sending 1 offers to framework 201203290332-0-0003
I0329 03:49:17.582701 10927 master.cpp:679] Received reply for offer 201203290332-0-496
I0329 03:49:17.582856 10927 master.cpp:1403] Filtered slave 201203290332-0-0 for framework 201203290332-0-0003 for 1 seconds
I0329 03:49:18.582959 10927 master.cpp:1184] Sending 1 offers to framework 201203290332-0-0002
I0329 03:49:18.584560 10927 master.cpp:679] Received reply for offer 201203290332-0-497
I0329 03:49:18.584714 10927 master.cpp:1403] Filtered slave 201203290332-0-0 for framework 201203290332-0-0002 for 1 seconds
I0329 03:49:19.584776 10927 master.cpp:1184] Sending 1 offers to framework 201203290332-0-0003
I0329 03:49:19.586421 10927 master.cpp:679] Received reply for offer 201203290332-0-498
I0329 03:49:19.586647 10927 master.cpp:1403] Filtered slave 201203290332-0-0 for framework 201203290332-0-0003 for 1 seconds
I0329 03:49:20.586619 10927 master.cpp:1184] Sending 1 offers to framework 201203290332-0-0002
I0329 03:49:20.588147 10927 master.cpp:679] Received reply for offer 201203290332-0-499
I0329 03:49:20.588340 10927 master.cpp:1403] Filtered slave 201203290332-0-0 for framework 201203290332-0-0002 for 1 seconds
I0329 03:49:21.588335 10927 master.cpp:1184] Sending 1 offers to framework 201203290332-0-0003
I0329 03:49:21.590003 10927 master.cpp:679] Received reply for offer 201203290332-0-500
I0329 03:49:21.590158 10927 master.cpp:1403] Filtered slave 201203290332-0-0 for framework 201203290332-0-0003 for 1 seconds
I0329 03:49:22.590222 10927 master.cpp:1184] Sending 1 offers to framework 201203290332-0-0002
I0329 03:49:22.591776 10927 master.cpp:679] Received reply for offer 201203290332-0-501
I0329 03:49:22.591970 10927 master.cpp:1403] Filtered slave 201203290332-0-0 for framework 201203290332-0-0002 for 1 seconds
I0329 03:49:23.591367 10927 master.cpp:1184] Sending 1 offers to framework 201203290332-0-0003
I0329 03:49:23.592890 10927 master.cpp:679] Received reply for offer 201203290332-0-502
I0329 03:49:23.593045 10927 master.cpp:1403] Filtered slave 201203290332-0-0 for framework 201203290332-0-0003 for 1 seconds
I0329 03:49:24.592777 10927 master.cpp:1184] Sending 1 offers to framework 201203290332-0-0002
I0329 03:49:24.594202 10927 master.cpp:679] Received reply for offer 201203290332-0-503
I0329 03:49:24.594300 10927 master.cpp:1403] Filtered slave 201203290332-0-0 for framework 201203290332-0-0002 for 1 seconds
I0329 03:49:25.593503 10927 master.cpp:1184] Sending 1 offers to framework 201203290332-0-0003
I0329 03:49:25.595331 10927 master.cpp:679] Received reply for offer 201203290332-0-504
I0329 03:49:25.595486 10927 master.cpp:1403] Filtered slave 201203290332-0-0 for framework 201203290332-0-0003 for 1 seconds
I0329 03:49:26.595371 10927 master.cpp:1184] Sending 1 offers to framework 201203290332-0-0002
I0329 03:49:26.596958 10927 master.cpp:679] Received reply for offer 201203290332-0-505
I0329 03:49:26.597115 10927 master.cpp:1403] Filtered slave 201203290332-0-0 for framework 201203290332-0-0002 for 1 seconds
I0329 03:49:27.596328 10927 master.cpp:1184] Sending 1 offers to framework 201203290332-0-0003
I0329 03:49:27.597913 10927 master.cpp:679] Received reply for offer 201203290332-0-506
I0329 03:49:27.598073 10927 master.cpp:1403] Filtered slave 201203290332-0-0 for framework 201203290332-0-0003 for 1 seconds
I0329 03:49:28.597658 10927 master.cpp:1184] Sending 1 offers to framework 201203290332-0-0002
I0329 03:49:28.599055 10927 master.cpp:679] Received reply for offer 201203290332-0-507
I0329 03:49:28.599267 10927 master.cpp:1403] Filtered slave 201203290332-0-0 for framework 201203290332-0-0002 for 1 seconds
I0329 03:49:29.599436 10927 master.cpp:1184] Sending 1 offers to framework 201203290332-0-0003
I0329 03:49:29.600957 10927 master.cpp:679] Received reply for offer 201203290332-0-508
I0329 03:49:29.601057 10927 master.cpp:1403] Filtered slave 201203290332-0-0 for framework 201203290332-0-0003 for 1 seconds
I0329 03:49:30.601177 10927 master.cpp:1184] Sending 1 offers to framework 201203290332-0-0002
I0329 03:49:30.602815 10927 master.cpp:679] Received reply for offer 201203290332-0-509
I0329 03:49:30.603034 10927 master.cpp:1403] Filtered slave 201203290332-0-0 for framework 201203290332-0-0002 for 1 seconds
I0329 03:49:31.603010 10927 master.cpp:1184] Sending 1 offers to framework 201203290332-0-0003
I0329 03:49:31.604588 10927 master.cpp:679] Received reply for offer 201203290332-0-510
I0329 03:49:31.604744 10927 master.cpp:1403] Filtered slave 201203290332-0-0 for framework 201203290332-0-0003 for 1 seconds
I0329 03:49:32.604786 10927 master.cpp:1184] Sending 1 offers to framework 201203290332-0-0002
I0329 03:49:32.606334 10927 master.cpp:679] Received reply for offer 201203290332-0-511
I0329 03:49:32.606488 10927 master.cpp:1403] Filtered slave 201203290332-0-0 for framework 201203290332-0-0002 for 1 seconds
I0329 03:49:33.606540 10927 master.cpp:1184] Sending 1 offers to framework 201203290332-0-0003
I0329 03:49:33.608126 10927 master.cpp:679] Received reply for offer 201203290332-0-512
I0329 03:49:33.608283 10927 master.cpp:1403] Filtered slave 201203290332-0-0 for framework 201203290332-0-0003 for 1 seconds
I0329 03:49:34.607811 10927 master.cpp:1184] Sending 1 offers to framework 201203290332-0-0002
I0329 03:49:34.609380 10927 master.cpp:679] Received reply for offer 201203290332-0-513
I0329 03:49:34.609477 10927 master.cpp:1403] Filtered slave 201203290332-0-0 for framework 201203290332-0-0002 for 1 seconds
I0329 03:49:35.609599 10927 master.cpp:1184] Sending 1 offers to framework 201203290332-0-0003
I0329 03:49:35.611174 10927 master.cpp:679] Received reply for offer 201203290332-0-514
I0329 03:49:35.611332 10927 master.cpp:1403] Filtered slave 201203290332-0-0 for framework 201203290332-0-0003 for 1 seconds
I0329 03:49:36.611379 10927 master.cpp:1184] Sending 1 offers to framework 201203290332-0-0002
I0329 03:49:36.612921 10927 master.cpp:679] Received reply for offer 201203290332-0-515
I0329 03:49:36.613075 10927 master.cpp:1403] Filtered slave 201203290332-0-0 for framework 201203290332-0-0002 for 1 seconds
I0329 03:49:37.613116 10927 master.cpp:1184] Sending 1 offers to framework 201203290332-0-0003
I0329 03:49:37.614591 10927 master.cpp:679] Received reply for offer 201203290332-0-516
I0329 03:49:37.614745 10927 master.cpp:1403] Filtered slave 201203290332-0-0 for framework 201203290332-0-0003 for 1 seconds
I0329 03:49:38.614791 10927 master.cpp:1184] Sending 1 offers to framework 201203290332-0-0002
I0329 03:49:38.616389 10927 master.cpp:679] Received reply for offer 201203290332-0-517
I0329 03:49:38.616543 10927 master.cpp:1403] Filtered slave 201203290332-0-0 for framework 201203290332-0-0002 for 1 seconds
I0329 03:49:39.616246 10927 master.cpp:1184] Sending 1 offers to framework 201203290332-0-0003
I0329 03:49:39.617794 10927 master.cpp:679] Received reply for offer 201203290332-0-518
I0329 03:49:39.617892 10927 master.cpp:1403] Filtered slave 201203290332-0-0 for framework 201203290332-0-0003 for 1 seconds
I0329 03:49:40.618013 10927 master.cpp:1184] Sending 1 offers to framework 201203290332-0-0002
I0329 03:49:40.619590 10927 master.cpp:679] Received reply for offer 201203290332-0-519
I0329 03:49:40.619745 10927 master.cpp:1403] Filtered slave 201203290332-0-0 for framework 201203290332-0-0002 for 1 seconds
I0329 03:49:41.619811 10927 master.cpp:1184] Sending 1 offers to framework 201203290332-0-0003
I0329 03:49:41.621423 10927 master.cpp:679] Received reply for offer 201203290332-0-520
I0329 03:49:41.621579 10927 master.cpp:1403] Filtered slave 201203290332-0-0 for framework 201203290332-0-0003 for 1 seconds
I0329 03:49:42.620882 10927 master.cpp:1184] Sending 1 offers to framework 201203290332-0-0002
I0329 03:49:42.622263 10927 master.cpp:679] Received reply for offer 201203290332-0-521
I0329 03:49:42.622423 10927 master.cpp:1403] Filtered slave 201203290332-0-0 for framework 201203290332-0-0002 for 1 seconds
I0329 03:49:43.622483 10927 master.cpp:1184] Sending 1 offers to framework 201203290332-0-0003
I0329 03:49:43.624058 10927 master.cpp:679] Received reply for offer 201203290332-0-522
I0329 03:49:43.624246 10927 master.cpp:1403] Filtered slave 201203290332-0-0 for framework 201203290332-0-0003 for 1 seconds
I0329 03:49:44.624279 10927 master.cpp:1184] Sending 1 offers to framework 201203290332-0-0002
I0329 03:49:44.625809 10927 master.cpp:679] Received reply for offer 201203290332-0-523
I0329 03:49:44.625910 10927 master.cpp:1403] Filtered slave 201203290332-0-0 for framework 201203290332-0-0002 for 1 seconds
I0329 03:49:45.626026 10927 master.cpp:1184] Sending 1 offers to framework 201203290332-0-0003
I0329 03:49:45.627630 10927 master.cpp:679] Received reply for offer 201203290332-0-524
I0329 03:49:45.627790 10927 master.cpp:1403] Filtered slave 201203290332-0-0 for framework 201203290332-0-0003 for 1 seconds
I0329 03:49:46.627924 10927 master.cpp:1184] Sending 1 offers to framework 201203290332-0-0002
I0329 03:49:46.629534 10927 master.cpp:679] Received reply for offer 201203290332-0-525
I0329 03:49:46.629688 10927 master.cpp:1403] Filtered slave 201203290332-0-0 for framework 201203290332-0-0002 for 1 seconds
I0329 03:49:47.629763 10927 master.cpp:1184] Sending 1 offers to framework 201203290332-0-0003
I0329 03:49:47.631319 10927 master.cpp:679] Received reply for offer 201203290332-0-526
I0329 03:49:47.631474 10927 master.cpp:1403] Filtered slave 201203290332-0-0 for framework 201203290332-0-0003 for 1 seconds
I0329 03:49:48.631408 10927 master.cpp:1184] Sending 1 offers to framework 201203290332-0-0002
I0329 03:49:48.632980 10927 master.cpp:679] Received reply for offer 201203290332-0-527
I0329 03:49:48.633136 10927 master.cpp:1403] Filtered slave 201203290332-0-0 for framework 201203290332-0-0002 for 1 seconds
I0329 03:49:49.633209 10927 master.cpp:1184] Sending 1 offers to framework 201203290332-0-0003
I0329 03:49:49.634938 10927 master.cpp:679] Received reply for offer 201203290332-0-528
I0329 03:49:49.635040 10927 master.cpp:1403] Filtered slave 201203290332-0-0 for framework 201203290332-0-0003 for 1 seconds
I0329 03:49:50.635225 10927 master.cpp:1184] Sending 1 offers to framework 201203290332-0-0002
I0329 03:49:50.636685 10927 master.cpp:679] Received reply for offer 201203290332-0-529
I0329 03:49:50.636838 10927 master.cpp:1403] Filtered slave 201203290332-0-0 for framework 201203290332-0-0002 for 1 seconds
I0329 03:49:51.636905 10927 master.cpp:1184] Sending 1 offers to framework 201203290332-0-0003
I0329 03:49:51.638417 10927 master.cpp:679] Received reply for offer 201203290332-0-530
I0329 03:49:51.638571 10927 master.cpp:1403] Filtered slave 201203290332-0-0 for framework 201203290332-0-0003 for 1 seconds
I0329 03:49:52.638641 10927 master.cpp:1184] Sending 1 offers to framework 201203290332-0-0002
I0329 03:49:52.640184 10927 master.cpp:679] Received reply for offer 201203290332-0-531
I0329 03:49:52.640336 10927 master.cpp:1403] Filtered slave 201203290332-0-0 for framework 201203290332-0-0002 for 1 seconds
I0329 03:49:53.640384 10927 master.cpp:1184] Sending 1 offers to framework 201203290332-0-0003
I0329 03:49:53.641984 10927 master.cpp:679] Received reply for offer 201203290332-0-532
I0329 03:49:53.642139 10927 master.cpp:1403] Filtered slave 201203290332-0-0 for framework 201203290332-0-0003 for 1 seconds
I0329 03:49:54.641870 10927 master.cpp:1184] Sending 1 offers to framework 201203290332-0-0002
I0329 03:49:54.643463 10927 master.cpp:679] Received reply for offer 201203290332-0-533
I0329 03:49:54.643584 10927 master.cpp:1403] Filtered slave 201203290332-0-0 for framework 201203290332-0-0002 for 1 seconds
I0329 03:49:55.643688 10927 master.cpp:1184] Sending 1 offers to framework 201203290332-0-0003
I0329 03:49:55.645190 10927 master.cpp:679] Received reply for offer 201203290332-0-534
I0329 03:49:55.645344 10927 master.cpp:1403] Filtered slave 201203290332-0-0 for framework 201203290332-0-0003 for 1 seconds
I0329 03:49:56.372386 10927 master.cpp:1118] Framework 201203290332-0-0003 disconnected
I0329 03:49:56.372580 10927 master.cpp:1118] Framework 201203290332-0-0002 disconnected
I0329 03:51:21.749970 10927 master.cpp:492] Registering framework 201203290332-0-0004 at 3@192.168.1.64:36024
I0329 03:51:21.750234 10927 simple_allocator.cpp:48] Added framework 201203290332-0-0004
I0329 03:51:21.750514 10927 master.cpp:1184] Sending 2 offers to framework 201203290332-0-0004
I0329 03:51:21.750661 10927 master.cpp:492] Registering framework 201203290332-0-0005 at 2@192.168.1.64:36024
I0329 03:51:21.750907 10927 simple_allocator.cpp:48] Added framework 201203290332-0-0005
I0329 03:51:21.774371 10927 master.cpp:679] Received reply for offer 201203290332-0-535
I0329 03:51:21.774538 10927 master.cpp:1403] Filtered slave 201203290332-0-0 for framework 201203290332-0-0004 for 1 seconds
I0329 03:51:21.774795 10927 master.cpp:679] Received reply for offer 201203290332-0-536
I0329 03:51:21.775266 10927 master.cpp:1184] Sending 1 offers to framework 201203290332-0-0005
I0329 03:51:21.775382 10927 master.cpp:1403] Filtered slave 201203290332-0-1 for framework 201203290332-0-0004 for 1 seconds
I0329 03:51:21.776645 10927 master.cpp:679] Received reply for offer 201203290332-0-537
I0329 03:51:21.776994 10927 master.cpp:1403] Filtered slave 201203290332-0-0 for framework 201203290332-0-0005 for 1 seconds
I0329 03:51:22.139804 10927 master.cpp:718] Reviving offers for framework 201203290332-0-0005
I0329 03:51:22.139950 10927 simple_allocator.cpp:145] Filters removed for framework 201203290332-0-0005
I0329 03:53:36.973211 10927 master.cpp:1118] Framework 201203290332-0-0005 disconnected
I0329 03:53:36.973474 10927 master.cpp:1118] Framework 201203290332-0-0004 disconnected
I0329 03:54:18.065423 10927 master.cpp:492] Registering framework 201203290332-0-0006 at 3@192.168.1.64:35514
I0329 03:54:18.065719 10927 simple_allocator.cpp:48] Added framework 201203290332-0-0006
I0329 03:54:18.065918 10927 master.cpp:1184] Sending 2 offers to framework 201203290332-0-0006
I0329 03:54:18.066143 10927 master.cpp:492] Registering framework 201203290332-0-0007 at 2@192.168.1.64:35514
I0329 03:54:18.066274 10927 simple_allocator.cpp:48] Added framework 201203290332-0-0007
I0329 03:54:18.088105 10927 master.cpp:679] Received reply for offer 201203290332-0-538
I0329 03:54:18.088321 10927 master.cpp:1403] Filtered slave 201203290332-0-0 for framework 201203290332-0-0006 for 1 seconds
I0329 03:54:18.088449 10927 master.cpp:679] Received reply for offer 201203290332-0-539
I0329 03:54:18.088690 10927 master.cpp:1184] Sending 1 offers to framework 201203290332-0-0007
I0329 03:54:18.088795 10927 master.cpp:1403] Filtered slave 201203290332-0-1 for framework 201203290332-0-0006 for 1 seconds
I0329 03:54:18.089687 10927 master.cpp:679] Received reply for offer 201203290332-0-540
I0329 03:54:18.089817 10927 master.cpp:1403] Filtered slave 201203290332-0-0 for framework 201203290332-0-0007 for 1 seconds
I0329 03:54:18.452678 10927 master.cpp:718] Reviving offers for framework 201203290332-0-0007
I0329 03:54:18.452852 10927 simple_allocator.cpp:145] Filters removed for framework 201203290332-0-0007
I0329 04:00:10.101106 10927 master.cpp:1118] Framework 201203290332-0-0007 disconnected
I0329 04:00:10.101310 10927 master.cpp:1118] Framework 201203290332-0-0006 disconnected
I0329 04:00:26.028095 10927 master.cpp:1143] Slave 201203290332-0-1 disconnected
I0329 04:00:26.028676 10927 simple_allocator.cpp:83] Removed slave 201203290332-0-1
