Log file created at: 2012/03/29 10:14:20
Running on machine: azad
Log line format: [IWEF]mmdd hh:mm:ss.uuuuuu threadid file:line] msg
I0329 10:14:20.739042  6087 logging.cpp:70] Logging to /mesos-distro/logdir
I0329 10:14:20.740042  6087 main.cpp:95] Build: 2012-03-28 23:30:52 by hduser
I0329 10:14:20.740147  6087 main.cpp:96] Starting Mesos master
I0329 10:14:20.741385  6088 master.cpp:264] Master started at mesos://master@192.168.1.64:5050
I0329 10:14:20.741406  6087 webui.cpp:81] Starting master web server on port 9836
I0329 10:14:20.741607  6088 master.cpp:279] Master ID: 201203291014-0
I0329 10:14:20.741716  6091 webui.cpp:47] Master web server thread started
I0329 10:14:20.741837  6088 master.cpp:462] Elected as master!
I0329 10:14:20.755157  6091 webui.cpp:59] Loading webui/master/webui.py
I0329 10:14:21.593579  6088 master.cpp:814] Attempting to register slave 201203291014-0-0 at slave@192.168.1.64:57346
I0329 10:14:21.593888  6088 master.cpp:1057] Master now considering a slave at azad.gateway.2wire.net:57346 as active
I0329 10:14:21.593935  6088 master.cpp:1588] Adding slave 201203291014-0-0 at azad.gateway.2wire.net with cpus=8; mem=16384
I0329 10:14:21.594194  6088 simple_allocator.cpp:71] Added slave 201203291014-0-0 with cpus=8; mem=16384
I0329 10:14:23.790720  6088 master.cpp:814] Attempting to register slave 201203291014-0-1 at slave@192.168.1.66:37117
I0329 10:14:23.791004  6088 master.cpp:1057] Master now considering a slave at ubuntu.gateway.2wire.net:37117 as active
I0329 10:14:23.791396  6088 master.cpp:1588] Adding slave 201203291014-0-1 at ubuntu.gateway.2wire.net with cpus=8; mem=8192
I0329 10:14:23.791538  6088 simple_allocator.cpp:71] Added slave 201203291014-0-1 with cpus=8; mem=8192
I0329 10:14:34.227798  6088 master.cpp:492] Registering framework 201203291014-0-0000 at 3@192.168.1.64:44036
I0329 10:14:34.227954  6088 simple_allocator.cpp:48] Added framework 201203291014-0-0000
I0329 10:14:34.228091  6088 master.cpp:1184] Sending 2 offers to framework 201203291014-0-0000
I0329 10:14:34.228368  6088 master.cpp:492] Registering framework 201203291014-0-0001 at 2@192.168.1.64:44036
I0329 10:14:34.228420  6088 simple_allocator.cpp:48] Added framework 201203291014-0-0001
I0329 10:14:34.245049  6088 master.cpp:679] Received reply for offer 201203291014-0-0
I0329 10:14:34.245128  6088 master.cpp:1403] Filtered slave 201203291014-0-1 for framework 201203291014-0-0000 for 1 seconds
I0329 10:14:34.245169  6088 master.cpp:679] Received reply for offer 201203291014-0-1
I0329 10:14:34.245225  6088 master.cpp:1184] Sending 1 offers to framework 201203291014-0-0001
I0329 10:14:34.245265  6088 master.cpp:1403] Filtered slave 201203291014-0-0 for framework 201203291014-0-0000 for 1 seconds
I0329 10:14:34.246080  6088 master.cpp:679] Received reply for offer 201203291014-0-2
I0329 10:14:34.246134  6088 master.cpp:1403] Filtered slave 201203291014-0-1 for framework 201203291014-0-0001 for 1 seconds
I0329 10:14:34.616921  6088 master.cpp:718] Reviving offers for framework 201203291014-0-0001
I0329 10:14:34.616961  6088 simple_allocator.cpp:145] Filters removed for framework 201203291014-0-0001
I0329 10:14:34.617041  6088 master.cpp:1184] Sending 2 offers to framework 201203291014-0-0001
I0329 10:14:34.698642  6088 master.cpp:679] Received reply for offer 201203291014-0-3
I0329 10:14:34.698724  6088 master.cpp:1403] Filtered slave 201203291014-0-1 for framework 201203291014-0-0001 for 1 seconds
I0329 10:14:34.700089  6088 master.cpp:679] Received reply for offer 201203291014-0-4
I0329 10:14:34.700170  6088 master.cpp:1453] Launching task 0 on slave 201203291014-0-0
I0329 10:14:34.700268  6088 master.cpp:1453] Launching task 1 on slave 201203291014-0-0
I0329 10:14:34.700356  6088 master.cpp:1453] Launching task 2 on slave 201203291014-0-0
I0329 10:14:34.700505  6088 master.cpp:1453] Launching task 3 on slave 201203291014-0-0
I0329 10:14:34.700588  6088 master.cpp:1453] Launching task 4 on slave 201203291014-0-0
I0329 10:14:34.700672  6088 master.cpp:1453] Launching task 5 on slave 201203291014-0-0
I0329 10:14:34.700754  6088 master.cpp:1453] Launching task 6 on slave 201203291014-0-0
I0329 10:14:34.700949  6088 master.cpp:1453] Launching task 7 on slave 201203291014-0-0
I0329 10:14:35.650943  6088 master.cpp:902] Status update from slave@192.168.1.64:57346: task 3 of framework 201203291014-0-0001 is now in state TASK_RUNNING
I0329 10:14:35.653293  6088 master.cpp:902] Status update from slave@192.168.1.64:57346: task 4 of framework 201203291014-0-0001 is now in state TASK_RUNNING
I0329 10:14:35.654840  6088 master.cpp:902] Status update from slave@192.168.1.64:57346: task 0 of framework 201203291014-0-0001 is now in state TASK_RUNNING
I0329 10:14:35.656980  6088 master.cpp:902] Status update from slave@192.168.1.64:57346: task 5 of framework 201203291014-0-0001 is now in state TASK_RUNNING
I0329 10:14:35.659735  6088 master.cpp:902] Status update from slave@192.168.1.64:57346: task 1 of framework 201203291014-0-0001 is now in state TASK_RUNNING
I0329 10:14:35.661967  6088 master.cpp:902] Status update from slave@192.168.1.64:57346: task 7 of framework 201203291014-0-0001 is now in state TASK_RUNNING
I0329 10:14:35.664392  6088 master.cpp:902] Status update from slave@192.168.1.64:57346: task 6 of framework 201203291014-0-0001 is now in state TASK_RUNNING
I0329 10:14:35.666692  6088 master.cpp:902] Status update from slave@192.168.1.64:57346: task 2 of framework 201203291014-0-0001 is now in state TASK_RUNNING
I0329 10:14:35.758154  6088 master.cpp:1184] Sending 1 offers to framework 201203291014-0-0000
I0329 10:14:35.759568  6088 master.cpp:679] Received reply for offer 201203291014-0-5
I0329 10:14:35.759716  6088 master.cpp:1403] Filtered slave 201203291014-0-1 for framework 201203291014-0-0000 for 1 seconds
I0329 10:14:36.759170  6088 master.cpp:1184] Sending 1 offers to framework 201203291014-0-0001
I0329 10:14:36.760473  6088 master.cpp:679] Received reply for offer 201203291014-0-6
I0329 10:14:36.760612  6088 master.cpp:1403] Filtered slave 201203291014-0-1 for framework 201203291014-0-0001 for 1 seconds
I0329 10:14:36.893637  6088 master.cpp:902] Status update from slave@192.168.1.64:57346: task 6 of framework 201203291014-0-0001 is now in state TASK_FINISHED
I0329 10:14:36.893918  6088 master.cpp:1184] Sending 1 offers to framework 201203291014-0-0000
I0329 10:14:36.896358  6088 master.cpp:902] Status update from slave@192.168.1.64:57346: task 0 of framework 201203291014-0-0001 is now in state TASK_FINISHED
I0329 10:14:36.899204  6088 master.cpp:902] Status update from slave@192.168.1.64:57346: task 4 of framework 201203291014-0-0001 is now in state TASK_FINISHED
I0329 10:14:36.902104  6088 master.cpp:902] Status update from slave@192.168.1.64:57346: task 2 of framework 201203291014-0-0001 is now in state TASK_FINISHED
I0329 10:14:36.904657  6088 master.cpp:902] Status update from slave@192.168.1.64:57346: task 7 of framework 201203291014-0-0001 is now in state TASK_FINISHED
I0329 10:14:36.907122  6088 master.cpp:902] Status update from slave@192.168.1.64:57346: task 5 of framework 201203291014-0-0001 is now in state TASK_FINISHED
I0329 10:14:36.908866  6088 master.cpp:902] Status update from slave@192.168.1.64:57346: task 1 of framework 201203291014-0-0001 is now in state TASK_FINISHED
I0329 10:14:36.909736  6088 master.cpp:679] Received reply for offer 201203291014-0-7
I0329 10:14:36.909878  6088 master.cpp:1403] Filtered slave 201203291014-0-0 for framework 201203291014-0-0000 for 1 seconds
I0329 10:14:36.910774  6088 master.cpp:902] Status update from slave@192.168.1.64:57346: task 3 of framework 201203291014-0-0001 is now in state TASK_FINISHED
I0329 10:14:36.910974  6088 master.cpp:1184] Sending 1 offers to framework 201203291014-0-0001
I0329 10:14:36.953320  6088 master.cpp:679] Received reply for offer 201203291014-0-8
I0329 10:14:36.953479  6088 master.cpp:1453] Launching task 8 on slave 201203291014-0-0
I0329 10:14:36.953752  6088 master.cpp:1453] Launching task 9 on slave 201203291014-0-0
I0329 10:14:36.954262  6088 master.cpp:1453] Launching task 10 on slave 201203291014-0-0
I0329 10:14:36.954552  6088 master.cpp:1453] Launching task 11 on slave 201203291014-0-0
I0329 10:14:36.955060  6088 master.cpp:1453] Launching task 12 on slave 201203291014-0-0
I0329 10:14:36.955698  6088 master.cpp:1453] Launching task 13 on slave 201203291014-0-0
I0329 10:14:36.956135  6088 master.cpp:1453] Launching task 14 on slave 201203291014-0-0
I0329 10:14:36.956603  6088 master.cpp:1453] Launching task 15 on slave 201203291014-0-0
I0329 10:14:36.957931  6088 master.cpp:902] Status update from slave@192.168.1.64:57346: task 8 of framework 201203291014-0-0001 is now in state TASK_RUNNING
I0329 10:14:36.960448  6088 master.cpp:902] Status update from slave@192.168.1.64:57346: task 9 of framework 201203291014-0-0001 is now in state TASK_RUNNING
I0329 10:14:36.963927  6088 master.cpp:902] Status update from slave@192.168.1.64:57346: task 10 of framework 201203291014-0-0001 is now in state TASK_RUNNING
I0329 10:14:36.966730  6088 master.cpp:902] Status update from slave@192.168.1.64:57346: task 11 of framework 201203291014-0-0001 is now in state TASK_RUNNING
I0329 10:14:36.973323  6088 master.cpp:902] Status update from slave@192.168.1.64:57346: task 12 of framework 201203291014-0-0001 is now in state TASK_RUNNING
I0329 10:14:36.973507  6088 master.cpp:902] Status update from slave@192.168.1.64:57346: task 13 of framework 201203291014-0-0001 is now in state TASK_RUNNING
I0329 10:14:36.976446  6088 master.cpp:902] Status update from slave@192.168.1.64:57346: task 14 of framework 201203291014-0-0001 is now in state TASK_RUNNING
I0329 10:14:36.982964  6088 master.cpp:902] Status update from slave@192.168.1.64:57346: task 15 of framework 201203291014-0-0001 is now in state TASK_RUNNING
I0329 10:14:37.085155  6088 master.cpp:902] Status update from slave@192.168.1.64:57346: task 9 of framework 201203291014-0-0001 is now in state TASK_FINISHED
I0329 10:14:37.085427  6088 master.cpp:1184] Sending 1 offers to framework 201203291014-0-0001
I0329 10:14:37.094279  6088 master.cpp:902] Status update from slave@192.168.1.64:57346: task 10 of framework 201203291014-0-0001 is now in state TASK_FINISHED
I0329 10:14:37.113544  6088 master.cpp:902] Status update from slave@192.168.1.64:57346: task 13 of framework 201203291014-0-0001 is now in state TASK_FINISHED
I0329 10:14:37.118630  6088 master.cpp:902] Status update from slave@192.168.1.64:57346: task 11 of framework 201203291014-0-0001 is now in state TASK_FINISHED
I0329 10:14:37.133765  6088 master.cpp:679] Received reply for offer 201203291014-0-9
I0329 10:14:37.133916  6088 master.cpp:1453] Launching task 16 on slave 201203291014-0-0
I0329 10:14:37.136405  6088 master.cpp:902] Status update from slave@192.168.1.64:57346: task 8 of framework 201203291014-0-0001 is now in state TASK_FINISHED
I0329 10:14:37.136662  6088 master.cpp:1184] Sending 1 offers to framework 201203291014-0-0001
I0329 10:14:37.137367  6088 master.cpp:902] Status update from slave@192.168.1.64:57346: task 12 of framework 201203291014-0-0001 is now in state TASK_FINISHED
I0329 10:14:37.141007  6088 master.cpp:902] Status update from slave@192.168.1.64:57346: task 16 of framework 201203291014-0-0001 is now in state TASK_RUNNING
I0329 10:14:37.145768  6088 master.cpp:902] Status update from slave@192.168.1.64:57346: task 14 of framework 201203291014-0-0001 is now in state TASK_FINISHED
I0329 10:14:37.148481  6088 master.cpp:902] Status update from slave@192.168.1.64:57346: task 15 of framework 201203291014-0-0001 is now in state TASK_FINISHED
I0329 10:14:37.185811  6088 master.cpp:679] Received reply for offer 201203291014-0-10
I0329 10:14:37.185971  6088 master.cpp:1453] Launching task 17 on slave 201203291014-0-0
I0329 10:14:37.186400  6088 master.cpp:1453] Launching task 18 on slave 201203291014-0-0
I0329 10:14:37.186596  6088 master.cpp:1453] Launching task 19 on slave 201203291014-0-0
I0329 10:14:37.186882  6088 master.cpp:1453] Launching task 20 on slave 201203291014-0-0
I0329 10:14:37.193442  6088 master.cpp:902] Status update from slave@192.168.1.64:57346: task 17 of framework 201203291014-0-0001 is now in state TASK_RUNNING
I0329 10:14:37.196040  6088 master.cpp:902] Status update from slave@192.168.1.64:57346: task 18 of framework 201203291014-0-0001 is now in state TASK_RUNNING
I0329 10:14:37.209251  6088 master.cpp:902] Status update from slave@192.168.1.64:57346: task 19 of framework 201203291014-0-0001 is now in state TASK_RUNNING
I0329 10:14:37.213541  6088 master.cpp:902] Status update from slave@192.168.1.64:57346: task 20 of framework 201203291014-0-0001 is now in state TASK_RUNNING
I0329 10:14:37.223551  6088 master.cpp:902] Status update from slave@192.168.1.64:57346: task 16 of framework 201203291014-0-0001 is now in state TASK_FINISHED
I0329 10:14:37.223806  6088 master.cpp:1184] Sending 1 offers to framework 201203291014-0-0001
I0329 10:14:37.241739  6088 master.cpp:679] Received reply for offer 201203291014-0-11
I0329 10:14:37.241915  6088 master.cpp:1453] Launching task 21 on slave 201203291014-0-0
I0329 10:14:37.242195  6088 master.cpp:1453] Launching task 22 on slave 201203291014-0-0
I0329 10:14:37.242434  6088 master.cpp:1453] Launching task 23 on slave 201203291014-0-0
I0329 10:14:37.242590  6088 master.cpp:1453] Launching task 24 on slave 201203291014-0-0
I0329 10:14:37.248603  6088 master.cpp:902] Status update from slave@192.168.1.64:57346: task 21 of framework 201203291014-0-0001 is now in state TASK_RUNNING
I0329 10:14:37.252035  6088 master.cpp:902] Status update from slave@192.168.1.64:57346: task 22 of framework 201203291014-0-0001 is now in state TASK_RUNNING
I0329 10:14:37.255530  6088 master.cpp:902] Status update from slave@192.168.1.64:57346: task 23 of framework 201203291014-0-0001 is now in state TASK_RUNNING
I0329 10:14:37.278621  6088 master.cpp:902] Status update from slave@192.168.1.64:57346: task 24 of framework 201203291014-0-0001 is now in state TASK_RUNNING
I0329 10:14:37.294631  6088 master.cpp:902] Status update from slave@192.168.1.64:57346: task 18 of framework 201203291014-0-0001 is now in state TASK_FINISHED
I0329 10:14:37.294886  6088 master.cpp:1184] Sending 1 offers to framework 201203291014-0-0001
I0329 10:14:37.304522  6088 master.cpp:679] Received reply for offer 201203291014-0-12
I0329 10:14:37.304702  6088 master.cpp:1453] Launching task 25 on slave 201203291014-0-0
I0329 10:14:37.311749  6088 master.cpp:902] Status update from slave@192.168.1.64:57346: task 25 of framework 201203291014-0-0001 is now in state TASK_RUNNING
I0329 10:14:37.327682  6088 master.cpp:902] Status update from slave@192.168.1.64:57346: task 19 of framework 201203291014-0-0001 is now in state TASK_FINISHED
I0329 10:14:37.327956  6088 master.cpp:1184] Sending 1 offers to framework 201203291014-0-0001
I0329 10:14:37.334091  6088 master.cpp:679] Received reply for offer 201203291014-0-13
I0329 10:14:37.334277  6088 master.cpp:1453] Launching task 26 on slave 201203291014-0-0
I0329 10:14:37.348235  6088 master.cpp:902] Status update from slave@192.168.1.64:57346: task 26 of framework 201203291014-0-0001 is now in state TASK_RUNNING
I0329 10:14:37.356406  6088 master.cpp:902] Status update from slave@192.168.1.64:57346: task 20 of framework 201203291014-0-0001 is now in state TASK_FINISHED
I0329 10:14:37.356678  6088 master.cpp:1184] Sending 1 offers to framework 201203291014-0-0001
I0329 10:14:37.360988  6088 master.cpp:902] Status update from slave@192.168.1.64:57346: task 17 of framework 201203291014-0-0001 is now in state TASK_FINISHED
I0329 10:14:37.369983  6088 master.cpp:902] Status update from slave@192.168.1.64:57346: task 23 of framework 201203291014-0-0001 is now in state TASK_FINISHED
I0329 10:14:37.371238  6088 master.cpp:679] Received reply for offer 201203291014-0-14
I0329 10:14:37.371404  6088 master.cpp:1453] Launching task 27 on slave 201203291014-0-0
I0329 10:14:37.378700  6088 master.cpp:902] Status update from slave@192.168.1.64:57346: task 21 of framework 201203291014-0-0001 is now in state TASK_FINISHED
I0329 10:14:37.378962  6088 master.cpp:1184] Sending 1 offers to framework 201203291014-0-0001
I0329 10:14:37.389694  6088 master.cpp:902] Status update from slave@192.168.1.64:57346: task 27 of framework 201203291014-0-0001 is now in state TASK_RUNNING
I0329 10:14:37.403379  6088 master.cpp:902] Status update from slave@192.168.1.64:57346: task 22 of framework 201203291014-0-0001 is now in state TASK_FINISHED
I0329 10:14:37.406970  6088 master.cpp:902] Status update from slave@192.168.1.64:57346: task 24 of framework 201203291014-0-0001 is now in state TASK_FINISHED
I0329 10:14:37.418470  6088 master.cpp:679] Received reply for offer 201203291014-0-15
I0329 10:14:37.418632  6088 master.cpp:1453] Launching task 28 on slave 201203291014-0-0
I0329 10:14:37.418956  6088 master.cpp:1453] Launching task 29 on slave 201203291014-0-0
I0329 10:14:37.419137  6088 master.cpp:1453] Launching task 30 on slave 201203291014-0-0
I0329 10:14:37.423924  6088 master.cpp:902] Status update from slave@192.168.1.64:57346: task 28 of framework 201203291014-0-0001 is now in state TASK_RUNNING
I0329 10:14:37.426574  6088 master.cpp:902] Status update from slave@192.168.1.64:57346: task 29 of framework 201203291014-0-0001 is now in state TASK_RUNNING
I0329 10:14:37.429149  6088 master.cpp:902] Status update from slave@192.168.1.64:57346: task 30 of framework 201203291014-0-0001 is now in state TASK_RUNNING
I0329 10:14:37.443987  6088 master.cpp:902] Status update from slave@192.168.1.64:57346: task 26 of framework 201203291014-0-0001 is now in state TASK_FINISHED
I0329 10:14:37.444249  6088 master.cpp:1184] Sending 1 offers to framework 201203291014-0-0001
I0329 10:14:37.446575  6088 master.cpp:902] Status update from slave@192.168.1.64:57346: task 25 of framework 201203291014-0-0001 is now in state TASK_FINISHED
I0329 10:14:37.455054  6088 master.cpp:679] Received reply for offer 201203291014-0-16
I0329 10:14:37.455243  6088 master.cpp:1453] Launching task 31 on slave 201203291014-0-0
I0329 10:14:37.455518  6088 master.cpp:1453] Launching task 32 on slave 201203291014-0-0
I0329 10:14:37.455766  6088 master.cpp:1453] Launching task 33 on slave 201203291014-0-0
I0329 10:14:37.460839  6088 master.cpp:902] Status update from slave@192.168.1.64:57346: task 31 of framework 201203291014-0-0001 is now in state TASK_RUNNING
I0329 10:14:37.464040  6088 master.cpp:902] Status update from slave@192.168.1.64:57346: task 32 of framework 201203291014-0-0001 is now in state TASK_RUNNING
I0329 10:14:37.467161  6088 master.cpp:902] Status update from slave@192.168.1.64:57346: task 33 of framework 201203291014-0-0001 is now in state TASK_RUNNING
I0329 10:14:37.487725  6088 master.cpp:902] Status update from slave@192.168.1.64:57346: task 27 of framework 201203291014-0-0001 is now in state TASK_FINISHED
I0329 10:14:37.487982  6088 master.cpp:1184] Sending 1 offers to framework 201203291014-0-0001
I0329 10:14:37.497514  6088 master.cpp:679] Received reply for offer 201203291014-0-17
I0329 10:14:37.497697  6088 master.cpp:1453] Launching task 34 on slave 201203291014-0-0
I0329 10:14:37.497971  6088 master.cpp:1453] Launching task 35 on slave 201203291014-0-0
I0329 10:14:37.515655  6088 master.cpp:902] Status update from slave@192.168.1.64:57346: task 34 of framework 201203291014-0-0001 is now in state TASK_RUNNING
I0329 10:14:37.524410  6088 master.cpp:902] Status update from slave@192.168.1.64:57346: task 35 of framework 201203291014-0-0001 is now in state TASK_RUNNING
I0329 10:14:37.535119  6088 master.cpp:902] Status update from slave@192.168.1.64:57346: task 30 of framework 201203291014-0-0001 is now in state TASK_FINISHED
I0329 10:14:37.535351  6088 master.cpp:1184] Sending 1 offers to framework 201203291014-0-0001
I0329 10:14:37.540312  6088 master.cpp:679] Received reply for offer 201203291014-0-18
I0329 10:14:37.540488  6088 master.cpp:1453] Launching task 36 on slave 201203291014-0-0
I0329 10:14:37.541260  6088 master.cpp:902] Status update from slave@192.168.1.64:57346: task 28 of framework 201203291014-0-0001 is now in state TASK_FINISHED
I0329 10:14:37.541440  6088 master.cpp:1184] Sending 1 offers to framework 201203291014-0-0001
I0329 10:14:37.547770  6088 master.cpp:679] Received reply for offer 201203291014-0-19
I0329 10:14:37.548099  6088 master.cpp:1453] Launching task 37 on slave 201203291014-0-0
I0329 10:14:37.554522  6088 master.cpp:902] Status update from slave@192.168.1.64:57346: task 29 of framework 201203291014-0-0001 is now in state TASK_FINISHED
I0329 10:14:37.554756  6088 master.cpp:1184] Sending 1 offers to framework 201203291014-0-0001
I0329 10:14:37.562988  6088 master.cpp:902] Status update from slave@192.168.1.64:57346: task 33 of framework 201203291014-0-0001 is now in state TASK_FINISHED
I0329 10:14:37.568126  6088 master.cpp:902] Status update from slave@192.168.1.64:57346: task 36 of framework 201203291014-0-0001 is now in state TASK_RUNNING
I0329 10:14:37.577651  6088 master.cpp:902] Status update from slave@192.168.1.64:57346: task 32 of framework 201203291014-0-0001 is now in state TASK_FINISHED
I0329 10:14:37.583752  6088 master.cpp:902] Status update from slave@192.168.1.64:57346: task 37 of framework 201203291014-0-0001 is now in state TASK_RUNNING
I0329 10:14:37.587280  6088 master.cpp:679] Received reply for offer 201203291014-0-20
I0329 10:14:37.587471  6088 master.cpp:1453] Launching task 38 on slave 201203291014-0-0
I0329 10:14:37.604038  6088 master.cpp:902] Status update from slave@192.168.1.64:57346: task 31 of framework 201203291014-0-0001 is now in state TASK_FINISHED
I0329 10:14:37.604307  6088 master.cpp:1184] Sending 1 offers to framework 201203291014-0-0001
I0329 10:14:37.609662  6088 master.cpp:902] Status update from slave@192.168.1.64:57346: task 34 of framework 201203291014-0-0001 is now in state TASK_FINISHED
I0329 10:14:37.624119  6088 master.cpp:902] Status update from slave@192.168.1.64:57346: task 38 of framework 201203291014-0-0001 is now in state TASK_RUNNING
I0329 10:14:37.627250  6088 master.cpp:679] Received reply for offer 201203291014-0-21
I0329 10:14:37.627398  6088 master.cpp:1453] Launching task 39 on slave 201203291014-0-0
I0329 10:14:37.627749  6088 master.cpp:902] Status update from slave@192.168.1.64:57346: task 35 of framework 201203291014-0-0001 is now in state TASK_FINISHED
I0329 10:14:37.627919  6088 master.cpp:1184] Sending 1 offers to framework 201203291014-0-0001
I0329 10:14:37.642102  6088 master.cpp:902] Status update from slave@192.168.1.64:57346: task 36 of framework 201203291014-0-0001 is now in state TASK_FINISHED
I0329 10:14:37.657960  6088 master.cpp:902] Status update from slave@192.168.1.64:57346: task 37 of framework 201203291014-0-0001 is now in state TASK_FINISHED
I0329 10:14:37.667322  6088 master.cpp:679] Received reply for offer 201203291014-0-22
I0329 10:14:37.667527  6088 master.cpp:1403] Filtered slave 201203291014-0-0 for framework 201203291014-0-0001 for 1 seconds
I0329 10:14:37.668692  6088 master.cpp:902] Status update from slave@192.168.1.64:57346: task 39 of framework 201203291014-0-0001 is now in state TASK_RUNNING
I0329 10:14:37.695756  6088 master.cpp:902] Status update from slave@192.168.1.64:57346: task 38 of framework 201203291014-0-0001 is now in state TASK_FINISHED
I0329 10:14:37.760212  6088 master.cpp:1184] Sending 1 offers to framework 201203291014-0-0000
I0329 10:14:37.761457  6088 master.cpp:679] Received reply for offer 201203291014-0-23
I0329 10:14:37.761597  6088 master.cpp:1403] Filtered slave 201203291014-0-1 for framework 201203291014-0-0000 for 1 seconds
I0329 10:14:37.780933  6088 master.cpp:902] Status update from slave@192.168.1.64:57346: task 39 of framework 201203291014-0-0001 is now in state TASK_FINISHED
I0329 10:14:37.803894  6088 master.cpp:718] Reviving offers for framework 201203291014-0-0001
I0329 10:14:37.804030  6088 simple_allocator.cpp:145] Filters removed for framework 201203291014-0-0001
I0329 10:14:37.804402  6088 master.cpp:1184] Sending 2 offers to framework 201203291014-0-0001
I0329 10:14:37.842453  6088 master.cpp:679] Received reply for offer 201203291014-0-24
I0329 10:14:37.842628  6088 master.cpp:1403] Filtered slave 201203291014-0-1 for framework 201203291014-0-0001 for 1 seconds
I0329 10:14:37.844033  6088 master.cpp:679] Received reply for offer 201203291014-0-25
I0329 10:14:37.844169  6088 master.cpp:1453] Launching task 40 on slave 201203291014-0-0
I0329 10:14:37.844353  6088 master.cpp:1453] Launching task 41 on slave 201203291014-0-0
I0329 10:14:37.844775  6088 master.cpp:1453] Launching task 42 on slave 201203291014-0-0
I0329 10:14:37.845191  6088 master.cpp:1453] Launching task 43 on slave 201203291014-0-0
I0329 10:14:37.845437  6088 master.cpp:1453] Launching task 44 on slave 201203291014-0-0
I0329 10:14:37.845612  6088 master.cpp:1453] Launching task 45 on slave 201203291014-0-0
I0329 10:14:37.846088  6088 master.cpp:1453] Launching task 46 on slave 201203291014-0-0
I0329 10:14:37.846580  6088 master.cpp:1453] Launching task 47 on slave 201203291014-0-0
I0329 10:14:37.848877  6088 master.cpp:902] Status update from slave@192.168.1.64:57346: task 40 of framework 201203291014-0-0001 is now in state TASK_RUNNING
I0329 10:14:37.852290  6088 master.cpp:902] Status update from slave@192.168.1.64:57346: task 41 of framework 201203291014-0-0001 is now in state TASK_RUNNING
I0329 10:14:37.854966  6088 master.cpp:902] Status update from slave@192.168.1.64:57346: task 42 of framework 201203291014-0-0001 is now in state TASK_RUNNING
I0329 10:14:37.861001  6088 master.cpp:902] Status update from slave@192.168.1.64:57346: task 43 of framework 201203291014-0-0001 is now in state TASK_RUNNING
I0329 10:14:37.863729  6088 master.cpp:902] Status update from slave@192.168.1.64:57346: task 44 of framework 201203291014-0-0001 is now in state TASK_RUNNING
I0329 10:14:37.867123  6088 master.cpp:902] Status update from slave@192.168.1.64:57346: task 45 of framework 201203291014-0-0001 is now in state TASK_RUNNING
I0329 10:14:37.869889  6088 master.cpp:902] Status update from slave@192.168.1.64:57346: task 46 of framework 201203291014-0-0001 is now in state TASK_RUNNING
I0329 10:14:37.877459  6088 master.cpp:902] Status update from slave@192.168.1.64:57346: task 47 of framework 201203291014-0-0001 is now in state TASK_RUNNING
I0329 10:14:38.019708  6088 master.cpp:902] Status update from slave@192.168.1.64:57346: task 46 of framework 201203291014-0-0001 is now in state TASK_FAILED
I0329 10:14:38.019965  6088 master.cpp:1184] Sending 1 offers to framework 201203291014-0-0001
I0329 10:14:38.059968  6088 master.cpp:902] Status update from slave@192.168.1.64:57346: task 41 of framework 201203291014-0-0001 is now in state TASK_FAILED
I0329 10:14:38.060333  6088 master.cpp:902] Status update from slave@192.168.1.64:57346: task 47 of framework 201203291014-0-0001 is now in state TASK_FAILED
I0329 10:14:38.060720  6088 master.cpp:902] Status update from slave@192.168.1.64:57346: task 44 of framework 201203291014-0-0001 is now in state TASK_FAILED
I0329 10:14:38.061056  6088 master.cpp:902] Status update from slave@192.168.1.64:57346: task 40 of framework 201203291014-0-0001 is now in state TASK_FAILED
I0329 10:14:38.061498  6088 master.cpp:902] Status update from slave@192.168.1.64:57346: task 42 of framework 201203291014-0-0001 is now in state TASK_FAILED
I0329 10:14:38.061960  6088 master.cpp:902] Status update from slave@192.168.1.64:57346: task 43 of framework 201203291014-0-0001 is now in state TASK_FAILED
I0329 10:14:38.062404  6088 master.cpp:902] Status update from slave@192.168.1.64:57346: task 45 of framework 201203291014-0-0001 is now in state TASK_FAILED
I0329 10:14:38.063014  6088 master.cpp:679] Received reply for offer 201203291014-0-26
I0329 10:14:38.063267  6088 master.cpp:1453] Launching task 48 on slave 201203291014-0-0
I0329 10:14:38.099848  6088 master.cpp:902] Status update from slave@192.168.1.64:57346: task 48 of framework 201203291014-0-0001 is now in state TASK_RUNNING
I0329 10:14:38.104136  6088 master.cpp:902] Status update from slave@192.168.1.64:57346: task 48 of framework 201203291014-0-0001 is now in state TASK_FAILED
I0329 10:14:38.104387  6088 master.cpp:1184] Sending 1 offers to framework 201203291014-0-0001
I0329 10:14:38.159982  6088 master.cpp:679] Received reply for offer 201203291014-0-27
I0329 10:14:38.160152  6088 master.cpp:1453] Launching task 49 on slave 201203291014-0-0
I0329 10:14:38.160604  6088 master.cpp:1453] Launching task 50 on slave 201203291014-0-0
I0329 10:14:38.160907  6088 master.cpp:1453] Launching task 51 on slave 201203291014-0-0
I0329 10:14:38.161491  6088 master.cpp:1453] Launching task 52 on slave 201203291014-0-0
I0329 10:14:38.162009  6088 master.cpp:1453] Launching task 53 on slave 201203291014-0-0
I0329 10:14:38.162919  6088 master.cpp:1453] Launching task 54 on slave 201203291014-0-0
I0329 10:14:38.163187  6088 master.cpp:1453] Launching task 55 on slave 201203291014-0-0
I0329 10:14:38.163393  6088 master.cpp:1453] Launching task 56 on slave 201203291014-0-0
I0329 10:14:38.614316  6088 master.cpp:1001] Executor default of framework 201203291014-0-0001 on slave 201203291014-0-0 (azad.gateway.2wire.net) exited with status 256
I0329 10:14:38.615926  6088 master.cpp:1033] Removing task 56 of framework 201203291014-0-0001 because of lost executor
I0329 10:14:38.616220  6088 master.cpp:1184] Sending 1 offers to framework 201203291014-0-0001
I0329 10:14:38.617853  6088 master.cpp:1033] Removing task 54 of framework 201203291014-0-0001 because of lost executor
I0329 10:14:38.619488  6088 master.cpp:1033] Removing task 55 of framework 201203291014-0-0001 because of lost executor
I0329 10:14:38.620967  6088 master.cpp:1033] Removing task 52 of framework 201203291014-0-0001 because of lost executor
I0329 10:14:38.622442  6088 master.cpp:1033] Removing task 53 of framework 201203291014-0-0001 because of lost executor
I0329 10:14:38.624078  6088 master.cpp:1033] Removing task 50 of framework 201203291014-0-0001 because of lost executor
I0329 10:14:38.625709  6088 master.cpp:1033] Removing task 51 of framework 201203291014-0-0001 because of lost executor
I0329 10:14:38.627341  6088 master.cpp:1033] Removing task 49 of framework 201203291014-0-0001 because of lost executor
I0329 10:14:38.627560  6088 master.cpp:679] Received reply for offer 201203291014-0-28
I0329 10:14:38.627815  6088 master.cpp:1453] Launching task 57 on slave 201203291014-0-0
I0329 10:14:38.760783  6088 master.cpp:1184] Sending 1 offers to framework 201203291014-0-0000
I0329 10:14:38.762209  6088 master.cpp:679] Received reply for offer 201203291014-0-29
I0329 10:14:38.762337  6088 master.cpp:1403] Filtered slave 201203291014-0-0 for framework 201203291014-0-0000 for 1 seconds
I0329 10:14:39.561393  6088 master.cpp:902] Status update from slave@192.168.1.64:57346: task 57 of framework 201203291014-0-0001 is now in state TASK_RUNNING
I0329 10:14:39.762090  6088 master.cpp:1184] Sending 1 offers to framework 201203291014-0-0000
I0329 10:14:39.762269  6088 master.cpp:1184] Sending 1 offers to framework 201203291014-0-0001
I0329 10:14:39.763708  6088 master.cpp:679] Received reply for offer 201203291014-0-30
I0329 10:14:39.763831  6088 master.cpp:1403] Filtered slave 201203291014-0-1 for framework 201203291014-0-0000 for 1 seconds
I0329 10:14:39.774824  6088 master.cpp:679] Received reply for offer 201203291014-0-31
I0329 10:14:39.774977  6088 master.cpp:1453] Launching task 58 on slave 201203291014-0-0
I0329 10:14:39.775254  6088 master.cpp:1453] Launching task 59 on slave 201203291014-0-0
I0329 10:14:39.775470  6088 master.cpp:1453] Launching task 60 on slave 201203291014-0-0
I0329 10:14:39.775630  6088 master.cpp:1453] Launching task 61 on slave 201203291014-0-0
I0329 10:14:39.775727  6088 master.cpp:1453] Launching task 62 on slave 201203291014-0-0
I0329 10:14:39.776366  6088 master.cpp:1453] Launching task 63 on slave 201203291014-0-0
I0329 10:14:39.777075  6088 master.cpp:1453] Launching task 64 on slave 201203291014-0-0
I0329 10:14:39.777672  6088 master.cpp:1184] Sending 1 offers to framework 201203291014-0-0001
I0329 10:14:39.778795  6088 master.cpp:679] Received reply for offer 201203291014-0-32
I0329 10:14:39.778928  6088 master.cpp:1403] Filtered slave 201203291014-0-1 for framework 201203291014-0-0001 for 1 seconds
I0329 10:14:39.782101  6088 master.cpp:902] Status update from slave@192.168.1.64:57346: task 59 of framework 201203291014-0-0001 is now in state TASK_RUNNING
I0329 10:14:39.782835  6088 master.cpp:902] Status update from slave@192.168.1.64:57346: task 58 of framework 201203291014-0-0001 is now in state TASK_RUNNING
I0329 10:14:39.785478  6088 master.cpp:902] Status update from slave@192.168.1.64:57346: task 60 of framework 201203291014-0-0001 is now in state TASK_RUNNING
I0329 10:14:39.791863  6088 master.cpp:902] Status update from slave@192.168.1.64:57346: task 61 of framework 201203291014-0-0001 is now in state TASK_RUNNING
I0329 10:14:39.792033  6088 master.cpp:902] Status update from slave@192.168.1.64:57346: task 62 of framework 201203291014-0-0001 is now in state TASK_RUNNING
I0329 10:14:39.796797  6088 master.cpp:902] Status update from slave@192.168.1.64:57346: task 63 of framework 201203291014-0-0001 is now in state TASK_RUNNING
I0329 10:14:39.800295  6088 master.cpp:902] Status update from slave@192.168.1.64:57346: task 64 of framework 201203291014-0-0001 is now in state TASK_RUNNING
I0329 10:14:40.764593  6088 master.cpp:1184] Sending 1 offers to framework 201203291014-0-0000
I0329 10:14:40.765770  6088 master.cpp:679] Received reply for offer 201203291014-0-33
I0329 10:14:40.765908  6088 master.cpp:1403] Filtered slave 201203291014-0-1 for framework 201203291014-0-0000 for 1 seconds
I0329 10:14:41.265288  6088 master.cpp:902] Status update from slave@192.168.1.64:57346: task 60 of framework 201203291014-0-0001 is now in state TASK_FAILED
I0329 10:14:41.265543  6088 master.cpp:1184] Sending 1 offers to framework 201203291014-0-0000
I0329 10:14:41.268399  6088 master.cpp:679] Received reply for offer 201203291014-0-34
I0329 10:14:41.268533  6088 master.cpp:1403] Filtered slave 201203291014-0-0 for framework 201203291014-0-0000 for 1 seconds
I0329 10:14:41.268950  6088 master.cpp:902] Status update from slave@192.168.1.64:57346: task 59 of framework 201203291014-0-0001 is now in state TASK_FAILED
I0329 10:14:41.269316  6088 master.cpp:1184] Sending 1 offers to framework 201203291014-0-0001
I0329 10:14:41.271847  6088 master.cpp:902] Status update from slave@192.168.1.64:57346: task 58 of framework 201203291014-0-0001 is now in state TASK_FAILED
I0329 10:14:41.275173  6088 master.cpp:902] Status update from slave@192.168.1.64:57346: task 57 of framework 201203291014-0-0001 is now in state TASK_FAILED
I0329 10:14:41.276602  6088 master.cpp:679] Received reply for offer 201203291014-0-35
I0329 10:14:41.276727  6088 master.cpp:1453] Launching task 65 on slave 201203291014-0-0
I0329 10:14:41.276991  6088 master.cpp:1453] Launching task 66 on slave 201203291014-0-0
I0329 10:14:41.278154  6088 master.cpp:902] Status update from slave@192.168.1.64:57346: task 64 of framework 201203291014-0-0001 is now in state TASK_FAILED
I0329 10:14:41.278343  6088 master.cpp:1184] Sending 1 offers to framework 201203291014-0-0001
I0329 10:14:41.280156  6088 master.cpp:902] Status update from slave@192.168.1.64:57346: task 63 of framework 201203291014-0-0001 is now in state TASK_FAILED
I0329 10:14:41.282410  6088 master.cpp:902] Status update from slave@192.168.1.64:57346: task 62 of framework 201203291014-0-0001 is now in state TASK_FAILED
I0329 10:14:41.284765  6088 master.cpp:902] Status update from slave@192.168.1.64:57346: task 61 of framework 201203291014-0-0001 is now in state TASK_FAILED
I0329 10:14:41.288738  6088 master.cpp:902] Status update from slave@192.168.1.64:57346: task 65 of framework 201203291014-0-0001 is now in state TASK_RUNNING
I0329 10:14:41.292058  6088 master.cpp:902] Status update from slave@192.168.1.64:57346: task 66 of framework 201203291014-0-0001 is now in state TASK_RUNNING
I0329 10:14:41.324214  6088 master.cpp:679] Received reply for offer 201203291014-0-36
I0329 10:14:41.324384  6088 master.cpp:1453] Launching task 67 on slave 201203291014-0-0
I0329 10:14:41.324673  6088 master.cpp:1453] Launching task 68 on slave 201203291014-0-0
I0329 10:14:41.324879  6088 master.cpp:1453] Launching task 69 on slave 201203291014-0-0
I0329 10:14:41.335160  6088 master.cpp:902] Status update from slave@192.168.1.64:57346: task 67 of framework 201203291014-0-0001 is now in state TASK_RUNNING
I0329 10:14:41.338794  6088 master.cpp:902] Status update from slave@192.168.1.64:57346: task 69 of framework 201203291014-0-0001 is now in state TASK_RUNNING
I0329 10:14:41.342933  6088 master.cpp:902] Status update from slave@192.168.1.64:57346: task 66 of framework 201203291014-0-0001 is now in state TASK_FAILED
I0329 10:14:41.343205  6088 master.cpp:1184] Sending 1 offers to framework 201203291014-0-0001
I0329 10:14:41.345916  6088 master.cpp:902] Status update from slave@192.168.1.64:57346: task 68 of framework 201203291014-0-0001 is now in state TASK_RUNNING
I0329 10:14:41.348849  6088 master.cpp:902] Status update from slave@192.168.1.64:57346: task 65 of framework 201203291014-0-0001 is now in state TASK_FAILED
I0329 10:14:41.368593  6088 master.cpp:679] Received reply for offer 201203291014-0-37
I0329 10:14:41.368773  6088 master.cpp:1453] Launching task 70 on slave 201203291014-0-0
I0329 10:14:41.369336  6088 master.cpp:1453] Launching task 71 on slave 201203291014-0-0
I0329 10:14:41.369483  6088 master.cpp:1453] Launching task 72 on slave 201203291014-0-0
I0329 10:14:41.370143  6088 master.cpp:1453] Launching task 73 on slave 201203291014-0-0
I0329 10:14:41.765635  6088 master.cpp:1184] Sending 1 offers to framework 201203291014-0-0001
I0329 10:14:41.767257  6088 master.cpp:679] Received reply for offer 201203291014-0-38
I0329 10:14:41.767410  6088 master.cpp:1403] Filtered slave 201203291014-0-1 for framework 201203291014-0-0001 for 1 seconds
I0329 10:14:42.617725  6088 master.cpp:1001] Executor default of framework 201203291014-0-0001 on slave 201203291014-0-0 (azad.gateway.2wire.net) exited with status 256
I0329 10:14:42.619231  6088 master.cpp:1033] Removing task 69 of framework 201203291014-0-0001 because of lost executor
I0329 10:14:42.619460  6088 master.cpp:1184] Sending 1 offers to framework 201203291014-0-0001
I0329 10:14:42.622010  6088 master.cpp:1033] Removing task 68 of framework 201203291014-0-0001 because of lost executor
I0329 10:14:42.624356  6088 master.cpp:1033] Removing task 67 of framework 201203291014-0-0001 because of lost executor
I0329 10:14:42.625969  6088 master.cpp:1033] Removing task 70 of framework 201203291014-0-0001 because of lost executor
I0329 10:14:42.627970  6088 master.cpp:1033] Removing task 71 of framework 201203291014-0-0001 because of lost executor
I0329 10:14:42.629765  6088 master.cpp:1033] Removing task 72 of framework 201203291014-0-0001 because of lost executor
I0329 10:14:42.631510  6088 master.cpp:1033] Removing task 73 of framework 201203291014-0-0001 because of lost executor
I0329 10:14:42.631656  6088 master.cpp:679] Received reply for offer 201203291014-0-39
I0329 10:14:42.631912  6088 master.cpp:1403] Filtered slave 201203291014-0-0 for framework 201203291014-0-0001 for 1 seconds
I0329 10:14:42.767113  6088 master.cpp:1184] Sending 2 offers to framework 201203291014-0-0000
I0329 10:14:42.768865  6088 master.cpp:679] Received reply for offer 201203291014-0-40
I0329 10:14:42.769049  6088 master.cpp:1403] Filtered slave 201203291014-0-1 for framework 201203291014-0-0000 for 1 seconds
I0329 10:14:42.769438  6088 master.cpp:679] Received reply for offer 201203291014-0-41
I0329 10:14:42.769651  6088 master.cpp:1403] Filtered slave 201203291014-0-0 for framework 201203291014-0-0000 for 1 seconds
I0329 10:14:43.769165  6088 master.cpp:1184] Sending 2 offers to framework 201203291014-0-0001
I0329 10:14:43.771004  6088 master.cpp:679] Received reply for offer 201203291014-0-42
I0329 10:14:43.771201  6088 master.cpp:1403] Filtered slave 201203291014-0-1 for framework 201203291014-0-0001 for 1 seconds
I0329 10:14:43.771548  6088 master.cpp:679] Received reply for offer 201203291014-0-43
I0329 10:14:43.771771  6088 master.cpp:1403] Filtered slave 201203291014-0-0 for framework 201203291014-0-0001 for 1 seconds
I0329 10:14:44.771404  6088 master.cpp:1184] Sending 2 offers to framework 201203291014-0-0000
I0329 10:14:44.773251  6088 master.cpp:679] Received reply for offer 201203291014-0-44
I0329 10:14:44.773468  6088 master.cpp:1403] Filtered slave 201203291014-0-1 for framework 201203291014-0-0000 for 1 seconds
I0329 10:14:44.798429  6088 master.cpp:679] Received reply for offer 201203291014-0-45
I0329 10:14:44.828008  6088 master.cpp:1403] Filtered slave 201203291014-0-0 for framework 201203291014-0-0000 for 1 seconds
I0329 10:14:45.773597  6088 master.cpp:1184] Sending 2 offers to framework 201203291014-0-0001
I0329 10:14:45.775619  6088 master.cpp:679] Received reply for offer 201203291014-0-46
I0329 10:14:45.775766  6088 master.cpp:1403] Filtered slave 201203291014-0-1 for framework 201203291014-0-0001 for 1 seconds
I0329 10:14:45.776041  6088 master.cpp:679] Received reply for offer 201203291014-0-47
I0329 10:14:45.776196  6088 master.cpp:1403] Filtered slave 201203291014-0-0 for framework 201203291014-0-0001 for 1 seconds
I0329 10:14:46.775852  6088 master.cpp:1184] Sending 2 offers to framework 201203291014-0-0000
I0329 10:14:46.777647  6088 master.cpp:679] Received reply for offer 201203291014-0-48
I0329 10:14:46.777796  6088 master.cpp:1403] Filtered slave 201203291014-0-1 for framework 201203291014-0-0000 for 1 seconds
I0329 10:14:46.778090  6088 master.cpp:679] Received reply for offer 201203291014-0-49
I0329 10:14:46.778272  6088 master.cpp:1403] Filtered slave 201203291014-0-0 for framework 201203291014-0-0000 for 1 seconds
I0329 10:14:47.777894  6088 master.cpp:1184] Sending 2 offers to framework 201203291014-0-0001
I0329 10:14:47.779772  6088 master.cpp:679] Received reply for offer 201203291014-0-50
I0329 10:14:47.779918  6088 master.cpp:1403] Filtered slave 201203291014-0-1 for framework 201203291014-0-0001 for 1 seconds
I0329 10:14:47.780251  6088 master.cpp:679] Received reply for offer 201203291014-0-51
I0329 10:14:47.780429  6088 master.cpp:1403] Filtered slave 201203291014-0-0 for framework 201203291014-0-0001 for 1 seconds
I0329 10:14:48.780145  6088 master.cpp:1184] Sending 2 offers to framework 201203291014-0-0000
I0329 10:14:48.781929  6088 master.cpp:679] Received reply for offer 201203291014-0-52
I0329 10:14:48.782078  6088 master.cpp:1403] Filtered slave 201203291014-0-1 for framework 201203291014-0-0000 for 1 seconds
I0329 10:14:48.782341  6088 master.cpp:679] Received reply for offer 201203291014-0-53
I0329 10:14:48.782521  6088 master.cpp:1403] Filtered slave 201203291014-0-0 for framework 201203291014-0-0000 for 1 seconds
I0329 10:14:49.782210  6088 master.cpp:1184] Sending 2 offers to framework 201203291014-0-0001
I0329 10:14:49.784080  6088 master.cpp:679] Received reply for offer 201203291014-0-54
I0329 10:14:49.784174  6088 master.cpp:1403] Filtered slave 201203291014-0-1 for framework 201203291014-0-0001 for 1 seconds
I0329 10:14:49.810058  6088 master.cpp:679] Received reply for offer 201203291014-0-55
I0329 10:14:49.834666  6088 master.cpp:1403] Filtered slave 201203291014-0-0 for framework 201203291014-0-0001 for 1 seconds
I0329 10:14:50.784390  6088 master.cpp:1184] Sending 2 offers to framework 201203291014-0-0000
I0329 10:14:50.786259  6088 master.cpp:679] Received reply for offer 201203291014-0-56
I0329 10:14:50.786409  6088 master.cpp:1403] Filtered slave 201203291014-0-1 for framework 201203291014-0-0000 for 1 seconds
I0329 10:14:50.786671  6088 master.cpp:679] Received reply for offer 201203291014-0-57
I0329 10:14:50.786838  6088 master.cpp:1403] Filtered slave 201203291014-0-0 for framework 201203291014-0-0000 for 1 seconds
I0329 10:14:51.785549  6088 master.cpp:1184] Sending 2 offers to framework 201203291014-0-0001
I0329 10:14:51.787502  6088 master.cpp:679] Received reply for offer 201203291014-0-58
I0329 10:14:51.787649  6088 master.cpp:1403] Filtered slave 201203291014-0-1 for framework 201203291014-0-0001 for 1 seconds
I0329 10:14:51.787991  6088 master.cpp:679] Received reply for offer 201203291014-0-59
I0329 10:14:51.788171  6088 master.cpp:1403] Filtered slave 201203291014-0-0 for framework 201203291014-0-0001 for 1 seconds
I0329 10:14:52.787847  6088 master.cpp:1184] Sending 2 offers to framework 201203291014-0-0000
I0329 10:14:52.789703  6088 master.cpp:679] Received reply for offer 201203291014-0-60
I0329 10:14:52.789852  6088 master.cpp:1403] Filtered slave 201203291014-0-1 for framework 201203291014-0-0000 for 1 seconds
I0329 10:14:52.790241  6088 master.cpp:679] Received reply for offer 201203291014-0-61
I0329 10:14:52.790776  6088 master.cpp:1403] Filtered slave 201203291014-0-0 for framework 201203291014-0-0000 for 1 seconds
I0329 10:14:53.790009  6088 master.cpp:1184] Sending 2 offers to framework 201203291014-0-0001
I0329 10:14:53.791885  6088 master.cpp:679] Received reply for offer 201203291014-0-62
I0329 10:14:53.792032  6088 master.cpp:1403] Filtered slave 201203291014-0-1 for framework 201203291014-0-0001 for 1 seconds
I0329 10:14:53.792304  6088 master.cpp:679] Received reply for offer 201203291014-0-63
I0329 10:14:53.792479  6088 master.cpp:1403] Filtered slave 201203291014-0-0 for framework 201203291014-0-0001 for 1 seconds
I0329 10:14:54.792230  6088 master.cpp:1184] Sending 2 offers to framework 201203291014-0-0000
I0329 10:14:54.794131  6088 master.cpp:679] Received reply for offer 201203291014-0-64
I0329 10:14:54.794226  6088 master.cpp:1403] Filtered slave 201203291014-0-1 for framework 201203291014-0-0000 for 1 seconds
I0329 10:14:54.822002  6088 master.cpp:679] Received reply for offer 201203291014-0-65
I0329 10:14:54.850940  6088 master.cpp:1403] Filtered slave 201203291014-0-0 for framework 201203291014-0-0000 for 1 seconds
I0329 10:14:55.794378  6088 master.cpp:1184] Sending 2 offers to framework 201203291014-0-0001
I0329 10:14:55.796007  6088 master.cpp:679] Received reply for offer 201203291014-0-66
I0329 10:14:55.796157  6088 master.cpp:1403] Filtered slave 201203291014-0-1 for framework 201203291014-0-0001 for 1 seconds
I0329 10:14:55.796457  6088 master.cpp:679] Received reply for offer 201203291014-0-67
I0329 10:14:55.796627  6088 master.cpp:1403] Filtered slave 201203291014-0-0 for framework 201203291014-0-0001 for 1 seconds
I0329 10:14:56.796229  6088 master.cpp:1184] Sending 2 offers to framework 201203291014-0-0000
I0329 10:14:56.797879  6088 master.cpp:679] Received reply for offer 201203291014-0-68
I0329 10:14:56.798027  6088 master.cpp:1403] Filtered slave 201203291014-0-1 for framework 201203291014-0-0000 for 1 seconds
I0329 10:14:56.798313  6088 master.cpp:679] Received reply for offer 201203291014-0-69
I0329 10:14:56.798531  6088 master.cpp:1403] Filtered slave 201203291014-0-0 for framework 201203291014-0-0000 for 1 seconds
I0329 10:14:57.798117  6088 master.cpp:1184] Sending 2 offers to framework 201203291014-0-0001
I0329 10:14:57.799830  6088 master.cpp:679] Received reply for offer 201203291014-0-70
I0329 10:14:57.799983  6088 master.cpp:1403] Filtered slave 201203291014-0-1 for framework 201203291014-0-0001 for 1 seconds
I0329 10:14:57.800313  6088 master.cpp:679] Received reply for offer 201203291014-0-71
I0329 10:14:57.800521  6088 master.cpp:1403] Filtered slave 201203291014-0-0 for framework 201203291014-0-0001 for 1 seconds
I0329 10:14:58.800078  6088 master.cpp:1184] Sending 2 offers to framework 201203291014-0-0000
I0329 10:14:58.801802  6088 master.cpp:679] Received reply for offer 201203291014-0-72
I0329 10:14:58.801952  6088 master.cpp:1403] Filtered slave 201203291014-0-1 for framework 201203291014-0-0000 for 1 seconds
I0329 10:14:58.802248  6088 master.cpp:679] Received reply for offer 201203291014-0-73
I0329 10:14:58.802417  6088 master.cpp:1403] Filtered slave 201203291014-0-0 for framework 201203291014-0-0000 for 1 seconds
I0329 10:14:59.802045  6088 master.cpp:1184] Sending 2 offers to framework 201203291014-0-0001
I0329 10:14:59.804043  6088 master.cpp:679] Received reply for offer 201203291014-0-74
I0329 10:14:59.804137  6088 master.cpp:1403] Filtered slave 201203291014-0-1 for framework 201203291014-0-0001 for 1 seconds
I0329 10:14:59.833591  6088 master.cpp:679] Received reply for offer 201203291014-0-75
I0329 10:14:59.862540  6088 master.cpp:1403] Filtered slave 201203291014-0-0 for framework 201203291014-0-0001 for 1 seconds
I0329 10:15:00.804307  6088 master.cpp:1184] Sending 2 offers to framework 201203291014-0-0000
I0329 10:15:00.806179  6088 master.cpp:679] Received reply for offer 201203291014-0-76
I0329 10:15:00.806328  6088 master.cpp:1403] Filtered slave 201203291014-0-1 for framework 201203291014-0-0000 for 1 seconds
I0329 10:15:00.806681  6088 master.cpp:679] Received reply for offer 201203291014-0-77
I0329 10:15:00.807155  6088 master.cpp:1403] Filtered slave 201203291014-0-0 for framework 201203291014-0-0000 for 1 seconds
I0329 10:15:01.806416  6088 master.cpp:1184] Sending 2 offers to framework 201203291014-0-0001
I0329 10:15:01.808378  6088 master.cpp:679] Received reply for offer 201203291014-0-78
I0329 10:15:01.808527  6088 master.cpp:1403] Filtered slave 201203291014-0-1 for framework 201203291014-0-0001 for 1 seconds
I0329 10:15:01.808797  6088 master.cpp:679] Received reply for offer 201203291014-0-79
I0329 10:15:01.808950  6088 master.cpp:1403] Filtered slave 201203291014-0-0 for framework 201203291014-0-0001 for 1 seconds
I0329 10:15:02.808593  6088 master.cpp:1184] Sending 2 offers to framework 201203291014-0-0000
I0329 10:15:02.810184  6088 master.cpp:679] Received reply for offer 201203291014-0-80
I0329 10:15:02.810307  6088 master.cpp:1403] Filtered slave 201203291014-0-1 for framework 201203291014-0-0000 for 1 seconds
I0329 10:15:02.810591  6088 master.cpp:679] Received reply for offer 201203291014-0-81
I0329 10:15:02.810719  6088 master.cpp:1403] Filtered slave 201203291014-0-0 for framework 201203291014-0-0000 for 1 seconds
I0329 10:15:03.810423  6088 master.cpp:1184] Sending 2 offers to framework 201203291014-0-0001
I0329 10:15:03.812440  6088 master.cpp:679] Received reply for offer 201203291014-0-82
I0329 10:15:03.812623  6088 master.cpp:1403] Filtered slave 201203291014-0-1 for framework 201203291014-0-0001 for 1 seconds
I0329 10:15:03.812974  6088 master.cpp:679] Received reply for offer 201203291014-0-83
I0329 10:15:03.813148  6088 master.cpp:1403] Filtered slave 201203291014-0-0 for framework 201203291014-0-0001 for 1 seconds
I0329 10:15:04.812764  6088 master.cpp:1184] Sending 2 offers to framework 201203291014-0-0000
I0329 10:15:04.815069  6088 master.cpp:679] Received reply for offer 201203291014-0-84
I0329 10:15:04.815191  6088 master.cpp:1403] Filtered slave 201203291014-0-1 for framework 201203291014-0-0000 for 1 seconds
I0329 10:15:04.837194  6088 master.cpp:679] Received reply for offer 201203291014-0-85
I0329 10:15:04.861332  6088 master.cpp:1403] Filtered slave 201203291014-0-0 for framework 201203291014-0-0000 for 1 seconds
I0329 10:15:05.814393  6088 master.cpp:1184] Sending 2 offers to framework 201203291014-0-0001
I0329 10:15:05.816138  6088 master.cpp:679] Received reply for offer 201203291014-0-86
I0329 10:15:05.816284  6088 master.cpp:1403] Filtered slave 201203291014-0-1 for framework 201203291014-0-0001 for 1 seconds
I0329 10:15:05.816561  6088 master.cpp:679] Received reply for offer 201203291014-0-87
I0329 10:15:05.816720  6088 master.cpp:1403] Filtered slave 201203291014-0-0 for framework 201203291014-0-0001 for 1 seconds
I0329 10:15:06.815233  6088 master.cpp:1184] Sending 2 offers to framework 201203291014-0-0000
I0329 10:15:06.817124  6088 master.cpp:679] Received reply for offer 201203291014-0-88
I0329 10:15:06.817272  6088 master.cpp:1403] Filtered slave 201203291014-0-1 for framework 201203291014-0-0000 for 1 seconds
I0329 10:15:06.817677  6088 master.cpp:679] Received reply for offer 201203291014-0-89
I0329 10:15:06.818133  6088 master.cpp:1403] Filtered slave 201203291014-0-0 for framework 201203291014-0-0000 for 1 seconds
I0329 10:15:07.817282  6088 master.cpp:1184] Sending 2 offers to framework 201203291014-0-0001
I0329 10:15:07.819069  6088 master.cpp:679] Received reply for offer 201203291014-0-90
I0329 10:15:07.819224  6088 master.cpp:1403] Filtered slave 201203291014-0-1 for framework 201203291014-0-0001 for 1 seconds
I0329 10:15:07.819524  6088 master.cpp:679] Received reply for offer 201203291014-0-91
I0329 10:15:07.819675  6088 master.cpp:1403] Filtered slave 201203291014-0-0 for framework 201203291014-0-0001 for 1 seconds
I0329 10:15:08.202945  6088 master.cpp:1118] Framework 201203291014-0-0001 disconnected
I0329 10:15:08.203145  6088 master.cpp:1118] Framework 201203291014-0-0000 disconnected
I0329 10:18:23.856773  6088 master.cpp:492] Registering framework 201203291014-0-0002 at 3@192.168.1.64:49414
I0329 10:18:23.857141  6088 simple_allocator.cpp:48] Added framework 201203291014-0-0002
I0329 10:18:23.857395  6088 master.cpp:1184] Sending 2 offers to framework 201203291014-0-0002
I0329 10:18:23.857671  6088 master.cpp:492] Registering framework 201203291014-0-0003 at 2@192.168.1.64:49414
I0329 10:18:23.857897  6088 simple_allocator.cpp:48] Added framework 201203291014-0-0003
I0329 10:18:23.880254  6088 master.cpp:679] Received reply for offer 201203291014-0-92
I0329 10:18:23.880525  6088 master.cpp:1403] Filtered slave 201203291014-0-1 for framework 201203291014-0-0002 for 1 seconds
I0329 10:18:23.880822  6088 master.cpp:679] Received reply for offer 201203291014-0-93
I0329 10:18:23.881124  6088 master.cpp:1184] Sending 1 offers to framework 201203291014-0-0003
I0329 10:18:23.881335  6088 master.cpp:1403] Filtered slave 201203291014-0-0 for framework 201203291014-0-0002 for 1 seconds
I0329 10:18:23.882220  6088 master.cpp:679] Received reply for offer 201203291014-0-94
I0329 10:18:23.882344  6088 master.cpp:1403] Filtered slave 201203291014-0-1 for framework 201203291014-0-0003 for 1 seconds
I0329 10:18:24.041581  6088 master.cpp:1184] Sending 1 offers to framework 201203291014-0-0003
I0329 10:18:24.042845  6088 master.cpp:679] Received reply for offer 201203291014-0-95
I0329 10:18:24.042965  6088 master.cpp:1403] Filtered slave 201203291014-0-0 for framework 201203291014-0-0003 for 1 seconds
I0329 10:18:24.238682  6088 master.cpp:718] Reviving offers for framework 201203291014-0-0003
I0329 10:18:24.238829  6088 simple_allocator.cpp:145] Filters removed for framework 201203291014-0-0003
I0329 10:18:24.239194  6088 master.cpp:1184] Sending 2 offers to framework 201203291014-0-0003
I0329 10:18:24.334545  6088 master.cpp:679] Received reply for offer 201203291014-0-96
I0329 10:18:24.334758  6088 master.cpp:1403] Filtered slave 201203291014-0-1 for framework 201203291014-0-0003 for 1 seconds
I0329 10:18:24.336115  6088 master.cpp:679] Received reply for offer 201203291014-0-97
I0329 10:18:24.336263  6088 master.cpp:1453] Launching task 0 on slave 201203291014-0-0
I0329 10:18:24.336421  6088 master.cpp:1453] Launching task 1 on slave 201203291014-0-0
I0329 10:18:24.336602  6088 master.cpp:1453] Launching task 2 on slave 201203291014-0-0
I0329 10:18:24.336875  6088 master.cpp:1453] Launching task 3 on slave 201203291014-0-0
I0329 10:18:24.336998  6088 master.cpp:1453] Launching task 4 on slave 201203291014-0-0
I0329 10:18:24.337410  6088 master.cpp:1453] Launching task 5 on slave 201203291014-0-0
I0329 10:18:24.337867  6088 master.cpp:1453] Launching task 6 on slave 201203291014-0-0
I0329 10:18:24.338363  6088 master.cpp:1453] Launching task 7 on slave 201203291014-0-0
I0329 10:18:25.043431  6088 master.cpp:1184] Sending 1 offers to framework 201203291014-0-0002
I0329 10:18:25.044821  6088 master.cpp:679] Received reply for offer 201203291014-0-98
I0329 10:18:25.044946  6088 master.cpp:1403] Filtered slave 201203291014-0-1 for framework 201203291014-0-0002 for 1 seconds
I0329 10:18:25.333834  6088 master.cpp:902] Status update from slave@192.168.1.64:57346: task 4 of framework 201203291014-0-0003 is now in state TASK_RUNNING
I0329 10:18:25.336213  6088 master.cpp:902] Status update from slave@192.168.1.64:57346: task 5 of framework 201203291014-0-0003 is now in state TASK_RUNNING
I0329 10:18:25.338737  6088 master.cpp:902] Status update from slave@192.168.1.64:57346: task 3 of framework 201203291014-0-0003 is now in state TASK_RUNNING
I0329 10:18:25.341249  6088 master.cpp:902] Status update from slave@192.168.1.64:57346: task 0 of framework 201203291014-0-0003 is now in state TASK_RUNNING
I0329 10:18:25.343688  6088 master.cpp:902] Status update from slave@192.168.1.64:57346: task 2 of framework 201203291014-0-0003 is now in state TASK_RUNNING
I0329 10:18:25.346117  6088 master.cpp:902] Status update from slave@192.168.1.64:57346: task 1 of framework 201203291014-0-0003 is now in state TASK_RUNNING
I0329 10:18:25.348506  6088 master.cpp:902] Status update from slave@192.168.1.64:57346: task 6 of framework 201203291014-0-0003 is now in state TASK_RUNNING
I0329 10:18:25.350946  6088 master.cpp:902] Status update from slave@192.168.1.64:57346: task 7 of framework 201203291014-0-0003 is now in state TASK_RUNNING
I0329 10:18:26.044945  6088 master.cpp:1184] Sending 1 offers to framework 201203291014-0-0003
I0329 10:18:26.046180  6088 master.cpp:679] Received reply for offer 201203291014-0-99
I0329 10:18:26.046304  6088 master.cpp:1403] Filtered slave 201203291014-0-1 for framework 201203291014-0-0003 for 1 seconds
I0329 10:18:26.692477  6088 master.cpp:902] Status update from slave@192.168.1.64:57346: task 7 of framework 201203291014-0-0003 is now in state TASK_FINISHED
I0329 10:18:26.692731  6088 master.cpp:1184] Sending 1 offers to framework 201203291014-0-0002
I0329 10:18:26.694541  6088 master.cpp:902] Status update from slave@192.168.1.64:57346: task 6 of framework 201203291014-0-0003 is now in state TASK_FINISHED
I0329 10:18:26.697433  6088 master.cpp:902] Status update from slave@192.168.1.64:57346: task 0 of framework 201203291014-0-0003 is now in state TASK_FINISHED
I0329 10:18:26.698812  6088 master.cpp:902] Status update from slave@192.168.1.64:57346: task 1 of framework 201203291014-0-0003 is now in state TASK_FINISHED
I0329 10:18:26.701061  6088 master.cpp:902] Status update from slave@192.168.1.64:57346: task 3 of framework 201203291014-0-0003 is now in state TASK_FINISHED
I0329 10:18:26.702985  6088 master.cpp:902] Status update from slave@192.168.1.64:57346: task 5 of framework 201203291014-0-0003 is now in state TASK_FINISHED
I0329 10:18:26.705251  6088 master.cpp:902] Status update from slave@192.168.1.64:57346: task 4 of framework 201203291014-0-0003 is now in state TASK_FINISHED
I0329 10:18:26.707227  6088 master.cpp:902] Status update from slave@192.168.1.64:57346: task 2 of framework 201203291014-0-0003 is now in state TASK_FINISHED
I0329 10:18:26.710675  6088 master.cpp:679] Received reply for offer 201203291014-0-100
I0329 10:18:26.710876  6088 master.cpp:1403] Filtered slave 201203291014-0-0 for framework 201203291014-0-0002 for 1 seconds
I0329 10:18:27.046219  6088 master.cpp:1184] Sending 1 offers to framework 201203291014-0-0002
I0329 10:18:27.047888  6088 master.cpp:679] Received reply for offer 201203291014-0-101
I0329 10:18:27.048040  6088 master.cpp:1403] Filtered slave 201203291014-0-1 for framework 201203291014-0-0002 for 1 seconds
I0329 10:18:28.047329  6088 master.cpp:1184] Sending 2 offers to framework 201203291014-0-0003
I0329 10:18:28.088490  6088 master.cpp:679] Received reply for offer 201203291014-0-102
I0329 10:18:28.088647  6088 master.cpp:1403] Filtered slave 201203291014-0-1 for framework 201203291014-0-0003 for 1 seconds
I0329 10:18:28.090060  6088 master.cpp:679] Received reply for offer 201203291014-0-103
I0329 10:18:28.090217  6088 master.cpp:1453] Launching task 8 on slave 201203291014-0-0
I0329 10:18:28.090456  6088 master.cpp:1453] Launching task 9 on slave 201203291014-0-0
I0329 10:18:28.090679  6088 master.cpp:1453] Launching task 10 on slave 201203291014-0-0
I0329 10:18:28.090957  6088 master.cpp:1453] Launching task 11 on slave 201203291014-0-0
I0329 10:18:28.091230  6088 master.cpp:1453] Launching task 12 on slave 201203291014-0-0
I0329 10:18:28.091791  6088 master.cpp:1453] Launching task 13 on slave 201203291014-0-0
I0329 10:18:28.092010  6088 master.cpp:1453] Launching task 14 on slave 201203291014-0-0
I0329 10:18:28.092529  6088 master.cpp:1453] Launching task 15 on slave 201203291014-0-0
I0329 10:18:28.095036  6088 master.cpp:902] Status update from slave@192.168.1.64:57346: task 8 of framework 201203291014-0-0003 is now in state TASK_RUNNING
I0329 10:18:28.096760  6088 master.cpp:902] Status update from slave@192.168.1.64:57346: task 9 of framework 201203291014-0-0003 is now in state TASK_RUNNING
I0329 10:18:28.098412  6088 master.cpp:902] Status update from slave@192.168.1.64:57346: task 10 of framework 201203291014-0-0003 is now in state TASK_RUNNING
I0329 10:18:28.119257  6088 master.cpp:902] Status update from slave@192.168.1.64:57346: task 11 of framework 201203291014-0-0003 is now in state TASK_RUNNING
I0329 10:18:28.122773  6088 master.cpp:902] Status update from slave@192.168.1.64:57346: task 12 of framework 201203291014-0-0003 is now in state TASK_RUNNING
I0329 10:18:28.125509  6088 master.cpp:902] Status update from slave@192.168.1.64:57346: task 14 of framework 201203291014-0-0003 is now in state TASK_RUNNING
I0329 10:18:28.128198  6088 master.cpp:902] Status update from slave@192.168.1.64:57346: task 13 of framework 201203291014-0-0003 is now in state TASK_RUNNING
I0329 10:18:28.130941  6088 master.cpp:902] Status update from slave@192.168.1.64:57346: task 15 of framework 201203291014-0-0003 is now in state TASK_RUNNING
I0329 10:18:28.214998  6088 master.cpp:902] Status update from slave@192.168.1.64:57346: task 10 of framework 201203291014-0-0003 is now in state TASK_FINISHED
I0329 10:18:28.215265  6088 master.cpp:1184] Sending 1 offers to framework 201203291014-0-0002
I0329 10:18:28.227150  6088 master.cpp:679] Received reply for offer 201203291014-0-104
I0329 10:18:28.227359  6088 master.cpp:1403] Filtered slave 201203291014-0-0 for framework 201203291014-0-0002 for 1 seconds
I0329 10:18:28.229703  6088 master.cpp:902] Status update from slave@192.168.1.64:57346: task 12 of framework 201203291014-0-0003 is now in state TASK_FINISHED
I0329 10:18:28.229954  6088 master.cpp:1184] Sending 1 offers to framework 201203291014-0-0003
I0329 10:18:28.243329  6088 master.cpp:902] Status update from slave@192.168.1.64:57346: task 8 of framework 201203291014-0-0003 is now in state TASK_FINISHED
I0329 10:18:28.254384  6088 master.cpp:679] Received reply for offer 201203291014-0-105
I0329 10:18:28.254577  6088 master.cpp:1453] Launching task 16 on slave 201203291014-0-0
I0329 10:18:28.254871  6088 master.cpp:1453] Launching task 17 on slave 201203291014-0-0
I0329 10:18:28.263700  6088 master.cpp:902] Status update from slave@192.168.1.64:57346: task 16 of framework 201203291014-0-0003 is now in state TASK_RUNNING
I0329 10:18:28.263924  6088 master.cpp:902] Status update from slave@192.168.1.64:57346: task 11 of framework 201203291014-0-0003 is now in state TASK_FINISHED
I0329 10:18:28.264410  6088 master.cpp:1184] Sending 1 offers to framework 201203291014-0-0003
I0329 10:18:28.270186  6088 master.cpp:902] Status update from slave@192.168.1.64:57346: task 9 of framework 201203291014-0-0003 is now in state TASK_FINISHED
I0329 10:18:28.270596  6088 master.cpp:902] Status update from slave@192.168.1.64:57346: task 13 of framework 201203291014-0-0003 is now in state TASK_FINISHED
I0329 10:18:28.272001  6088 master.cpp:902] Status update from slave@192.168.1.64:57346: task 14 of framework 201203291014-0-0003 is now in state TASK_FINISHED
I0329 10:18:28.276113  6088 master.cpp:679] Received reply for offer 201203291014-0-106
I0329 10:18:28.276281  6088 master.cpp:1453] Launching task 18 on slave 201203291014-0-0
I0329 10:18:28.276556  6088 master.cpp:1453] Launching task 19 on slave 201203291014-0-0
I0329 10:18:28.278172  6088 master.cpp:902] Status update from slave@192.168.1.64:57346: task 15 of framework 201203291014-0-0003 is now in state TASK_FINISHED
I0329 10:18:28.278410  6088 master.cpp:1184] Sending 1 offers to framework 201203291014-0-0003
I0329 10:18:28.281746  6088 master.cpp:902] Status update from slave@192.168.1.64:57346: task 17 of framework 201203291014-0-0003 is now in state TASK_RUNNING
I0329 10:18:28.284915  6088 master.cpp:902] Status update from slave@192.168.1.64:57346: task 19 of framework 201203291014-0-0003 is now in state TASK_RUNNING
I0329 10:18:28.288045  6088 master.cpp:902] Status update from slave@192.168.1.64:57346: task 18 of framework 201203291014-0-0003 is now in state TASK_RUNNING
I0329 10:18:28.331189  6088 master.cpp:679] Received reply for offer 201203291014-0-107
I0329 10:18:28.331356  6088 master.cpp:1453] Launching task 20 on slave 201203291014-0-0
I0329 10:18:28.331634  6088 master.cpp:1453] Launching task 21 on slave 201203291014-0-0
I0329 10:18:28.332011  6088 master.cpp:1453] Launching task 22 on slave 201203291014-0-0
I0329 10:18:28.332748  6088 master.cpp:1453] Launching task 23 on slave 201203291014-0-0
I0329 10:18:28.343844  6088 master.cpp:902] Status update from slave@192.168.1.64:57346: task 20 of framework 201203291014-0-0003 is now in state TASK_RUNNING
I0329 10:18:28.353649  6088 master.cpp:902] Status update from slave@192.168.1.64:57346: task 21 of framework 201203291014-0-0003 is now in state TASK_RUNNING
I0329 10:18:28.363605  6088 master.cpp:902] Status update from slave@192.168.1.64:57346: task 23 of framework 201203291014-0-0003 is now in state TASK_RUNNING
I0329 10:18:28.368147  6088 master.cpp:902] Status update from slave@192.168.1.64:57346: task 22 of framework 201203291014-0-0003 is now in state TASK_RUNNING
I0329 10:18:28.371698  6088 master.cpp:902] Status update from slave@192.168.1.64:57346: task 16 of framework 201203291014-0-0003 is now in state TASK_FINISHED
I0329 10:18:28.371985  6088 master.cpp:1184] Sending 1 offers to framework 201203291014-0-0003
I0329 10:18:28.375283  6088 master.cpp:902] Status update from slave@192.168.1.64:57346: task 17 of framework 201203291014-0-0003 is now in state TASK_FINISHED
I0329 10:18:28.382969  6088 master.cpp:679] Received reply for offer 201203291014-0-108
I0329 10:18:28.383167  6088 master.cpp:1453] Launching task 24 on slave 201203291014-0-0
I0329 10:18:28.383455  6088 master.cpp:902] Status update from slave@192.168.1.64:57346: task 18 of framework 201203291014-0-0003 is now in state TASK_FINISHED
I0329 10:18:28.383846  6088 master.cpp:1184] Sending 1 offers to framework 201203291014-0-0003
I0329 10:18:28.389539  6088 master.cpp:902] Status update from slave@192.168.1.64:57346: task 24 of framework 201203291014-0-0003 is now in state TASK_RUNNING
I0329 10:18:28.427750  6088 master.cpp:902] Status update from slave@192.168.1.64:57346: task 19 of framework 201203291014-0-0003 is now in state TASK_FINISHED
I0329 10:18:28.431335  6088 master.cpp:679] Received reply for offer 201203291014-0-109
I0329 10:18:28.431526  6088 master.cpp:1453] Launching task 25 on slave 201203291014-0-0
I0329 10:18:28.431840  6088 master.cpp:1453] Launching task 26 on slave 201203291014-0-0
I0329 10:18:28.440875  6088 master.cpp:902] Status update from slave@192.168.1.64:57346: task 25 of framework 201203291014-0-0003 is now in state TASK_RUNNING
I0329 10:18:28.450398  6088 master.cpp:902] Status update from slave@192.168.1.64:57346: task 26 of framework 201203291014-0-0003 is now in state TASK_RUNNING
I0329 10:18:28.493679  6088 master.cpp:902] Status update from slave@192.168.1.64:57346: task 22 of framework 201203291014-0-0003 is now in state TASK_FINISHED
I0329 10:18:28.493947  6088 master.cpp:1184] Sending 1 offers to framework 201203291014-0-0003
I0329 10:18:28.499434  6088 master.cpp:902] Status update from slave@192.168.1.64:57346: task 20 of framework 201203291014-0-0003 is now in state TASK_FINISHED
I0329 10:18:28.501802  6088 master.cpp:902] Status update from slave@192.168.1.64:57346: task 21 of framework 201203291014-0-0003 is now in state TASK_FINISHED
I0329 10:18:28.505290  6088 master.cpp:902] Status update from slave@192.168.1.64:57346: task 23 of framework 201203291014-0-0003 is now in state TASK_FINISHED
I0329 10:18:28.507236  6088 master.cpp:902] Status update from slave@192.168.1.64:57346: task 24 of framework 201203291014-0-0003 is now in state TASK_FINISHED
I0329 10:18:28.511874  6088 master.cpp:679] Received reply for offer 201203291014-0-110
I0329 10:18:28.512058  6088 master.cpp:1453] Launching task 27 on slave 201203291014-0-0
I0329 10:18:28.512377  6088 master.cpp:1453] Launching task 28 on slave 201203291014-0-0
I0329 10:18:28.516567  6088 master.cpp:902] Status update from slave@192.168.1.64:57346: task 27 of framework 201203291014-0-0003 is now in state TASK_RUNNING
I0329 10:18:28.535997  6088 master.cpp:902] Status update from slave@192.168.1.64:57346: task 26 of framework 201203291014-0-0003 is now in state TASK_FINISHED
I0329 10:18:28.536257  6088 master.cpp:1184] Sending 1 offers to framework 201203291014-0-0003
I0329 10:18:28.542290  6088 master.cpp:902] Status update from slave@192.168.1.64:57346: task 25 of framework 201203291014-0-0003 is now in state TASK_FINISHED
I0329 10:18:28.555642  6088 master.cpp:679] Received reply for offer 201203291014-0-111
I0329 10:18:28.555737  6088 master.cpp:1453] Launching task 29 on slave 201203291014-0-0
I0329 10:18:28.556172  6088 master.cpp:1453] Launching task 30 on slave 201203291014-0-0
I0329 10:18:28.556380  6088 master.cpp:1453] Launching task 31 on slave 201203291014-0-0
I0329 10:18:28.556612  6088 master.cpp:1453] Launching task 32 on slave 201203291014-0-0
I0329 10:18:28.556790  6088 master.cpp:1453] Launching task 33 on slave 201203291014-0-0
I0329 10:18:28.557399  6088 master.cpp:902] Status update from slave@192.168.1.64:57346: task 28 of framework 201203291014-0-0003 is now in state TASK_RUNNING
I0329 10:18:28.561075  6088 master.cpp:902] Status update from slave@192.168.1.64:57346: task 29 of framework 201203291014-0-0003 is now in state TASK_RUNNING
I0329 10:18:28.564542  6088 master.cpp:902] Status update from slave@192.168.1.64:57346: task 30 of framework 201203291014-0-0003 is now in state TASK_RUNNING
I0329 10:18:28.581639  6088 master.cpp:902] Status update from slave@192.168.1.64:57346: task 32 of framework 201203291014-0-0003 is now in state TASK_RUNNING
I0329 10:18:28.585335  6088 master.cpp:902] Status update from slave@192.168.1.64:57346: task 31 of framework 201203291014-0-0003 is now in state TASK_RUNNING
I0329 10:18:28.602020  6088 master.cpp:902] Status update from slave@192.168.1.64:57346: task 33 of framework 201203291014-0-0003 is now in state TASK_RUNNING
I0329 10:18:28.617383  6088 master.cpp:902] Status update from slave@192.168.1.64:57346: task 27 of framework 201203291014-0-0003 is now in state TASK_FINISHED
I0329 10:18:28.617668  6088 master.cpp:1184] Sending 1 offers to framework 201203291014-0-0003
I0329 10:18:28.626874  6088 master.cpp:679] Received reply for offer 201203291014-0-112
I0329 10:18:28.627066  6088 master.cpp:1453] Launching task 34 on slave 201203291014-0-0
I0329 10:18:28.627348  6088 master.cpp:1453] Launching task 35 on slave 201203291014-0-0
I0329 10:18:28.633743  6088 master.cpp:902] Status update from slave@192.168.1.64:57346: task 34 of framework 201203291014-0-0003 is now in state TASK_RUNNING
I0329 10:18:28.636680  6088 master.cpp:902] Status update from slave@192.168.1.64:57346: task 35 of framework 201203291014-0-0003 is now in state TASK_RUNNING
I0329 10:18:28.672781  6088 master.cpp:902] Status update from slave@192.168.1.64:57346: task 29 of framework 201203291014-0-0003 is now in state TASK_FINISHED
I0329 10:18:28.673069  6088 master.cpp:1184] Sending 1 offers to framework 201203291014-0-0003
I0329 10:18:28.684923  6088 master.cpp:902] Status update from slave@192.168.1.64:57346: task 28 of framework 201203291014-0-0003 is now in state TASK_FINISHED
I0329 10:18:28.689823  6088 master.cpp:902] Status update from slave@192.168.1.64:57346: task 30 of framework 201203291014-0-0003 is now in state TASK_FINISHED
I0329 10:18:28.690239  6088 master.cpp:679] Received reply for offer 201203291014-0-113
I0329 10:18:28.690367  6088 master.cpp:1453] Launching task 36 on slave 201203291014-0-0
I0329 10:18:28.697084  6088 master.cpp:902] Status update from slave@192.168.1.64:57346: task 36 of framework 201203291014-0-0003 is now in state TASK_RUNNING
I0329 10:18:28.700558  6088 master.cpp:902] Status update from slave@192.168.1.64:57346: task 32 of framework 201203291014-0-0003 is now in state TASK_FINISHED
I0329 10:18:28.700783  6088 master.cpp:1184] Sending 1 offers to framework 201203291014-0-0003
I0329 10:18:28.704813  6088 master.cpp:902] Status update from slave@192.168.1.64:57346: task 31 of framework 201203291014-0-0003 is now in state TASK_FINISHED
I0329 10:18:28.727979  6088 master.cpp:902] Status update from slave@192.168.1.64:57346: task 33 of framework 201203291014-0-0003 is now in state TASK_FINISHED
I0329 10:18:28.738628  6088 master.cpp:679] Received reply for offer 201203291014-0-114
I0329 10:18:28.738809  6088 master.cpp:1453] Launching task 37 on slave 201203291014-0-0
I0329 10:18:28.739158  6088 master.cpp:1453] Launching task 38 on slave 201203291014-0-0
I0329 10:18:28.739802  6088 master.cpp:1453] Launching task 39 on slave 201203291014-0-0
I0329 10:18:28.743758  6088 master.cpp:902] Status update from slave@192.168.1.64:57346: task 37 of framework 201203291014-0-0003 is now in state TASK_RUNNING
I0329 10:18:28.747365  6088 master.cpp:902] Status update from slave@192.168.1.64:57346: task 39 of framework 201203291014-0-0003 is now in state TASK_RUNNING
I0329 10:18:28.749541  6088 master.cpp:902] Status update from slave@192.168.1.64:57346: task 38 of framework 201203291014-0-0003 is now in state TASK_RUNNING
I0329 10:18:28.751791  6088 master.cpp:902] Status update from slave@192.168.1.64:57346: task 35 of framework 201203291014-0-0003 is now in state TASK_FINISHED
I0329 10:18:28.752022  6088 master.cpp:1184] Sending 1 offers to framework 201203291014-0-0003
I0329 10:18:28.753926  6088 master.cpp:902] Status update from slave@192.168.1.64:57346: task 34 of framework 201203291014-0-0003 is now in state TASK_FINISHED
I0329 10:18:28.776034  6088 master.cpp:679] Received reply for offer 201203291014-0-115
I0329 10:18:28.776211  6088 master.cpp:1403] Filtered slave 201203291014-0-0 for framework 201203291014-0-0003 for 1 seconds
I0329 10:18:28.840497  6088 master.cpp:902] Status update from slave@192.168.1.64:57346: task 36 of framework 201203291014-0-0003 is now in state TASK_FINISHED
I0329 10:18:28.842412  6088 master.cpp:902] Status update from slave@192.168.1.64:57346: task 37 of framework 201203291014-0-0003 is now in state TASK_FINISHED
I0329 10:18:28.844676  6088 master.cpp:902] Status update from slave@192.168.1.64:57346: task 38 of framework 201203291014-0-0003 is now in state TASK_FINISHED
I0329 10:18:29.020908  6088 master.cpp:902] Status update from slave@192.168.1.64:57346: task 39 of framework 201203291014-0-0003 is now in state TASK_FINISHED
I0329 10:18:29.048491  6088 master.cpp:1184] Sending 1 offers to framework 201203291014-0-0002
I0329 10:18:29.060299  6088 master.cpp:679] Received reply for offer 201203291014-0-116
I0329 10:18:29.060459  6088 master.cpp:1403] Filtered slave 201203291014-0-1 for framework 201203291014-0-0002 for 1 seconds
I0329 10:18:30.050509  6088 master.cpp:1184] Sending 1 offers to framework 201203291014-0-0002
I0329 10:18:30.050700  6088 master.cpp:1184] Sending 1 offers to framework 201203291014-0-0003
I0329 10:18:30.052090  6088 master.cpp:679] Received reply for offer 201203291014-0-117
I0329 10:18:30.052266  6088 master.cpp:1403] Filtered slave 201203291014-0-0 for framework 201203291014-0-0002 for 1 seconds
I0329 10:18:30.052487  6088 master.cpp:679] Received reply for offer 201203291014-0-118
I0329 10:18:30.052652  6088 master.cpp:1403] Filtered slave 201203291014-0-1 for framework 201203291014-0-0003 for 1 seconds
I0329 10:18:31.052809  6088 master.cpp:1184] Sending 1 offers to framework 201203291014-0-0002
I0329 10:18:31.054316  6088 master.cpp:679] Received reply for offer 201203291014-0-119
I0329 10:18:31.054471  6088 master.cpp:1403] Filtered slave 201203291014-0-1 for framework 201203291014-0-0002 for 1 seconds
I0329 10:18:32.054577  6088 master.cpp:1184] Sending 2 offers to framework 201203291014-0-0003
I0329 10:18:32.056493  6088 master.cpp:679] Received reply for offer 201203291014-0-120
I0329 10:18:32.056643  6088 master.cpp:1403] Filtered slave 201203291014-0-1 for framework 201203291014-0-0003 for 1 seconds
I0329 10:18:32.057062  6088 master.cpp:679] Received reply for offer 201203291014-0-121
I0329 10:18:32.057221  6088 master.cpp:1403] Filtered slave 201203291014-0-0 for framework 201203291014-0-0003 for 1 seconds
I0329 10:18:33.056813  6088 master.cpp:1184] Sending 2 offers to framework 201203291014-0-0002
I0329 10:18:33.058573  6088 master.cpp:679] Received reply for offer 201203291014-0-122
I0329 10:18:33.058720  6088 master.cpp:1403] Filtered slave 201203291014-0-1 for framework 201203291014-0-0002 for 1 seconds
I0329 10:18:33.058977  6088 master.cpp:679] Received reply for offer 201203291014-0-123
I0329 10:18:33.059273  6088 master.cpp:1403] Filtered slave 201203291014-0-0 for framework 201203291014-0-0002 for 1 seconds
I0329 10:18:34.058889  6088 master.cpp:1184] Sending 2 offers to framework 201203291014-0-0003
I0329 10:18:34.060925  6088 master.cpp:679] Received reply for offer 201203291014-0-124
I0329 10:18:34.061014  6088 master.cpp:1403] Filtered slave 201203291014-0-1 for framework 201203291014-0-0003 for 1 seconds
I0329 10:18:34.087718  6088 master.cpp:679] Received reply for offer 201203291014-0-125
I0329 10:18:34.117523  6088 master.cpp:1403] Filtered slave 201203291014-0-0 for framework 201203291014-0-0003 for 1 seconds
I0329 10:18:35.060523  6088 master.cpp:1184] Sending 2 offers to framework 201203291014-0-0002
I0329 10:18:35.062378  6088 master.cpp:679] Received reply for offer 201203291014-0-126
I0329 10:18:35.062526  6088 master.cpp:1403] Filtered slave 201203291014-0-1 for framework 201203291014-0-0002 for 1 seconds
I0329 10:18:35.062803  6088 master.cpp:679] Received reply for offer 201203291014-0-127
I0329 10:18:35.062963  6088 master.cpp:1403] Filtered slave 201203291014-0-0 for framework 201203291014-0-0002 for 1 seconds
I0329 10:18:36.062574  6088 master.cpp:1184] Sending 2 offers to framework 201203291014-0-0003
I0329 10:18:36.064738  6088 master.cpp:679] Received reply for offer 201203291014-0-128
I0329 10:18:36.064903  6088 master.cpp:1403] Filtered slave 201203291014-0-1 for framework 201203291014-0-0003 for 1 seconds
I0329 10:18:36.065223  6088 master.cpp:679] Received reply for offer 201203291014-0-129
I0329 10:18:36.065382  6088 master.cpp:1403] Filtered slave 201203291014-0-0 for framework 201203291014-0-0003 for 1 seconds
I0329 10:18:37.064168  6088 master.cpp:1184] Sending 2 offers to framework 201203291014-0-0002
I0329 10:18:37.066133  6088 master.cpp:679] Received reply for offer 201203291014-0-130
I0329 10:18:37.066282  6088 master.cpp:1403] Filtered slave 201203291014-0-1 for framework 201203291014-0-0002 for 1 seconds
I0329 10:18:37.066583  6088 master.cpp:679] Received reply for offer 201203291014-0-131
I0329 10:18:37.066741  6088 master.cpp:1403] Filtered slave 201203291014-0-0 for framework 201203291014-0-0002 for 1 seconds
I0329 10:18:38.066581  6088 master.cpp:1184] Sending 2 offers to framework 201203291014-0-0003
I0329 10:18:38.068598  6088 master.cpp:679] Received reply for offer 201203291014-0-132
I0329 10:18:38.068747  6088 master.cpp:1403] Filtered slave 201203291014-0-1 for framework 201203291014-0-0003 for 1 seconds
I0329 10:18:38.069054  6088 master.cpp:679] Received reply for offer 201203291014-0-133
I0329 10:18:38.069210  6088 master.cpp:1403] Filtered slave 201203291014-0-0 for framework 201203291014-0-0003 for 1 seconds
I0329 10:18:39.067848  6088 master.cpp:1184] Sending 2 offers to framework 201203291014-0-0002
I0329 10:18:39.069628  6088 master.cpp:679] Received reply for offer 201203291014-0-134
I0329 10:18:39.069728  6088 master.cpp:1403] Filtered slave 201203291014-0-1 for framework 201203291014-0-0002 for 1 seconds
I0329 10:18:39.091114  6088 master.cpp:679] Received reply for offer 201203291014-0-135
I0329 10:18:39.120918  6088 master.cpp:1403] Filtered slave 201203291014-0-0 for framework 201203291014-0-0002 for 1 seconds
I0329 10:18:40.069933  6088 master.cpp:1184] Sending 2 offers to framework 201203291014-0-0003
I0329 10:18:40.071777  6088 master.cpp:679] Received reply for offer 201203291014-0-136
I0329 10:18:40.071931  6088 master.cpp:1403] Filtered slave 201203291014-0-1 for framework 201203291014-0-0003 for 1 seconds
I0329 10:18:40.072262  6088 master.cpp:679] Received reply for offer 201203291014-0-137
I0329 10:18:40.072420  6088 master.cpp:1403] Filtered slave 201203291014-0-0 for framework 201203291014-0-0003 for 1 seconds
I0329 10:18:41.071377  6088 master.cpp:1184] Sending 2 offers to framework 201203291014-0-0002
I0329 10:18:41.073127  6088 master.cpp:679] Received reply for offer 201203291014-0-138
I0329 10:18:41.073281  6088 master.cpp:1403] Filtered slave 201203291014-0-1 for framework 201203291014-0-0002 for 1 seconds
I0329 10:18:41.073612  6088 master.cpp:679] Received reply for offer 201203291014-0-139
I0329 10:18:41.074079  6088 master.cpp:1403] Filtered slave 201203291014-0-0 for framework 201203291014-0-0002 for 1 seconds
I0329 10:18:42.073386  6088 master.cpp:1184] Sending 2 offers to framework 201203291014-0-0003
I0329 10:18:42.075235  6088 master.cpp:679] Received reply for offer 201203291014-0-140
I0329 10:18:42.075387  6088 master.cpp:1403] Filtered slave 201203291014-0-1 for framework 201203291014-0-0003 for 1 seconds
I0329 10:18:42.075675  6088 master.cpp:679] Received reply for offer 201203291014-0-141
I0329 10:18:42.075916  6088 master.cpp:1403] Filtered slave 201203291014-0-0 for framework 201203291014-0-0003 for 1 seconds
I0329 10:18:43.075510  6088 master.cpp:1184] Sending 2 offers to framework 201203291014-0-0002
I0329 10:18:43.077307  6088 master.cpp:679] Received reply for offer 201203291014-0-142
I0329 10:18:43.077461  6088 master.cpp:1403] Filtered slave 201203291014-0-1 for framework 201203291014-0-0002 for 1 seconds
I0329 10:18:43.077747  6088 master.cpp:679] Received reply for offer 201203291014-0-143
I0329 10:18:43.077999  6088 master.cpp:1403] Filtered slave 201203291014-0-0 for framework 201203291014-0-0002 for 1 seconds
I0329 10:18:44.077580  6088 master.cpp:1184] Sending 2 offers to framework 201203291014-0-0003
I0329 10:18:44.079548  6088 master.cpp:679] Received reply for offer 201203291014-0-144
I0329 10:18:44.079644  6088 master.cpp:1403] Filtered slave 201203291014-0-1 for framework 201203291014-0-0003 for 1 seconds
I0329 10:18:44.102974  6088 master.cpp:679] Received reply for offer 201203291014-0-145
I0329 10:18:44.140868  6088 master.cpp:1403] Filtered slave 201203291014-0-0 for framework 201203291014-0-0003 for 1 seconds
I0329 10:18:45.079803  6088 master.cpp:1184] Sending 2 offers to framework 201203291014-0-0002
I0329 10:18:45.081526  6088 master.cpp:679] Received reply for offer 201203291014-0-146
I0329 10:18:45.081681  6088 master.cpp:1403] Filtered slave 201203291014-0-1 for framework 201203291014-0-0002 for 1 seconds
I0329 10:18:45.081960  6088 master.cpp:679] Received reply for offer 201203291014-0-147
I0329 10:18:45.082134  6088 master.cpp:1403] Filtered slave 201203291014-0-0 for framework 201203291014-0-0002 for 1 seconds
I0329 10:18:46.081112  6088 master.cpp:1184] Sending 2 offers to framework 201203291014-0-0003
I0329 10:18:46.082988  6088 master.cpp:679] Received reply for offer 201203291014-0-148
I0329 10:18:46.083150  6088 master.cpp:1403] Filtered slave 201203291014-0-1 for framework 201203291014-0-0003 for 1 seconds
I0329 10:18:46.083492  6088 master.cpp:679] Received reply for offer 201203291014-0-149
I0329 10:18:46.083688  6088 master.cpp:1403] Filtered slave 201203291014-0-0 for framework 201203291014-0-0003 for 1 seconds
I0329 10:18:47.083238  6088 master.cpp:1184] Sending 2 offers to framework 201203291014-0-0002
I0329 10:18:47.084826  6088 master.cpp:679] Received reply for offer 201203291014-0-150
I0329 10:18:47.084947  6088 master.cpp:1403] Filtered slave 201203291014-0-1 for framework 201203291014-0-0002 for 1 seconds
I0329 10:18:47.085218  6088 master.cpp:679] Received reply for offer 201203291014-0-151
I0329 10:18:47.085350  6088 master.cpp:1403] Filtered slave 201203291014-0-0 for framework 201203291014-0-0002 for 1 seconds
I0329 10:18:48.085146  6088 master.cpp:1184] Sending 2 offers to framework 201203291014-0-0003
I0329 10:18:48.086959  6088 master.cpp:679] Received reply for offer 201203291014-0-152
I0329 10:18:48.087123  6088 master.cpp:1403] Filtered slave 201203291014-0-1 for framework 201203291014-0-0003 for 1 seconds
I0329 10:18:48.087388  6088 master.cpp:679] Received reply for offer 201203291014-0-153
I0329 10:18:48.087546  6088 master.cpp:1403] Filtered slave 201203291014-0-0 for framework 201203291014-0-0003 for 1 seconds
I0329 10:18:49.087252  6088 master.cpp:1184] Sending 2 offers to framework 201203291014-0-0002
I0329 10:18:49.089126  6088 master.cpp:679] Received reply for offer 201203291014-0-154
I0329 10:18:49.089253  6088 master.cpp:1403] Filtered slave 201203291014-0-1 for framework 201203291014-0-0002 for 1 seconds
I0329 10:18:49.114801  6088 master.cpp:679] Received reply for offer 201203291014-0-155
I0329 10:18:49.144150  6088 master.cpp:1403] Filtered slave 201203291014-0-0 for framework 201203291014-0-0002 for 1 seconds
I0329 10:18:50.089412  6088 master.cpp:1184] Sending 2 offers to framework 201203291014-0-0003
I0329 10:18:50.091300  6088 master.cpp:679] Received reply for offer 201203291014-0-156
I0329 10:18:50.091455  6088 master.cpp:1403] Filtered slave 201203291014-0-1 for framework 201203291014-0-0003 for 1 seconds
I0329 10:18:50.091827  6088 master.cpp:679] Received reply for offer 201203291014-0-157
I0329 10:18:50.092023  6088 master.cpp:1403] Filtered slave 201203291014-0-0 for framework 201203291014-0-0003 for 1 seconds
I0329 10:18:51.091413  6088 master.cpp:1184] Sending 2 offers to framework 201203291014-0-0002
I0329 10:18:51.093214  6088 master.cpp:679] Received reply for offer 201203291014-0-158
I0329 10:18:51.093368  6088 master.cpp:1403] Filtered slave 201203291014-0-1 for framework 201203291014-0-0002 for 1 seconds
I0329 10:18:51.093765  6088 master.cpp:679] Received reply for offer 201203291014-0-159
I0329 10:18:51.093976  6088 master.cpp:1403] Filtered slave 201203291014-0-0 for framework 201203291014-0-0002 for 1 seconds
I0329 10:18:52.092370  6088 master.cpp:1184] Sending 2 offers to framework 201203291014-0-0003
I0329 10:18:52.094332  6088 master.cpp:679] Received reply for offer 201203291014-0-160
I0329 10:18:52.094483  6088 master.cpp:1403] Filtered slave 201203291014-0-1 for framework 201203291014-0-0003 for 1 seconds
I0329 10:18:52.094960  6088 master.cpp:679] Received reply for offer 201203291014-0-161
I0329 10:18:52.095289  6088 master.cpp:1403] Filtered slave 201203291014-0-0 for framework 201203291014-0-0003 for 1 seconds
I0329 10:18:53.094612  6088 master.cpp:1184] Sending 2 offers to framework 201203291014-0-0002
I0329 10:18:53.096439  6088 master.cpp:679] Received reply for offer 201203291014-0-162
I0329 10:18:53.096592  6088 master.cpp:1403] Filtered slave 201203291014-0-1 for framework 201203291014-0-0002 for 1 seconds
I0329 10:18:53.096874  6088 master.cpp:679] Received reply for offer 201203291014-0-163
I0329 10:18:53.097115  6088 master.cpp:1403] Filtered slave 201203291014-0-0 for framework 201203291014-0-0002 for 1 seconds
I0329 10:18:54.095721  6088 master.cpp:1184] Sending 2 offers to framework 201203291014-0-0003
I0329 10:18:54.097755  6088 master.cpp:679] Received reply for offer 201203291014-0-164
I0329 10:18:54.097869  6088 master.cpp:1403] Filtered slave 201203291014-0-1 for framework 201203291014-0-0003 for 1 seconds
I0329 10:18:54.126971  6088 master.cpp:679] Received reply for offer 201203291014-0-165
I0329 10:18:54.155848  6088 master.cpp:1403] Filtered slave 201203291014-0-0 for framework 201203291014-0-0003 for 1 seconds
I0329 10:18:55.098073  6088 master.cpp:1184] Sending 2 offers to framework 201203291014-0-0002
I0329 10:18:55.099931  6088 master.cpp:679] Received reply for offer 201203291014-0-166
I0329 10:18:55.100096  6088 master.cpp:1403] Filtered slave 201203291014-0-1 for framework 201203291014-0-0002 for 1 seconds
I0329 10:18:55.100371  6088 master.cpp:679] Received reply for offer 201203291014-0-167
I0329 10:18:55.100610  6088 master.cpp:1403] Filtered slave 201203291014-0-0 for framework 201203291014-0-0002 for 1 seconds
I0329 10:18:56.100251  6088 master.cpp:1184] Sending 2 offers to framework 201203291014-0-0003
I0329 10:18:56.102257  6088 master.cpp:679] Received reply for offer 201203291014-0-168
I0329 10:18:56.102404  6088 master.cpp:1403] Filtered slave 201203291014-0-1 for framework 201203291014-0-0003 for 1 seconds
I0329 10:18:56.102705  6088 master.cpp:679] Received reply for offer 201203291014-0-169
I0329 10:18:56.102859  6088 master.cpp:1403] Filtered slave 201203291014-0-0 for framework 201203291014-0-0003 for 1 seconds
I0329 10:18:57.102521  6088 master.cpp:1184] Sending 2 offers to framework 201203291014-0-0002
I0329 10:18:57.104272  6088 master.cpp:679] Received reply for offer 201203291014-0-170
I0329 10:18:57.104454  6088 master.cpp:1403] Filtered slave 201203291014-0-1 for framework 201203291014-0-0002 for 1 seconds
I0329 10:18:57.104727  6088 master.cpp:679] Received reply for offer 201203291014-0-171
I0329 10:18:57.105257  6088 master.cpp:1403] Filtered slave 201203291014-0-0 for framework 201203291014-0-0002 for 1 seconds
I0329 10:18:58.104533  6088 master.cpp:1184] Sending 2 offers to framework 201203291014-0-0003
I0329 10:18:58.106407  6088 master.cpp:679] Received reply for offer 201203291014-0-172
I0329 10:18:58.106559  6088 master.cpp:1403] Filtered slave 201203291014-0-1 for framework 201203291014-0-0003 for 1 seconds
I0329 10:18:58.106835  6088 master.cpp:679] Received reply for offer 201203291014-0-173
I0329 10:18:58.107110  6088 master.cpp:1403] Filtered slave 201203291014-0-0 for framework 201203291014-0-0003 for 1 seconds
I0329 10:18:59.106716  6088 master.cpp:1184] Sending 2 offers to framework 201203291014-0-0002
I0329 10:18:59.108566  6088 master.cpp:679] Received reply for offer 201203291014-0-174
I0329 10:18:59.108664  6088 master.cpp:1403] Filtered slave 201203291014-0-1 for framework 201203291014-0-0002 for 1 seconds
I0329 10:18:59.138865  6088 master.cpp:679] Received reply for offer 201203291014-0-175
I0329 10:18:59.167611  6088 master.cpp:1403] Filtered slave 201203291014-0-0 for framework 201203291014-0-0002 for 1 seconds
I0329 10:19:00.108842  6088 master.cpp:1184] Sending 2 offers to framework 201203291014-0-0003
I0329 10:19:00.110677  6088 master.cpp:679] Received reply for offer 201203291014-0-176
I0329 10:19:00.110828  6088 master.cpp:1403] Filtered slave 201203291014-0-1 for framework 201203291014-0-0003 for 1 seconds
I0329 10:19:00.111124  6088 master.cpp:679] Received reply for offer 201203291014-0-177
I0329 10:19:00.111374  6088 master.cpp:1403] Filtered slave 201203291014-0-0 for framework 201203291014-0-0003 for 1 seconds
I0329 10:19:01.110950  6088 master.cpp:1184] Sending 2 offers to framework 201203291014-0-0002
I0329 10:19:01.112720  6088 master.cpp:679] Received reply for offer 201203291014-0-178
I0329 10:19:01.112874  6088 master.cpp:1403] Filtered slave 201203291014-0-1 for framework 201203291014-0-0002 for 1 seconds
I0329 10:19:01.113198  6088 master.cpp:679] Received reply for offer 201203291014-0-179
I0329 10:19:01.113371  6088 master.cpp:1403] Filtered slave 201203291014-0-0 for framework 201203291014-0-0002 for 1 seconds
I0329 10:19:02.112994  6088 master.cpp:1184] Sending 2 offers to framework 201203291014-0-0003
I0329 10:19:02.114760  6088 master.cpp:679] Received reply for offer 201203291014-0-180
I0329 10:19:02.114913  6088 master.cpp:1403] Filtered slave 201203291014-0-1 for framework 201203291014-0-0003 for 1 seconds
I0329 10:19:02.115231  6088 master.cpp:679] Received reply for offer 201203291014-0-181
I0329 10:19:02.115473  6088 master.cpp:1403] Filtered slave 201203291014-0-0 for framework 201203291014-0-0003 for 1 seconds
I0329 10:19:03.115033  6088 master.cpp:1184] Sending 2 offers to framework 201203291014-0-0002
I0329 10:19:03.116847  6088 master.cpp:679] Received reply for offer 201203291014-0-182
I0329 10:19:03.117007  6088 master.cpp:1403] Filtered slave 201203291014-0-1 for framework 201203291014-0-0002 for 1 seconds
I0329 10:19:03.117270  6088 master.cpp:679] Received reply for offer 201203291014-0-183
I0329 10:19:03.117455  6088 master.cpp:1403] Filtered slave 201203291014-0-0 for framework 201203291014-0-0002 for 1 seconds
I0329 10:19:04.117099  6088 master.cpp:1184] Sending 2 offers to framework 201203291014-0-0003
I0329 10:19:04.118968  6088 master.cpp:679] Received reply for offer 201203291014-0-184
I0329 10:19:04.119120  6088 master.cpp:1403] Filtered slave 201203291014-0-1 for framework 201203291014-0-0003 for 1 seconds
I0329 10:19:04.142278  6088 master.cpp:679] Received reply for offer 201203291014-0-185
I0329 10:19:04.170907  6088 master.cpp:1403] Filtered slave 201203291014-0-0 for framework 201203291014-0-0003 for 1 seconds
I0329 10:19:05.119261  6088 master.cpp:1184] Sending 2 offers to framework 201203291014-0-0002
I0329 10:19:05.121101  6088 master.cpp:679] Received reply for offer 201203291014-0-186
I0329 10:19:05.121292  6088 master.cpp:1403] Filtered slave 201203291014-0-1 for framework 201203291014-0-0002 for 1 seconds
I0329 10:19:05.121525  6088 master.cpp:679] Received reply for offer 201203291014-0-187
I0329 10:19:05.121794  6088 master.cpp:1403] Filtered slave 201203291014-0-0 for framework 201203291014-0-0002 for 1 seconds
I0329 10:19:06.121381  6088 master.cpp:1184] Sending 2 offers to framework 201203291014-0-0003
I0329 10:19:06.123198  6088 master.cpp:679] Received reply for offer 201203291014-0-188
I0329 10:19:06.123352  6088 master.cpp:1403] Filtered slave 201203291014-0-1 for framework 201203291014-0-0003 for 1 seconds
I0329 10:19:06.123741  6088 master.cpp:679] Received reply for offer 201203291014-0-189
I0329 10:19:06.123951  6088 master.cpp:1403] Filtered slave 201203291014-0-0 for framework 201203291014-0-0003 for 1 seconds
I0329 10:19:07.123229  6088 master.cpp:1184] Sending 2 offers to framework 201203291014-0-0002
I0329 10:19:07.124991  6088 master.cpp:679] Received reply for offer 201203291014-0-190
I0329 10:19:07.125136  6088 master.cpp:1403] Filtered slave 201203291014-0-1 for framework 201203291014-0-0002 for 1 seconds
I0329 10:19:07.125412  6088 master.cpp:679] Received reply for offer 201203291014-0-191
I0329 10:19:07.125592  6088 master.cpp:1403] Filtered slave 201203291014-0-0 for framework 201203291014-0-0002 for 1 seconds
I0329 10:19:08.125201  6088 master.cpp:1184] Sending 2 offers to framework 201203291014-0-0003
I0329 10:19:08.126943  6088 master.cpp:679] Received reply for offer 201203291014-0-192
I0329 10:19:08.127120  6088 master.cpp:1403] Filtered slave 201203291014-0-1 for framework 201203291014-0-0003 for 1 seconds
I0329 10:19:08.127363  6088 master.cpp:679] Received reply for offer 201203291014-0-193
I0329 10:19:08.127538  6088 master.cpp:1403] Filtered slave 201203291014-0-0 for framework 201203291014-0-0003 for 1 seconds
I0329 10:19:09.126194  6088 master.cpp:1184] Sending 2 offers to framework 201203291014-0-0002
I0329 10:19:09.128068  6088 master.cpp:679] Received reply for offer 201203291014-0-194
I0329 10:19:09.128221  6088 master.cpp:1403] Filtered slave 201203291014-0-1 for framework 201203291014-0-0002 for 1 seconds
I0329 10:19:09.154181  6088 master.cpp:679] Received reply for offer 201203291014-0-195
I0329 10:19:09.182528  6088 master.cpp:1403] Filtered slave 201203291014-0-0 for framework 201203291014-0-0002 for 1 seconds
I0329 10:19:10.128334  6088 master.cpp:1184] Sending 2 offers to framework 201203291014-0-0003
I0329 10:19:10.130128  6088 master.cpp:679] Received reply for offer 201203291014-0-196
I0329 10:19:10.130280  6088 master.cpp:1403] Filtered slave 201203291014-0-1 for framework 201203291014-0-0003 for 1 seconds
I0329 10:19:10.130566  6088 master.cpp:679] Received reply for offer 201203291014-0-197
I0329 10:19:10.130743  6088 master.cpp:1403] Filtered slave 201203291014-0-0 for framework 201203291014-0-0003 for 1 seconds
I0329 10:19:11.130398  6088 master.cpp:1184] Sending 2 offers to framework 201203291014-0-0002
I0329 10:19:11.132413  6088 master.cpp:679] Received reply for offer 201203291014-0-198
I0329 10:19:11.132566  6088 master.cpp:1403] Filtered slave 201203291014-0-1 for framework 201203291014-0-0002 for 1 seconds
I0329 10:19:11.132833  6088 master.cpp:679] Received reply for offer 201203291014-0-199
I0329 10:19:11.133012  6088 master.cpp:1403] Filtered slave 201203291014-0-0 for framework 201203291014-0-0002 for 1 seconds
I0329 10:19:12.132666  6088 master.cpp:1184] Sending 2 offers to framework 201203291014-0-0003
I0329 10:19:12.134488  6088 master.cpp:679] Received reply for offer 201203291014-0-200
I0329 10:19:12.134634  6088 master.cpp:1403] Filtered slave 201203291014-0-1 for framework 201203291014-0-0003 for 1 seconds
I0329 10:19:12.135006  6088 master.cpp:679] Received reply for offer 201203291014-0-201
I0329 10:19:12.135181  6088 master.cpp:1403] Filtered slave 201203291014-0-0 for framework 201203291014-0-0003 for 1 seconds
I0329 10:19:13.134660  6088 master.cpp:1184] Sending 2 offers to framework 201203291014-0-0002
I0329 10:19:13.136472  6088 master.cpp:679] Received reply for offer 201203291014-0-202
I0329 10:19:13.136626  6088 master.cpp:1403] Filtered slave 201203291014-0-1 for framework 201203291014-0-0002 for 1 seconds
I0329 10:19:13.136916  6088 master.cpp:679] Received reply for offer 201203291014-0-203
I0329 10:19:13.137075  6088 master.cpp:1403] Filtered slave 201203291014-0-0 for framework 201203291014-0-0002 for 1 seconds
I0329 10:19:14.136731  6088 master.cpp:1184] Sending 2 offers to framework 201203291014-0-0003
I0329 10:19:14.138450  6088 master.cpp:679] Received reply for offer 201203291014-0-204
I0329 10:19:14.157624  6088 master.cpp:1403] Filtered slave 201203291014-0-1 for framework 201203291014-0-0003 for 1 seconds
I0329 10:19:14.185817  6088 master.cpp:679] Received reply for offer 201203291014-0-205
I0329 10:19:14.186105  6088 master.cpp:1403] Filtered slave 201203291014-0-0 for framework 201203291014-0-0003 for 1 seconds
I0329 10:19:15.138775  6088 master.cpp:1184] Sending 2 offers to framework 201203291014-0-0002
I0329 10:19:15.140555  6088 master.cpp:679] Received reply for offer 201203291014-0-206
I0329 10:19:15.140746  6088 master.cpp:1403] Filtered slave 201203291014-0-1 for framework 201203291014-0-0002 for 1 seconds
I0329 10:19:15.140979  6088 master.cpp:679] Received reply for offer 201203291014-0-207
I0329 10:19:15.141161  6088 master.cpp:1403] Filtered slave 201203291014-0-0 for framework 201203291014-0-0002 for 1 seconds
I0329 10:19:16.139814  6088 master.cpp:1184] Sending 2 offers to framework 201203291014-0-0003
I0329 10:19:16.141645  6088 master.cpp:679] Received reply for offer 201203291014-0-208
I0329 10:19:16.141798  6088 master.cpp:1403] Filtered slave 201203291014-0-1 for framework 201203291014-0-0003 for 1 seconds
I0329 10:19:16.142067  6088 master.cpp:679] Received reply for offer 201203291014-0-209
I0329 10:19:16.142232  6088 master.cpp:1403] Filtered slave 201203291014-0-0 for framework 201203291014-0-0003 for 1 seconds
I0329 10:19:17.141942  6088 master.cpp:1184] Sending 2 offers to framework 201203291014-0-0002
I0329 10:19:17.143785  6088 master.cpp:679] Received reply for offer 201203291014-0-210
I0329 10:19:17.143939  6088 master.cpp:1403] Filtered slave 201203291014-0-1 for framework 201203291014-0-0002 for 1 seconds
I0329 10:19:17.144243  6088 master.cpp:679] Received reply for offer 201203291014-0-211
I0329 10:19:17.144423  6088 master.cpp:1403] Filtered slave 201203291014-0-0 for framework 201203291014-0-0002 for 1 seconds
I0329 10:19:18.143997  6088 master.cpp:1184] Sending 2 offers to framework 201203291014-0-0003
I0329 10:19:18.145880  6088 master.cpp:679] Received reply for offer 201203291014-0-212
I0329 10:19:18.146034  6088 master.cpp:1403] Filtered slave 201203291014-0-1 for framework 201203291014-0-0003 for 1 seconds
I0329 10:19:18.146301  6088 master.cpp:679] Received reply for offer 201203291014-0-213
I0329 10:19:18.146479  6088 master.cpp:1403] Filtered slave 201203291014-0-0 for framework 201203291014-0-0003 for 1 seconds
I0329 10:19:19.146178  6088 master.cpp:1184] Sending 2 offers to framework 201203291014-0-0002
I0329 10:19:19.148001  6088 master.cpp:679] Received reply for offer 201203291014-0-214
I0329 10:19:19.148154  6088 master.cpp:1403] Filtered slave 201203291014-0-1 for framework 201203291014-0-0002 for 1 seconds
I0329 10:19:19.177660  6088 master.cpp:679] Received reply for offer 201203291014-0-215
I0329 10:19:19.205801  6088 master.cpp:1403] Filtered slave 201203291014-0-0 for framework 201203291014-0-0002 for 1 seconds
I0329 10:19:20.148285  6088 master.cpp:1184] Sending 2 offers to framework 201203291014-0-0003
I0329 10:19:20.150099  6088 master.cpp:679] Received reply for offer 201203291014-0-216
I0329 10:19:20.150251  6088 master.cpp:1403] Filtered slave 201203291014-0-1 for framework 201203291014-0-0003 for 1 seconds
I0329 10:19:20.150511  6088 master.cpp:679] Received reply for offer 201203291014-0-217
I0329 10:19:20.150684  6088 master.cpp:1403] Filtered slave 201203291014-0-0 for framework 201203291014-0-0003 for 1 seconds
I0329 10:19:21.150382  6088 master.cpp:1184] Sending 2 offers to framework 201203291014-0-0002
I0329 10:19:21.152179  6088 master.cpp:679] Received reply for offer 201203291014-0-218
I0329 10:19:21.152333  6088 master.cpp:1403] Filtered slave 201203291014-0-1 for framework 201203291014-0-0002 for 1 seconds
I0329 10:19:21.152627  6088 master.cpp:679] Received reply for offer 201203291014-0-219
I0329 10:19:21.152833  6088 master.cpp:1403] Filtered slave 201203291014-0-0 for framework 201203291014-0-0002 for 1 seconds
I0329 10:19:22.152186  6088 master.cpp:1184] Sending 2 offers to framework 201203291014-0-0003
I0329 10:19:22.154006  6088 master.cpp:679] Received reply for offer 201203291014-0-220
I0329 10:19:22.154158  6088 master.cpp:1403] Filtered slave 201203291014-0-1 for framework 201203291014-0-0003 for 1 seconds
I0329 10:19:22.154428  6088 master.cpp:679] Received reply for offer 201203291014-0-221
I0329 10:19:22.154603  6088 master.cpp:1403] Filtered slave 201203291014-0-0 for framework 201203291014-0-0003 for 1 seconds
I0329 10:19:23.154275  6088 master.cpp:1184] Sending 2 offers to framework 201203291014-0-0002
I0329 10:19:23.156072  6088 master.cpp:679] Received reply for offer 201203291014-0-222
I0329 10:19:23.156227  6088 master.cpp:1403] Filtered slave 201203291014-0-1 for framework 201203291014-0-0002 for 1 seconds
I0329 10:19:23.156525  6088 master.cpp:679] Received reply for offer 201203291014-0-223
I0329 10:19:23.156697  6088 master.cpp:1403] Filtered slave 201203291014-0-0 for framework 201203291014-0-0002 for 1 seconds
I0329 10:19:24.155350  6088 master.cpp:1184] Sending 2 offers to framework 201203291014-0-0003
I0329 10:19:24.157249  6088 master.cpp:679] Received reply for offer 201203291014-0-224
I0329 10:19:24.157379  6088 master.cpp:1403] Filtered slave 201203291014-0-1 for framework 201203291014-0-0003 for 1 seconds
I0329 10:19:24.181161  6088 master.cpp:679] Received reply for offer 201203291014-0-225
I0329 10:19:24.209164  6088 master.cpp:1403] Filtered slave 201203291014-0-0 for framework 201203291014-0-0003 for 1 seconds
I0329 10:19:25.157533  6088 master.cpp:1184] Sending 2 offers to framework 201203291014-0-0002
I0329 10:19:25.159374  6088 master.cpp:679] Received reply for offer 201203291014-0-226
I0329 10:19:25.159528  6088 master.cpp:1403] Filtered slave 201203291014-0-1 for framework 201203291014-0-0002 for 1 seconds
I0329 10:19:25.159864  6088 master.cpp:679] Received reply for offer 201203291014-0-227
I0329 10:19:25.160070  6088 master.cpp:1403] Filtered slave 201203291014-0-0 for framework 201203291014-0-0002 for 1 seconds
I0329 10:19:26.159412  6088 master.cpp:1184] Sending 2 offers to framework 201203291014-0-0003
I0329 10:19:26.161255  6088 master.cpp:679] Received reply for offer 201203291014-0-228
I0329 10:19:26.161406  6088 master.cpp:1403] Filtered slave 201203291014-0-1 for framework 201203291014-0-0003 for 1 seconds
I0329 10:19:26.161679  6088 master.cpp:679] Received reply for offer 201203291014-0-229
I0329 10:19:26.161851  6088 master.cpp:1403] Filtered slave 201203291014-0-0 for framework 201203291014-0-0003 for 1 seconds
I0329 10:19:27.161520  6088 master.cpp:1184] Sending 2 offers to framework 201203291014-0-0002
I0329 10:19:27.163317  6088 master.cpp:679] Received reply for offer 201203291014-0-230
I0329 10:19:27.163471  6088 master.cpp:1403] Filtered slave 201203291014-0-1 for framework 201203291014-0-0002 for 1 seconds
I0329 10:19:27.163779  6088 master.cpp:679] Received reply for offer 201203291014-0-231
I0329 10:19:27.164021  6088 master.cpp:1403] Filtered slave 201203291014-0-0 for framework 201203291014-0-0002 for 1 seconds
I0329 10:19:28.163559  6088 master.cpp:1184] Sending 2 offers to framework 201203291014-0-0003
I0329 10:19:28.165456  6088 master.cpp:679] Received reply for offer 201203291014-0-232
I0329 10:19:28.165644  6088 master.cpp:1403] Filtered slave 201203291014-0-1 for framework 201203291014-0-0003 for 1 seconds
I0329 10:19:28.165884  6088 master.cpp:679] Received reply for offer 201203291014-0-233
I0329 10:19:28.166113  6088 master.cpp:1403] Filtered slave 201203291014-0-0 for framework 201203291014-0-0003 for 1 seconds
I0329 10:19:29.165376  6088 master.cpp:1184] Sending 2 offers to framework 201203291014-0-0002
I0329 10:19:29.167058  6088 master.cpp:679] Received reply for offer 201203291014-0-234
I0329 10:19:29.167225  6088 master.cpp:1403] Filtered slave 201203291014-0-1 for framework 201203291014-0-0002 for 1 seconds
I0329 10:19:29.193011  6088 master.cpp:679] Received reply for offer 201203291014-0-235
I0329 10:19:29.221004  6088 master.cpp:1403] Filtered slave 201203291014-0-0 for framework 201203291014-0-0002 for 1 seconds
I0329 10:19:30.167363  6088 master.cpp:1184] Sending 2 offers to framework 201203291014-0-0003
I0329 10:19:30.169193  6088 master.cpp:679] Received reply for offer 201203291014-0-236
I0329 10:19:30.169347  6088 master.cpp:1403] Filtered slave 201203291014-0-1 for framework 201203291014-0-0003 for 1 seconds
I0329 10:19:30.169635  6088 master.cpp:679] Received reply for offer 201203291014-0-237
I0329 10:19:30.169801  6088 master.cpp:1403] Filtered slave 201203291014-0-0 for framework 201203291014-0-0003 for 1 seconds
I0329 10:19:31.169481  6088 master.cpp:1184] Sending 2 offers to framework 201203291014-0-0002
I0329 10:19:31.171496  6088 master.cpp:679] Received reply for offer 201203291014-0-238
I0329 10:19:31.171624  6088 master.cpp:1403] Filtered slave 201203291014-0-1 for framework 201203291014-0-0002 for 1 seconds
I0329 10:19:31.171865  6088 master.cpp:679] Received reply for offer 201203291014-0-239
I0329 10:19:31.172026  6088 master.cpp:1403] Filtered slave 201203291014-0-0 for framework 201203291014-0-0002 for 1 seconds
I0329 10:19:32.171341  6088 master.cpp:1184] Sending 2 offers to framework 201203291014-0-0003
I0329 10:19:32.172832  6088 master.cpp:679] Received reply for offer 201203291014-0-240
I0329 10:19:32.172952  6088 master.cpp:1403] Filtered slave 201203291014-0-1 for framework 201203291014-0-0003 for 1 seconds
I0329 10:19:32.173198  6088 master.cpp:679] Received reply for offer 201203291014-0-241
I0329 10:19:32.173358  6088 master.cpp:1403] Filtered slave 201203291014-0-0 for framework 201203291014-0-0003 for 1 seconds
I0329 10:19:33.173032  6088 master.cpp:1184] Sending 2 offers to framework 201203291014-0-0002
I0329 10:19:33.174701  6088 master.cpp:679] Received reply for offer 201203291014-0-242
I0329 10:19:33.174867  6088 master.cpp:1403] Filtered slave 201203291014-0-1 for framework 201203291014-0-0002 for 1 seconds
I0329 10:19:33.175138  6088 master.cpp:679] Received reply for offer 201203291014-0-243
I0329 10:19:33.175283  6088 master.cpp:1403] Filtered slave 201203291014-0-0 for framework 201203291014-0-0002 for 1 seconds
I0329 10:19:34.175040  6088 master.cpp:1184] Sending 2 offers to framework 201203291014-0-0003
I0329 10:19:34.176892  6088 master.cpp:679] Received reply for offer 201203291014-0-244
I0329 10:19:34.176971  6088 master.cpp:1403] Filtered slave 201203291014-0-1 for framework 201203291014-0-0003 for 1 seconds
I0329 10:19:34.213711  6088 master.cpp:679] Received reply for offer 201203291014-0-245
I0329 10:19:34.240780  6088 master.cpp:1403] Filtered slave 201203291014-0-0 for framework 201203291014-0-0003 for 1 seconds
I0329 10:19:35.177042  6088 master.cpp:1184] Sending 2 offers to framework 201203291014-0-0002
I0329 10:19:35.178679  6088 master.cpp:679] Received reply for offer 201203291014-0-246
I0329 10:19:35.178810  6088 master.cpp:1403] Filtered slave 201203291014-0-1 for framework 201203291014-0-0002 for 1 seconds
I0329 10:19:35.179066  6088 master.cpp:679] Received reply for offer 201203291014-0-247
I0329 10:19:35.179225  6088 master.cpp:1403] Filtered slave 201203291014-0-0 for framework 201203291014-0-0002 for 1 seconds
I0329 10:19:36.178967  6088 master.cpp:1184] Sending 2 offers to framework 201203291014-0-0003
I0329 10:19:36.180620  6088 master.cpp:679] Received reply for offer 201203291014-0-248
I0329 10:19:36.180760  6088 master.cpp:1403] Filtered slave 201203291014-0-1 for framework 201203291014-0-0003 for 1 seconds
I0329 10:19:36.181025  6088 master.cpp:679] Received reply for offer 201203291014-0-249
I0329 10:19:36.181444  6088 master.cpp:1403] Filtered slave 201203291014-0-0 for framework 201203291014-0-0003 for 1 seconds
I0329 10:19:36.668352  6088 master.cpp:492] Registering framework 201203291014-0-0004 at 3@192.168.1.64:55613
I0329 10:19:36.668624  6088 simple_allocator.cpp:48] Added framework 201203291014-0-0004
I0329 10:19:36.668864  6088 master.cpp:1184] Sending 2 offers to framework 201203291014-0-0004
I0329 10:19:36.669064  6088 master.cpp:492] Registering framework 201203291014-0-0005 at 2@192.168.1.64:55613
I0329 10:19:36.669178  6088 simple_allocator.cpp:48] Added framework 201203291014-0-0005
I0329 10:19:36.685713  6088 master.cpp:679] Received reply for offer 201203291014-0-250
I0329 10:19:36.685889  6088 master.cpp:1403] Filtered slave 201203291014-0-1 for framework 201203291014-0-0004 for 1 seconds
I0329 10:19:36.685992  6088 master.cpp:679] Received reply for offer 201203291014-0-251
I0329 10:19:36.686177  6088 master.cpp:1184] Sending 1 offers to framework 201203291014-0-0005
I0329 10:19:36.686276  6088 master.cpp:1403] Filtered slave 201203291014-0-0 for framework 201203291014-0-0004 for 1 seconds
I0329 10:19:36.687085  6088 master.cpp:679] Received reply for offer 201203291014-0-252
I0329 10:19:36.687217  6088 master.cpp:1403] Filtered slave 201203291014-0-1 for framework 201203291014-0-0005 for 1 seconds
I0329 10:19:37.048183  6088 master.cpp:718] Reviving offers for framework 201203291014-0-0005
I0329 10:19:37.048317  6088 simple_allocator.cpp:145] Filters removed for framework 201203291014-0-0005
I0329 10:19:37.180661  6088 master.cpp:1184] Sending 1 offers to framework 201203291014-0-0002
I0329 10:19:37.182250  6088 master.cpp:679] Received reply for offer 201203291014-0-253
I0329 10:19:37.182410  6088 master.cpp:1403] Filtered slave 201203291014-0-1 for framework 201203291014-0-0002 for 1 seconds
I0329 10:19:38.182505  6088 master.cpp:1184] Sending 1 offers to framework 201203291014-0-0004
I0329 10:19:38.182694  6088 master.cpp:1184] Sending 1 offers to framework 201203291014-0-0005
I0329 10:19:38.184348  6088 master.cpp:679] Received reply for offer 201203291014-0-254
I0329 10:19:38.184550  6088 master.cpp:1403] Filtered slave 201203291014-0-1 for framework 201203291014-0-0004 for 1 seconds
I0329 10:19:38.300427  6088 master.cpp:679] Received reply for offer 201203291014-0-255
I0329 10:19:38.300634  6088 master.cpp:1453] Launching task 0 on slave 201203291014-0-0
I0329 10:19:38.301062  6088 master.cpp:1453] Launching task 1 on slave 201203291014-0-0
I0329 10:19:38.301308  6088 master.cpp:1453] Launching task 2 on slave 201203291014-0-0
I0329 10:19:38.301558  6088 master.cpp:1453] Launching task 3 on slave 201203291014-0-0
I0329 10:19:38.301707  6088 master.cpp:1453] Launching task 4 on slave 201203291014-0-0
I0329 10:19:38.302178  6088 master.cpp:1453] Launching task 5 on slave 201203291014-0-0
I0329 10:19:38.302577  6088 master.cpp:1453] Launching task 6 on slave 201203291014-0-0
I0329 10:19:38.303076  6088 master.cpp:1453] Launching task 7 on slave 201203291014-0-0
I0329 10:19:38.303483  6088 master.cpp:1184] Sending 1 offers to framework 201203291014-0-0003
I0329 10:19:38.304697  6088 master.cpp:679] Received reply for offer 201203291014-0-256
I0329 10:19:38.304869  6088 master.cpp:1403] Filtered slave 201203291014-0-1 for framework 201203291014-0-0003 for 1 seconds
I0329 10:19:39.183903  6088 master.cpp:1184] Sending 1 offers to framework 201203291014-0-0002
I0329 10:19:39.185161  6088 master.cpp:679] Received reply for offer 201203291014-0-257
I0329 10:19:39.185236  6088 master.cpp:1403] Filtered slave 201203291014-0-1 for framework 201203291014-0-0002 for 1 seconds
I0329 10:19:39.305649  6088 master.cpp:902] Status update from slave@192.168.1.64:57346: task 3 of framework 201203291014-0-0005 is now in state TASK_RUNNING
I0329 10:19:39.309353  6088 master.cpp:902] Status update from slave@192.168.1.64:57346: task 4 of framework 201203291014-0-0005 is now in state TASK_RUNNING
I0329 10:19:39.311715  6088 master.cpp:902] Status update from slave@192.168.1.64:57346: task 1 of framework 201203291014-0-0005 is now in state TASK_RUNNING
I0329 10:19:39.314074  6088 master.cpp:902] Status update from slave@192.168.1.64:57346: task 5 of framework 201203291014-0-0005 is now in state TASK_RUNNING
I0329 10:19:39.317445  6088 master.cpp:902] Status update from slave@192.168.1.64:57346: task 0 of framework 201203291014-0-0005 is now in state TASK_RUNNING
I0329 10:19:39.319445  6088 master.cpp:902] Status update from slave@192.168.1.64:57346: task 7 of framework 201203291014-0-0005 is now in state TASK_RUNNING
I0329 10:19:39.323047  6088 master.cpp:902] Status update from slave@192.168.1.64:57346: task 2 of framework 201203291014-0-0005 is now in state TASK_RUNNING
I0329 10:19:39.326777  6088 master.cpp:902] Status update from slave@192.168.1.64:57346: task 6 of framework 201203291014-0-0005 is now in state TASK_RUNNING
I0329 10:19:40.186003  6088 master.cpp:1184] Sending 1 offers to framework 201203291014-0-0005
I0329 10:19:40.187491  6088 master.cpp:679] Received reply for offer 201203291014-0-258
I0329 10:19:40.187648  6088 master.cpp:1403] Filtered slave 201203291014-0-1 for framework 201203291014-0-0005 for 1 seconds
I0329 10:19:40.499260  6088 master.cpp:902] Status update from slave@192.168.1.64:57346: task 7 of framework 201203291014-0-0005 is now in state TASK_FINISHED
I0329 10:19:40.499482  6088 master.cpp:1184] Sending 1 offers to framework 201203291014-0-0002
I0329 10:19:40.499646  6088 master.cpp:1184] Sending 1 offers to framework 201203291014-0-0004
I0329 10:19:40.500812  6088 master.cpp:679] Received reply for offer 201203291014-0-259
I0329 10:19:40.500968  6088 master.cpp:1403] Filtered slave 201203291014-0-0 for framework 201203291014-0-0002 for 1 seconds
I0329 10:19:40.501951  6088 master.cpp:902] Status update from slave@192.168.1.64:57346: task 1 of framework 201203291014-0-0005 is now in state TASK_FINISHED
I0329 10:19:40.502187  6088 master.cpp:1184] Sending 1 offers to framework 201203291014-0-0003
I0329 10:19:40.503149  6088 master.cpp:679] Received reply for offer 201203291014-0-261
I0329 10:19:40.503273  6088 master.cpp:1403] Filtered slave 201203291014-0-0 for framework 201203291014-0-0003 for 1 seconds
I0329 10:19:40.504813  6088 master.cpp:902] Status update from slave@192.168.1.64:57346: task 4 of framework 201203291014-0-0005 is now in state TASK_FINISHED
I0329 10:19:40.505025  6088 master.cpp:1184] Sending 1 offers to framework 201203291014-0-0005
I0329 10:19:40.507457  6088 master.cpp:902] Status update from slave@192.168.1.64:57346: task 3 of framework 201203291014-0-0005 is now in state TASK_FINISHED
I0329 10:19:40.510076  6088 master.cpp:902] Status update from slave@192.168.1.64:57346: task 5 of framework 201203291014-0-0005 is now in state TASK_FINISHED
I0329 10:19:40.512778  6088 master.cpp:902] Status update from slave@192.168.1.64:57346: task 2 of framework 201203291014-0-0005 is now in state TASK_FINISHED
I0329 10:19:40.514303  6088 master.cpp:679] Received reply for offer 201203291014-0-260
I0329 10:19:40.514423  6088 master.cpp:1403] Filtered slave 201203291014-0-1 for framework 201203291014-0-0004 for 1 seconds
I0329 10:19:40.515527  6088 master.cpp:902] Status update from slave@192.168.1.64:57346: task 0 of framework 201203291014-0-0005 is now in state TASK_FINISHED
I0329 10:19:40.515769  6088 master.cpp:1184] Sending 1 offers to framework 201203291014-0-0003
I0329 10:19:40.516737  6088 master.cpp:679] Received reply for offer 201203291014-0-263
I0329 10:19:40.516865  6088 master.cpp:1403] Filtered slave 201203291014-0-1 for framework 201203291014-0-0003 for 1 seconds
I0329 10:19:40.518393  6088 master.cpp:902] Status update from slave@192.168.1.64:57346: task 6 of framework 201203291014-0-0005 is now in state TASK_FINISHED
I0329 10:19:40.530500  6088 master.cpp:679] Received reply for offer 201203291014-0-262
I0329 10:19:40.530655  6088 master.cpp:1453] Launching task 8 on slave 201203291014-0-0
I0329 10:19:40.530911  6088 master.cpp:1453] Launching task 9 on slave 201203291014-0-0
I0329 10:19:40.531548  6088 master.cpp:1453] Launching task 10 on slave 201203291014-0-0
I0329 10:19:40.535702  6088 master.cpp:902] Status update from slave@192.168.1.64:57346: task 8 of framework 201203291014-0-0005 is now in state TASK_RUNNING
I0329 10:19:40.538609  6088 master.cpp:902] Status update from slave@192.168.1.64:57346: task 9 of framework 201203291014-0-0005 is now in state TASK_RUNNING
I0329 10:19:40.541661  6088 master.cpp:902] Status update from slave@192.168.1.64:57346: task 10 of framework 201203291014-0-0005 is now in state TASK_RUNNING
I0329 10:19:40.614589  6088 master.cpp:902] Status update from slave@192.168.1.64:57346: task 9 of framework 201203291014-0-0005 is now in state TASK_FINISHED
I0329 10:19:40.614846  6088 master.cpp:1184] Sending 1 offers to framework 201203291014-0-0004
I0329 10:19:40.616601  6088 master.cpp:902] Status update from slave@192.168.1.64:57346: task 10 of framework 201203291014-0-0005 is now in state TASK_FINISHED
I0329 10:19:40.616907  6088 master.cpp:679] Received reply for offer 201203291014-0-264
I0329 10:19:40.617059  6088 master.cpp:1403] Filtered slave 201203291014-0-0 for framework 201203291014-0-0004 for 1 seconds
I0329 10:19:40.631860  6088 master.cpp:902] Status update from slave@192.168.1.64:57346: task 8 of framework 201203291014-0-0005 is now in state TASK_FINISHED
I0329 10:19:40.632171  6088 master.cpp:1184] Sending 1 offers to framework 201203291014-0-0005
I0329 10:19:40.683660  6088 master.cpp:679] Received reply for offer 201203291014-0-265
I0329 10:19:40.683809  6088 master.cpp:1453] Launching task 11 on slave 201203291014-0-0
I0329 10:19:40.684160  6088 master.cpp:1453] Launching task 12 on slave 201203291014-0-0
I0329 10:19:40.684445  6088 master.cpp:1453] Launching task 13 on slave 201203291014-0-0
I0329 10:19:40.684540  6088 master.cpp:1453] Launching task 14 on slave 201203291014-0-0
I0329 10:19:40.685124  6088 master.cpp:1453] Launching task 15 on slave 201203291014-0-0
I0329 10:19:40.685549  6088 master.cpp:1453] Launching task 16 on slave 201203291014-0-0
I0329 10:19:40.686000  6088 master.cpp:1453] Launching task 17 on slave 201203291014-0-0
I0329 10:19:40.686467  6088 master.cpp:1453] Launching task 18 on slave 201203291014-0-0
I0329 10:19:40.688635  6088 master.cpp:902] Status update from slave@192.168.1.64:57346: task 11 of framework 201203291014-0-0005 is now in state TASK_RUNNING
I0329 10:19:40.691637  6088 master.cpp:902] Status update from slave@192.168.1.64:57346: task 12 of framework 201203291014-0-0005 is now in state TASK_RUNNING
I0329 10:19:40.695515  6088 master.cpp:902] Status update from slave@192.168.1.64:57346: task 13 of framework 201203291014-0-0005 is now in state TASK_RUNNING
I0329 10:19:40.705211  6088 master.cpp:902] Status update from slave@192.168.1.64:57346: task 14 of framework 201203291014-0-0005 is now in state TASK_RUNNING
I0329 10:19:40.708530  6088 master.cpp:902] Status update from slave@192.168.1.64:57346: task 15 of framework 201203291014-0-0005 is now in state TASK_RUNNING
I0329 10:19:40.712014  6088 master.cpp:902] Status update from slave@192.168.1.64:57346: task 16 of framework 201203291014-0-0005 is now in state TASK_RUNNING
I0329 10:19:40.715095  6088 master.cpp:902] Status update from slave@192.168.1.64:57346: task 17 of framework 201203291014-0-0005 is now in state TASK_RUNNING
I0329 10:19:40.718001  6088 master.cpp:902] Status update from slave@192.168.1.64:57346: task 18 of framework 201203291014-0-0005 is now in state TASK_RUNNING
I0329 10:19:40.808496  6088 master.cpp:902] Status update from slave@192.168.1.64:57346: task 14 of framework 201203291014-0-0005 is now in state TASK_FINISHED
I0329 10:19:40.808783  6088 master.cpp:1184] Sending 1 offers to framework 201203291014-0-0005
I0329 10:19:40.829256  6088 master.cpp:902] Status update from slave@192.168.1.64:57346: task 13 of framework 201203291014-0-0005 is now in state TASK_FINISHED
I0329 10:19:40.834593  6088 master.cpp:902] Status update from slave@192.168.1.64:57346: task 11 of framework 201203291014-0-0005 is now in state TASK_FINISHED
I0329 10:19:40.837360  6088 master.cpp:902] Status update from slave@192.168.1.64:57346: task 17 of framework 201203291014-0-0005 is now in state TASK_FINISHED
I0329 10:19:40.843699  6088 master.cpp:902] Status update from slave@192.168.1.64:57346: task 15 of framework 201203291014-0-0005 is now in state TASK_FINISHED
I0329 10:19:40.845753  6088 master.cpp:902] Status update from slave@192.168.1.64:57346: task 16 of framework 201203291014-0-0005 is now in state TASK_FINISHED
I0329 10:19:40.847901  6088 master.cpp:902] Status update from slave@192.168.1.64:57346: task 18 of framework 201203291014-0-0005 is now in state TASK_FINISHED
I0329 10:19:40.850116  6088 master.cpp:902] Status update from slave@192.168.1.64:57346: task 12 of framework 201203291014-0-0005 is now in state TASK_FINISHED
I0329 10:19:40.855377  6088 master.cpp:679] Received reply for offer 201203291014-0-266
I0329 10:19:40.855509  6088 master.cpp:1453] Launching task 19 on slave 201203291014-0-0
I0329 10:19:40.861734  6088 master.cpp:902] Status update from slave@192.168.1.64:57346: task 19 of framework 201203291014-0-0005 is now in state TASK_RUNNING
I0329 10:19:40.985380  6088 master.cpp:902] Status update from slave@192.168.1.64:57346: task 19 of framework 201203291014-0-0005 is now in state TASK_FINISHED
I0329 10:19:40.985654  6088 master.cpp:1184] Sending 1 offers to framework 201203291014-0-0005
I0329 10:19:41.016324  6088 master.cpp:679] Received reply for offer 201203291014-0-267
I0329 10:19:41.016536  6088 master.cpp:1453] Launching task 20 on slave 201203291014-0-0
I0329 10:19:41.016871  6088 master.cpp:1453] Launching task 21 on slave 201203291014-0-0
I0329 10:19:41.017135  6088 master.cpp:1453] Launching task 22 on slave 201203291014-0-0
I0329 10:19:41.017235  6088 master.cpp:1453] Launching task 23 on slave 201203291014-0-0
I0329 10:19:41.017767  6088 master.cpp:1453] Launching task 24 on slave 201203291014-0-0
I0329 10:19:41.018223  6088 master.cpp:1453] Launching task 25 on slave 201203291014-0-0
I0329 10:19:41.018688  6088 master.cpp:1453] Launching task 26 on slave 201203291014-0-0
I0329 10:19:41.019141  6088 master.cpp:1453] Launching task 27 on slave 201203291014-0-0
I0329 10:19:41.021486  6088 master.cpp:902] Status update from slave@192.168.1.64:57346: task 20 of framework 201203291014-0-0005 is now in state TASK_RUNNING
I0329 10:19:41.024222  6088 master.cpp:902] Status update from slave@192.168.1.64:57346: task 21 of framework 201203291014-0-0005 is now in state TASK_RUNNING
I0329 10:19:41.028136  6088 master.cpp:902] Status update from slave@192.168.1.64:57346: task 22 of framework 201203291014-0-0005 is now in state TASK_RUNNING
I0329 10:19:41.030879  6088 master.cpp:902] Status update from slave@192.168.1.64:57346: task 24 of framework 201203291014-0-0005 is now in state TASK_RUNNING
I0329 10:19:41.033190  6088 master.cpp:902] Status update from slave@192.168.1.64:57346: task 23 of framework 201203291014-0-0005 is now in state TASK_RUNNING
I0329 10:19:41.035979  6088 master.cpp:902] Status update from slave@192.168.1.64:57346: task 26 of framework 201203291014-0-0005 is now in state TASK_RUNNING
I0329 10:19:41.038717  6088 master.cpp:902] Status update from slave@192.168.1.64:57346: task 25 of framework 201203291014-0-0005 is now in state TASK_RUNNING
I0329 10:19:41.041406  6088 master.cpp:902] Status update from slave@192.168.1.64:57346: task 27 of framework 201203291014-0-0005 is now in state TASK_RUNNING
I0329 10:19:41.143827  6088 master.cpp:902] Status update from slave@192.168.1.64:57346: task 22 of framework 201203291014-0-0005 is now in state TASK_FINISHED
I0329 10:19:41.144115  6088 master.cpp:1184] Sending 1 offers to framework 201203291014-0-0005
I0329 10:19:41.148386  6088 master.cpp:902] Status update from slave@192.168.1.64:57346: task 25 of framework 201203291014-0-0005 is now in state TASK_FINISHED
I0329 10:19:41.150974  6088 master.cpp:679] Received reply for offer 201203291014-0-268
I0329 10:19:41.151209  6088 master.cpp:1453] Launching task 28 on slave 201203291014-0-0
I0329 10:19:41.163208  6088 master.cpp:902] Status update from slave@192.168.1.64:57346: task 28 of framework 201203291014-0-0005 is now in state TASK_RUNNING
I0329 10:19:41.179903  6088 master.cpp:902] Status update from slave@192.168.1.64:57346: task 24 of framework 201203291014-0-0005 is now in state TASK_FINISHED
I0329 10:19:41.180213  6088 master.cpp:1184] Sending 1 offers to framework 201203291014-0-0005
I0329 10:19:41.186594  6088 master.cpp:1184] Sending 1 offers to framework 201203291014-0-0002
I0329 10:19:41.192816  6088 master.cpp:679] Received reply for offer 201203291014-0-270
I0329 10:19:41.192987  6088 master.cpp:1403] Filtered slave 201203291014-0-1 for framework 201203291014-0-0002 for 1 seconds
I0329 10:19:41.193510  6088 master.cpp:902] Status update from slave@192.168.1.64:57346: task 26 of framework 201203291014-0-0005 is now in state TASK_FINISHED
I0329 10:19:41.194190  6088 master.cpp:679] Received reply for offer 201203291014-0-269
I0329 10:19:41.194250  6088 master.cpp:1453] Launching task 29 on slave 201203291014-0-0
I0329 10:19:41.194999  6088 master.cpp:1453] Launching task 30 on slave 201203291014-0-0
I0329 10:19:41.197964  6088 master.cpp:902] Status update from slave@192.168.1.64:57346: task 20 of framework 201203291014-0-0005 is now in state TASK_FINISHED
I0329 10:19:41.198254  6088 master.cpp:1184] Sending 1 offers to framework 201203291014-0-0005
I0329 10:19:41.199381  6088 master.cpp:902] Status update from slave@192.168.1.64:57346: task 23 of framework 201203291014-0-0005 is now in state TASK_FINISHED
I0329 10:19:41.201640  6088 master.cpp:902] Status update from slave@192.168.1.64:57346: task 21 of framework 201203291014-0-0005 is now in state TASK_FINISHED
I0329 10:19:41.205790  6088 master.cpp:902] Status update from slave@192.168.1.64:57346: task 27 of framework 201203291014-0-0005 is now in state TASK_FINISHED
I0329 10:19:41.206047  6088 master.cpp:902] Status update from slave@192.168.1.64:57346: task 29 of framework 201203291014-0-0005 is now in state TASK_RUNNING
I0329 10:19:41.242085  6088 master.cpp:679] Received reply for offer 201203291014-0-271
I0329 10:19:41.242260  6088 master.cpp:1453] Launching task 31 on slave 201203291014-0-0
I0329 10:19:41.242683  6088 master.cpp:1453] Launching task 32 on slave 201203291014-0-0
I0329 10:19:41.243435  6088 master.cpp:902] Status update from slave@192.168.1.64:57346: task 30 of framework 201203291014-0-0005 is now in state TASK_RUNNING
I0329 10:19:41.250442  6088 master.cpp:902] Status update from slave@192.168.1.64:57346: task 31 of framework 201203291014-0-0005 is now in state TASK_RUNNING
I0329 10:19:41.254382  6088 master.cpp:902] Status update from slave@192.168.1.64:57346: task 32 of framework 201203291014-0-0005 is now in state TASK_RUNNING
I0329 10:19:41.271757  6088 master.cpp:902] Status update from slave@192.168.1.64:57346: task 28 of framework 201203291014-0-0005 is now in state TASK_FINISHED
I0329 10:19:41.271981  6088 master.cpp:1184] Sending 1 offers to framework 201203291014-0-0005
I0329 10:19:41.275296  6088 master.cpp:902] Status update from slave@192.168.1.64:57346: task 29 of framework 201203291014-0-0005 is now in state TASK_FINISHED
I0329 10:19:41.292455  6088 master.cpp:679] Received reply for offer 201203291014-0-272
I0329 10:19:41.292657  6088 master.cpp:1453] Launching task 33 on slave 201203291014-0-0
I0329 10:19:41.292928  6088 master.cpp:1453] Launching task 34 on slave 201203291014-0-0
I0329 10:19:41.293233  6088 master.cpp:1453] Launching task 35 on slave 201203291014-0-0
I0329 10:19:41.293354  6088 master.cpp:1453] Launching task 36 on slave 201203291014-0-0
I0329 10:19:41.298229  6088 master.cpp:902] Status update from slave@192.168.1.64:57346: task 33 of framework 201203291014-0-0005 is now in state TASK_RUNNING
I0329 10:19:41.301765  6088 master.cpp:902] Status update from slave@192.168.1.64:57346: task 34 of framework 201203291014-0-0005 is now in state TASK_RUNNING
I0329 10:19:41.305565  6088 master.cpp:902] Status update from slave@192.168.1.64:57346: task 30 of framework 201203291014-0-0005 is now in state TASK_FINISHED
I0329 10:19:41.305966  6088 master.cpp:1184] Sending 1 offers to framework 201203291014-0-0005
I0329 10:19:41.314316  6088 master.cpp:679] Received reply for offer 201203291014-0-273
I0329 10:19:41.314576  6088 master.cpp:1453] Launching task 37 on slave 201203291014-0-0
I0329 10:19:41.314918  6088 master.cpp:1453] Launching task 38 on slave 201203291014-0-0
I0329 10:19:41.318322  6088 master.cpp:902] Status update from slave@192.168.1.64:57346: task 36 of framework 201203291014-0-0005 is now in state TASK_RUNNING
I0329 10:19:41.323716  6088 master.cpp:902] Status update from slave@192.168.1.64:57346: task 35 of framework 201203291014-0-0005 is now in state TASK_RUNNING
I0329 10:19:41.335177  6088 master.cpp:902] Status update from slave@192.168.1.64:57346: task 37 of framework 201203291014-0-0005 is now in state TASK_RUNNING
I0329 10:19:41.337935  6088 master.cpp:902] Status update from slave@192.168.1.64:57346: task 38 of framework 201203291014-0-0005 is now in state TASK_RUNNING
I0329 10:19:41.341106  6088 master.cpp:902] Status update from slave@192.168.1.64:57346: task 31 of framework 201203291014-0-0005 is now in state TASK_FINISHED
I0329 10:19:41.341382  6088 master.cpp:1184] Sending 1 offers to framework 201203291014-0-0005
I0329 10:19:41.346091  6088 master.cpp:679] Received reply for offer 201203291014-0-274
I0329 10:19:41.346267  6088 master.cpp:1453] Launching task 39 on slave 201203291014-0-0
I0329 10:19:41.353015  6088 master.cpp:902] Status update from slave@192.168.1.64:57346: task 32 of framework 201203291014-0-0005 is now in state TASK_FINISHED
I0329 10:19:41.353245  6088 master.cpp:1184] Sending 1 offers to framework 201203291014-0-0005
I0329 10:19:41.355437  6088 master.cpp:679] Received reply for offer 201203291014-0-275
I0329 10:19:41.355634  6088 master.cpp:1403] Filtered slave 201203291014-0-0 for framework 201203291014-0-0005 for 1 seconds
I0329 10:19:41.363606  6088 master.cpp:902] Status update from slave@192.168.1.64:57346: task 39 of framework 201203291014-0-0005 is now in state TASK_RUNNING
I0329 10:19:41.422214  6088 master.cpp:902] Status update from slave@192.168.1.64:57346: task 37 of framework 201203291014-0-0005 is now in state TASK_FINISHED
I0329 10:19:41.425645  6088 master.cpp:902] Status update from slave@192.168.1.64:57346: task 35 of framework 201203291014-0-0005 is now in state TASK_FINISHED
I0329 10:19:41.433657  6088 master.cpp:902] Status update from slave@192.168.1.64:57346: task 33 of framework 201203291014-0-0005 is now in state TASK_FINISHED
I0329 10:19:41.441189  6088 master.cpp:902] Status update from slave@192.168.1.64:57346: task 34 of framework 201203291014-0-0005 is now in state TASK_FINISHED
I0329 10:19:41.444048  6088 master.cpp:902] Status update from slave@192.168.1.64:57346: task 36 of framework 201203291014-0-0005 is now in state TASK_FINISHED
I0329 10:19:41.460450  6088 master.cpp:902] Status update from slave@192.168.1.64:57346: task 38 of framework 201203291014-0-0005 is now in state TASK_FINISHED
I0329 10:19:41.464150  6088 master.cpp:902] Status update from slave@192.168.1.64:57346: task 39 of framework 201203291014-0-0005 is now in state TASK_FINISHED
I0329 10:19:41.530520  6088 master.cpp:718] Reviving offers for framework 201203291014-0-0005
I0329 10:19:41.530652  6088 simple_allocator.cpp:145] Filters removed for framework 201203291014-0-0005
I0329 10:19:41.531043  6088 master.cpp:1184] Sending 2 offers to framework 201203291014-0-0005
I0329 10:19:41.563040  6088 master.cpp:679] Received reply for offer 201203291014-0-276
I0329 10:19:41.563256  6088 master.cpp:1403] Filtered slave 201203291014-0-1 for framework 201203291014-0-0005 for 1 seconds
I0329 10:19:41.564574  6088 master.cpp:679] Received reply for offer 201203291014-0-277
I0329 10:19:41.564721  6088 master.cpp:1453] Launching task 40 on slave 201203291014-0-0
I0329 10:19:41.564937  6088 master.cpp:1453] Launching task 41 on slave 201203291014-0-0
I0329 10:19:41.565096  6088 master.cpp:1453] Launching task 42 on slave 201203291014-0-0
I0329 10:19:41.565255  6088 master.cpp:1453] Launching task 43 on slave 201203291014-0-0
I0329 10:19:41.565402  6088 master.cpp:1453] Launching task 44 on slave 201203291014-0-0
I0329 10:19:41.565883  6088 master.cpp:1453] Launching task 45 on slave 201203291014-0-0
I0329 10:19:41.566345  6088 master.cpp:1453] Launching task 46 on slave 201203291014-0-0
I0329 10:19:41.566797  6088 master.cpp:1453] Launching task 47 on slave 201203291014-0-0
I0329 10:19:41.570538  6088 master.cpp:902] Status update from slave@192.168.1.64:57346: task 40 of framework 201203291014-0-0005 is now in state TASK_RUNNING
I0329 10:19:41.574808  6088 master.cpp:902] Status update from slave@192.168.1.64:57346: task 41 of framework 201203291014-0-0005 is now in state TASK_RUNNING
I0329 10:19:41.576817  6088 master.cpp:902] Status update from slave@192.168.1.64:57346: task 42 of framework 201203291014-0-0005 is now in state TASK_RUNNING
I0329 10:19:41.588006  6088 master.cpp:902] Status update from slave@192.168.1.64:57346: task 43 of framework 201203291014-0-0005 is now in state TASK_RUNNING
I0329 10:19:41.591418  6088 master.cpp:902] Status update from slave@192.168.1.64:57346: task 46 of framework 201203291014-0-0005 is now in state TASK_RUNNING
I0329 10:19:41.594106  6088 master.cpp:902] Status update from slave@192.168.1.64:57346: task 47 of framework 201203291014-0-0005 is now in state TASK_RUNNING
I0329 10:19:41.597092  6088 master.cpp:902] Status update from slave@192.168.1.64:57346: task 44 of framework 201203291014-0-0005 is now in state TASK_RUNNING
I0329 10:19:41.599864  6088 master.cpp:902] Status update from slave@192.168.1.64:57346: task 45 of framework 201203291014-0-0005 is now in state TASK_RUNNING
I0329 10:19:41.782982  6088 master.cpp:902] Status update from slave@192.168.1.64:57346: task 45 of framework 201203291014-0-0005 is now in state TASK_FAILED
I0329 10:19:41.783246  6088 master.cpp:1184] Sending 1 offers to framework 201203291014-0-0005
I0329 10:19:41.797435  6088 master.cpp:679] Received reply for offer 201203291014-0-278
I0329 10:19:41.797590  6088 master.cpp:1453] Launching task 48 on slave 201203291014-0-0
I0329 10:19:41.819864  6088 master.cpp:902] Status update from slave@192.168.1.64:57346: task 46 of framework 201203291014-0-0005 is now in state TASK_FAILED
I0329 10:19:41.820050  6088 master.cpp:1184] Sending 1 offers to framework 201203291014-0-0005
I0329 10:19:41.820431  6088 master.cpp:902] Status update from slave@192.168.1.64:57346: task 40 of framework 201203291014-0-0005 is now in state TASK_FAILED
I0329 10:19:41.820919  6088 master.cpp:902] Status update from slave@192.168.1.64:57346: task 44 of framework 201203291014-0-0005 is now in state TASK_FAILED
I0329 10:19:41.821416  6088 master.cpp:902] Status update from slave@192.168.1.64:57346: task 47 of framework 201203291014-0-0005 is now in state TASK_FAILED
I0329 10:19:41.821629  6088 master.cpp:902] Status update from slave@192.168.1.64:57346: task 41 of framework 201203291014-0-0005 is now in state TASK_FAILED
I0329 10:19:41.822227  6088 master.cpp:902] Status update from slave@192.168.1.64:57346: task 43 of framework 201203291014-0-0005 is now in state TASK_FAILED
I0329 10:19:41.822628  6088 master.cpp:902] Status update from slave@192.168.1.64:57346: task 42 of framework 201203291014-0-0005 is now in state TASK_FAILED
I0329 10:19:41.823093  6088 master.cpp:902] Status update from slave@192.168.1.64:57346: task 48 of framework 201203291014-0-0005 is now in state TASK_RUNNING
I0329 10:19:41.826557  6088 master.cpp:679] Received reply for offer 201203291014-0-279
I0329 10:19:41.826746  6088 master.cpp:1453] Launching task 49 on slave 201203291014-0-0
I0329 10:19:41.859808  6088 master.cpp:902] Status update from slave@192.168.1.64:57346: task 49 of framework 201203291014-0-0005 is now in state TASK_RUNNING
I0329 10:19:41.860183  6088 master.cpp:902] Status update from slave@192.168.1.64:57346: task 48 of framework 201203291014-0-0005 is now in state TASK_FAILED
I0329 10:19:41.860344  6088 master.cpp:1184] Sending 1 offers to framework 201203291014-0-0005
I0329 10:19:41.876550  6088 master.cpp:902] Status update from slave@192.168.1.64:57346: task 49 of framework 201203291014-0-0005 is now in state TASK_FAILED
I0329 10:19:41.922673  6088 master.cpp:679] Received reply for offer 201203291014-0-280
I0329 10:19:41.922888  6088 master.cpp:1453] Launching task 50 on slave 201203291014-0-0
I0329 10:19:41.923567  6088 master.cpp:1453] Launching task 51 on slave 201203291014-0-0
I0329 10:19:41.923745  6088 master.cpp:1453] Launching task 52 on slave 201203291014-0-0
I0329 10:19:41.923866  6088 master.cpp:1453] Launching task 53 on slave 201203291014-0-0
I0329 10:19:41.924520  6088 master.cpp:1453] Launching task 54 on slave 201203291014-0-0
I0329 10:19:41.925067  6088 master.cpp:1453] Launching task 55 on slave 201203291014-0-0
I0329 10:19:41.925470  6088 master.cpp:1453] Launching task 56 on slave 201203291014-0-0
I0329 10:19:42.187579  6088 master.cpp:1184] Sending 1 offers to framework 201203291014-0-0002
I0329 10:19:42.187850  6088 master.cpp:1184] Sending 1 offers to framework 201203291014-0-0004
I0329 10:19:42.189286  6088 master.cpp:679] Received reply for offer 201203291014-0-282
I0329 10:19:42.189453  6088 master.cpp:1403] Filtered slave 201203291014-0-1 for framework 201203291014-0-0004 for 1 seconds
I0329 10:19:42.189590  6088 master.cpp:679] Received reply for offer 201203291014-0-281
I0329 10:19:42.189785  6088 master.cpp:1184] Sending 1 offers to framework 201203291014-0-0003
I0329 10:19:42.189904  6088 master.cpp:1403] Filtered slave 201203291014-0-0 for framework 201203291014-0-0002 for 1 seconds
I0329 10:19:42.191159  6088 master.cpp:679] Received reply for offer 201203291014-0-283
I0329 10:19:42.191351  6088 master.cpp:1403] Filtered slave 201203291014-0-1 for framework 201203291014-0-0003 for 1 seconds
I0329 10:19:42.990380  6088 master.cpp:1001] Executor default of framework 201203291014-0-0005 on slave 201203291014-0-0 (azad.gateway.2wire.net) exited with status 256
I0329 10:19:42.991811  6088 master.cpp:1033] Removing task 56 of framework 201203291014-0-0005 because of lost executor
I0329 10:19:42.992025  6088 master.cpp:1184] Sending 1 offers to framework 201203291014-0-0004
I0329 10:19:42.993763  6088 master.cpp:1033] Removing task 54 of framework 201203291014-0-0005 because of lost executor
I0329 10:19:42.995376  6088 master.cpp:1033] Removing task 55 of framework 201203291014-0-0005 because of lost executor
I0329 10:19:42.996829  6088 master.cpp:1033] Removing task 52 of framework 201203291014-0-0005 because of lost executor
I0329 10:19:42.998268  6088 master.cpp:1033] Removing task 53 of framework 201203291014-0-0005 because of lost executor
I0329 10:19:43.000063  6088 master.cpp:1033] Removing task 50 of framework 201203291014-0-0005 because of lost executor
I0329 10:19:43.001622  6088 master.cpp:1033] Removing task 51 of framework 201203291014-0-0005 because of lost executor
I0329 10:19:43.001811  6088 master.cpp:679] Received reply for offer 201203291014-0-284
I0329 10:19:43.002182  6088 master.cpp:1184] Sending 1 offers to framework 201203291014-0-0005
I0329 10:19:43.002625  6088 master.cpp:1403] Filtered slave 201203291014-0-0 for framework 201203291014-0-0004 for 1 seconds
I0329 10:19:43.016720  6088 master.cpp:679] Received reply for offer 201203291014-0-285
I0329 10:19:43.016933  6088 master.cpp:1453] Launching task 57 on slave 201203291014-0-0
I0329 10:19:43.017288  6088 master.cpp:1453] Launching task 58 on slave 201203291014-0-0
I0329 10:19:43.017483  6088 master.cpp:1453] Launching task 59 on slave 201203291014-0-0
I0329 10:19:43.017694  6088 master.cpp:1453] Launching task 60 on slave 201203291014-0-0
I0329 10:19:43.018023  6088 master.cpp:1453] Launching task 61 on slave 201203291014-0-0
I0329 10:19:43.018528  6088 master.cpp:1453] Launching task 62 on slave 201203291014-0-0
I0329 10:19:43.189502  6088 master.cpp:1184] Sending 1 offers to framework 201203291014-0-0002
I0329 10:19:43.189831  6088 master.cpp:1184] Sending 1 offers to framework 201203291014-0-0005
I0329 10:19:43.190840  6088 master.cpp:679] Received reply for offer 201203291014-0-286
I0329 10:19:43.191010  6088 master.cpp:1403] Filtered slave 201203291014-0-1 for framework 201203291014-0-0002 for 1 seconds
I0329 10:19:43.194263  6088 master.cpp:679] Received reply for offer 201203291014-0-287
I0329 10:19:43.194439  6088 master.cpp:1453] Launching task 63 on slave 201203291014-0-0
I0329 10:19:43.194839  6088 master.cpp:1453] Launching task 64 on slave 201203291014-0-0
I0329 10:19:43.195241  6088 master.cpp:1184] Sending 1 offers to framework 201203291014-0-0005
I0329 10:19:43.196046  6088 master.cpp:679] Received reply for offer 201203291014-0-288
I0329 10:19:43.196214  6088 master.cpp:1403] Filtered slave 201203291014-0-1 for framework 201203291014-0-0005 for 1 seconds
I0329 10:19:43.956738  6088 master.cpp:902] Status update from slave@192.168.1.64:57346: task 59 of framework 201203291014-0-0005 is now in state TASK_RUNNING
I0329 10:19:43.958518  6088 master.cpp:902] Status update from slave@192.168.1.64:57346: task 64 of framework 201203291014-0-0005 is now in state TASK_RUNNING
I0329 10:19:43.960760  6088 master.cpp:902] Status update from slave@192.168.1.64:57346: task 62 of framework 201203291014-0-0005 is now in state TASK_RUNNING
I0329 10:19:43.966832  6088 master.cpp:902] Status update from slave@192.168.1.64:57346: task 61 of framework 201203291014-0-0005 is now in state TASK_RUNNING
I0329 10:19:43.966965  6088 master.cpp:902] Status update from slave@192.168.1.64:57346: task 60 of framework 201203291014-0-0005 is now in state TASK_RUNNING
I0329 10:19:43.968472  6088 master.cpp:902] Status update from slave@192.168.1.64:57346: task 58 of framework 201203291014-0-0005 is now in state TASK_RUNNING
I0329 10:19:43.970943  6088 master.cpp:902] Status update from slave@192.168.1.64:57346: task 57 of framework 201203291014-0-0005 is now in state TASK_RUNNING
I0329 10:19:43.973203  6088 master.cpp:902] Status update from slave@192.168.1.64:57346: task 63 of framework 201203291014-0-0005 is now in state TASK_RUNNING
I0329 10:19:44.190770  6088 master.cpp:1184] Sending 1 offers to framework 201203291014-0-0004
I0329 10:19:44.192090  6088 master.cpp:679] Received reply for offer 201203291014-0-289
I0329 10:19:44.192188  6088 master.cpp:1403] Filtered slave 201203291014-0-1 for framework 201203291014-0-0004 for 1 seconds
I0329 10:19:45.191251  6088 master.cpp:1184] Sending 1 offers to framework 201203291014-0-0002
I0329 10:19:45.194999  6088 master.cpp:679] Received reply for offer 201203291014-0-290
I0329 10:19:45.195178  6088 master.cpp:1403] Filtered slave 201203291014-0-1 for framework 201203291014-0-0002 for 1 seconds
I0329 10:19:45.662231  6088 master.cpp:902] Status update from slave@192.168.1.64:57346: task 57 of framework 201203291014-0-0005 is now in state TASK_FAILED
I0329 10:19:45.662498  6088 master.cpp:1184] Sending 1 offers to framework 201203291014-0-0002
I0329 10:19:45.662647  6088 master.cpp:1184] Sending 1 offers to framework 201203291014-0-0003
I0329 10:19:45.664216  6088 master.cpp:679] Received reply for offer 201203291014-0-291
I0329 10:19:45.664381  6088 master.cpp:1403] Filtered slave 201203291014-0-0 for framework 201203291014-0-0002 for 1 seconds
I0329 10:19:45.664598  6088 master.cpp:679] Received reply for offer 201203291014-0-292
I0329 10:19:45.664849  6088 master.cpp:1184] Sending 1 offers to framework 201203291014-0-0005
I0329 10:19:45.665415  6088 master.cpp:1403] Filtered slave 201203291014-0-1 for framework 201203291014-0-0003 for 1 seconds
I0329 10:19:45.665689  6088 master.cpp:902] Status update from slave@192.168.1.64:57346: task 59 of framework 201203291014-0-0005 is now in state TASK_FAILED
I0329 10:19:45.665918  6088 master.cpp:1184] Sending 1 offers to framework 201203291014-0-0005
I0329 10:19:45.667408  6088 master.cpp:902] Status update from slave@192.168.1.64:57346: task 60 of framework 201203291014-0-0005 is now in state TASK_FAILED
I0329 10:19:45.668361  6088 master.cpp:679] Received reply for offer 201203291014-0-293
I0329 10:19:45.668500  6088 master.cpp:1453] Launching task 65 on slave 201203291014-0-0
I0329 10:19:45.669183  6088 master.cpp:902] Status update from slave@192.168.1.64:57346: task 61 of framework 201203291014-0-0005 is now in state TASK_FAILED
I0329 10:19:45.669395  6088 master.cpp:1184] Sending 1 offers to framework 201203291014-0-0004
I0329 10:19:45.670831  6088 master.cpp:679] Received reply for offer 201203291014-0-294
I0329 10:19:45.670981  6088 master.cpp:1403] Filtered slave 201203291014-0-1 for framework 201203291014-0-0005 for 1 seconds
I0329 10:19:45.671433  6088 master.cpp:902] Status update from slave@192.168.1.64:57346: task 58 of framework 201203291014-0-0005 is now in state TASK_FAILED
I0329 10:19:45.673161  6088 master.cpp:902] Status update from slave@192.168.1.64:57346: task 62 of framework 201203291014-0-0005 is now in state TASK_FAILED
I0329 10:19:45.674968  6088 master.cpp:902] Status update from slave@192.168.1.64:57346: task 64 of framework 201203291014-0-0005 is now in state TASK_FAILED
I0329 10:19:45.676928  6088 master.cpp:902] Status update from slave@192.168.1.64:57346: task 63 of framework 201203291014-0-0005 is now in state TASK_FAILED
I0329 10:19:45.679620  6088 master.cpp:902] Status update from slave@192.168.1.64:57346: task 65 of framework 201203291014-0-0005 is now in state TASK_RUNNING
I0329 10:19:45.708214  6088 master.cpp:679] Received reply for offer 201203291014-0-295
I0329 10:19:45.708308  6088 master.cpp:1403] Filtered slave 201203291014-0-0 for framework 201203291014-0-0004 for 1 seconds
I0329 10:19:45.730538  6088 master.cpp:902] Status update from slave@192.168.1.64:57346: task 65 of framework 201203291014-0-0005 is now in state TASK_FAILED
I0329 10:19:45.730800  6088 master.cpp:1184] Sending 1 offers to framework 201203291014-0-0003
I0329 10:19:45.731997  6088 master.cpp:679] Received reply for offer 201203291014-0-296
I0329 10:19:45.732127  6088 master.cpp:1403] Filtered slave 201203291014-0-0 for framework 201203291014-0-0003 for 1 seconds
I0329 10:19:46.192688  6088 master.cpp:1184] Sending 1 offers to framework 201203291014-0-0004
I0329 10:19:46.192888  6088 master.cpp:1184] Sending 1 offers to framework 201203291014-0-0005
I0329 10:19:46.194319  6088 master.cpp:679] Received reply for offer 201203291014-0-297
I0329 10:19:46.194466  6088 master.cpp:1403] Filtered slave 201203291014-0-1 for framework 201203291014-0-0004 for 1 seconds
I0329 10:19:46.209863  6088 master.cpp:679] Received reply for offer 201203291014-0-298
I0329 10:19:46.210047  6088 master.cpp:1453] Launching task 66 on slave 201203291014-0-0
I0329 10:19:46.210237  6088 master.cpp:1453] Launching task 67 on slave 201203291014-0-0
I0329 10:19:46.210418  6088 master.cpp:1453] Launching task 68 on slave 201203291014-0-0
I0329 10:19:46.210643  6088 master.cpp:1453] Launching task 69 on slave 201203291014-0-0
I0329 10:19:46.210774  6088 master.cpp:1453] Launching task 70 on slave 201203291014-0-0
I0329 10:19:46.211231  6088 master.cpp:1453] Launching task 71 on slave 201203291014-0-0
I0329 10:19:46.211778  6088 master.cpp:1453] Launching task 72 on slave 201203291014-0-0
I0329 10:19:46.212244  6088 master.cpp:1453] Launching task 73 on slave 201203291014-0-0
I0329 10:19:46.992930  6088 master.cpp:1001] Executor default of framework 201203291014-0-0005 on slave 201203291014-0-0 (azad.gateway.2wire.net) exited with status 256
I0329 10:19:46.994396  6088 master.cpp:1033] Removing task 69 of framework 201203291014-0-0005 because of lost executor
I0329 10:19:46.994602  6088 master.cpp:1184] Sending 1 offers to framework 201203291014-0-0005
I0329 10:19:46.996244  6088 master.cpp:1033] Removing task 68 of framework 201203291014-0-0005 because of lost executor
I0329 10:19:46.997750  6088 master.cpp:1033] Removing task 67 of framework 201203291014-0-0005 because of lost executor
I0329 10:19:46.999522  6088 master.cpp:1033] Removing task 66 of framework 201203291014-0-0005 because of lost executor
I0329 10:19:47.001168  6088 master.cpp:1033] Removing task 70 of framework 201203291014-0-0005 because of lost executor
I0329 10:19:47.002691  6088 master.cpp:1033] Removing task 71 of framework 201203291014-0-0005 because of lost executor
I0329 10:19:47.004307  6088 master.cpp:1033] Removing task 72 of framework 201203291014-0-0005 because of lost executor
I0329 10:19:47.005877  6088 master.cpp:1033] Removing task 73 of framework 201203291014-0-0005 because of lost executor
I0329 10:19:47.006113  6088 master.cpp:679] Received reply for offer 201203291014-0-299
I0329 10:19:47.006280  6088 master.cpp:1453] Launching task 74 on slave 201203291014-0-0
I0329 10:19:47.194092  6088 master.cpp:1184] Sending 2 offers to framework 201203291014-0-0002
I0329 10:19:47.195888  6088 master.cpp:679] Received reply for offer 201203291014-0-300
I0329 10:19:47.196033  6088 master.cpp:1403] Filtered slave 201203291014-0-1 for framework 201203291014-0-0002 for 1 seconds
I0329 10:19:47.196400  6088 master.cpp:679] Received reply for offer 201203291014-0-301
I0329 10:19:47.196652  6088 master.cpp:1184] Sending 1 offers to framework 201203291014-0-0003
I0329 10:19:47.196794  6088 master.cpp:1403] Filtered slave 201203291014-0-0 for framework 201203291014-0-0002 for 1 seconds
I0329 10:19:47.197814  6088 master.cpp:679] Received reply for offer 201203291014-0-302
I0329 10:19:47.197984  6088 master.cpp:1403] Filtered slave 201203291014-0-1 for framework 201203291014-0-0003 for 1 seconds
I0329 10:19:47.956066  6088 master.cpp:902] Status update from slave@192.168.1.64:57346: task 74 of framework 201203291014-0-0005 is now in state TASK_RUNNING
I0329 10:19:48.195781  6088 master.cpp:1184] Sending 1 offers to framework 201203291014-0-0005
I0329 10:19:48.197113  6088 master.cpp:679] Received reply for offer 201203291014-0-303
I0329 10:19:48.197240  6088 master.cpp:1403] Filtered slave 201203291014-0-1 for framework 201203291014-0-0005 for 1 seconds
I0329 10:19:48.663259  6088 master.cpp:902] Status update from slave@192.168.1.64:57346: task 74 of framework 201203291014-0-0005 is now in state TASK_FAILED
I0329 10:19:48.663573  6088 master.cpp:1184] Sending 2 offers to framework 201203291014-0-0004
I0329 10:19:48.665333  6088 master.cpp:679] Received reply for offer 201203291014-0-304
I0329 10:19:48.665633  6088 master.cpp:1403] Filtered slave 201203291014-0-1 for framework 201203291014-0-0004 for 1 seconds
I0329 10:19:48.665761  6088 master.cpp:679] Received reply for offer 201203291014-0-305
I0329 10:19:48.666100  6088 master.cpp:1403] Filtered slave 201203291014-0-0 for framework 201203291014-0-0004 for 1 seconds
I0329 10:19:49.197296  6088 master.cpp:1184] Sending 2 offers to framework 201203291014-0-0002
I0329 10:19:49.199208  6088 master.cpp:679] Received reply for offer 201203291014-0-306
I0329 10:19:49.199306  6088 master.cpp:1403] Filtered slave 201203291014-0-1 for framework 201203291014-0-0002 for 1 seconds
I0329 10:19:49.225174  6088 master.cpp:679] Received reply for offer 201203291014-0-307
I0329 10:19:49.262295  6088 master.cpp:1184] Sending 1 offers to framework 201203291014-0-0003
I0329 10:19:49.262621  6088 master.cpp:1403] Filtered slave 201203291014-0-0 for framework 201203291014-0-0002 for 1 seconds
I0329 10:19:49.263943  6088 master.cpp:679] Received reply for offer 201203291014-0-308
I0329 10:19:49.264133  6088 master.cpp:1184] Sending 1 offers to framework 201203291014-0-0005
I0329 10:19:49.264241  6088 master.cpp:1403] Filtered slave 201203291014-0-1 for framework 201203291014-0-0003 for 1 seconds
I0329 10:19:49.265730  6088 master.cpp:679] Received reply for offer 201203291014-0-309
I0329 10:19:49.265902  6088 master.cpp:1403] Filtered slave 201203291014-0-0 for framework 201203291014-0-0005 for 1 seconds
I0329 10:19:49.996189  6088 master.cpp:1001] Executor default of framework 201203291014-0-0005 on slave 201203291014-0-0 (azad.gateway.2wire.net) exited with status 256
I0329 10:19:50.198676  6088 master.cpp:1184] Sending 1 offers to framework 201203291014-0-0005
I0329 10:19:50.200296  6088 master.cpp:679] Received reply for offer 201203291014-0-310
I0329 10:19:50.200455  6088 master.cpp:1403] Filtered slave 201203291014-0-1 for framework 201203291014-0-0005 for 1 seconds
I0329 10:19:51.200237  6088 master.cpp:1184] Sending 1 offers to framework 201203291014-0-0002
I0329 10:19:51.200417  6088 master.cpp:1184] Sending 1 offers to framework 201203291014-0-0003
I0329 10:19:51.201781  6088 master.cpp:679] Received reply for offer 201203291014-0-311
I0329 10:19:51.201942  6088 master.cpp:1403] Filtered slave 201203291014-0-1 for framework 201203291014-0-0002 for 1 seconds
I0329 10:19:51.202303  6088 master.cpp:679] Received reply for offer 201203291014-0-312
I0329 10:19:51.202615  6088 master.cpp:1184] Sending 1 offers to framework 201203291014-0-0004
I0329 10:19:51.202793  6088 master.cpp:1403] Filtered slave 201203291014-0-0 for framework 201203291014-0-0003 for 1 seconds
I0329 10:19:51.204112  6088 master.cpp:679] Received reply for offer 201203291014-0-313
I0329 10:19:51.204290  6088 master.cpp:1184] Sending 1 offers to framework 201203291014-0-0002
I0329 10:19:51.204491  6088 master.cpp:1403] Filtered slave 201203291014-0-1 for framework 201203291014-0-0004 for 1 seconds
I0329 10:19:51.205636  6088 master.cpp:679] Received reply for offer 201203291014-0-314
I0329 10:19:51.205809  6088 master.cpp:1184] Sending 1 offers to framework 201203291014-0-0003
I0329 10:19:51.205981  6088 master.cpp:1403] Filtered slave 201203291014-0-0 for framework 201203291014-0-0002 for 1 seconds
I0329 10:19:51.207171  6088 master.cpp:679] Received reply for offer 201203291014-0-315
I0329 10:19:51.207334  6088 master.cpp:1184] Sending 1 offers to framework 201203291014-0-0005
I0329 10:19:51.207509  6088 master.cpp:1403] Filtered slave 201203291014-0-1 for framework 201203291014-0-0003 for 1 seconds
I0329 10:19:51.208474  6088 master.cpp:679] Received reply for offer 201203291014-0-316
I0329 10:19:51.208623  6088 master.cpp:1403] Filtered slave 201203291014-0-0 for framework 201203291014-0-0005 for 1 seconds
I0329 10:19:52.201874  6088 master.cpp:1184] Sending 1 offers to framework 201203291014-0-0005
I0329 10:19:52.203533  6088 master.cpp:679] Received reply for offer 201203291014-0-317
I0329 10:19:52.203697  6088 master.cpp:1403] Filtered slave 201203291014-0-1 for framework 201203291014-0-0005 for 1 seconds
I0329 10:19:53.080502  6088 master.cpp:1118] Framework 201203291014-0-0005 disconnected
I0329 10:19:53.080659  6088 master.cpp:1118] Framework 201203291014-0-0004 disconnected
I0329 10:19:53.202958  6088 master.cpp:1184] Sending 1 offers to framework 201203291014-0-0002
I0329 10:19:53.204788  6088 master.cpp:679] Received reply for offer 201203291014-0-318
I0329 10:19:53.204946  6088 master.cpp:1403] Filtered slave 201203291014-0-0 for framework 201203291014-0-0002 for 1 seconds
I0329 10:20:27.086210  6088 master.cpp:492] Registering framework 201203291014-0-0006 at 3@192.168.1.64:32913
I0329 10:20:27.086462  6088 simple_allocator.cpp:48] Added framework 201203291014-0-0006
I0329 10:20:27.086707  6088 master.cpp:1184] Sending 2 offers to framework 201203291014-0-0006
I0329 10:20:27.086902  6088 master.cpp:492] Registering framework 201203291014-0-0007 at 2@192.168.1.64:32913
I0329 10:20:27.087023  6088 simple_allocator.cpp:48] Added framework 201203291014-0-0007
I0329 10:20:27.103502  6088 master.cpp:679] Received reply for offer 201203291014-0-319
I0329 10:20:27.103705  6088 master.cpp:1403] Filtered slave 201203291014-0-1 for framework 201203291014-0-0006 for 1 seconds
I0329 10:20:27.103832  6088 master.cpp:679] Received reply for offer 201203291014-0-320
I0329 10:20:27.104003  6088 master.cpp:1184] Sending 1 offers to framework 201203291014-0-0007
I0329 10:20:27.104125  6088 master.cpp:1403] Filtered slave 201203291014-0-0 for framework 201203291014-0-0006 for 1 seconds
I0329 10:20:27.104871  6088 master.cpp:679] Received reply for offer 201203291014-0-321
I0329 10:20:27.105033  6088 master.cpp:1403] Filtered slave 201203291014-0-1 for framework 201203291014-0-0007 for 1 seconds
I0329 10:20:27.454356  6088 master.cpp:718] Reviving offers for framework 201203291014-0-0007
I0329 10:20:27.454530  6088 simple_allocator.cpp:145] Filters removed for framework 201203291014-0-0007
I0329 10:20:34.966164  6088 master.cpp:1118] Framework 201203291014-0-0003 disconnected
I0329 10:20:34.966336  6088 master.cpp:1118] Framework 201203291014-0-0002 disconnected
I0329 10:20:35.251335  6088 master.cpp:1184] Sending 1 offers to framework 201203291014-0-0006
I0329 10:20:35.252892  6088 master.cpp:679] Received reply for offer 201203291014-0-322
I0329 10:20:35.253049  6088 master.cpp:1403] Filtered slave 201203291014-0-0 for framework 201203291014-0-0006 for 1 seconds
I0329 10:20:39.747999  6088 master.cpp:1118] Framework 201203291014-0-0007 disconnected
I0329 10:20:39.748195  6088 master.cpp:1118] Framework 201203291014-0-0006 disconnected
I0329 10:20:46.680889  6088 master.cpp:492] Registering framework 201203291014-0-0008 at 3@192.168.1.64:39213
I0329 10:20:46.681195  6088 simple_allocator.cpp:48] Added framework 201203291014-0-0008
I0329 10:20:46.681392  6088 master.cpp:1184] Sending 2 offers to framework 201203291014-0-0008
I0329 10:20:46.681638  6088 master.cpp:492] Registering framework 201203291014-0-0009 at 2@192.168.1.64:39213
I0329 10:20:46.681776  6088 simple_allocator.cpp:48] Added framework 201203291014-0-0009
I0329 10:20:46.698432  6088 master.cpp:679] Received reply for offer 201203291014-0-323
I0329 10:20:46.698633  6088 master.cpp:1403] Filtered slave 201203291014-0-1 for framework 201203291014-0-0008 for 1 seconds
I0329 10:20:46.698740  6088 master.cpp:679] Received reply for offer 201203291014-0-324
I0329 10:20:46.698897  6088 master.cpp:1184] Sending 1 offers to framework 201203291014-0-0009
I0329 10:20:46.698995  6088 master.cpp:1403] Filtered slave 201203291014-0-0 for framework 201203291014-0-0008 for 1 seconds
I0329 10:20:46.700080  6088 master.cpp:679] Received reply for offer 201203291014-0-325
I0329 10:20:46.700211  6088 master.cpp:1403] Filtered slave 201203291014-0-1 for framework 201203291014-0-0009 for 1 seconds
I0329 10:20:47.049664  6088 master.cpp:718] Reviving offers for framework 201203291014-0-0009
I0329 10:20:47.049803  6088 simple_allocator.cpp:145] Filters removed for framework 201203291014-0-0009
I0329 10:20:55.853386  6088 master.cpp:1143] Slave 201203291014-0-0 disconnected
I0329 10:20:55.854048  6088 simple_allocator.cpp:83] Removed slave 201203291014-0-0
I0329 10:20:59.127141  6088 master.cpp:1143] Slave 201203291014-0-1 disconnected
I0329 10:20:59.127815  6088 simple_allocator.cpp:83] Removed slave 201203291014-0-1
I0329 10:21:00.726362  6088 master.cpp:814] Attempting to register slave 201203291014-0-2 at slave@192.168.1.66:39104
I0329 10:21:00.726732  6088 master.cpp:1057] Master now considering a slave at ubuntu.gateway.2wire.net:39104 as active
I0329 10:21:00.726856  6088 master.cpp:1588] Adding slave 201203291014-0-2 at ubuntu.gateway.2wire.net with cpus=8; mem=8192
I0329 10:21:00.727285  6088 simple_allocator.cpp:71] Added slave 201203291014-0-2 with cpus=8; mem=8192
I0329 10:21:00.727476  6088 master.cpp:1184] Sending 1 offers to framework 201203291014-0-0008
I0329 10:21:00.729243  6088 master.cpp:679] Received reply for offer 201203291014-0-326
I0329 10:21:00.729740  6088 master.cpp:1403] Filtered slave 201203291014-0-2 for framework 201203291014-0-0008 for 1 seconds
I0329 10:21:01.281960  6088 master.cpp:1184] Sending 1 offers to framework 201203291014-0-0009
I0329 10:21:01.356041  6088 master.cpp:679] Received reply for offer 201203291014-0-327
I0329 10:21:01.356215  6088 master.cpp:1453] Launching task 0 on slave 201203291014-0-2
I0329 10:21:01.356600  6088 master.cpp:1453] Launching task 1 on slave 201203291014-0-2
I0329 10:21:01.356899  6088 master.cpp:1453] Launching task 2 on slave 201203291014-0-2
I0329 10:21:01.357105  6088 master.cpp:1453] Launching task 3 on slave 201203291014-0-2
I0329 10:21:01.357332  6088 master.cpp:1453] Launching task 4 on slave 201203291014-0-2
I0329 10:21:01.357552  6088 master.cpp:1453] Launching task 5 on slave 201203291014-0-2
I0329 10:21:01.357761  6088 master.cpp:1453] Launching task 6 on slave 201203291014-0-2
I0329 10:21:01.358000  6088 master.cpp:1453] Launching task 7 on slave 201203291014-0-2
I0329 10:21:02.261644  6088 master.cpp:902] Status update from slave@192.168.1.66:39104: task 0 of framework 201203291014-0-0009 is now in state TASK_RUNNING
I0329 10:21:02.263842  6088 master.cpp:902] Status update from slave@192.168.1.66:39104: task 7 of framework 201203291014-0-0009 is now in state TASK_RUNNING
I0329 10:21:02.267185  6088 master.cpp:902] Status update from slave@192.168.1.66:39104: task 2 of framework 201203291014-0-0009 is now in state TASK_RUNNING
I0329 10:21:02.271235  6088 master.cpp:902] Status update from slave@192.168.1.66:39104: task 4 of framework 201203291014-0-0009 is now in state TASK_RUNNING
I0329 10:21:02.272970  6088 master.cpp:902] Status update from slave@192.168.1.66:39104: task 6 of framework 201203291014-0-0009 is now in state TASK_RUNNING
I0329 10:21:02.274164  6088 master.cpp:902] Status update from slave@192.168.1.66:39104: task 3 of framework 201203291014-0-0009 is now in state TASK_RUNNING
I0329 10:21:02.276394  6088 master.cpp:902] Status update from slave@192.168.1.66:39104: task 5 of framework 201203291014-0-0009 is now in state TASK_RUNNING
I0329 10:21:02.278403  6088 master.cpp:902] Status update from slave@192.168.1.66:39104: task 1 of framework 201203291014-0-0009 is now in state TASK_RUNNING
I0329 10:21:03.727068  6088 master.cpp:902] Status update from slave@192.168.1.66:39104: task 1 of framework 201203291014-0-0009 is now in state TASK_FINISHED
I0329 10:21:03.727388  6088 master.cpp:1184] Sending 1 offers to framework 201203291014-0-0008
I0329 10:21:03.745477  6088 master.cpp:679] Received reply for offer 201203291014-0-328
I0329 10:21:03.745687  6088 master.cpp:1403] Filtered slave 201203291014-0-2 for framework 201203291014-0-0008 for 1 seconds
I0329 10:21:03.750746  6088 master.cpp:902] Status update from slave@192.168.1.66:39104: task 5 of framework 201203291014-0-0009 is now in state TASK_FINISHED
I0329 10:21:03.751015  6088 master.cpp:1184] Sending 1 offers to framework 201203291014-0-0009
I0329 10:21:03.761800  6088 master.cpp:902] Status update from slave@192.168.1.66:39104: task 6 of framework 201203291014-0-0009 is now in state TASK_FINISHED
I0329 10:21:03.764085  6088 master.cpp:679] Received reply for offer 201203291014-0-329
I0329 10:21:03.764236  6088 master.cpp:1453] Launching task 8 on slave 201203291014-0-2
I0329 10:21:03.764415  6088 master.cpp:1453] Launching task 9 on slave 201203291014-0-2
I0329 10:21:03.776159  6088 master.cpp:902] Status update from slave@192.168.1.66:39104: task 8 of framework 201203291014-0-0009 is now in state TASK_RUNNING
I0329 10:21:03.780467  6088 master.cpp:902] Status update from slave@192.168.1.66:39104: task 9 of framework 201203291014-0-0009 is now in state TASK_RUNNING
I0329 10:21:03.842870  6088 master.cpp:902] Status update from slave@192.168.1.66:39104: task 0 of framework 201203291014-0-0009 is now in state TASK_FINISHED
I0329 10:21:03.843154  6088 master.cpp:1184] Sending 1 offers to framework 201203291014-0-0009
I0329 10:21:03.861760  6088 master.cpp:679] Received reply for offer 201203291014-0-330
I0329 10:21:03.861937  6088 master.cpp:1453] Launching task 10 on slave 201203291014-0-2
I0329 10:21:03.862226  6088 master.cpp:1453] Launching task 11 on slave 201203291014-0-2
I0329 10:21:03.872283  6088 master.cpp:902] Status update from slave@192.168.1.66:39104: task 7 of framework 201203291014-0-0009 is now in state TASK_FINISHED
I0329 10:21:03.872544  6088 master.cpp:1184] Sending 1 offers to framework 201203291014-0-0009
I0329 10:21:03.876626  6088 master.cpp:902] Status update from slave@192.168.1.66:39104: task 10 of framework 201203291014-0-0009 is now in state TASK_RUNNING
I0329 10:21:03.876808  6088 master.cpp:902] Status update from slave@192.168.1.66:39104: task 11 of framework 201203291014-0-0009 is now in state TASK_RUNNING
I0329 10:21:03.883857  6088 master.cpp:679] Received reply for offer 201203291014-0-331
I0329 10:21:03.884012  6088 master.cpp:1453] Launching task 12 on slave 201203291014-0-2
I0329 10:21:03.895483  6088 master.cpp:902] Status update from slave@192.168.1.66:39104: task 12 of framework 201203291014-0-0009 is now in state TASK_RUNNING
I0329 10:21:04.025154  6088 master.cpp:902] Status update from slave@192.168.1.66:39104: task 2 of framework 201203291014-0-0009 is now in state TASK_FINISHED
I0329 10:21:04.025446  6088 master.cpp:1184] Sending 1 offers to framework 201203291014-0-0009
I0329 10:21:04.033769  6088 master.cpp:679] Received reply for offer 201203291014-0-332
I0329 10:21:04.033941  6088 master.cpp:1453] Launching task 13 on slave 201203291014-0-2
I0329 10:21:04.039885  6088 master.cpp:902] Status update from slave@192.168.1.66:39104: task 3 of framework 201203291014-0-0009 is now in state TASK_FINISHED
I0329 10:21:04.040133  6088 master.cpp:1184] Sending 1 offers to framework 201203291014-0-0009
I0329 10:21:04.046623  6088 master.cpp:902] Status update from slave@192.168.1.66:39104: task 13 of framework 201203291014-0-0009 is now in state TASK_RUNNING
I0329 10:21:04.086367  6088 master.cpp:679] Received reply for offer 201203291014-0-333
I0329 10:21:04.086514  6088 master.cpp:1453] Launching task 14 on slave 201203291014-0-2
I0329 10:21:04.098991  6088 master.cpp:902] Status update from slave@192.168.1.66:39104: task 14 of framework 201203291014-0-0009 is now in state TASK_RUNNING
I0329 10:21:04.106967  6088 master.cpp:902] Status update from slave@192.168.1.66:39104: task 4 of framework 201203291014-0-0009 is now in state TASK_FINISHED
I0329 10:21:04.107303  6088 master.cpp:1184] Sending 1 offers to framework 201203291014-0-0009
I0329 10:21:04.127666  6088 master.cpp:679] Received reply for offer 201203291014-0-334
I0329 10:21:04.127924  6088 master.cpp:1453] Launching task 15 on slave 201203291014-0-2
I0329 10:21:04.141587  6088 master.cpp:902] Status update from slave@192.168.1.66:39104: task 15 of framework 201203291014-0-0009 is now in state TASK_RUNNING
I0329 10:21:04.361557  6088 master.cpp:902] Status update from slave@192.168.1.66:39104: task 12 of framework 201203291014-0-0009 is now in state TASK_FINISHED
I0329 10:21:04.361860  6088 master.cpp:1184] Sending 1 offers to framework 201203291014-0-0009
I0329 10:21:04.372215  6088 master.cpp:679] Received reply for offer 201203291014-0-335
I0329 10:21:04.372380  6088 master.cpp:1453] Launching task 16 on slave 201203291014-0-2
I0329 10:21:04.391207  6088 master.cpp:902] Status update from slave@192.168.1.66:39104: task 10 of framework 201203291014-0-0009 is now in state TASK_FINISHED
I0329 10:21:04.391471  6088 master.cpp:1184] Sending 1 offers to framework 201203291014-0-0009
I0329 10:21:04.398869  6088 master.cpp:679] Received reply for offer 201203291014-0-336
I0329 10:21:04.399021  6088 master.cpp:1453] Launching task 17 on slave 201203291014-0-2
I0329 10:21:04.413753  6088 master.cpp:902] Status update from slave@192.168.1.66:39104: task 16 of framework 201203291014-0-0009 is now in state TASK_RUNNING
I0329 10:21:04.434249  6088 master.cpp:902] Status update from slave@192.168.1.66:39104: task 17 of framework 201203291014-0-0009 is now in state TASK_RUNNING
I0329 10:21:04.511384  6088 master.cpp:902] Status update from slave@192.168.1.66:39104: task 13 of framework 201203291014-0-0009 is now in state TASK_FINISHED
I0329 10:21:04.511618  6088 master.cpp:1184] Sending 1 offers to framework 201203291014-0-0009
I0329 10:21:04.518148  6088 master.cpp:679] Received reply for offer 201203291014-0-337
I0329 10:21:04.518373  6088 master.cpp:1453] Launching task 18 on slave 201203291014-0-2
I0329 10:21:04.553973  6088 master.cpp:902] Status update from slave@192.168.1.66:39104: task 18 of framework 201203291014-0-0009 is now in state TASK_RUNNING
I0329 10:21:04.630995  6088 master.cpp:902] Status update from slave@192.168.1.66:39104: task 8 of framework 201203291014-0-0009 is now in state TASK_FINISHED
I0329 10:21:04.631253  6088 master.cpp:1184] Sending 1 offers to framework 201203291014-0-0009
I0329 10:21:04.638350  6088 master.cpp:679] Received reply for offer 201203291014-0-338
I0329 10:21:04.638552  6088 master.cpp:1453] Launching task 19 on slave 201203291014-0-2
I0329 10:21:04.648527  6088 master.cpp:902] Status update from slave@192.168.1.66:39104: task 15 of framework 201203291014-0-0009 is now in state TASK_FINISHED
I0329 10:21:04.648779  6088 master.cpp:1184] Sending 1 offers to framework 201203291014-0-0009
I0329 10:21:04.655789  6088 master.cpp:679] Received reply for offer 201203291014-0-339
I0329 10:21:04.655961  6088 master.cpp:1453] Launching task 20 on slave 201203291014-0-2
I0329 10:21:04.676283  6088 master.cpp:902] Status update from slave@192.168.1.66:39104: task 14 of framework 201203291014-0-0009 is now in state TASK_FINISHED
I0329 10:21:04.676527  6088 master.cpp:1184] Sending 1 offers to framework 201203291014-0-0009
I0329 10:21:04.682736  6088 master.cpp:679] Received reply for offer 201203291014-0-340
I0329 10:21:04.682896  6088 master.cpp:1453] Launching task 21 on slave 201203291014-0-2
I0329 10:21:04.684484  6088 master.cpp:902] Status update from slave@192.168.1.66:39104: task 19 of framework 201203291014-0-0009 is now in state TASK_RUNNING
I0329 10:21:04.714084  6088 master.cpp:902] Status update from slave@192.168.1.66:39104: task 20 of framework 201203291014-0-0009 is now in state TASK_RUNNING
I0329 10:21:04.731305  6088 master.cpp:902] Status update from slave@192.168.1.66:39104: task 21 of framework 201203291014-0-0009 is now in state TASK_RUNNING
I0329 10:21:04.933240  6088 master.cpp:902] Status update from slave@192.168.1.66:39104: task 9 of framework 201203291014-0-0009 is now in state TASK_FINISHED
I0329 10:21:04.933555  6088 master.cpp:1184] Sending 1 offers to framework 201203291014-0-0009
I0329 10:21:04.941002  6088 master.cpp:679] Received reply for offer 201203291014-0-341
I0329 10:21:04.941278  6088 master.cpp:1453] Launching task 22 on slave 201203291014-0-2
I0329 10:21:04.967422  6088 master.cpp:902] Status update from slave@192.168.1.66:39104: task 16 of framework 201203291014-0-0009 is now in state TASK_FINISHED
I0329 10:21:04.967732  6088 master.cpp:1184] Sending 1 offers to framework 201203291014-0-0009
I0329 10:21:04.972165  6088 master.cpp:902] Status update from slave@192.168.1.66:39104: task 22 of framework 201203291014-0-0009 is now in state TASK_RUNNING
I0329 10:21:04.975694  6088 master.cpp:679] Received reply for offer 201203291014-0-342
I0329 10:21:04.975852  6088 master.cpp:1453] Launching task 23 on slave 201203291014-0-2
I0329 10:21:04.998473  6088 master.cpp:902] Status update from slave@192.168.1.66:39104: task 23 of framework 201203291014-0-0009 is now in state TASK_RUNNING
I0329 10:21:05.126171  6088 master.cpp:902] Status update from slave@192.168.1.66:39104: task 11 of framework 201203291014-0-0009 is now in state TASK_FINISHED
I0329 10:21:05.126488  6088 master.cpp:1184] Sending 1 offers to framework 201203291014-0-0009
I0329 10:21:05.131934  6088 master.cpp:679] Received reply for offer 201203291014-0-343
I0329 10:21:05.132083  6088 master.cpp:1453] Launching task 24 on slave 201203291014-0-2
I0329 10:21:05.144340  6088 master.cpp:902] Status update from slave@192.168.1.66:39104: task 24 of framework 201203291014-0-0009 is now in state TASK_RUNNING
I0329 10:21:05.162972  6088 master.cpp:902] Status update from slave@192.168.1.66:39104: task 18 of framework 201203291014-0-0009 is now in state TASK_FINISHED
I0329 10:21:05.163245  6088 master.cpp:1184] Sending 1 offers to framework 201203291014-0-0009
I0329 10:21:05.168169  6088 master.cpp:679] Received reply for offer 201203291014-0-344
I0329 10:21:05.168328  6088 master.cpp:1453] Launching task 25 on slave 201203291014-0-2
I0329 10:21:05.181021  6088 master.cpp:902] Status update from slave@192.168.1.66:39104: task 25 of framework 201203291014-0-0009 is now in state TASK_RUNNING
I0329 10:21:05.354770  6088 master.cpp:902] Status update from slave@192.168.1.66:39104: task 17 of framework 201203291014-0-0009 is now in state TASK_FINISHED
I0329 10:21:05.355062  6088 master.cpp:1184] Sending 1 offers to framework 201203291014-0-0008
I0329 10:21:05.357417  6088 master.cpp:679] Received reply for offer 201203291014-0-345
I0329 10:21:05.357583  6088 master.cpp:1403] Filtered slave 201203291014-0-2 for framework 201203291014-0-0008 for 1 seconds
I0329 10:21:05.440619  6088 master.cpp:902] Status update from slave@192.168.1.66:39104: task 20 of framework 201203291014-0-0009 is now in state TASK_FINISHED
I0329 10:21:05.440875  6088 master.cpp:1184] Sending 1 offers to framework 201203291014-0-0009
I0329 10:21:05.445142  6088 master.cpp:902] Status update from slave@192.168.1.66:39104: task 19 of framework 201203291014-0-0009 is now in state TASK_FINISHED
I0329 10:21:05.448879  6088 master.cpp:679] Received reply for offer 201203291014-0-346
I0329 10:21:05.449019  6088 master.cpp:1453] Launching task 26 on slave 201203291014-0-2
I0329 10:21:05.449481  6088 master.cpp:1453] Launching task 27 on slave 201203291014-0-2
I0329 10:21:05.456776  6088 master.cpp:902] Status update from slave@192.168.1.66:39104: task 21 of framework 201203291014-0-0009 is now in state TASK_FINISHED
I0329 10:21:05.457046  6088 master.cpp:1184] Sending 1 offers to framework 201203291014-0-0009
I0329 10:21:05.461937  6088 master.cpp:902] Status update from slave@192.168.1.66:39104: task 26 of framework 201203291014-0-0009 is now in state TASK_RUNNING
I0329 10:21:05.468436  6088 master.cpp:902] Status update from slave@192.168.1.66:39104: task 27 of framework 201203291014-0-0009 is now in state TASK_RUNNING
I0329 10:21:05.501875  6088 master.cpp:679] Received reply for offer 201203291014-0-347
I0329 10:21:05.502066  6088 master.cpp:1453] Launching task 28 on slave 201203291014-0-2
I0329 10:21:05.502404  6088 master.cpp:1453] Launching task 29 on slave 201203291014-0-2
I0329 10:21:05.515210  6088 master.cpp:902] Status update from slave@192.168.1.66:39104: task 28 of framework 201203291014-0-0009 is now in state TASK_RUNNING
I0329 10:21:05.520392  6088 master.cpp:902] Status update from slave@192.168.1.66:39104: task 29 of framework 201203291014-0-0009 is now in state TASK_RUNNING
I0329 10:21:05.659355  6088 master.cpp:902] Status update from slave@192.168.1.66:39104: task 25 of framework 201203291014-0-0009 is now in state TASK_FINISHED
I0329 10:21:05.659663  6088 master.cpp:1184] Sending 1 offers to framework 201203291014-0-0009
I0329 10:21:05.664726  6088 master.cpp:679] Received reply for offer 201203291014-0-348
I0329 10:21:05.664870  6088 master.cpp:1453] Launching task 30 on slave 201203291014-0-2
I0329 10:21:05.682152  6088 master.cpp:902] Status update from slave@192.168.1.66:39104: task 30 of framework 201203291014-0-0009 is now in state TASK_RUNNING
I0329 10:21:05.753468  6088 master.cpp:902] Status update from slave@192.168.1.66:39104: task 23 of framework 201203291014-0-0009 is now in state TASK_FINISHED
I0329 10:21:05.753789  6088 master.cpp:1184] Sending 1 offers to framework 201203291014-0-0009
I0329 10:21:05.758810  6088 master.cpp:679] Received reply for offer 201203291014-0-349
I0329 10:21:05.758960  6088 master.cpp:1453] Launching task 31 on slave 201203291014-0-2
I0329 10:21:05.785533  6088 master.cpp:902] Status update from slave@192.168.1.66:39104: task 22 of framework 201203291014-0-0009 is now in state TASK_FINISHED
I0329 10:21:05.785868  6088 master.cpp:1184] Sending 1 offers to framework 201203291014-0-0009
I0329 10:21:05.795219  6088 master.cpp:679] Received reply for offer 201203291014-0-350
I0329 10:21:05.795426  6088 master.cpp:1453] Launching task 32 on slave 201203291014-0-2
I0329 10:21:05.809154  6088 master.cpp:902] Status update from slave@192.168.1.66:39104: task 31 of framework 201203291014-0-0009 is now in state TASK_RUNNING
I0329 10:21:05.809345  6088 master.cpp:902] Status update from slave@192.168.1.66:39104: task 32 of framework 201203291014-0-0009 is now in state TASK_RUNNING
I0329 10:21:06.031503  6088 master.cpp:902] Status update from slave@192.168.1.66:39104: task 26 of framework 201203291014-0-0009 is now in state TASK_FINISHED
I0329 10:21:06.031823  6088 master.cpp:1184] Sending 1 offers to framework 201203291014-0-0009
I0329 10:21:06.036921  6088 master.cpp:679] Received reply for offer 201203291014-0-351
I0329 10:21:06.037117  6088 master.cpp:1453] Launching task 33 on slave 201203291014-0-2
I0329 10:21:06.074180  6088 master.cpp:902] Status update from slave@192.168.1.66:39104: task 33 of framework 201203291014-0-0009 is now in state TASK_RUNNING
I0329 10:21:06.110741  6088 master.cpp:902] Status update from slave@192.168.1.66:39104: task 29 of framework 201203291014-0-0009 is now in state TASK_FINISHED
I0329 10:21:06.111042  6088 master.cpp:1184] Sending 1 offers to framework 201203291014-0-0009
I0329 10:21:06.116045  6088 master.cpp:679] Received reply for offer 201203291014-0-352
I0329 10:21:06.116193  6088 master.cpp:1453] Launching task 34 on slave 201203291014-0-2
I0329 10:21:06.138777  6088 master.cpp:902] Status update from slave@192.168.1.66:39104: task 27 of framework 201203291014-0-0009 is now in state TASK_FINISHED
I0329 10:21:06.139037  6088 master.cpp:1184] Sending 1 offers to framework 201203291014-0-0009
I0329 10:21:06.139292  6088 master.cpp:902] Status update from slave@192.168.1.66:39104: task 34 of framework 201203291014-0-0009 is now in state TASK_RUNNING
I0329 10:21:06.144114  6088 master.cpp:679] Received reply for offer 201203291014-0-353
I0329 10:21:06.144264  6088 master.cpp:1453] Launching task 35 on slave 201203291014-0-2
I0329 10:21:06.168854  6088 master.cpp:902] Status update from slave@192.168.1.66:39104: task 35 of framework 201203291014-0-0009 is now in state TASK_RUNNING
I0329 10:21:06.208297  6088 master.cpp:902] Status update from slave@192.168.1.66:39104: task 24 of framework 201203291014-0-0009 is now in state TASK_FINISHED
I0329 10:21:06.208595  6088 master.cpp:1184] Sending 1 offers to framework 201203291014-0-0009
I0329 10:21:06.213260  6088 master.cpp:679] Received reply for offer 201203291014-0-354
I0329 10:21:06.213407  6088 master.cpp:1453] Launching task 36 on slave 201203291014-0-2
I0329 10:21:06.247828  6088 master.cpp:902] Status update from slave@192.168.1.66:39104: task 36 of framework 201203291014-0-0009 is now in state TASK_RUNNING
I0329 10:21:06.292079  6088 master.cpp:902] Status update from slave@192.168.1.66:39104: task 32 of framework 201203291014-0-0009 is now in state TASK_FINISHED
I0329 10:21:06.292372  6088 master.cpp:1184] Sending 1 offers to framework 201203291014-0-0009
I0329 10:21:06.297785  6088 master.cpp:679] Received reply for offer 201203291014-0-355
I0329 10:21:06.297930  6088 master.cpp:1453] Launching task 37 on slave 201203291014-0-2
I0329 10:21:06.337380  6088 master.cpp:902] Status update from slave@192.168.1.66:39104: task 37 of framework 201203291014-0-0009 is now in state TASK_RUNNING
I0329 10:21:06.473148  6088 master.cpp:902] Status update from slave@192.168.1.66:39104: task 31 of framework 201203291014-0-0009 is now in state TASK_FINISHED
I0329 10:21:06.473440  6088 master.cpp:1184] Sending 1 offers to framework 201203291014-0-0009
I0329 10:21:06.478358  6088 master.cpp:679] Received reply for offer 201203291014-0-356
I0329 10:21:06.478507  6088 master.cpp:1453] Launching task 38 on slave 201203291014-0-2
I0329 10:21:06.507994  6088 master.cpp:902] Status update from slave@192.168.1.66:39104: task 38 of framework 201203291014-0-0009 is now in state TASK_RUNNING
I0329 10:21:06.589454  6088 master.cpp:902] Status update from slave@192.168.1.66:39104: task 33 of framework 201203291014-0-0009 is now in state TASK_FINISHED
I0329 10:21:06.589756  6088 master.cpp:1184] Sending 1 offers to framework 201203291014-0-0009
I0329 10:21:06.594693  6088 master.cpp:679] Received reply for offer 201203291014-0-357
I0329 10:21:06.594888  6088 master.cpp:1453] Launching task 39 on slave 201203291014-0-2
I0329 10:21:06.620854  6088 master.cpp:902] Status update from slave@192.168.1.66:39104: task 39 of framework 201203291014-0-0009 is now in state TASK_RUNNING
I0329 10:21:06.659237  6088 master.cpp:902] Status update from slave@192.168.1.66:39104: task 28 of framework 201203291014-0-0009 is now in state TASK_FINISHED
I0329 10:21:06.659601  6088 master.cpp:1184] Sending 1 offers to framework 201203291014-0-0009
I0329 10:21:06.662298  6088 master.cpp:679] Received reply for offer 201203291014-0-358
I0329 10:21:06.662533  6088 master.cpp:1403] Filtered slave 201203291014-0-2 for framework 201203291014-0-0009 for 1 seconds
I0329 10:21:06.763464  6088 master.cpp:902] Status update from slave@192.168.1.66:39104: task 34 of framework 201203291014-0-0009 is now in state TASK_FINISHED
I0329 10:21:06.863314  6088 master.cpp:902] Status update from slave@192.168.1.66:39104: task 30 of framework 201203291014-0-0009 is now in state TASK_FINISHED
I0329 10:21:06.953722  6088 master.cpp:902] Status update from slave@192.168.1.66:39104: task 37 of framework 201203291014-0-0009 is now in state TASK_FINISHED
I0329 10:21:07.011632  6088 master.cpp:902] Status update from slave@192.168.1.66:39104: task 38 of framework 201203291014-0-0009 is now in state TASK_FINISHED
I0329 10:21:07.055498  6088 master.cpp:902] Status update from slave@192.168.1.66:39104: task 35 of framework 201203291014-0-0009 is now in state TASK_FINISHED
I0329 10:21:07.097872  6088 master.cpp:902] Status update from slave@192.168.1.66:39104: task 39 of framework 201203291014-0-0009 is now in state TASK_FINISHED
I0329 10:21:07.098116  6088 master.cpp:902] Status update from slave@192.168.1.66:39104: task 36 of framework 201203291014-0-0009 is now in state TASK_FINISHED
I0329 10:21:07.286747  6088 master.cpp:1184] Sending 1 offers to framework 201203291014-0-0008
I0329 10:21:07.288338  6088 master.cpp:679] Received reply for offer 201203291014-0-359
I0329 10:21:07.288478  6088 master.cpp:1403] Filtered slave 201203291014-0-2 for framework 201203291014-0-0008 for 1 seconds
I0329 10:21:08.288547  6088 master.cpp:1184] Sending 1 offers to framework 201203291014-0-0009
I0329 10:21:08.290005  6088 master.cpp:679] Received reply for offer 201203291014-0-360
I0329 10:21:08.290144  6088 master.cpp:1403] Filtered slave 201203291014-0-2 for framework 201203291014-0-0009 for 1 seconds
I0329 10:21:09.290186  6088 master.cpp:1184] Sending 1 offers to framework 201203291014-0-0008
I0329 10:21:09.291605  6088 master.cpp:679] Received reply for offer 201203291014-0-361
I0329 10:21:09.291741  6088 master.cpp:1403] Filtered slave 201203291014-0-2 for framework 201203291014-0-0008 for 1 seconds
I0329 10:21:10.291867  6088 master.cpp:1184] Sending 1 offers to framework 201203291014-0-0009
I0329 10:21:10.293442  6088 master.cpp:679] Received reply for offer 201203291014-0-362
I0329 10:21:10.293581  6088 master.cpp:1403] Filtered slave 201203291014-0-2 for framework 201203291014-0-0009 for 1 seconds
I0329 10:21:11.293643  6088 master.cpp:1184] Sending 1 offers to framework 201203291014-0-0008
I0329 10:21:11.295181  6088 master.cpp:679] Received reply for offer 201203291014-0-363
I0329 10:21:11.295321  6088 master.cpp:1403] Filtered slave 201203291014-0-2 for framework 201203291014-0-0008 for 1 seconds
I0329 10:21:12.295392  6088 master.cpp:1184] Sending 1 offers to framework 201203291014-0-0009
I0329 10:21:12.296619  6088 master.cpp:679] Received reply for offer 201203291014-0-364
I0329 10:21:12.296758  6088 master.cpp:1403] Filtered slave 201203291014-0-2 for framework 201203291014-0-0009 for 1 seconds
I0329 10:21:13.296824  6088 master.cpp:1184] Sending 1 offers to framework 201203291014-0-0008
I0329 10:21:13.298228  6088 master.cpp:679] Received reply for offer 201203291014-0-365
I0329 10:21:13.298367  6088 master.cpp:1403] Filtered slave 201203291014-0-2 for framework 201203291014-0-0008 for 1 seconds
I0329 10:21:14.298437  6088 master.cpp:1184] Sending 1 offers to framework 201203291014-0-0009
I0329 10:21:14.299887  6088 master.cpp:679] Received reply for offer 201203291014-0-366
I0329 10:21:14.299970  6088 master.cpp:1403] Filtered slave 201203291014-0-2 for framework 201203291014-0-0009 for 1 seconds
I0329 10:21:15.300089  6088 master.cpp:1184] Sending 1 offers to framework 201203291014-0-0008
I0329 10:21:15.301508  6088 master.cpp:679] Received reply for offer 201203291014-0-367
I0329 10:21:15.301647  6088 master.cpp:1403] Filtered slave 201203291014-0-2 for framework 201203291014-0-0008 for 1 seconds
I0329 10:21:16.301736  6088 master.cpp:1184] Sending 1 offers to framework 201203291014-0-0009
I0329 10:21:16.303124  6088 master.cpp:679] Received reply for offer 201203291014-0-368
I0329 10:21:16.303262  6088 master.cpp:1403] Filtered slave 201203291014-0-2 for framework 201203291014-0-0009 for 1 seconds
I0329 10:21:17.303362  6088 master.cpp:1184] Sending 1 offers to framework 201203291014-0-0008
I0329 10:21:17.304827  6088 master.cpp:679] Received reply for offer 201203291014-0-369
I0329 10:21:17.304970  6088 master.cpp:1403] Filtered slave 201203291014-0-2 for framework 201203291014-0-0008 for 1 seconds
I0329 10:21:18.305037  6088 master.cpp:1184] Sending 1 offers to framework 201203291014-0-0009
I0329 10:21:18.306486  6088 master.cpp:679] Received reply for offer 201203291014-0-370
I0329 10:21:18.306624  6088 master.cpp:1403] Filtered slave 201203291014-0-2 for framework 201203291014-0-0009 for 1 seconds
I0329 10:21:19.306695  6088 master.cpp:1184] Sending 1 offers to framework 201203291014-0-0008
I0329 10:21:19.308097  6088 master.cpp:679] Received reply for offer 201203291014-0-371
I0329 10:21:19.308213  6088 master.cpp:1403] Filtered slave 201203291014-0-2 for framework 201203291014-0-0008 for 1 seconds
I0329 10:21:20.308303  6088 master.cpp:1184] Sending 1 offers to framework 201203291014-0-0009
I0329 10:21:20.309684  6088 master.cpp:679] Received reply for offer 201203291014-0-372
I0329 10:21:20.309819  6088 master.cpp:1403] Filtered slave 201203291014-0-2 for framework 201203291014-0-0009 for 1 seconds
I0329 10:21:21.309862  6088 master.cpp:1184] Sending 1 offers to framework 201203291014-0-0008
I0329 10:21:21.311293  6088 master.cpp:679] Received reply for offer 201203291014-0-373
I0329 10:21:21.311465  6088 master.cpp:1403] Filtered slave 201203291014-0-2 for framework 201203291014-0-0008 for 1 seconds
I0329 10:21:22.311496  6088 master.cpp:1184] Sending 1 offers to framework 201203291014-0-0009
I0329 10:21:22.313020  6088 master.cpp:679] Received reply for offer 201203291014-0-374
I0329 10:21:22.313189  6088 master.cpp:1403] Filtered slave 201203291014-0-2 for framework 201203291014-0-0009 for 1 seconds
I0329 10:21:23.313227  6088 master.cpp:1184] Sending 1 offers to framework 201203291014-0-0008
I0329 10:21:23.314990  6088 master.cpp:679] Received reply for offer 201203291014-0-375
I0329 10:21:23.315175  6088 master.cpp:1403] Filtered slave 201203291014-0-2 for framework 201203291014-0-0008 for 1 seconds
I0329 10:21:24.315234  6088 master.cpp:1184] Sending 1 offers to framework 201203291014-0-0009
I0329 10:21:24.316740  6088 master.cpp:679] Received reply for offer 201203291014-0-376
I0329 10:21:24.316823  6088 master.cpp:1403] Filtered slave 201203291014-0-2 for framework 201203291014-0-0009 for 1 seconds
I0329 10:21:25.316951  6088 master.cpp:1184] Sending 1 offers to framework 201203291014-0-0008
I0329 10:21:25.318392  6088 master.cpp:679] Received reply for offer 201203291014-0-377
I0329 10:21:25.318532  6088 master.cpp:1403] Filtered slave 201203291014-0-2 for framework 201203291014-0-0008 for 1 seconds
I0329 10:21:26.318608  6088 master.cpp:1184] Sending 1 offers to framework 201203291014-0-0009
I0329 10:21:26.320034  6088 master.cpp:679] Received reply for offer 201203291014-0-378
I0329 10:21:26.320170  6088 master.cpp:1403] Filtered slave 201203291014-0-2 for framework 201203291014-0-0009 for 1 seconds
I0329 10:21:27.320237  6088 master.cpp:1184] Sending 1 offers to framework 201203291014-0-0008
I0329 10:21:27.321706  6088 master.cpp:679] Received reply for offer 201203291014-0-379
I0329 10:21:27.321845  6088 master.cpp:1403] Filtered slave 201203291014-0-2 for framework 201203291014-0-0008 for 1 seconds
I0329 10:21:28.321898  6088 master.cpp:1184] Sending 1 offers to framework 201203291014-0-0009
I0329 10:21:28.323397  6088 master.cpp:679] Received reply for offer 201203291014-0-380
I0329 10:21:28.323536  6088 master.cpp:1403] Filtered slave 201203291014-0-2 for framework 201203291014-0-0009 for 1 seconds
I0329 10:21:29.323608  6088 master.cpp:1184] Sending 1 offers to framework 201203291014-0-0008
I0329 10:21:29.325008  6088 master.cpp:679] Received reply for offer 201203291014-0-381
I0329 10:21:29.325158  6088 master.cpp:1403] Filtered slave 201203291014-0-2 for framework 201203291014-0-0008 for 1 seconds
I0329 10:21:30.325261  6088 master.cpp:1184] Sending 1 offers to framework 201203291014-0-0009
I0329 10:21:30.326684  6088 master.cpp:679] Received reply for offer 201203291014-0-382
I0329 10:21:30.326858  6088 master.cpp:1403] Filtered slave 201203291014-0-2 for framework 201203291014-0-0009 for 1 seconds
I0329 10:21:31.326890  6088 master.cpp:1184] Sending 1 offers to framework 201203291014-0-0008
I0329 10:21:31.328343  6088 master.cpp:679] Received reply for offer 201203291014-0-383
I0329 10:21:31.328485  6088 master.cpp:1403] Filtered slave 201203291014-0-2 for framework 201203291014-0-0008 for 1 seconds
I0329 10:21:32.328533  6088 master.cpp:1184] Sending 1 offers to framework 201203291014-0-0009
I0329 10:21:32.329967  6088 master.cpp:679] Received reply for offer 201203291014-0-384
I0329 10:21:32.330106  6088 master.cpp:1403] Filtered slave 201203291014-0-2 for framework 201203291014-0-0009 for 1 seconds
I0329 10:21:33.330212  6088 master.cpp:1184] Sending 1 offers to framework 201203291014-0-0008
I0329 10:21:33.331703  6088 master.cpp:679] Received reply for offer 201203291014-0-385
I0329 10:21:33.331845  6088 master.cpp:1403] Filtered slave 201203291014-0-2 for framework 201203291014-0-0008 for 1 seconds
I0329 10:21:34.331897  6088 master.cpp:1184] Sending 1 offers to framework 201203291014-0-0009
I0329 10:21:34.333392  6088 master.cpp:679] Received reply for offer 201203291014-0-386
I0329 10:21:34.333475  6088 master.cpp:1403] Filtered slave 201203291014-0-2 for framework 201203291014-0-0009 for 1 seconds
I0329 10:21:35.333605  6088 master.cpp:1184] Sending 1 offers to framework 201203291014-0-0008
I0329 10:21:35.335001  6088 master.cpp:679] Received reply for offer 201203291014-0-387
I0329 10:21:35.335150  6088 master.cpp:1403] Filtered slave 201203291014-0-2 for framework 201203291014-0-0008 for 1 seconds
I0329 10:21:36.335209  6088 master.cpp:1184] Sending 1 offers to framework 201203291014-0-0009
I0329 10:21:36.336597  6088 master.cpp:679] Received reply for offer 201203291014-0-388
I0329 10:21:36.336781  6088 master.cpp:1403] Filtered slave 201203291014-0-2 for framework 201203291014-0-0009 for 1 seconds
I0329 10:21:37.336781  6088 master.cpp:1184] Sending 1 offers to framework 201203291014-0-0008
I0329 10:21:37.338129  6088 master.cpp:679] Received reply for offer 201203291014-0-389
I0329 10:21:37.338300  6088 master.cpp:1403] Filtered slave 201203291014-0-2 for framework 201203291014-0-0008 for 1 seconds
I0329 10:21:38.338307  6088 master.cpp:1184] Sending 1 offers to framework 201203291014-0-0009
I0329 10:21:38.339735  6088 master.cpp:679] Received reply for offer 201203291014-0-390
I0329 10:21:38.339874  6088 master.cpp:1403] Filtered slave 201203291014-0-2 for framework 201203291014-0-0009 for 1 seconds
I0329 10:21:39.339324  6088 master.cpp:1184] Sending 1 offers to framework 201203291014-0-0008
I0329 10:21:39.340688  6088 master.cpp:679] Received reply for offer 201203291014-0-391
I0329 10:21:39.340806  6088 master.cpp:1403] Filtered slave 201203291014-0-2 for framework 201203291014-0-0008 for 1 seconds
I0329 10:21:40.340869  6088 master.cpp:1184] Sending 1 offers to framework 201203291014-0-0009
I0329 10:21:40.342241  6088 master.cpp:679] Received reply for offer 201203291014-0-392
I0329 10:21:40.342377  6088 master.cpp:1403] Filtered slave 201203291014-0-2 for framework 201203291014-0-0009 for 1 seconds
I0329 10:21:41.342448  6088 master.cpp:1184] Sending 1 offers to framework 201203291014-0-0008
I0329 10:21:41.343868  6088 master.cpp:679] Received reply for offer 201203291014-0-393
I0329 10:21:41.344007  6088 master.cpp:1403] Filtered slave 201203291014-0-2 for framework 201203291014-0-0008 for 1 seconds
I0329 10:21:42.343322  6088 master.cpp:1184] Sending 1 offers to framework 201203291014-0-0009
I0329 10:21:42.344744  6088 master.cpp:679] Received reply for offer 201203291014-0-394
I0329 10:21:42.344914  6088 master.cpp:1403] Filtered slave 201203291014-0-2 for framework 201203291014-0-0009 for 1 seconds
I0329 10:21:43.344926  6088 master.cpp:1184] Sending 1 offers to framework 201203291014-0-0008
I0329 10:21:43.346290  6088 master.cpp:679] Received reply for offer 201203291014-0-395
I0329 10:21:43.346429  6088 master.cpp:1403] Filtered slave 201203291014-0-2 for framework 201203291014-0-0008 for 1 seconds
I0329 10:21:44.345685  6088 master.cpp:1184] Sending 1 offers to framework 201203291014-0-0009
I0329 10:21:44.347015  6088 master.cpp:679] Received reply for offer 201203291014-0-396
I0329 10:21:44.347209  6088 master.cpp:1403] Filtered slave 201203291014-0-2 for framework 201203291014-0-0009 for 1 seconds
I0329 10:21:45.347259  6088 master.cpp:1184] Sending 1 offers to framework 201203291014-0-0008
I0329 10:21:45.348649  6088 master.cpp:679] Received reply for offer 201203291014-0-397
I0329 10:21:45.348786  6088 master.cpp:1403] Filtered slave 201203291014-0-2 for framework 201203291014-0-0008 for 1 seconds
I0329 10:21:46.348736  6088 master.cpp:1184] Sending 1 offers to framework 201203291014-0-0009
I0329 10:21:46.350159  6088 master.cpp:679] Received reply for offer 201203291014-0-398
I0329 10:21:46.350296  6088 master.cpp:1403] Filtered slave 201203291014-0-2 for framework 201203291014-0-0009 for 1 seconds
I0329 10:21:47.350329  6088 master.cpp:1184] Sending 1 offers to framework 201203291014-0-0008
I0329 10:21:47.351744  6088 master.cpp:679] Received reply for offer 201203291014-0-399
I0329 10:21:47.351915  6088 master.cpp:1403] Filtered slave 201203291014-0-2 for framework 201203291014-0-0008 for 1 seconds
I0329 10:21:48.351933  6088 master.cpp:1184] Sending 1 offers to framework 201203291014-0-0009
I0329 10:21:48.353237  6088 master.cpp:679] Received reply for offer 201203291014-0-400
I0329 10:21:48.353374  6088 master.cpp:1403] Filtered slave 201203291014-0-2 for framework 201203291014-0-0009 for 1 seconds
I0329 10:21:49.353088  6088 master.cpp:1184] Sending 1 offers to framework 201203291014-0-0008
I0329 10:21:49.354480  6088 master.cpp:679] Received reply for offer 201203291014-0-401
I0329 10:21:49.354598  6088 master.cpp:1403] Filtered slave 201203291014-0-2 for framework 201203291014-0-0008 for 1 seconds
I0329 10:21:50.354675  6088 master.cpp:1184] Sending 1 offers to framework 201203291014-0-0009
I0329 10:21:50.356228  6088 master.cpp:679] Received reply for offer 201203291014-0-402
I0329 10:21:50.356367  6088 master.cpp:1403] Filtered slave 201203291014-0-2 for framework 201203291014-0-0009 for 1 seconds
I0329 10:21:51.355736  6088 master.cpp:1184] Sending 1 offers to framework 201203291014-0-0008
I0329 10:21:51.357261  6088 master.cpp:679] Received reply for offer 201203291014-0-403
I0329 10:21:51.357404  6088 master.cpp:1403] Filtered slave 201203291014-0-2 for framework 201203291014-0-0008 for 1 seconds
I0329 10:21:52.357409  6088 master.cpp:1184] Sending 1 offers to framework 201203291014-0-0009
I0329 10:21:52.358784  6088 master.cpp:679] Received reply for offer 201203291014-0-404
I0329 10:21:52.358922  6088 master.cpp:1403] Filtered slave 201203291014-0-2 for framework 201203291014-0-0009 for 1 seconds
I0329 10:21:53.358949  6088 master.cpp:1184] Sending 1 offers to framework 201203291014-0-0008
I0329 10:21:53.360379  6088 master.cpp:679] Received reply for offer 201203291014-0-405
I0329 10:21:53.360520  6088 master.cpp:1403] Filtered slave 201203291014-0-2 for framework 201203291014-0-0008 for 1 seconds
I0329 10:21:54.360584  6088 master.cpp:1184] Sending 1 offers to framework 201203291014-0-0009
I0329 10:21:54.361989  6088 master.cpp:679] Received reply for offer 201203291014-0-406
I0329 10:21:54.362103  6088 master.cpp:1403] Filtered slave 201203291014-0-2 for framework 201203291014-0-0009 for 1 seconds
I0329 10:21:55.362200  6088 master.cpp:1184] Sending 1 offers to framework 201203291014-0-0008
I0329 10:21:55.363627  6088 master.cpp:679] Received reply for offer 201203291014-0-407
I0329 10:21:55.363769  6088 master.cpp:1403] Filtered slave 201203291014-0-2 for framework 201203291014-0-0008 for 1 seconds
I0329 10:21:56.363832  6088 master.cpp:1184] Sending 1 offers to framework 201203291014-0-0009
I0329 10:21:56.365385  6088 master.cpp:679] Received reply for offer 201203291014-0-408
I0329 10:21:56.365521  6088 master.cpp:1403] Filtered slave 201203291014-0-2 for framework 201203291014-0-0009 for 1 seconds
I0329 10:21:57.365567  6088 master.cpp:1184] Sending 1 offers to framework 201203291014-0-0008
I0329 10:21:57.366977  6088 master.cpp:679] Received reply for offer 201203291014-0-409
I0329 10:21:57.367180  6088 master.cpp:1403] Filtered slave 201203291014-0-2 for framework 201203291014-0-0008 for 1 seconds
I0329 10:21:58.367161  6088 master.cpp:1184] Sending 1 offers to framework 201203291014-0-0009
I0329 10:21:58.368710  6088 master.cpp:679] Received reply for offer 201203291014-0-410
I0329 10:21:58.368849  6088 master.cpp:1403] Filtered slave 201203291014-0-2 for framework 201203291014-0-0009 for 1 seconds
I0329 10:21:59.368892  6088 master.cpp:1184] Sending 1 offers to framework 201203291014-0-0008
I0329 10:21:59.370270  6088 master.cpp:679] Received reply for offer 201203291014-0-411
I0329 10:21:59.370354  6088 master.cpp:1403] Filtered slave 201203291014-0-2 for framework 201203291014-0-0008 for 1 seconds
I0329 10:22:00.370484  6088 master.cpp:1184] Sending 1 offers to framework 201203291014-0-0009
I0329 10:22:00.371937  6088 master.cpp:679] Received reply for offer 201203291014-0-412
I0329 10:22:00.372076  6088 master.cpp:1403] Filtered slave 201203291014-0-2 for framework 201203291014-0-0009 for 1 seconds
I0329 10:22:01.372022  6088 master.cpp:1184] Sending 1 offers to framework 201203291014-0-0008
I0329 10:22:01.373625  6088 master.cpp:679] Received reply for offer 201203291014-0-413
I0329 10:22:01.373764  6088 master.cpp:1403] Filtered slave 201203291014-0-2 for framework 201203291014-0-0008 for 1 seconds
I0329 10:22:02.373831  6088 master.cpp:1184] Sending 1 offers to framework 201203291014-0-0009
I0329 10:22:02.375242  6088 master.cpp:679] Received reply for offer 201203291014-0-414
I0329 10:22:02.375381  6088 master.cpp:1403] Filtered slave 201203291014-0-2 for framework 201203291014-0-0009 for 1 seconds
I0329 10:22:03.375443  6088 master.cpp:1184] Sending 1 offers to framework 201203291014-0-0008
I0329 10:22:03.377033  6088 master.cpp:679] Received reply for offer 201203291014-0-415
I0329 10:22:03.377172  6088 master.cpp:1403] Filtered slave 201203291014-0-2 for framework 201203291014-0-0008 for 1 seconds
I0329 10:22:04.377223  6088 master.cpp:1184] Sending 1 offers to framework 201203291014-0-0009
I0329 10:22:04.378592  6088 master.cpp:679] Received reply for offer 201203291014-0-416
I0329 10:22:04.378674  6088 master.cpp:1403] Filtered slave 201203291014-0-2 for framework 201203291014-0-0009 for 1 seconds
I0329 10:22:05.378793  6088 master.cpp:1184] Sending 1 offers to framework 201203291014-0-0008
I0329 10:22:05.380349  6088 master.cpp:679] Received reply for offer 201203291014-0-417
I0329 10:22:05.380489  6088 master.cpp:1403] Filtered slave 201203291014-0-2 for framework 201203291014-0-0008 for 1 seconds
I0329 10:22:06.380549  6088 master.cpp:1184] Sending 1 offers to framework 201203291014-0-0009
I0329 10:22:06.381916  6088 master.cpp:679] Received reply for offer 201203291014-0-418
I0329 10:22:06.382053  6088 master.cpp:1403] Filtered slave 201203291014-0-2 for framework 201203291014-0-0009 for 1 seconds
I0329 10:22:07.382104  6088 master.cpp:1184] Sending 1 offers to framework 201203291014-0-0008
I0329 10:22:07.383692  6088 master.cpp:679] Received reply for offer 201203291014-0-419
I0329 10:22:07.383832  6088 master.cpp:1403] Filtered slave 201203291014-0-2 for framework 201203291014-0-0008 for 1 seconds
I0329 10:22:08.383893  6088 master.cpp:1184] Sending 1 offers to framework 201203291014-0-0009
I0329 10:22:08.385345  6088 master.cpp:679] Received reply for offer 201203291014-0-420
I0329 10:22:08.385481  6088 master.cpp:1403] Filtered slave 201203291014-0-2 for framework 201203291014-0-0009 for 1 seconds
I0329 10:22:09.385530  6088 master.cpp:1184] Sending 1 offers to framework 201203291014-0-0008
I0329 10:22:09.386926  6088 master.cpp:679] Received reply for offer 201203291014-0-421
I0329 10:22:09.387043  6088 master.cpp:1403] Filtered slave 201203291014-0-2 for framework 201203291014-0-0008 for 1 seconds
I0329 10:22:10.387116  6088 master.cpp:1184] Sending 1 offers to framework 201203291014-0-0009
I0329 10:22:10.388684  6088 master.cpp:679] Received reply for offer 201203291014-0-422
I0329 10:22:10.388854  6088 master.cpp:1403] Filtered slave 201203291014-0-2 for framework 201203291014-0-0009 for 1 seconds
I0329 10:22:11.388895  6088 master.cpp:1184] Sending 1 offers to framework 201203291014-0-0008
I0329 10:22:11.390312  6088 master.cpp:679] Received reply for offer 201203291014-0-423
I0329 10:22:11.390488  6088 master.cpp:1403] Filtered slave 201203291014-0-2 for framework 201203291014-0-0008 for 1 seconds
I0329 10:22:12.390470  6088 master.cpp:1184] Sending 1 offers to framework 201203291014-0-0009
I0329 10:22:12.391907  6088 master.cpp:679] Received reply for offer 201203291014-0-424
I0329 10:22:12.392045  6088 master.cpp:1403] Filtered slave 201203291014-0-2 for framework 201203291014-0-0009 for 1 seconds
I0329 10:22:13.392113  6088 master.cpp:1184] Sending 1 offers to framework 201203291014-0-0008
I0329 10:22:13.393708  6088 master.cpp:679] Received reply for offer 201203291014-0-425
I0329 10:22:13.393846  6088 master.cpp:1403] Filtered slave 201203291014-0-2 for framework 201203291014-0-0008 for 1 seconds
I0329 10:22:14.393919  6088 master.cpp:1184] Sending 1 offers to framework 201203291014-0-0009
I0329 10:22:14.395447  6088 master.cpp:679] Received reply for offer 201203291014-0-426
I0329 10:22:14.395531  6088 master.cpp:1403] Filtered slave 201203291014-0-2 for framework 201203291014-0-0009 for 1 seconds
I0329 10:22:15.395653  6088 master.cpp:1184] Sending 1 offers to framework 201203291014-0-0008
I0329 10:22:15.397073  6088 master.cpp:679] Received reply for offer 201203291014-0-427
I0329 10:22:15.397212  6088 master.cpp:1403] Filtered slave 201203291014-0-2 for framework 201203291014-0-0008 for 1 seconds
I0329 10:22:16.397145  6088 master.cpp:1184] Sending 1 offers to framework 201203291014-0-0009
I0329 10:22:16.398684  6088 master.cpp:679] Received reply for offer 201203291014-0-428
I0329 10:22:16.398820  6088 master.cpp:1403] Filtered slave 201203291014-0-2 for framework 201203291014-0-0009 for 1 seconds
I0329 10:22:17.398921  6088 master.cpp:1184] Sending 1 offers to framework 201203291014-0-0008
I0329 10:22:17.400236  6088 master.cpp:679] Received reply for offer 201203291014-0-429
I0329 10:22:17.400374  6088 master.cpp:1403] Filtered slave 201203291014-0-2 for framework 201203291014-0-0008 for 1 seconds
I0329 10:22:18.400418  6088 master.cpp:1184] Sending 1 offers to framework 201203291014-0-0009
I0329 10:22:18.401790  6088 master.cpp:679] Received reply for offer 201203291014-0-430
I0329 10:22:18.401927  6088 master.cpp:1403] Filtered slave 201203291014-0-2 for framework 201203291014-0-0009 for 1 seconds
I0329 10:22:19.402000  6088 master.cpp:1184] Sending 1 offers to framework 201203291014-0-0008
I0329 10:22:19.403415  6088 master.cpp:679] Received reply for offer 201203291014-0-431
I0329 10:22:19.403501  6088 master.cpp:1403] Filtered slave 201203291014-0-2 for framework 201203291014-0-0008 for 1 seconds
I0329 10:22:20.403622  6088 master.cpp:1184] Sending 1 offers to framework 201203291014-0-0009
I0329 10:22:20.405030  6088 master.cpp:679] Received reply for offer 201203291014-0-432
I0329 10:22:20.405168  6088 master.cpp:1403] Filtered slave 201203291014-0-2 for framework 201203291014-0-0009 for 1 seconds
I0329 10:22:21.405237  6088 master.cpp:1184] Sending 1 offers to framework 201203291014-0-0008
I0329 10:22:21.406648  6088 master.cpp:679] Received reply for offer 201203291014-0-433
I0329 10:22:21.406824  6088 master.cpp:1403] Filtered slave 201203291014-0-2 for framework 201203291014-0-0008 for 1 seconds
I0329 10:22:22.406924  6088 master.cpp:1184] Sending 1 offers to framework 201203291014-0-0009
I0329 10:22:22.408335  6088 master.cpp:679] Received reply for offer 201203291014-0-434
I0329 10:22:22.408473  6088 master.cpp:1403] Filtered slave 201203291014-0-2 for framework 201203291014-0-0009 for 1 seconds
I0329 10:22:23.407769  6088 master.cpp:1184] Sending 1 offers to framework 201203291014-0-0008
I0329 10:22:23.408910  6088 master.cpp:679] Received reply for offer 201203291014-0-435
I0329 10:22:23.409025  6088 master.cpp:1403] Filtered slave 201203291014-0-2 for framework 201203291014-0-0008 for 1 seconds
I0329 10:22:24.410099  6088 master.cpp:1184] Sending 1 offers to framework 201203291014-0-0009
I0329 10:22:24.411504  6088 master.cpp:679] Received reply for offer 201203291014-0-436
I0329 10:22:24.411588  6088 master.cpp:1403] Filtered slave 201203291014-0-2 for framework 201203291014-0-0009 for 1 seconds
I0329 10:22:25.411708  6088 master.cpp:1184] Sending 1 offers to framework 201203291014-0-0008
I0329 10:22:25.413120  6088 master.cpp:679] Received reply for offer 201203291014-0-437
I0329 10:22:25.413259  6088 master.cpp:1403] Filtered slave 201203291014-0-2 for framework 201203291014-0-0008 for 1 seconds
I0329 10:22:26.413347  6088 master.cpp:1184] Sending 1 offers to framework 201203291014-0-0009
I0329 10:22:26.414783  6088 master.cpp:679] Received reply for offer 201203291014-0-438
I0329 10:22:26.414919  6088 master.cpp:1403] Filtered slave 201203291014-0-2 for framework 201203291014-0-0009 for 1 seconds
I0329 10:22:27.414984  6088 master.cpp:1184] Sending 1 offers to framework 201203291014-0-0008
I0329 10:22:27.416404  6088 master.cpp:679] Received reply for offer 201203291014-0-439
I0329 10:22:27.416543  6088 master.cpp:1403] Filtered slave 201203291014-0-2 for framework 201203291014-0-0008 for 1 seconds
I0329 10:22:28.416616  6088 master.cpp:1184] Sending 1 offers to framework 201203291014-0-0009
I0329 10:22:28.418025  6088 master.cpp:679] Received reply for offer 201203291014-0-440
I0329 10:22:28.418160  6088 master.cpp:1403] Filtered slave 201203291014-0-2 for framework 201203291014-0-0009 for 1 seconds
I0329 10:22:29.418234  6088 master.cpp:1184] Sending 1 offers to framework 201203291014-0-0008
I0329 10:22:29.419631  6088 master.cpp:679] Received reply for offer 201203291014-0-441
I0329 10:22:29.419749  6088 master.cpp:1403] Filtered slave 201203291014-0-2 for framework 201203291014-0-0008 for 1 seconds
I0329 10:22:30.419828  6088 master.cpp:1184] Sending 1 offers to framework 201203291014-0-0009
I0329 10:22:30.421264  6088 master.cpp:679] Received reply for offer 201203291014-0-442
I0329 10:22:30.421432  6088 master.cpp:1403] Filtered slave 201203291014-0-2 for framework 201203291014-0-0009 for 1 seconds
I0329 10:22:31.421368  6088 master.cpp:1184] Sending 1 offers to framework 201203291014-0-0008
I0329 10:22:31.422796  6088 master.cpp:679] Received reply for offer 201203291014-0-443
I0329 10:22:31.422934  6088 master.cpp:1403] Filtered slave 201203291014-0-2 for framework 201203291014-0-0008 for 1 seconds
I0329 10:22:32.423009  6088 master.cpp:1184] Sending 1 offers to framework 201203291014-0-0009
I0329 10:22:32.424434  6088 master.cpp:679] Received reply for offer 201203291014-0-444
I0329 10:22:32.424574  6088 master.cpp:1403] Filtered slave 201203291014-0-2 for framework 201203291014-0-0009 for 1 seconds
I0329 10:22:33.424653  6088 master.cpp:1184] Sending 1 offers to framework 201203291014-0-0008
I0329 10:22:33.426072  6088 master.cpp:679] Received reply for offer 201203291014-0-445
I0329 10:22:33.426213  6088 master.cpp:1403] Filtered slave 201203291014-0-2 for framework 201203291014-0-0008 for 1 seconds
I0329 10:22:34.426281  6088 master.cpp:1184] Sending 1 offers to framework 201203291014-0-0009
I0329 10:22:34.427757  6088 master.cpp:679] Received reply for offer 201203291014-0-446
I0329 10:22:34.427870  6088 master.cpp:1403] Filtered slave 201203291014-0-2 for framework 201203291014-0-0009 for 1 seconds
I0329 10:22:35.427973  6088 master.cpp:1184] Sending 1 offers to framework 201203291014-0-0008
I0329 10:22:35.429365  6088 master.cpp:679] Received reply for offer 201203291014-0-447
I0329 10:22:35.429507  6088 master.cpp:1403] Filtered slave 201203291014-0-2 for framework 201203291014-0-0008 for 1 seconds
I0329 10:22:36.429569  6088 master.cpp:1184] Sending 1 offers to framework 201203291014-0-0009
I0329 10:22:36.430958  6088 master.cpp:679] Received reply for offer 201203291014-0-448
I0329 10:22:36.431161  6088 master.cpp:1403] Filtered slave 201203291014-0-2 for framework 201203291014-0-0009 for 1 seconds
I0329 10:22:37.431164  6088 master.cpp:1184] Sending 1 offers to framework 201203291014-0-0008
I0329 10:22:37.432587  6088 master.cpp:679] Received reply for offer 201203291014-0-449
I0329 10:22:37.432728  6088 master.cpp:1403] Filtered slave 201203291014-0-2 for framework 201203291014-0-0008 for 1 seconds
I0329 10:22:38.432770  6088 master.cpp:1184] Sending 1 offers to framework 201203291014-0-0009
I0329 10:22:38.434192  6088 master.cpp:679] Received reply for offer 201203291014-0-450
I0329 10:22:38.434329  6088 master.cpp:1403] Filtered slave 201203291014-0-2 for framework 201203291014-0-0009 for 1 seconds
I0329 10:22:39.434373  6088 master.cpp:1184] Sending 1 offers to framework 201203291014-0-0008
I0329 10:22:39.435762  6088 master.cpp:679] Received reply for offer 201203291014-0-451
I0329 10:22:39.435878  6088 master.cpp:1403] Filtered slave 201203291014-0-2 for framework 201203291014-0-0008 for 1 seconds
I0329 10:22:40.435966  6088 master.cpp:1184] Sending 1 offers to framework 201203291014-0-0009
I0329 10:22:40.437422  6088 master.cpp:679] Received reply for offer 201203291014-0-452
I0329 10:22:40.437558  6088 master.cpp:1403] Filtered slave 201203291014-0-2 for framework 201203291014-0-0009 for 1 seconds
I0329 10:22:41.437608  6088 master.cpp:1184] Sending 1 offers to framework 201203291014-0-0008
I0329 10:22:41.438985  6088 master.cpp:679] Received reply for offer 201203291014-0-453
I0329 10:22:41.439170  6088 master.cpp:1403] Filtered slave 201203291014-0-2 for framework 201203291014-0-0008 for 1 seconds
I0329 10:22:42.438488  6088 master.cpp:1184] Sending 1 offers to framework 201203291014-0-0009
I0329 10:22:42.440042  6088 master.cpp:679] Received reply for offer 201203291014-0-454
I0329 10:22:42.440182  6088 master.cpp:1403] Filtered slave 201203291014-0-2 for framework 201203291014-0-0009 for 1 seconds
I0329 10:22:43.440227  6088 master.cpp:1184] Sending 1 offers to framework 201203291014-0-0008
I0329 10:22:43.441614  6088 master.cpp:679] Received reply for offer 201203291014-0-455
I0329 10:22:43.441787  6088 master.cpp:1403] Filtered slave 201203291014-0-2 for framework 201203291014-0-0008 for 1 seconds
I0329 10:22:44.441087  6088 master.cpp:1184] Sending 1 offers to framework 201203291014-0-0009
I0329 10:22:44.442512  6088 master.cpp:679] Received reply for offer 201203291014-0-456
I0329 10:22:44.442623  6088 master.cpp:1403] Filtered slave 201203291014-0-2 for framework 201203291014-0-0009 for 1 seconds
I0329 10:22:45.442155  6088 master.cpp:1184] Sending 1 offers to framework 201203291014-0-0008
I0329 10:22:45.443644  6088 master.cpp:679] Received reply for offer 201203291014-0-457
I0329 10:22:45.443794  6088 master.cpp:1403] Filtered slave 201203291014-0-2 for framework 201203291014-0-0008 for 1 seconds
I0329 10:22:46.443367  6088 master.cpp:1184] Sending 1 offers to framework 201203291014-0-0009
I0329 10:22:46.444788  6088 master.cpp:679] Received reply for offer 201203291014-0-458
I0329 10:22:46.444926  6088 master.cpp:1403] Filtered slave 201203291014-0-2 for framework 201203291014-0-0009 for 1 seconds
I0329 10:22:47.445003  6088 master.cpp:1184] Sending 1 offers to framework 201203291014-0-0008
I0329 10:22:47.446333  6088 master.cpp:679] Received reply for offer 201203291014-0-459
I0329 10:22:47.446473  6088 master.cpp:1403] Filtered slave 201203291014-0-2 for framework 201203291014-0-0008 for 1 seconds
I0329 10:22:48.446540  6088 master.cpp:1184] Sending 1 offers to framework 201203291014-0-0009
I0329 10:22:48.447932  6088 master.cpp:679] Received reply for offer 201203291014-0-460
I0329 10:22:48.448070  6088 master.cpp:1403] Filtered slave 201203291014-0-2 for framework 201203291014-0-0009 for 1 seconds
I0329 10:22:49.448163  6088 master.cpp:1184] Sending 1 offers to framework 201203291014-0-0008
I0329 10:22:49.449591  6088 master.cpp:679] Received reply for offer 201203291014-0-461
I0329 10:22:49.449729  6088 master.cpp:1403] Filtered slave 201203291014-0-2 for framework 201203291014-0-0008 for 1 seconds
I0329 10:22:50.449808  6088 master.cpp:1184] Sending 1 offers to framework 201203291014-0-0009
I0329 10:22:50.451390  6088 master.cpp:679] Received reply for offer 201203291014-0-462
I0329 10:22:50.451532  6088 master.cpp:1403] Filtered slave 201203291014-0-2 for framework 201203291014-0-0009 for 1 seconds
I0329 10:22:51.451591  6088 master.cpp:1184] Sending 1 offers to framework 201203291014-0-0008
I0329 10:22:51.453042  6088 master.cpp:679] Received reply for offer 201203291014-0-463
I0329 10:22:51.453181  6088 master.cpp:1403] Filtered slave 201203291014-0-2 for framework 201203291014-0-0008 for 1 seconds
I0329 10:22:52.453266  6088 master.cpp:1184] Sending 1 offers to framework 201203291014-0-0009
I0329 10:22:52.454872  6088 master.cpp:679] Received reply for offer 201203291014-0-464
I0329 10:22:52.455008  6088 master.cpp:1403] Filtered slave 201203291014-0-2 for framework 201203291014-0-0009 for 1 seconds
I0329 10:22:53.455070  6088 master.cpp:1184] Sending 1 offers to framework 201203291014-0-0008
I0329 10:22:53.456792  6088 master.cpp:679] Received reply for offer 201203291014-0-465
I0329 10:22:53.456933  6088 master.cpp:1403] Filtered slave 201203291014-0-2 for framework 201203291014-0-0008 for 1 seconds
I0329 10:22:54.456374  6088 master.cpp:1184] Sending 1 offers to framework 201203291014-0-0009
I0329 10:22:54.457942  6088 master.cpp:679] Received reply for offer 201203291014-0-466
I0329 10:22:54.458034  6088 master.cpp:1403] Filtered slave 201203291014-0-2 for framework 201203291014-0-0009 for 1 seconds
I0329 10:22:55.458153  6088 master.cpp:1184] Sending 1 offers to framework 201203291014-0-0008
I0329 10:22:55.459552  6088 master.cpp:679] Received reply for offer 201203291014-0-467
I0329 10:22:55.459692  6088 master.cpp:1403] Filtered slave 201203291014-0-2 for framework 201203291014-0-0008 for 1 seconds
I0329 10:22:56.459774  6088 master.cpp:1184] Sending 1 offers to framework 201203291014-0-0009
I0329 10:22:56.461269  6088 master.cpp:679] Received reply for offer 201203291014-0-468
I0329 10:22:56.461413  6088 master.cpp:1403] Filtered slave 201203291014-0-2 for framework 201203291014-0-0009 for 1 seconds
I0329 10:22:57.461457  6088 master.cpp:1184] Sending 1 offers to framework 201203291014-0-0008
I0329 10:22:57.462888  6088 master.cpp:679] Received reply for offer 201203291014-0-469
I0329 10:22:57.463027  6088 master.cpp:1403] Filtered slave 201203291014-0-2 for framework 201203291014-0-0008 for 1 seconds
I0329 10:22:58.463062  6088 master.cpp:1184] Sending 1 offers to framework 201203291014-0-0009
I0329 10:22:58.464521  6088 master.cpp:679] Received reply for offer 201203291014-0-470
I0329 10:22:58.464690  6088 master.cpp:1403] Filtered slave 201203291014-0-2 for framework 201203291014-0-0009 for 1 seconds
I0329 10:22:59.464732  6088 master.cpp:1184] Sending 1 offers to framework 201203291014-0-0008
I0329 10:22:59.466271  6088 master.cpp:679] Received reply for offer 201203291014-0-471
I0329 10:22:59.466357  6088 master.cpp:1403] Filtered slave 201203291014-0-2 for framework 201203291014-0-0008 for 1 seconds
I0329 10:23:00.466490  6088 master.cpp:1184] Sending 1 offers to framework 201203291014-0-0009
I0329 10:23:00.468027  6088 master.cpp:679] Received reply for offer 201203291014-0-472
I0329 10:23:00.468196  6088 master.cpp:1403] Filtered slave 201203291014-0-2 for framework 201203291014-0-0009 for 1 seconds
I0329 10:23:01.467895  6088 master.cpp:1184] Sending 1 offers to framework 201203291014-0-0008
I0329 10:23:01.469523  6088 master.cpp:679] Received reply for offer 201203291014-0-473
I0329 10:23:01.469663  6088 master.cpp:1403] Filtered slave 201203291014-0-2 for framework 201203291014-0-0008 for 1 seconds
I0329 10:23:02.469706  6088 master.cpp:1184] Sending 1 offers to framework 201203291014-0-0009
I0329 10:23:02.471384  6088 master.cpp:679] Received reply for offer 201203291014-0-474
I0329 10:23:02.471524  6088 master.cpp:1403] Filtered slave 201203291014-0-2 for framework 201203291014-0-0009 for 1 seconds
I0329 10:23:03.471149  6088 master.cpp:1184] Sending 1 offers to framework 201203291014-0-0008
I0329 10:23:03.472707  6088 master.cpp:679] Received reply for offer 201203291014-0-475
I0329 10:23:03.472877  6088 master.cpp:1403] Filtered slave 201203291014-0-2 for framework 201203291014-0-0008 for 1 seconds
I0329 10:23:04.472934  6088 master.cpp:1184] Sending 1 offers to framework 201203291014-0-0009
I0329 10:23:04.474573  6088 master.cpp:679] Received reply for offer 201203291014-0-476
I0329 10:23:04.474655  6088 master.cpp:1403] Filtered slave 201203291014-0-2 for framework 201203291014-0-0009 for 1 seconds
I0329 10:23:05.474792  6088 master.cpp:1184] Sending 1 offers to framework 201203291014-0-0008
I0329 10:23:05.476380  6088 master.cpp:679] Received reply for offer 201203291014-0-477
I0329 10:23:05.476522  6088 master.cpp:1403] Filtered slave 201203291014-0-2 for framework 201203291014-0-0008 for 1 seconds
I0329 10:23:06.476605  6088 master.cpp:1184] Sending 1 offers to framework 201203291014-0-0009
I0329 10:23:06.478214  6088 master.cpp:679] Received reply for offer 201203291014-0-478
I0329 10:23:06.478353  6088 master.cpp:1403] Filtered slave 201203291014-0-2 for framework 201203291014-0-0009 for 1 seconds
I0329 10:23:07.478437  6088 master.cpp:1184] Sending 1 offers to framework 201203291014-0-0008
I0329 10:23:07.479882  6088 master.cpp:679] Received reply for offer 201203291014-0-479
I0329 10:23:07.480025  6088 master.cpp:1403] Filtered slave 201203291014-0-2 for framework 201203291014-0-0008 for 1 seconds
I0329 10:23:08.480105  6088 master.cpp:1184] Sending 1 offers to framework 201203291014-0-0009
I0329 10:23:08.481714  6088 master.cpp:679] Received reply for offer 201203291014-0-480
I0329 10:23:08.481850  6088 master.cpp:1403] Filtered slave 201203291014-0-2 for framework 201203291014-0-0009 for 1 seconds
I0329 10:23:09.481899  6088 master.cpp:1184] Sending 1 offers to framework 201203291014-0-0008
I0329 10:23:09.483135  6088 master.cpp:679] Received reply for offer 201203291014-0-481
I0329 10:23:09.483199  6088 master.cpp:1403] Filtered slave 201203291014-0-2 for framework 201203291014-0-0008 for 1 seconds
I0329 10:23:10.483263  6088 master.cpp:1184] Sending 1 offers to framework 201203291014-0-0009
I0329 10:23:10.484348  6088 master.cpp:679] Received reply for offer 201203291014-0-482
I0329 10:23:10.484462  6088 master.cpp:1403] Filtered slave 201203291014-0-2 for framework 201203291014-0-0009 for 1 seconds
I0329 10:23:11.485575  6088 master.cpp:1184] Sending 1 offers to framework 201203291014-0-0008
I0329 10:23:11.487033  6088 master.cpp:679] Received reply for offer 201203291014-0-483
I0329 10:23:11.487221  6088 master.cpp:1403] Filtered slave 201203291014-0-2 for framework 201203291014-0-0008 for 1 seconds
I0329 10:23:12.487241  6088 master.cpp:1184] Sending 1 offers to framework 201203291014-0-0009
I0329 10:23:12.488899  6088 master.cpp:679] Received reply for offer 201203291014-0-484
I0329 10:23:12.489070  6088 master.cpp:1403] Filtered slave 201203291014-0-2 for framework 201203291014-0-0009 for 1 seconds
I0329 10:23:13.489117  6088 master.cpp:1184] Sending 1 offers to framework 201203291014-0-0008
I0329 10:23:13.490664  6088 master.cpp:679] Received reply for offer 201203291014-0-485
I0329 10:23:13.490804  6088 master.cpp:1403] Filtered slave 201203291014-0-2 for framework 201203291014-0-0008 for 1 seconds
I0329 10:23:14.490890  6088 master.cpp:1184] Sending 1 offers to framework 201203291014-0-0009
I0329 10:23:14.492565  6088 master.cpp:679] Received reply for offer 201203291014-0-486
I0329 10:23:14.492648  6088 master.cpp:1403] Filtered slave 201203291014-0-2 for framework 201203291014-0-0009 for 1 seconds
I0329 10:23:15.492745  6088 master.cpp:1184] Sending 1 offers to framework 201203291014-0-0008
I0329 10:23:15.494206  6088 master.cpp:679] Received reply for offer 201203291014-0-487
I0329 10:23:15.494348  6088 master.cpp:1403] Filtered slave 201203291014-0-2 for framework 201203291014-0-0008 for 1 seconds
I0329 10:23:16.494125  6088 master.cpp:1184] Sending 1 offers to framework 201203291014-0-0009
I0329 10:23:16.495472  6088 master.cpp:679] Received reply for offer 201203291014-0-488
I0329 10:23:16.495585  6088 master.cpp:1403] Filtered slave 201203291014-0-2 for framework 201203291014-0-0009 for 1 seconds
I0329 10:23:17.495698  6088 master.cpp:1184] Sending 1 offers to framework 201203291014-0-0008
I0329 10:23:17.497145  6088 master.cpp:679] Received reply for offer 201203291014-0-489
I0329 10:23:17.497349  6088 master.cpp:1403] Filtered slave 201203291014-0-2 for framework 201203291014-0-0008 for 1 seconds
I0329 10:23:18.497364  6088 master.cpp:1184] Sending 1 offers to framework 201203291014-0-0009
I0329 10:23:18.498848  6088 master.cpp:679] Received reply for offer 201203291014-0-490
I0329 10:23:18.499049  6088 master.cpp:1403] Filtered slave 201203291014-0-2 for framework 201203291014-0-0009 for 1 seconds
I0329 10:23:19.499068  6088 master.cpp:1184] Sending 1 offers to framework 201203291014-0-0008
I0329 10:23:19.500612  6088 master.cpp:679] Received reply for offer 201203291014-0-491
I0329 10:23:19.500697  6088 master.cpp:1403] Filtered slave 201203291014-0-2 for framework 201203291014-0-0008 for 1 seconds
I0329 10:23:20.500170  6088 master.cpp:1184] Sending 1 offers to framework 201203291014-0-0009
I0329 10:23:20.501763  6088 master.cpp:679] Received reply for offer 201203291014-0-492
I0329 10:23:20.501903  6088 master.cpp:1403] Filtered slave 201203291014-0-2 for framework 201203291014-0-0009 for 1 seconds
I0329 10:23:21.501276  6088 master.cpp:1184] Sending 1 offers to framework 201203291014-0-0008
I0329 10:23:21.502687  6088 master.cpp:679] Received reply for offer 201203291014-0-493
I0329 10:23:21.502827  6088 master.cpp:1403] Filtered slave 201203291014-0-2 for framework 201203291014-0-0008 for 1 seconds
I0329 10:23:22.502903  6088 master.cpp:1184] Sending 1 offers to framework 201203291014-0-0009
I0329 10:23:22.504559  6088 master.cpp:679] Received reply for offer 201203291014-0-494
I0329 10:23:22.504696  6088 master.cpp:1403] Filtered slave 201203291014-0-2 for framework 201203291014-0-0009 for 1 seconds
I0329 10:23:23.504833  6088 master.cpp:1184] Sending 1 offers to framework 201203291014-0-0008
I0329 10:23:23.506222  6088 master.cpp:679] Received reply for offer 201203291014-0-495
I0329 10:23:23.506398  6088 master.cpp:1403] Filtered slave 201203291014-0-2 for framework 201203291014-0-0008 for 1 seconds
I0329 10:23:24.506479  6088 master.cpp:1184] Sending 1 offers to framework 201203291014-0-0009
I0329 10:23:24.507820  6088 master.cpp:679] Received reply for offer 201203291014-0-496
I0329 10:23:24.507905  6088 master.cpp:1403] Filtered slave 201203291014-0-2 for framework 201203291014-0-0009 for 1 seconds
I0329 10:23:25.507966  6088 master.cpp:1184] Sending 1 offers to framework 201203291014-0-0008
I0329 10:23:25.509449  6088 master.cpp:679] Received reply for offer 201203291014-0-497
I0329 10:23:25.509589  6088 master.cpp:1403] Filtered slave 201203291014-0-2 for framework 201203291014-0-0008 for 1 seconds
I0329 10:23:26.509635  6088 master.cpp:1184] Sending 1 offers to framework 201203291014-0-0009
I0329 10:23:26.511103  6088 master.cpp:679] Received reply for offer 201203291014-0-498
I0329 10:23:26.511248  6088 master.cpp:1403] Filtered slave 201203291014-0-2 for framework 201203291014-0-0009 for 1 seconds
I0329 10:23:27.511276  6088 master.cpp:1184] Sending 1 offers to framework 201203291014-0-0008
I0329 10:23:27.512681  6088 master.cpp:679] Received reply for offer 201203291014-0-499
I0329 10:23:27.512820  6088 master.cpp:1403] Filtered slave 201203291014-0-2 for framework 201203291014-0-0008 for 1 seconds
I0329 10:23:28.512881  6088 master.cpp:1184] Sending 1 offers to framework 201203291014-0-0009
I0329 10:23:28.514345  6088 master.cpp:679] Received reply for offer 201203291014-0-500
I0329 10:23:28.514483  6088 master.cpp:1403] Filtered slave 201203291014-0-2 for framework 201203291014-0-0009 for 1 seconds
I0329 10:23:29.514538  6088 master.cpp:1184] Sending 1 offers to framework 201203291014-0-0008
I0329 10:23:29.516093  6088 master.cpp:679] Received reply for offer 201203291014-0-501
I0329 10:23:29.516180  6088 master.cpp:1403] Filtered slave 201203291014-0-2 for framework 201203291014-0-0008 for 1 seconds
I0329 10:23:30.516317  6088 master.cpp:1184] Sending 1 offers to framework 201203291014-0-0009
I0329 10:23:30.517741  6088 master.cpp:679] Received reply for offer 201203291014-0-502
I0329 10:23:30.517885  6088 master.cpp:1403] Filtered slave 201203291014-0-2 for framework 201203291014-0-0009 for 1 seconds
I0329 10:23:31.517189  6088 master.cpp:1184] Sending 1 offers to framework 201203291014-0-0008
I0329 10:23:31.518726  6088 master.cpp:679] Received reply for offer 201203291014-0-503
I0329 10:23:31.518868  6088 master.cpp:1403] Filtered slave 201203291014-0-2 for framework 201203291014-0-0008 for 1 seconds
I0329 10:23:32.518949  6088 master.cpp:1184] Sending 1 offers to framework 201203291014-0-0009
I0329 10:23:32.520418  6088 master.cpp:679] Received reply for offer 201203291014-0-504
I0329 10:23:32.520557  6088 master.cpp:1403] Filtered slave 201203291014-0-2 for framework 201203291014-0-0009 for 1 seconds
I0329 10:23:33.520627  6088 master.cpp:1184] Sending 1 offers to framework 201203291014-0-0008
I0329 10:23:33.522110  6088 master.cpp:679] Received reply for offer 201203291014-0-505
I0329 10:23:33.522250  6088 master.cpp:1403] Filtered slave 201203291014-0-2 for framework 201203291014-0-0008 for 1 seconds
I0329 10:23:34.522390  6088 master.cpp:1184] Sending 1 offers to framework 201203291014-0-0009
I0329 10:23:34.524130  6088 master.cpp:679] Received reply for offer 201203291014-0-506
I0329 10:23:34.524215  6088 master.cpp:1403] Filtered slave 201203291014-0-2 for framework 201203291014-0-0009 for 1 seconds
I0329 10:23:35.524325  6088 master.cpp:1184] Sending 1 offers to framework 201203291014-0-0008
I0329 10:23:35.525879  6088 master.cpp:679] Received reply for offer 201203291014-0-507
I0329 10:23:35.526021  6088 master.cpp:1403] Filtered slave 201203291014-0-2 for framework 201203291014-0-0008 for 1 seconds
I0329 10:23:36.526039  6088 master.cpp:1184] Sending 1 offers to framework 201203291014-0-0009
I0329 10:23:36.527734  6088 master.cpp:679] Received reply for offer 201203291014-0-508
I0329 10:23:36.527871  6088 master.cpp:1403] Filtered slave 201203291014-0-2 for framework 201203291014-0-0009 for 1 seconds
I0329 10:23:37.527909  6088 master.cpp:1184] Sending 1 offers to framework 201203291014-0-0008
I0329 10:23:37.529567  6088 master.cpp:679] Received reply for offer 201203291014-0-509
I0329 10:23:37.529706  6088 master.cpp:1403] Filtered slave 201203291014-0-2 for framework 201203291014-0-0008 for 1 seconds
I0329 10:23:38.529296  6088 master.cpp:1184] Sending 1 offers to framework 201203291014-0-0009
I0329 10:23:38.530505  6088 master.cpp:679] Received reply for offer 201203291014-0-510
I0329 10:23:38.530654  6088 master.cpp:1403] Filtered slave 201203291014-0-2 for framework 201203291014-0-0009 for 1 seconds
I0329 10:23:39.531713  6088 master.cpp:1184] Sending 1 offers to framework 201203291014-0-0008
I0329 10:23:39.533010  6088 master.cpp:679] Received reply for offer 201203291014-0-511
I0329 10:23:39.533084  6088 master.cpp:1403] Filtered slave 201203291014-0-2 for framework 201203291014-0-0008 for 1 seconds
I0329 10:23:40.534314  6088 master.cpp:1184] Sending 1 offers to framework 201203291014-0-0009
I0329 10:23:40.535899  6088 master.cpp:679] Received reply for offer 201203291014-0-512
I0329 10:23:40.536015  6088 master.cpp:1403] Filtered slave 201203291014-0-2 for framework 201203291014-0-0009 for 1 seconds
I0329 10:23:41.536051  6088 master.cpp:1184] Sending 1 offers to framework 201203291014-0-0008
I0329 10:23:41.537411  6088 master.cpp:679] Received reply for offer 201203291014-0-513
I0329 10:23:41.537547  6088 master.cpp:1403] Filtered slave 201203291014-0-2 for framework 201203291014-0-0008 for 1 seconds
I0329 10:23:42.437420  6088 master.cpp:492] Registering framework 201203291014-0-0010 at 2@192.168.1.64:59889
I0329 10:23:42.437644  6088 simple_allocator.cpp:48] Added framework 201203291014-0-0010
I0329 10:23:42.437857  6088 master.cpp:1184] Sending 1 offers to framework 201203291014-0-0010
I0329 10:23:42.438117  6088 master.cpp:492] Registering framework 201203291014-0-0011 at 3@192.168.1.64:59889
I0329 10:23:42.438231  6088 simple_allocator.cpp:48] Added framework 201203291014-0-0011
I0329 10:23:42.455359  6088 master.cpp:679] Received reply for offer 201203291014-0-514
I0329 10:23:42.455528  6088 master.cpp:1403] Filtered slave 201203291014-0-2 for framework 201203291014-0-0010 for 1 seconds
I0329 10:23:42.537731  6088 master.cpp:1184] Sending 1 offers to framework 201203291014-0-0011
I0329 10:23:42.539199  6088 master.cpp:679] Received reply for offer 201203291014-0-515
I0329 10:23:42.539320  6088 master.cpp:1403] Filtered slave 201203291014-0-2 for framework 201203291014-0-0011 for 1 seconds
I0329 10:23:42.820230  6088 master.cpp:718] Reviving offers for framework 201203291014-0-0011
I0329 10:23:42.820374  6088 simple_allocator.cpp:145] Filters removed for framework 201203291014-0-0011
I0329 10:23:42.820777  6088 master.cpp:1184] Sending 1 offers to framework 201203291014-0-0009
I0329 10:23:42.822376  6088 master.cpp:679] Received reply for offer 201203291014-0-516
I0329 10:23:42.822543  6088 master.cpp:1403] Filtered slave 201203291014-0-2 for framework 201203291014-0-0009 for 1 seconds
I0329 10:23:43.539329  6088 master.cpp:1184] Sending 1 offers to framework 201203291014-0-0008
I0329 10:23:43.540788  6088 master.cpp:679] Received reply for offer 201203291014-0-517
I0329 10:23:43.540935  6088 master.cpp:1403] Filtered slave 201203291014-0-2 for framework 201203291014-0-0008 for 1 seconds
I0329 10:23:44.541043  6088 master.cpp:1184] Sending 1 offers to framework 201203291014-0-0010
I0329 10:23:44.542745  6088 master.cpp:679] Received reply for offer 201203291014-0-518
I0329 10:23:44.542837  6088 master.cpp:1403] Filtered slave 201203291014-0-2 for framework 201203291014-0-0010 for 1 seconds
I0329 10:23:45.542366  6088 master.cpp:1184] Sending 1 offers to framework 201203291014-0-0011
I0329 10:23:45.546332  6088 master.cpp:679] Received reply for offer 201203291014-0-519
I0329 10:23:45.546483  6088 master.cpp:1403] Filtered slave 201203291014-0-2 for framework 201203291014-0-0011 for 1 seconds
I0329 10:23:46.544553  6088 master.cpp:1184] Sending 1 offers to framework 201203291014-0-0009
I0329 10:23:46.546167  6088 master.cpp:679] Received reply for offer 201203291014-0-520
I0329 10:23:46.546309  6088 master.cpp:1403] Filtered slave 201203291014-0-2 for framework 201203291014-0-0009 for 1 seconds
I0329 10:23:47.546368  6088 master.cpp:1184] Sending 1 offers to framework 201203291014-0-0008
I0329 10:23:47.547900  6088 master.cpp:679] Received reply for offer 201203291014-0-521
I0329 10:23:47.548041  6088 master.cpp:1403] Filtered slave 201203291014-0-2 for framework 201203291014-0-0008 for 1 seconds
I0329 10:23:48.547384  6088 master.cpp:1184] Sending 1 offers to framework 201203291014-0-0010
I0329 10:23:48.548951  6088 master.cpp:679] Received reply for offer 201203291014-0-522
I0329 10:23:48.549095  6088 master.cpp:1403] Filtered slave 201203291014-0-2 for framework 201203291014-0-0010 for 1 seconds
I0329 10:23:49.549154  6088 master.cpp:1184] Sending 1 offers to framework 201203291014-0-0011
I0329 10:23:49.626441  6088 master.cpp:679] Received reply for offer 201203291014-0-523
I0329 10:23:49.626621  6088 master.cpp:1453] Launching task 0 on slave 201203291014-0-2
I0329 10:23:49.627054  6088 master.cpp:1453] Launching task 1 on slave 201203291014-0-2
I0329 10:23:49.627424  6088 master.cpp:1453] Launching task 2 on slave 201203291014-0-2
I0329 10:23:49.627609  6088 master.cpp:1453] Launching task 3 on slave 201203291014-0-2
I0329 10:23:49.627807  6088 master.cpp:1453] Launching task 4 on slave 201203291014-0-2
I0329 10:23:49.628008  6088 master.cpp:1453] Launching task 5 on slave 201203291014-0-2
I0329 10:23:49.628216  6088 master.cpp:1453] Launching task 6 on slave 201203291014-0-2
I0329 10:23:49.628407  6088 master.cpp:1453] Launching task 7 on slave 201203291014-0-2
I0329 10:23:50.593523  6088 master.cpp:902] Status update from slave@192.168.1.66:39104: task 3 of framework 201203291014-0-0011 is now in state TASK_RUNNING
I0329 10:23:50.595409  6088 master.cpp:902] Status update from slave@192.168.1.66:39104: task 7 of framework 201203291014-0-0011 is now in state TASK_RUNNING
I0329 10:23:50.597309  6088 master.cpp:902] Status update from slave@192.168.1.66:39104: task 4 of framework 201203291014-0-0011 is now in state TASK_RUNNING
I0329 10:23:50.599449  6088 master.cpp:902] Status update from slave@192.168.1.66:39104: task 5 of framework 201203291014-0-0011 is now in state TASK_RUNNING
I0329 10:23:50.599825  6088 master.cpp:902] Status update from slave@192.168.1.66:39104: task 0 of framework 201203291014-0-0011 is now in state TASK_RUNNING
I0329 10:23:50.601008  6088 master.cpp:902] Status update from slave@192.168.1.66:39104: task 1 of framework 201203291014-0-0011 is now in state TASK_RUNNING
I0329 10:23:50.602402  6088 master.cpp:902] Status update from slave@192.168.1.66:39104: task 2 of framework 201203291014-0-0011 is now in state TASK_RUNNING
I0329 10:23:50.603685  6088 master.cpp:902] Status update from slave@192.168.1.66:39104: task 6 of framework 201203291014-0-0011 is now in state TASK_RUNNING
I0329 10:23:51.954203  6088 master.cpp:902] Status update from slave@192.168.1.66:39104: task 5 of framework 201203291014-0-0011 is now in state TASK_FINISHED
I0329 10:23:51.954511  6088 master.cpp:1184] Sending 1 offers to framework 201203291014-0-0008
I0329 10:23:51.955957  6088 master.cpp:679] Received reply for offer 201203291014-0-524
I0329 10:23:51.956114  6088 master.cpp:1403] Filtered slave 201203291014-0-2 for framework 201203291014-0-0008 for 1 seconds
I0329 10:23:51.977437  6088 master.cpp:902] Status update from slave@192.168.1.66:39104: task 3 of framework 201203291014-0-0011 is now in state TASK_FINISHED
I0329 10:23:51.977763  6088 master.cpp:1184] Sending 1 offers to framework 201203291014-0-0010
I0329 10:23:51.977993  6088 master.cpp:902] Status update from slave@192.168.1.66:39104: task 4 of framework 201203291014-0-0011 is now in state TASK_FINISHED
I0329 10:23:51.979549  6088 master.cpp:679] Received reply for offer 201203291014-0-525
I0329 10:23:51.979737  6088 master.cpp:1403] Filtered slave 201203291014-0-2 for framework 201203291014-0-0010 for 1 seconds
I0329 10:23:51.988749  6088 master.cpp:902] Status update from slave@192.168.1.66:39104: task 2 of framework 201203291014-0-0011 is now in state TASK_FINISHED
I0329 10:23:51.989017  6088 master.cpp:1184] Sending 1 offers to framework 201203291014-0-0009
I0329 10:23:51.990442  6088 master.cpp:679] Received reply for offer 201203291014-0-526
I0329 10:23:51.990607  6088 master.cpp:1403] Filtered slave 201203291014-0-2 for framework 201203291014-0-0009 for 1 seconds
I0329 10:23:52.088970  6088 master.cpp:902] Status update from slave@192.168.1.66:39104: task 1 of framework 201203291014-0-0011 is now in state TASK_FINISHED
I0329 10:23:52.089251  6088 master.cpp:1184] Sending 1 offers to framework 201203291014-0-0011
I0329 10:23:52.109726  6088 master.cpp:902] Status update from slave@192.168.1.66:39104: task 7 of framework 201203291014-0-0011 is now in state TASK_FINISHED
I0329 10:23:52.115499  6088 master.cpp:679] Received reply for offer 201203291014-0-527
I0329 10:23:52.115641  6088 master.cpp:1453] Launching task 8 on slave 201203291014-0-2
I0329 10:23:52.115833  6088 master.cpp:1453] Launching task 9 on slave 201203291014-0-2
I0329 10:23:52.116024  6088 master.cpp:1453] Launching task 10 on slave 201203291014-0-2
I0329 10:23:52.116252  6088 master.cpp:1453] Launching task 11 on slave 201203291014-0-2
I0329 10:23:52.116463  6088 master.cpp:1453] Launching task 12 on slave 201203291014-0-2
I0329 10:23:52.131319  6088 master.cpp:902] Status update from slave@192.168.1.66:39104: task 6 of framework 201203291014-0-0011 is now in state TASK_FINISHED
I0329 10:23:52.131670  6088 master.cpp:1184] Sending 1 offers to framework 201203291014-0-0011
I0329 10:23:52.141626  6088 master.cpp:902] Status update from slave@192.168.1.66:39104: task 8 of framework 201203291014-0-0011 is now in state TASK_RUNNING
I0329 10:23:52.141824  6088 master.cpp:902] Status update from slave@192.168.1.66:39104: task 9 of framework 201203291014-0-0011 is now in state TASK_RUNNING
I0329 10:23:52.142405  6088 master.cpp:902] Status update from slave@192.168.1.66:39104: task 10 of framework 201203291014-0-0011 is now in state TASK_RUNNING
I0329 10:23:52.144057  6088 master.cpp:679] Received reply for offer 201203291014-0-528
I0329 10:23:52.144186  6088 master.cpp:1453] Launching task 13 on slave 201203291014-0-2
I0329 10:23:52.144927  6088 master.cpp:1453] Launching task 14 on slave 201203291014-0-2
I0329 10:23:52.147527  6088 master.cpp:902] Status update from slave@192.168.1.66:39104: task 11 of framework 201203291014-0-0011 is now in state TASK_RUNNING
I0329 10:23:52.147716  6088 master.cpp:902] Status update from slave@192.168.1.66:39104: task 12 of framework 201203291014-0-0011 is now in state TASK_RUNNING
I0329 10:23:52.149365  6088 master.cpp:902] Status update from slave@192.168.1.66:39104: task 0 of framework 201203291014-0-0011 is now in state TASK_FINISHED
I0329 10:23:52.149651  6088 master.cpp:1184] Sending 1 offers to framework 201203291014-0-0011
I0329 10:23:52.153442  6088 master.cpp:902] Status update from slave@192.168.1.66:39104: task 14 of framework 201203291014-0-0011 is now in state TASK_RUNNING
I0329 10:23:52.155827  6088 master.cpp:679] Received reply for offer 201203291014-0-529
I0329 10:23:52.155958  6088 master.cpp:1453] Launching task 15 on slave 201203291014-0-2
I0329 10:23:52.166250  6088 master.cpp:902] Status update from slave@192.168.1.66:39104: task 15 of framework 201203291014-0-0011 is now in state TASK_RUNNING
I0329 10:23:52.168108  6088 master.cpp:902] Status update from slave@192.168.1.66:39104: task 13 of framework 201203291014-0-0011 is now in state TASK_RUNNING
I0329 10:23:52.577491  6088 master.cpp:902] Status update from slave@192.168.1.66:39104: task 8 of framework 201203291014-0-0011 is now in state TASK_FINISHED
I0329 10:23:52.577802  6088 master.cpp:1184] Sending 1 offers to framework 201203291014-0-0011
I0329 10:23:52.586398  6088 master.cpp:679] Received reply for offer 201203291014-0-530
I0329 10:23:52.586577  6088 master.cpp:1453] Launching task 16 on slave 201203291014-0-2
I0329 10:23:52.626724  6088 master.cpp:902] Status update from slave@192.168.1.66:39104: task 16 of framework 201203291014-0-0011 is now in state TASK_RUNNING
I0329 10:23:52.805510  6088 master.cpp:902] Status update from slave@192.168.1.66:39104: task 10 of framework 201203291014-0-0011 is now in state TASK_FINISHED
I0329 10:23:52.805834  6088 master.cpp:1184] Sending 1 offers to framework 201203291014-0-0011
I0329 10:23:52.813071  6088 master.cpp:679] Received reply for offer 201203291014-0-531
I0329 10:23:52.813237  6088 master.cpp:1453] Launching task 17 on slave 201203291014-0-2
I0329 10:23:52.861472  6088 master.cpp:902] Status update from slave@192.168.1.66:39104: task 17 of framework 201203291014-0-0011 is now in state TASK_RUNNING
I0329 10:23:52.905226  6088 master.cpp:902] Status update from slave@192.168.1.66:39104: task 14 of framework 201203291014-0-0011 is now in state TASK_FINISHED
I0329 10:23:52.905591  6088 master.cpp:1184] Sending 1 offers to framework 201203291014-0-0011
I0329 10:23:52.905822  6088 master.cpp:902] Status update from slave@192.168.1.66:39104: task 13 of framework 201203291014-0-0011 is now in state TASK_FINISHED
I0329 10:23:52.911700  6088 master.cpp:679] Received reply for offer 201203291014-0-532
I0329 10:23:52.911818  6088 master.cpp:1453] Launching task 18 on slave 201203291014-0-2
I0329 10:23:52.942639  6088 master.cpp:902] Status update from slave@192.168.1.66:39104: task 18 of framework 201203291014-0-0011 is now in state TASK_RUNNING
I0329 10:23:52.942823  6088 master.cpp:902] Status update from slave@192.168.1.66:39104: task 9 of framework 201203291014-0-0011 is now in state TASK_FINISHED
I0329 10:23:52.943145  6088 master.cpp:1184] Sending 1 offers to framework 201203291014-0-0011
I0329 10:23:52.951468  6088 master.cpp:679] Received reply for offer 201203291014-0-533
I0329 10:23:52.951607  6088 master.cpp:1453] Launching task 19 on slave 201203291014-0-2
I0329 10:23:52.951820  6088 master.cpp:1453] Launching task 20 on slave 201203291014-0-2
I0329 10:23:52.962985  6088 master.cpp:902] Status update from slave@192.168.1.66:39104: task 19 of framework 201203291014-0-0011 is now in state TASK_RUNNING
I0329 10:23:52.967383  6088 master.cpp:902] Status update from slave@192.168.1.66:39104: task 20 of framework 201203291014-0-0011 is now in state TASK_RUNNING
I0329 10:23:53.029976  6088 master.cpp:902] Status update from slave@192.168.1.66:39104: task 16 of framework 201203291014-0-0011 is now in state TASK_FINISHED
I0329 10:23:53.030297  6088 master.cpp:1184] Sending 1 offers to framework 201203291014-0-0011
I0329 10:23:53.036756  6088 master.cpp:679] Received reply for offer 201203291014-0-534
I0329 10:23:53.036918  6088 master.cpp:1453] Launching task 21 on slave 201203291014-0-2
I0329 10:23:53.051482  6088 master.cpp:902] Status update from slave@192.168.1.66:39104: task 21 of framework 201203291014-0-0011 is now in state TASK_RUNNING
I0329 10:23:53.103736  6088 master.cpp:902] Status update from slave@192.168.1.66:39104: task 15 of framework 201203291014-0-0011 is now in state TASK_FINISHED
I0329 10:23:53.104017  6088 master.cpp:1184] Sending 1 offers to framework 201203291014-0-0011
I0329 10:23:53.148283  6088 master.cpp:679] Received reply for offer 201203291014-0-535
I0329 10:23:53.148504  6088 master.cpp:1453] Launching task 22 on slave 201203291014-0-2
I0329 10:23:53.162430  6088 master.cpp:902] Status update from slave@192.168.1.66:39104: task 22 of framework 201203291014-0-0011 is now in state TASK_RUNNING
I0329 10:23:53.266778  6088 master.cpp:902] Status update from slave@192.168.1.66:39104: task 11 of framework 201203291014-0-0011 is now in state TASK_FINISHED
I0329 10:23:53.267242  6088 master.cpp:1184] Sending 1 offers to framework 201203291014-0-0011
I0329 10:23:53.312216  6088 master.cpp:679] Received reply for offer 201203291014-0-536
I0329 10:23:53.312415  6088 master.cpp:1453] Launching task 23 on slave 201203291014-0-2
I0329 10:23:53.327635  6088 master.cpp:902] Status update from slave@192.168.1.66:39104: task 23 of framework 201203291014-0-0011 is now in state TASK_RUNNING
I0329 10:23:53.350371  6088 master.cpp:902] Status update from slave@192.168.1.66:39104: task 20 of framework 201203291014-0-0011 is now in state TASK_FINISHED
I0329 10:23:53.350661  6088 master.cpp:1184] Sending 1 offers to framework 201203291014-0-0011
I0329 10:23:53.354991  6088 master.cpp:902] Status update from slave@192.168.1.66:39104: task 12 of framework 201203291014-0-0011 is now in state TASK_FINISHED
I0329 10:23:53.390899  6088 master.cpp:679] Received reply for offer 201203291014-0-537
I0329 10:23:53.391103  6088 master.cpp:1453] Launching task 24 on slave 201203291014-0-2
I0329 10:23:53.409236  6088 master.cpp:902] Status update from slave@192.168.1.66:39104: task 24 of framework 201203291014-0-0011 is now in state TASK_RUNNING
I0329 10:23:53.485538  6088 master.cpp:902] Status update from slave@192.168.1.66:39104: task 21 of framework 201203291014-0-0011 is now in state TASK_FINISHED
I0329 10:23:53.485857  6088 master.cpp:1184] Sending 1 offers to framework 201203291014-0-0011
I0329 10:23:53.492395  6088 master.cpp:679] Received reply for offer 201203291014-0-538
I0329 10:23:53.492573  6088 master.cpp:1453] Launching task 25 on slave 201203291014-0-2
I0329 10:23:53.492802  6088 master.cpp:1453] Launching task 26 on slave 201203291014-0-2
I0329 10:23:53.527714  6088 master.cpp:902] Status update from slave@192.168.1.66:39104: task 25 of framework 201203291014-0-0011 is now in state TASK_RUNNING
I0329 10:23:53.532199  6088 master.cpp:902] Status update from slave@192.168.1.66:39104: task 26 of framework 201203291014-0-0011 is now in state TASK_RUNNING
I0329 10:23:53.574007  6088 master.cpp:902] Status update from slave@192.168.1.66:39104: task 17 of framework 201203291014-0-0011 is now in state TASK_FINISHED
I0329 10:23:53.574301  6088 master.cpp:1184] Sending 1 offers to framework 201203291014-0-0008
I0329 10:23:53.575562  6088 master.cpp:679] Received reply for offer 201203291014-0-539
I0329 10:23:53.575723  6088 master.cpp:1403] Filtered slave 201203291014-0-2 for framework 201203291014-0-0008 for 1 seconds
I0329 10:23:53.739187  6088 master.cpp:902] Status update from slave@192.168.1.66:39104: task 23 of framework 201203291014-0-0011 is now in state TASK_FINISHED
I0329 10:23:53.739478  6088 master.cpp:1184] Sending 1 offers to framework 201203291014-0-0010
I0329 10:23:53.779523  6088 master.cpp:902] Status update from slave@192.168.1.66:39104: task 19 of framework 201203291014-0-0011 is now in state TASK_FINISHED
I0329 10:23:53.780413  6088 master.cpp:679] Received reply for offer 201203291014-0-540
I0329 10:23:53.780577  6088 master.cpp:1403] Filtered slave 201203291014-0-2 for framework 201203291014-0-0010 for 1 seconds
I0329 10:23:53.823799  6088 master.cpp:902] Status update from slave@192.168.1.66:39104: task 18 of framework 201203291014-0-0011 is now in state TASK_FINISHED
I0329 10:23:53.824141  6088 master.cpp:1184] Sending 1 offers to framework 201203291014-0-0009
I0329 10:23:53.825605  6088 master.cpp:679] Received reply for offer 201203291014-0-541
I0329 10:23:53.825780  6088 master.cpp:1403] Filtered slave 201203291014-0-2 for framework 201203291014-0-0009 for 1 seconds
I0329 10:23:53.948622  6088 master.cpp:902] Status update from slave@192.168.1.66:39104: task 22 of framework 201203291014-0-0011 is now in state TASK_FINISHED
I0329 10:23:53.948885  6088 master.cpp:1184] Sending 1 offers to framework 201203291014-0-0011
I0329 10:23:53.991447  6088 master.cpp:902] Status update from slave@192.168.1.66:39104: task 24 of framework 201203291014-0-0011 is now in state TASK_FINISHED
I0329 10:23:53.997051  6088 master.cpp:679] Received reply for offer 201203291014-0-542
I0329 10:23:53.997217  6088 master.cpp:1453] Launching task 27 on slave 201203291014-0-2
I0329 10:23:53.997436  6088 master.cpp:1453] Launching task 28 on slave 201203291014-0-2
I0329 10:23:53.997625  6088 master.cpp:1453] Launching task 29 on slave 201203291014-0-2
I0329 10:23:53.997813  6088 master.cpp:1453] Launching task 30 on slave 201203291014-0-2
I0329 10:23:53.997998  6088 master.cpp:1453] Launching task 31 on slave 201203291014-0-2
I0329 10:23:54.026412  6088 master.cpp:902] Status update from slave@192.168.1.66:39104: task 27 of framework 201203291014-0-0011 is now in state TASK_RUNNING
I0329 10:23:54.026608  6088 master.cpp:902] Status update from slave@192.168.1.66:39104: task 28 of framework 201203291014-0-0011 is now in state TASK_RUNNING
I0329 10:23:54.026914  6088 master.cpp:902] Status update from slave@192.168.1.66:39104: task 29 of framework 201203291014-0-0011 is now in state TASK_RUNNING
I0329 10:23:54.027245  6088 master.cpp:902] Status update from slave@192.168.1.66:39104: task 30 of framework 201203291014-0-0011 is now in state TASK_RUNNING
I0329 10:23:54.030514  6088 master.cpp:902] Status update from slave@192.168.1.66:39104: task 31 of framework 201203291014-0-0011 is now in state TASK_RUNNING
I0329 10:23:54.043341  6088 master.cpp:902] Status update from slave@192.168.1.66:39104: task 26 of framework 201203291014-0-0011 is now in state TASK_FINISHED
I0329 10:23:54.043599  6088 master.cpp:1184] Sending 1 offers to framework 201203291014-0-0011
I0329 10:23:54.054766  6088 master.cpp:902] Status update from slave@192.168.1.66:39104: task 25 of framework 201203291014-0-0011 is now in state TASK_FINISHED
I0329 10:23:54.077919  6088 master.cpp:679] Received reply for offer 201203291014-0-543
I0329 10:23:54.078107  6088 master.cpp:1453] Launching task 32 on slave 201203291014-0-2
I0329 10:23:54.078414  6088 master.cpp:1453] Launching task 33 on slave 201203291014-0-2
I0329 10:23:54.095567  6088 master.cpp:902] Status update from slave@192.168.1.66:39104: task 32 of framework 201203291014-0-0011 is now in state TASK_RUNNING
I0329 10:23:54.105919  6088 master.cpp:902] Status update from slave@192.168.1.66:39104: task 33 of framework 201203291014-0-0011 is now in state TASK_RUNNING
I0329 10:23:54.486857  6088 master.cpp:902] Status update from slave@192.168.1.66:39104: task 28 of framework 201203291014-0-0011 is now in state TASK_FINISHED
I0329 10:23:54.487236  6088 master.cpp:1184] Sending 1 offers to framework 201203291014-0-0011
I0329 10:23:54.495379  6088 master.cpp:679] Received reply for offer 201203291014-0-544
I0329 10:23:54.495535  6088 master.cpp:1453] Launching task 34 on slave 201203291014-0-2
I0329 10:23:54.496261  6088 master.cpp:1453] Launching task 35 on slave 201203291014-0-2
I0329 10:23:54.527802  6088 master.cpp:902] Status update from slave@192.168.1.66:39104: task 34 of framework 201203291014-0-0011 is now in state TASK_RUNNING
I0329 10:23:54.533900  6088 master.cpp:902] Status update from slave@192.168.1.66:39104: task 35 of framework 201203291014-0-0011 is now in state TASK_RUNNING
I0329 10:23:54.568755  6088 master.cpp:902] Status update from slave@192.168.1.66:39104: task 32 of framework 201203291014-0-0011 is now in state TASK_FINISHED
I0329 10:23:54.569046  6088 master.cpp:1184] Sending 1 offers to framework 201203291014-0-0011
I0329 10:23:54.573287  6088 master.cpp:679] Received reply for offer 201203291014-0-545
I0329 10:23:54.599673  6088 master.cpp:1453] Launching task 36 on slave 201203291014-0-2
I0329 10:23:54.633554  6088 master.cpp:902] Status update from slave@192.168.1.66:39104: task 33 of framework 201203291014-0-0011 is now in state TASK_FINISHED
I0329 10:23:54.633796  6088 master.cpp:1184] Sending 1 offers to framework 201203291014-0-0011
I0329 10:23:54.637449  6088 master.cpp:679] Received reply for offer 201203291014-0-546
I0329 10:23:54.637578  6088 master.cpp:1453] Launching task 37 on slave 201203291014-0-2
I0329 10:23:54.652219  6088 master.cpp:902] Status update from slave@192.168.1.66:39104: task 36 of framework 201203291014-0-0011 is now in state TASK_RUNNING
I0329 10:23:54.664245  6088 master.cpp:902] Status update from slave@192.168.1.66:39104: task 37 of framework 201203291014-0-0011 is now in state TASK_RUNNING
I0329 10:23:54.836940  6088 master.cpp:902] Status update from slave@192.168.1.66:39104: task 30 of framework 201203291014-0-0011 is now in state TASK_FINISHED
I0329 10:23:54.837237  6088 master.cpp:1184] Sending 1 offers to framework 201203291014-0-0011
I0329 10:23:54.841712  6088 master.cpp:679] Received reply for offer 201203291014-0-547
I0329 10:23:54.841919  6088 master.cpp:1453] Launching task 38 on slave 201203291014-0-2
I0329 10:23:54.858197  6088 master.cpp:902] Status update from slave@192.168.1.66:39104: task 29 of framework 201203291014-0-0011 is now in state TASK_FINISHED
I0329 10:23:54.858466  6088 master.cpp:1184] Sending 1 offers to framework 201203291014-0-0011
I0329 10:23:54.879231  6088 master.cpp:679] Received reply for offer 201203291014-0-548
I0329 10:23:54.879376  6088 master.cpp:1453] Launching task 39 on slave 201203291014-0-2
I0329 10:23:54.887152  6088 master.cpp:902] Status update from slave@192.168.1.66:39104: task 38 of framework 201203291014-0-0011 is now in state TASK_RUNNING
I0329 10:23:54.919941  6088 master.cpp:902] Status update from slave@192.168.1.66:39104: task 31 of framework 201203291014-0-0011 is now in state TASK_FINISHED
I0329 10:23:54.920204  6088 master.cpp:1184] Sending 1 offers to framework 201203291014-0-0011
I0329 10:23:54.920393  6088 master.cpp:902] Status update from slave@192.168.1.66:39104: task 39 of framework 201203291014-0-0011 is now in state TASK_RUNNING
I0329 10:23:54.922304  6088 master.cpp:679] Received reply for offer 201203291014-0-549
I0329 10:23:54.922467  6088 master.cpp:1403] Filtered slave 201203291014-0-2 for framework 201203291014-0-0011 for 1 seconds
I0329 10:23:54.947917  6088 master.cpp:902] Status update from slave@192.168.1.66:39104: task 27 of framework 201203291014-0-0011 is now in state TASK_FINISHED
I0329 10:23:55.117136  6088 master.cpp:902] Status update from slave@192.168.1.66:39104: task 34 of framework 201203291014-0-0011 is now in state TASK_FINISHED
I0329 10:23:55.157042  6088 master.cpp:902] Status update from slave@192.168.1.66:39104: task 35 of framework 201203291014-0-0011 is now in state TASK_FINISHED
I0329 10:23:55.209529  6088 master.cpp:902] Status update from slave@192.168.1.66:39104: task 36 of framework 201203291014-0-0011 is now in state TASK_FINISHED
I0329 10:23:55.215898  6088 master.cpp:902] Status update from slave@192.168.1.66:39104: task 37 of framework 201203291014-0-0011 is now in state TASK_FINISHED
I0329 10:23:55.306128  6088 master.cpp:902] Status update from slave@192.168.1.66:39104: task 38 of framework 201203291014-0-0011 is now in state TASK_FINISHED
I0329 10:23:55.343651  6088 master.cpp:902] Status update from slave@192.168.1.66:39104: task 39 of framework 201203291014-0-0011 is now in state TASK_FINISHED
I0329 10:23:55.369866  6088 master.cpp:718] Reviving offers for framework 201203291014-0-0011
I0329 10:23:55.370005  6088 simple_allocator.cpp:145] Filters removed for framework 201203291014-0-0011
I0329 10:23:55.370352  6088 master.cpp:1184] Sending 1 offers to framework 201203291014-0-0011
I0329 10:23:55.388417  6088 master.cpp:679] Received reply for offer 201203291014-0-550
I0329 10:23:55.388610  6088 master.cpp:1403] Filtered slave 201203291014-0-2 for framework 201203291014-0-0011 for 1 seconds
I0329 10:23:55.556779  6088 master.cpp:1184] Sending 1 offers to framework 201203291014-0-0008
I0329 10:23:55.558212  6088 master.cpp:679] Received reply for offer 201203291014-0-551
I0329 10:23:55.558357  6088 master.cpp:1403] Filtered slave 201203291014-0-2 for framework 201203291014-0-0008 for 1 seconds
I0329 10:23:56.558394  6088 master.cpp:1184] Sending 1 offers to framework 201203291014-0-0010
I0329 10:23:56.560106  6088 master.cpp:679] Received reply for offer 201203291014-0-552
I0329 10:23:56.560252  6088 master.cpp:1403] Filtered slave 201203291014-0-2 for framework 201203291014-0-0010 for 1 seconds
I0329 10:23:57.560300  6088 master.cpp:1184] Sending 1 offers to framework 201203291014-0-0009
I0329 10:23:57.561751  6088 master.cpp:679] Received reply for offer 201203291014-0-553
I0329 10:23:57.561926  6088 master.cpp:1403] Filtered slave 201203291014-0-2 for framework 201203291014-0-0009 for 1 seconds
I0329 10:23:58.561964  6088 master.cpp:1184] Sending 1 offers to framework 201203291014-0-0008
I0329 10:23:58.563417  6088 master.cpp:679] Received reply for offer 201203291014-0-554
I0329 10:23:58.563571  6088 master.cpp:1403] Filtered slave 201203291014-0-2 for framework 201203291014-0-0008 for 1 seconds
I0329 10:23:59.563645  6088 master.cpp:1184] Sending 1 offers to framework 201203291014-0-0010
I0329 10:23:59.565201  6088 master.cpp:679] Received reply for offer 201203291014-0-555
I0329 10:23:59.565342  6088 master.cpp:1403] Filtered slave 201203291014-0-2 for framework 201203291014-0-0010 for 1 seconds
I0329 10:24:00.565400  6088 master.cpp:1184] Sending 1 offers to framework 201203291014-0-0009
I0329 10:24:00.566933  6088 master.cpp:679] Received reply for offer 201203291014-0-556
I0329 10:24:00.567167  6088 master.cpp:1403] Filtered slave 201203291014-0-2 for framework 201203291014-0-0009 for 1 seconds
I0329 10:24:01.567042  6088 master.cpp:1184] Sending 1 offers to framework 201203291014-0-0011
I0329 10:24:01.590699  6088 master.cpp:679] Received reply for offer 201203291014-0-557
I0329 10:24:01.590879  6088 master.cpp:1453] Launching task 40 on slave 201203291014-0-2
I0329 10:24:01.591488  6088 master.cpp:1453] Launching task 41 on slave 201203291014-0-2
I0329 10:24:01.591744  6088 master.cpp:1453] Launching task 42 on slave 201203291014-0-2
I0329 10:24:01.591984  6088 master.cpp:1453] Launching task 43 on slave 201203291014-0-2
I0329 10:24:01.592213  6088 master.cpp:1453] Launching task 44 on slave 201203291014-0-2
I0329 10:24:01.592485  6088 master.cpp:1453] Launching task 45 on slave 201203291014-0-2
I0329 10:24:01.592764  6088 master.cpp:1453] Launching task 46 on slave 201203291014-0-2
I0329 10:24:01.593025  6088 master.cpp:1453] Launching task 47 on slave 201203291014-0-2
I0329 10:24:01.598081  6088 master.cpp:902] Status update from slave@192.168.1.66:39104: task 40 of framework 201203291014-0-0011 is now in state TASK_RUNNING
I0329 10:24:01.602591  6088 master.cpp:902] Status update from slave@192.168.1.66:39104: task 41 of framework 201203291014-0-0011 is now in state TASK_RUNNING
I0329 10:24:01.605803  6088 master.cpp:902] Status update from slave@192.168.1.66:39104: task 42 of framework 201203291014-0-0011 is now in state TASK_RUNNING
I0329 10:24:01.607993  6088 master.cpp:902] Status update from slave@192.168.1.66:39104: task 43 of framework 201203291014-0-0011 is now in state TASK_RUNNING
I0329 10:24:01.612864  6088 master.cpp:902] Status update from slave@192.168.1.66:39104: task 44 of framework 201203291014-0-0011 is now in state TASK_RUNNING
I0329 10:24:01.617327  6088 master.cpp:902] Status update from slave@192.168.1.66:39104: task 45 of framework 201203291014-0-0011 is now in state TASK_RUNNING
I0329 10:24:01.617805  6088 master.cpp:902] Status update from slave@192.168.1.66:39104: task 47 of framework 201203291014-0-0011 is now in state TASK_RUNNING
I0329 10:24:01.618659  6088 master.cpp:902] Status update from slave@192.168.1.66:39104: task 46 of framework 201203291014-0-0011 is now in state TASK_RUNNING
I0329 10:24:01.762985  6088 master.cpp:902] Status update from slave@192.168.1.66:39104: task 46 of framework 201203291014-0-0011 is now in state TASK_FAILED
I0329 10:24:01.763360  6088 master.cpp:1184] Sending 1 offers to framework 201203291014-0-0008
I0329 10:24:01.764935  6088 master.cpp:679] Received reply for offer 201203291014-0-558
I0329 10:24:01.765106  6088 master.cpp:1403] Filtered slave 201203291014-0-2 for framework 201203291014-0-0008 for 1 seconds
I0329 10:24:01.765437  6088 master.cpp:902] Status update from slave@192.168.1.66:39104: task 42 of framework 201203291014-0-0011 is now in state TASK_FAILED
I0329 10:24:01.765737  6088 master.cpp:1184] Sending 1 offers to framework 201203291014-0-0010
I0329 10:24:01.767940  6088 master.cpp:902] Status update from slave@192.168.1.66:39104: task 43 of framework 201203291014-0-0011 is now in state TASK_FAILED
I0329 10:24:01.770397  6088 master.cpp:902] Status update from slave@192.168.1.66:39104: task 47 of framework 201203291014-0-0011 is now in state TASK_FAILED
I0329 10:24:01.772899  6088 master.cpp:902] Status update from slave@192.168.1.66:39104: task 44 of framework 201203291014-0-0011 is now in state TASK_FAILED
I0329 10:24:01.775326  6088 master.cpp:902] Status update from slave@192.168.1.66:39104: task 45 of framework 201203291014-0-0011 is now in state TASK_FAILED
I0329 10:24:01.777854  6088 master.cpp:902] Status update from slave@192.168.1.66:39104: task 41 of framework 201203291014-0-0011 is now in state TASK_FAILED
I0329 10:24:01.778306  6088 master.cpp:679] Received reply for offer 201203291014-0-559
I0329 10:24:01.778426  6088 master.cpp:1403] Filtered slave 201203291014-0-2 for framework 201203291014-0-0010 for 1 seconds
I0329 10:24:01.780097  6088 master.cpp:902] Status update from slave@192.168.1.66:39104: task 40 of framework 201203291014-0-0011 is now in state TASK_FAILED
I0329 10:24:01.780385  6088 master.cpp:1184] Sending 1 offers to framework 201203291014-0-0011
I0329 10:24:01.832772  6088 master.cpp:679] Received reply for offer 201203291014-0-560
I0329 10:24:01.832984  6088 master.cpp:1453] Launching task 48 on slave 201203291014-0-2
I0329 10:24:01.833268  6088 master.cpp:1453] Launching task 49 on slave 201203291014-0-2
I0329 10:24:01.833583  6088 master.cpp:1453] Launching task 50 on slave 201203291014-0-2
I0329 10:24:01.833745  6088 master.cpp:1453] Launching task 51 on slave 201203291014-0-2
I0329 10:24:01.834020  6088 master.cpp:1453] Launching task 52 on slave 201203291014-0-2
I0329 10:24:01.834480  6088 master.cpp:1453] Launching task 53 on slave 201203291014-0-2
I0329 10:24:01.835114  6088 master.cpp:1453] Launching task 54 on slave 201203291014-0-2
I0329 10:24:01.835773  6088 master.cpp:1453] Launching task 55 on slave 201203291014-0-2
I0329 10:24:01.838417  6088 master.cpp:902] Status update from slave@192.168.1.66:39104: task 48 of framework 201203291014-0-0011 is now in state TASK_RUNNING
I0329 10:24:01.843168  6088 master.cpp:902] Status update from slave@192.168.1.66:39104: task 49 of framework 201203291014-0-0011 is now in state TASK_RUNNING
I0329 10:24:01.849028  6088 master.cpp:902] Status update from slave@192.168.1.66:39104: task 50 of framework 201203291014-0-0011 is now in state TASK_RUNNING
I0329 10:24:01.852071  6088 master.cpp:902] Status update from slave@192.168.1.66:39104: task 51 of framework 201203291014-0-0011 is now in state TASK_RUNNING
I0329 10:24:01.855592  6088 master.cpp:902] Status update from slave@192.168.1.66:39104: task 52 of framework 201203291014-0-0011 is now in state TASK_RUNNING
I0329 10:24:01.859148  6088 master.cpp:902] Status update from slave@192.168.1.66:39104: task 53 of framework 201203291014-0-0011 is now in state TASK_RUNNING
I0329 10:24:01.865375  6088 master.cpp:902] Status update from slave@192.168.1.66:39104: task 54 of framework 201203291014-0-0011 is now in state TASK_RUNNING
I0329 10:24:01.865843  6088 master.cpp:902] Status update from slave@192.168.1.66:39104: task 55 of framework 201203291014-0-0011 is now in state TASK_RUNNING
I0329 10:24:02.922788  6088 master.cpp:1001] Executor default of framework 201203291014-0-0011 on slave 201203291014-0-2 (ubuntu.gateway.2wire.net) exited with status 256
I0329 10:24:02.924279  6088 master.cpp:1033] Removing task 54 of framework 201203291014-0-0011 because of lost executor
I0329 10:24:02.924540  6088 master.cpp:1184] Sending 1 offers to framework 201203291014-0-0009
I0329 10:24:02.926328  6088 master.cpp:1033] Removing task 55 of framework 201203291014-0-0011 because of lost executor
I0329 10:24:02.927994  6088 master.cpp:1033] Removing task 52 of framework 201203291014-0-0011 because of lost executor
I0329 10:24:02.929608  6088 master.cpp:1033] Removing task 53 of framework 201203291014-0-0011 because of lost executor
I0329 10:24:02.931167  6088 master.cpp:1033] Removing task 50 of framework 201203291014-0-0011 because of lost executor
I0329 10:24:02.932476  6088 master.cpp:1033] Removing task 51 of framework 201203291014-0-0011 because of lost executor
I0329 10:24:02.933539  6088 master.cpp:1033] Removing task 49 of framework 201203291014-0-0011 because of lost executor
I0329 10:24:02.934586  6088 master.cpp:1033] Removing task 48 of framework 201203291014-0-0011 because of lost executor
I0329 10:24:02.934798  6088 master.cpp:679] Received reply for offer 201203291014-0-561
I0329 10:24:02.934958  6088 master.cpp:1184] Sending 1 offers to framework 201203291014-0-0011
I0329 10:24:02.935065  6088 master.cpp:1403] Filtered slave 201203291014-0-2 for framework 201203291014-0-0009 for 1 seconds
I0329 10:24:02.948722  6088 master.cpp:679] Received reply for offer 201203291014-0-562
I0329 10:24:02.948946  6088 master.cpp:1453] Launching task 56 on slave 201203291014-0-2
I0329 10:24:02.949260  6088 master.cpp:1453] Launching task 57 on slave 201203291014-0-2
I0329 10:24:02.949517  6088 master.cpp:1453] Launching task 58 on slave 201203291014-0-2
I0329 10:24:02.949759  6088 master.cpp:1453] Launching task 59 on slave 201203291014-0-2
I0329 10:24:02.950055  6088 master.cpp:1453] Launching task 60 on slave 201203291014-0-2
I0329 10:24:02.950320  6088 master.cpp:1453] Launching task 61 on slave 201203291014-0-2
I0329 10:24:02.950543  6088 master.cpp:1453] Launching task 62 on slave 201203291014-0-2
I0329 10:24:03.570580  6088 master.cpp:1184] Sending 1 offers to framework 201203291014-0-0008
I0329 10:24:03.572208  6088 master.cpp:679] Received reply for offer 201203291014-0-563
I0329 10:24:03.572425  6088 master.cpp:1403] Filtered slave 201203291014-0-2 for framework 201203291014-0-0008 for 1 seconds
I0329 10:24:03.827275  6088 master.cpp:902] Status update from slave@192.168.1.66:39104: task 61 of framework 201203291014-0-0011 is now in state TASK_RUNNING
I0329 10:24:03.830415  6088 master.cpp:902] Status update from slave@192.168.1.66:39104: task 59 of framework 201203291014-0-0011 is now in state TASK_RUNNING
I0329 10:24:03.833271  6088 master.cpp:902] Status update from slave@192.168.1.66:39104: task 62 of framework 201203291014-0-0011 is now in state TASK_RUNNING
I0329 10:24:03.836586  6088 master.cpp:902] Status update from slave@192.168.1.66:39104: task 57 of framework 201203291014-0-0011 is now in state TASK_RUNNING
I0329 10:24:03.838572  6088 master.cpp:902] Status update from slave@192.168.1.66:39104: task 58 of framework 201203291014-0-0011 is now in state TASK_RUNNING
I0329 10:24:03.841151  6088 master.cpp:902] Status update from slave@192.168.1.66:39104: task 56 of framework 201203291014-0-0011 is now in state TASK_RUNNING
I0329 10:24:03.842538  6088 master.cpp:902] Status update from slave@192.168.1.66:39104: task 60 of framework 201203291014-0-0011 is now in state TASK_RUNNING
I0329 10:24:04.572692  6088 master.cpp:1184] Sending 1 offers to framework 201203291014-0-0010
I0329 10:24:04.574337  6088 master.cpp:679] Received reply for offer 201203291014-0-564
I0329 10:24:04.574503  6088 master.cpp:1403] Filtered slave 201203291014-0-2 for framework 201203291014-0-0010 for 1 seconds
I0329 10:24:05.119272  6088 master.cpp:1118] Framework 201203291014-0-0009 disconnected
I0329 10:24:05.119457  6088 master.cpp:1118] Framework 201203291014-0-0008 disconnected
I0329 10:24:05.327873  6088 master.cpp:902] Status update from slave@192.168.1.66:39104: task 62 of framework 201203291014-0-0011 is now in state TASK_FAILED
I0329 10:24:05.328183  6088 master.cpp:1184] Sending 1 offers to framework 201203291014-0-0011
I0329 10:24:05.332195  6088 master.cpp:902] Status update from slave@192.168.1.66:39104: task 56 of framework 201203291014-0-0011 is now in state TASK_FAILED
I0329 10:24:05.335011  6088 master.cpp:902] Status update from slave@192.168.1.66:39104: task 57 of framework 201203291014-0-0011 is now in state TASK_FAILED
I0329 10:24:05.335860  6088 master.cpp:679] Received reply for offer 201203291014-0-565
I0329 10:24:05.336041  6088 master.cpp:1453] Launching task 63 on slave 201203291014-0-2
I0329 10:24:05.336304  6088 master.cpp:1453] Launching task 64 on slave 201203291014-0-2
I0329 10:24:05.336604  6088 master.cpp:902] Status update from slave@192.168.1.66:39104: task 61 of framework 201203291014-0-0011 is now in state TASK_FAILED
I0329 10:24:05.336925  6088 master.cpp:1184] Sending 1 offers to framework 201203291014-0-0011
I0329 10:24:05.340662  6088 master.cpp:902] Status update from slave@192.168.1.66:39104: task 59 of framework 201203291014-0-0011 is now in state TASK_FAILED
I0329 10:24:05.340929  6088 master.cpp:902] Status update from slave@192.168.1.66:39104: task 58 of framework 201203291014-0-0011 is now in state TASK_FAILED
I0329 10:24:05.345160  6088 master.cpp:902] Status update from slave@192.168.1.66:39104: task 60 of framework 201203291014-0-0011 is now in state TASK_FAILED
I0329 10:24:05.346946  6088 master.cpp:679] Received reply for offer 201203291014-0-566
I0329 10:24:05.347065  6088 master.cpp:1453] Launching task 65 on slave 201203291014-0-2
I0329 10:24:05.347219  6088 master.cpp:1453] Launching task 66 on slave 201203291014-0-2
I0329 10:24:05.347362  6088 master.cpp:1453] Launching task 67 on slave 201203291014-0-2
I0329 10:24:05.348420  6088 master.cpp:902] Status update from slave@192.168.1.66:39104: task 63 of framework 201203291014-0-0011 is now in state TASK_RUNNING
I0329 10:24:05.351651  6088 master.cpp:902] Status update from slave@192.168.1.66:39104: task 64 of framework 201203291014-0-0011 is now in state TASK_RUNNING
I0329 10:24:05.355278  6088 master.cpp:902] Status update from slave@192.168.1.66:39104: task 65 of framework 201203291014-0-0011 is now in state TASK_RUNNING
I0329 10:24:05.358515  6088 master.cpp:902] Status update from slave@192.168.1.66:39104: task 66 of framework 201203291014-0-0011 is now in state TASK_RUNNING
I0329 10:24:05.366261  6088 master.cpp:902] Status update from slave@192.168.1.66:39104: task 67 of framework 201203291014-0-0011 is now in state TASK_RUNNING
I0329 10:24:05.406167  6088 master.cpp:902] Status update from slave@192.168.1.66:39104: task 63 of framework 201203291014-0-0011 is now in state TASK_FAILED
I0329 10:24:05.406445  6088 master.cpp:1184] Sending 1 offers to framework 201203291014-0-0011
I0329 10:24:05.416067  6088 master.cpp:902] Status update from slave@192.168.1.66:39104: task 66 of framework 201203291014-0-0011 is now in state TASK_FAILED
I0329 10:24:05.420274  6088 master.cpp:902] Status update from slave@192.168.1.66:39104: task 67 of framework 201203291014-0-0011 is now in state TASK_FAILED
I0329 10:24:05.422849  6088 master.cpp:902] Status update from slave@192.168.1.66:39104: task 65 of framework 201203291014-0-0011 is now in state TASK_FAILED
I0329 10:24:05.452021  6088 master.cpp:679] Received reply for offer 201203291014-0-567
I0329 10:24:05.452194  6088 master.cpp:1453] Launching task 68 on slave 201203291014-0-2
I0329 10:24:05.452530  6088 master.cpp:1453] Launching task 69 on slave 201203291014-0-2
I0329 10:24:05.452764  6088 master.cpp:1453] Launching task 70 on slave 201203291014-0-2
I0329 10:24:05.452936  6088 master.cpp:1453] Launching task 71 on slave 201203291014-0-2
I0329 10:24:05.925282  6088 master.cpp:1001] Executor default of framework 201203291014-0-0011 on slave 201203291014-0-2 (ubuntu.gateway.2wire.net) exited with status 256
I0329 10:24:05.926889  6088 master.cpp:1033] Removing task 69 of framework 201203291014-0-0011 because of lost executor
I0329 10:24:05.927130  6088 master.cpp:1184] Sending 1 offers to framework 201203291014-0-0011
I0329 10:24:05.956984  6088 master.cpp:1033] Removing task 68 of framework 201203291014-0-0011 because of lost executor
I0329 10:24:05.981936  6088 master.cpp:1033] Removing task 64 of framework 201203291014-0-0011 because of lost executor
I0329 10:24:05.983724  6088 master.cpp:1033] Removing task 70 of framework 201203291014-0-0011 because of lost executor
I0329 10:24:05.985162  6088 master.cpp:1033] Removing task 71 of framework 201203291014-0-0011 because of lost executor
I0329 10:24:05.985447  6088 master.cpp:679] Received reply for offer 201203291014-0-568
I0329 10:24:05.985616  6088 master.cpp:1453] Launching task 72 on slave 201203291014-0-2
I0329 10:24:05.985816  6088 master.cpp:1453] Launching task 73 on slave 201203291014-0-2
I0329 10:24:05.986040  6088 master.cpp:1453] Launching task 74 on slave 201203291014-0-2
I0329 10:24:05.986284  6088 master.cpp:1453] Launching task 75 on slave 201203291014-0-2
I0329 10:24:06.575238  6088 master.cpp:1184] Sending 1 offers to framework 201203291014-0-0010
I0329 10:24:06.576716  6088 master.cpp:679] Received reply for offer 201203291014-0-569
I0329 10:24:06.576853  6088 master.cpp:1403] Filtered slave 201203291014-0-2 for framework 201203291014-0-0010 for 1 seconds
I0329 10:24:06.859035  6088 master.cpp:902] Status update from slave@192.168.1.66:39104: task 72 of framework 201203291014-0-0011 is now in state TASK_RUNNING
I0329 10:24:06.861726  6088 master.cpp:902] Status update from slave@192.168.1.66:39104: task 73 of framework 201203291014-0-0011 is now in state TASK_RUNNING
I0329 10:24:06.865095  6088 master.cpp:902] Status update from slave@192.168.1.66:39104: task 75 of framework 201203291014-0-0011 is now in state TASK_RUNNING
I0329 10:24:06.868213  6088 master.cpp:902] Status update from slave@192.168.1.66:39104: task 74 of framework 201203291014-0-0011 is now in state TASK_RUNNING
I0329 10:24:07.577291  6088 master.cpp:1184] Sending 1 offers to framework 201203291014-0-0010
I0329 10:24:07.578800  6088 master.cpp:679] Received reply for offer 201203291014-0-570
I0329 10:24:07.578969  6088 master.cpp:1403] Filtered slave 201203291014-0-2 for framework 201203291014-0-0010 for 1 seconds
I0329 10:24:08.578984  6088 master.cpp:1184] Sending 1 offers to framework 201203291014-0-0011
I0329 10:24:08.580591  6088 master.cpp:679] Received reply for offer 201203291014-0-571
I0329 10:24:08.580765  6088 master.cpp:1403] Filtered slave 201203291014-0-2 for framework 201203291014-0-0011 for 1 seconds
I0329 10:24:09.580832  6088 master.cpp:1184] Sending 1 offers to framework 201203291014-0-0010
I0329 10:24:09.634461  6088 master.cpp:1118] Framework 201203291014-0-0010 disconnected
I0329 10:24:09.634841  6088 master.cpp:1118] Framework 201203291014-0-0011 disconnected
I0329 10:24:16.596989  6088 master.cpp:492] Registering framework 201203291014-0-0012 at 2@192.168.1.64:51900
I0329 10:24:16.597254  6088 simple_allocator.cpp:48] Added framework 201203291014-0-0012
I0329 10:24:16.597457  6088 master.cpp:1184] Sending 1 offers to framework 201203291014-0-0012
I0329 10:24:16.597810  6088 master.cpp:492] Registering framework 201203291014-0-0013 at 3@192.168.1.64:51900
I0329 10:24:16.598203  6088 simple_allocator.cpp:48] Added framework 201203291014-0-0013
I0329 10:24:16.614192  6088 master.cpp:679] Received reply for offer 201203291014-0-573
I0329 10:24:16.614356  6088 master.cpp:1403] Filtered slave 201203291014-0-2 for framework 201203291014-0-0012 for 1 seconds
I0329 10:24:17.009630  6088 master.cpp:718] Reviving offers for framework 201203291014-0-0013
I0329 10:24:17.009784  6088 simple_allocator.cpp:145] Filters removed for framework 201203291014-0-0013
I0329 10:24:17.010094  6088 master.cpp:1184] Sending 1 offers to framework 201203291014-0-0013
I0329 10:24:17.013802  6088 master.cpp:679] Received reply for offer 201203291014-0-574
I0329 10:24:17.013984  6088 master.cpp:1403] Filtered slave 201203291014-0-2 for framework 201203291014-0-0013 for 1 seconds
I0329 10:24:18.593142  6088 master.cpp:1184] Sending 1 offers to framework 201203291014-0-0012
I0329 10:24:18.594761  6088 master.cpp:679] Received reply for offer 201203291014-0-575
I0329 10:24:18.594851  6088 master.cpp:1403] Filtered slave 201203291014-0-2 for framework 201203291014-0-0012 for 1 seconds
I0329 10:24:19.595058  6088 master.cpp:1184] Sending 1 offers to framework 201203291014-0-0013
I0329 10:24:19.596798  6088 master.cpp:679] Received reply for offer 201203291014-0-576
I0329 10:24:19.596946  6088 master.cpp:1403] Filtered slave 201203291014-0-2 for framework 201203291014-0-0013 for 1 seconds
I0329 10:24:20.597067  6088 master.cpp:1184] Sending 1 offers to framework 201203291014-0-0012
I0329 10:24:20.598711  6088 master.cpp:679] Received reply for offer 201203291014-0-577
I0329 10:24:20.598853  6088 master.cpp:1403] Filtered slave 201203291014-0-2 for framework 201203291014-0-0012 for 1 seconds
I0329 10:24:21.599014  6088 master.cpp:1184] Sending 1 offers to framework 201203291014-0-0013
I0329 10:24:21.600749  6088 master.cpp:679] Received reply for offer 201203291014-0-578
I0329 10:24:21.600894  6088 master.cpp:1403] Filtered slave 201203291014-0-2 for framework 201203291014-0-0013 for 1 seconds
I0329 10:24:22.600972  6088 master.cpp:1184] Sending 1 offers to framework 201203291014-0-0012
I0329 10:24:22.602597  6088 master.cpp:679] Received reply for offer 201203291014-0-579
I0329 10:24:22.602741  6088 master.cpp:1403] Filtered slave 201203291014-0-2 for framework 201203291014-0-0012 for 1 seconds
I0329 10:24:23.602867  6088 master.cpp:1184] Sending 1 offers to framework 201203291014-0-0013
I0329 10:24:23.661978  6088 master.cpp:679] Received reply for offer 201203291014-0-580
I0329 10:24:23.662157  6088 master.cpp:1453] Launching task 0 on slave 201203291014-0-2
I0329 10:24:23.662530  6088 master.cpp:1453] Launching task 1 on slave 201203291014-0-2
I0329 10:24:23.662854  6088 master.cpp:1453] Launching task 2 on slave 201203291014-0-2
I0329 10:24:23.663000  6088 master.cpp:1453] Launching task 3 on slave 201203291014-0-2
I0329 10:24:24.566550  6088 master.cpp:902] Status update from slave@192.168.1.66:39104: task 0 of framework 201203291014-0-0013 is now in state TASK_RUNNING
I0329 10:24:24.567531  6088 master.cpp:902] Status update from slave@192.168.1.66:39104: task 3 of framework 201203291014-0-0013 is now in state TASK_RUNNING
I0329 10:24:24.568794  6088 master.cpp:902] Status update from slave@192.168.1.66:39104: task 2 of framework 201203291014-0-0013 is now in state TASK_RUNNING
I0329 10:24:24.570320  6088 master.cpp:902] Status update from slave@192.168.1.66:39104: task 1 of framework 201203291014-0-0013 is now in state TASK_RUNNING
I0329 10:24:25.375046  6088 master.cpp:902] Status update from slave@192.168.1.66:39104: task 3 of framework 201203291014-0-0013 is now in state TASK_FINISHED
I0329 10:24:25.375370  6088 master.cpp:1184] Sending 1 offers to framework 201203291014-0-0012
I0329 10:24:25.379246  6088 master.cpp:902] Status update from slave@192.168.1.66:39104: task 1 of framework 201203291014-0-0013 is now in state TASK_FINISHED
I0329 10:24:25.390557  6088 master.cpp:679] Received reply for offer 201203291014-0-581
I0329 10:24:25.390838  6088 master.cpp:1403] Filtered slave 201203291014-0-2 for framework 201203291014-0-0012 for 1 seconds
I0329 10:24:25.429962  6088 master.cpp:902] Status update from slave@192.168.1.66:39104: task 0 of framework 201203291014-0-0013 is now in state TASK_FINISHED
I0329 10:24:25.430227  6088 master.cpp:1184] Sending 1 offers to framework 201203291014-0-0013
I0329 10:24:25.446208  6088 master.cpp:902] Status update from slave@192.168.1.66:39104: task 2 of framework 201203291014-0-0013 is now in state TASK_FINISHED
I0329 10:24:25.450968  6088 master.cpp:679] Received reply for offer 201203291014-0-582
I0329 10:24:25.451232  6088 master.cpp:1453] Launching task 4 on slave 201203291014-0-2
I0329 10:24:25.452079  6088 master.cpp:1453] Launching task 5 on slave 201203291014-0-2
I0329 10:24:25.452471  6088 master.cpp:1453] Launching task 6 on slave 201203291014-0-2
I0329 10:24:25.459764  6088 master.cpp:902] Status update from slave@192.168.1.66:39104: task 4 of framework 201203291014-0-0013 is now in state TASK_RUNNING
I0329 10:24:25.462206  6088 master.cpp:902] Status update from slave@192.168.1.66:39104: task 5 of framework 201203291014-0-0013 is now in state TASK_RUNNING
I0329 10:24:25.467052  6088 master.cpp:902] Status update from slave@192.168.1.66:39104: task 6 of framework 201203291014-0-0013 is now in state TASK_RUNNING
I0329 10:24:25.775583  6088 master.cpp:902] Status update from slave@192.168.1.66:39104: task 5 of framework 201203291014-0-0013 is now in state TASK_FINISHED
I0329 10:24:25.775892  6088 master.cpp:1184] Sending 1 offers to framework 201203291014-0-0013
I0329 10:24:25.779809  6088 master.cpp:902] Status update from slave@192.168.1.66:39104: task 6 of framework 201203291014-0-0013 is now in state TASK_FINISHED
I0329 10:24:25.791962  6088 master.cpp:679] Received reply for offer 201203291014-0-583
I0329 10:24:25.792095  6088 master.cpp:1453] Launching task 7 on slave 201203291014-0-2
I0329 10:24:25.792383  6088 master.cpp:1453] Launching task 8 on slave 201203291014-0-2
I0329 10:24:25.794386  6088 master.cpp:902] Status update from slave@192.168.1.66:39104: task 4 of framework 201203291014-0-0013 is now in state TASK_FINISHED
I0329 10:24:25.794648  6088 master.cpp:1184] Sending 1 offers to framework 201203291014-0-0013
I0329 10:24:25.801985  6088 master.cpp:902] Status update from slave@192.168.1.66:39104: task 7 of framework 201203291014-0-0013 is now in state TASK_RUNNING
I0329 10:24:25.805246  6088 master.cpp:679] Received reply for offer 201203291014-0-584
I0329 10:24:25.805402  6088 master.cpp:1453] Launching task 9 on slave 201203291014-0-2
I0329 10:24:25.805595  6088 master.cpp:1453] Launching task 10 on slave 201203291014-0-2
I0329 10:24:25.806550  6088 master.cpp:902] Status update from slave@192.168.1.66:39104: task 8 of framework 201203291014-0-0013 is now in state TASK_RUNNING
I0329 10:24:25.812367  6088 master.cpp:902] Status update from slave@192.168.1.66:39104: task 9 of framework 201203291014-0-0013 is now in state TASK_RUNNING
I0329 10:24:25.816727  6088 master.cpp:902] Status update from slave@192.168.1.66:39104: task 10 of framework 201203291014-0-0013 is now in state TASK_RUNNING
I0329 10:24:26.180289  6088 master.cpp:902] Status update from slave@192.168.1.66:39104: task 7 of framework 201203291014-0-0013 is now in state TASK_FINISHED
I0329 10:24:26.180604  6088 master.cpp:1184] Sending 1 offers to framework 201203291014-0-0013
I0329 10:24:26.190490  6088 master.cpp:679] Received reply for offer 201203291014-0-585
I0329 10:24:26.190732  6088 master.cpp:1453] Launching task 11 on slave 201203291014-0-2
I0329 10:24:26.205479  6088 master.cpp:902] Status update from slave@192.168.1.66:39104: task 11 of framework 201203291014-0-0013 is now in state TASK_RUNNING
I0329 10:24:26.217229  6088 master.cpp:902] Status update from slave@192.168.1.66:39104: task 8 of framework 201203291014-0-0013 is now in state TASK_FINISHED
I0329 10:24:26.217514  6088 master.cpp:1184] Sending 1 offers to framework 201203291014-0-0013
I0329 10:24:26.222998  6088 master.cpp:902] Status update from slave@192.168.1.66:39104: task 10 of framework 201203291014-0-0013 is now in state TASK_FINISHED
I0329 10:24:26.225491  6088 master.cpp:679] Received reply for offer 201203291014-0-586
I0329 10:24:26.225666  6088 master.cpp:1453] Launching task 12 on slave 201203291014-0-2
I0329 10:24:26.227340  6088 master.cpp:902] Status update from slave@192.168.1.66:39104: task 9 of framework 201203291014-0-0013 is now in state TASK_FINISHED
I0329 10:24:26.227589  6088 master.cpp:1184] Sending 1 offers to framework 201203291014-0-0013
I0329 10:24:26.236868  6088 master.cpp:902] Status update from slave@192.168.1.66:39104: task 12 of framework 201203291014-0-0013 is now in state TASK_RUNNING
I0329 10:24:26.241296  6088 master.cpp:679] Received reply for offer 201203291014-0-587
I0329 10:24:26.241452  6088 master.cpp:1453] Launching task 13 on slave 201203291014-0-2
I0329 10:24:26.241824  6088 master.cpp:1453] Launching task 14 on slave 201203291014-0-2
I0329 10:24:26.249901  6088 master.cpp:902] Status update from slave@192.168.1.66:39104: task 13 of framework 201203291014-0-0013 is now in state TASK_RUNNING
I0329 10:24:26.251700  6088 master.cpp:902] Status update from slave@192.168.1.66:39104: task 14 of framework 201203291014-0-0013 is now in state TASK_RUNNING
I0329 10:24:26.480630  6088 master.cpp:902] Status update from slave@192.168.1.66:39104: task 11 of framework 201203291014-0-0013 is now in state TASK_FINISHED
I0329 10:24:26.480960  6088 master.cpp:1184] Sending 1 offers to framework 201203291014-0-0013
I0329 10:24:26.488785  6088 master.cpp:679] Received reply for offer 201203291014-0-588
I0329 10:24:26.488986  6088 master.cpp:1453] Launching task 15 on slave 201203291014-0-2
I0329 10:24:26.503833  6088 master.cpp:902] Status update from slave@192.168.1.66:39104: task 15 of framework 201203291014-0-0013 is now in state TASK_RUNNING
I0329 10:24:26.613195  6088 master.cpp:902] Status update from slave@192.168.1.66:39104: task 12 of framework 201203291014-0-0013 is now in state TASK_FINISHED
I0329 10:24:26.613487  6088 master.cpp:1184] Sending 1 offers to framework 201203291014-0-0012
I0329 10:24:26.615764  6088 master.cpp:679] Received reply for offer 201203291014-0-589
I0329 10:24:26.615922  6088 master.cpp:1403] Filtered slave 201203291014-0-2 for framework 201203291014-0-0012 for 1 seconds
I0329 10:24:26.633954  6088 master.cpp:902] Status update from slave@192.168.1.66:39104: task 13 of framework 201203291014-0-0013 is now in state TASK_FINISHED
I0329 10:24:26.634256  6088 master.cpp:1184] Sending 1 offers to framework 201203291014-0-0013
I0329 10:24:26.634433  6088 master.cpp:902] Status update from slave@192.168.1.66:39104: task 14 of framework 201203291014-0-0013 is now in state TASK_FINISHED
I0329 10:24:26.645666  6088 master.cpp:679] Received reply for offer 201203291014-0-590
I0329 10:24:26.645817  6088 master.cpp:1453] Launching task 16 on slave 201203291014-0-2
I0329 10:24:26.646002  6088 master.cpp:1453] Launching task 17 on slave 201203291014-0-2
I0329 10:24:26.654957  6088 master.cpp:902] Status update from slave@192.168.1.66:39104: task 16 of framework 201203291014-0-0013 is now in state TASK_RUNNING
I0329 10:24:26.659817  6088 master.cpp:902] Status update from slave@192.168.1.66:39104: task 17 of framework 201203291014-0-0013 is now in state TASK_RUNNING
I0329 10:24:26.770087  6088 master.cpp:902] Status update from slave@192.168.1.66:39104: task 15 of framework 201203291014-0-0013 is now in state TASK_FINISHED
I0329 10:24:26.770406  6088 master.cpp:1184] Sending 1 offers to framework 201203291014-0-0013
I0329 10:24:26.779438  6088 master.cpp:679] Received reply for offer 201203291014-0-591
I0329 10:24:26.779640  6088 master.cpp:1453] Launching task 18 on slave 201203291014-0-2
I0329 10:24:26.779893  6088 master.cpp:1453] Launching task 19 on slave 201203291014-0-2
I0329 10:24:26.792044  6088 master.cpp:902] Status update from slave@192.168.1.66:39104: task 18 of framework 201203291014-0-0013 is now in state TASK_RUNNING
I0329 10:24:26.796202  6088 master.cpp:902] Status update from slave@192.168.1.66:39104: task 19 of framework 201203291014-0-0013 is now in state TASK_RUNNING
I0329 10:24:26.958618  6088 master.cpp:902] Status update from slave@192.168.1.66:39104: task 17 of framework 201203291014-0-0013 is now in state TASK_FINISHED
I0329 10:24:26.959063  6088 master.cpp:1184] Sending 1 offers to framework 201203291014-0-0013
I0329 10:24:26.964550  6088 master.cpp:679] Received reply for offer 201203291014-0-592
I0329 10:24:26.964751  6088 master.cpp:1453] Launching task 20 on slave 201203291014-0-2
I0329 10:24:26.976012  6088 master.cpp:902] Status update from slave@192.168.1.66:39104: task 20 of framework 201203291014-0-0013 is now in state TASK_RUNNING
I0329 10:24:27.015799  6088 master.cpp:902] Status update from slave@192.168.1.66:39104: task 16 of framework 201203291014-0-0013 is now in state TASK_FINISHED
I0329 10:24:27.016079  6088 master.cpp:1184] Sending 1 offers to framework 201203291014-0-0013
I0329 10:24:27.060673  6088 master.cpp:679] Received reply for offer 201203291014-0-593
I0329 10:24:27.060885  6088 master.cpp:1453] Launching task 21 on slave 201203291014-0-2
I0329 10:24:27.072474  6088 master.cpp:902] Status update from slave@192.168.1.66:39104: task 21 of framework 201203291014-0-0013 is now in state TASK_RUNNING
I0329 10:24:27.081058  6088 master.cpp:902] Status update from slave@192.168.1.66:39104: task 18 of framework 201203291014-0-0013 is now in state TASK_FINISHED
I0329 10:24:27.081321  6088 master.cpp:1184] Sending 1 offers to framework 201203291014-0-0013
I0329 10:24:27.128566  6088 master.cpp:679] Received reply for offer 201203291014-0-594
I0329 10:24:27.128736  6088 master.cpp:1453] Launching task 22 on slave 201203291014-0-2
I0329 10:24:27.142520  6088 master.cpp:902] Status update from slave@192.168.1.66:39104: task 22 of framework 201203291014-0-0013 is now in state TASK_RUNNING
I0329 10:24:27.177160  6088 master.cpp:902] Status update from slave@192.168.1.66:39104: task 19 of framework 201203291014-0-0013 is now in state TASK_FINISHED
I0329 10:24:27.177489  6088 master.cpp:1184] Sending 1 offers to framework 201203291014-0-0013
I0329 10:24:27.220250  6088 master.cpp:679] Received reply for offer 201203291014-0-595
I0329 10:24:27.220422  6088 master.cpp:1453] Launching task 23 on slave 201203291014-0-2
I0329 10:24:27.233862  6088 master.cpp:902] Status update from slave@192.168.1.66:39104: task 23 of framework 201203291014-0-0013 is now in state TASK_RUNNING
I0329 10:24:27.368608  6088 master.cpp:902] Status update from slave@192.168.1.66:39104: task 20 of framework 201203291014-0-0013 is now in state TASK_FINISHED
I0329 10:24:27.368912  6088 master.cpp:1184] Sending 1 offers to framework 201203291014-0-0013
I0329 10:24:27.388242  6088 master.cpp:902] Status update from slave@192.168.1.66:39104: task 21 of framework 201203291014-0-0013 is now in state TASK_FINISHED
I0329 10:24:27.411341  6088 master.cpp:679] Received reply for offer 201203291014-0-596
I0329 10:24:27.411530  6088 master.cpp:1453] Launching task 24 on slave 201203291014-0-2
I0329 10:24:27.431402  6088 master.cpp:902] Status update from slave@192.168.1.66:39104: task 24 of framework 201203291014-0-0013 is now in state TASK_RUNNING
I0329 10:24:27.449285  6088 master.cpp:902] Status update from slave@192.168.1.66:39104: task 22 of framework 201203291014-0-0013 is now in state TASK_FINISHED
I0329 10:24:27.449545  6088 master.cpp:1184] Sending 1 offers to framework 201203291014-0-0013
I0329 10:24:27.457424  6088 master.cpp:679] Received reply for offer 201203291014-0-597
I0329 10:24:27.457622  6088 master.cpp:1453] Launching task 25 on slave 201203291014-0-2
I0329 10:24:27.457862  6088 master.cpp:1453] Launching task 26 on slave 201203291014-0-2
I0329 10:24:27.491392  6088 master.cpp:902] Status update from slave@192.168.1.66:39104: task 25 of framework 201203291014-0-0013 is now in state TASK_RUNNING
I0329 10:24:27.491585  6088 master.cpp:902] Status update from slave@192.168.1.66:39104: task 26 of framework 201203291014-0-0013 is now in state TASK_RUNNING
I0329 10:24:27.556769  6088 master.cpp:902] Status update from slave@192.168.1.66:39104: task 23 of framework 201203291014-0-0013 is now in state TASK_FINISHED
I0329 10:24:27.557148  6088 master.cpp:1184] Sending 1 offers to framework 201203291014-0-0013
I0329 10:24:27.564014  6088 master.cpp:679] Received reply for offer 201203291014-0-598
I0329 10:24:27.564173  6088 master.cpp:1453] Launching task 27 on slave 201203291014-0-2
I0329 10:24:27.577365  6088 master.cpp:902] Status update from slave@192.168.1.66:39104: task 27 of framework 201203291014-0-0013 is now in state TASK_RUNNING
I0329 10:24:27.747733  6088 master.cpp:902] Status update from slave@192.168.1.66:39104: task 24 of framework 201203291014-0-0013 is now in state TASK_FINISHED
I0329 10:24:27.748051  6088 master.cpp:1184] Sending 1 offers to framework 201203291014-0-0013
I0329 10:24:27.752887  6088 master.cpp:679] Received reply for offer 201203291014-0-599
I0329 10:24:27.753049  6088 master.cpp:1453] Launching task 28 on slave 201203291014-0-2
I0329 10:24:27.768534  6088 master.cpp:902] Status update from slave@192.168.1.66:39104: task 28 of framework 201203291014-0-0013 is now in state TASK_RUNNING
I0329 10:24:27.856153  6088 master.cpp:902] Status update from slave@192.168.1.66:39104: task 25 of framework 201203291014-0-0013 is now in state TASK_FINISHED
I0329 10:24:27.856536  6088 master.cpp:1184] Sending 1 offers to framework 201203291014-0-0013
I0329 10:24:27.861361  6088 master.cpp:679] Received reply for offer 201203291014-0-600
I0329 10:24:27.861532  6088 master.cpp:1453] Launching task 29 on slave 201203291014-0-2
I0329 10:24:27.876873  6088 master.cpp:902] Status update from slave@192.168.1.66:39104: task 29 of framework 201203291014-0-0013 is now in state TASK_RUNNING
I0329 10:24:27.898095  6088 master.cpp:902] Status update from slave@192.168.1.66:39104: task 26 of framework 201203291014-0-0013 is now in state TASK_FINISHED
I0329 10:24:27.898367  6088 master.cpp:1184] Sending 1 offers to framework 201203291014-0-0013
I0329 10:24:27.903105  6088 master.cpp:679] Received reply for offer 201203291014-0-601
I0329 10:24:27.903280  6088 master.cpp:1453] Launching task 30 on slave 201203291014-0-2
I0329 10:24:27.915766  6088 master.cpp:902] Status update from slave@192.168.1.66:39104: task 30 of framework 201203291014-0-0013 is now in state TASK_RUNNING
I0329 10:24:27.947968  6088 master.cpp:902] Status update from slave@192.168.1.66:39104: task 27 of framework 201203291014-0-0013 is now in state TASK_FINISHED
I0329 10:24:27.948240  6088 master.cpp:1184] Sending 1 offers to framework 201203291014-0-0013
I0329 10:24:27.954280  6088 master.cpp:679] Received reply for offer 201203291014-0-602
I0329 10:24:27.954476  6088 master.cpp:1453] Launching task 31 on slave 201203291014-0-2
I0329 10:24:27.965214  6088 master.cpp:902] Status update from slave@192.168.1.66:39104: task 31 of framework 201203291014-0-0013 is now in state TASK_RUNNING
I0329 10:24:28.094928  6088 master.cpp:902] Status update from slave@192.168.1.66:39104: task 28 of framework 201203291014-0-0013 is now in state TASK_FINISHED
I0329 10:24:28.095319  6088 master.cpp:1184] Sending 1 offers to framework 201203291014-0-0013
I0329 10:24:28.100307  6088 master.cpp:679] Received reply for offer 201203291014-0-603
I0329 10:24:28.100563  6088 master.cpp:1453] Launching task 32 on slave 201203291014-0-2
I0329 10:24:28.113801  6088 master.cpp:902] Status update from slave@192.168.1.66:39104: task 32 of framework 201203291014-0-0013 is now in state TASK_RUNNING
I0329 10:24:28.205065  6088 master.cpp:902] Status update from slave@192.168.1.66:39104: task 30 of framework 201203291014-0-0013 is now in state TASK_FINISHED
I0329 10:24:28.205368  6088 master.cpp:1184] Sending 1 offers to framework 201203291014-0-0013
I0329 10:24:28.210124  6088 master.cpp:679] Received reply for offer 201203291014-0-604
I0329 10:24:28.210317  6088 master.cpp:1453] Launching task 33 on slave 201203291014-0-2
I0329 10:24:28.222885  6088 master.cpp:902] Status update from slave@192.168.1.66:39104: task 33 of framework 201203291014-0-0013 is now in state TASK_RUNNING
I0329 10:24:28.235512  6088 master.cpp:902] Status update from slave@192.168.1.66:39104: task 29 of framework 201203291014-0-0013 is now in state TASK_FINISHED
I0329 10:24:28.235785  6088 master.cpp:1184] Sending 1 offers to framework 201203291014-0-0013
I0329 10:24:28.247251  6088 master.cpp:679] Received reply for offer 201203291014-0-605
I0329 10:24:28.247406  6088 master.cpp:1453] Launching task 34 on slave 201203291014-0-2
I0329 10:24:28.256854  6088 master.cpp:902] Status update from slave@192.168.1.66:39104: task 34 of framework 201203291014-0-0013 is now in state TASK_RUNNING
I0329 10:24:28.419481  6088 master.cpp:902] Status update from slave@192.168.1.66:39104: task 31 of framework 201203291014-0-0013 is now in state TASK_FINISHED
I0329 10:24:28.419796  6088 master.cpp:1184] Sending 1 offers to framework 201203291014-0-0013
I0329 10:24:28.424036  6088 master.cpp:679] Received reply for offer 201203291014-0-606
I0329 10:24:28.424269  6088 master.cpp:1453] Launching task 35 on slave 201203291014-0-2
I0329 10:24:28.437224  6088 master.cpp:902] Status update from slave@192.168.1.66:39104: task 35 of framework 201203291014-0-0013 is now in state TASK_RUNNING
I0329 10:24:28.525357  6088 master.cpp:902] Status update from slave@192.168.1.66:39104: task 32 of framework 201203291014-0-0013 is now in state TASK_FINISHED
I0329 10:24:28.525662  6088 master.cpp:1184] Sending 1 offers to framework 201203291014-0-0013
I0329 10:24:28.531693  6088 master.cpp:679] Received reply for offer 201203291014-0-607
I0329 10:24:28.531893  6088 master.cpp:1453] Launching task 36 on slave 201203291014-0-2
I0329 10:24:28.545678  6088 master.cpp:902] Status update from slave@192.168.1.66:39104: task 36 of framework 201203291014-0-0013 is now in state TASK_RUNNING
I0329 10:24:28.593400  6088 master.cpp:902] Status update from slave@192.168.1.66:39104: task 33 of framework 201203291014-0-0013 is now in state TASK_FINISHED
I0329 10:24:28.593866  6088 master.cpp:1184] Sending 1 offers to framework 201203291014-0-0013
I0329 10:24:28.598027  6088 master.cpp:679] Received reply for offer 201203291014-0-608
I0329 10:24:28.598162  6088 master.cpp:1453] Launching task 37 on slave 201203291014-0-2
I0329 10:24:28.610831  6088 master.cpp:902] Status update from slave@192.168.1.66:39104: task 37 of framework 201203291014-0-0013 is now in state TASK_RUNNING
I0329 10:24:28.717350  6088 master.cpp:902] Status update from slave@192.168.1.66:39104: task 34 of framework 201203291014-0-0013 is now in state TASK_FINISHED
I0329 10:24:28.717668  6088 master.cpp:1184] Sending 1 offers to framework 201203291014-0-0012
I0329 10:24:28.719789  6088 master.cpp:679] Received reply for offer 201203291014-0-609
I0329 10:24:28.719938  6088 master.cpp:1403] Filtered slave 201203291014-0-2 for framework 201203291014-0-0012 for 1 seconds
I0329 10:24:28.748744  6088 master.cpp:902] Status update from slave@192.168.1.66:39104: task 35 of framework 201203291014-0-0013 is now in state TASK_FINISHED
I0329 10:24:28.749006  6088 master.cpp:1184] Sending 1 offers to framework 201203291014-0-0013
I0329 10:24:28.755506  6088 master.cpp:679] Received reply for offer 201203291014-0-610
I0329 10:24:28.755736  6088 master.cpp:1453] Launching task 38 on slave 201203291014-0-2
I0329 10:24:28.756052  6088 master.cpp:1453] Launching task 39 on slave 201203291014-0-2
I0329 10:24:28.791632  6088 master.cpp:902] Status update from slave@192.168.1.66:39104: task 38 of framework 201203291014-0-0013 is now in state TASK_RUNNING
I0329 10:24:28.791820  6088 master.cpp:902] Status update from slave@192.168.1.66:39104: task 39 of framework 201203291014-0-0013 is now in state TASK_RUNNING
I0329 10:24:28.875818  6088 master.cpp:902] Status update from slave@192.168.1.66:39104: task 36 of framework 201203291014-0-0013 is now in state TASK_FINISHED
I0329 10:24:28.876139  6088 master.cpp:1184] Sending 1 offers to framework 201203291014-0-0013
I0329 10:24:28.878245  6088 master.cpp:679] Received reply for offer 201203291014-0-611
I0329 10:24:28.878427  6088 master.cpp:1403] Filtered slave 201203291014-0-2 for framework 201203291014-0-0013 for 1 seconds
I0329 10:24:28.946960  6088 master.cpp:902] Status update from slave@192.168.1.66:39104: task 37 of framework 201203291014-0-0013 is now in state TASK_FINISHED
I0329 10:24:29.068167  6088 master.cpp:902] Status update from slave@192.168.1.66:39104: task 39 of framework 201203291014-0-0013 is now in state TASK_FINISHED
I0329 10:24:29.107832  6088 master.cpp:902] Status update from slave@192.168.1.66:39104: task 38 of framework 201203291014-0-0013 is now in state TASK_FINISHED
I0329 10:24:29.130894  6088 master.cpp:718] Reviving offers for framework 201203291014-0-0013
I0329 10:24:29.131027  6088 simple_allocator.cpp:145] Filters removed for framework 201203291014-0-0013
I0329 10:24:29.131578  6088 master.cpp:1184] Sending 1 offers to framework 201203291014-0-0013
I0329 10:24:29.152369  6088 master.cpp:679] Received reply for offer 201203291014-0-612
I0329 10:24:29.152536  6088 master.cpp:1403] Filtered slave 201203291014-0-2 for framework 201203291014-0-0013 for 1 seconds
I0329 10:24:30.609283  6088 master.cpp:1184] Sending 1 offers to framework 201203291014-0-0012
I0329 10:24:30.610730  6088 master.cpp:679] Received reply for offer 201203291014-0-613
I0329 10:24:30.610872  6088 master.cpp:1403] Filtered slave 201203291014-0-2 for framework 201203291014-0-0012 for 1 seconds
I0329 10:24:31.610929  6088 master.cpp:1184] Sending 1 offers to framework 201203291014-0-0013
I0329 10:24:31.612493  6088 master.cpp:679] Received reply for offer 201203291014-0-614
I0329 10:24:31.612670  6088 master.cpp:1403] Filtered slave 201203291014-0-2 for framework 201203291014-0-0013 for 1 seconds
I0329 10:24:32.612681  6088 master.cpp:1184] Sending 1 offers to framework 201203291014-0-0012
I0329 10:24:32.614033  6088 master.cpp:679] Received reply for offer 201203291014-0-615
I0329 10:24:32.614172  6088 master.cpp:1403] Filtered slave 201203291014-0-2 for framework 201203291014-0-0012 for 1 seconds
I0329 10:24:33.614246  6088 master.cpp:1184] Sending 1 offers to framework 201203291014-0-0013
I0329 10:24:33.615761  6088 master.cpp:679] Received reply for offer 201203291014-0-616
I0329 10:24:33.615847  6088 master.cpp:1403] Filtered slave 201203291014-0-2 for framework 201203291014-0-0013 for 1 seconds
I0329 10:24:34.615950  6088 master.cpp:1184] Sending 1 offers to framework 201203291014-0-0012
I0329 10:24:34.617338  6088 master.cpp:679] Received reply for offer 201203291014-0-617
I0329 10:24:34.617480  6088 master.cpp:1403] Filtered slave 201203291014-0-2 for framework 201203291014-0-0012 for 1 seconds
I0329 10:24:35.617557  6088 master.cpp:1184] Sending 1 offers to framework 201203291014-0-0013
I0329 10:24:35.635406  6088 master.cpp:679] Received reply for offer 201203291014-0-618
I0329 10:24:35.635568  6088 master.cpp:1453] Launching task 40 on slave 201203291014-0-2
I0329 10:24:35.635907  6088 master.cpp:1453] Launching task 41 on slave 201203291014-0-2
I0329 10:24:35.636214  6088 master.cpp:1453] Launching task 42 on slave 201203291014-0-2
I0329 10:24:35.636440  6088 master.cpp:1453] Launching task 43 on slave 201203291014-0-2
I0329 10:24:35.642372  6088 master.cpp:902] Status update from slave@192.168.1.66:39104: task 40 of framework 201203291014-0-0013 is now in state TASK_RUNNING
I0329 10:24:35.645007  6088 master.cpp:902] Status update from slave@192.168.1.66:39104: task 41 of framework 201203291014-0-0013 is now in state TASK_RUNNING
I0329 10:24:35.649411  6088 master.cpp:902] Status update from slave@192.168.1.66:39104: task 42 of framework 201203291014-0-0013 is now in state TASK_RUNNING
I0329 10:24:35.652370  6088 master.cpp:902] Status update from slave@192.168.1.66:39104: task 43 of framework 201203291014-0-0013 is now in state TASK_RUNNING
I0329 10:24:35.782358  6088 master.cpp:902] Status update from slave@192.168.1.66:39104: task 43 of framework 201203291014-0-0013 is now in state TASK_FAILED
I0329 10:24:35.782635  6088 master.cpp:1184] Sending 1 offers to framework 201203291014-0-0013
I0329 10:24:35.783932  6088 master.cpp:902] Status update from slave@192.168.1.66:39104: task 41 of framework 201203291014-0-0013 is now in state TASK_FAILED
I0329 10:24:35.785670  6088 master.cpp:902] Status update from slave@192.168.1.66:39104: task 40 of framework 201203291014-0-0013 is now in state TASK_FAILED
I0329 10:24:35.787447  6088 master.cpp:902] Status update from slave@192.168.1.66:39104: task 42 of framework 201203291014-0-0013 is now in state TASK_FAILED
I0329 10:24:35.798715  6088 master.cpp:679] Received reply for offer 201203291014-0-619
I0329 10:24:35.798856  6088 master.cpp:1453] Launching task 44 on slave 201203291014-0-2
I0329 10:24:35.804204  6088 master.cpp:902] Status update from slave@192.168.1.66:39104: task 44 of framework 201203291014-0-0013 is now in state TASK_RUNNING
I0329 10:24:35.844475  6088 master.cpp:902] Status update from slave@192.168.1.66:39104: task 44 of framework 201203291014-0-0013 is now in state TASK_FAILED
I0329 10:24:35.844748  6088 master.cpp:1184] Sending 1 offers to framework 201203291014-0-0013
I0329 10:24:35.856734  6088 master.cpp:679] Received reply for offer 201203291014-0-620
I0329 10:24:35.856961  6088 master.cpp:1453] Launching task 45 on slave 201203291014-0-2
I0329 10:24:35.857718  6088 master.cpp:1453] Launching task 46 on slave 201203291014-0-2
I0329 10:24:35.858177  6088 master.cpp:1453] Launching task 47 on slave 201203291014-0-2
I0329 10:24:35.858803  6088 master.cpp:1453] Launching task 48 on slave 201203291014-0-2
I0329 10:24:35.862820  6088 master.cpp:902] Status update from slave@192.168.1.66:39104: task 45 of framework 201203291014-0-0013 is now in state TASK_RUNNING
I0329 10:24:35.865244  6088 master.cpp:902] Status update from slave@192.168.1.66:39104: task 46 of framework 201203291014-0-0013 is now in state TASK_RUNNING
I0329 10:24:35.867683  6088 master.cpp:902] Status update from slave@192.168.1.66:39104: task 47 of framework 201203291014-0-0013 is now in state TASK_RUNNING
I0329 10:24:35.870254  6088 master.cpp:902] Status update from slave@192.168.1.66:39104: task 48 of framework 201203291014-0-0013 is now in state TASK_RUNNING
I0329 10:24:36.955199  6088 master.cpp:1001] Executor default of framework 201203291014-0-0013 on slave 201203291014-0-2 (ubuntu.gateway.2wire.net) exited with status 256
I0329 10:24:36.956661  6088 master.cpp:1033] Removing task 48 of framework 201203291014-0-0013 because of lost executor
I0329 10:24:36.956902  6088 master.cpp:1184] Sending 1 offers to framework 201203291014-0-0012
I0329 10:24:36.958575  6088 master.cpp:1033] Removing task 45 of framework 201203291014-0-0013 because of lost executor
I0329 10:24:36.960309  6088 master.cpp:1033] Removing task 47 of framework 201203291014-0-0013 because of lost executor
I0329 10:24:36.961815  6088 master.cpp:1033] Removing task 46 of framework 201203291014-0-0013 because of lost executor
I0329 10:24:36.962049  6088 master.cpp:679] Received reply for offer 201203291014-0-621
I0329 10:24:36.962224  6088 master.cpp:1184] Sending 1 offers to framework 201203291014-0-0013
I0329 10:24:36.962414  6088 master.cpp:1403] Filtered slave 201203291014-0-2 for framework 201203291014-0-0012 for 1 seconds
I0329 10:24:36.969791  6088 master.cpp:679] Received reply for offer 201203291014-0-622
I0329 10:24:36.969996  6088 master.cpp:1453] Launching task 49 on slave 201203291014-0-2
I0329 10:24:36.970199  6088 master.cpp:1453] Launching task 50 on slave 201203291014-0-2
I0329 10:24:36.970434  6088 master.cpp:1453] Launching task 51 on slave 201203291014-0-2
I0329 10:24:37.620565  6088 master.cpp:1184] Sending 1 offers to framework 201203291014-0-0013
I0329 10:24:37.624522  6088 master.cpp:679] Received reply for offer 201203291014-0-623
I0329 10:24:37.624660  6088 master.cpp:1453] Launching task 52 on slave 201203291014-0-2
I0329 10:24:37.816027  6088 master.cpp:902] Status update from slave@192.168.1.66:39104: task 51 of framework 201203291014-0-0013 is now in state TASK_RUNNING
I0329 10:24:37.817442  6088 master.cpp:902] Status update from slave@192.168.1.66:39104: task 52 of framework 201203291014-0-0013 is now in state TASK_RUNNING
I0329 10:24:37.818312  6088 master.cpp:902] Status update from slave@192.168.1.66:39104: task 50 of framework 201203291014-0-0013 is now in state TASK_RUNNING
I0329 10:24:37.819699  6088 master.cpp:902] Status update from slave@192.168.1.66:39104: task 49 of framework 201203291014-0-0013 is now in state TASK_RUNNING
I0329 10:24:38.710114  6088 master.cpp:902] Status update from slave@192.168.1.66:39104: task 50 of framework 201203291014-0-0013 is now in state TASK_FAILED
I0329 10:24:38.710382  6088 master.cpp:1184] Sending 1 offers to framework 201203291014-0-0012
I0329 10:24:38.711055  6088 master.cpp:902] Status update from slave@192.168.1.66:39104: task 49 of framework 201203291014-0-0013 is now in state TASK_FAILED
I0329 10:24:38.723909  6088 master.cpp:902] Status update from slave@192.168.1.66:39104: task 51 of framework 201203291014-0-0013 is now in state TASK_FAILED
I0329 10:24:38.764684  6088 master.cpp:679] Received reply for offer 201203291014-0-624
I0329 10:24:38.764957  6088 master.cpp:1403] Filtered slave 201203291014-0-2 for framework 201203291014-0-0012 for 1 seconds
I0329 10:24:38.765130  6088 master.cpp:902] Status update from slave@192.168.1.66:39104: task 52 of framework 201203291014-0-0013 is now in state TASK_FAILED
I0329 10:24:38.765390  6088 master.cpp:1184] Sending 1 offers to framework 201203291014-0-0013
I0329 10:24:38.777588  6088 master.cpp:679] Received reply for offer 201203291014-0-625
I0329 10:24:38.777719  6088 master.cpp:1453] Launching task 53 on slave 201203291014-0-2
I0329 10:24:38.777945  6088 master.cpp:1453] Launching task 54 on slave 201203291014-0-2
I0329 10:24:38.778179  6088 master.cpp:1453] Launching task 55 on slave 201203291014-0-2
I0329 10:24:38.778328  6088 master.cpp:1453] Launching task 56 on slave 201203291014-0-2
I0329 10:24:39.957269  6088 master.cpp:1001] Executor default of framework 201203291014-0-0013 on slave 201203291014-0-2 (ubuntu.gateway.2wire.net) exited with status 256
I0329 10:24:39.958734  6088 master.cpp:1033] Removing task 56 of framework 201203291014-0-0013 because of lost executor
I0329 10:24:39.958946  6088 master.cpp:1184] Sending 1 offers to framework 201203291014-0-0013
I0329 10:24:39.960640  6088 master.cpp:1033] Removing task 54 of framework 201203291014-0-0013 because of lost executor
I0329 10:24:39.962177  6088 master.cpp:1033] Removing task 55 of framework 201203291014-0-0013 because of lost executor
I0329 10:24:39.963692  6088 master.cpp:1033] Removing task 53 of framework 201203291014-0-0013 because of lost executor
I0329 10:24:39.964318  6088 master.cpp:679] Received reply for offer 201203291014-0-626
I0329 10:24:39.964514  6088 master.cpp:1453] Launching task 57 on slave 201203291014-0-2
I0329 10:24:40.624688  6088 master.cpp:1184] Sending 1 offers to framework 201203291014-0-0012
I0329 10:24:40.626042  6088 master.cpp:679] Received reply for offer 201203291014-0-627
I0329 10:24:40.626183  6088 master.cpp:1403] Filtered slave 201203291014-0-2 for framework 201203291014-0-0012 for 1 seconds
I0329 10:24:40.836078  6088 master.cpp:902] Status update from slave@192.168.1.66:39104: task 57 of framework 201203291014-0-0013 is now in state TASK_RUNNING
I0329 10:24:41.522718  6088 master.cpp:902] Status update from slave@192.168.1.66:39104: task 57 of framework 201203291014-0-0013 is now in state TASK_FAILED
I0329 10:24:41.523038  6088 master.cpp:1184] Sending 1 offers to framework 201203291014-0-0013
I0329 10:24:41.524715  6088 master.cpp:679] Received reply for offer 201203291014-0-628
I0329 10:24:41.524880  6088 master.cpp:1403] Filtered slave 201203291014-0-2 for framework 201203291014-0-0013 for 1 seconds
I0329 10:24:41.957741  6088 master.cpp:1001] Executor default of framework 201203291014-0-0013 on slave 201203291014-0-2 (ubuntu.gateway.2wire.net) exited with status 256
I0329 10:24:42.627609  6088 master.cpp:1184] Sending 1 offers to framework 201203291014-0-0012
I0329 10:24:42.629034  6088 master.cpp:679] Received reply for offer 201203291014-0-629
I0329 10:24:42.629173  6088 master.cpp:1403] Filtered slave 201203291014-0-2 for framework 201203291014-0-0012 for 1 seconds
I0329 10:24:43.629241  6088 master.cpp:1184] Sending 1 offers to framework 201203291014-0-0013
I0329 10:24:43.630689  6088 master.cpp:679] Received reply for offer 201203291014-0-630
I0329 10:24:43.630866  6088 master.cpp:1403] Filtered slave 201203291014-0-2 for framework 201203291014-0-0013 for 1 seconds
I0329 10:24:44.630873  6088 master.cpp:1184] Sending 1 offers to framework 201203291014-0-0012
I0329 10:24:44.632297  6088 master.cpp:679] Received reply for offer 201203291014-0-631
I0329 10:24:44.632468  6088 master.cpp:1403] Filtered slave 201203291014-0-2 for framework 201203291014-0-0012 for 1 seconds
I0329 10:24:45.632504  6088 master.cpp:1184] Sending 1 offers to framework 201203291014-0-0013
I0329 10:24:45.633924  6088 master.cpp:679] Received reply for offer 201203291014-0-632
I0329 10:24:45.634098  6088 master.cpp:1403] Filtered slave 201203291014-0-2 for framework 201203291014-0-0013 for 1 seconds
I0329 10:24:46.633216  6088 master.cpp:1184] Sending 1 offers to framework 201203291014-0-0012
I0329 10:24:46.634686  6088 master.cpp:679] Received reply for offer 201203291014-0-633
I0329 10:24:46.634856  6088 master.cpp:1403] Filtered slave 201203291014-0-2 for framework 201203291014-0-0012 for 1 seconds
I0329 10:24:47.634863  6088 master.cpp:1184] Sending 1 offers to framework 201203291014-0-0013
I0329 10:24:47.636339  6088 master.cpp:679] Received reply for offer 201203291014-0-634
I0329 10:24:47.636481  6088 master.cpp:1403] Filtered slave 201203291014-0-2 for framework 201203291014-0-0013 for 1 seconds
I0329 10:24:48.636526  6088 master.cpp:1184] Sending 1 offers to framework 201203291014-0-0012
I0329 10:24:48.637951  6088 master.cpp:679] Received reply for offer 201203291014-0-635
I0329 10:24:48.638089  6088 master.cpp:1403] Filtered slave 201203291014-0-2 for framework 201203291014-0-0012 for 1 seconds
I0329 10:24:49.638166  6088 master.cpp:1184] Sending 1 offers to framework 201203291014-0-0013
I0329 10:24:49.639612  6088 master.cpp:679] Received reply for offer 201203291014-0-636
I0329 10:24:49.639729  6088 master.cpp:1403] Filtered slave 201203291014-0-2 for framework 201203291014-0-0013 for 1 seconds
I0329 10:24:50.639799  6088 master.cpp:1184] Sending 1 offers to framework 201203291014-0-0012
I0329 10:24:50.641247  6088 master.cpp:679] Received reply for offer 201203291014-0-637
I0329 10:24:50.641383  6088 master.cpp:1403] Filtered slave 201203291014-0-2 for framework 201203291014-0-0012 for 1 seconds
I0329 10:24:51.641438  6088 master.cpp:1184] Sending 1 offers to framework 201203291014-0-0013
I0329 10:24:51.642827  6088 master.cpp:679] Received reply for offer 201203291014-0-638
I0329 10:24:51.642964  6088 master.cpp:1403] Filtered slave 201203291014-0-2 for framework 201203291014-0-0013 for 1 seconds
I0329 10:24:52.642190  6088 master.cpp:1184] Sending 1 offers to framework 201203291014-0-0012
I0329 10:24:52.643601  6088 master.cpp:679] Received reply for offer 201203291014-0-639
I0329 10:24:52.643738  6088 master.cpp:1403] Filtered slave 201203291014-0-2 for framework 201203291014-0-0012 for 1 seconds
I0329 10:24:53.643790  6088 master.cpp:1184] Sending 1 offers to framework 201203291014-0-0013
I0329 10:24:53.645144  6088 master.cpp:679] Received reply for offer 201203291014-0-640
I0329 10:24:53.645283  6088 master.cpp:1403] Filtered slave 201203291014-0-2 for framework 201203291014-0-0013 for 1 seconds
I0329 10:24:54.645334  6088 master.cpp:1184] Sending 1 offers to framework 201203291014-0-0012
I0329 10:24:54.646730  6088 master.cpp:679] Received reply for offer 201203291014-0-641
I0329 10:24:54.646814  6088 master.cpp:1403] Filtered slave 201203291014-0-2 for framework 201203291014-0-0012 for 1 seconds
I0329 10:24:55.646935  6088 master.cpp:1184] Sending 1 offers to framework 201203291014-0-0013
I0329 10:24:55.648398  6088 master.cpp:679] Received reply for offer 201203291014-0-642
I0329 10:24:55.648540  6088 master.cpp:1403] Filtered slave 201203291014-0-2 for framework 201203291014-0-0013 for 1 seconds
I0329 10:24:56.648365  6088 master.cpp:1184] Sending 1 offers to framework 201203291014-0-0012
I0329 10:24:56.649807  6088 master.cpp:679] Received reply for offer 201203291014-0-643
I0329 10:24:56.649976  6088 master.cpp:1403] Filtered slave 201203291014-0-2 for framework 201203291014-0-0012 for 1 seconds
I0329 10:24:57.649955  6088 master.cpp:1184] Sending 1 offers to framework 201203291014-0-0013
I0329 10:24:57.651423  6088 master.cpp:679] Received reply for offer 201203291014-0-644
I0329 10:24:57.651564  6088 master.cpp:1403] Filtered slave 201203291014-0-2 for framework 201203291014-0-0013 for 1 seconds
I0329 10:24:58.651310  6088 master.cpp:1184] Sending 1 offers to framework 201203291014-0-0012
I0329 10:24:58.652679  6088 master.cpp:679] Received reply for offer 201203291014-0-645
I0329 10:24:58.652816  6088 master.cpp:1403] Filtered slave 201203291014-0-2 for framework 201203291014-0-0012 for 1 seconds
I0329 10:24:59.652874  6088 master.cpp:1184] Sending 1 offers to framework 201203291014-0-0013
I0329 10:24:59.654259  6088 master.cpp:679] Received reply for offer 201203291014-0-646
I0329 10:24:59.654345  6088 master.cpp:1403] Filtered slave 201203291014-0-2 for framework 201203291014-0-0013 for 1 seconds
I0329 10:25:00.654464  6088 master.cpp:1184] Sending 1 offers to framework 201203291014-0-0012
I0329 10:25:00.655869  6088 master.cpp:679] Received reply for offer 201203291014-0-647
I0329 10:25:00.656008  6088 master.cpp:1403] Filtered slave 201203291014-0-2 for framework 201203291014-0-0012 for 1 seconds
I0329 10:25:01.655397  6088 master.cpp:1184] Sending 1 offers to framework 201203291014-0-0013
I0329 10:25:01.656854  6088 master.cpp:679] Received reply for offer 201203291014-0-648
I0329 10:25:01.657027  6088 master.cpp:1403] Filtered slave 201203291014-0-2 for framework 201203291014-0-0013 for 1 seconds
I0329 10:25:02.657021  6088 master.cpp:1184] Sending 1 offers to framework 201203291014-0-0012
I0329 10:25:02.658474  6088 master.cpp:679] Received reply for offer 201203291014-0-649
I0329 10:25:02.658612  6088 master.cpp:1403] Filtered slave 201203291014-0-2 for framework 201203291014-0-0012 for 1 seconds
I0329 10:25:03.658673  6088 master.cpp:1184] Sending 1 offers to framework 201203291014-0-0013
I0329 10:25:03.660136  6088 master.cpp:679] Received reply for offer 201203291014-0-650
I0329 10:25:03.660279  6088 master.cpp:1403] Filtered slave 201203291014-0-2 for framework 201203291014-0-0013 for 1 seconds
I0329 10:25:04.660308  6088 master.cpp:1184] Sending 1 offers to framework 201203291014-0-0012
I0329 10:25:04.662161  6088 master.cpp:679] Received reply for offer 201203291014-0-651
I0329 10:25:04.662245  6088 master.cpp:1403] Filtered slave 201203291014-0-2 for framework 201203291014-0-0012 for 1 seconds
I0329 10:25:05.662375  6088 master.cpp:1184] Sending 1 offers to framework 201203291014-0-0013
I0329 10:25:05.664057  6088 master.cpp:679] Received reply for offer 201203291014-0-652
I0329 10:25:05.664197  6088 master.cpp:1403] Filtered slave 201203291014-0-2 for framework 201203291014-0-0013 for 1 seconds
I0329 10:25:06.663315  6088 master.cpp:1184] Sending 1 offers to framework 201203291014-0-0012
I0329 10:25:06.664752  6088 master.cpp:679] Received reply for offer 201203291014-0-653
I0329 10:25:06.664870  6088 master.cpp:1403] Filtered slave 201203291014-0-2 for framework 201203291014-0-0012 for 1 seconds
I0329 10:25:07.664949  6088 master.cpp:1184] Sending 1 offers to framework 201203291014-0-0013
I0329 10:25:07.666440  6088 master.cpp:679] Received reply for offer 201203291014-0-654
I0329 10:25:07.666564  6088 master.cpp:1403] Filtered slave 201203291014-0-2 for framework 201203291014-0-0013 for 1 seconds
I0329 10:25:08.666659  6088 master.cpp:1184] Sending 1 offers to framework 201203291014-0-0012
I0329 10:25:08.668441  6088 master.cpp:679] Received reply for offer 201203291014-0-655
I0329 10:25:08.668580  6088 master.cpp:1403] Filtered slave 201203291014-0-2 for framework 201203291014-0-0012 for 1 seconds
I0329 10:25:09.668614  6088 master.cpp:1184] Sending 1 offers to framework 201203291014-0-0013
I0329 10:25:09.670227  6088 master.cpp:679] Received reply for offer 201203291014-0-656
I0329 10:25:09.670312  6088 master.cpp:1403] Filtered slave 201203291014-0-2 for framework 201203291014-0-0013 for 1 seconds
I0329 10:25:10.670428  6088 master.cpp:1184] Sending 1 offers to framework 201203291014-0-0012
I0329 10:25:10.672191  6088 master.cpp:679] Received reply for offer 201203291014-0-657
I0329 10:25:10.672330  6088 master.cpp:1403] Filtered slave 201203291014-0-2 for framework 201203291014-0-0012 for 1 seconds
I0329 10:25:11.672377  6088 master.cpp:1184] Sending 1 offers to framework 201203291014-0-0013
I0329 10:25:11.673867  6088 master.cpp:679] Received reply for offer 201203291014-0-658
I0329 10:25:11.674037  6088 master.cpp:1403] Filtered slave 201203291014-0-2 for framework 201203291014-0-0013 for 1 seconds
I0329 10:25:12.674082  6088 master.cpp:1184] Sending 1 offers to framework 201203291014-0-0012
I0329 10:25:12.675814  6088 master.cpp:679] Received reply for offer 201203291014-0-659
I0329 10:25:12.675953  6088 master.cpp:1403] Filtered slave 201203291014-0-2 for framework 201203291014-0-0012 for 1 seconds
I0329 10:25:13.676025  6088 master.cpp:1184] Sending 1 offers to framework 201203291014-0-0013
I0329 10:25:13.677665  6088 master.cpp:679] Received reply for offer 201203291014-0-660
I0329 10:25:13.677872  6088 master.cpp:1403] Filtered slave 201203291014-0-2 for framework 201203291014-0-0013 for 1 seconds
I0329 10:25:14.677849  6088 master.cpp:1184] Sending 1 offers to framework 201203291014-0-0012
I0329 10:25:14.679366  6088 master.cpp:679] Received reply for offer 201203291014-0-661
I0329 10:25:14.679451  6088 master.cpp:1403] Filtered slave 201203291014-0-2 for framework 201203291014-0-0012 for 1 seconds
I0329 10:25:15.679558  6088 master.cpp:1184] Sending 1 offers to framework 201203291014-0-0013
I0329 10:25:15.681099  6088 master.cpp:679] Received reply for offer 201203291014-0-662
I0329 10:25:15.681351  6088 master.cpp:1403] Filtered slave 201203291014-0-2 for framework 201203291014-0-0013 for 1 seconds
I0329 10:25:16.681319  6088 master.cpp:1184] Sending 1 offers to framework 201203291014-0-0012
I0329 10:25:16.682816  6088 master.cpp:679] Received reply for offer 201203291014-0-663
I0329 10:25:16.682955  6088 master.cpp:1403] Filtered slave 201203291014-0-2 for framework 201203291014-0-0012 for 1 seconds
I0329 10:25:17.683045  6088 master.cpp:1184] Sending 1 offers to framework 201203291014-0-0013
I0329 10:25:17.684669  6088 master.cpp:679] Received reply for offer 201203291014-0-664
I0329 10:25:17.684813  6088 master.cpp:1403] Filtered slave 201203291014-0-2 for framework 201203291014-0-0013 for 1 seconds
I0329 10:25:18.684882  6088 master.cpp:1184] Sending 1 offers to framework 201203291014-0-0012
I0329 10:25:18.686374  6088 master.cpp:679] Received reply for offer 201203291014-0-665
I0329 10:25:18.686512  6088 master.cpp:1403] Filtered slave 201203291014-0-2 for framework 201203291014-0-0012 for 1 seconds
I0329 10:25:19.686593  6088 master.cpp:1184] Sending 1 offers to framework 201203291014-0-0013
I0329 10:25:19.688204  6088 master.cpp:679] Received reply for offer 201203291014-0-666
I0329 10:25:19.688320  6088 master.cpp:1403] Filtered slave 201203291014-0-2 for framework 201203291014-0-0013 for 1 seconds
I0329 10:25:20.688415  6088 master.cpp:1184] Sending 1 offers to framework 201203291014-0-0012
I0329 10:25:20.690109  6088 master.cpp:679] Received reply for offer 201203291014-0-667
I0329 10:25:20.690248  6088 master.cpp:1403] Filtered slave 201203291014-0-2 for framework 201203291014-0-0012 for 1 seconds
I0329 10:25:21.690316  6088 master.cpp:1184] Sending 1 offers to framework 201203291014-0-0013
I0329 10:25:21.691990  6088 master.cpp:679] Received reply for offer 201203291014-0-668
I0329 10:25:21.692167  6088 master.cpp:1403] Filtered slave 201203291014-0-2 for framework 201203291014-0-0013 for 1 seconds
I0329 10:25:22.692332  6088 master.cpp:1184] Sending 1 offers to framework 201203291014-0-0012
I0329 10:25:22.694080  6088 master.cpp:679] Received reply for offer 201203291014-0-669
I0329 10:25:22.694222  6088 master.cpp:1403] Filtered slave 201203291014-0-2 for framework 201203291014-0-0012 for 1 seconds
I0329 10:25:23.694339  6088 master.cpp:1184] Sending 1 offers to framework 201203291014-0-0013
I0329 10:25:23.696094  6088 master.cpp:679] Received reply for offer 201203291014-0-670
I0329 10:25:23.696238  6088 master.cpp:1403] Filtered slave 201203291014-0-2 for framework 201203291014-0-0013 for 1 seconds
I0329 10:25:24.696352  6088 master.cpp:1184] Sending 1 offers to framework 201203291014-0-0012
I0329 10:25:24.698153  6088 master.cpp:679] Received reply for offer 201203291014-0-671
I0329 10:25:24.698240  6088 master.cpp:1403] Filtered slave 201203291014-0-2 for framework 201203291014-0-0012 for 1 seconds
I0329 10:25:25.697947  6088 master.cpp:1184] Sending 1 offers to framework 201203291014-0-0013
I0329 10:25:25.699708  6088 master.cpp:679] Received reply for offer 201203291014-0-672
I0329 10:25:25.699852  6088 master.cpp:1403] Filtered slave 201203291014-0-2 for framework 201203291014-0-0013 for 1 seconds
I0329 10:25:26.699991  6088 master.cpp:1184] Sending 1 offers to framework 201203291014-0-0012
I0329 10:25:26.701767  6088 master.cpp:679] Received reply for offer 201203291014-0-673
I0329 10:25:26.701908  6088 master.cpp:1403] Filtered slave 201203291014-0-2 for framework 201203291014-0-0012 for 1 seconds
I0329 10:25:27.701984  6088 master.cpp:1184] Sending 1 offers to framework 201203291014-0-0013
I0329 10:25:27.703778  6088 master.cpp:679] Received reply for offer 201203291014-0-674
I0329 10:25:27.703922  6088 master.cpp:1403] Filtered slave 201203291014-0-2 for framework 201203291014-0-0013 for 1 seconds
I0329 10:25:28.704052  6088 master.cpp:1184] Sending 1 offers to framework 201203291014-0-0012
I0329 10:25:28.705781  6088 master.cpp:679] Received reply for offer 201203291014-0-675
I0329 10:25:28.705924  6088 master.cpp:1403] Filtered slave 201203291014-0-2 for framework 201203291014-0-0012 for 1 seconds
I0329 10:25:29.706068  6088 master.cpp:1184] Sending 1 offers to framework 201203291014-0-0013
I0329 10:25:29.707875  6088 master.cpp:679] Received reply for offer 201203291014-0-676
I0329 10:25:29.707964  6088 master.cpp:1403] Filtered slave 201203291014-0-2 for framework 201203291014-0-0013 for 1 seconds
I0329 10:25:30.708153  6088 master.cpp:1184] Sending 1 offers to framework 201203291014-0-0012
I0329 10:25:30.709904  6088 master.cpp:679] Received reply for offer 201203291014-0-677
I0329 10:25:30.710047  6088 master.cpp:1403] Filtered slave 201203291014-0-2 for framework 201203291014-0-0012 for 1 seconds
I0329 10:25:31.710258  6088 master.cpp:1184] Sending 1 offers to framework 201203291014-0-0013
I0329 10:25:31.711808  6088 master.cpp:679] Received reply for offer 201203291014-0-678
I0329 10:25:31.711948  6088 master.cpp:1403] Filtered slave 201203291014-0-2 for framework 201203291014-0-0013 for 1 seconds
I0329 10:25:32.711992  6088 master.cpp:1184] Sending 1 offers to framework 201203291014-0-0012
I0329 10:25:32.713584  6088 master.cpp:679] Received reply for offer 201203291014-0-679
I0329 10:25:32.713778  6088 master.cpp:1403] Filtered slave 201203291014-0-2 for framework 201203291014-0-0012 for 1 seconds
I0329 10:25:33.713768  6088 master.cpp:1184] Sending 1 offers to framework 201203291014-0-0013
I0329 10:25:33.715297  6088 master.cpp:679] Received reply for offer 201203291014-0-680
I0329 10:25:33.715437  6088 master.cpp:1403] Filtered slave 201203291014-0-2 for framework 201203291014-0-0013 for 1 seconds
I0329 10:25:34.715512  6088 master.cpp:1184] Sending 1 offers to framework 201203291014-0-0012
I0329 10:25:34.717161  6088 master.cpp:679] Received reply for offer 201203291014-0-681
I0329 10:25:34.717244  6088 master.cpp:1403] Filtered slave 201203291014-0-2 for framework 201203291014-0-0012 for 1 seconds
I0329 10:25:35.717356  6088 master.cpp:1184] Sending 1 offers to framework 201203291014-0-0013
I0329 10:25:35.718983  6088 master.cpp:679] Received reply for offer 201203291014-0-682
I0329 10:25:35.719130  6088 master.cpp:1403] Filtered slave 201203291014-0-2 for framework 201203291014-0-0013 for 1 seconds
I0329 10:25:36.719192  6088 master.cpp:1184] Sending 1 offers to framework 201203291014-0-0012
I0329 10:25:36.720727  6088 master.cpp:679] Received reply for offer 201203291014-0-683
I0329 10:25:36.720867  6088 master.cpp:1403] Filtered slave 201203291014-0-2 for framework 201203291014-0-0012 for 1 seconds
I0329 10:25:37.720942  6088 master.cpp:1184] Sending 1 offers to framework 201203291014-0-0013
I0329 10:25:37.722489  6088 master.cpp:679] Received reply for offer 201203291014-0-684
I0329 10:25:37.722630  6088 master.cpp:1403] Filtered slave 201203291014-0-2 for framework 201203291014-0-0013 for 1 seconds
I0329 10:25:38.722658  6088 master.cpp:1184] Sending 1 offers to framework 201203291014-0-0012
I0329 10:25:38.724305  6088 master.cpp:679] Received reply for offer 201203291014-0-685
I0329 10:25:38.724444  6088 master.cpp:1403] Filtered slave 201203291014-0-2 for framework 201203291014-0-0012 for 1 seconds
I0329 10:25:39.627444  6088 master.cpp:1118] Framework 201203291014-0-0012 disconnected
I0329 10:25:39.627673  6088 master.cpp:1118] Framework 201203291014-0-0013 disconnected
I0329 10:48:47.870471  6088 master.cpp:492] Registering framework 201203291014-0-0014 at 3@192.168.1.64:45372
I0329 10:48:47.870818  6088 simple_allocator.cpp:48] Added framework 201203291014-0-0014
I0329 10:48:47.870997  6088 master.cpp:1184] Sending 1 offers to framework 201203291014-0-0014
I0329 10:48:47.871290  6088 master.cpp:492] Registering framework 201203291014-0-0015 at 2@192.168.1.64:45372
I0329 10:48:47.871436  6088 simple_allocator.cpp:48] Added framework 201203291014-0-0015
I0329 10:48:47.887347  6088 master.cpp:679] Received reply for offer 201203291014-0-686
I0329 10:48:47.887526  6088 master.cpp:1403] Filtered slave 201203291014-0-2 for framework 201203291014-0-0014 for 1 seconds
I0329 10:48:48.270975  6088 master.cpp:718] Reviving offers for framework 201203291014-0-0014
I0329 10:48:48.271126  6088 simple_allocator.cpp:145] Filters removed for framework 201203291014-0-0014
I0329 10:48:48.271448  6088 master.cpp:1184] Sending 1 offers to framework 201203291014-0-0015
I0329 10:48:48.272989  6088 master.cpp:679] Received reply for offer 201203291014-0-687
I0329 10:48:48.273226  6088 master.cpp:1403] Filtered slave 201203291014-0-2 for framework 201203291014-0-0015 for 1 seconds
I0329 10:49:03.687758  6088 master.cpp:1143] Slave 201203291014-0-2 disconnected
I0329 10:49:03.694152  6088 simple_allocator.cpp:83] Removed slave 201203291014-0-2
I0329 10:49:05.289335  6088 master.cpp:814] Attempting to register slave 201203291014-0-3 at slave@192.168.1.66:38817
I0329 10:49:05.289718  6088 master.cpp:1057] Master now considering a slave at ubuntu.gateway.2wire.net:38817 as active
I0329 10:49:05.289918  6088 master.cpp:1588] Adding slave 201203291014-0-3 at ubuntu.gateway.2wire.net with cpus=8; mem=8192
I0329 10:49:05.290293  6088 simple_allocator.cpp:71] Added slave 201203291014-0-3 with cpus=8; mem=8192
I0329 10:49:05.290489  6088 master.cpp:1184] Sending 1 offers to framework 201203291014-0-0014
I0329 10:49:05.373680  6088 master.cpp:679] Received reply for offer 201203291014-0-688
I0329 10:49:05.373915  6088 master.cpp:1453] Launching task 0 on slave 201203291014-0-3
I0329 10:49:05.374263  6088 master.cpp:1453] Launching task 1 on slave 201203291014-0-3
I0329 10:49:05.374518  6088 master.cpp:1453] Launching task 2 on slave 201203291014-0-3
I0329 10:49:05.374711  6088 master.cpp:1453] Launching task 3 on slave 201203291014-0-3
I0329 10:49:05.374973  6088 master.cpp:1453] Launching task 4 on slave 201203291014-0-3
I0329 10:49:05.375219  6088 master.cpp:1453] Launching task 5 on slave 201203291014-0-3
I0329 10:49:05.375437  6088 master.cpp:1453] Launching task 6 on slave 201203291014-0-3
I0329 10:49:05.375641  6088 master.cpp:1453] Launching task 7 on slave 201203291014-0-3
I0329 10:49:06.255592  6088 master.cpp:902] Status update from slave@192.168.1.66:38817: task 2 of framework 201203291014-0-0014 is now in state TASK_RUNNING
I0329 10:49:06.258254  6088 master.cpp:902] Status update from slave@192.168.1.66:38817: task 5 of framework 201203291014-0-0014 is now in state TASK_RUNNING
I0329 10:49:06.261070  6088 master.cpp:902] Status update from slave@192.168.1.66:38817: task 3 of framework 201203291014-0-0014 is now in state TASK_RUNNING
I0329 10:49:06.263006  6088 master.cpp:902] Status update from slave@192.168.1.66:38817: task 1 of framework 201203291014-0-0014 is now in state TASK_RUNNING
I0329 10:49:06.264895  6088 master.cpp:902] Status update from slave@192.168.1.66:38817: task 0 of framework 201203291014-0-0014 is now in state TASK_RUNNING
I0329 10:49:06.266026  6088 master.cpp:902] Status update from slave@192.168.1.66:38817: task 4 of framework 201203291014-0-0014 is now in state TASK_RUNNING
I0329 10:49:06.295841  6088 master.cpp:902] Status update from slave@192.168.1.66:38817: task 6 of framework 201203291014-0-0014 is now in state TASK_RUNNING
I0329 10:49:06.296411  6088 master.cpp:902] Status update from slave@192.168.1.66:38817: task 7 of framework 201203291014-0-0014 is now in state TASK_RUNNING
I0329 10:49:09.786021  6088 master.cpp:814] Attempting to register slave 201203291014-0-4 at slave@192.168.1.64:40765
I0329 10:49:09.786370  6088 master.cpp:1057] Master now considering a slave at azad.gateway.2wire.net:40765 as active
I0329 10:49:09.786502  6088 master.cpp:1588] Adding slave 201203291014-0-4 at azad.gateway.2wire.net with cpus=8; mem=16384
I0329 10:49:09.786943  6088 simple_allocator.cpp:71] Added slave 201203291014-0-4 with cpus=8; mem=16384
I0329 10:49:09.787209  6088 master.cpp:1184] Sending 1 offers to framework 201203291014-0-0015
I0329 10:49:09.788946  6088 master.cpp:679] Received reply for offer 201203291014-0-689
I0329 10:49:09.789110  6088 master.cpp:1403] Filtered slave 201203291014-0-4 for framework 201203291014-0-0015 for 1 seconds
I0329 10:49:10.415788  6088 master.cpp:1184] Sending 1 offers to framework 201203291014-0-0014
I0329 10:49:10.460218  6088 master.cpp:679] Received reply for offer 201203291014-0-690
I0329 10:49:10.460418  6088 master.cpp:1453] Launching task 8 on slave 201203291014-0-4
I0329 10:49:10.460708  6088 master.cpp:1453] Launching task 9 on slave 201203291014-0-4
I0329 10:49:10.461012  6088 master.cpp:1453] Launching task 10 on slave 201203291014-0-4
I0329 10:49:10.461233  6088 master.cpp:1453] Launching task 11 on slave 201203291014-0-4
I0329 10:49:10.461477  6088 master.cpp:1453] Launching task 12 on slave 201203291014-0-4
I0329 10:49:10.461691  6088 master.cpp:1453] Launching task 13 on slave 201203291014-0-4
I0329 10:49:10.461905  6088 master.cpp:1453] Launching task 14 on slave 201203291014-0-4
I0329 10:49:10.462177  6088 master.cpp:1453] Launching task 15 on slave 201203291014-0-4
I0329 10:49:11.399324  6088 master.cpp:902] Status update from slave@192.168.1.64:40765: task 11 of framework 201203291014-0-0014 is now in state TASK_RUNNING
I0329 10:49:11.402045  6088 master.cpp:902] Status update from slave@192.168.1.64:40765: task 13 of framework 201203291014-0-0014 is now in state TASK_RUNNING
I0329 10:49:11.404687  6088 master.cpp:902] Status update from slave@192.168.1.64:40765: task 15 of framework 201203291014-0-0014 is now in state TASK_RUNNING
I0329 10:49:11.407068  6088 master.cpp:902] Status update from slave@192.168.1.64:40765: task 10 of framework 201203291014-0-0014 is now in state TASK_RUNNING
I0329 10:49:11.409836  6088 master.cpp:902] Status update from slave@192.168.1.64:40765: task 9 of framework 201203291014-0-0014 is now in state TASK_RUNNING
I0329 10:49:11.411757  6088 master.cpp:902] Status update from slave@192.168.1.64:40765: task 14 of framework 201203291014-0-0014 is now in state TASK_RUNNING
I0329 10:49:11.427794  6088 master.cpp:902] Status update from slave@192.168.1.64:40765: task 12 of framework 201203291014-0-0014 is now in state TASK_RUNNING
I0329 10:49:11.427938  6088 master.cpp:902] Status update from slave@192.168.1.64:40765: task 8 of framework 201203291014-0-0014 is now in state TASK_RUNNING
I0329 10:49:20.084492  6088 master.cpp:902] Status update from slave@192.168.1.66:38817: task 0 of framework 201203291014-0-0014 is now in state TASK_FINISHED
I0329 10:49:20.136087  6088 master.cpp:1184] Sending 1 offers to framework 201203291014-0-0015
I0329 10:49:20.360780  6088 master.cpp:679] Received reply for offer 201203291014-0-691
I0329 10:49:20.360985  6088 master.cpp:1403] Filtered slave 201203291014-0-3 for framework 201203291014-0-0015 for 1 seconds
I0329 10:49:20.371948  6088 master.cpp:902] Status update from slave@192.168.1.66:38817: task 3 of framework 201203291014-0-0014 is now in state TASK_FINISHED
I0329 10:49:20.404830  6088 master.cpp:1184] Sending 1 offers to framework 201203291014-0-0014
I0329 10:49:20.589813  6088 master.cpp:679] Received reply for offer 201203291014-0-692
I0329 10:49:20.590055  6088 master.cpp:1453] Launching task 16 on slave 201203291014-0-3
I0329 10:49:20.591833  6088 master.cpp:1453] Launching task 17 on slave 201203291014-0-3
I0329 10:49:20.669134  6088 master.cpp:902] Status update from slave@192.168.1.66:38817: task 7 of framework 201203291014-0-0014 is now in state TASK_FINISHED
I0329 10:49:20.711272  6088 master.cpp:1184] Sending 1 offers to framework 201203291014-0-0014
I0329 10:49:20.816154  6088 master.cpp:679] Received reply for offer 201203291014-0-693
I0329 10:49:20.816592  6088 master.cpp:1453] Launching task 18 on slave 201203291014-0-3
I0329 10:49:20.962431  6088 master.cpp:902] Status update from slave@192.168.1.66:38817: task 5 of framework 201203291014-0-0014 is now in state TASK_FINISHED
I0329 10:49:20.990022  6088 master.cpp:1184] Sending 1 offers to framework 201203291014-0-0014
I0329 10:49:21.081722  6088 master.cpp:679] Received reply for offer 201203291014-0-694
I0329 10:49:21.082135  6088 master.cpp:1453] Launching task 19 on slave 201203291014-0-3
I0329 10:49:21.258008  6088 master.cpp:902] Status update from slave@192.168.1.66:38817: task 2 of framework 201203291014-0-0014 is now in state TASK_FINISHED
I0329 10:49:21.297035  6088 master.cpp:1184] Sending 1 offers to framework 201203291014-0-0014
I0329 10:49:21.514816  6088 master.cpp:679] Received reply for offer 201203291014-0-695
I0329 10:49:21.515269  6088 master.cpp:1453] Launching task 20 on slave 201203291014-0-3
I0329 10:49:21.553848  6088 master.cpp:902] Status update from slave@192.168.1.66:38817: task 1 of framework 201203291014-0-0014 is now in state TASK_FINISHED
I0329 10:49:21.592084  6088 master.cpp:1184] Sending 1 offers to framework 201203291014-0-0015
I0329 10:49:21.663926  6088 master.cpp:679] Received reply for offer 201203291014-0-696
I0329 10:49:21.664260  6088 master.cpp:1403] Filtered slave 201203291014-0-3 for framework 201203291014-0-0015 for 1 seconds
I0329 10:49:21.848319  6088 master.cpp:902] Status update from slave@192.168.1.66:38817: task 4 of framework 201203291014-0-0014 is now in state TASK_FINISHED
I0329 10:49:21.879374  6088 master.cpp:1184] Sending 1 offers to framework 201203291014-0-0014
I0329 10:49:21.974570  6088 master.cpp:679] Received reply for offer 201203291014-0-697
I0329 10:49:21.974938  6088 master.cpp:1453] Launching task 21 on slave 201203291014-0-3
I0329 10:49:21.975296  6088 master.cpp:1453] Launching task 22 on slave 201203291014-0-3
I0329 10:49:22.147145  6088 master.cpp:902] Status update from slave@192.168.1.66:38817: task 6 of framework 201203291014-0-0014 is now in state TASK_FINISHED
I0329 10:49:22.181366  6088 master.cpp:1184] Sending 1 offers to framework 201203291014-0-0014
I0329 10:49:22.183923  6088 master.cpp:902] Status update from slave@192.168.1.66:38817: task 16 of framework 201203291014-0-0014 is now in state TASK_RUNNING
I0329 10:49:22.184322  6088 master.cpp:902] Status update from slave@192.168.1.66:38817: task 17 of framework 201203291014-0-0014 is now in state TASK_RUNNING
I0329 10:49:22.184545  6088 master.cpp:902] Status update from slave@192.168.1.66:38817: task 18 of framework 201203291014-0-0014 is now in state TASK_RUNNING
I0329 10:49:22.184746  6088 master.cpp:902] Status update from slave@192.168.1.66:38817: task 19 of framework 201203291014-0-0014 is now in state TASK_RUNNING
I0329 10:49:22.184957  6088 master.cpp:902] Status update from slave@192.168.1.66:38817: task 20 of framework 201203291014-0-0014 is now in state TASK_RUNNING
I0329 10:49:22.185184  6088 master.cpp:902] Status update from slave@192.168.1.66:38817: task 21 of framework 201203291014-0-0014 is now in state TASK_RUNNING
I0329 10:49:22.185526  6088 master.cpp:902] Status update from slave@192.168.1.66:38817: task 22 of framework 201203291014-0-0014 is now in state TASK_RUNNING
I0329 10:49:22.317667  6088 master.cpp:679] Received reply for offer 201203291014-0-698
I0329 10:49:22.317857  6088 master.cpp:1453] Launching task 23 on slave 201203291014-0-3
I0329 10:49:22.331460  6088 master.cpp:902] Status update from slave@192.168.1.66:38817: task 23 of framework 201203291014-0-0014 is now in state TASK_RUNNING
I0329 10:49:24.564590  6088 master.cpp:902] Status update from slave@192.168.1.64:40765: task 9 of framework 201203291014-0-0014 is now in state TASK_FINISHED
I0329 10:49:24.589737  6088 master.cpp:1184] Sending 1 offers to framework 201203291014-0-0015
I0329 10:49:24.597671  6088 master.cpp:902] Status update from slave@192.168.1.64:40765: task 11 of framework 201203291014-0-0014 is now in state TASK_FINISHED
I0329 10:49:24.666337  6088 master.cpp:902] Status update from slave@192.168.1.64:40765: task 8 of framework 201203291014-0-0014 is now in state TASK_FINISHED
I0329 10:49:24.692965  6088 master.cpp:679] Received reply for offer 201203291014-0-699
I0329 10:49:24.693256  6088 master.cpp:1403] Filtered slave 201203291014-0-4 for framework 201203291014-0-0015 for 1 seconds
I0329 10:49:24.730548  6088 master.cpp:902] Status update from slave@192.168.1.64:40765: task 15 of framework 201203291014-0-0014 is now in state TASK_FINISHED
I0329 10:49:24.750105  6088 master.cpp:1184] Sending 1 offers to framework 201203291014-0-0014
I0329 10:49:24.859506  6088 master.cpp:902] Status update from slave@192.168.1.64:40765: task 14 of framework 201203291014-0-0014 is now in state TASK_FINISHED
I0329 10:49:24.876029  6088 master.cpp:679] Received reply for offer 201203291014-0-700
I0329 10:49:24.876324  6088 master.cpp:1453] Launching task 24 on slave 201203291014-0-4
I0329 10:49:24.876942  6088 master.cpp:1453] Launching task 25 on slave 201203291014-0-4
I0329 10:49:24.877375  6088 master.cpp:1453] Launching task 26 on slave 201203291014-0-4
I0329 10:49:24.878005  6088 master.cpp:1453] Launching task 27 on slave 201203291014-0-4
I0329 10:49:24.894506  6088 master.cpp:902] Status update from slave@192.168.1.64:40765: task 12 of framework 201203291014-0-0014 is now in state TASK_FINISHED
I0329 10:49:24.912703  6088 master.cpp:1184] Sending 1 offers to framework 201203291014-0-0014
I0329 10:49:24.916231  6088 master.cpp:902] Status update from slave@192.168.1.64:40765: task 10 of framework 201203291014-0-0014 is now in state TASK_FINISHED
I0329 10:49:24.931567  6088 master.cpp:902] Status update from slave@192.168.1.64:40765: task 24 of framework 201203291014-0-0014 is now in state TASK_RUNNING
I0329 10:49:24.931975  6088 master.cpp:902] Status update from slave@192.168.1.64:40765: task 25 of framework 201203291014-0-0014 is now in state TASK_RUNNING
I0329 10:49:24.932147  6088 master.cpp:902] Status update from slave@192.168.1.64:40765: task 27 of framework 201203291014-0-0014 is now in state TASK_RUNNING
I0329 10:49:24.932446  6088 master.cpp:902] Status update from slave@192.168.1.64:40765: task 26 of framework 201203291014-0-0014 is now in state TASK_RUNNING
I0329 10:49:24.981699  6088 master.cpp:902] Status update from slave@192.168.1.64:40765: task 13 of framework 201203291014-0-0014 is now in state TASK_FINISHED
I0329 10:49:25.034976  6088 master.cpp:679] Received reply for offer 201203291014-0-701
I0329 10:49:25.035223  6088 master.cpp:1453] Launching task 28 on slave 201203291014-0-4
I0329 10:49:25.035470  6088 master.cpp:1453] Launching task 29 on slave 201203291014-0-4
I0329 10:49:25.042851  6088 master.cpp:902] Status update from slave@192.168.1.64:40765: task 28 of framework 201203291014-0-0014 is now in state TASK_RUNNING
I0329 10:49:25.047041  6088 master.cpp:902] Status update from slave@192.168.1.64:40765: task 29 of framework 201203291014-0-0014 is now in state TASK_RUNNING
I0329 10:49:26.447486  6088 master.cpp:1184] Sending 1 offers to framework 201203291014-0-0015
I0329 10:49:26.449570  6088 master.cpp:679] Received reply for offer 201203291014-0-702
I0329 10:49:26.449741  6088 master.cpp:1403] Filtered slave 201203291014-0-4 for framework 201203291014-0-0015 for 1 seconds
I0329 10:49:27.449844  6088 master.cpp:1184] Sending 1 offers to framework 201203291014-0-0014
I0329 10:49:27.462209  6088 master.cpp:679] Received reply for offer 201203291014-0-703
I0329 10:49:27.462416  6088 master.cpp:1453] Launching task 30 on slave 201203291014-0-4
I0329 10:49:27.462695  6088 master.cpp:1453] Launching task 31 on slave 201203291014-0-4
I0329 10:49:27.476424  6088 master.cpp:902] Status update from slave@192.168.1.64:40765: task 30 of framework 201203291014-0-0014 is now in state TASK_RUNNING
I0329 10:49:27.477545  6088 master.cpp:902] Status update from slave@192.168.1.64:40765: task 31 of framework 201203291014-0-0014 is now in state TASK_RUNNING
I0329 10:49:34.147764  6088 master.cpp:902] Status update from slave@192.168.1.66:38817: task 20 of framework 201203291014-0-0014 is now in state TASK_FINISHED
I0329 10:49:34.187227  6088 master.cpp:1184] Sending 1 offers to framework 201203291014-0-0015
I0329 10:49:34.283609  6088 master.cpp:679] Received reply for offer 201203291014-0-704
I0329 10:49:34.283851  6088 master.cpp:1403] Filtered slave 201203291014-0-3 for framework 201203291014-0-0015 for 1 seconds
I0329 10:49:34.645320  6088 master.cpp:902] Status update from slave@192.168.1.66:38817: task 21 of framework 201203291014-0-0014 is now in state TASK_FINISHED
I0329 10:49:34.665370  6088 master.cpp:1184] Sending 1 offers to framework 201203291014-0-0014
I0329 10:49:34.779567  6088 master.cpp:679] Received reply for offer 201203291014-0-705
I0329 10:49:34.780354  6088 master.cpp:1453] Launching task 32 on slave 201203291014-0-3
I0329 10:49:34.782491  6088 master.cpp:1453] Launching task 33 on slave 201203291014-0-3
I0329 10:49:34.936285  6088 master.cpp:902] Status update from slave@192.168.1.66:38817: task 16 of framework 201203291014-0-0014 is now in state TASK_FINISHED
I0329 10:49:34.966259  6088 master.cpp:1184] Sending 1 offers to framework 201203291014-0-0014
I0329 10:49:35.066484  6088 master.cpp:679] Received reply for offer 201203291014-0-706
I0329 10:49:35.067106  6088 master.cpp:1453] Launching task 34 on slave 201203291014-0-3
I0329 10:49:35.243301  6088 master.cpp:902] Status update from slave@192.168.1.66:38817: task 19 of framework 201203291014-0-0014 is now in state TASK_FINISHED
I0329 10:49:35.291251  6088 master.cpp:1184] Sending 1 offers to framework 201203291014-0-0014
I0329 10:49:35.371556  6088 master.cpp:679] Received reply for offer 201203291014-0-707
I0329 10:49:35.371723  6088 master.cpp:1453] Launching task 35 on slave 201203291014-0-3
I0329 10:49:35.531831  6088 master.cpp:902] Status update from slave@192.168.1.64:40765: task 27 of framework 201203291014-0-0014 is now in state TASK_FINISHED
I0329 10:49:35.556668  6088 master.cpp:1184] Sending 1 offers to framework 201203291014-0-0015
I0329 10:49:35.559779  6088 master.cpp:902] Status update from slave@192.168.1.66:38817: task 23 of framework 201203291014-0-0014 is now in state TASK_FINISHED
I0329 10:49:35.591264  6088 master.cpp:1184] Sending 1 offers to framework 201203291014-0-0015
I0329 10:49:35.626220  6088 master.cpp:679] Received reply for offer 201203291014-0-708
I0329 10:49:35.626561  6088 master.cpp:1403] Filtered slave 201203291014-0-4 for framework 201203291014-0-0015 for 1 seconds
I0329 10:49:35.677171  6088 master.cpp:679] Received reply for offer 201203291014-0-709
I0329 10:49:35.678381  6088 master.cpp:1184] Sending 1 offers to framework 201203291014-0-0014
I0329 10:49:35.681427  6088 master.cpp:1403] Filtered slave 201203291014-0-3 for framework 201203291014-0-0015 for 1 seconds
I0329 10:49:35.686384  6088 master.cpp:679] Received reply for offer 201203291014-0-710
I0329 10:49:35.686585  6088 master.cpp:1453] Launching task 36 on slave 201203291014-0-4
I0329 10:49:35.699321  6088 master.cpp:902] Status update from slave@192.168.1.64:40765: task 36 of framework 201203291014-0-0014 is now in state TASK_RUNNING
I0329 10:49:35.828846  6088 master.cpp:902] Status update from slave@192.168.1.66:38817: task 22 of framework 201203291014-0-0014 is now in state TASK_FINISHED
I0329 10:49:35.861723  6088 master.cpp:1184] Sending 1 offers to framework 201203291014-0-0014
I0329 10:49:35.952644  6088 master.cpp:679] Received reply for offer 201203291014-0-711
I0329 10:49:35.953160  6088 master.cpp:1403] Filtered slave 201203291014-0-3 for framework 201203291014-0-0014 for 1 seconds
I0329 10:49:36.099814  6088 master.cpp:902] Status update from slave@192.168.1.64:40765: task 24 of framework 201203291014-0-0014 is now in state TASK_FINISHED
I0329 10:49:36.132455  6088 master.cpp:1184] Sending 1 offers to framework 201203291014-0-0014
I0329 10:49:36.140030  6088 master.cpp:902] Status update from slave@192.168.1.66:38817: task 17 of framework 201203291014-0-0014 is now in state TASK_FINISHED
I0329 10:49:36.171700  6088 master.cpp:902] Status update from slave@192.168.1.64:40765: task 26 of framework 201203291014-0-0014 is now in state TASK_FINISHED
I0329 10:49:36.254343  6088 master.cpp:902] Status update from slave@192.168.1.64:40765: task 28 of framework 201203291014-0-0014 is now in state TASK_FINISHED
I0329 10:49:36.302373  6088 master.cpp:679] Received reply for offer 201203291014-0-712
I0329 10:49:36.302556  6088 master.cpp:1453] Launching task 37 on slave 201203291014-0-4
I0329 10:49:36.320508  6088 master.cpp:902] Status update from slave@192.168.1.64:40765: task 37 of framework 201203291014-0-0014 is now in state TASK_RUNNING
I0329 10:49:36.411855  6088 master.cpp:902] Status update from slave@192.168.1.66:38817: task 18 of framework 201203291014-0-0014 is now in state TASK_FINISHED
I0329 10:49:36.436543  6088 master.cpp:902] Status update from slave@192.168.1.66:38817: task 32 of framework 201203291014-0-0014 is now in state TASK_RUNNING
I0329 10:49:36.436858  6088 master.cpp:902] Status update from slave@192.168.1.66:38817: task 33 of framework 201203291014-0-0014 is now in state TASK_RUNNING
I0329 10:49:36.437103  6088 master.cpp:902] Status update from slave@192.168.1.66:38817: task 34 of framework 201203291014-0-0014 is now in state TASK_RUNNING
I0329 10:49:36.437405  6088 master.cpp:902] Status update from slave@192.168.1.66:38817: task 35 of framework 201203291014-0-0014 is now in state TASK_RUNNING
I0329 10:49:36.712025  6088 master.cpp:902] Status update from slave@192.168.1.64:40765: task 29 of framework 201203291014-0-0014 is now in state TASK_FINISHED
I0329 10:49:36.738862  6088 master.cpp:1184] Sending 1 offers to framework 201203291014-0-0014
I0329 10:49:36.745744  6088 master.cpp:902] Status update from slave@192.168.1.64:40765: task 25 of framework 201203291014-0-0014 is now in state TASK_FINISHED
I0329 10:49:36.861678  6088 master.cpp:679] Received reply for offer 201203291014-0-713
I0329 10:49:36.862138  6088 master.cpp:1453] Launching task 38 on slave 201203291014-0-4
I0329 10:49:36.862640  6088 master.cpp:1453] Launching task 39 on slave 201203291014-0-4
I0329 10:49:36.870810  6088 master.cpp:902] Status update from slave@192.168.1.64:40765: task 38 of framework 201203291014-0-0014 is now in state TASK_RUNNING
I0329 10:49:36.874490  6088 master.cpp:902] Status update from slave@192.168.1.64:40765: task 39 of framework 201203291014-0-0014 is now in state TASK_RUNNING
I0329 10:49:37.462684  6088 master.cpp:1184] Sending 2 offers to framework 201203291014-0-0015
I0329 10:49:37.464449  6088 master.cpp:679] Received reply for offer 201203291014-0-714
I0329 10:49:37.464608  6088 master.cpp:1403] Filtered slave 201203291014-0-3 for framework 201203291014-0-0015 for 1 seconds
I0329 10:49:37.464874  6088 master.cpp:679] Received reply for offer 201203291014-0-715
I0329 10:49:37.465040  6088 master.cpp:1403] Filtered slave 201203291014-0-4 for framework 201203291014-0-0015 for 1 seconds
I0329 10:49:38.465065  6088 master.cpp:1184] Sending 2 offers to framework 201203291014-0-0014
I0329 10:49:38.467639  6088 master.cpp:679] Received reply for offer 201203291014-0-716
I0329 10:49:38.468309  6088 master.cpp:1403] Filtered slave 201203291014-0-3 for framework 201203291014-0-0014 for 1 seconds
I0329 10:49:38.469069  6088 master.cpp:679] Received reply for offer 201203291014-0-717
I0329 10:49:38.469465  6088 master.cpp:1403] Filtered slave 201203291014-0-4 for framework 201203291014-0-0014 for 1 seconds
I0329 10:49:38.917388  6088 master.cpp:902] Status update from slave@192.168.1.64:40765: task 31 of framework 201203291014-0-0014 is now in state TASK_FINISHED
I0329 10:49:39.125283  6088 master.cpp:902] Status update from slave@192.168.1.64:40765: task 30 of framework 201203291014-0-0014 is now in state TASK_FINISHED
I0329 10:49:39.467058  6088 master.cpp:1184] Sending 2 offers to framework 201203291014-0-0015
I0329 10:49:39.470792  6088 master.cpp:679] Received reply for offer 201203291014-0-718
I0329 10:49:39.471030  6088 master.cpp:1403] Filtered slave 201203291014-0-3 for framework 201203291014-0-0015 for 1 seconds
I0329 10:49:39.471274  6088 master.cpp:679] Received reply for offer 201203291014-0-719
I0329 10:49:39.471505  6088 master.cpp:1403] Filtered slave 201203291014-0-4 for framework 201203291014-0-0015 for 1 seconds
I0329 10:49:40.468749  6088 master.cpp:1184] Sending 2 offers to framework 201203291014-0-0014
I0329 10:49:40.470602  6088 master.cpp:679] Received reply for offer 201203291014-0-720
I0329 10:49:40.470816  6088 master.cpp:1403] Filtered slave 201203291014-0-3 for framework 201203291014-0-0014 for 1 seconds
I0329 10:49:40.471130  6088 master.cpp:679] Received reply for offer 201203291014-0-721
I0329 10:49:40.471259  6088 master.cpp:1403] Filtered slave 201203291014-0-4 for framework 201203291014-0-0014 for 1 seconds
I0329 10:49:41.471276  6088 master.cpp:1184] Sending 2 offers to framework 201203291014-0-0015
I0329 10:49:41.475749  6088 master.cpp:679] Received reply for offer 201203291014-0-722
I0329 10:49:41.476217  6088 master.cpp:1403] Filtered slave 201203291014-0-3 for framework 201203291014-0-0015 for 1 seconds
I0329 10:49:41.476523  6088 master.cpp:679] Received reply for offer 201203291014-0-723
I0329 10:49:41.476861  6088 master.cpp:1403] Filtered slave 201203291014-0-4 for framework 201203291014-0-0015 for 1 seconds
I0329 10:49:42.438523  6088 master.cpp:902] Status update from slave@192.168.1.66:38817: task 34 of framework 201203291014-0-0014 is now in state TASK_FINISHED
I0329 10:49:42.473323  6088 master.cpp:1184] Sending 2 offers to framework 201203291014-0-0014
I0329 10:49:42.569190  6088 master.cpp:679] Received reply for offer 201203291014-0-724
I0329 10:49:42.570003  6088 master.cpp:1403] Filtered slave 201203291014-0-3 for framework 201203291014-0-0014 for 1 seconds
I0329 10:49:42.570799  6088 master.cpp:679] Received reply for offer 201203291014-0-725
I0329 10:49:42.571216  6088 master.cpp:1403] Filtered slave 201203291014-0-4 for framework 201203291014-0-0014 for 1 seconds
I0329 10:49:42.729809  6088 master.cpp:902] Status update from slave@192.168.1.66:38817: task 35 of framework 201203291014-0-0014 is now in state TASK_FINISHED
I0329 10:49:42.908731  6088 master.cpp:902] Status update from slave@192.168.1.64:40765: task 36 of framework 201203291014-0-0014 is now in state TASK_FINISHED
I0329 10:49:43.021978  6088 master.cpp:902] Status update from slave@192.168.1.66:38817: task 32 of framework 201203291014-0-0014 is now in state TASK_FINISHED
I0329 10:49:43.150656  6088 master.cpp:902] Status update from slave@192.168.1.64:40765: task 38 of framework 201203291014-0-0014 is now in state TASK_FINISHED
I0329 10:49:43.173140  6088 master.cpp:902] Status update from slave@192.168.1.64:40765: task 37 of framework 201203291014-0-0014 is now in state TASK_FINISHED
I0329 10:49:43.288385  6088 master.cpp:902] Status update from slave@192.168.1.64:40765: task 39 of framework 201203291014-0-0014 is now in state TASK_FINISHED
I0329 10:49:43.311995  6088 master.cpp:902] Status update from slave@192.168.1.66:38817: task 33 of framework 201203291014-0-0014 is now in state TASK_FINISHED
I0329 10:49:43.475029  6088 master.cpp:1184] Sending 2 offers to framework 201203291014-0-0015
I0329 10:49:43.476703  6088 master.cpp:679] Received reply for offer 201203291014-0-726
I0329 10:49:43.476866  6088 master.cpp:1403] Filtered slave 201203291014-0-3 for framework 201203291014-0-0015 for 1 seconds
I0329 10:49:43.477085  6088 master.cpp:679] Received reply for offer 201203291014-0-727
I0329 10:49:43.477417  6088 master.cpp:1403] Filtered slave 201203291014-0-4 for framework 201203291014-0-0015 for 1 seconds
I0329 10:49:44.477038  6088 master.cpp:1184] Sending 2 offers to framework 201203291014-0-0014
I0329 10:49:44.478842  6088 master.cpp:679] Received reply for offer 201203291014-0-728
I0329 10:49:44.483623  6088 master.cpp:1403] Filtered slave 201203291014-0-3 for framework 201203291014-0-0014 for 1 seconds
I0329 10:49:44.530019  6088 master.cpp:679] Received reply for offer 201203291014-0-729
I0329 10:49:44.567653  6088 master.cpp:1403] Filtered slave 201203291014-0-4 for framework 201203291014-0-0014 for 1 seconds
I0329 10:49:45.479212  6088 master.cpp:1184] Sending 2 offers to framework 201203291014-0-0015
I0329 10:49:45.480989  6088 master.cpp:679] Received reply for offer 201203291014-0-730
I0329 10:49:45.481139  6088 master.cpp:1403] Filtered slave 201203291014-0-3 for framework 201203291014-0-0015 for 1 seconds
I0329 10:49:45.481415  6088 master.cpp:679] Received reply for offer 201203291014-0-731
I0329 10:49:45.481601  6088 master.cpp:1403] Filtered slave 201203291014-0-4 for framework 201203291014-0-0015 for 1 seconds
I0329 10:49:46.481153  6088 master.cpp:1184] Sending 2 offers to framework 201203291014-0-0014
I0329 10:49:46.482954  6088 master.cpp:679] Received reply for offer 201203291014-0-732
I0329 10:49:46.483217  6088 master.cpp:1403] Filtered slave 201203291014-0-3 for framework 201203291014-0-0014 for 1 seconds
I0329 10:49:46.483458  6088 master.cpp:679] Received reply for offer 201203291014-0-733
I0329 10:49:46.483643  6088 master.cpp:1403] Filtered slave 201203291014-0-4 for framework 201203291014-0-0014 for 1 seconds
I0329 10:49:47.483327  6088 master.cpp:1184] Sending 2 offers to framework 201203291014-0-0015
I0329 10:49:47.485142  6088 master.cpp:679] Received reply for offer 201203291014-0-734
I0329 10:49:47.485296  6088 master.cpp:1403] Filtered slave 201203291014-0-3 for framework 201203291014-0-0015 for 1 seconds
I0329 10:49:47.485563  6088 master.cpp:679] Received reply for offer 201203291014-0-735
I0329 10:49:47.485736  6088 master.cpp:1403] Filtered slave 201203291014-0-4 for framework 201203291014-0-0015 for 1 seconds
I0329 10:49:48.485512  6088 master.cpp:1184] Sending 2 offers to framework 201203291014-0-0014
I0329 10:49:48.487278  6088 master.cpp:679] Received reply for offer 201203291014-0-736
I0329 10:49:48.487432  6088 master.cpp:1403] Filtered slave 201203291014-0-3 for framework 201203291014-0-0014 for 1 seconds
I0329 10:49:48.487726  6088 master.cpp:679] Received reply for offer 201203291014-0-737
I0329 10:49:48.487934  6088 master.cpp:1403] Filtered slave 201203291014-0-4 for framework 201203291014-0-0014 for 1 seconds
I0329 10:49:49.487591  6088 master.cpp:1184] Sending 2 offers to framework 201203291014-0-0015
I0329 10:49:49.489202  6088 master.cpp:679] Received reply for offer 201203291014-0-738
I0329 10:49:49.489297  6088 master.cpp:1403] Filtered slave 201203291014-0-3 for framework 201203291014-0-0015 for 1 seconds
I0329 10:49:49.512908  6088 master.cpp:679] Received reply for offer 201203291014-0-739
I0329 10:49:49.540761  6088 master.cpp:1403] Filtered slave 201203291014-0-4 for framework 201203291014-0-0015 for 1 seconds
I0329 10:49:50.489562  6088 master.cpp:1184] Sending 2 offers to framework 201203291014-0-0014
I0329 10:49:50.491328  6088 master.cpp:679] Received reply for offer 201203291014-0-740
I0329 10:49:50.491518  6088 master.cpp:1403] Filtered slave 201203291014-0-3 for framework 201203291014-0-0014 for 1 seconds
I0329 10:49:50.491799  6088 master.cpp:679] Received reply for offer 201203291014-0-741
I0329 10:49:50.492035  6088 master.cpp:1403] Filtered slave 201203291014-0-4 for framework 201203291014-0-0014 for 1 seconds
I0329 10:49:51.491719  6088 master.cpp:1184] Sending 2 offers to framework 201203291014-0-0015
I0329 10:49:51.493474  6088 master.cpp:679] Received reply for offer 201203291014-0-742
I0329 10:49:51.493773  6088 master.cpp:1403] Filtered slave 201203291014-0-3 for framework 201203291014-0-0015 for 1 seconds
I0329 10:49:51.494076  6088 master.cpp:679] Received reply for offer 201203291014-0-743
I0329 10:49:51.494268  6088 master.cpp:1403] Filtered slave 201203291014-0-4 for framework 201203291014-0-0015 for 1 seconds
I0329 10:49:52.492862  6088 master.cpp:1184] Sending 2 offers to framework 201203291014-0-0014
I0329 10:49:52.494334  6088 master.cpp:679] Received reply for offer 201203291014-0-744
I0329 10:49:52.494458  6088 master.cpp:1403] Filtered slave 201203291014-0-3 for framework 201203291014-0-0014 for 1 seconds
I0329 10:49:52.494721  6088 master.cpp:679] Received reply for offer 201203291014-0-745
I0329 10:49:52.494848  6088 master.cpp:1403] Filtered slave 201203291014-0-4 for framework 201203291014-0-0014 for 1 seconds
I0329 10:49:53.494608  6088 master.cpp:1184] Sending 2 offers to framework 201203291014-0-0015
I0329 10:49:53.496387  6088 master.cpp:679] Received reply for offer 201203291014-0-746
I0329 10:49:53.496546  6088 master.cpp:1403] Filtered slave 201203291014-0-3 for framework 201203291014-0-0015 for 1 seconds
I0329 10:49:53.496837  6088 master.cpp:679] Received reply for offer 201203291014-0-747
I0329 10:49:53.497025  6088 master.cpp:1403] Filtered slave 201203291014-0-4 for framework 201203291014-0-0015 for 1 seconds
I0329 10:49:54.496670  6088 master.cpp:1184] Sending 2 offers to framework 201203291014-0-0014
I0329 10:49:54.499191  6088 master.cpp:679] Received reply for offer 201203291014-0-748
I0329 10:49:54.499337  6088 master.cpp:1403] Filtered slave 201203291014-0-3 for framework 201203291014-0-0014 for 1 seconds
I0329 10:49:54.524729  6088 master.cpp:679] Received reply for offer 201203291014-0-749
I0329 10:49:54.552587  6088 master.cpp:1403] Filtered slave 201203291014-0-4 for framework 201203291014-0-0014 for 1 seconds
I0329 10:49:55.498116  6088 master.cpp:1184] Sending 2 offers to framework 201203291014-0-0015
I0329 10:49:55.499996  6088 master.cpp:679] Received reply for offer 201203291014-0-750
I0329 10:49:55.500262  6088 master.cpp:1403] Filtered slave 201203291014-0-3 for framework 201203291014-0-0015 for 1 seconds
I0329 10:49:55.500567  6088 master.cpp:679] Received reply for offer 201203291014-0-751
I0329 10:49:55.500730  6088 master.cpp:1403] Filtered slave 201203291014-0-4 for framework 201203291014-0-0015 for 1 seconds
I0329 10:49:56.500411  6088 master.cpp:1184] Sending 2 offers to framework 201203291014-0-0014
I0329 10:49:56.502187  6088 master.cpp:679] Received reply for offer 201203291014-0-752
I0329 10:49:56.502349  6088 master.cpp:1403] Filtered slave 201203291014-0-3 for framework 201203291014-0-0014 for 1 seconds
I0329 10:49:56.502624  6088 master.cpp:679] Received reply for offer 201203291014-0-753
I0329 10:49:56.502790  6088 master.cpp:1403] Filtered slave 201203291014-0-4 for framework 201203291014-0-0014 for 1 seconds
I0329 10:49:57.502655  6088 master.cpp:1184] Sending 2 offers to framework 201203291014-0-0015
I0329 10:49:57.504462  6088 master.cpp:679] Received reply for offer 201203291014-0-754
I0329 10:49:57.504559  6088 master.cpp:1403] Filtered slave 201203291014-0-3 for framework 201203291014-0-0015 for 1 seconds
I0329 10:49:57.505678  6088 master.cpp:679] Received reply for offer 201203291014-0-755
I0329 10:49:57.505949  6088 master.cpp:1403] Filtered slave 201203291014-0-4 for framework 201203291014-0-0015 for 1 seconds
I0329 10:49:58.504650  6088 master.cpp:1184] Sending 2 offers to framework 201203291014-0-0014
I0329 10:49:58.506367  6088 master.cpp:679] Received reply for offer 201203291014-0-756
I0329 10:49:58.506525  6088 master.cpp:1403] Filtered slave 201203291014-0-3 for framework 201203291014-0-0014 for 1 seconds
I0329 10:49:58.506798  6088 master.cpp:679] Received reply for offer 201203291014-0-757
I0329 10:49:58.506965  6088 master.cpp:1403] Filtered slave 201203291014-0-4 for framework 201203291014-0-0014 for 1 seconds
I0329 10:49:59.506603  6088 master.cpp:1184] Sending 2 offers to framework 201203291014-0-0015
I0329 10:49:59.508466  6088 master.cpp:679] Received reply for offer 201203291014-0-758
I0329 10:49:59.508632  6088 master.cpp:1403] Filtered slave 201203291014-0-3 for framework 201203291014-0-0015 for 1 seconds
I0329 10:49:59.536563  6088 master.cpp:679] Received reply for offer 201203291014-0-759
I0329 10:49:59.564162  6088 master.cpp:1403] Filtered slave 201203291014-0-4 for framework 201203291014-0-0015 for 1 seconds
I0329 10:50:00.508991  6088 master.cpp:1184] Sending 2 offers to framework 201203291014-0-0014
I0329 10:50:00.510694  6088 master.cpp:679] Received reply for offer 201203291014-0-760
I0329 10:50:00.510859  6088 master.cpp:1403] Filtered slave 201203291014-0-3 for framework 201203291014-0-0014 for 1 seconds
I0329 10:50:00.511144  6088 master.cpp:679] Received reply for offer 201203291014-0-761
I0329 10:50:00.511312  6088 master.cpp:1403] Filtered slave 201203291014-0-4 for framework 201203291014-0-0014 for 1 seconds
I0329 10:50:01.511205  6088 master.cpp:1184] Sending 2 offers to framework 201203291014-0-0015
I0329 10:50:01.512891  6088 master.cpp:679] Received reply for offer 201203291014-0-762
I0329 10:50:01.513047  6088 master.cpp:1403] Filtered slave 201203291014-0-3 for framework 201203291014-0-0015 for 1 seconds
I0329 10:50:01.513330  6088 master.cpp:679] Received reply for offer 201203291014-0-763
I0329 10:50:01.513514  6088 master.cpp:1403] Filtered slave 201203291014-0-4 for framework 201203291014-0-0015 for 1 seconds
I0329 10:50:02.513126  6088 master.cpp:1184] Sending 2 offers to framework 201203291014-0-0014
I0329 10:50:02.515009  6088 master.cpp:679] Received reply for offer 201203291014-0-764
I0329 10:50:02.515307  6088 master.cpp:1403] Filtered slave 201203291014-0-3 for framework 201203291014-0-0014 for 1 seconds
I0329 10:50:02.515480  6088 master.cpp:679] Received reply for offer 201203291014-0-765
I0329 10:50:02.515638  6088 master.cpp:1403] Filtered slave 201203291014-0-4 for framework 201203291014-0-0014 for 1 seconds
I0329 10:50:03.515403  6088 master.cpp:1184] Sending 2 offers to framework 201203291014-0-0015
I0329 10:50:03.517212  6088 master.cpp:679] Received reply for offer 201203291014-0-766
I0329 10:50:03.517395  6088 master.cpp:1403] Filtered slave 201203291014-0-3 for framework 201203291014-0-0015 for 1 seconds
I0329 10:50:03.517678  6088 master.cpp:679] Received reply for offer 201203291014-0-767
I0329 10:50:03.517843  6088 master.cpp:1403] Filtered slave 201203291014-0-4 for framework 201203291014-0-0015 for 1 seconds
I0329 10:50:04.517484  6088 master.cpp:1184] Sending 2 offers to framework 201203291014-0-0014
I0329 10:50:04.519928  6088 master.cpp:679] Received reply for offer 201203291014-0-768
I0329 10:50:04.520108  6088 master.cpp:1403] Filtered slave 201203291014-0-3 for framework 201203291014-0-0014 for 1 seconds
I0329 10:50:04.548279  6088 master.cpp:679] Received reply for offer 201203291014-0-769
I0329 10:50:04.575762  6088 master.cpp:1403] Filtered slave 201203291014-0-4 for framework 201203291014-0-0014 for 1 seconds
I0329 10:50:05.519269  6088 master.cpp:1184] Sending 2 offers to framework 201203291014-0-0015
I0329 10:50:05.521039  6088 master.cpp:679] Received reply for offer 201203291014-0-770
I0329 10:50:05.521196  6088 master.cpp:1403] Filtered slave 201203291014-0-3 for framework 201203291014-0-0015 for 1 seconds
I0329 10:50:05.521476  6088 master.cpp:679] Received reply for offer 201203291014-0-771
I0329 10:50:05.521642  6088 master.cpp:1403] Filtered slave 201203291014-0-4 for framework 201203291014-0-0015 for 1 seconds
I0329 10:50:06.521307  6088 master.cpp:1184] Sending 2 offers to framework 201203291014-0-0014
I0329 10:50:06.523247  6088 master.cpp:679] Received reply for offer 201203291014-0-772
I0329 10:50:06.523407  6088 master.cpp:1403] Filtered slave 201203291014-0-3 for framework 201203291014-0-0014 for 1 seconds
I0329 10:50:06.523679  6088 master.cpp:679] Received reply for offer 201203291014-0-773
I0329 10:50:06.523921  6088 master.cpp:1403] Filtered slave 201203291014-0-4 for framework 201203291014-0-0014 for 1 seconds
I0329 10:50:07.522459  6088 master.cpp:1184] Sending 2 offers to framework 201203291014-0-0015
I0329 10:50:07.524135  6088 master.cpp:679] Received reply for offer 201203291014-0-774
I0329 10:50:07.524296  6088 master.cpp:1403] Filtered slave 201203291014-0-3 for framework 201203291014-0-0015 for 1 seconds
I0329 10:50:07.524520  6088 master.cpp:679] Received reply for offer 201203291014-0-775
I0329 10:50:07.524658  6088 master.cpp:1403] Filtered slave 201203291014-0-4 for framework 201203291014-0-0015 for 1 seconds
I0329 10:50:08.523464  6088 master.cpp:1184] Sending 2 offers to framework 201203291014-0-0014
I0329 10:50:08.525120  6088 master.cpp:679] Received reply for offer 201203291014-0-776
I0329 10:50:08.525246  6088 master.cpp:1403] Filtered slave 201203291014-0-3 for framework 201203291014-0-0014 for 1 seconds
I0329 10:50:08.525506  6088 master.cpp:679] Received reply for offer 201203291014-0-777
I0329 10:50:08.525640  6088 master.cpp:1403] Filtered slave 201203291014-0-4 for framework 201203291014-0-0014 for 1 seconds
I0329 10:50:09.525480  6088 master.cpp:1184] Sending 2 offers to framework 201203291014-0-0015
I0329 10:50:09.527366  6088 master.cpp:679] Received reply for offer 201203291014-0-778
I0329 10:50:09.527463  6088 master.cpp:1403] Filtered slave 201203291014-0-3 for framework 201203291014-0-0015 for 1 seconds
I0329 10:50:09.551611  6088 master.cpp:679] Received reply for offer 201203291014-0-779
I0329 10:50:09.579049  6088 master.cpp:1403] Filtered slave 201203291014-0-4 for framework 201203291014-0-0015 for 1 seconds
I0329 10:50:10.527470  6088 master.cpp:1184] Sending 2 offers to framework 201203291014-0-0014
I0329 10:50:10.529330  6088 master.cpp:679] Received reply for offer 201203291014-0-780
I0329 10:50:10.529482  6088 master.cpp:1403] Filtered slave 201203291014-0-3 for framework 201203291014-0-0014 for 1 seconds
I0329 10:50:10.529748  6088 master.cpp:679] Received reply for offer 201203291014-0-781
I0329 10:50:10.529908  6088 master.cpp:1403] Filtered slave 201203291014-0-4 for framework 201203291014-0-0014 for 1 seconds
I0329 10:50:11.529636  6088 master.cpp:1184] Sending 2 offers to framework 201203291014-0-0015
I0329 10:50:11.531415  6088 master.cpp:679] Received reply for offer 201203291014-0-782
I0329 10:50:11.531565  6088 master.cpp:1403] Filtered slave 201203291014-0-3 for framework 201203291014-0-0015 for 1 seconds
I0329 10:50:11.531826  6088 master.cpp:679] Received reply for offer 201203291014-0-783
I0329 10:50:11.531991  6088 master.cpp:1403] Filtered slave 201203291014-0-4 for framework 201203291014-0-0015 for 1 seconds
I0329 10:50:12.531929  6088 master.cpp:1184] Sending 2 offers to framework 201203291014-0-0014
I0329 10:50:12.534137  6088 master.cpp:679] Received reply for offer 201203291014-0-784
I0329 10:50:12.534308  6088 master.cpp:1403] Filtered slave 201203291014-0-3 for framework 201203291014-0-0014 for 1 seconds
I0329 10:50:12.534559  6088 master.cpp:679] Received reply for offer 201203291014-0-785
I0329 10:50:12.534744  6088 master.cpp:1184] Sending 1 offers to framework 201203291014-0-0015
I0329 10:50:12.534883  6088 master.cpp:1403] Filtered slave 201203291014-0-4 for framework 201203291014-0-0014 for 1 seconds
I0329 10:50:12.536208  6088 master.cpp:679] Received reply for offer 201203291014-0-786
I0329 10:50:12.536386  6088 master.cpp:1403] Filtered slave 201203291014-0-3 for framework 201203291014-0-0015 for 1 seconds
I0329 10:50:13.534347  6088 master.cpp:1184] Sending 1 offers to framework 201203291014-0-0015
I0329 10:50:13.535804  6088 master.cpp:679] Received reply for offer 201203291014-0-787
I0329 10:50:13.535966  6088 master.cpp:1403] Filtered slave 201203291014-0-4 for framework 201203291014-0-0015 for 1 seconds
I0329 10:50:14.536154  6088 master.cpp:1184] Sending 2 offers to framework 201203291014-0-0014
I0329 10:50:14.537979  6088 master.cpp:679] Received reply for offer 201203291014-0-788
I0329 10:50:14.538106  6088 master.cpp:1403] Filtered slave 201203291014-0-3 for framework 201203291014-0-0014 for 1 seconds
I0329 10:50:14.563519  6088 master.cpp:679] Received reply for offer 201203291014-0-789
I0329 10:50:14.590833  6088 master.cpp:1184] Sending 1 offers to framework 201203291014-0-0015
I0329 10:50:14.591153  6088 master.cpp:1403] Filtered slave 201203291014-0-4 for framework 201203291014-0-0014 for 1 seconds
I0329 10:50:14.591996  6088 master.cpp:679] Received reply for offer 201203291014-0-790
I0329 10:50:14.592165  6088 master.cpp:1403] Filtered slave 201203291014-0-3 for framework 201203291014-0-0015 for 1 seconds
I0329 10:50:15.538336  6088 master.cpp:1184] Sending 1 offers to framework 201203291014-0-0015
I0329 10:50:15.539856  6088 master.cpp:679] Received reply for offer 201203291014-0-791
I0329 10:50:15.540019  6088 master.cpp:1403] Filtered slave 201203291014-0-4 for framework 201203291014-0-0015 for 1 seconds
I0329 10:50:16.540134  6088 master.cpp:1184] Sending 2 offers to framework 201203291014-0-0014
I0329 10:50:16.541909  6088 master.cpp:679] Received reply for offer 201203291014-0-792
I0329 10:50:16.542060  6088 master.cpp:1403] Filtered slave 201203291014-0-3 for framework 201203291014-0-0014 for 1 seconds
I0329 10:50:16.542333  6088 master.cpp:679] Received reply for offer 201203291014-0-793
I0329 10:50:16.542549  6088 master.cpp:1184] Sending 1 offers to framework 201203291014-0-0015
I0329 10:50:16.542700  6088 master.cpp:1403] Filtered slave 201203291014-0-4 for framework 201203291014-0-0014 for 1 seconds
I0329 10:50:16.543759  6088 master.cpp:679] Received reply for offer 201203291014-0-794
I0329 10:50:16.543938  6088 master.cpp:1403] Filtered slave 201203291014-0-3 for framework 201203291014-0-0015 for 1 seconds
I0329 10:50:17.542078  6088 master.cpp:1184] Sending 1 offers to framework 201203291014-0-0015
I0329 10:50:17.543550  6088 master.cpp:679] Received reply for offer 201203291014-0-795
I0329 10:50:17.543710  6088 master.cpp:1403] Filtered slave 201203291014-0-4 for framework 201203291014-0-0015 for 1 seconds
I0329 10:50:18.542788  6088 master.cpp:1184] Sending 2 offers to framework 201203291014-0-0014
I0329 10:50:18.544529  6088 master.cpp:679] Received reply for offer 201203291014-0-796
I0329 10:50:18.544682  6088 master.cpp:1403] Filtered slave 201203291014-0-3 for framework 201203291014-0-0014 for 1 seconds
I0329 10:50:18.544950  6088 master.cpp:679] Received reply for offer 201203291014-0-797
I0329 10:50:18.545168  6088 master.cpp:1184] Sending 1 offers to framework 201203291014-0-0015
I0329 10:50:18.545325  6088 master.cpp:1403] Filtered slave 201203291014-0-4 for framework 201203291014-0-0014 for 1 seconds
I0329 10:50:18.546390  6088 master.cpp:679] Received reply for offer 201203291014-0-798
I0329 10:50:18.546567  6088 master.cpp:1403] Filtered slave 201203291014-0-3 for framework 201203291014-0-0015 for 1 seconds
I0329 10:50:19.544711  6088 master.cpp:1184] Sending 1 offers to framework 201203291014-0-0015
I0329 10:50:19.546125  6088 master.cpp:679] Received reply for offer 201203291014-0-799
I0329 10:50:19.546232  6088 master.cpp:1403] Filtered slave 201203291014-0-4 for framework 201203291014-0-0015 for 1 seconds
I0329 10:50:20.546466  6088 master.cpp:1184] Sending 2 offers to framework 201203291014-0-0014
I0329 10:50:20.548229  6088 master.cpp:679] Received reply for offer 201203291014-0-800
I0329 10:50:20.548382  6088 master.cpp:1403] Filtered slave 201203291014-0-3 for framework 201203291014-0-0014 for 1 seconds
I0329 10:50:20.548646  6088 master.cpp:679] Received reply for offer 201203291014-0-801
I0329 10:50:20.548866  6088 master.cpp:1184] Sending 1 offers to framework 201203291014-0-0015
I0329 10:50:20.549042  6088 master.cpp:1403] Filtered slave 201203291014-0-4 for framework 201203291014-0-0014 for 1 seconds
I0329 10:50:20.549995  6088 master.cpp:679] Received reply for offer 201203291014-0-802
I0329 10:50:20.550174  6088 master.cpp:1403] Filtered slave 201203291014-0-3 for framework 201203291014-0-0015 for 1 seconds
I0329 10:50:21.547327  6088 master.cpp:1184] Sending 1 offers to framework 201203291014-0-0015
I0329 10:50:21.548794  6088 master.cpp:679] Received reply for offer 201203291014-0-803
I0329 10:50:21.548995  6088 master.cpp:1403] Filtered slave 201203291014-0-4 for framework 201203291014-0-0015 for 1 seconds
I0329 10:50:22.548272  6088 master.cpp:1184] Sending 2 offers to framework 201203291014-0-0014
I0329 10:50:22.549989  6088 master.cpp:679] Received reply for offer 201203291014-0-804
I0329 10:50:22.550140  6088 master.cpp:1403] Filtered slave 201203291014-0-3 for framework 201203291014-0-0014 for 1 seconds
I0329 10:50:22.550434  6088 master.cpp:679] Received reply for offer 201203291014-0-805
I0329 10:50:22.550650  6088 master.cpp:1184] Sending 1 offers to framework 201203291014-0-0015
I0329 10:50:22.550799  6088 master.cpp:1403] Filtered slave 201203291014-0-4 for framework 201203291014-0-0014 for 1 seconds
I0329 10:50:22.551985  6088 master.cpp:679] Received reply for offer 201203291014-0-806
I0329 10:50:22.552157  6088 master.cpp:1403] Filtered slave 201203291014-0-3 for framework 201203291014-0-0015 for 1 seconds
I0329 10:50:23.550194  6088 master.cpp:1184] Sending 1 offers to framework 201203291014-0-0015
I0329 10:50:23.551686  6088 master.cpp:679] Received reply for offer 201203291014-0-807
I0329 10:50:23.551846  6088 master.cpp:1403] Filtered slave 201203291014-0-4 for framework 201203291014-0-0015 for 1 seconds
I0329 10:50:24.551914  6088 master.cpp:1184] Sending 2 offers to framework 201203291014-0-0014
I0329 10:50:24.553625  6088 master.cpp:679] Received reply for offer 201203291014-0-808
I0329 10:50:24.553726  6088 master.cpp:1403] Filtered slave 201203291014-0-3 for framework 201203291014-0-0014 for 1 seconds
I0329 10:50:24.578785  6088 master.cpp:679] Received reply for offer 201203291014-0-809
I0329 10:50:24.605803  6088 master.cpp:1184] Sending 1 offers to framework 201203291014-0-0015
I0329 10:50:24.606048  6088 master.cpp:1403] Filtered slave 201203291014-0-4 for framework 201203291014-0-0014 for 1 seconds
I0329 10:50:24.607137  6088 master.cpp:679] Received reply for offer 201203291014-0-810
I0329 10:50:24.607303  6088 master.cpp:1403] Filtered slave 201203291014-0-3 for framework 201203291014-0-0015 for 1 seconds
I0329 10:50:25.553978  6088 master.cpp:1184] Sending 1 offers to framework 201203291014-0-0015
I0329 10:50:25.555459  6088 master.cpp:679] Received reply for offer 201203291014-0-811
I0329 10:50:25.555619  6088 master.cpp:1403] Filtered slave 201203291014-0-4 for framework 201203291014-0-0015 for 1 seconds
I0329 10:50:26.555719  6088 master.cpp:1184] Sending 2 offers to framework 201203291014-0-0014
I0329 10:50:26.557503  6088 master.cpp:679] Received reply for offer 201203291014-0-812
I0329 10:50:26.557657  6088 master.cpp:1403] Filtered slave 201203291014-0-3 for framework 201203291014-0-0014 for 1 seconds
I0329 10:50:26.557926  6088 master.cpp:679] Received reply for offer 201203291014-0-813
I0329 10:50:26.558125  6088 master.cpp:1184] Sending 1 offers to framework 201203291014-0-0015
I0329 10:50:26.558276  6088 master.cpp:1403] Filtered slave 201203291014-0-4 for framework 201203291014-0-0014 for 1 seconds
I0329 10:50:26.559517  6088 master.cpp:679] Received reply for offer 201203291014-0-814
I0329 10:50:26.559694  6088 master.cpp:1403] Filtered slave 201203291014-0-3 for framework 201203291014-0-0015 for 1 seconds
I0329 10:50:27.557732  6088 master.cpp:1184] Sending 1 offers to framework 201203291014-0-0015
I0329 10:50:27.559190  6088 master.cpp:679] Received reply for offer 201203291014-0-815
I0329 10:50:27.559350  6088 master.cpp:1403] Filtered slave 201203291014-0-4 for framework 201203291014-0-0015 for 1 seconds
I0329 10:50:28.559448  6088 master.cpp:1184] Sending 2 offers to framework 201203291014-0-0014
I0329 10:50:28.561210  6088 master.cpp:679] Received reply for offer 201203291014-0-816
I0329 10:50:28.561363  6088 master.cpp:1403] Filtered slave 201203291014-0-3 for framework 201203291014-0-0014 for 1 seconds
I0329 10:50:28.561676  6088 master.cpp:679] Received reply for offer 201203291014-0-817
I0329 10:50:28.561893  6088 master.cpp:1184] Sending 1 offers to framework 201203291014-0-0015
I0329 10:50:28.562072  6088 master.cpp:1403] Filtered slave 201203291014-0-4 for framework 201203291014-0-0014 for 1 seconds
I0329 10:50:28.563105  6088 master.cpp:679] Received reply for offer 201203291014-0-818
I0329 10:50:28.563261  6088 master.cpp:1403] Filtered slave 201203291014-0-3 for framework 201203291014-0-0015 for 1 seconds
I0329 10:50:29.561347  6088 master.cpp:1184] Sending 1 offers to framework 201203291014-0-0015
I0329 10:50:29.562808  6088 master.cpp:679] Received reply for offer 201203291014-0-819
I0329 10:50:29.562911  6088 master.cpp:1403] Filtered slave 201203291014-0-4 for framework 201203291014-0-0015 for 1 seconds
I0329 10:50:30.563115  6088 master.cpp:1184] Sending 2 offers to framework 201203291014-0-0014
I0329 10:50:30.564899  6088 master.cpp:679] Received reply for offer 201203291014-0-820
I0329 10:50:30.565052  6088 master.cpp:1403] Filtered slave 201203291014-0-3 for framework 201203291014-0-0014 for 1 seconds
I0329 10:50:30.565351  6088 master.cpp:679] Received reply for offer 201203291014-0-821
I0329 10:50:30.565567  6088 master.cpp:1184] Sending 1 offers to framework 201203291014-0-0015
I0329 10:50:30.565717  6088 master.cpp:1403] Filtered slave 201203291014-0-4 for framework 201203291014-0-0014 for 1 seconds
I0329 10:50:30.566752  6088 master.cpp:679] Received reply for offer 201203291014-0-822
I0329 10:50:30.566927  6088 master.cpp:1403] Filtered slave 201203291014-0-3 for framework 201203291014-0-0015 for 1 seconds
I0329 10:50:31.564966  6088 master.cpp:1184] Sending 1 offers to framework 201203291014-0-0015
I0329 10:50:31.566479  6088 master.cpp:679] Received reply for offer 201203291014-0-823
I0329 10:50:31.566637  6088 master.cpp:1403] Filtered slave 201203291014-0-4 for framework 201203291014-0-0015 for 1 seconds
I0329 10:50:32.566735  6088 master.cpp:1184] Sending 2 offers to framework 201203291014-0-0014
I0329 10:50:32.568516  6088 master.cpp:679] Received reply for offer 201203291014-0-824
I0329 10:50:32.568670  6088 master.cpp:1403] Filtered slave 201203291014-0-3 for framework 201203291014-0-0014 for 1 seconds
I0329 10:50:32.569314  6088 master.cpp:679] Received reply for offer 201203291014-0-825
I0329 10:50:32.569504  6088 master.cpp:1184] Sending 1 offers to framework 201203291014-0-0015
I0329 10:50:32.569721  6088 master.cpp:1403] Filtered slave 201203291014-0-4 for framework 201203291014-0-0014 for 1 seconds
I0329 10:50:32.570776  6088 master.cpp:679] Received reply for offer 201203291014-0-826
I0329 10:50:32.570938  6088 master.cpp:1403] Filtered slave 201203291014-0-3 for framework 201203291014-0-0015 for 1 seconds
I0329 10:50:33.568974  6088 master.cpp:1184] Sending 1 offers to framework 201203291014-0-0015
I0329 10:50:33.570444  6088 master.cpp:679] Received reply for offer 201203291014-0-827
I0329 10:50:33.570605  6088 master.cpp:1403] Filtered slave 201203291014-0-4 for framework 201203291014-0-0015 for 1 seconds
I0329 10:50:34.570687  6088 master.cpp:1184] Sending 2 offers to framework 201203291014-0-0014
I0329 10:50:34.572589  6088 master.cpp:679] Received reply for offer 201203291014-0-828
I0329 10:50:34.572692  6088 master.cpp:1403] Filtered slave 201203291014-0-3 for framework 201203291014-0-0014 for 1 seconds
I0329 10:50:34.602221  6088 master.cpp:679] Received reply for offer 201203291014-0-829
I0329 10:50:34.629190  6088 master.cpp:1184] Sending 1 offers to framework 201203291014-0-0015
I0329 10:50:34.629444  6088 master.cpp:1403] Filtered slave 201203291014-0-4 for framework 201203291014-0-0014 for 1 seconds
I0329 10:50:34.630447  6088 master.cpp:679] Received reply for offer 201203291014-0-830
I0329 10:50:34.630625  6088 master.cpp:1403] Filtered slave 201203291014-0-3 for framework 201203291014-0-0015 for 1 seconds
I0329 10:50:35.042218  6088 master.cpp:1118] Framework 201203291014-0-0015 disconnected
I0329 10:50:35.042408  6088 master.cpp:1118] Framework 201203291014-0-0014 disconnected
I0329 11:25:14.131924  6088 master.cpp:492] Registering framework 201203291014-0-0016 at 2@192.168.1.64:38347
I0329 11:25:14.132212  6088 simple_allocator.cpp:48] Added framework 201203291014-0-0016
I0329 11:25:14.132462  6088 master.cpp:1184] Sending 2 offers to framework 201203291014-0-0016
I0329 11:25:14.132653  6088 master.cpp:492] Registering framework 201203291014-0-0017 at 4@192.168.1.64:38347
I0329 11:25:14.132833  6088 simple_allocator.cpp:48] Added framework 201203291014-0-0017
I0329 11:25:14.153836  6088 master.cpp:679] Received reply for offer 201203291014-0-831
I0329 11:25:14.154027  6088 master.cpp:1403] Filtered slave 201203291014-0-3 for framework 201203291014-0-0016 for 1 seconds
I0329 11:25:14.154283  6088 master.cpp:679] Received reply for offer 201203291014-0-832
I0329 11:25:14.154584  6088 master.cpp:1184] Sending 1 offers to framework 201203291014-0-0017
I0329 11:25:14.154872  6088 master.cpp:1403] Filtered slave 201203291014-0-4 for framework 201203291014-0-0016 for 1 seconds
I0329 11:25:14.155611  6088 master.cpp:679] Received reply for offer 201203291014-0-833
I0329 11:25:14.155740  6088 master.cpp:1184] Sending 1 offers to framework 201203291014-0-0017
I0329 11:25:14.156033  6088 master.cpp:1403] Filtered slave 201203291014-0-3 for framework 201203291014-0-0017 for 1 seconds
I0329 11:25:14.156795  6088 master.cpp:679] Received reply for offer 201203291014-0-834
I0329 11:25:14.156959  6088 master.cpp:1403] Filtered slave 201203291014-0-4 for framework 201203291014-0-0017 for 1 seconds
I0329 11:25:14.510606  6088 master.cpp:718] Reviving offers for framework 201203291014-0-0017
I0329 11:25:14.510758  6088 simple_allocator.cpp:145] Filters removed for framework 201203291014-0-0017
I0329 11:25:14.511260  6088 master.cpp:1184] Sending 2 offers to framework 201203291014-0-0017
I0329 11:25:14.621805  6088 master.cpp:679] Received reply for offer 201203291014-0-835
I0329 11:25:14.621989  6088 master.cpp:1403] Filtered slave 201203291014-0-3 for framework 201203291014-0-0017 for 1 seconds
I0329 11:25:14.623672  6088 master.cpp:679] Received reply for offer 201203291014-0-836
I0329 11:25:14.623800  6088 master.cpp:1453] Launching task 0 on slave 201203291014-0-4
I0329 11:25:14.623931  6088 master.cpp:1453] Launching task 1 on slave 201203291014-0-4
I0329 11:25:14.624246  6088 master.cpp:1453] Launching task 2 on slave 201203291014-0-4
I0329 11:25:14.624419  6088 master.cpp:1453] Launching task 3 on slave 201203291014-0-4
I0329 11:25:14.624515  6088 master.cpp:1453] Launching task 4 on slave 201203291014-0-4
I0329 11:25:14.625108  6088 master.cpp:1453] Launching task 5 on slave 201203291014-0-4
I0329 11:25:14.625507  6088 master.cpp:1453] Launching task 6 on slave 201203291014-0-4
I0329 11:25:14.626021  6088 master.cpp:1453] Launching task 7 on slave 201203291014-0-4
I0329 11:25:15.597245  6088 master.cpp:902] Status update from slave@192.168.1.64:40765: task 0 of framework 201203291014-0-0017 is now in state TASK_RUNNING
I0329 11:25:15.600811  6088 master.cpp:902] Status update from slave@192.168.1.64:40765: task 1 of framework 201203291014-0-0017 is now in state TASK_RUNNING
I0329 11:25:15.603318  6088 master.cpp:902] Status update from slave@192.168.1.64:40765: task 7 of framework 201203291014-0-0017 is now in state TASK_RUNNING
I0329 11:25:15.605455  6088 master.cpp:902] Status update from slave@192.168.1.64:40765: task 3 of framework 201203291014-0-0017 is now in state TASK_RUNNING
I0329 11:25:15.609369  6088 master.cpp:902] Status update from slave@192.168.1.64:40765: task 2 of framework 201203291014-0-0017 is now in state TASK_RUNNING
I0329 11:25:15.610770  6088 master.cpp:902] Status update from slave@192.168.1.64:40765: task 6 of framework 201203291014-0-0017 is now in state TASK_RUNNING
I0329 11:25:15.613162  6088 master.cpp:902] Status update from slave@192.168.1.64:40765: task 5 of framework 201203291014-0-0017 is now in state TASK_RUNNING
I0329 11:25:15.615398  6088 master.cpp:902] Status update from slave@192.168.1.64:40765: task 4 of framework 201203291014-0-0017 is now in state TASK_RUNNING
I0329 11:25:16.046229  6088 master.cpp:1184] Sending 1 offers to framework 201203291014-0-0016
I0329 11:25:16.047387  6088 master.cpp:679] Received reply for offer 201203291014-0-837
I0329 11:25:16.061391  6088 master.cpp:1403] Filtered slave 201203291014-0-3 for framework 201203291014-0-0016 for 1 seconds
I0329 11:25:16.967357  6088 master.cpp:902] Status update from slave@192.168.1.64:40765: task 0 of framework 201203291014-0-0017 is now in state TASK_FAILED
I0329 11:25:16.967681  6088 master.cpp:1184] Sending 1 offers to framework 201203291014-0-0016
I0329 11:25:16.967841  6088 master.cpp:1184] Sending 1 offers to framework 201203291014-0-0017
I0329 11:25:16.970350  6088 master.cpp:902] Status update from slave@192.168.1.64:40765: task 1 of framework 201203291014-0-0017 is now in state TASK_FAILED
I0329 11:25:16.972470  6088 master.cpp:902] Status update from slave@192.168.1.64:40765: task 4 of framework 201203291014-0-0017 is now in state TASK_FAILED
I0329 11:25:16.974270  6088 master.cpp:902] Status update from slave@192.168.1.64:40765: task 6 of framework 201203291014-0-0017 is now in state TASK_FAILED
I0329 11:25:16.976060  6088 master.cpp:902] Status update from slave@192.168.1.64:40765: task 7 of framework 201203291014-0-0017 is now in state TASK_FAILED
I0329 11:25:16.977833  6088 master.cpp:902] Status update from slave@192.168.1.64:40765: task 5 of framework 201203291014-0-0017 is now in state TASK_FAILED
I0329 11:25:16.979790  6088 master.cpp:902] Status update from slave@192.168.1.64:40765: task 2 of framework 201203291014-0-0017 is now in state TASK_FAILED
I0329 11:25:16.982139  6088 master.cpp:679] Received reply for offer 201203291014-0-838
I0329 11:25:16.982270  6088 master.cpp:1403] Filtered slave 201203291014-0-4 for framework 201203291014-0-0016 for 1 seconds
I0329 11:25:16.982683  6088 master.cpp:679] Received reply for offer 201203291014-0-839
I0329 11:25:16.982843  6088 master.cpp:1184] Sending 1 offers to framework 201203291014-0-0017
I0329 11:25:16.982940  6088 master.cpp:1403] Filtered slave 201203291014-0-3 for framework 201203291014-0-0017 for 1 seconds
I0329 11:25:17.032003  6088 master.cpp:679] Received reply for offer 201203291014-0-840
I0329 11:25:17.032192  6088 master.cpp:1453] Launching task 8 on slave 201203291014-0-4
I0329 11:25:17.032449  6088 master.cpp:1453] Launching task 9 on slave 201203291014-0-4
I0329 11:25:17.032629  6088 master.cpp:1453] Launching task 10 on slave 201203291014-0-4
I0329 11:25:17.032788  6088 master.cpp:1453] Launching task 11 on slave 201203291014-0-4
I0329 11:25:17.032881  6088 master.cpp:1453] Launching task 12 on slave 201203291014-0-4
I0329 11:25:17.034626  6088 master.cpp:1453] Launching task 13 on slave 201203291014-0-4
I0329 11:25:17.035245  6088 master.cpp:1453] Launching task 14 on slave 201203291014-0-4
I0329 11:25:17.506311  6088 master.cpp:1001] Executor default of framework 201203291014-0-0017 on slave 201203291014-0-4 (azad.gateway.2wire.net) exited with status 256
I0329 11:25:17.507845  6088 master.cpp:1033] Removing task 10 of framework 201203291014-0-0017 because of lost executor
I0329 11:25:17.508124  6088 master.cpp:1184] Sending 1 offers to framework 201203291014-0-0017
I0329 11:25:17.509778  6088 master.cpp:1033] Removing task 13 of framework 201203291014-0-0017 because of lost executor
I0329 11:25:17.511351  6088 master.cpp:1033] Removing task 14 of framework 201203291014-0-0017 because of lost executor
I0329 11:25:17.512861  6088 master.cpp:1033] Removing task 11 of framework 201203291014-0-0017 because of lost executor
I0329 11:25:17.514366  6088 master.cpp:1033] Removing task 12 of framework 201203291014-0-0017 because of lost executor
I0329 11:25:17.515650  6088 master.cpp:1033] Removing task 3 of framework 201203291014-0-0017 because of lost executor
I0329 11:25:17.516638  6088 master.cpp:1033] Removing task 8 of framework 201203291014-0-0017 because of lost executor
I0329 11:25:17.517688  6088 master.cpp:1033] Removing task 9 of framework 201203291014-0-0017 because of lost executor
I0329 11:25:17.517866  6088 master.cpp:679] Received reply for offer 201203291014-0-841
I0329 11:25:17.518189  6088 master.cpp:1453] Launching task 15 on slave 201203291014-0-4
I0329 11:25:18.048305  6088 master.cpp:1184] Sending 2 offers to framework 201203291014-0-0016
I0329 11:25:18.050133  6088 master.cpp:679] Received reply for offer 201203291014-0-842
I0329 11:25:18.050282  6088 master.cpp:1403] Filtered slave 201203291014-0-3 for framework 201203291014-0-0016 for 1 seconds
I0329 11:25:18.050518  6088 master.cpp:679] Received reply for offer 201203291014-0-843
I0329 11:25:18.050662  6088 master.cpp:1184] Sending 1 offers to framework 201203291014-0-0017
I0329 11:25:18.050765  6088 master.cpp:1403] Filtered slave 201203291014-0-4 for framework 201203291014-0-0016 for 1 seconds
I0329 11:25:18.051877  6088 master.cpp:679] Received reply for offer 201203291014-0-844
I0329 11:25:18.052031  6088 master.cpp:1184] Sending 1 offers to framework 201203291014-0-0017
I0329 11:25:18.052134  6088 master.cpp:1403] Filtered slave 201203291014-0-3 for framework 201203291014-0-0017 for 1 seconds
I0329 11:25:18.074666  6088 master.cpp:679] Received reply for offer 201203291014-0-845
I0329 11:25:18.074875  6088 master.cpp:1453] Launching task 16 on slave 201203291014-0-4
I0329 11:25:18.075139  6088 master.cpp:1453] Launching task 17 on slave 201203291014-0-4
I0329 11:25:18.075407  6088 master.cpp:1453] Launching task 18 on slave 201203291014-0-4
I0329 11:25:18.075698  6088 master.cpp:1453] Launching task 19 on slave 201203291014-0-4
I0329 11:25:18.075822  6088 master.cpp:1453] Launching task 20 on slave 201203291014-0-4
I0329 11:25:18.076275  6088 master.cpp:1453] Launching task 21 on slave 201203291014-0-4
I0329 11:25:18.076724  6088 master.cpp:1453] Launching task 22 on slave 201203291014-0-4
I0329 11:25:18.480851  6088 master.cpp:902] Status update from slave@192.168.1.64:40765: task 16 of framework 201203291014-0-0017 is now in state TASK_RUNNING
I0329 11:25:18.483556  6088 master.cpp:902] Status update from slave@192.168.1.64:40765: task 20 of framework 201203291014-0-0017 is now in state TASK_RUNNING
I0329 11:25:18.485983  6088 master.cpp:902] Status update from slave@192.168.1.64:40765: task 22 of framework 201203291014-0-0017 is now in state TASK_RUNNING
I0329 11:25:18.489199  6088 master.cpp:902] Status update from slave@192.168.1.64:40765: task 18 of framework 201203291014-0-0017 is now in state TASK_RUNNING
I0329 11:25:18.490993  6088 master.cpp:902] Status update from slave@192.168.1.64:40765: task 15 of framework 201203291014-0-0017 is now in state TASK_RUNNING
I0329 11:25:18.492842  6088 master.cpp:902] Status update from slave@192.168.1.64:40765: task 21 of framework 201203291014-0-0017 is now in state TASK_RUNNING
