Log file created at: 2012/03/29 04:23:34
Running on machine: azad
Log line format: [IWEF]mmdd hh:mm:ss.uuuuuu threadid file:line] msg
I0329 04:23:34.942718 26223 logging.cpp:70] Logging to /mesos-distro/logdir
I0329 04:23:34.943685 26223 main.cpp:95] Build: 2012-03-28 23:30:52 by hduser
I0329 04:23:34.943727 26223 main.cpp:96] Starting Mesos master
I0329 04:23:34.944886 26224 master.cpp:264] Master started at mesos://master@192.168.1.64:5050
I0329 04:23:34.944892 26223 webui.cpp:81] Starting master web server on port 9836
I0329 04:23:34.945080 26224 master.cpp:279] Master ID: 201203290423-0
I0329 04:23:34.945147 26227 webui.cpp:47] Master web server thread started
I0329 04:23:34.945487 26224 master.cpp:462] Elected as master!
I0329 04:23:34.956125 26227 webui.cpp:59] Loading webui/master/webui.py
I0329 04:23:39.138574 26224 master.cpp:814] Attempting to register slave 201203290423-0-0 at slave@192.168.1.64:34315
I0329 04:23:39.138777 26224 master.cpp:1057] Master now considering a slave at azad.gateway.2wire.net:34315 as active
I0329 04:23:39.138823 26224 master.cpp:1588] Adding slave 201203290423-0-0 at azad.gateway.2wire.net with cpus=8; mem=16384
I0329 04:23:39.138980 26224 simple_allocator.cpp:71] Added slave 201203290423-0-0 with cpus=8; mem=16384
I0329 04:24:32.242543 26224 master.cpp:492] Registering framework 201203290423-0-0000 at 3@192.168.1.64:43531
I0329 04:24:32.242710 26224 simple_allocator.cpp:48] Added framework 201203290423-0-0000
I0329 04:24:32.242826 26224 master.cpp:1184] Sending 1 offers to framework 201203290423-0-0000
I0329 04:24:32.243643 26224 master.cpp:492] Registering framework 201203290423-0-0001 at 2@192.168.1.64:43531
I0329 04:24:32.243695 26224 simple_allocator.cpp:48] Added framework 201203290423-0-0001
I0329 04:24:32.259925 26224 master.cpp:679] Received reply for offer 201203290423-0-0
I0329 04:24:32.260014 26224 master.cpp:1403] Filtered slave 201203290423-0-0 for framework 201203290423-0-0000 for 1 seconds
I0329 04:24:32.601676 26224 master.cpp:718] Reviving offers for framework 201203290423-0-0000
I0329 04:24:32.601722 26224 simple_allocator.cpp:145] Filters removed for framework 201203290423-0-0000
I0329 04:24:32.601801 26224 master.cpp:1184] Sending 1 offers to framework 201203290423-0-0001
I0329 04:24:32.603060 26224 master.cpp:679] Received reply for offer 201203290423-0-1
I0329 04:24:32.603185 26224 master.cpp:1403] Filtered slave 201203290423-0-0 for framework 201203290423-0-0001 for 1 seconds
I0329 04:24:33.015687 26224 master.cpp:1184] Sending 1 offers to framework 201203290423-0-0000
I0329 04:24:33.118801 26224 master.cpp:679] Received reply for offer 201203290423-0-2
I0329 04:24:33.118924 26224 master.cpp:1453] Launching task 0 on slave 201203290423-0-0
I0329 04:24:33.119096 26224 master.cpp:1453] Launching task 1 on slave 201203290423-0-0
I0329 04:24:33.119254 26224 master.cpp:1453] Launching task 2 on slave 201203290423-0-0
I0329 04:24:33.119392 26224 master.cpp:1453] Launching task 3 on slave 201203290423-0-0
I0329 04:24:33.119524 26224 master.cpp:1453] Launching task 4 on slave 201203290423-0-0
I0329 04:24:33.119611 26224 master.cpp:1453] Launching task 5 on slave 201203290423-0-0
I0329 04:24:33.119714 26224 master.cpp:1453] Launching task 6 on slave 201203290423-0-0
I0329 04:24:33.119799 26224 master.cpp:1453] Launching task 7 on slave 201203290423-0-0
I0329 04:24:34.091603 26224 master.cpp:902] Status update from slave@192.168.1.64:34315: task 3 of framework 201203290423-0-0000 is now in state TASK_RUNNING
I0329 04:24:34.094550 26224 master.cpp:902] Status update from slave@192.168.1.64:34315: task 1 of framework 201203290423-0-0000 is now in state TASK_RUNNING
I0329 04:24:34.096987 26224 master.cpp:902] Status update from slave@192.168.1.64:34315: task 5 of framework 201203290423-0-0000 is now in state TASK_RUNNING
I0329 04:24:34.099632 26224 master.cpp:902] Status update from slave@192.168.1.64:34315: task 0 of framework 201203290423-0-0000 is now in state TASK_RUNNING
I0329 04:24:34.102041 26224 master.cpp:902] Status update from slave@192.168.1.64:34315: task 7 of framework 201203290423-0-0000 is now in state TASK_RUNNING
I0329 04:24:34.104390 26224 master.cpp:902] Status update from slave@192.168.1.64:34315: task 4 of framework 201203290423-0-0000 is now in state TASK_RUNNING
I0329 04:24:34.106636 26224 master.cpp:902] Status update from slave@192.168.1.64:34315: task 6 of framework 201203290423-0-0000 is now in state TASK_RUNNING
I0329 04:24:34.109031 26224 master.cpp:902] Status update from slave@192.168.1.64:34315: task 2 of framework 201203290423-0-0000 is now in state TASK_RUNNING
I0329 04:24:35.177688 26224 master.cpp:902] Status update from slave@192.168.1.64:34315: task 4 of framework 201203290423-0-0000 is now in state TASK_FINISHED
I0329 04:24:35.177928 26224 master.cpp:1184] Sending 1 offers to framework 201203290423-0-0001
I0329 04:24:35.181296 26224 master.cpp:902] Status update from slave@192.168.1.64:34315: task 3 of framework 201203290423-0-0000 is now in state TASK_FINISHED
I0329 04:24:35.184262 26224 master.cpp:902] Status update from slave@192.168.1.64:34315: task 6 of framework 201203290423-0-0000 is now in state TASK_FINISHED
I0329 04:24:35.187150 26224 master.cpp:902] Status update from slave@192.168.1.64:34315: task 0 of framework 201203290423-0-0000 is now in state TASK_FINISHED
I0329 04:24:35.189949 26224 master.cpp:902] Status update from slave@192.168.1.64:34315: task 5 of framework 201203290423-0-0000 is now in state TASK_FINISHED
I0329 04:24:35.192570 26224 master.cpp:902] Status update from slave@192.168.1.64:34315: task 2 of framework 201203290423-0-0000 is now in state TASK_FINISHED
I0329 04:24:35.194310 26224 master.cpp:902] Status update from slave@192.168.1.64:34315: task 7 of framework 201203290423-0-0000 is now in state TASK_FINISHED
I0329 04:24:35.198922 26224 master.cpp:679] Received reply for offer 201203290423-0-3
I0329 04:24:35.199112 26224 master.cpp:1403] Filtered slave 201203290423-0-0 for framework 201203290423-0-0001 for 1 seconds
I0329 04:24:35.205665 26224 master.cpp:902] Status update from slave@192.168.1.64:34315: task 1 of framework 201203290423-0-0000 is now in state TASK_FINISHED
I0329 04:24:35.205968 26224 master.cpp:1184] Sending 1 offers to framework 201203290423-0-0000
I0329 04:24:35.248172 26224 master.cpp:679] Received reply for offer 201203290423-0-4
I0329 04:24:35.248327 26224 master.cpp:1453] Launching task 8 on slave 201203290423-0-0
I0329 04:24:35.248613 26224 master.cpp:1453] Launching task 9 on slave 201203290423-0-0
I0329 04:24:35.248880 26224 master.cpp:1453] Launching task 10 on slave 201203290423-0-0
I0329 04:24:35.249759 26224 master.cpp:1453] Launching task 11 on slave 201203290423-0-0
I0329 04:24:35.250023 26224 master.cpp:1453] Launching task 12 on slave 201203290423-0-0
I0329 04:24:35.250248 26224 master.cpp:1453] Launching task 13 on slave 201203290423-0-0
I0329 04:24:35.250475 26224 master.cpp:1453] Launching task 14 on slave 201203290423-0-0
I0329 04:24:35.250730 26224 master.cpp:1453] Launching task 15 on slave 201203290423-0-0
I0329 04:24:35.253425 26224 master.cpp:902] Status update from slave@192.168.1.64:34315: task 8 of framework 201203290423-0-0000 is now in state TASK_RUNNING
I0329 04:24:35.258556 26224 master.cpp:902] Status update from slave@192.168.1.64:34315: task 9 of framework 201203290423-0-0000 is now in state TASK_RUNNING
I0329 04:24:35.259922 26224 master.cpp:902] Status update from slave@192.168.1.64:34315: task 10 of framework 201203290423-0-0000 is now in state TASK_RUNNING
I0329 04:24:35.261464 26224 master.cpp:902] Status update from slave@192.168.1.64:34315: task 11 of framework 201203290423-0-0000 is now in state TASK_RUNNING
I0329 04:24:35.263020 26224 master.cpp:902] Status update from slave@192.168.1.64:34315: task 15 of framework 201203290423-0-0000 is now in state TASK_RUNNING
I0329 04:24:35.264660 26224 master.cpp:902] Status update from slave@192.168.1.64:34315: task 12 of framework 201203290423-0-0000 is now in state TASK_RUNNING
I0329 04:24:35.266290 26224 master.cpp:902] Status update from slave@192.168.1.64:34315: task 14 of framework 201203290423-0-0000 is now in state TASK_RUNNING
I0329 04:24:35.271502 26224 master.cpp:902] Status update from slave@192.168.1.64:34315: task 13 of framework 201203290423-0-0000 is now in state TASK_RUNNING
I0329 04:24:35.366792 26224 master.cpp:902] Status update from slave@192.168.1.64:34315: task 10 of framework 201203290423-0-0000 is now in state TASK_FINISHED
I0329 04:24:35.367100 26224 master.cpp:1184] Sending 1 offers to framework 201203290423-0-0000
I0329 04:24:35.374706 26224 master.cpp:902] Status update from slave@192.168.1.64:34315: task 9 of framework 201203290423-0-0000 is now in state TASK_FINISHED
I0329 04:24:35.379155 26224 master.cpp:679] Received reply for offer 201203290423-0-5
I0329 04:24:35.379338 26224 master.cpp:1453] Launching task 16 on slave 201203290423-0-0
I0329 04:24:35.382597 26224 master.cpp:902] Status update from slave@192.168.1.64:34315: task 8 of framework 201203290423-0-0000 is now in state TASK_FINISHED
I0329 04:24:35.382897 26224 master.cpp:1184] Sending 1 offers to framework 201203290423-0-0000
I0329 04:24:35.387332 26224 master.cpp:902] Status update from slave@192.168.1.64:34315: task 16 of framework 201203290423-0-0000 is now in state TASK_RUNNING
I0329 04:24:35.390316 26224 master.cpp:902] Status update from slave@192.168.1.64:34315: task 13 of framework 201203290423-0-0000 is now in state TASK_FINISHED
I0329 04:24:35.395331 26224 master.cpp:902] Status update from slave@192.168.1.64:34315: task 15 of framework 201203290423-0-0000 is now in state TASK_FINISHED
I0329 04:24:35.399888 26224 master.cpp:902] Status update from slave@192.168.1.64:34315: task 11 of framework 201203290423-0-0000 is now in state TASK_FINISHED
I0329 04:24:35.408934 26224 master.cpp:902] Status update from slave@192.168.1.64:34315: task 14 of framework 201203290423-0-0000 is now in state TASK_FINISHED
I0329 04:24:35.430680 26224 master.cpp:679] Received reply for offer 201203290423-0-6
I0329 04:24:35.430831 26224 master.cpp:1453] Launching task 17 on slave 201203290423-0-0
I0329 04:24:35.431177 26224 master.cpp:1453] Launching task 18 on slave 201203290423-0-0
I0329 04:24:35.447307 26224 master.cpp:902] Status update from slave@192.168.1.64:34315: task 12 of framework 201203290423-0-0000 is now in state TASK_FINISHED
I0329 04:24:35.447624 26224 master.cpp:1184] Sending 1 offers to framework 201203290423-0-0000
I0329 04:24:35.448425 26224 master.cpp:902] Status update from slave@192.168.1.64:34315: task 17 of framework 201203290423-0-0000 is now in state TASK_RUNNING
I0329 04:24:35.449089 26224 master.cpp:902] Status update from slave@192.168.1.64:34315: task 18 of framework 201203290423-0-0000 is now in state TASK_RUNNING
I0329 04:24:35.483325 26224 master.cpp:679] Received reply for offer 201203290423-0-7
I0329 04:24:35.483511 26224 master.cpp:1453] Launching task 19 on slave 201203290423-0-0
I0329 04:24:35.483808 26224 master.cpp:1453] Launching task 20 on slave 201203290423-0-0
I0329 04:24:35.483991 26224 master.cpp:1453] Launching task 21 on slave 201203290423-0-0
I0329 04:24:35.484169 26224 master.cpp:1453] Launching task 22 on slave 201203290423-0-0
I0329 04:24:35.485251 26224 master.cpp:1453] Launching task 23 on slave 201203290423-0-0
I0329 04:24:35.490880 26224 master.cpp:902] Status update from slave@192.168.1.64:34315: task 16 of framework 201203290423-0-0000 is now in state TASK_FINISHED
I0329 04:24:35.491205 26224 master.cpp:1184] Sending 1 offers to framework 201203290423-0-0000
I0329 04:24:35.493000 26224 master.cpp:902] Status update from slave@192.168.1.64:34315: task 19 of framework 201203290423-0-0000 is now in state TASK_RUNNING
I0329 04:24:35.493218 26224 master.cpp:902] Status update from slave@192.168.1.64:34315: task 20 of framework 201203290423-0-0000 is now in state TASK_RUNNING
I0329 04:24:35.497107 26224 master.cpp:902] Status update from slave@192.168.1.64:34315: task 21 of framework 201203290423-0-0000 is now in state TASK_RUNNING
I0329 04:24:35.498559 26224 master.cpp:679] Received reply for offer 201203290423-0-8
I0329 04:24:35.498704 26224 master.cpp:1453] Launching task 24 on slave 201203290423-0-0
I0329 04:24:35.499130 26224 master.cpp:902] Status update from slave@192.168.1.64:34315: task 22 of framework 201203290423-0-0000 is now in state TASK_RUNNING
I0329 04:24:35.514857 26224 master.cpp:902] Status update from slave@192.168.1.64:34315: task 23 of framework 201203290423-0-0000 is now in state TASK_RUNNING
I0329 04:24:35.519721 26224 master.cpp:902] Status update from slave@192.168.1.64:34315: task 17 of framework 201203290423-0-0000 is now in state TASK_FINISHED
I0329 04:24:35.520012 26224 master.cpp:1184] Sending 1 offers to framework 201203290423-0-0000
I0329 04:24:35.526041 26224 master.cpp:902] Status update from slave@192.168.1.64:34315: task 18 of framework 201203290423-0-0000 is now in state TASK_FINISHED
I0329 04:24:35.527799 26224 master.cpp:679] Received reply for offer 201203290423-0-9
I0329 04:24:35.527943 26224 master.cpp:1453] Launching task 25 on slave 201203290423-0-0
I0329 04:24:35.567680 26224 master.cpp:902] Status update from slave@192.168.1.64:34315: task 24 of framework 201203290423-0-0000 is now in state TASK_RUNNING
I0329 04:24:35.571624 26224 master.cpp:902] Status update from slave@192.168.1.64:34315: task 25 of framework 201203290423-0-0000 is now in state TASK_RUNNING
I0329 04:24:35.601459 26224 master.cpp:902] Status update from slave@192.168.1.64:34315: task 23 of framework 201203290423-0-0000 is now in state TASK_FINISHED
I0329 04:24:35.601706 26224 master.cpp:1184] Sending 1 offers to framework 201203290423-0-0000
I0329 04:24:35.609623 26224 master.cpp:679] Received reply for offer 201203290423-0-10
I0329 04:24:35.609774 26224 master.cpp:1453] Launching task 26 on slave 201203290423-0-0
I0329 04:24:35.610049 26224 master.cpp:1453] Launching task 27 on slave 201203290423-0-0
I0329 04:24:35.639410 26224 master.cpp:902] Status update from slave@192.168.1.64:34315: task 22 of framework 201203290423-0-0000 is now in state TASK_FINISHED
I0329 04:24:35.639626 26224 master.cpp:1184] Sending 1 offers to framework 201203290423-0-0000
I0329 04:24:35.639807 26224 master.cpp:902] Status update from slave@192.168.1.64:34315: task 19 of framework 201203290423-0-0000 is now in state TASK_FINISHED
I0329 04:24:35.640106 26224 master.cpp:902] Status update from slave@192.168.1.64:34315: task 26 of framework 201203290423-0-0000 is now in state TASK_RUNNING
I0329 04:24:35.640280 26224 master.cpp:902] Status update from slave@192.168.1.64:34315: task 21 of framework 201203290423-0-0000 is now in state TASK_FINISHED
I0329 04:24:35.640579 26224 master.cpp:902] Status update from slave@192.168.1.64:34315: task 24 of framework 201203290423-0-0000 is now in state TASK_FINISHED
I0329 04:24:35.641176 26224 master.cpp:902] Status update from slave@192.168.1.64:34315: task 20 of framework 201203290423-0-0000 is now in state TASK_FINISHED
I0329 04:24:35.644906 26224 master.cpp:679] Received reply for offer 201203290423-0-11
I0329 04:24:35.645040 26224 master.cpp:1453] Launching task 28 on slave 201203290423-0-0
I0329 04:24:35.683329 26224 master.cpp:902] Status update from slave@192.168.1.64:34315: task 27 of framework 201203290423-0-0000 is now in state TASK_RUNNING
I0329 04:24:35.683547 26224 master.cpp:902] Status update from slave@192.168.1.64:34315: task 28 of framework 201203290423-0-0000 is now in state TASK_RUNNING
I0329 04:24:35.700027 26224 master.cpp:902] Status update from slave@192.168.1.64:34315: task 28 of framework 201203290423-0-0000 is now in state TASK_FINISHED
I0329 04:24:35.700235 26224 master.cpp:1184] Sending 1 offers to framework 201203290423-0-0000
I0329 04:24:35.702354 26224 master.cpp:902] Status update from slave@192.168.1.64:34315: task 27 of framework 201203290423-0-0000 is now in state TASK_FINISHED
I0329 04:24:35.729456 26224 master.cpp:679] Received reply for offer 201203290423-0-12
I0329 04:24:35.729614 26224 master.cpp:1453] Launching task 29 on slave 201203290423-0-0
I0329 04:24:35.729995 26224 master.cpp:1453] Launching task 30 on slave 201203290423-0-0
I0329 04:24:35.730319 26224 master.cpp:1453] Launching task 31 on slave 201203290423-0-0
I0329 04:24:35.730499 26224 master.cpp:1453] Launching task 32 on slave 201203290423-0-0
I0329 04:24:35.730869 26224 master.cpp:1453] Launching task 33 on slave 201203290423-0-0
I0329 04:24:35.739269 26224 master.cpp:902] Status update from slave@192.168.1.64:34315: task 30 of framework 201203290423-0-0000 is now in state TASK_RUNNING
I0329 04:24:35.739452 26224 master.cpp:902] Status update from slave@192.168.1.64:34315: task 29 of framework 201203290423-0-0000 is now in state TASK_RUNNING
I0329 04:24:35.739938 26224 master.cpp:902] Status update from slave@192.168.1.64:34315: task 31 of framework 201203290423-0-0000 is now in state TASK_RUNNING
I0329 04:24:35.779278 26224 master.cpp:902] Status update from slave@192.168.1.64:34315: task 32 of framework 201203290423-0-0000 is now in state TASK_RUNNING
I0329 04:24:35.779500 26224 master.cpp:902] Status update from slave@192.168.1.64:34315: task 33 of framework 201203290423-0-0000 is now in state TASK_RUNNING
I0329 04:24:35.810904 26224 master.cpp:902] Status update from slave@192.168.1.64:34315: task 29 of framework 201203290423-0-0000 is now in state TASK_FINISHED
I0329 04:24:35.811208 26224 master.cpp:1184] Sending 1 offers to framework 201203290423-0-0000
I0329 04:24:35.813009 26224 master.cpp:902] Status update from slave@192.168.1.64:34315: task 30 of framework 201203290423-0-0000 is now in state TASK_FINISHED
I0329 04:24:35.818135 26224 master.cpp:679] Received reply for offer 201203290423-0-13
I0329 04:24:35.818282 26224 master.cpp:1453] Launching task 34 on slave 201203290423-0-0
I0329 04:24:35.818500 26224 master.cpp:1453] Launching task 35 on slave 201203290423-0-0
I0329 04:24:35.851284 26224 master.cpp:902] Status update from slave@192.168.1.64:34315: task 32 of framework 201203290423-0-0000 is now in state TASK_FINISHED
I0329 04:24:35.851541 26224 master.cpp:1184] Sending 1 offers to framework 201203290423-0-0000
I0329 04:24:35.851686 26224 master.cpp:902] Status update from slave@192.168.1.64:34315: task 31 of framework 201203290423-0-0000 is now in state TASK_FINISHED
I0329 04:24:35.851939 26224 master.cpp:902] Status update from slave@192.168.1.64:34315: task 33 of framework 201203290423-0-0000 is now in state TASK_FINISHED
I0329 04:24:35.852161 26224 master.cpp:902] Status update from slave@192.168.1.64:34315: task 34 of framework 201203290423-0-0000 is now in state TASK_RUNNING
I0329 04:24:35.852298 26224 master.cpp:902] Status update from slave@192.168.1.64:34315: task 25 of framework 201203290423-0-0000 is now in state TASK_FINISHED
I0329 04:24:35.891290 26224 master.cpp:902] Status update from slave@192.168.1.64:34315: task 35 of framework 201203290423-0-0000 is now in state TASK_RUNNING
I0329 04:24:35.891520 26224 master.cpp:902] Status update from slave@192.168.1.64:34315: task 34 of framework 201203290423-0-0000 is now in state TASK_FINISHED
I0329 04:24:35.897917 26224 master.cpp:679] Received reply for offer 201203290423-0-14
I0329 04:24:35.898100 26224 master.cpp:1453] Launching task 36 on slave 201203290423-0-0
I0329 04:24:35.898368 26224 master.cpp:1453] Launching task 37 on slave 201203290423-0-0
I0329 04:24:35.904141 26224 master.cpp:902] Status update from slave@192.168.1.64:34315: task 36 of framework 201203290423-0-0000 is now in state TASK_RUNNING
I0329 04:24:35.906700 26224 master.cpp:902] Status update from slave@192.168.1.64:34315: task 26 of framework 201203290423-0-0000 is now in state TASK_FINISHED
I0329 04:24:35.906903 26224 master.cpp:1184] Sending 1 offers to framework 201203290423-0-0000
I0329 04:24:35.924171 26224 master.cpp:902] Status update from slave@192.168.1.64:34315: task 35 of framework 201203290423-0-0000 is now in state TASK_FINISHED
I0329 04:24:35.938781 26224 master.cpp:679] Received reply for offer 201203290423-0-15
I0329 04:24:35.938947 26224 master.cpp:1453] Launching task 38 on slave 201203290423-0-0
I0329 04:24:35.939306 26224 master.cpp:1453] Launching task 39 on slave 201203290423-0-0
I0329 04:24:35.963294 26224 master.cpp:902] Status update from slave@192.168.1.64:34315: task 37 of framework 201203290423-0-0000 is now in state TASK_RUNNING
I0329 04:24:35.963496 26224 master.cpp:902] Status update from slave@192.168.1.64:34315: task 38 of framework 201203290423-0-0000 is now in state TASK_RUNNING
I0329 04:24:35.963759 26224 master.cpp:902] Status update from slave@192.168.1.64:34315: task 39 of framework 201203290423-0-0000 is now in state TASK_RUNNING
I0329 04:24:36.003434 26224 master.cpp:902] Status update from slave@192.168.1.64:34315: task 36 of framework 201203290423-0-0000 is now in state TASK_FINISHED
I0329 04:24:36.003720 26224 master.cpp:1184] Sending 1 offers to framework 201203290423-0-0000
I0329 04:24:36.003865 26224 master.cpp:902] Status update from slave@192.168.1.64:34315: task 37 of framework 201203290423-0-0000 is now in state TASK_FINISHED
I0329 04:24:36.004262 26224 master.cpp:902] Status update from slave@192.168.1.64:34315: task 38 of framework 201203290423-0-0000 is now in state TASK_FINISHED
I0329 04:24:36.006029 26224 master.cpp:679] Received reply for offer 201203290423-0-16
I0329 04:24:36.006186 26224 master.cpp:1403] Filtered slave 201203290423-0-0 for framework 201203290423-0-0000 for 1 seconds
I0329 04:24:36.047363 26224 master.cpp:902] Status update from slave@192.168.1.64:34315: task 39 of framework 201203290423-0-0000 is now in state TASK_FINISHED
I0329 04:24:36.489354 26224 master.cpp:1118] Framework 201203290423-0-0001 disconnected
I0329 04:24:36.489547 26224 master.cpp:1118] Framework 201203290423-0-0000 disconnected
I0329 04:25:02.926977 26224 master.cpp:1143] Slave 201203290423-0-0 disconnected
I0329 04:25:02.927386 26224 simple_allocator.cpp:83] Removed slave 201203290423-0-0
